Workbook

Sheet README
B1: DCT Laboratory — Vol II, Ch 5: Dynamic Enterprise Optimization
B2: Seed 26205 · Companion to DCT_V2_Ch05_Lab.ipynb and AXIOM Lab 2.5 (module AXIOM-05). Money in $ million.
B4: Worked Example 5.1, When Should Meridian Pay Its Shareholders?, with the book's declarations, in formulas.
B5: Declarations: the inputs of Step 1. Simulate: the CFO's rule and decisions judged year by year (Step 2).
B6: Transcribe: all 64 schedules of rounds, each with its war chest, its payouts and its value; BestPlan: the best of them, year by year (Step 3).
B7: Prices: the prices of cash and of efficiency, the binding commitments, perturbation checks and the round test (Step 4).
B8: Rates: the best plan at hurdle rates from 3 to 30 percent and the switch rates certified; Horizons: terminal values and planning windows of 1 to 20 years (Step 5).
B9: Replan: the present-biased board's yearly re-plans (Section 5.6). Stress and ShortfallKnown: each round a point short, Step 3's schedule against the war-chest rule (Step 6).
B10: Table5_3: Table 5.3 assembled from these sheets. The bisection for the switch rates, the linear-program check, the rolling windows and the figures run in the notebook.
B11: Reference_Values and Checks: the engine's numbers and a PASS/FAIL comparison with this workbook's formulas.
B13: LEGEND
B14: Input: blue on pale gold. A declaration from the book; change it to explore.
... B17: Cross-sheet link: green.

Sheet Declarations
A1: Declarations (Worked Example 5.1, Step 1). Money in $ million; efficiency in points.
A3: Quantity | B3: Value | C3: Source
A4: Hurdle rate r (a year) | B4: 0.1 | C4: The board's declaration: payouts discounted at 10 percent a year
A5: Discount factor a year, beta = 1/(1 + r) | B5: =1/(1+B4) -> 0.90909091
A6: Cost of a round | B6: 120 | C6: Volume I, Worked Example 6.1
A7: Efficiency ceiling | B7: 85 | C7: A round closes half the gap to 85
A8: Share of the remaining gap a round closes | B8: 0.5
A9: Savings per point of efficiency a year | B9: 10 | C9: S_k = 10 (e_k - 71)
A10: Today's efficiency, e_0 | B10: 71
A11: Today's cash, q_0 | B11: 620
A12: Floor on cash at every year end | B12: 350 | C12: The board's $350 million floor
A13: Cash a round needs on hand when it starts | B13: 470 | C13: So the floor holds after paying for the round
A14: End condition: cash at the end of year 6 | B14: 470 | C14: Cash for another round
A15: Life of the automated lines (years) | B15: 20 | C15: Step 5: savings valued only over the lines' life
A16: Part I's years of undiscounted credit | B16: 10 | C16: Worked Examples 2.1 and 3.1
A17: Shortfall per round in the stress scenario (points) | B17: 1 | C17: Step 6: each round a point short
A18: Present-biased board's weight on later years, b | B18: 0.9 | C18: Section 5.6: later years at 90 percent
A20: Six years, one period a year; cash earns nothing. Dynamics: e_k = e_(k-1) + z_k (85 - e_(k-1))/2; q_k = q_(k-1) - 120 z_k + S_k - p_k. A round needs q_(k-1) >= 470; every year ends with q_k >= 350; year 6 ends with q_6 >= 470.
A21: Value: sum over k of beta^k p_k + beta^6 S_6 / r, the payouts plus the year-6 savings forever (at 10 percent the perpetuity is 10 S_6, Part I's ten years of credit).

Sheet Simulate
A1: Simulate: the CFO's rule (Proposition 5.1; Worked Example 5.1, Step 2; AXIOM Lab 2.5, step 1)
A2: Pay out, every year end, whatever cash exceeds the floor; a planned round runs only if the year opens with the cash it needs. The payout leaves 350, so no round after the first can start.
A4: The CFO's rule: rounds planned for years 1 to 3
A5: Year | B5: Round planned | C5: Cash at the start | D5: Round runs | E5: Efficiency | F5: Savings | G5: Payout | H5: Year-end cash | I5: Discount factor | J5: PV of payout | K5: Breach
A6: 1 | B6: 1 | C6: =Q_zero -> 620 | D6: =IF(AND(B6=1,C6>=Pre_q-0.000000001),1,0) -> 1 | E6: =E_zero+D6*(Half_gap*(Ceiling_e-E_zero)-0) -> 78 | F6: =Val_pt*(E6-E_zero) -> 70 | G6: =MAX(0,C6-Cost_round*D6+F6-Floor_q) -> 220 | H6: =C6-Cost_round*D6+F6-G6 -> 350 | I6: =Beta_y^A6 -> 0.90909091 | J6: =G6*I6 -> 200 | K6: =IF(AND(B6=1,D6=0),"round cannot start; ","")&IF(H6<Floor_q-0.000000001,"floor breached; ","")
A7: 2 | B7: 1 | C7: =H6 -> 350 | D7: =IF(AND(B7=1,C7>=Pre_q-0.000000001),1,0) -> 0 | E7: =E6+D7*(Half_gap*(Ceiling_e-E6)-0) -> 78 | F7: =Val_pt*(E7-E_zero) -> 70 | G7: =MAX(0,C7-Cost_round*D7+F7-Floor_q) -> 70 | H7: =C7-Cost_round*D7+F7-G7 -> 350 | I7: =Beta_y^A7 -> 0.82644628 | J7: =G7*I7 -> 57.85124 | K7: =IF(AND(B7=1,D7=0),"round cannot start; ","")&IF(H7<Floor_q-0.000000001,"floor breached; ","") -> round cannot start;
A8: 3 | B8: 1 | C8: =H7 -> 350 | D8: =IF(AND(B8=1,C8>=Pre_q-0.000000001),1,0) -> 0 | E8: =E7+D8*(Half_gap*(Ceiling_e-E7)-0) -> 78 | F8: =Val_pt*(E8-E_zero) -> 70 | G8: =MAX(0,C8-Cost_round*D8+F8-Floor_q) -> 70 | H8: =C8-Cost_round*D8+F8-G8 -> 350 | I8: =Beta_y^A8 -> 0.7513148 | J8: =G8*I8 -> 52.592036 | K8: =IF(AND(B8=1,D8=0),"round cannot start; ","")&IF(H8<Floor_q-0.000000001,"floor breached; ","") -> round cannot start;
A9: 4 | B9: 0 | C9: =H8 -> 350 | D9: =IF(AND(B9=1,C9>=Pre_q-0.000000001),1,0) -> 0 | E9: =E8+D9*(Half_gap*(Ceiling_e-E8)-0) -> 78 | F9: =Val_pt*(E9-E_zero) -> 70 | G9: =MAX(0,C9-Cost_round*D9+F9-Floor_q) -> 70 | H9: =C9-Cost_round*D9+F9-G9 -> 350 | I9: =Beta_y^A9 -> 0.68301346 | J9: =G9*I9 -> 47.810942 | K9: =IF(AND(B9=1,D9=0),"round cannot start; ","")&IF(H9<Floor_q-0.000000001,"floor breached; ","")
A10: 5 | B10: 0 | C10: =H9 -> 350 | D10: =IF(AND(B10=1,C10>=Pre_q-0.000000001),1,0) -> 0 | E10: =E9+D10*(Half_gap*(Ceiling_e-E9)-0) -> 78 | F10: =Val_pt*(E10-E_zero) -> 70 | G10: =MAX(0,C10-Cost_round*D10+F10-Floor_q) -> 70 | H10: =C10-Cost_round*D10+F10-G10 -> 350 | I10: =Beta_y^A10 -> 0.62092132 | J10: =G10*I10 -> 43.464493 | K10: =IF(AND(B10=1,D10=0),"round cannot start; ","")&IF(H10<Floor_q-0.000000001,"floor breached; ","")
A11: 6 | B11: 0 | C11: =H10 -> 350 | D11: =IF(AND(B11=1,C11>=Pre_q-0.000000001),1,0) -> 0 | E11: =E10+D11*(Half_gap*(Ceiling_e-E10)-0) -> 78 | F11: =Val_pt*(E11-E_zero) -> 70 | G11: =MAX(0,C11-Cost_round*D11+F11-Floor_q) -> 70 | H11: =C11-Cost_round*D11+F11-G11 -> 350 | I11: =Beta_y^A11 -> 0.56447393 | J11: =G11*I11 -> 39.513175 | K11: =IF(AND(B11=1,D11=0),"round cannot start; ","")&IF(H11<Floor_q-0.000000001,"floor breached; ","")&IF(H11<End_q-0.000000001,"end condition missed","") -> end condition missed
A13: Rounds run | H13: =SUM(D6:D11) -> 1
A14: Planned rounds that could not start | H14: =SUMPRODUCT((B6:B11=1)*(D6:D11=0)) -> 2
A15: Year ends below the floor | H15: =COUNTIF(H6:H11,"<"&(Floor_q-0.000000001)) -> 0
A16: Cash at the end of year 6 | H16: =H11 -> 350
A17: End condition | H17: =IF(H11>=End_q-0.000000001,"kept","missed") -> missed
A18: Payouts, present value | H18: =SUM(J6:J11) -> 441.23189
A19: Savings after year 6 forever, today | H19: =I11*F11/Hurdle_r -> 395.13175
A20: Value: payouts plus savings forever (-- if the floor breaks) | H20: =IF(H15>0,"--",H18+H19) -> 836.36364
A23: Decided year by year: no round is ever worth its cost within its own year
A24: Year | B24: Round planned | C24: Cash at the start | D24: Round runs | E24: Efficiency | F24: Savings | G24: Payout | H24: Year-end cash | I24: Discount factor | J24: PV of payout | K24: Breach
A25: 1 | B25: 0 | C25: =Q_zero -> 620 | D25: =IF(AND(B25=1,C25>=Pre_q-0.000000001),1,0) -> 0 | E25: =E_zero+D25*(Half_gap*(Ceiling_e-E_zero)-0) -> 71 | F25: =Val_pt*(E25-E_zero) -> 0 | G25: =MAX(0,C25-Cost_round*D25+F25-Floor_q) -> 270 | H25: =C25-Cost_round*D25+F25-G25 -> 350 | I25: =Beta_y^A25 -> 0.90909091 | J25: =G25*I25 -> 245.45455 | K25: =IF(AND(B25=1,D25=0),"round cannot start; ","")&IF(H25<Floor_q-0.000000001,"floor breached; ","")
A26: 2 | B26: 0 | C26: =H25 -> 350 | D26: =IF(AND(B26=1,C26>=Pre_q-0.000000001),1,0) -> 0 | E26: =E25+D26*(Half_gap*(Ceiling_e-E25)-0) -> 71 | F26: =Val_pt*(E26-E_zero) -> 0 | G26: =MAX(0,C26-Cost_round*D26+F26-Floor_q) -> 0 | H26: =C26-Cost_round*D26+F26-G26 -> 350 | I26: =Beta_y^A26 -> 0.82644628 | J26: =G26*I26 -> 0 | K26: =IF(AND(B26=1,D26=0),"round cannot start; ","")&IF(H26<Floor_q-0.000000001,"floor breached; ","")
A27: 3 | B27: 0 | C27: =H26 -> 350 | D27: =IF(AND(B27=1,C27>=Pre_q-0.000000001),1,0) -> 0 | E27: =E26+D27*(Half_gap*(Ceiling_e-E26)-0) -> 71 | F27: =Val_pt*(E27-E_zero) -> 0 | G27: =MAX(0,C27-Cost_round*D27+F27-Floor_q) -> 0 | H27: =C27-Cost_round*D27+F27-G27 -> 350 | I27: =Beta_y^A27 -> 0.7513148 | J27: =G27*I27 -> 0 | K27: =IF(AND(B27=1,D27=0),"round cannot start; ","")&IF(H27<Floor_q-0.000000001,"floor breached; ","")
A28: 4 | B28: 0 | C28: =H27 -> 350 | D28: =IF(AND(B28=1,C28>=Pre_q-0.000000001),1,0) -> 0 | E28: =E27+D28*(Half_gap*(Ceiling_e-E27)-0) -> 71 | F28: =Val_pt*(E28-E_zero) -> 0 | G28: =MAX(0,C28-Cost_round*D28+F28-Floor_q) -> 0 | H28: =C28-Cost_round*D28+F28-G28 -> 350 | I28: =Beta_y^A28 -> 0.68301346 | J28: =G28*I28 -> 0 | K28: =IF(AND(B28=1,D28=0),"round cannot start; ","")&IF(H28<Floor_q-0.000000001,"floor breached; ","")
A29: 5 | B29: 0 | C29: =H28 -> 350 | D29: =IF(AND(B29=1,C29>=Pre_q-0.000000001),1,0) -> 0 | E29: =E28+D29*(Half_gap*(Ceiling_e-E28)-0) -> 71 | F29: =Val_pt*(E29-E_zero) -> 0 | G29: =MAX(0,C29-Cost_round*D29+F29-Floor_q) -> 0 | H29: =C29-Cost_round*D29+F29-G29 -> 350 | I29: =Beta_y^A29 -> 0.62092132 | J29: =G29*I29 -> 0 | K29: =IF(AND(B29=1,D29=0),"round cannot start; ","")&IF(H29<Floor_q-0.000000001,"floor breached; ","")
A30: 6 | B30: 0 | C30: =H29 -> 350 | D30: =IF(AND(B30=1,C30>=Pre_q-0.000000001),1,0) -> 0 | E30: =E29+D30*(Half_gap*(Ceiling_e-E29)-0) -> 71 | F30: =Val_pt*(E30-E_zero) -> 0 | G30: =MAX(0,C30-Cost_round*D30+F30-Floor_q) -> 0 | H30: =C30-Cost_round*D30+F30-G30 -> 350 | I30: =Beta_y^A30 -> 0.56447393 | J30: =G30*I30 -> 0 | K30: =IF(AND(B30=1,D30=0),"round cannot start; ","")&IF(H30<Floor_q-0.000000001,"floor breached; ","")&IF(H30<End_q-0.000000001,"end condition missed","") -> end condition missed
A32: Rounds run | H32: =SUM(D25:D30) -> 0
A33: Planned rounds that could not start | H33: =SUMPRODUCT((B25:B30=1)*(D25:D30=0)) -> 0
A34: Year ends below the floor | H34: =COUNTIF(H25:H30,"<"&(Floor_q-0.000000001)) -> 0
A35: Cash at the end of year 6 | H35: =H30 -> 350
A36: End condition | H36: =IF(H30>=End_q-0.000000001,"kept","missed") -> missed
A37: Payouts, present value | H37: =SUM(J25:J30) -> 245.45455
A38: Savings after year 6 forever, today | H38: =I30*F30/Hurdle_r -> 0
A39: Value: payouts plus savings forever (-- if the floor breaks) | H39: =IF(H34>0,"--",H37+H38) -> 245.45455
A42: Most savings a round adds in its own year | H42: =Val_pt*Half_gap*(Ceiling_e-E_zero) -> 70
A43: Against the cost of a round | H43: =Cost_round -> 120
A45: The value of a plan that misses the end condition is shown as if the board waived it (Table 5.3, note a).

Sheet Transcribe
A1: Transcribe and solve: all 64 schedules of rounds, each with its payout program (Theorem 5.1; Proposition 5.3(ii); AXIOM Lab 2.5, step 2)
A2: Each row is a schedule of rounds (z_k = 1: a round in year k). Its best payouts pay out, every year end, everything above the war chest R_k: R_6 = 470; R_(k-1) = max(R_k + 120 z_k - S_k, 470 if z_k = 1, 350), with no floor term for R_0.
A3: The schedule keeps every commitment exactly when today's cash covers R_0; then p_1 = q_0 - 120 z_1 + S_1 - R_1 and p_k = R_(k-1) - 120 z_k + S_k - R_k (Proposition 5.3(ii): pay as early as the commitments allow).
A4: Shortfall per round on this sheet (points) | F4: 0
AK6: Hurdle rate for the column: | AP6: 0.03 | AQ6: 0.05 | AR6: 0.08 | AS6: 0.1 | AT6: 0.12 | AU6: 0.15 | AV6: 0.2 | AW6: 0.3 | AX6: 0.018229167 | AY6: 0.036458333 | AZ6: 0.072916667 | BA6: 0.14549722 | BB6: 0.29871078
A7: # | B7: Rounds by year | C7: Rounds | D7: z1 | E7: z2 | F7: z3 | G7: z4 | H7: z5 | I7: z6 | J7: e1 | K7: e2 | L7: e3 | M7: e4 | N7: e5 | O7: e6 | P7: S1 | Q7: S2 | R7: S3 | S7: S4 | T7: S5 | U7: S6 | V7: R0 | W7: R1 | X7: R2 | Y7: R3 | Z7: R4 | AA7: R5 | AB7: R6 | AC7: Keeps every commitment | AD7: p1 | AE7: p2 | AF7: p3 | AG7: p4 | AH7: p5 | AI7: p6 | AJ7: Paid out | AK7: Payouts, PV | AL7: Value: savings forever | AM7: Value: no terminal value | AN7: Value: savings over the lines' life | AO7: Undiscounted, Part I's credit | AP7: Value at 3% | AQ7: Value at 5% | AR7: Value at 8% | AS7: Value at 10% | AT7: Value at 12% | AU7: Value at 15% | AV7: Value at 20% | AW7: Value at 30% | AX7: Value at switch rate 1 | AY7: Value at switch rate 2 | AZ7: Value at switch rate 3 | BA7: Value at switch rate 4 | BB7: Value at switch rate 5
A8: 0 | B8: =D8&E8&F8&G8&H8&I8 -> 000000 | C8: =SUM(D8:I8) -> 0 | D8: =MOD(INT($A8/32),2) -> 0 | E8: =MOD(INT($A8/16),2) -> 0 | F8: =MOD(INT($A8/8),2) -> 0 | G8: =MOD(INT($A8/4),2) -> 0 | H8: =MOD(INT($A8/2),2) -> 0 | I8: =MOD(INT($A8/1),2) -> 0 | J8: =E_zero+D8*(Half_gap*(Ceiling_e-E_zero)-$F$4) -> 71 | K8: =J8+E8*(Half_gap*(Ceiling_e-J8)-$F$4) -> 71 | L8: =K8+F8*(Half_gap*(Ceiling_e-K8)-$F$4) -> 71 | M8: =L8+G8*(Half_gap*(Ceiling_e-L8)-$F$4) -> 71 | N8: =M8+H8*(Half_gap*(Ceiling_e-M8)-$F$4) -> 71 | O8: =N8+I8*(Half_gap*(Ceiling_e-N8)-$F$4) -> 71 | P8: =Val_pt*(J8-E_zero) -> 0 | Q8: =Val_pt*(K8-E_zero) -> 0 | R8: =Val_pt*(L8-E_zero) -> 0 | S8: =Val_pt*(M8-E_zero) -> 0 | T8: =Val_pt*(N8-E_zero) -> 0 | U8: =Val_pt*(O8-E_zero) -> 0 | V8: =MAX(W8+Cost_round*D8-P8,IF(D8=1,Pre_q,0)) -> 470 | W8: =MAX(X8+Cost_round*E8-Q8,IF(E8=1,Pre_q,0),Floor_q) -> 470 | X8: =MAX(Y8+Cost_round*F8-R8,IF(F8=1,Pre_q,0),Floor_q) -> 470 | Y8: =MAX(Z8+Cost_round*G8-S8,IF(G8=1,Pre_q,0),Floor_q) -> 470 | Z8: =MAX(AA8+Cost_round*H8-T8,IF(H8=1,Pre_q,0),Floor_q) -> 470 | AA8: =MAX(AB8+Cost_round*I8-U8,IF(I8=1,Pre_q,0),Floor_q) -> 470 | AB8: =MAX(End_q,Floor_q) -> 470 | AC8: =IF(Q_zero>=V8-0.000000001,1,0) -> 1 | AD8: =IF($AC8=1,Q_zero-Cost_round*D8+P8-W8,"") -> 150 | AE8: =IF($AC8=1,W8-Cost_round*E8+Q8-X8,"") -> 0 | AF8: =IF($AC8=1,X8-Cost_round*F8+R8-Y8,"") -> 0 | AG8: =IF($AC8=1,Y8-Cost_round*G8+S8-Z8,"") -> 0 | AH8: =IF($AC8=1,Z8-Cost_round*H8+T8-AA8,"") -> 0 | AI8: =IF($AC8=1,AA8-Cost_round*I8+U8-AB8,"") -> 0 | AJ8: =IF($AC8=1,SUM(AD8:AI8),"") -> 150 | AK8: =IF($AC8=1,AD8*Beta_y^1+AE8*Beta_y^2+AF8*Beta_y^3+AG8*Beta_y^4+AH8*Beta_y^5+AI8*Beta_y^6,"") -> 136.36364 | AL8: =IF($AC8=1,AK8+Beta_y^6*U8/Hurdle_r,"") -> 136.36364 | AM8: =IF($AC8=1,AK8,"") -> 136.36364 | AN8: =IF($AC8=1,AK8+Beta_y^6*U8*(1-(1+Hurdle_r)^(-Life_yrs))/Hurdle_r,"") -> 136.36364 | AO8: =IF($AC8=1,AJ8+Credit_yrs*U8,"") -> 150 | AP8: =IF($AC8=1,$AD8/(1+AP$6)^1+$AE8/(1+AP$6)^2+$AF8/(1+AP$6)^3+$AG8/(1+AP$6)^4+$AH8/(1+AP$6)^5+$AI8/(1+AP$6)^6+$U8/AP$6/(1+AP$6)^6,"") -> 145.63107 | AQ8: =IF($AC8=1,$AD8/(1+AQ$6)^1+$AE8/(1+AQ$6)^2+$AF8/(1+AQ$6)^3+$AG8/(1+AQ$6)^4+$AH8/(1+AQ$6)^5+$AI8/(1+AQ$6)^6+$U8/AQ$6/(1+AQ$6)^6,"") -> 142.85714 | AR8: =IF($AC8=1,$AD8/(1+AR$6)^1+$AE8/(1+AR$6)^2+$AF8/(1+AR$6)^3+$AG8/(1+AR$6)^4+$AH8/(1+AR$6)^5+$AI8/(1+AR$6)^6+$U8/AR$6/(1+AR$6)^6,"") -> 138.88889 | AS8: =IF($AC8=1,$AD8/(1+AS$6)^1+$AE8/(1+AS$6)^2+$AF8/(1+AS$6)^3+$AG8/(1+AS$6)^4+$AH8/(1+AS$6)^5+$AI8/(1+AS$6)^6+$U8/AS$6/(1+AS$6)^6,"") -> 136.36364 | AT8: =IF($AC8=1,$AD8/(1+AT$6)^1+$AE8/(1+AT$6)^2+$AF8/(1+AT$6)^3+$AG8/(1+AT$6)^4+$AH8/(1+AT$6)^5+$AI8/(1+AT$6)^6+$U8/AT$6/(1+AT$6)^6,"") -> 133.92857 | AU8: =IF($AC8=1,$AD8/(1+AU$6)^1+$AE8/(1+AU$6)^2+$AF8/(1+AU$6)^3+$AG8/(1+AU$6)^4+$AH8/(1+AU$6)^5+$AI8/(1+AU$6)^6+$U8/AU$6/(1+AU$6)^6,"") -> 130.43478 | AV8: =IF($AC8=1,$AD8/(1+AV$6)^1+$AE8/(1+AV$6)^2+$AF8/(1+AV$6)^3+$AG8/(1+AV$6)^4+$AH8/(1+AV$6)^5+$AI8/(1+AV$6)^6+$U8/AV$6/(1+AV$6)^6,"") -> 125 | AW8: =IF($AC8=1,$AD8/(1+AW$6)^1+$AE8/(1+AW$6)^2+$AF8/(1+AW$6)^3+$AG8/(1+AW$6)^4+$AH8/(1+AW$6)^5+$AI8/(1+AW$6)^6+$U8/AW$6/(1+AW$6)^6,"") -> 115.38462 | ... BB8: =IF($AC8=1,$AD8/(1+BB$6)^1+$AE8/(1+BB$6)^2+$AF8/(1+BB$6)^3+$AG8/(1+BB$6)^4+$AH8/(1+BB$6)^5+$AI8/(1+BB$6)^6+$U8/BB$6/(1+BB$6)^6,"") -> 115.49916
A9: 1 | B9: =D9&E9&F9&G9&H9&I9 -> 000001 | C9: =SUM(D9:I9) -> 1 | D9: =MOD(INT($A9/32),2) -> 0 | E9: =MOD(INT($A9/16),2) -> 0 | F9: =MOD(INT($A9/8),2) -> 0 | G9: =MOD(INT($A9/4),2) -> 0 | H9: =MOD(INT($A9/2),2) -> 0 | I9: =MOD(INT($A9/1),2) -> 1 | J9: =E_zero+D9*(Half_gap*(Ceiling_e-E_zero)-$F$4) -> 71 | K9: =J9+E9*(Half_gap*(Ceiling_e-J9)-$F$4) -> 71 | L9: =K9+F9*(Half_gap*(Ceiling_e-K9)-$F$4) -> 71 | M9: =L9+G9*(Half_gap*(Ceiling_e-L9)-$F$4) -> 71 | N9: =M9+H9*(Half_gap*(Ceiling_e-M9)-$F$4) -> 71 | O9: =N9+I9*(Half_gap*(Ceiling_e-N9)-$F$4) -> 78 | P9: =Val_pt*(J9-E_zero) -> 0 | Q9: =Val_pt*(K9-E_zero) -> 0 | R9: =Val_pt*(L9-E_zero) -> 0 | S9: =Val_pt*(M9-E_zero) -> 0 | T9: =Val_pt*(N9-E_zero) -> 0 | U9: =Val_pt*(O9-E_zero) -> 70 | V9: =MAX(W9+Cost_round*D9-P9,IF(D9=1,Pre_q,0)) -> 520 | W9: =MAX(X9+Cost_round*E9-Q9,IF(E9=1,Pre_q,0),Floor_q) -> 520 | X9: =MAX(Y9+Cost_round*F9-R9,IF(F9=1,Pre_q,0),Floor_q) -> 520 | Y9: =MAX(Z9+Cost_round*G9-S9,IF(G9=1,Pre_q,0),Floor_q) -> 520 | Z9: =MAX(AA9+Cost_round*H9-T9,IF(H9=1,Pre_q,0),Floor_q) -> 520 | AA9: =MAX(AB9+Cost_round*I9-U9,IF(I9=1,Pre_q,0),Floor_q) -> 520 | AB9: =MAX(End_q,Floor_q) -> 470 | AC9: =IF(Q_zero>=V9-0.000000001,1,0) -> 1 | AD9: =IF($AC9=1,Q_zero-Cost_round*D9+P9-W9,"") -> 100 | AE9: =IF($AC9=1,W9-Cost_round*E9+Q9-X9,"") -> 0 | AF9: =IF($AC9=1,X9-Cost_round*F9+R9-Y9,"") -> 0 | AG9: =IF($AC9=1,Y9-Cost_round*G9+S9-Z9,"") -> 0 | AH9: =IF($AC9=1,Z9-Cost_round*H9+T9-AA9,"") -> 0 | AI9: =IF($AC9=1,AA9-Cost_round*I9+U9-AB9,"") -> 0 | AJ9: =IF($AC9=1,SUM(AD9:AI9),"") -> 100 | AK9: =IF($AC9=1,AD9*Beta_y^1+AE9*Beta_y^2+AF9*Beta_y^3+AG9*Beta_y^4+AH9*Beta_y^5+AI9*Beta_y^6,"") -> 90.909091 | AL9: =IF($AC9=1,AK9+Beta_y^6*U9/Hurdle_r,"") -> 486.04084 | AM9: =IF($AC9=1,AK9,"") -> 90.909091 | AN9: =IF($AC9=1,AK9+Beta_y^6*U9*(1-(1+Hurdle_r)^(-Life_yrs))/Hurdle_r,"") -> 427.30702 | AO9: =IF($AC9=1,AJ9+Credit_yrs*U9,"") -> 800 | AP9: =IF($AC9=1,$AD9/(1+AP$6)^1+$AE9/(1+AP$6)^2+$AF9/(1+AP$6)^3+$AG9/(1+AP$6)^4+$AH9/(1+AP$6)^5+$AI9/(1+AP$6)^6+$U9/AP$6/(1+AP$6)^6,"") -> 2051.2173 | AQ9: =IF($AC9=1,$AD9/(1+AQ$6)^1+$AE9/(1+AQ$6)^2+$AF9/(1+AQ$6)^3+$AG9/(1+AQ$6)^4+$AH9/(1+AQ$6)^5+$AI9/(1+AQ$6)^6+$U9/AQ$6/(1+AQ$6)^6,"") -> 1139.9397 | AR9: =IF($AC9=1,$AD9/(1+AR$6)^1+$AE9/(1+AR$6)^2+$AF9/(1+AR$6)^3+$AG9/(1+AR$6)^4+$AH9/(1+AR$6)^5+$AI9/(1+AR$6)^6+$U9/AR$6/(1+AR$6)^6,"") -> 643.99102 | AS9: =IF($AC9=1,$AD9/(1+AS$6)^1+$AE9/(1+AS$6)^2+$AF9/(1+AS$6)^3+$AG9/(1+AS$6)^4+$AH9/(1+AS$6)^5+$AI9/(1+AS$6)^6+$U9/AS$6/(1+AS$6)^6,"") -> 486.04084 | AT9: =IF($AC9=1,$AD9/(1+AT$6)^1+$AE9/(1+AT$6)^2+$AF9/(1+AT$6)^3+$AG9/(1+AT$6)^4+$AH9/(1+AT$6)^5+$AI9/(1+AT$6)^6+$U9/AT$6/(1+AT$6)^6,"") -> 384.82053 | AU9: =IF($AC9=1,$AD9/(1+AU$6)^1+$AE9/(1+AU$6)^2+$AF9/(1+AU$6)^3+$AG9/(1+AU$6)^4+$AH9/(1+AU$6)^5+$AI9/(1+AU$6)^6+$U9/AU$6/(1+AU$6)^6,"") -> 288.7094 | AV9: =IF($AC9=1,$AD9/(1+AV$6)^1+$AE9/(1+AV$6)^2+$AF9/(1+AV$6)^3+$AG9/(1+AV$6)^4+$AH9/(1+AV$6)^5+$AI9/(1+AV$6)^6+$U9/AV$6/(1+AV$6)^6,"") -> 200.54763 | AW9: =IF($AC9=1,$AD9/(1+AW$6)^1+$AE9/(1+AW$6)^2+$AF9/(1+AW$6)^3+$AG9/(1+AW$6)^4+$AH9/(1+AW$6)^5+$AI9/(1+AW$6)^6+$U9/AW$6/(1+AW$6)^6,"") -> 125.26419 | ... BB9: =IF($AC9=1,$AD9/(1+BB$6)^1+$AE9/(1+BB$6)^2+$AF9/(1+BB$6)^3+$AG9/(1+BB$6)^4+$AH9/(1+BB$6)^5+$AI9/(1+BB$6)^6+$U9/BB$6/(1+BB$6)^6,"") -> 125.83908
A10: 2 | B10: =D10&E10&F10&G10&H10&I10 -> 000010 | C10: =SUM(D10:I10) -> 1 | D10: =MOD(INT($A10/32),2) -> 0 | E10: =MOD(INT($A10/16),2) -> 0 | F10: =MOD(INT($A10/8),2) -> 0 | G10: =MOD(INT($A10/4),2) -> 0 | H10: =MOD(INT($A10/2),2) -> 1 | I10: =MOD(INT($A10/1),2) -> 0 | J10: =E_zero+D10*(Half_gap*(Ceiling_e-E_zero)-$F$4) -> 71 | K10: =J10+E10*(Half_gap*(Ceiling_e-J10)-$F$4) -> 71 | L10: =K10+F10*(Half_gap*(Ceiling_e-K10)-$F$4) -> 71 | M10: =L10+G10*(Half_gap*(Ceiling_e-L10)-$F$4) -> 71 | N10: =M10+H10*(Half_gap*(Ceiling_e-M10)-$F$4) -> 78 | O10: =N10+I10*(Half_gap*(Ceiling_e-N10)-$F$4) -> 78 | P10: =Val_pt*(J10-E_zero) -> 0 | Q10: =Val_pt*(K10-E_zero) -> 0 | R10: =Val_pt*(L10-E_zero) -> 0 | S10: =Val_pt*(M10-E_zero) -> 0 | T10: =Val_pt*(N10-E_zero) -> 70 | U10: =Val_pt*(O10-E_zero) -> 70 | V10: =MAX(W10+Cost_round*D10-P10,IF(D10=1,Pre_q,0)) -> 470 | W10: =MAX(X10+Cost_round*E10-Q10,IF(E10=1,Pre_q,0),Floor_q) -> 470 | X10: =MAX(Y10+Cost_round*F10-R10,IF(F10=1,Pre_q,0),Floor_q) -> 470 | Y10: =MAX(Z10+Cost_round*G10-S10,IF(G10=1,Pre_q,0),Floor_q) -> 470 | Z10: =MAX(AA10+Cost_round*H10-T10,IF(H10=1,Pre_q,0),Floor_q) -> 470 | AA10: =MAX(AB10+Cost_round*I10-U10,IF(I10=1,Pre_q,0),Floor_q) -> 400 | AB10: =MAX(End_q,Floor_q) -> 470 | AC10: =IF(Q_zero>=V10-0.000000001,1,0) -> 1 | AD10: =IF($AC10=1,Q_zero-Cost_round*D10+P10-W10,"") -> 150 | AE10: =IF($AC10=1,W10-Cost_round*E10+Q10-X10,"") -> 0 | AF10: =IF($AC10=1,X10-Cost_round*F10+R10-Y10,"") -> 0 | AG10: =IF($AC10=1,Y10-Cost_round*G10+S10-Z10,"") -> 0 | AH10: =IF($AC10=1,Z10-Cost_round*H10+T10-AA10,"") -> 20 | AI10: =IF($AC10=1,AA10-Cost_round*I10+U10-AB10,"") -> 0 | AJ10: =IF($AC10=1,SUM(AD10:AI10),"") -> 170 | AK10: =IF($AC10=1,AD10*Beta_y^1+AE10*Beta_y^2+AF10*Beta_y^3+AG10*Beta_y^4+AH10*Beta_y^5+AI10*Beta_y^6,"") -> 148.78206 | AL10: =IF($AC10=1,AK10+Beta_y^6*U10/Hurdle_r,"") -> 543.91381 | AM10: =IF($AC10=1,AK10,"") -> 148.78206 | AN10: =IF($AC10=1,AK10+Beta_y^6*U10*(1-(1+Hurdle_r)^(-Life_yrs))/Hurdle_r,"") -> 485.18 | AO10: =IF($AC10=1,AJ10+Credit_yrs*U10,"") -> 870 | AP10: =IF($AC10=1,$AD10/(1+AP$6)^1+$AE10/(1+AP$6)^2+$AF10/(1+AP$6)^3+$AG10/(1+AP$6)^4+$AH10/(1+AP$6)^5+$AI10/(1+AP$6)^6+$U10/AP$6/(1+AP$6)^6,"") -> 2117.0132 | AQ10: =IF($AC10=1,$AD10/(1+AQ$6)^1+$AE10/(1+AQ$6)^2+$AF10/(1+AQ$6)^3+$AG10/(1+AQ$6)^4+$AH10/(1+AQ$6)^5+$AI10/(1+AQ$6)^6+$U10/AQ$6/(1+AQ$6)^6,"") -> 1203.2292 | AR10: =IF($AC10=1,$AD10/(1+AR$6)^1+$AE10/(1+AR$6)^2+$AF10/(1+AR$6)^3+$AG10/(1+AR$6)^4+$AH10/(1+AR$6)^5+$AI10/(1+AR$6)^6+$U10/AR$6/(1+AR$6)^6,"") -> 703.89898 | AS10: =IF($AC10=1,$AD10/(1+AS$6)^1+$AE10/(1+AS$6)^2+$AF10/(1+AS$6)^3+$AG10/(1+AS$6)^4+$AH10/(1+AS$6)^5+$AI10/(1+AS$6)^6+$U10/AS$6/(1+AS$6)^6,"") -> 543.91381 | AT10: =IF($AC10=1,$AD10/(1+AT$6)^1+$AE10/(1+AT$6)^2+$AF10/(1+AT$6)^3+$AG10/(1+AT$6)^4+$AH10/(1+AT$6)^5+$AI10/(1+AT$6)^6+$U10/AT$6/(1+AT$6)^6,"") -> 440.81193 | AU10: =IF($AC10=1,$AD10/(1+AU$6)^1+$AE10/(1+AU$6)^2+$AF10/(1+AU$6)^3+$AG10/(1+AU$6)^4+$AH10/(1+AU$6)^5+$AI10/(1+AU$6)^6+$U10/AU$6/(1+AU$6)^6,"") -> 342.1312 | AV10: =IF($AC10=1,$AD10/(1+AV$6)^1+$AE10/(1+AV$6)^2+$AF10/(1+AV$6)^3+$AG10/(1+AV$6)^4+$AH10/(1+AV$6)^5+$AI10/(1+AV$6)^6+$U10/AV$6/(1+AV$6)^6,"") -> 250.25184 | AW10: =IF($AC10=1,$AD10/(1+AW$6)^1+$AE10/(1+AW$6)^2+$AF10/(1+AW$6)^3+$AG10/(1+AW$6)^4+$AH10/(1+AW$6)^5+$AI10/(1+AW$6)^6+$U10/AW$6/(1+AW$6)^6,"") -> 169.11231 | ... BB10: =IF($AC10=1,$AD10/(1+BB$6)^1+$AE10/(1+BB$6)^2+$AF10/(1+BB$6)^3+$AG10/(1+BB$6)^4+$AH10/(1+BB$6)^5+$AI10/(1+BB$6)^6+$U10/BB$6/(1+BB$6)^6,"") -> 169.75217
A11: 3 | B11: =D11&E11&F11&G11&H11&I11 -> 000011 | C11: =SUM(D11:I11) -> 2 | D11: =MOD(INT($A11/32),2) -> 0 | E11: =MOD(INT($A11/16),2) -> 0 | F11: =MOD(INT($A11/8),2) -> 0 | G11: =MOD(INT($A11/4),2) -> 0 | H11: =MOD(INT($A11/2),2) -> 1 | I11: =MOD(INT($A11/1),2) -> 1 | J11: =E_zero+D11*(Half_gap*(Ceiling_e-E_zero)-$F$4) -> 71 | K11: =J11+E11*(Half_gap*(Ceiling_e-J11)-$F$4) -> 71 | L11: =K11+F11*(Half_gap*(Ceiling_e-K11)-$F$4) -> 71 | M11: =L11+G11*(Half_gap*(Ceiling_e-L11)-$F$4) -> 71 | N11: =M11+H11*(Half_gap*(Ceiling_e-M11)-$F$4) -> 78 | O11: =N11+I11*(Half_gap*(Ceiling_e-N11)-$F$4) -> 81.5 | P11: =Val_pt*(J11-E_zero) -> 0 | Q11: =Val_pt*(K11-E_zero) -> 0 | R11: =Val_pt*(L11-E_zero) -> 0 | S11: =Val_pt*(M11-E_zero) -> 0 | T11: =Val_pt*(N11-E_zero) -> 70 | U11: =Val_pt*(O11-E_zero) -> 105 | V11: =MAX(W11+Cost_round*D11-P11,IF(D11=1,Pre_q,0)) -> 535 | W11: =MAX(X11+Cost_round*E11-Q11,IF(E11=1,Pre_q,0),Floor_q) -> 535 | X11: =MAX(Y11+Cost_round*F11-R11,IF(F11=1,Pre_q,0),Floor_q) -> 535 | Y11: =MAX(Z11+Cost_round*G11-S11,IF(G11=1,Pre_q,0),Floor_q) -> 535 | Z11: =MAX(AA11+Cost_round*H11-T11,IF(H11=1,Pre_q,0),Floor_q) -> 535 | AA11: =MAX(AB11+Cost_round*I11-U11,IF(I11=1,Pre_q,0),Floor_q) -> 485 | AB11: =MAX(End_q,Floor_q) -> 470 | AC11: =IF(Q_zero>=V11-0.000000001,1,0) -> 1 | AD11: =IF($AC11=1,Q_zero-Cost_round*D11+P11-W11,"") -> 85 | AE11: =IF($AC11=1,W11-Cost_round*E11+Q11-X11,"") -> 0 | AF11: =IF($AC11=1,X11-Cost_round*F11+R11-Y11,"") -> 0 | AG11: =IF($AC11=1,Y11-Cost_round*G11+S11-Z11,"") -> 0 | AH11: =IF($AC11=1,Z11-Cost_round*H11+T11-AA11,"") -> 0 | AI11: =IF($AC11=1,AA11-Cost_round*I11+U11-AB11,"") -> 0 | AJ11: =IF($AC11=1,SUM(AD11:AI11),"") -> 85 | AK11: =IF($AC11=1,AD11*Beta_y^1+AE11*Beta_y^2+AF11*Beta_y^3+AG11*Beta_y^4+AH11*Beta_y^5+AI11*Beta_y^6,"") -> 77.272727 | AL11: =IF($AC11=1,AK11+Beta_y^6*U11/Hurdle_r,"") -> 669.97035 | AM11: =IF($AC11=1,AK11,"") -> 77.272727 | AN11: =IF($AC11=1,AK11+Beta_y^6*U11*(1-(1+Hurdle_r)^(-Life_yrs))/Hurdle_r,"") -> 581.86963 | AO11: =IF($AC11=1,AJ11+Credit_yrs*U11,"") -> 1135 | AP11: =IF($AC11=1,$AD11/(1+AP$6)^1+$AE11/(1+AP$6)^2+$AF11/(1+AP$6)^3+$AG11/(1+AP$6)^4+$AH11/(1+AP$6)^5+$AI11/(1+AP$6)^6+$U11/AP$6/(1+AP$6)^6,"") -> 3013.7192 | AQ11: =IF($AC11=1,$AD11/(1+AQ$6)^1+$AE11/(1+AQ$6)^2+$AF11/(1+AQ$6)^3+$AG11/(1+AQ$6)^4+$AH11/(1+AQ$6)^5+$AI11/(1+AQ$6)^6+$U11/AQ$6/(1+AQ$6)^6,"") -> 1648.0047 | AR11: =IF($AC11=1,$AD11/(1+AR$6)^1+$AE11/(1+AR$6)^2+$AF11/(1+AR$6)^3+$AG11/(1+AR$6)^4+$AH11/(1+AR$6)^5+$AI11/(1+AR$6)^6+$U11/AR$6/(1+AR$6)^6,"") -> 905.80134 | AS11: =IF($AC11=1,$AD11/(1+AS$6)^1+$AE11/(1+AS$6)^2+$AF11/(1+AS$6)^3+$AG11/(1+AS$6)^4+$AH11/(1+AS$6)^5+$AI11/(1+AS$6)^6+$U11/AS$6/(1+AS$6)^6,"") -> 669.97035 | AT11: =IF($AC11=1,$AD11/(1+AT$6)^1+$AE11/(1+AT$6)^2+$AF11/(1+AT$6)^3+$AG11/(1+AT$6)^4+$AH11/(1+AT$6)^5+$AI11/(1+AT$6)^6+$U11/AT$6/(1+AT$6)^6,"") -> 519.19509 | AU11: =IF($AC11=1,$AD11/(1+AU$6)^1+$AE11/(1+AU$6)^2+$AF11/(1+AU$6)^3+$AG11/(1+AU$6)^4+$AH11/(1+AU$6)^5+$AI11/(1+AU$6)^6+$U11/AU$6/(1+AU$6)^6,"") -> 376.54236 | AV11: =IF($AC11=1,$AD11/(1+AV$6)^1+$AE11/(1+AV$6)^2+$AF11/(1+AV$6)^3+$AG11/(1+AV$6)^4+$AH11/(1+AV$6)^5+$AI11/(1+AV$6)^6+$U11/AV$6/(1+AV$6)^6,"") -> 246.65477 | AW11: =IF($AC11=1,$AD11/(1+AW$6)^1+$AE11/(1+AW$6)^2+$AF11/(1+AW$6)^3+$AG11/(1+AW$6)^4+$AH11/(1+AW$6)^5+$AI11/(1+AW$6)^6+$U11/AW$6/(1+AW$6)^6,"") -> 137.89629 | ... BB11: =IF($AC11=1,$AD11/(1+BB$6)^1+$AE11/(1+BB$6)^2+$AF11/(1+BB$6)^3+$AG11/(1+BB$6)^4+$AH11/(1+BB$6)^5+$AI11/(1+BB$6)^6+$U11/BB$6/(1+BB$6)^6,"") -> 138.70898
A12: 4 | B12: =D12&E12&F12&G12&H12&I12 -> 000100 | C12: =SUM(D12:I12) -> 1 | D12: =MOD(INT($A12/32),2) -> 0 | E12: =MOD(INT($A12/16),2) -> 0 | F12: =MOD(INT($A12/8),2) -> 0 | G12: =MOD(INT($A12/4),2) -> 1 | H12: =MOD(INT($A12/2),2) -> 0 | I12: =MOD(INT($A12/1),2) -> 0 | J12: =E_zero+D12*(Half_gap*(Ceiling_e-E_zero)-$F$4) -> 71 | K12: =J12+E12*(Half_gap*(Ceiling_e-J12)-$F$4) -> 71 | L12: =K12+F12*(Half_gap*(Ceiling_e-K12)-$F$4) -> 71 | M12: =L12+G12*(Half_gap*(Ceiling_e-L12)-$F$4) -> 78 | N12: =M12+H12*(Half_gap*(Ceiling_e-M12)-$F$4) -> 78 | O12: =N12+I12*(Half_gap*(Ceiling_e-N12)-$F$4) -> 78 | P12: =Val_pt*(J12-E_zero) -> 0 | Q12: =Val_pt*(K12-E_zero) -> 0 | R12: =Val_pt*(L12-E_zero) -> 0 | S12: =Val_pt*(M12-E_zero) -> 70 | T12: =Val_pt*(N12-E_zero) -> 70 | U12: =Val_pt*(O12-E_zero) -> 70 | V12: =MAX(W12+Cost_round*D12-P12,IF(D12=1,Pre_q,0)) -> 470 | W12: =MAX(X12+Cost_round*E12-Q12,IF(E12=1,Pre_q,0),Floor_q) -> 470 | X12: =MAX(Y12+Cost_round*F12-R12,IF(F12=1,Pre_q,0),Floor_q) -> 470 | Y12: =MAX(Z12+Cost_round*G12-S12,IF(G12=1,Pre_q,0),Floor_q) -> 470 | Z12: =MAX(AA12+Cost_round*H12-T12,IF(H12=1,Pre_q,0),Floor_q) -> 350 | AA12: =MAX(AB12+Cost_round*I12-U12,IF(I12=1,Pre_q,0),Floor_q) -> 400 | AB12: =MAX(End_q,Floor_q) -> 470 | AC12: =IF(Q_zero>=V12-0.000000001,1,0) -> 1 | AD12: =IF($AC12=1,Q_zero-Cost_round*D12+P12-W12,"") -> 150 | AE12: =IF($AC12=1,W12-Cost_round*E12+Q12-X12,"") -> 0 | AF12: =IF($AC12=1,X12-Cost_round*F12+R12-Y12,"") -> 0 | AG12: =IF($AC12=1,Y12-Cost_round*G12+S12-Z12,"") -> 70 | AH12: =IF($AC12=1,Z12-Cost_round*H12+T12-AA12,"") -> 20 | AI12: =IF($AC12=1,AA12-Cost_round*I12+U12-AB12,"") -> 0 | AJ12: =IF($AC12=1,SUM(AD12:AI12),"") -> 240 | AK12: =IF($AC12=1,AD12*Beta_y^1+AE12*Beta_y^2+AF12*Beta_y^3+AG12*Beta_y^4+AH12*Beta_y^5+AI12*Beta_y^6,"") -> 196.593 | AL12: =IF($AC12=1,AK12+Beta_y^6*U12/Hurdle_r,"") -> 591.72476 | AM12: =IF($AC12=1,AK12,"") -> 196.593 | AN12: =IF($AC12=1,AK12+Beta_y^6*U12*(1-(1+Hurdle_r)^(-Life_yrs))/Hurdle_r,"") -> 532.99094 | AO12: =IF($AC12=1,AJ12+Credit_yrs*U12,"") -> 940 | AP12: =IF($AC12=1,$AD12/(1+AP$6)^1+$AE12/(1+AP$6)^2+$AF12/(1+AP$6)^3+$AG12/(1+AP$6)^4+$AH12/(1+AP$6)^5+$AI12/(1+AP$6)^6+$U12/AP$6/(1+AP$6)^6,"") -> 2179.2073 | AQ12: =IF($AC12=1,$AD12/(1+AQ$6)^1+$AE12/(1+AQ$6)^2+$AF12/(1+AQ$6)^3+$AG12/(1+AQ$6)^4+$AH12/(1+AQ$6)^5+$AI12/(1+AQ$6)^6+$U12/AQ$6/(1+AQ$6)^6,"") -> 1260.8184 | AR12: =IF($AC12=1,$AD12/(1+AR$6)^1+$AE12/(1+AR$6)^2+$AF12/(1+AR$6)^3+$AG12/(1+AR$6)^4+$AH12/(1+AR$6)^5+$AI12/(1+AR$6)^6+$U12/AR$6/(1+AR$6)^6,"") -> 755.35107 | AS12: =IF($AC12=1,$AD12/(1+AS$6)^1+$AE12/(1+AS$6)^2+$AF12/(1+AS$6)^3+$AG12/(1+AS$6)^4+$AH12/(1+AS$6)^5+$AI12/(1+AS$6)^6+$U12/AS$6/(1+AS$6)^6,"") -> 591.72476 | AT12: =IF($AC12=1,$AD12/(1+AT$6)^1+$AE12/(1+AT$6)^2+$AF12/(1+AT$6)^3+$AG12/(1+AT$6)^4+$AH12/(1+AT$6)^5+$AI12/(1+AT$6)^6+$U12/AT$6/(1+AT$6)^6,"") -> 485.29819 | AU12: =IF($AC12=1,$AD12/(1+AU$6)^1+$AE12/(1+AU$6)^2+$AF12/(1+AU$6)^3+$AG12/(1+AU$6)^4+$AH12/(1+AU$6)^5+$AI12/(1+AU$6)^6+$U12/AU$6/(1+AU$6)^6,"") -> 382.15392 | AV12: =IF($AC12=1,$AD12/(1+AV$6)^1+$AE12/(1+AV$6)^2+$AF12/(1+AV$6)^3+$AG12/(1+AV$6)^4+$AH12/(1+AV$6)^5+$AI12/(1+AV$6)^6+$U12/AV$6/(1+AV$6)^6,"") -> 284.00956 | AW12: =IF($AC12=1,$AD12/(1+AW$6)^1+$AE12/(1+AW$6)^2+$AF12/(1+AW$6)^3+$AG12/(1+AW$6)^4+$AH12/(1+AW$6)^5+$AI12/(1+AW$6)^6+$U12/AW$6/(1+AW$6)^6,"") -> 193.62126 | ... BB12: =IF($AC12=1,$AD12/(1+BB$6)^1+$AE12/(1+BB$6)^2+$AF12/(1+BB$6)^3+$AG12/(1+BB$6)^4+$AH12/(1+BB$6)^5+$AI12/(1+BB$6)^6+$U12/BB$6/(1+BB$6)^6,"") -> 194.35858
A13: 5 | B13: =D13&E13&F13&G13&H13&I13 -> 000101 | C13: =SUM(D13:I13) -> 2 | D13: =MOD(INT($A13/32),2) -> 0 | E13: =MOD(INT($A13/16),2) -> 0 | F13: =MOD(INT($A13/8),2) -> 0 | G13: =MOD(INT($A13/4),2) -> 1 | H13: =MOD(INT($A13/2),2) -> 0 | I13: =MOD(INT($A13/1),2) -> 1 | J13: =E_zero+D13*(Half_gap*(Ceiling_e-E_zero)-$F$4) -> 71 | K13: =J13+E13*(Half_gap*(Ceiling_e-J13)-$F$4) -> 71 | L13: =K13+F13*(Half_gap*(Ceiling_e-K13)-$F$4) -> 71 | M13: =L13+G13*(Half_gap*(Ceiling_e-L13)-$F$4) -> 78 | N13: =M13+H13*(Half_gap*(Ceiling_e-M13)-$F$4) -> 78 | O13: =N13+I13*(Half_gap*(Ceiling_e-N13)-$F$4) -> 81.5 | P13: =Val_pt*(J13-E_zero) -> 0 | Q13: =Val_pt*(K13-E_zero) -> 0 | R13: =Val_pt*(L13-E_zero) -> 0 | S13: =Val_pt*(M13-E_zero) -> 70 | T13: =Val_pt*(N13-E_zero) -> 70 | U13: =Val_pt*(O13-E_zero) -> 105 | V13: =MAX(W13+Cost_round*D13-P13,IF(D13=1,Pre_q,0)) -> 470 | W13: =MAX(X13+Cost_round*E13-Q13,IF(E13=1,Pre_q,0),Floor_q) -> 470 | X13: =MAX(Y13+Cost_round*F13-R13,IF(F13=1,Pre_q,0),Floor_q) -> 470 | Y13: =MAX(Z13+Cost_round*G13-S13,IF(G13=1,Pre_q,0),Floor_q) -> 470 | Z13: =MAX(AA13+Cost_round*H13-T13,IF(H13=1,Pre_q,0),Floor_q) -> 415 | AA13: =MAX(AB13+Cost_round*I13-U13,IF(I13=1,Pre_q,0),Floor_q) -> 485 | AB13: =MAX(End_q,Floor_q) -> 470 | AC13: =IF(Q_zero>=V13-0.000000001,1,0) -> 1 | AD13: =IF($AC13=1,Q_zero-Cost_round*D13+P13-W13,"") -> 150 | AE13: =IF($AC13=1,W13-Cost_round*E13+Q13-X13,"") -> 0 | AF13: =IF($AC13=1,X13-Cost_round*F13+R13-Y13,"") -> 0 | AG13: =IF($AC13=1,Y13-Cost_round*G13+S13-Z13,"") -> 5 | AH13: =IF($AC13=1,Z13-Cost_round*H13+T13-AA13,"") -> 0 | AI13: =IF($AC13=1,AA13-Cost_round*I13+U13-AB13,"") -> 0 | AJ13: =IF($AC13=1,SUM(AD13:AI13),"") -> 155 | AK13: =IF($AC13=1,AD13*Beta_y^1+AE13*Beta_y^2+AF13*Beta_y^3+AG13*Beta_y^4+AH13*Beta_y^5+AI13*Beta_y^6,"") -> 139.7787 | AL13: =IF($AC13=1,AK13+Beta_y^6*U13/Hurdle_r,"") -> 732.47633 | AM13: =IF($AC13=1,AK13,"") -> 139.7787 | AN13: =IF($AC13=1,AK13+Beta_y^6*U13*(1-(1+Hurdle_r)^(-Life_yrs))/Hurdle_r,"") -> 644.3756 | AO13: =IF($AC13=1,AJ13+Credit_yrs*U13,"") -> 1205 | AP13: =IF($AC13=1,$AD13/(1+AP$6)^1+$AE13/(1+AP$6)^2+$AF13/(1+AP$6)^3+$AG13/(1+AP$6)^4+$AH13/(1+AP$6)^5+$AI13/(1+AP$6)^6+$U13/AP$6/(1+AP$6)^6,"") -> 3081.2684 | AQ13: =IF($AC13=1,$AD13/(1+AQ$6)^1+$AE13/(1+AQ$6)^2+$AF13/(1+AQ$6)^3+$AG13/(1+AQ$6)^4+$AH13/(1+AQ$6)^5+$AI13/(1+AQ$6)^6+$U13/AQ$6/(1+AQ$6)^6,"") -> 1714.023 | AR13: =IF($AC13=1,$AD13/(1+AR$6)^1+$AE13/(1+AR$6)^2+$AF13/(1+AR$6)^3+$AG13/(1+AR$6)^4+$AH13/(1+AR$6)^5+$AI13/(1+AR$6)^6+$U13/AR$6/(1+AR$6)^6,"") -> 969.66167 | AS13: =IF($AC13=1,$AD13/(1+AS$6)^1+$AE13/(1+AS$6)^2+$AF13/(1+AS$6)^3+$AG13/(1+AS$6)^4+$AH13/(1+AS$6)^5+$AI13/(1+AS$6)^6+$U13/AS$6/(1+AS$6)^6,"") -> 732.47633 | AT13: =IF($AC13=1,$AD13/(1+AT$6)^1+$AE13/(1+AT$6)^2+$AF13/(1+AT$6)^3+$AG13/(1+AT$6)^4+$AH13/(1+AT$6)^5+$AI13/(1+AT$6)^6+$U13/AT$6/(1+AT$6)^6,"") -> 580.40839 | AU13: =IF($AC13=1,$AD13/(1+AU$6)^1+$AE13/(1+AU$6)^2+$AF13/(1+AU$6)^3+$AG13/(1+AU$6)^4+$AH13/(1+AU$6)^5+$AI13/(1+AU$6)^6+$U13/AU$6/(1+AU$6)^6,"") -> 435.92287 | AV13: =IF($AC13=1,$AD13/(1+AV$6)^1+$AE13/(1+AV$6)^2+$AF13/(1+AV$6)^3+$AG13/(1+AV$6)^4+$AH13/(1+AV$6)^5+$AI13/(1+AV$6)^6+$U13/AV$6/(1+AV$6)^6,"") -> 303.2327 | AW13: =IF($AC13=1,$AD13/(1+AW$6)^1+$AE13/(1+AW$6)^2+$AF13/(1+AW$6)^3+$AG13/(1+AW$6)^4+$AH13/(1+AW$6)^5+$AI13/(1+AW$6)^6+$U13/AW$6/(1+AW$6)^6,"") -> 189.64693 | ... BB13: =IF($AC13=1,$AD13/(1+BB$6)^1+$AE13/(1+BB$6)^2+$AF13/(1+BB$6)^3+$AG13/(1+BB$6)^4+$AH13/(1+BB$6)^5+$AI13/(1+BB$6)^6+$U13/BB$6/(1+BB$6)^6,"") -> 190.51622
A14: 6 | B14: =D14&E14&F14&G14&H14&I14 -> 000110 | C14: =SUM(D14:I14) -> 2 | D14: =MOD(INT($A14/32),2) -> 0 | E14: =MOD(INT($A14/16),2) -> 0 | F14: =MOD(INT($A14/8),2) -> 0 | G14: =MOD(INT($A14/4),2) -> 1 | H14: =MOD(INT($A14/2),2) -> 1 | I14: =MOD(INT($A14/1),2) -> 0 | J14: =E_zero+D14*(Half_gap*(Ceiling_e-E_zero)-$F$4) -> 71 | K14: =J14+E14*(Half_gap*(Ceiling_e-J14)-$F$4) -> 71 | L14: =K14+F14*(Half_gap*(Ceiling_e-K14)-$F$4) -> 71 | M14: =L14+G14*(Half_gap*(Ceiling_e-L14)-$F$4) -> 78 | N14: =M14+H14*(Half_gap*(Ceiling_e-M14)-$F$4) -> 81.5 | O14: =N14+I14*(Half_gap*(Ceiling_e-N14)-$F$4) -> 81.5 | P14: =Val_pt*(J14-E_zero) -> 0 | Q14: =Val_pt*(K14-E_zero) -> 0 | R14: =Val_pt*(L14-E_zero) -> 0 | S14: =Val_pt*(M14-E_zero) -> 70 | T14: =Val_pt*(N14-E_zero) -> 105 | U14: =Val_pt*(O14-E_zero) -> 105 | V14: =MAX(W14+Cost_round*D14-P14,IF(D14=1,Pre_q,0)) -> 520 | W14: =MAX(X14+Cost_round*E14-Q14,IF(E14=1,Pre_q,0),Floor_q) -> 520 | X14: =MAX(Y14+Cost_round*F14-R14,IF(F14=1,Pre_q,0),Floor_q) -> 520 | Y14: =MAX(Z14+Cost_round*G14-S14,IF(G14=1,Pre_q,0),Floor_q) -> 520 | Z14: =MAX(AA14+Cost_round*H14-T14,IF(H14=1,Pre_q,0),Floor_q) -> 470 | AA14: =MAX(AB14+Cost_round*I14-U14,IF(I14=1,Pre_q,0),Floor_q) -> 365 | AB14: =MAX(End_q,Floor_q) -> 470 | AC14: =IF(Q_zero>=V14-0.000000001,1,0) -> 1 | AD14: =IF($AC14=1,Q_zero-Cost_round*D14+P14-W14,"") -> 100 | AE14: =IF($AC14=1,W14-Cost_round*E14+Q14-X14,"") -> 0 | AF14: =IF($AC14=1,X14-Cost_round*F14+R14-Y14,"") -> 0 | AG14: =IF($AC14=1,Y14-Cost_round*G14+S14-Z14,"") -> 0 | AH14: =IF($AC14=1,Z14-Cost_round*H14+T14-AA14,"") -> 90 | AI14: =IF($AC14=1,AA14-Cost_round*I14+U14-AB14,"") -> 0 | AJ14: =IF($AC14=1,SUM(AD14:AI14),"") -> 190 | AK14: =IF($AC14=1,AD14*Beta_y^1+AE14*Beta_y^2+AF14*Beta_y^3+AG14*Beta_y^4+AH14*Beta_y^5+AI14*Beta_y^6,"") -> 146.79201 | AL14: =IF($AC14=1,AK14+Beta_y^6*U14/Hurdle_r,"") -> 739.48964 | AM14: =IF($AC14=1,AK14,"") -> 146.79201 | AN14: =IF($AC14=1,AK14+Beta_y^6*U14*(1-(1+Hurdle_r)^(-Life_yrs))/Hurdle_r,"") -> 651.38891 | AO14: =IF($AC14=1,AJ14+Credit_yrs*U14,"") -> 1240 | AP14: =IF($AC14=1,$AD14/(1+AP$6)^1+$AE14/(1+AP$6)^2+$AF14/(1+AP$6)^3+$AG14/(1+AP$6)^4+$AH14/(1+AP$6)^5+$AI14/(1+AP$6)^6+$U14/AP$6/(1+AP$6)^6,"") -> 3105.9171 | AQ14: =IF($AC14=1,$AD14/(1+AQ$6)^1+$AE14/(1+AQ$6)^2+$AF14/(1+AQ$6)^3+$AG14/(1+AQ$6)^4+$AH14/(1+AQ$6)^5+$AI14/(1+AQ$6)^6+$U14/AQ$6/(1+AQ$6)^6,"") -> 1732.8078 | AR14: =IF($AC14=1,$AD14/(1+AR$6)^1+$AE14/(1+AR$6)^2+$AF14/(1+AR$6)^3+$AG14/(1+AR$6)^4+$AH14/(1+AR$6)^5+$AI14/(1+AR$6)^6+$U14/AR$6/(1+AR$6)^6,"") -> 980.94272 | AS14: =IF($AC14=1,$AD14/(1+AS$6)^1+$AE14/(1+AS$6)^2+$AF14/(1+AS$6)^3+$AG14/(1+AS$6)^4+$AH14/(1+AS$6)^5+$AI14/(1+AS$6)^6+$U14/AS$6/(1+AS$6)^6,"") -> 739.48964 | AT14: =IF($AC14=1,$AD14/(1+AT$6)^1+$AE14/(1+AT$6)^2+$AF14/(1+AT$6)^3+$AG14/(1+AT$6)^4+$AH14/(1+AT$6)^5+$AI14/(1+AT$6)^6+$U14/AT$6/(1+AT$6)^6,"") -> 583.65636 | AU14: =IF($AC14=1,$AD14/(1+AU$6)^1+$AE14/(1+AU$6)^2+$AF14/(1+AU$6)^3+$AG14/(1+AU$6)^4+$AH14/(1+AU$6)^5+$AI14/(1+AU$6)^6+$U14/AU$6/(1+AU$6)^6,"") -> 434.33175 | AV14: =IF($AC14=1,$AD14/(1+AV$6)^1+$AE14/(1+AV$6)^2+$AF14/(1+AV$6)^3+$AG14/(1+AV$6)^4+$AH14/(1+AV$6)^5+$AI14/(1+AV$6)^6+$U14/AV$6/(1+AV$6)^6,"") -> 295.32375 | AW14: =IF($AC14=1,$AD14/(1+AW$6)^1+$AE14/(1+AW$6)^2+$AF14/(1+AW$6)^3+$AG14/(1+AW$6)^4+$AH14/(1+AW$6)^5+$AI14/(1+AW$6)^6+$U14/AW$6/(1+AW$6)^6,"") -> 173.67437 | ... BB14: =IF($AC14=1,$AD14/(1+BB$6)^1+$AE14/(1+BB$6)^2+$AF14/(1+BB$6)^3+$AG14/(1+BB$6)^4+$AH14/(1+BB$6)^5+$AI14/(1+BB$6)^6+$U14/BB$6/(1+BB$6)^6,"") -> 174.61907
A15: 7 | B15: =D15&E15&F15&G15&H15&I15 -> 000111 | C15: =SUM(D15:I15) -> 3 | D15: =MOD(INT($A15/32),2) -> 0 | E15: =MOD(INT($A15/16),2) -> 0 | F15: =MOD(INT($A15/8),2) -> 0 | G15: =MOD(INT($A15/4),2) -> 1 | H15: =MOD(INT($A15/2),2) -> 1 | I15: =MOD(INT($A15/1),2) -> 1 | J15: =E_zero+D15*(Half_gap*(Ceiling_e-E_zero)-$F$4) -> 71 | K15: =J15+E15*(Half_gap*(Ceiling_e-J15)-$F$4) -> 71 | L15: =K15+F15*(Half_gap*(Ceiling_e-K15)-$F$4) -> 71 | M15: =L15+G15*(Half_gap*(Ceiling_e-L15)-$F$4) -> 78 | N15: =M15+H15*(Half_gap*(Ceiling_e-M15)-$F$4) -> 81.5 | O15: =N15+I15*(Half_gap*(Ceiling_e-N15)-$F$4) -> 83.25 | P15: =Val_pt*(J15-E_zero) -> 0 | Q15: =Val_pt*(K15-E_zero) -> 0 | R15: =Val_pt*(L15-E_zero) -> 0 | S15: =Val_pt*(M15-E_zero) -> 70 | T15: =Val_pt*(N15-E_zero) -> 105 | U15: =Val_pt*(O15-E_zero) -> 122.5 | V15: =MAX(W15+Cost_round*D15-P15,IF(D15=1,Pre_q,0)) -> 535 | W15: =MAX(X15+Cost_round*E15-Q15,IF(E15=1,Pre_q,0),Floor_q) -> 535 | X15: =MAX(Y15+Cost_round*F15-R15,IF(F15=1,Pre_q,0),Floor_q) -> 535 | Y15: =MAX(Z15+Cost_round*G15-S15,IF(G15=1,Pre_q,0),Floor_q) -> 535 | Z15: =MAX(AA15+Cost_round*H15-T15,IF(H15=1,Pre_q,0),Floor_q) -> 485 | AA15: =MAX(AB15+Cost_round*I15-U15,IF(I15=1,Pre_q,0),Floor_q) -> 470 | AB15: =MAX(End_q,Floor_q) -> 470 | AC15: =IF(Q_zero>=V15-0.000000001,1,0) -> 1 | AD15: =IF($AC15=1,Q_zero-Cost_round*D15+P15-W15,"") -> 85 | AE15: =IF($AC15=1,W15-Cost_round*E15+Q15-X15,"") -> 0 | AF15: =IF($AC15=1,X15-Cost_round*F15+R15-Y15,"") -> 0 | AG15: =IF($AC15=1,Y15-Cost_round*G15+S15-Z15,"") -> 0 | AH15: =IF($AC15=1,Z15-Cost_round*H15+T15-AA15,"") -> 0 | AI15: =IF($AC15=1,AA15-Cost_round*I15+U15-AB15,"") -> 2.5 | AJ15: =IF($AC15=1,SUM(AD15:AI15),"") -> 87.5 | AK15: =IF($AC15=1,AD15*Beta_y^1+AE15*Beta_y^2+AF15*Beta_y^3+AG15*Beta_y^4+AH15*Beta_y^5+AI15*Beta_y^6,"") -> 78.683912 | AL15: =IF($AC15=1,AK15+Beta_y^6*U15/Hurdle_r,"") -> 770.16448 | AM15: =IF($AC15=1,AK15,"") -> 78.683912 | AN15: =IF($AC15=1,AK15+Beta_y^6*U15*(1-(1+Hurdle_r)^(-Life_yrs))/Hurdle_r,"") -> 667.3803 | AO15: =IF($AC15=1,AJ15+Credit_yrs*U15,"") -> 1312.5 | AP15: =IF($AC15=1,$AD15/(1+AP$6)^1+$AE15/(1+AP$6)^2+$AF15/(1+AP$6)^3+$AG15/(1+AP$6)^4+$AH15/(1+AP$6)^5+$AI15/(1+AP$6)^6+$U15/AP$6/(1+AP$6)^6,"") -> 3504.3454 | AQ15: =IF($AC15=1,$AD15/(1+AQ$6)^1+$AE15/(1+AQ$6)^2+$AF15/(1+AQ$6)^3+$AG15/(1+AQ$6)^4+$AH15/(1+AQ$6)^5+$AI15/(1+AQ$6)^6+$U15/AQ$6/(1+AQ$6)^6,"") -> 1911.0456 | AR15: =IF($AC15=1,$AD15/(1+AR$6)^1+$AE15/(1+AR$6)^2+$AF15/(1+AR$6)^3+$AG15/(1+AR$6)^4+$AH15/(1+AR$6)^5+$AI15/(1+AR$6)^6+$U15/AR$6/(1+AR$6)^6,"") -> 1045.2264 | AS15: =IF($AC15=1,$AD15/(1+AS$6)^1+$AE15/(1+AS$6)^2+$AF15/(1+AS$6)^3+$AG15/(1+AS$6)^4+$AH15/(1+AS$6)^5+$AI15/(1+AS$6)^6+$U15/AS$6/(1+AS$6)^6,"") -> 770.16448 | AT15: =IF($AC15=1,$AD15/(1+AT$6)^1+$AE15/(1+AT$6)^2+$AF15/(1+AT$6)^3+$AG15/(1+AT$6)^4+$AH15/(1+AT$6)^5+$AI15/(1+AT$6)^6+$U15/AT$6/(1+AT$6)^6,"") -> 594.34537 | AU15: =IF($AC15=1,$AD15/(1+AU$6)^1+$AE15/(1+AU$6)^2+$AF15/(1+AU$6)^3+$AG15/(1+AU$6)^4+$AH15/(1+AU$6)^5+$AI15/(1+AU$6)^6+$U15/AU$6/(1+AU$6)^6,"") -> 428.0614 | AV15: =IF($AC15=1,$AD15/(1+AV$6)^1+$AE15/(1+AV$6)^2+$AF15/(1+AV$6)^3+$AG15/(1+AV$6)^4+$AH15/(1+AV$6)^5+$AI15/(1+AV$6)^6+$U15/AV$6/(1+AV$6)^6,"") -> 276.79559 | AW15: =IF($AC15=1,$AD15/(1+AW$6)^1+$AE15/(1+AW$6)^2+$AF15/(1+AW$6)^3+$AG15/(1+AW$6)^4+$AH15/(1+AW$6)^5+$AI15/(1+AW$6)^6+$U15/AW$6/(1+AW$6)^6,"") -> 150.49951 | ... BB15: =IF($AC15=1,$AD15/(1+BB$6)^1+$AE15/(1+BB$6)^2+$AF15/(1+BB$6)^3+$AG15/(1+BB$6)^4+$AH15/(1+BB$6)^5+$AI15/(1+BB$6)^6+$U15/BB$6/(1+BB$6)^6,"") -> 151.43993
A16: 8 | B16: =D16&E16&F16&G16&H16&I16 -> 001000 | C16: =SUM(D16:I16) -> 1 | D16: =MOD(INT($A16/32),2) -> 0 | E16: =MOD(INT($A16/16),2) -> 0 | F16: =MOD(INT($A16/8),2) -> 1 | G16: =MOD(INT($A16/4),2) -> 0 | H16: =MOD(INT($A16/2),2) -> 0 | I16: =MOD(INT($A16/1),2) -> 0 | J16: =E_zero+D16*(Half_gap*(Ceiling_e-E_zero)-$F$4) -> 71 | K16: =J16+E16*(Half_gap*(Ceiling_e-J16)-$F$4) -> 71 | L16: =K16+F16*(Half_gap*(Ceiling_e-K16)-$F$4) -> 78 | M16: =L16+G16*(Half_gap*(Ceiling_e-L16)-$F$4) -> 78 | N16: =M16+H16*(Half_gap*(Ceiling_e-M16)-$F$4) -> 78 | O16: =N16+I16*(Half_gap*(Ceiling_e-N16)-$F$4) -> 78 | P16: =Val_pt*(J16-E_zero) -> 0 | Q16: =Val_pt*(K16-E_zero) -> 0 | R16: =Val_pt*(L16-E_zero) -> 70 | S16: =Val_pt*(M16-E_zero) -> 70 | T16: =Val_pt*(N16-E_zero) -> 70 | U16: =Val_pt*(O16-E_zero) -> 70 | V16: =MAX(W16+Cost_round*D16-P16,IF(D16=1,Pre_q,0)) -> 470 | W16: =MAX(X16+Cost_round*E16-Q16,IF(E16=1,Pre_q,0),Floor_q) -> 470 | X16: =MAX(Y16+Cost_round*F16-R16,IF(F16=1,Pre_q,0),Floor_q) -> 470 | Y16: =MAX(Z16+Cost_round*G16-S16,IF(G16=1,Pre_q,0),Floor_q) -> 350 | Z16: =MAX(AA16+Cost_round*H16-T16,IF(H16=1,Pre_q,0),Floor_q) -> 350 | AA16: =MAX(AB16+Cost_round*I16-U16,IF(I16=1,Pre_q,0),Floor_q) -> 400 | AB16: =MAX(End_q,Floor_q) -> 470 | AC16: =IF(Q_zero>=V16-0.000000001,1,0) -> 1 | AD16: =IF($AC16=1,Q_zero-Cost_round*D16+P16-W16,"") -> 150 | AE16: =IF($AC16=1,W16-Cost_round*E16+Q16-X16,"") -> 0 | AF16: =IF($AC16=1,X16-Cost_round*F16+R16-Y16,"") -> 70 | AG16: =IF($AC16=1,Y16-Cost_round*G16+S16-Z16,"") -> 70 | AH16: =IF($AC16=1,Z16-Cost_round*H16+T16-AA16,"") -> 20 | AI16: =IF($AC16=1,AA16-Cost_round*I16+U16-AB16,"") -> 0 | AJ16: =IF($AC16=1,SUM(AD16:AI16),"") -> 310 | AK16: =IF($AC16=1,AD16*Beta_y^1+AE16*Beta_y^2+AF16*Beta_y^3+AG16*Beta_y^4+AH16*Beta_y^5+AI16*Beta_y^6,"") -> 249.18504 | AL16: =IF($AC16=1,AK16+Beta_y^6*U16/Hurdle_r,"") -> 644.31679 | AM16: =IF($AC16=1,AK16,"") -> 249.18504 | AN16: =IF($AC16=1,AK16+Beta_y^6*U16*(1-(1+Hurdle_r)^(-Life_yrs))/Hurdle_r,"") -> 585.58297 | AO16: =IF($AC16=1,AJ16+Credit_yrs*U16,"") -> 1010 | AP16: =IF($AC16=1,$AD16/(1+AP$6)^1+$AE16/(1+AP$6)^2+$AF16/(1+AP$6)^3+$AG16/(1+AP$6)^4+$AH16/(1+AP$6)^5+$AI16/(1+AP$6)^6+$U16/AP$6/(1+AP$6)^6,"") -> 2243.2672 | AQ16: =IF($AC16=1,$AD16/(1+AQ$6)^1+$AE16/(1+AQ$6)^2+$AF16/(1+AQ$6)^3+$AG16/(1+AQ$6)^4+$AH16/(1+AQ$6)^5+$AI16/(1+AQ$6)^6+$U16/AQ$6/(1+AQ$6)^6,"") -> 1321.287 | AR16: =IF($AC16=1,$AD16/(1+AR$6)^1+$AE16/(1+AR$6)^2+$AF16/(1+AR$6)^3+$AG16/(1+AR$6)^4+$AH16/(1+AR$6)^5+$AI16/(1+AR$6)^6+$U16/AR$6/(1+AR$6)^6,"") -> 810.91932 | AS16: =IF($AC16=1,$AD16/(1+AS$6)^1+$AE16/(1+AS$6)^2+$AF16/(1+AS$6)^3+$AG16/(1+AS$6)^4+$AH16/(1+AS$6)^5+$AI16/(1+AS$6)^6+$U16/AS$6/(1+AS$6)^6,"") -> 644.31679 | AT16: =IF($AC16=1,$AD16/(1+AT$6)^1+$AE16/(1+AT$6)^2+$AF16/(1+AT$6)^3+$AG16/(1+AT$6)^4+$AH16/(1+AT$6)^5+$AI16/(1+AT$6)^6+$U16/AT$6/(1+AT$6)^6,"") -> 535.12281 | AU16: =IF($AC16=1,$AD16/(1+AU$6)^1+$AE16/(1+AU$6)^2+$AF16/(1+AU$6)^3+$AG16/(1+AU$6)^4+$AH16/(1+AU$6)^5+$AI16/(1+AU$6)^6+$U16/AU$6/(1+AU$6)^6,"") -> 428.18006 | AV16: =IF($AC16=1,$AD16/(1+AV$6)^1+$AE16/(1+AV$6)^2+$AF16/(1+AV$6)^3+$AG16/(1+AV$6)^4+$AH16/(1+AV$6)^5+$AI16/(1+AV$6)^6+$U16/AV$6/(1+AV$6)^6,"") -> 324.51882 | AW16: =IF($AC16=1,$AD16/(1+AW$6)^1+$AE16/(1+AW$6)^2+$AF16/(1+AW$6)^3+$AG16/(1+AW$6)^4+$AH16/(1+AW$6)^5+$AI16/(1+AW$6)^6+$U16/AW$6/(1+AW$6)^6,"") -> 225.48289 | ... BB16: =IF($AC16=1,$AD16/(1+BB$6)^1+$AE16/(1+BB$6)^2+$AF16/(1+BB$6)^3+$AG16/(1+BB$6)^4+$AH16/(1+BB$6)^5+$AI16/(1+BB$6)^6+$U16/BB$6/(1+BB$6)^6,"") -> 226.31519
A17: 9 | B17: =D17&E17&F17&G17&H17&I17 -> 001001 | C17: =SUM(D17:I17) -> 2 | D17: =MOD(INT($A17/32),2) -> 0 | E17: =MOD(INT($A17/16),2) -> 0 | F17: =MOD(INT($A17/8),2) -> 1 | G17: =MOD(INT($A17/4),2) -> 0 | H17: =MOD(INT($A17/2),2) -> 0 | I17: =MOD(INT($A17/1),2) -> 1 | J17: =E_zero+D17*(Half_gap*(Ceiling_e-E_zero)-$F$4) -> 71 | K17: =J17+E17*(Half_gap*(Ceiling_e-J17)-$F$4) -> 71 | L17: =K17+F17*(Half_gap*(Ceiling_e-K17)-$F$4) -> 78 | M17: =L17+G17*(Half_gap*(Ceiling_e-L17)-$F$4) -> 78 | N17: =M17+H17*(Half_gap*(Ceiling_e-M17)-$F$4) -> 78 | O17: =N17+I17*(Half_gap*(Ceiling_e-N17)-$F$4) -> 81.5 | P17: =Val_pt*(J17-E_zero) -> 0 | Q17: =Val_pt*(K17-E_zero) -> 0 | R17: =Val_pt*(L17-E_zero) -> 70 | S17: =Val_pt*(M17-E_zero) -> 70 | T17: =Val_pt*(N17-E_zero) -> 70 | U17: =Val_pt*(O17-E_zero) -> 105 | V17: =MAX(W17+Cost_round*D17-P17,IF(D17=1,Pre_q,0)) -> 470 | W17: =MAX(X17+Cost_round*E17-Q17,IF(E17=1,Pre_q,0),Floor_q) -> 470 | X17: =MAX(Y17+Cost_round*F17-R17,IF(F17=1,Pre_q,0),Floor_q) -> 470 | Y17: =MAX(Z17+Cost_round*G17-S17,IF(G17=1,Pre_q,0),Floor_q) -> 350 | Z17: =MAX(AA17+Cost_round*H17-T17,IF(H17=1,Pre_q,0),Floor_q) -> 415 | AA17: =MAX(AB17+Cost_round*I17-U17,IF(I17=1,Pre_q,0),Floor_q) -> 485 | AB17: =MAX(End_q,Floor_q) -> 470 | AC17: =IF(Q_zero>=V17-0.000000001,1,0) -> 1 | AD17: =IF($AC17=1,Q_zero-Cost_round*D17+P17-W17,"") -> 150 | AE17: =IF($AC17=1,W17-Cost_round*E17+Q17-X17,"") -> 0 | AF17: =IF($AC17=1,X17-Cost_round*F17+R17-Y17,"") -> 70 | AG17: =IF($AC17=1,Y17-Cost_round*G17+S17-Z17,"") -> 5 | AH17: =IF($AC17=1,Z17-Cost_round*H17+T17-AA17,"") -> 0 | AI17: =IF($AC17=1,AA17-Cost_round*I17+U17-AB17,"") -> 0 | AJ17: =IF($AC17=1,SUM(AD17:AI17),"") -> 225 | AK17: =IF($AC17=1,AD17*Beta_y^1+AE17*Beta_y^2+AF17*Beta_y^3+AG17*Beta_y^4+AH17*Beta_y^5+AI17*Beta_y^6,"") -> 192.37074 | AL17: =IF($AC17=1,AK17+Beta_y^6*U17/Hurdle_r,"") -> 785.06837 | AM17: =IF($AC17=1,AK17,"") -> 192.37074 | AN17: =IF($AC17=1,AK17+Beta_y^6*U17*(1-(1+Hurdle_r)^(-Life_yrs))/Hurdle_r,"") -> 696.96764 | AO17: =IF($AC17=1,AJ17+Credit_yrs*U17,"") -> 1275 | AP17: =IF($AC17=1,$AD17/(1+AP$6)^1+$AE17/(1+AP$6)^2+$AF17/(1+AP$6)^3+$AG17/(1+AP$6)^4+$AH17/(1+AP$6)^5+$AI17/(1+AP$6)^6+$U17/AP$6/(1+AP$6)^6,"") -> 3145.3283 | AQ17: =IF($AC17=1,$AD17/(1+AQ$6)^1+$AE17/(1+AQ$6)^2+$AF17/(1+AQ$6)^3+$AG17/(1+AQ$6)^4+$AH17/(1+AQ$6)^5+$AI17/(1+AQ$6)^6+$U17/AQ$6/(1+AQ$6)^6,"") -> 1774.4916 | AR17: =IF($AC17=1,$AD17/(1+AR$6)^1+$AE17/(1+AR$6)^2+$AF17/(1+AR$6)^3+$AG17/(1+AR$6)^4+$AH17/(1+AR$6)^5+$AI17/(1+AR$6)^6+$U17/AR$6/(1+AR$6)^6,"") -> 1025.2299 | AS17: =IF($AC17=1,$AD17/(1+AS$6)^1+$AE17/(1+AS$6)^2+$AF17/(1+AS$6)^3+$AG17/(1+AS$6)^4+$AH17/(1+AS$6)^5+$AI17/(1+AS$6)^6+$U17/AS$6/(1+AS$6)^6,"") -> 785.06837 | AT17: =IF($AC17=1,$AD17/(1+AT$6)^1+$AE17/(1+AT$6)^2+$AF17/(1+AT$6)^3+$AG17/(1+AT$6)^4+$AH17/(1+AT$6)^5+$AI17/(1+AT$6)^6+$U17/AT$6/(1+AT$6)^6,"") -> 630.23301 | AU17: =IF($AC17=1,$AD17/(1+AU$6)^1+$AE17/(1+AU$6)^2+$AF17/(1+AU$6)^3+$AG17/(1+AU$6)^4+$AH17/(1+AU$6)^5+$AI17/(1+AU$6)^6+$U17/AU$6/(1+AU$6)^6,"") -> 481.949 | AV17: =IF($AC17=1,$AD17/(1+AV$6)^1+$AE17/(1+AV$6)^2+$AF17/(1+AV$6)^3+$AG17/(1+AV$6)^4+$AH17/(1+AV$6)^5+$AI17/(1+AV$6)^6+$U17/AV$6/(1+AV$6)^6,"") -> 343.74196 | AW17: =IF($AC17=1,$AD17/(1+AW$6)^1+$AE17/(1+AW$6)^2+$AF17/(1+AW$6)^3+$AG17/(1+AW$6)^4+$AH17/(1+AW$6)^5+$AI17/(1+AW$6)^6+$U17/AW$6/(1+AW$6)^6,"") -> 221.50856 | ... BB17: =IF($AC17=1,$AD17/(1+BB$6)^1+$AE17/(1+BB$6)^2+$AF17/(1+BB$6)^3+$AG17/(1+BB$6)^4+$AH17/(1+BB$6)^5+$AI17/(1+BB$6)^6+$U17/BB$6/(1+BB$6)^6,"") -> 222.47283
A18: 10 | B18: =D18&E18&F18&G18&H18&I18 -> 001010 | C18: =SUM(D18:I18) -> 2 | D18: =MOD(INT($A18/32),2) -> 0 | E18: =MOD(INT($A18/16),2) -> 0 | F18: =MOD(INT($A18/8),2) -> 1 | G18: =MOD(INT($A18/4),2) -> 0 | H18: =MOD(INT($A18/2),2) -> 1 | I18: =MOD(INT($A18/1),2) -> 0 | J18: =E_zero+D18*(Half_gap*(Ceiling_e-E_zero)-$F$4) -> 71 | K18: =J18+E18*(Half_gap*(Ceiling_e-J18)-$F$4) -> 71 | L18: =K18+F18*(Half_gap*(Ceiling_e-K18)-$F$4) -> 78 | M18: =L18+G18*(Half_gap*(Ceiling_e-L18)-$F$4) -> 78 | N18: =M18+H18*(Half_gap*(Ceiling_e-M18)-$F$4) -> 81.5 | O18: =N18+I18*(Half_gap*(Ceiling_e-N18)-$F$4) -> 81.5 | P18: =Val_pt*(J18-E_zero) -> 0 | Q18: =Val_pt*(K18-E_zero) -> 0 | R18: =Val_pt*(L18-E_zero) -> 70 | S18: =Val_pt*(M18-E_zero) -> 70 | T18: =Val_pt*(N18-E_zero) -> 105 | U18: =Val_pt*(O18-E_zero) -> 105 | V18: =MAX(W18+Cost_round*D18-P18,IF(D18=1,Pre_q,0)) -> 470 | W18: =MAX(X18+Cost_round*E18-Q18,IF(E18=1,Pre_q,0),Floor_q) -> 470 | X18: =MAX(Y18+Cost_round*F18-R18,IF(F18=1,Pre_q,0),Floor_q) -> 470 | Y18: =MAX(Z18+Cost_round*G18-S18,IF(G18=1,Pre_q,0),Floor_q) -> 400 | Z18: =MAX(AA18+Cost_round*H18-T18,IF(H18=1,Pre_q,0),Floor_q) -> 470 | AA18: =MAX(AB18+Cost_round*I18-U18,IF(I18=1,Pre_q,0),Floor_q) -> 365 | AB18: =MAX(End_q,Floor_q) -> 470 | AC18: =IF(Q_zero>=V18-0.000000001,1,0) -> 1 | AD18: =IF($AC18=1,Q_zero-Cost_round*D18+P18-W18,"") -> 150 | AE18: =IF($AC18=1,W18-Cost_round*E18+Q18-X18,"") -> 0 | AF18: =IF($AC18=1,X18-Cost_round*F18+R18-Y18,"") -> 20 | AG18: =IF($AC18=1,Y18-Cost_round*G18+S18-Z18,"") -> 0 | AH18: =IF($AC18=1,Z18-Cost_round*H18+T18-AA18,"") -> 90 | AI18: =IF($AC18=1,AA18-Cost_round*I18+U18-AB18,"") -> 0 | AJ18: =IF($AC18=1,SUM(AD18:AI18),"") -> 260 | AK18: =IF($AC18=1,AD18*Beta_y^1+AE18*Beta_y^2+AF18*Beta_y^3+AG18*Beta_y^4+AH18*Beta_y^5+AI18*Beta_y^6,"") -> 207.27285 | AL18: =IF($AC18=1,AK18+Beta_y^6*U18/Hurdle_r,"") -> 799.97048 | AM18: =IF($AC18=1,AK18,"") -> 207.27285 | AN18: =IF($AC18=1,AK18+Beta_y^6*U18*(1-(1+Hurdle_r)^(-Life_yrs))/Hurdle_r,"") -> 711.86975 | AO18: =IF($AC18=1,AJ18+Credit_yrs*U18,"") -> 1310 | AP18: =IF($AC18=1,$AD18/(1+AP$6)^1+$AE18/(1+AP$6)^2+$AF18/(1+AP$6)^3+$AG18/(1+AP$6)^4+$AH18/(1+AP$6)^5+$AI18/(1+AP$6)^6+$U18/AP$6/(1+AP$6)^6,"") -> 3172.7636 | AQ18: =IF($AC18=1,$AD18/(1+AQ$6)^1+$AE18/(1+AQ$6)^2+$AF18/(1+AQ$6)^3+$AG18/(1+AQ$6)^4+$AH18/(1+AQ$6)^5+$AI18/(1+AQ$6)^6+$U18/AQ$6/(1+AQ$6)^6,"") -> 1797.7036 | AR18: =IF($AC18=1,$AD18/(1+AR$6)^1+$AE18/(1+AR$6)^2+$AF18/(1+AR$6)^3+$AG18/(1+AR$6)^4+$AH18/(1+AR$6)^5+$AI18/(1+AR$6)^6+$U18/AR$6/(1+AR$6)^6,"") -> 1043.1157 | AS18: =IF($AC18=1,$AD18/(1+AS$6)^1+$AE18/(1+AS$6)^2+$AF18/(1+AS$6)^3+$AG18/(1+AS$6)^4+$AH18/(1+AS$6)^5+$AI18/(1+AS$6)^6+$U18/AS$6/(1+AS$6)^6,"") -> 799.97048 | AT18: =IF($AC18=1,$AD18/(1+AT$6)^1+$AE18/(1+AT$6)^2+$AF18/(1+AT$6)^3+$AG18/(1+AT$6)^4+$AH18/(1+AT$6)^5+$AI18/(1+AT$6)^6+$U18/AT$6/(1+AT$6)^6,"") -> 642.53482 | AU18: =IF($AC18=1,$AD18/(1+AU$6)^1+$AE18/(1+AU$6)^2+$AF18/(1+AU$6)^3+$AG18/(1+AU$6)^4+$AH18/(1+AU$6)^5+$AI18/(1+AU$6)^6+$U18/AU$6/(1+AU$6)^6,"") -> 490.96033 | AV18: =IF($AC18=1,$AD18/(1+AV$6)^1+$AE18/(1+AV$6)^2+$AF18/(1+AV$6)^3+$AG18/(1+AV$6)^4+$AH18/(1+AV$6)^5+$AI18/(1+AV$6)^6+$U18/AV$6/(1+AV$6)^6,"") -> 348.56449 | AW18: =IF($AC18=1,$AD18/(1+AW$6)^1+$AE18/(1+AW$6)^2+$AF18/(1+AW$6)^3+$AG18/(1+AW$6)^4+$AH18/(1+AW$6)^5+$AI18/(1+AW$6)^6+$U18/AW$6/(1+AW$6)^6,"") -> 221.23923 | ... BB18: =IF($AC18=1,$AD18/(1+BB$6)^1+$AE18/(1+BB$6)^2+$AF18/(1+BB$6)^3+$AG18/(1+BB$6)^4+$AH18/(1+BB$6)^5+$AI18/(1+BB$6)^6+$U18/BB$6/(1+BB$6)^6,"") -> 222.24925
A19: 11 | B19: =D19&E19&F19&G19&H19&I19 -> 001011 | C19: =SUM(D19:I19) -> 3 | D19: =MOD(INT($A19/32),2) -> 0 | E19: =MOD(INT($A19/16),2) -> 0 | F19: =MOD(INT($A19/8),2) -> 1 | G19: =MOD(INT($A19/4),2) -> 0 | H19: =MOD(INT($A19/2),2) -> 1 | I19: =MOD(INT($A19/1),2) -> 1 | J19: =E_zero+D19*(Half_gap*(Ceiling_e-E_zero)-$F$4) -> 71 | K19: =J19+E19*(Half_gap*(Ceiling_e-J19)-$F$4) -> 71 | L19: =K19+F19*(Half_gap*(Ceiling_e-K19)-$F$4) -> 78 | M19: =L19+G19*(Half_gap*(Ceiling_e-L19)-$F$4) -> 78 | N19: =M19+H19*(Half_gap*(Ceiling_e-M19)-$F$4) -> 81.5 | O19: =N19+I19*(Half_gap*(Ceiling_e-N19)-$F$4) -> 83.25 | P19: =Val_pt*(J19-E_zero) -> 0 | Q19: =Val_pt*(K19-E_zero) -> 0 | R19: =Val_pt*(L19-E_zero) -> 70 | S19: =Val_pt*(M19-E_zero) -> 70 | T19: =Val_pt*(N19-E_zero) -> 105 | U19: =Val_pt*(O19-E_zero) -> 122.5 | V19: =MAX(W19+Cost_round*D19-P19,IF(D19=1,Pre_q,0)) -> 470 | W19: =MAX(X19+Cost_round*E19-Q19,IF(E19=1,Pre_q,0),Floor_q) -> 470 | X19: =MAX(Y19+Cost_round*F19-R19,IF(F19=1,Pre_q,0),Floor_q) -> 470 | Y19: =MAX(Z19+Cost_round*G19-S19,IF(G19=1,Pre_q,0),Floor_q) -> 415 | Z19: =MAX(AA19+Cost_round*H19-T19,IF(H19=1,Pre_q,0),Floor_q) -> 485 | AA19: =MAX(AB19+Cost_round*I19-U19,IF(I19=1,Pre_q,0),Floor_q) -> 470 | AB19: =MAX(End_q,Floor_q) -> 470 | AC19: =IF(Q_zero>=V19-0.000000001,1,0) -> 1 | AD19: =IF($AC19=1,Q_zero-Cost_round*D19+P19-W19,"") -> 150 | AE19: =IF($AC19=1,W19-Cost_round*E19+Q19-X19,"") -> 0 | AF19: =IF($AC19=1,X19-Cost_round*F19+R19-Y19,"") -> 5 | AG19: =IF($AC19=1,Y19-Cost_round*G19+S19-Z19,"") -> 0 | AH19: =IF($AC19=1,Z19-Cost_round*H19+T19-AA19,"") -> 0 | AI19: =IF($AC19=1,AA19-Cost_round*I19+U19-AB19,"") -> 2.5 | AJ19: =IF($AC19=1,SUM(AD19:AI19),"") -> 157.5 | AK19: =IF($AC19=1,AD19*Beta_y^1+AE19*Beta_y^2+AF19*Beta_y^3+AG19*Beta_y^4+AH19*Beta_y^5+AI19*Beta_y^6,"") -> 141.5314 | AL19: =IF($AC19=1,AK19+Beta_y^6*U19/Hurdle_r,"") -> 833.01196 | AM19: =IF($AC19=1,AK19,"") -> 141.5314 | AN19: =IF($AC19=1,AK19+Beta_y^6*U19*(1-(1+Hurdle_r)^(-Life_yrs))/Hurdle_r,"") -> 730.22778 | AO19: =IF($AC19=1,AJ19+Credit_yrs*U19,"") -> 1382.5 | AP19: =IF($AC19=1,$AD19/(1+AP$6)^1+$AE19/(1+AP$6)^2+$AF19/(1+AP$6)^3+$AG19/(1+AP$6)^4+$AH19/(1+AP$6)^5+$AI19/(1+AP$6)^6+$U19/AP$6/(1+AP$6)^6,"") -> 3572.0279 | AQ19: =IF($AC19=1,$AD19/(1+AQ$6)^1+$AE19/(1+AQ$6)^2+$AF19/(1+AQ$6)^3+$AG19/(1+AQ$6)^4+$AH19/(1+AQ$6)^5+$AI19/(1+AQ$6)^6+$U19/AQ$6/(1+AQ$6)^6,"") -> 1977.2696 | AR19: =IF($AC19=1,$AD19/(1+AR$6)^1+$AE19/(1+AR$6)^2+$AF19/(1+AR$6)^3+$AG19/(1+AR$6)^4+$AH19/(1+AR$6)^5+$AI19/(1+AR$6)^6+$U19/AR$6/(1+AR$6)^6,"") -> 1109.3807 | AS19: =IF($AC19=1,$AD19/(1+AS$6)^1+$AE19/(1+AS$6)^2+$AF19/(1+AS$6)^3+$AG19/(1+AS$6)^4+$AH19/(1+AS$6)^5+$AI19/(1+AS$6)^6+$U19/AS$6/(1+AS$6)^6,"") -> 833.01196 | AT19: =IF($AC19=1,$AD19/(1+AT$6)^1+$AE19/(1+AT$6)^2+$AF19/(1+AT$6)^3+$AG19/(1+AT$6)^4+$AH19/(1+AT$6)^5+$AI19/(1+AT$6)^6+$U19/AT$6/(1+AT$6)^6,"") -> 655.93999 | AU19: =IF($AC19=1,$AD19/(1+AU$6)^1+$AE19/(1+AU$6)^2+$AF19/(1+AU$6)^3+$AG19/(1+AU$6)^4+$AH19/(1+AU$6)^5+$AI19/(1+AU$6)^6+$U19/AU$6/(1+AU$6)^6,"") -> 487.87072 | AV19: =IF($AC19=1,$AD19/(1+AV$6)^1+$AE19/(1+AV$6)^2+$AF19/(1+AV$6)^3+$AG19/(1+AV$6)^4+$AH19/(1+AV$6)^5+$AI19/(1+AV$6)^6+$U19/AV$6/(1+AV$6)^6,"") -> 333.85577 | AW19: =IF($AC19=1,$AD19/(1+AW$6)^1+$AE19/(1+AW$6)^2+$AF19/(1+AW$6)^3+$AG19/(1+AW$6)^4+$AH19/(1+AW$6)^5+$AI19/(1+AW$6)^6+$U19/AW$6/(1+AW$6)^6,"") -> 202.77534 | ... BB19: =IF($AC19=1,$AD19/(1+BB$6)^1+$AE19/(1+BB$6)^2+$AF19/(1+BB$6)^3+$AG19/(1+BB$6)^4+$AH19/(1+BB$6)^5+$AI19/(1+BB$6)^6+$U19/BB$6/(1+BB$6)^6,"") -> 203.77218
... A71: 63 | B71: =D71&E71&F71&G71&H71&I71 -> 111111 | C71: =SUM(D71:I71) -> 6 | D71: =MOD(INT($A71/32),2) -> 1 | E71: =MOD(INT($A71/16),2) -> 1 | F71: =MOD(INT($A71/8),2) -> 1 | G71: =MOD(INT($A71/4),2) -> 1 | H71: =MOD(INT($A71/2),2) -> 1 | I71: =MOD(INT($A71/1),2) -> 1 | J71: =E_zero+D71*(Half_gap*(Ceiling_e-E_zero)-$F$4) -> 78 | K71: =J71+E71*(Half_gap*(Ceiling_e-J71)-$F$4) -> 81.5 | L71: =K71+F71*(Half_gap*(Ceiling_e-K71)-$F$4) -> 83.25 | M71: =L71+G71*(Half_gap*(Ceiling_e-L71)-$F$4) -> 84.125 | N71: =M71+H71*(Half_gap*(Ceiling_e-M71)-$F$4) -> 84.5625 | O71: =N71+I71*(Half_gap*(Ceiling_e-N71)-$F$4) -> 84.78125 | P71: =Val_pt*(J71-E_zero) -> 70 | Q71: =Val_pt*(K71-E_zero) -> 105 | R71: =Val_pt*(L71-E_zero) -> 122.5 | S71: =Val_pt*(M71-E_zero) -> 131.25 | T71: =Val_pt*(N71-E_zero) -> 135.625 | U71: =Val_pt*(O71-E_zero) -> 137.8125 | V71: =MAX(W71+Cost_round*D71-P71,IF(D71=1,Pre_q,0)) -> 535 | W71: =MAX(X71+Cost_round*E71-Q71,IF(E71=1,Pre_q,0),Floor_q) -> 485 | X71: =MAX(Y71+Cost_round*F71-R71,IF(F71=1,Pre_q,0),Floor_q) -> 470 | Y71: =MAX(Z71+Cost_round*G71-S71,IF(G71=1,Pre_q,0),Floor_q) -> 470 | Z71: =MAX(AA71+Cost_round*H71-T71,IF(H71=1,Pre_q,0),Floor_q) -> 470 | AA71: =MAX(AB71+Cost_round*I71-U71,IF(I71=1,Pre_q,0),Floor_q) -> 470 | AB71: =MAX(End_q,Floor_q) -> 470 | AC71: =IF(Q_zero>=V71-0.000000001,1,0) -> 1 | AD71: =IF($AC71=1,Q_zero-Cost_round*D71+P71-W71,"") -> 85 | AE71: =IF($AC71=1,W71-Cost_round*E71+Q71-X71,"") -> 0 | AF71: =IF($AC71=1,X71-Cost_round*F71+R71-Y71,"") -> 2.5 | AG71: =IF($AC71=1,Y71-Cost_round*G71+S71-Z71,"") -> 11.25 | AH71: =IF($AC71=1,Z71-Cost_round*H71+T71-AA71,"") -> 15.625 | AI71: =IF($AC71=1,AA71-Cost_round*I71+U71-AB71,"") -> 17.8125 | AJ71: =IF($AC71=1,SUM(AD71:AI71),"") -> 132.1875 | AK71: =IF($AC71=1,AD71*Beta_y^1+AE71*Beta_y^2+AF71*Beta_y^3+AG71*Beta_y^4+AH71*Beta_y^5+AI71*Beta_y^6,"") -> 106.5915 | AL71: =IF($AC71=1,AK71+Beta_y^6*U71/Hurdle_r,"") -> 884.50714 | AM71: =IF($AC71=1,AK71,"") -> 106.5915 | AN71: =IF($AC71=1,AK71+Beta_y^6*U71*(1-(1+Hurdle_r)^(-Life_yrs))/Hurdle_r,"") -> 768.87494 | AO71: =IF($AC71=1,AJ71+Credit_yrs*U71,"") -> 1510.3125 | AP71: =IF($AC71=1,$AD71/(1+AP$6)^1+$AE71/(1+AP$6)^2+$AF71/(1+AP$6)^3+$AG71/(1+AP$6)^4+$AH71/(1+AP$6)^5+$AI71/(1+AP$6)^6+$U71/AP$6/(1+AP$6)^6,"") -> 3970.3969 | AQ71: =IF($AC71=1,$AD71/(1+AQ$6)^1+$AE71/(1+AQ$6)^2+$AF71/(1+AQ$6)^3+$AG71/(1+AQ$6)^4+$AH71/(1+AQ$6)^5+$AI71/(1+AQ$6)^6+$U71/AQ$6/(1+AQ$6)^6,"") -> 2174.6581 | AR71: =IF($AC71=1,$AD71/(1+AR$6)^1+$AE71/(1+AR$6)^2+$AF71/(1+AR$6)^3+$AG71/(1+AR$6)^4+$AH71/(1+AR$6)^5+$AI71/(1+AR$6)^6+$U71/AR$6/(1+AR$6)^6,"") -> 1196.382 | AS71: =IF($AC71=1,$AD71/(1+AS$6)^1+$AE71/(1+AS$6)^2+$AF71/(1+AS$6)^3+$AG71/(1+AS$6)^4+$AH71/(1+AS$6)^5+$AI71/(1+AS$6)^6+$U71/AS$6/(1+AS$6)^6,"") -> 884.50714 | AT71: =IF($AC71=1,$AD71/(1+AT$6)^1+$AE71/(1+AT$6)^2+$AF71/(1+AT$6)^3+$AG71/(1+AT$6)^4+$AH71/(1+AT$6)^5+$AI71/(1+AT$6)^6+$U71/AT$6/(1+AT$6)^6,"") -> 684.54648 | AU71: =IF($AC71=1,$AD71/(1+AU$6)^1+$AE71/(1+AU$6)^2+$AF71/(1+AU$6)^3+$AG71/(1+AU$6)^4+$AH71/(1+AU$6)^5+$AI71/(1+AU$6)^6+$U71/AU$6/(1+AU$6)^6,"") -> 494.65926 | AV71: =IF($AC71=1,$AD71/(1+AV$6)^1+$AE71/(1+AV$6)^2+$AF71/(1+AV$6)^3+$AG71/(1+AV$6)^4+$AH71/(1+AV$6)^5+$AI71/(1+AV$6)^6+$U71/AV$6/(1+AV$6)^6,"") -> 320.71578 | AW71: =IF($AC71=1,$AD71/(1+AW$6)^1+$AE71/(1+AW$6)^2+$AF71/(1+AW$6)^3+$AG71/(1+AW$6)^4+$AH71/(1+AW$6)^5+$AI71/(1+AW$6)^6+$U71/AW$6/(1+AW$6)^6,"") -> 173.53163 | ... BB71: =IF($AC71=1,$AD71/(1+BB$6)^1+$AE71/(1+BB$6)^2+$AF71/(1+BB$6)^3+$AG71/(1+BB$6)^4+$AH71/(1+BB$6)^5+$AI71/(1+BB$6)^6+$U71/BB$6/(1+BB$6)^6,"") -> 174.64003

Sheet BestPlan
A1: Transcribe and solve: the best plan pays out above a war chest (Worked Example 5.1, Step 3)
A2: The best of the 64 schedules on Transcribe, by MAX; its year-end cash equals its war chest every year: everything above it is paid out at once.
A4: Best value: payouts plus the savings after year 6 forever | H4: =MAX(Transcribe!$AL$8:$AL$71) -> 1021.9325
A5: Its row among the 64 schedules | H5: =MATCH(H4,Transcribe!$AL$8:$AL$71,0) -> 57
A6: Rounds by year (1 = a round) | H6: =INDEX(Transcribe!$B$8:$B$71,H5) -> 111000
A7: Number of rounds | H7: =INDEX(Transcribe!$C$8:$C$71,H5) -> 3
A8: Schedules that keep every commitment | H8: =SUM(Transcribe!$AC$8:$AC$71) -> 64
A10: Year | B10: Round | C10: Efficiency | D10: Savings | E10: War chest | F10: Payout | G10: Year-end cash | H10: Discount factor | I10: PV of payout
A11: 0 | C11: =E_zero -> 71 | E11: =INDEX(Transcribe!$V$8:$V$71,$H$5) -> 535 | G11: =Q_zero -> 620
A12: 1 | B12: =INDEX(Transcribe!$D$8:$D$71,$H$5) -> 1 | C12: =INDEX(Transcribe!$J$8:$J$71,$H$5) -> 78 | D12: =INDEX(Transcribe!$P$8:$P$71,$H$5) -> 70 | E12: =INDEX(Transcribe!$W$8:$W$71,$H$5) -> 485 | F12: =INDEX(Transcribe!$AD$8:$AD$71,$H$5) -> 85 | G12: =G11-Cost_round*B12+D12-F12 -> 485 | H12: =Beta_y^A12 -> 0.90909091 | I12: =F12*H12 -> 77.272727
A13: 2 | B13: =INDEX(Transcribe!$E$8:$E$71,$H$5) -> 1 | C13: =INDEX(Transcribe!$K$8:$K$71,$H$5) -> 81.5 | D13: =INDEX(Transcribe!$Q$8:$Q$71,$H$5) -> 105 | E13: =INDEX(Transcribe!$X$8:$X$71,$H$5) -> 470 | F13: =INDEX(Transcribe!$AE$8:$AE$71,$H$5) -> 0 | G13: =G12-Cost_round*B13+D13-F13 -> 470 | H13: =Beta_y^A13 -> 0.82644628 | I13: =F13*H13 -> 0
A14: 3 | B14: =INDEX(Transcribe!$F$8:$F$71,$H$5) -> 1 | C14: =INDEX(Transcribe!$L$8:$L$71,$H$5) -> 83.25 | D14: =INDEX(Transcribe!$R$8:$R$71,$H$5) -> 122.5 | E14: =INDEX(Transcribe!$Y$8:$Y$71,$H$5) -> 350 | F14: =INDEX(Transcribe!$AF$8:$AF$71,$H$5) -> 122.5 | G14: =G13-Cost_round*B14+D14-F14 -> 350 | H14: =Beta_y^A14 -> 0.7513148 | I14: =F14*H14 -> 92.036063
A15: 4 | B15: =INDEX(Transcribe!$G$8:$G$71,$H$5) -> 0 | C15: =INDEX(Transcribe!$M$8:$M$71,$H$5) -> 83.25 | D15: =INDEX(Transcribe!$S$8:$S$71,$H$5) -> 122.5 | E15: =INDEX(Transcribe!$Z$8:$Z$71,$H$5) -> 350 | F15: =INDEX(Transcribe!$AG$8:$AG$71,$H$5) -> 122.5 | G15: =G14-Cost_round*B15+D15-F15 -> 350 | H15: =Beta_y^A15 -> 0.68301346 | I15: =F15*H15 -> 83.669148
