Workbook

Sheet README
B1: DCT Laboratory — Vol I, Ch 7: Dynamic Enterprise Systems
B2: Seed 26107 · Companion to DCT_V1_Ch07_Lab.ipynb and AXIOM Lab 1.7 (module AXIOM-07). Gaps in engineers, readings in index points.
B4: Worked Example 7.1, How Hard Should Meridian Steer Its Hiring?, with the book's declarations, and the five steps of AXIOM Lab 1.7, Steering Meridian Through Time.
B5: Declarations: the hiring loop of Worked Example 7.1, the three-reading company of Equation 3.2, the covenant model of Online Appendix 7.B.2, the start-up's law and the forecastable horizon's inputs.
B6: Clock: the forecastable horizon, the start-up's law against quarterly, monthly and weekly steps, the exponential plan, and which hiring rules are samples of a continuous law (lab step 1).
B7: QuarterlyLaw: the yearly law of Equation 3.2 as quarters (engine matrices), certified by formulas: four quarters reproduce every year end (Proposition 7.2(i)).
B8: Superposition: momentum plus program, year by year, and Figure 7.1's numbers (Theorem 7.2(i); lab step 2).
B9: PolicyMap: the steady state of every held investment by Cramer's rule, the eigenvalues and the half-life of a shock (Theorems 7.3(ii) and 7.4(i); lab step 2).
B10: Disclosure: the rows of the observability matrix, the rank of each case, and how long technology stays uncertain from covenant certificates (Theorem 7.2(iii); Online Appendix 7.B.2; lab step 3).
B11: Gains and Delay: the hiring loop without and with the one-quarter delay, Table 7.4's regimes, Table 7.5 and the deadbeat rule's cycle (Worked Example 7.1, Steps 1-4; lab step 4).
B12: GainBench: every gain through every regime, without and with the delay, and the committee that retunes its rule (Figure 7.2; Online Appendix 7.B.8).
B13: Lyapunov: the series of Remark 7.1 for the delayed hiring loop and the three-reading company, and the health index against a plain scorecard (Theorem 7.4(iii); lab step 5).
... B20: Cross-sheet link: green.

Sheet Declarations
A1: Declarations (Worked Example 7.1, Step 1; Equation 3.2; Online Appendix 7.B.1, 7.B.2, 7.B.4). Gaps in engineers; readings in index points.
A3: Quantity | B3: Value | C3: Source
A4: Share of a gap that carries over each quarter, a | B4: 0.9 | C4: Worked Example 7.1: retraining and internal moves close 10 percent of any gap
A5: Share of approved hires productive within the quarter, b | B5: 0.6 | C5: Worked Example 7.1
A6: Starting gap, bench minus target (engineers) | B6: -100 | C6: Meridian's bench is 100 engineers short of target
A7: Cautious gain | B7: 0.5 | C7: Table 7.5
A8: Moderate gain | B8: 1 | C8: Figure 7.3
A9: Deadbeat gain, a / b | B9: =Carry_a/Hire_b -> 1.5 | C9: Worked Example 7.1, Step 2: 1.5
A10: Aggressive gain | B10: 2.5 | C10: Figures 7.2 and 7.3
A11: Overcorrecting gain | B11: 3.5 | C11: Table 7.5
A12: A gain beyond the limit with the delay | B12: 1.8 | C12: Figure 7.2
A13: Gain at which the delayed roots merge, a^2 / (4b) | B13: =Carry_a^2/(4*Hire_b) -> 0.3375 | C13: Online Appendix 7.B.7: 0.81/2.4
A14: Tolerance band (engineers) | B14: 10 | C14: Worked Example 7.1, Step 4
A15: Tighter band (engineers) | B15: 5 | C15: Online Appendix 7.B.7
A16: Committee's retuning intensity, eta | B16: 3.5 | C16: Online Appendix 7.B.8
A17: Committee's starting gain | B17: =Gain_cautious -> 0.5 | C17: The cautious gain
A19: Equation 3.2: the three-reading company, yearly | B19: capability | C19: technology | D19: efficiency
A20: A, capability row | B20: 0.9 | C20: 0.05 | D20: 0
A21: A, technology row | B21: 0.1 | C21: 0.85 | D21: 0
A22: A, efficiency row | B22: 0.05 | C22: 0.1 | D22: 0.8
A23: B: capability investment builds capability and the platform | B23: 0.6 | C23: 0.3 | D23: 0
A24: Today, x0 | B24: 50 | C24: 40 | D24: 60
A25: Held investment of Figure 7.1, a year | B25: 8
A26: Investment in Section 3.4's one-year step | B26: 10
A28: Online Appendix 7.B.2: the covenant model, quarterly | B28: liquidity | C28: leverage | D28: capability | E28: technology
A29: A, liquidity row | B29: 0.95 | C29: 0 | D29: 0.04 | E29: 0
A30: A, leverage row | B30: 0 | C30: 0.9 | D30: 0 | E30: 0
A31: A, capability row | B31: 0 | C31: 0 | D31: 0.9 | E31: 0.05
A32: A, technology row | B32: 0 | C32: 0 | D32: 0 | E32: 0.92
A33: Case 2: capability's response to technology | B33: 0 | C33: Technology feeds nothing (the entry 0.05 becomes 0)
A34: Error on each reported number (one unit) | B34: 1
A36: Proposition 7.4: the start-up's logistic law | B36: Value | C36: Source
A37: Growth rate while small, r (a year) | B37: 0.9 | C37: Online Appendix 7.B.4
A38: Market wall, kappa | B38: 100 | C38: Figure 5.3
A39: Users today, x0 | B39: 2 | C39: Chapter 5's start-up
A41: Section 7.3: the forecastable horizon | B41: Value | C41: Source
A42: Measurement error on capability (points) | B42: 5 | C42: Table 5.2: skills survey
A43: Tolerance the decisions need (points) | B43: 15 | C43: Section 7.3
A44: Sensitivity of the capability dynamics, L (a year) | B44: 0.5 | C44: Section 7.3
A46: Hiring loop: d' = a d + b u under the rule u = -gamma d; with the delay d' = a d + b u_(k-1), nothing in the pipeline at the start. The other models are declared yearly (Equation 3.2) and quarterly (Online Appendix 7.B.2).

Sheet Clock
A1: Check the clock: how far a model can see, and the start-up's law against its steps (Theorem 7.1(ii); Proposition 7.2; Online Appendix 7.B.1, 7.B.4; AXIOM Lab 1.7, step 1)
A3: Forecastable horizon (Online Appendix 7.B.1) | B3: Value | C3: Reading | H3: Proposition 7.2(iii): the hiring rules | I3: Gain | J3: Closed-loop coefficient a - b gamma | K3: Continuous rate ln(coefficient), a quarter
A4: Horizon (1/L) ln(tolerance / error), years | B4: =LN(Tol_tau/Err_0)/Sens_L -> 2.1972246 | C4: 2 ln 3 = 2.2 years | H4: cautious | I4: =Gain_cautious -> 0.5 | J4: =Carry_a-Hire_b*I4 -> 0.6 | K4: =IF(J4>0.000000000001,LN(J4),"none: no continuous law") -> -0.51082562
A5: Halving the measurement error adds, years | B5: =LN(2)/Sens_L -> 1.3862944 | C5: 1.4 years | H5: moderate | I5: =Gain_moderate -> 1 | J5: =Carry_a-Hire_b*I5 -> 0.3 | K5: =IF(J5>0.000000000001,LN(J5),"none: no continuous law") -> -1.2039728
A6: Dynamics twice as fast: the horizon, years | B6: =B4/2 -> 1.0986123 | C6: Doubling the speed halves the horizon | H6: deadbeat | I6: =Gain_deadbeat -> 1.5 | J6: =Carry_a-Hire_b*I6 -> 0 | K6: =IF(J6>0.000000000001,LN(J6),"none: no continuous law") -> none: no continuous law
H7: aggressive | I7: =Gain_aggressive -> 2.5 | J7: =Carry_a-Hire_b*I7 -> -0.6 | K7: =IF(J7>0.000000000001,LN(J7),"none: no continuous law") -> none: no continuous law
A8: The start-up's law (Online Appendix 7.B.4) | B8: Value | C8: Reading | H8: overcorrecting | I8: =Gain_over -> 3.5 | J8: =Carry_a-Hire_b*I8 -> -1.2 | K8: =IF(J8>0.000000000001,LN(J8),"none: no continuous law") -> none: no continuous law
A9: Doubling time while small, (ln 2) / r, years | B9: =LN(2)/Rate_r -> 0.77016353 | C9: about 0.77 years, nine months
A10: Inflection date, ln((kappa - x0) / x0) / r, years | B10: =LN((Kappa-Users_x0)/Users_x0)/Rate_r -> 4.3242448 | C10: growth peaks at 50 after 4.3 years | H10: A coefficient that is zero or negative is the sample of no continuous law: such rules belong to decisions taken at review dates and held in between (Online Appendix 7.B.4's reading).
A11: A quarter's growth while small: the law, e^(r/4) - 1 | B11: =EXP(Rate_r/4)-1 -> 0.25232272 | C11: exact discretization (Equation 7.2): about 25 percent
A12: A quarter's growth while small: the quarterly step, r/4 | B12: =Rate_r/4 -> 0.225 | C12: 22.5 percent
A13: The law at year 5 | B13: =Kappa*Users_x0/(Users_x0+(Kappa-Users_x0)*EXP(-Rate_r*5)) -> 64.752546
A14: The law at year 6 | B14: =Kappa*Users_x0/(Users_x0+(Kappa-Users_x0)*EXP(-Rate_r*6)) -> 81.879128 | C14: 81.9
A15: The law at year 10 | B15: =Kappa*Users_x0/(Users_x0+(Kappa-Users_x0)*EXP(-Rate_r*10)) -> 99.398927 | C15: 99.4
A16: Quarterly step at year 5 | B16: =B50 -> 58.128602 | C16: 58.1
A17: Monthly step at year 5 | B17: =C90 -> 62.609958
A18: Weekly step at year 5 | B18: =D290 -> 64.265371
A19: Gap to the law at year 5: quarterly step | B19: =B13-B16 -> 6.6239432 | C19: in proportion to the step
A20: Gap to the law at year 5: monthly step | B20: =B13-B17 -> 2.142588 | C20: 2.1
A21: Gap to the law at year 5: weekly step | B21: =B13-B18 -> 0.48717415 | C21: 0.5
A22: Exponential plan 2e^(rt) at the inflection date | B22: =Users_x0*EXP(Rate_r*B10) -> 98 | C22: 98
A23: Exponential plan at year 5 | B23: =Users_x0*EXP(Rate_r*5) -> 180.03426 | C23: 180
A24: Exponential plan at year 6 | B24: =Users_x0*EXP(Rate_r*6) -> 442.81283 | C24: 443, more than four times the market
A25: Exponential plan at year 6, as a multiple of the market | B25: =B24/Kappa -> 4.4281283
A27: Each step: x' = x + (1/steps a year) r x (1 - x/kappa), Chapter 5's quarterly map with 4 steps a year (Proposition 7.2(ii)). The law column samples the exact solution at the weekly dates.
A28: Step k | B28: Quarterly steps | C28: Monthly steps | D28: Weekly steps | E28: Time t (weeks), years | F28: The law at t
A29: Steps a year | B29: 4 | C29: 12 | D29: 52
A30: 0 | B30: =Users_x0 -> 2 | C30: =Users_x0 -> 2 | D30: =Users_x0 -> 2 | E30: =A30/$D$29 -> 0 | F30: =Kappa*Users_x0/(Users_x0+(Kappa-Users_x0)*EXP(-Rate_r*E30)) -> 2
A31: 1 | B31: =B30+(1/B$29)*Rate_r*B30*(1-B30/Kappa) -> 2.441 | C31: =C30+(1/C$29)*Rate_r*C30*(1-C30/Kappa) -> 2.147 | D31: =D30+(1/D$29)*Rate_r*D30*(1-D30/Kappa) -> 2.0339231 | E31: =A31/$D$29 -> 0.019230769 | F31: =Kappa*Users_x0/(Users_x0+(Kappa-Users_x0)*EXP(-Rate_r*E31)) -> 2.0342064
A32: 2 | B32: =B31+(1/B$29)*Rate_r*B31*(1-B31/Kappa) -> 2.9768184 | C32: =C31+(1/C$29)*Rate_r*C31*(1-C31/Kappa) -> 2.3045678 | D32: =D31+(1/D$29)*Rate_r*D31*(1-D31/Kappa) -> 2.0684096 | E32: =A32/$D$29 -> 0.038461538 | F32: =Kappa*Users_x0/(Users_x0+(Kappa-Users_x0)*EXP(-Rate_r*E32)) -> 2.0689855
A33: 3 | B33: =B32+(1/B$29)*Rate_r*B32*(1-B32/Kappa) -> 3.6266643 | C33: =C32+(1/C$29)*Rate_r*C32*(1-C32/Kappa) -> 2.4734271 | D33: =D32+(1/D$29)*Rate_r*D32*(1-D32/Kappa) -> 2.1034685 | E33: =A33/$D$29 -> 0.057692308 | F33: =Kappa*Users_x0/(Users_x0+(Kappa-Users_x0)*EXP(-Rate_r*E33)) -> 2.1043464
A34: 4 | B34: =B33+(1/B$29)*Rate_r*B33*(1-B33/Kappa) -> 4.4130702 | C34: =C33+(1/C$29)*Rate_r*C33*(1-C33/Kappa) -> 2.6543458 | D34: =D33+(1/D$29)*Rate_r*D33*(1-D33/Kappa) -> 2.1391089 | E34: =A34/$D$29 -> 0.076923077 | F34: =Kappa*Users_x0/(Users_x0+(Kappa-Users_x0)*EXP(-Rate_r*E34)) -> 2.1402985
A35: 5 | B35: =B34+(1/B$29)*Rate_r*B34*(1-B34/Kappa) -> 5.3621918 | C35: =C34+(1/C$29)*Rate_r*C34*(1-C34/Kappa) -> 2.8481375 | D35: =D34+(1/D$29)*Rate_r*D34*(1-D34/Kappa) -> 2.17534 | E35: =A35/$D$29 -> 0.096153846 | F35: =Kappa*Users_x0/(Users_x0+(Kappa-Users_x0)*EXP(-Rate_r*E35)) -> 2.1768512
A36: 6 | B36: =B35+(1/B$29)*Rate_r*B35*(1-B35/Kappa) -> 6.5039905 | C36: =C35+(1/C$29)*Rate_r*C35*(1-C35/Kappa) -> 3.0556639 | D36: =D35+(1/D$29)*Rate_r*D35*(1-D35/Kappa) -> 2.2121711 | E36: =A36/$D$29 -> 0.11538462 | F36: =Kappa*Users_x0/(Users_x0+(Kappa-Users_x0)*EXP(-Rate_r*E36)) -> 2.2140139
A37: 7 | B37: =B36+(1/B$29)*Rate_r*B36*(1-B36/Kappa) -> 7.8722091 | C37: =C36+(1/C$29)*Rate_r*C36*(1-C36/Kappa) -> 3.2778359 | D37: =D36+(1/D$29)*Rate_r*D36*(1-D36/Kappa) -> 2.2496117 | E37: =A37/$D$29 -> 0.13461538 | F37: =Kappa*Users_x0/(Users_x0+(Kappa-Users_x0)*EXP(-Rate_r*E37)) -> 2.2517966
A38: 8 | B38: =B37+(1/B$29)*Rate_r*B37*(1-B37/Kappa) -> 9.5040199 | C38: =C37+(1/C$29)*Rate_r*C37*(1-C37/Kappa) -> 3.5156154 | D38: =D37+(1/D$29)*Rate_r*D37*(1-D37/Kappa) -> 2.2876714 | E38: =A38/$D$29 -> 0.15384615 | F38: =Kappa*Users_x0/(Users_x0+(Kappa-Users_x0)*EXP(-Rate_r*E38)) -> 2.2902088
A39: 9 | B39: =B38+(1/B$29)*Rate_r*B38*(1-B38/Kappa) -> 11.43919 | C39: =C38+(1/C$29)*Rate_r*C38*(1-C38/Kappa) -> 3.7700169 | D39: =D38+(1/D$29)*Rate_r*D38*(1-D38/Kappa) -> 2.3263599 | E39: =A39/$D$29 -> 0.17307692 | F39: =Kappa*Users_x0/(Users_x0+(Kappa-Users_x0)*EXP(-Rate_r*E39)) -> 2.3292608
A40: 10 | B40: =B39+(1/B$29)*Rate_r*B39*(1-B39/Kappa) -> 13.718584 | C40: =C39+(1/C$29)*Rate_r*C39*(1-C39/Kappa) -> 4.0421084 | D40: =D39+(1/D$29)*Rate_r*D39*(1-D39/Kappa) -> 2.3656871 | E40: =A40/$D$29 -> 0.19230769 | F40: =Kappa*Users_x0/(Users_x0+(Kappa-Users_x0)*EXP(-Rate_r*E40)) -> 2.3689625
A41: 11 | B41: =B40+(1/B$29)*Rate_r*B40*(1-B40/Kappa) -> 16.381816 | C41: =C40+(1/C$29)*Rate_r*C40*(1-C40/Kappa) -> 4.3330126 | D41: =D40+(1/D$29)*Rate_r*D40*(1-D40/Kappa) -> 2.4056631 | E41: =A41/$D$29 -> 0.21153846 | F41: =Kappa*Users_x0/(Users_x0+(Kappa-Users_x0)*EXP(-Rate_r*E41)) -> 2.4093241
A42: 12 | B42: =B41+(1/B$29)*Rate_r*B41*(1-B41/Kappa) -> 19.463906 | C42: =C41+(1/C$29)*Rate_r*C41*(1-C41/Kappa) -> 4.6439073 | D42: =D41+(1/D$29)*Rate_r*D41*(1-D41/Kappa) -> 2.4462979 | E42: =A42/$D$29 -> 0.23076923 | F42: =Kappa*Users_x0/(Users_x0+(Kappa-Users_x0)*EXP(-Rate_r*E42)) -> 2.4503563
...

Sheet QuarterlyLaw
A1: The yearly law of Equation 3.2 as quarters: exact discretization (Proposition 7.2(i); AXIOM Lab 1.7, step 1)
A2: Engine values: the continuous law dx/dt = Ac x + Bc u whose yearly sample, investment held level within the year, is Equation 3.2, and its quarterly sample A_q = e^(Ac/4), B_q. The formulas certify them: four quarters reproduce every year end.
A4: Engine values | B4: capability | C4: technology | D4: efficiency
A5: A_q, capability row | B5: 0.97341957 | C5: 0.013838979 | D5: 0
A6: A_q, technology row | B6: 0.027677957 | C6: 0.95958059 | D6: 0
A7: A_q, efficiency row | B7: 0.012900745 | C7: 0.028616191 | D7: 0.94574161
A8: B_q | B8: 0.15454375 | C8: 0.07315616 | D8: -0.0064125042
A9: Ac, capability row | B9: -0.10857671 | C9: 0.057283419 | D9: 0
A10: Ac, technology row | B10: 0.11456684 | C10: -0.16586013 | D10: 0
A11: Ac, efficiency row | B11: 0.052066838 | C11: 0.11978342 | D11: -0.22314355
A12: Bc | B12: 0.62450472 | C12: 0.28978939 | D12: -0.034854766
A14: A_q squared (formula) | B14: capability | C14: technology | D14: efficiency
B15: =B5*B5+C5*B6+D5*B7 -> 0.94792869 | C15: =B5*C5+C5*C6+D5*C7 -> 0.026750748 | D15: =B5*D5+C5*D6+D5*D7 -> 0
B16: =B6*B5+C6*B6+D6*B7 -> 0.053501496 | C16: =B6*C5+C6*C6+D6*C7 -> 0.92117794 | D16: =B6*D5+C6*D6+D6*D7 -> 0
B17: =B7*B5+C7*B6+D7*B7 -> 0.025550646 | C17: =B7*C5+C7*C6+D7*C7 -> 0.054701598 | D17: =B7*D5+C7*D6+D7*D7 -> 0.89442719
A18: A_q to the fourth (formula) | B18: capability | C18: technology | D18: efficiency
B19: =B15*B15+C15*B16+D15*B17 -> 0.9 | C19: =B15*C15+C15*C16+D15*C17 -> 0.05 | D19: =B15*D15+C15*D16+D15*D17 -> 0
B20: =B16*B15+C16*B16+D16*B17 -> 0.1 | C20: =B16*C15+C16*C16+D16*C17 -> 0.85 | D20: =B16*D15+C16*D16+D16*D17 -> 0
B21: =B17*B15+C17*B16+D17*B17 -> 0.05 | C21: =B17*C15+C17*C16+D17*C17 -> 0.1 | D21: =B17*D15+C17*D16+D17*D17 -> 0.8
A22: |A_q^4 - A| | B22: capability | C22: technology | D22: efficiency
B23: =ABS(B19-Declarations!$B$20) -> 0 | C23: =ABS(C19-Declarations!$C$20) -> 0 | D23: =ABS(D19-Declarations!$D$20) -> 0
B24: =ABS(B20-Declarations!$B$21) -> 0 | C24: =ABS(C20-Declarations!$C$21) -> 0 | D24: =ABS(D20-Declarations!$D$21) -> 0
B25: =ABS(B21-Declarations!$B$22) -> 0 | C25: =ABS(C21-Declarations!$C$22) -> 0 | D25: =ABS(D21-Declarations!$D$22) -> 0
A26: Largest |A_q^4 - A| | B26: =MAX(B23:D25) -> 0
A29: Quarter | B29: Quarterly law: capability | C29: technology | D29: efficiency | E29: Simple steps: capability | F29: technology | G29: efficiency | H29: Year | I29: Yearly law: capability | J29: technology | K29: efficiency | L29: Gap at the year end
A30: 0 | B30: =Declarations!$B$24 -> 50 | C30: =Declarations!$C$24 -> 40 | D30: =Declarations!$D$24 -> 60 | E30: =Declarations!$B$24 -> 50 | F30: =Declarations!$C$24 -> 40 | G30: =Declarations!$D$24 -> 60 | H30: 0 | I30: =Declarations!$B$24 -> 50 | J30: =Declarations!$C$24 -> 40 | K30: =Declarations!$D$24 -> 60 | L30: =MAX(ABS(I30-B30),ABS(J30-C30),ABS(K30-D30)) -> 0
A31: 1 | B31: =B$5*B30+C$5*C30+D$5*D30+B$8*U_held -> 50.460887 | C31: =B$6*B30+C$6*C30+D$6*D30+C$8*U_held -> 40.352371 | D31: =B$7*B30+C$7*C30+D$7*D30+D$8*U_held -> 58.482881 | E31: =E30+0.25*(B$9*E30+C$9*F30+D$9*G30+B$12*U_held) -> 50.464635 | F31: =F30+0.25*(B$10*E30+C$10*F30+D$10*G30+C$12*U_held) -> 40.353063 | G31: =G30+0.25*(B$11*E30+C$11*F30+D$11*G30+D$12*U_held) -> 58.431807 | H31: 1 | I31: =Declarations!$B$20*I30+Declarations!$C$20*J30+Declarations!$D$20*K30+Declarations!$B$23*U_held -> 51.8 | J31: =Declarations!$B$21*I30+Declarations!$C$21*J30+Declarations!$D$21*K30+Declarations!$C$23*U_held -> 41.4 | K31: =Declarations!$B$22*I30+Declarations!$C$22*J30+Declarations!$D$22*K30+Declarations!$D$23*U_held -> 54.5 | L31: =MAX(ABS(I31-B34),ABS(J31-C34),ABS(K31-D34)) -> 0
A32: 2 | B32: =B$5*B31+C$5*C31+D$5*D31+B$8*U_held -> 50.914401 | C32: =B$6*B31+C$6*C31+D$6*D31+C$8*U_held -> 40.703255 | D32: =B$7*B31+C$7*C31+D$7*D31+D$8*U_held -> 57.064108 | E32: =E31+0.25*(B$9*E31+C$9*F31+D$9*G31+B$12*U_held) -> 50.921713 | F32: =F31+0.25*(B$10*E31+C$10*F31+D$10*G31+C$12*U_held) -> 40.704794 | G32: =G31+0.25*(B$11*E31+C$11*F31+D$11*G31+D$12*U_held) -> 56.967718 | H32: 2 | I32: =Declarations!$B$20*I31+Declarations!$C$20*J31+Declarations!$D$20*K31+Declarations!$B$23*U_held -> 53.49 | J32: =Declarations!$B$21*I31+Declarations!$C$21*J31+Declarations!$D$21*K31+Declarations!$C$23*U_held -> 42.77 | K32: =Declarations!$B$22*I31+Declarations!$C$22*J31+Declarations!$D$22*K31+Declarations!$D$23*U_held -> 50.33 | L32: =MAX(ABS(I32-B38),ABS(J32-C38),ABS(K32-D38)) -> 0
A33: 3 | B33: =B$5*B32+C$5*C32+D$5*D32+B$8*U_held -> 51.360715 | C33: =B$6*B32+C$6*C32+D$6*D32+C$8*U_held -> 41.052509 | D33: =B$7*B32+C$7*C32+D$7*D32+D$8*U_held -> 55.738208 | E33: =E32+0.25*(B$9*E32+C$9*F32+D$9*G32+B$12*U_held) -> 51.371422 | F33: =F32+0.25*(B$10*E32+C$10*F32+D$10*G32+C$12*U_held) -> 41.055032 | G33: =G32+0.25*(B$11*E32+C$11*F32+D$11*G32+D$12*U_held) -> 55.601786 | H33: 3 | I33: =Declarations!$B$20*I32+Declarations!$C$20*J32+Declarations!$D$20*K32+Declarations!$B$23*U_held -> 55.0795 | J33: =Declarations!$B$21*I32+Declarations!$C$21*J32+Declarations!$D$21*K32+Declarations!$C$23*U_held -> 44.1035 | K33: =Declarations!$B$22*I32+Declarations!$C$22*J32+Declarations!$D$22*K32+Declarations!$D$23*U_held -> 47.2155 | L33: =MAX(ABS(I33-B42),ABS(J33-C42),ABS(K33-D42)) -> 0
A34: 4 | B34: =B$5*B33+C$5*C33+D$5*D33+B$8*U_held -> 51.8 | C34: =B$6*B33+C$6*C33+D$6*D33+C$8*U_held -> 41.4 | D34: =B$7*B33+C$7*C33+D$7*D33+D$8*U_held -> 54.5 | E34: =E33+0.25*(B$9*E33+C$9*F33+D$9*G33+B$12*U_held) -> 51.81394 | F34: =F33+0.25*(B$10*E33+C$10*F33+D$10*G33+C$12*U_held) -> 41.403628 | G34: =G33+0.25*(B$11*E33+C$11*F33+D$11*G33+D$12*U_held) -> 54.328397 | H34: 4 | I34: =Declarations!$B$20*I33+Declarations!$C$20*J33+Declarations!$D$20*K33+Declarations!$B$23*U_held -> 56.576725 | J34: =Declarations!$B$21*I33+Declarations!$C$21*J33+Declarations!$D$21*K33+Declarations!$C$23*U_held -> 45.395925 | K34: =Declarations!$B$22*I33+Declarations!$C$22*J33+Declarations!$D$22*K33+Declarations!$D$23*U_held -> 44.936725 | L34: =MAX(ABS(I34-B46),ABS(J34-C46),ABS(K34-D46)) -> 0
A35: 5 | B35: =B$5*B34+C$5*C34+D$5*D34+B$8*U_held -> 52.232417 | C35: =B$6*B34+C$6*C34+D$6*D34+C$8*U_held -> 41.745604 | D35: =B$7*B34+C$7*C34+D$7*D34+D$8*U_held -> 53.344587 | E35: =E34+0.25*(B$9*E34+C$9*F34+D$9*G34+B$12*U_held) -> 52.249438 | F35: =F34+0.25*(B$10*E34+C$10*F34+D$10*G34+C$12*U_held) -> 41.750444 | G35: =G34+0.25*(B$11*E34+C$11*F34+D$11*G34+D$12*U_held) -> 53.142243 | H35: 5 | I35: =Declarations!$B$20*I34+Declarations!$C$20*J34+Declarations!$D$20*K34+Declarations!$B$23*U_held -> 57.988849 | J35: =Declarations!$B$21*I34+Declarations!$C$21*J34+Declarations!$D$21*K34+Declarations!$C$23*U_held -> 46.644209 | K35: =Declarations!$B$22*I34+Declarations!$C$22*J34+Declarations!$D$22*K34+Declarations!$D$23*U_held -> 43.317809 | L35: =MAX(ABS(I35-B50),ABS(J35-C50),ABS(K35-D50)) -> 0
A36: 6 | B36: =B$5*B35+C$5*C35+D$5*D35+B$8*U_held -> 52.658123 | C36: =B$6*B35+C$6*C35+D$6*D35+C$8*U_held -> 42.089207 | D36: =B$7*B35+C$7*C35+D$7*D35+D$8*U_held -> 52.267332 | E36: =E35+0.25*(B$9*E35+C$9*F35+D$9*G35+B$12*U_held) -> 52.678081 | F36: =F35+0.25*(B$10*E35+C$10*F35+D$10*G35+C$12*U_held) -> 42.095352 | G36: =G35+0.25*(B$11*E35+C$11*F35+D$11*G35+D$12*U_held) -> 52.038315 | H36: 6 | I36: =Declarations!$B$20*I35+Declarations!$C$20*J35+Declarations!$D$20*K35+Declarations!$B$23*U_held -> 59.322174 | J36: =Declarations!$B$21*I35+Declarations!$C$21*J35+Declarations!$D$21*K35+Declarations!$C$23*U_held -> 47.846462 | K36: =Declarations!$B$22*I35+Declarations!$C$22*J35+Declarations!$D$22*K35+Declarations!$D$23*U_held -> 42.21811 | L36: =MAX(ABS(I36-B54),ABS(J36-C54),ABS(K36-D54)) -> 0
A37: 7 | B37: =B$5*B36+C$5*C36+D$5*D36+B$8*U_held -> 53.077269 | C37: =B$6*B36+C$6*C36+D$6*D36+C$8*U_held -> 42.430704 | D37: =B$7*B36+C$7*C36+D$7*D36+D$8*U_held -> 51.263853 | E37: =E36+0.25*(B$9*E36+C$9*F36+D$9*G36+B$12*U_held) -> 53.100029 | F37: =F36+0.25*(B$10*E36+C$10*F36+D$10*G36+C$12*U_held) -> 42.438236 | G37: =G36+0.25*(B$11*E36+C$11*F36+D$11*G36+D$12*U_held) -> 51.011879 | H37: 7 | I37: =Declarations!$B$20*I36+Declarations!$C$20*J36+Declarations!$D$20*K36+Declarations!$B$23*U_held -> 60.58228 | J37: =Declarations!$B$21*I36+Declarations!$C$21*J36+Declarations!$D$21*K36+Declarations!$C$23*U_held -> 49.00171 | K37: =Declarations!$B$22*I36+Declarations!$C$22*J36+Declarations!$D$22*K36+Declarations!$D$23*U_held -> 41.525243 | L37: =MAX(ABS(I37-B58),ABS(J37-C58),ABS(K37-D58)) -> 0
A38: 8 | B38: =B$5*B37+C$5*C37+D$5*D37+B$8*U_held -> 53.49 | C38: =B$6*B37+C$6*C37+D$6*D37+C$8*U_held -> 42.77 | D38: =B$7*B37+C$7*C37+D$7*D37+D$8*U_held -> 50.33 | E38: =E37+0.25*(B$9*E37+C$9*F37+D$9*G37+B$12*U_held) -> 53.515433 | F38: =F37+0.25*(B$10*E37+C$10*F37+D$10*G37+C$12*U_held) -> 42.778988 | G38: =G37+0.25*(B$11*E37+C$11*F37+D$11*G37+D$12*U_held) -> 50.058463 | H38: 8 | I38: =Declarations!$B$20*I37+Declarations!$C$20*J37+Declarations!$D$20*K37+Declarations!$B$23*U_held -> 61.774138 | J38: =Declarations!$B$21*I37+Declarations!$C$21*J37+Declarations!$D$21*K37+Declarations!$C$23*U_held -> 50.109682 | K38: =Declarations!$B$22*I37+Declarations!$C$22*J37+Declarations!$D$22*K37+Declarations!$D$23*U_held -> 41.14948 | L38: =MAX(ABS(I38-B62),ABS(J38-C62),ABS(K38-D62)) -> 0
A39: 9 | B39: =B$5*B38+C$5*C38+D$5*D38+B$8*U_held -> 53.896456 | C39: =B$6*B38+C$6*C38+D$6*D38+C$8*U_held -> 43.107005 | D39: =B$7*B38+C$7*C38+D$7*D38+D$8*U_held -> 49.46185 | E39: =E38+0.25*(B$9*E38+C$9*F38+D$9*G38+B$12*U_held) -> 53.924442 | F39: =F38+0.25*(B$10*E38+C$10*F38+D$10*G38+C$12*U_held) -> 43.117508 | G39: =G38+0.25*(B$11*E38+C$11*F38+D$11*G38+D$12*U_held) -> 49.173846 | H39: 9 | I39: =Declarations!$B$20*I38+Declarations!$C$20*J38+Declarations!$D$20*K38+Declarations!$B$23*U_held -> 62.902208 | J39: =Declarations!$B$21*I38+Declarations!$C$21*J38+Declarations!$D$21*K38+Declarations!$C$23*U_held -> 51.170643 | K39: =Declarations!$B$22*I38+Declarations!$C$22*J38+Declarations!$D$22*K38+Declarations!$D$23*U_held -> 41.019259 | L39: =MAX(ABS(I39-B66),ABS(J39-C66),ABS(K39-D66)) -> 0
A40: 10 | B40: =B$5*B39+C$5*C39+D$5*D39+B$8*U_held -> 54.296771 | C40: =B$6*B39+C$6*C39+D$6*D39+C$8*U_held -> 43.441638 | D40: =B$7*B39+C$7*C39+D$7*D39+D$8*U_held -> 48.655693 | E40: =E39+0.25*(B$9*E39+C$9*F39+D$9*G39+B$12*U_held) -> 54.327196 | F40: =F39+0.25*(B$10*E39+C$10*F39+D$10*G39+C$12*U_held) -> 43.453706 | G40: =G39+0.25*(B$11*E39+C$11*F39+D$11*G39+D$12*U_held) -> 48.354039 | H40: 10 | I40: =Declarations!$B$20*I39+Declarations!$C$20*J39+Declarations!$D$20*K39+Declarations!$B$23*U_held -> 63.970519 | J40: =Declarations!$B$21*I39+Declarations!$C$21*J39+Declarations!$D$21*K39+Declarations!$C$23*U_held -> 52.185268 | K40: =Declarations!$B$22*I39+Declarations!$C$22*J39+Declarations!$D$22*K39+Declarations!$D$23*U_held -> 41.077582 | L40: =MAX(ABS(I40-B70),ABS(J40-C70),ABS(K40-D70)) -> 0
A41: 11 | B41: =B$5*B40+C$5*C40+D$5*D40+B$8*U_held -> 54.691078 | C41: =B$6*B40+C$6*C40+D$6*D40+C$8*U_held -> 43.773826 | D41: =B$7*B40+C$7*C40+D$7*D40+D$8*U_held -> 47.908016 | E41: =E40+0.25*(B$9*E40+C$9*F40+D$9*G40+B$12*U_held) -> 54.723833 | F41: =F40+0.25*(B$10*E40+C$10*F40+D$10*G40+C$12*U_held) -> 43.787499 | G41: =G40+0.25*(B$11*E40+C$11*F40+D$11*G40+D$12*U_held) -> 47.595276
A42: 12 | B42: =B$5*B41+C$5*C41+D$5*D41+B$8*U_held -> 55.0795 | C42: =B$6*B41+C$6*C41+D$6*D41+C$8*U_held -> 44.1035 | D42: =B$7*B41+C$7*C41+D$7*D41+D$8*U_held -> 47.2155 | E42: =E41+0.25*(B$9*E41+C$9*F41+D$9*G41+B$12*U_held) -> 55.114483 | F42: =F41+0.25*(B$10*E41+C$10*F41+D$10*G41+C$12*U_held) -> 44.118812 | G42: =G41+0.25*(B$11*E41+C$11*F41+D$11*G41+D$12*U_held) -> 46.894
A43: 13 | B43: =B$5*B42+C$5*C42+D$5*D42+B$8*U_held -> 55.46216 | C43: =B$6*B42+C$6*C42+D$6*D42+C$8*U_held -> 44.4306 | D43: =B$7*B42+C$7*C42+D$7*D42+D$8*U_held -> 46.575004 | E43: =E42+0.25*(B$9*E42+C$9*F42+D$9*G42+B$12*U_held) -> 55.499274 | F43: =F42+0.25*(B$10*E42+C$10*F42+D$10*G42+C$12*U_held) -> 44.447576 | G43: =G42+0.25*(B$11*E42+C$11*F42+D$11*G42+D$12*U_held) -> 46.246852 | H43: Largest gap at the ten year ends | L43: =MAX(L30:L40) -> 0
A44: 14 | B44: =B$5*B43+C$5*C43+D$5*D43+B$8*U_held -> 55.839176 | C44: =B$6*B43+C$6*C43+D$6*D43+C$8*U_held -> 44.75507 | D44: =B$7*B43+C$7*C43+D$7*D43+D$8*U_held -> 45.983557 | E44: =E43+0.25*(B$9*E43+C$9*F43+D$9*G43+B$12*U_held) -> 55.878329 | F44: =F43+0.25*(B$10*E43+C$10*F43+D$10*G43+C$12*U_held) -> 44.773728 | G44: =G43+0.25*(B$11*E43+C$11*F43+D$11*G43+D$12*U_held) -> 45.650659 | H44: Simple steps after ten years, largest gap to the law | L44: =MAX(ABS(E70-I40),ABS(F70-J40),ABS(G70-K40)) -> 0.1791407
...

Sheet Superposition
A1: Split the path: momentum plus program for the three-reading company (Theorem 7.2(i); Figure 7.1; AXIOM Lab 1.7, step 2)
A2: Free response: A^k x0 (momentum alone). Forced response: from zero under the held investment (what the program adds). Path: the company simply run forward. Equation 7.4: path = free + forced.
N3: Figure 7.1 and Section 3.4 | O3: Value | P3: Reading
N4: Technology at year 10: momentum alone | O4: =C16 -> 27.225229 | P4: erodes from 40 to 27
A5: Year | B5: Momentum: capability | C5: technology | D5: efficiency | E5: Program: capability | F5: technology | G5: efficiency | H5: Path: capability | I5: technology | J5: efficiency | K5: |path - (momentum + program)| | L5: Program ahead (technology) | N5: Technology at year 10: program effect | O5: =F16 -> 24.960038 | P5: the program adds 25
A6: 0 | B6: =Declarations!$B$24 -> 50 | C6: =Declarations!$C$24 -> 40 | D6: =Declarations!$D$24 -> 60 | E6: =0 -> 0 | F6: =0 -> 0 | G6: =0 -> 0 | H6: =Declarations!$B$24 -> 50 | I6: =Declarations!$C$24 -> 40 | J6: =Declarations!$D$24 -> 60 | K6: =MAX(ABS(H6-B6-E6),ABS(I6-C6-F6),ABS(J6-D6-G6)) -> 0 | L6: =IF(F6>C6,A6,99) -> 99 | N6: Technology at year 10: path | O6: =I16 -> 52.185268 | P6: the company ends at 52
A7: 1 | B7: =Declarations!$B$20*B6+Declarations!$C$20*C6+Declarations!$D$20*D6 -> 47 | C7: =Declarations!$B$21*B6+Declarations!$C$21*C6+Declarations!$D$21*D6 -> 39 | D7: =Declarations!$B$22*B6+Declarations!$C$22*C6+Declarations!$D$22*D6 -> 54.5 | E7: =Declarations!$B$20*E6+Declarations!$C$20*F6+Declarations!$D$20*G6+Declarations!$B$23*U_held -> 4.8 | F7: =Declarations!$B$21*E6+Declarations!$C$21*F6+Declarations!$D$21*G6+Declarations!$C$23*U_held -> 2.4 | G7: =Declarations!$B$22*E6+Declarations!$C$22*F6+Declarations!$D$22*G6+Declarations!$D$23*U_held -> 0 | H7: =Declarations!$B$20*H6+Declarations!$C$20*I6+Declarations!$D$20*J6+Declarations!$B$23*U_held -> 51.8 | I7: =Declarations!$B$21*H6+Declarations!$C$21*I6+Declarations!$D$21*J6+Declarations!$C$23*U_held -> 41.4 | J7: =Declarations!$B$22*H6+Declarations!$C$22*I6+Declarations!$D$22*J6+Declarations!$D$23*U_held -> 54.5 | K7: =MAX(ABS(H7-B7-E7),ABS(I7-C7-F7),ABS(J7-D7-G7)) -> 0 | L7: =IF(F7>C7,A7,99) -> 99 | N7: Technology at year 20: momentum alone | O7: =C26 -> 16.652482
A8: 2 | B8: =Declarations!$B$20*B7+Declarations!$C$20*C7+Declarations!$D$20*D7 -> 44.25 | C8: =Declarations!$B$21*B7+Declarations!$C$21*C7+Declarations!$D$21*D7 -> 37.85 | D8: =Declarations!$B$22*B7+Declarations!$C$22*C7+Declarations!$D$22*D7 -> 49.85 | E8: =Declarations!$B$20*E7+Declarations!$C$20*F7+Declarations!$D$20*G7+Declarations!$B$23*U_held -> 9.24 | F8: =Declarations!$B$21*E7+Declarations!$C$21*F7+Declarations!$D$21*G7+Declarations!$C$23*U_held -> 4.92 | G8: =Declarations!$B$22*E7+Declarations!$C$22*F7+Declarations!$D$22*G7+Declarations!$D$23*U_held -> 0.48 | H8: =Declarations!$B$20*H7+Declarations!$C$20*I7+Declarations!$D$20*J7+Declarations!$B$23*U_held -> 53.49 | I8: =Declarations!$B$21*H7+Declarations!$C$21*I7+Declarations!$D$21*J7+Declarations!$C$23*U_held -> 42.77 | J8: =Declarations!$B$22*H7+Declarations!$C$22*I7+Declarations!$D$22*J7+Declarations!$D$23*U_held -> 50.33 | K8: =MAX(ABS(H8-B8-E8),ABS(I8-C8-F8),ABS(J8-D8-G8)) -> 3.1086245e-15 | L8: =IF(F8>C8,A8,99) -> 99 | N8: Technology at year 20: program effect | O8: =F26 -> 43.41336
A9: 3 | B9: =Declarations!$B$20*B8+Declarations!$C$20*C8+Declarations!$D$20*D8 -> 41.7175 | C9: =Declarations!$B$21*B8+Declarations!$C$21*C8+Declarations!$D$21*D8 -> 36.5975 | D9: =Declarations!$B$22*B8+Declarations!$C$22*C8+Declarations!$D$22*D8 -> 45.8775 | E9: =Declarations!$B$20*E8+Declarations!$C$20*F8+Declarations!$D$20*G8+Declarations!$B$23*U_held -> 13.362 | F9: =Declarations!$B$21*E8+Declarations!$C$21*F8+Declarations!$D$21*G8+Declarations!$C$23*U_held -> 7.506 | G9: =Declarations!$B$22*E8+Declarations!$C$22*F8+Declarations!$D$22*G8+Declarations!$D$23*U_held -> 1.338 | H9: =Declarations!$B$20*H8+Declarations!$C$20*I8+Declarations!$D$20*J8+Declarations!$B$23*U_held -> 55.0795 | I9: =Declarations!$B$21*H8+Declarations!$C$21*I8+Declarations!$D$21*J8+Declarations!$C$23*U_held -> 44.1035 | J9: =Declarations!$B$22*H8+Declarations!$C$22*I8+Declarations!$D$22*J8+Declarations!$D$23*U_held -> 47.2155 | K9: =MAX(ABS(H9-B9-E9),ABS(I9-C9-F9),ABS(J9-D9-G9)) -> 0 | L9: =IF(F9>C9,A9,99) -> 99 | N9: Technology at year 20: path | O9: =I26 -> 60.065842 | P9: approaching the steady state, 72
A10: 4 | B10: =Declarations!$B$20*B9+Declarations!$C$20*C9+Declarations!$D$20*D9 -> 39.375625 | C10: =Declarations!$B$21*B9+Declarations!$C$21*C9+Declarations!$D$21*D9 -> 35.279625 | D10: =Declarations!$B$22*B9+Declarations!$C$22*C9+Declarations!$D$22*D9 -> 42.447625 | E10: =Declarations!$B$20*E9+Declarations!$C$20*F9+Declarations!$D$20*G9+Declarations!$B$23*U_held -> 17.2011 | F10: =Declarations!$B$21*E9+Declarations!$C$21*F9+Declarations!$D$21*G9+Declarations!$C$23*U_held -> 10.1163 | G10: =Declarations!$B$22*E9+Declarations!$C$22*F9+Declarations!$D$22*G9+Declarations!$D$23*U_held -> 2.4891 | H10: =Declarations!$B$20*H9+Declarations!$C$20*I9+Declarations!$D$20*J9+Declarations!$B$23*U_held -> 56.576725 | I10: =Declarations!$B$21*H9+Declarations!$C$21*I9+Declarations!$D$21*J9+Declarations!$C$23*U_held -> 45.395925 | J10: =Declarations!$B$22*H9+Declarations!$C$22*I9+Declarations!$D$22*J9+Declarations!$D$23*U_held -> 44.936725 | K10: =MAX(ABS(H10-B10-E10),ABS(I10-C10-F10),ABS(J10-D10-G10)) -> 0 | L10: =IF(F10>C10,A10,99) -> 99 | N10: Largest |path - (momentum + program)| | O10: =MAX(K6:K26) -> 3.1086245e-15 | P10: exact in the linear regime
A11: 5 | B11: =Declarations!$B$20*B10+Declarations!$C$20*C10+Declarations!$D$20*D10 -> 37.202044 | C11: =Declarations!$B$21*B10+Declarations!$C$21*C10+Declarations!$D$21*D10 -> 33.925244 | D11: =Declarations!$B$22*B10+Declarations!$C$22*C10+Declarations!$D$22*D10 -> 39.454844 | E11: =Declarations!$B$20*E10+Declarations!$C$20*F10+Declarations!$D$20*G10+Declarations!$B$23*U_held -> 20.786805 | F11: =Declarations!$B$21*E10+Declarations!$C$21*F10+Declarations!$D$21*G10+Declarations!$C$23*U_held -> 12.718965 | G11: =Declarations!$B$22*E10+Declarations!$C$22*F10+Declarations!$D$22*G10+Declarations!$D$23*U_held -> 3.862965 | H11: =Declarations!$B$20*H10+Declarations!$C$20*I10+Declarations!$D$20*J10+Declarations!$B$23*U_held -> 57.988849 | I11: =Declarations!$B$21*H10+Declarations!$C$21*I10+Declarations!$D$21*J10+Declarations!$C$23*U_held -> 46.644209 | J11: =Declarations!$B$22*H10+Declarations!$C$22*I10+Declarations!$D$22*J10+Declarations!$D$23*U_held -> 43.317809 | K11: =MAX(ABS(H11-B11-E11),ABS(I11-C11-F11),ABS(J11-D11-G11)) -> 0 | L11: =IF(F11>C11,A11,99) -> 99 | N11: First year the program effect exceeds momentum | O11: =MIN(L6:L26) -> 11 | P11: technology
A12: 6 | B12: =Declarations!$B$20*B11+Declarations!$C$20*C11+Declarations!$D$20*D11 -> 35.178102 | C12: =Declarations!$B$21*B11+Declarations!$C$21*C11+Declarations!$D$21*D11 -> 32.556662 | D12: =Declarations!$B$22*B11+Declarations!$C$22*C11+Declarations!$D$22*D11 -> 36.816502 | E12: =Declarations!$B$20*E11+Declarations!$C$20*F11+Declarations!$D$20*G11+Declarations!$B$23*U_held -> 24.144073 | F12: =Declarations!$B$21*E11+Declarations!$C$21*F11+Declarations!$D$21*G11+Declarations!$C$23*U_held -> 15.289801 | G12: =Declarations!$B$22*E11+Declarations!$C$22*F11+Declarations!$D$22*G11+Declarations!$D$23*U_held -> 5.4016088 | H12: =Declarations!$B$20*H11+Declarations!$C$20*I11+Declarations!$D$20*J11+Declarations!$B$23*U_held -> 59.322174 | I12: =Declarations!$B$21*H11+Declarations!$C$21*I11+Declarations!$D$21*J11+Declarations!$C$23*U_held -> 47.846462 | J12: =Declarations!$B$22*H11+Declarations!$C$22*I11+Declarations!$D$22*J11+Declarations!$D$23*U_held -> 42.21811 | K12: =MAX(ABS(H12-B12-E12),ABS(I12-C12-F12),ABS(J12-D12-G12)) -> 0 | L12: =IF(F12>C12,A12,99) -> 99
A13: 7 | B13: =Declarations!$B$20*B12+Declarations!$C$20*C12+Declarations!$D$20*D12 -> 33.288124 | C13: =Declarations!$B$21*B12+Declarations!$C$21*C12+Declarations!$D$21*D12 -> 31.190972 | D13: =Declarations!$B$22*B12+Declarations!$C$22*C12+Declarations!$D$22*D12 -> 34.467772 | E13: =Declarations!$B$20*E12+Declarations!$C$20*F12+Declarations!$D$20*G12+Declarations!$B$23*U_held -> 27.294156 | F13: =Declarations!$B$21*E12+Declarations!$C$21*F12+Declarations!$D$21*G12+Declarations!$C$23*U_held -> 17.810738 | G13: =Declarations!$B$22*E12+Declarations!$C$22*F12+Declarations!$D$22*G12+Declarations!$D$23*U_held -> 7.0574707 | H13: =Declarations!$B$20*H12+Declarations!$C$20*I12+Declarations!$D$20*J12+Declarations!$B$23*U_held -> 60.58228 | I13: =Declarations!$B$21*H12+Declarations!$C$21*I12+Declarations!$D$21*J12+Declarations!$C$23*U_held -> 49.00171 | J13: =Declarations!$B$22*H12+Declarations!$C$22*I12+Declarations!$D$22*J12+Declarations!$D$23*U_held -> 41.525243 | K13: =MAX(ABS(H13-B13-E13),ABS(I13-C13-F13),ABS(J13-D13-G13)) -> 0 | L13: =IF(F13>C13,A13,99) -> 99 | N13: Section 3.4: capability a year after u = 10 | O13: =Declarations!$B$20*Declarations!$B$24+Declarations!$C$20*Declarations!$C$24+Declarations!$D$20*Declarations!$D$24+Declarations!$B$23*U_ch3 -> 53 | P13: 53.0
A14: 8 | B14: =Declarations!$B$20*B13+Declarations!$C$20*C13+Declarations!$D$20*D13 -> 31.518861 | C14: =Declarations!$B$21*B13+Declarations!$C$21*C13+Declarations!$D$21*D13 -> 29.841139 | D14: =Declarations!$B$22*B13+Declarations!$C$22*C13+Declarations!$D$22*D13 -> 32.357721 | E14: =Declarations!$B$20*E13+Declarations!$C$20*F13+Declarations!$D$20*G13+Declarations!$B$23*U_held -> 30.255277 | F14: =Declarations!$B$21*E13+Declarations!$C$21*F13+Declarations!$D$21*G13+Declarations!$C$23*U_held -> 20.268543 | G14: =Declarations!$B$22*E13+Declarations!$C$22*F13+Declarations!$D$22*G13+Declarations!$D$23*U_held -> 8.7917581 | H14: =Declarations!$B$20*H13+Declarations!$C$20*I13+Declarations!$D$20*J13+Declarations!$B$23*U_held -> 61.774138 | I14: =Declarations!$B$21*H13+Declarations!$C$21*I13+Declarations!$D$21*J13+Declarations!$C$23*U_held -> 50.109682 | J14: =Declarations!$B$22*H13+Declarations!$C$22*I13+Declarations!$D$22*J13+Declarations!$D$23*U_held -> 41.14948 | K14: =MAX(ABS(H14-B14-E14),ABS(I14-C14-F14),ABS(J14-D14-G14)) -> 0 | L14: =IF(F14>C14,A14,99) -> 99 | N14: Section 3.4: technology a year after u = 10 | O14: =Declarations!$B$21*Declarations!$B$24+Declarations!$C$21*Declarations!$C$24+Declarations!$D$21*Declarations!$D$24+Declarations!$C$23*U_ch3 -> 42 | P14: 42.0
A15: 9 | B15: =Declarations!$B$20*B14+Declarations!$C$20*C14+Declarations!$D$20*D14 -> 29.859032 | C15: =Declarations!$B$21*B14+Declarations!$C$21*C14+Declarations!$D$21*D14 -> 28.516854 | D15: =Declarations!$B$22*B14+Declarations!$C$22*C14+Declarations!$D$22*D14 -> 30.446234 | E15: =Declarations!$B$20*E14+Declarations!$C$20*F14+Declarations!$D$20*G14+Declarations!$B$23*U_held -> 33.043176 | F15: =Declarations!$B$21*E14+Declarations!$C$21*F14+Declarations!$D$21*G14+Declarations!$C$23*U_held -> 22.653789 | G15: =Declarations!$B$22*E14+Declarations!$C$22*F14+Declarations!$D$22*G14+Declarations!$D$23*U_held -> 10.573025 | H15: =Declarations!$B$20*H14+Declarations!$C$20*I14+Declarations!$D$20*J14+Declarations!$B$23*U_held -> 62.902208 | I15: =Declarations!$B$21*H14+Declarations!$C$21*I14+Declarations!$D$21*J14+Declarations!$C$23*U_held -> 51.170643 | J15: =Declarations!$B$22*H14+Declarations!$C$22*I14+Declarations!$D$22*J14+Declarations!$D$23*U_held -> 41.019259 | K15: =MAX(ABS(H15-B15-E15),ABS(I15-C15-F15),ABS(J15-D15-G15)) -> 0 | L15: =IF(F15>C15,A15,99) -> 99 | N15: Section 3.4: efficiency a year after u = 10 | O15: =Declarations!$B$22*Declarations!$B$24+Declarations!$C$22*Declarations!$C$24+Declarations!$D$22*Declarations!$D$24+Declarations!$D$23*U_ch3 -> 54.5 | P15: 54.5
A16: 10 | B16: =Declarations!$B$20*B15+Declarations!$C$20*C15+Declarations!$D$20*D15 -> 28.298971 | C16: =Declarations!$B$21*B15+Declarations!$C$21*C15+Declarations!$D$21*D15 -> 27.225229 | D16: =Declarations!$B$22*B15+Declarations!$C$22*C15+Declarations!$D$22*D15 -> 28.701624 | E16: =Declarations!$B$20*E15+Declarations!$C$20*F15+Declarations!$D$20*G15+Declarations!$B$23*U_held -> 35.671548 | F16: =Declarations!$B$21*E15+Declarations!$C$21*F15+Declarations!$D$21*G15+Declarations!$C$23*U_held -> 24.960038 | G16: =Declarations!$B$22*E15+Declarations!$C$22*F15+Declarations!$D$22*G15+Declarations!$D$23*U_held -> 12.375957 | H16: =Declarations!$B$20*H15+Declarations!$C$20*I15+Declarations!$D$20*J15+Declarations!$B$23*U_held -> 63.970519 | I16: =Declarations!$B$21*H15+Declarations!$C$21*I15+Declarations!$D$21*J15+Declarations!$C$23*U_held -> 52.185268 | J16: =Declarations!$B$22*H15+Declarations!$C$22*I15+Declarations!$D$22*J15+Declarations!$D$23*U_held -> 41.077582 | K16: =MAX(ABS(H16-B16-E16),ABS(I16-C16-F16),ABS(J16-D16-G16)) -> 0 | L16: =IF(F16>C16,A16,99) -> 99
A17: 11 | B17: =Declarations!$B$20*B16+Declarations!$C$20*C16+Declarations!$D$20*D16 -> 26.830335 | C17: =Declarations!$B$21*B16+Declarations!$C$21*C16+Declarations!$D$21*D16 -> 25.971342 | D17: =Declarations!$B$22*B16+Declarations!$C$22*C16+Declarations!$D$22*D16 -> 27.098771 | E17: =Declarations!$B$20*E16+Declarations!$C$20*F16+Declarations!$D$20*G16+Declarations!$B$23*U_held -> 38.152395 | F17: =Declarations!$B$21*E16+Declarations!$C$21*F16+Declarations!$D$21*G16+Declarations!$C$23*U_held -> 27.183187 | G17: =Declarations!$B$22*E16+Declarations!$C$22*F16+Declarations!$D$22*G16+Declarations!$D$23*U_held -> 14.180347 | H17: =Declarations!$B$20*H16+Declarations!$C$20*I16+Declarations!$D$20*J16+Declarations!$B$23*U_held -> 64.982731 | I17: =Declarations!$B$21*H16+Declarations!$C$21*I16+Declarations!$D$21*J16+Declarations!$C$23*U_held -> 53.154529 | J17: =Declarations!$B$22*H16+Declarations!$C$22*I16+Declarations!$D$22*J16+Declarations!$D$23*U_held -> 41.279118 | K17: =MAX(ABS(H17-B17-E17),ABS(I17-C17-F17),ABS(J17-D17-G17)) -> 0 | L17: =IF(F17>C17,A17,99) -> 11
A18: 12 | B18: =Declarations!$B$20*B17+Declarations!$C$20*C17+Declarations!$D$20*D17 -> 25.445869 | C18: =Declarations!$B$21*B17+Declarations!$C$21*C17+Declarations!$D$21*D17 -> 24.758674 | D18: =Declarations!$B$22*B17+Declarations!$C$22*C17+Declarations!$D$22*D17 -> 25.617668 | E18: =Declarations!$B$20*E17+Declarations!$C$20*F17+Declarations!$D$20*G17+Declarations!$B$23*U_held -> 40.496315 | F18: =Declarations!$B$21*E17+Declarations!$C$21*F17+Declarations!$D$21*G17+Declarations!$C$23*U_held -> 29.320949 | G18: =Declarations!$B$22*E17+Declarations!$C$22*F17+Declarations!$D$22*G17+Declarations!$D$23*U_held -> 15.970216 | H18: =Declarations!$B$20*H17+Declarations!$C$20*I17+Declarations!$D$20*J17+Declarations!$B$23*U_held -> 65.942184 | I18: =Declarations!$B$21*H17+Declarations!$C$21*I17+Declarations!$D$21*J17+Declarations!$C$23*U_held -> 54.079623 | J18: =Declarations!$B$22*H17+Declarations!$C$22*I17+Declarations!$D$22*J17+Declarations!$D$23*U_held -> 41.587884 | K18: =MAX(ABS(H18-B18-E18),ABS(I18-C18-F18),ABS(J18-D18-G18)) -> 0 | L18: =IF(F18>C18,A18,99) -> 12
A19: 13 | B19: =Declarations!$B$20*B18+Declarations!$C$20*C18+Declarations!$D$20*D18 -> 24.139216 | C19: =Declarations!$B$21*B18+Declarations!$C$21*C18+Declarations!$D$21*D18 -> 23.58946 | D19: =Declarations!$B$22*B18+Declarations!$C$22*C18+Declarations!$D$22*D18 -> 24.242295 | E19: =Declarations!$B$20*E18+Declarations!$C$20*F18+Declarations!$D$20*G18+Declarations!$B$23*U_held -> 42.712731 | F19: =Declarations!$B$21*E18+Declarations!$C$21*F18+Declarations!$D$21*G18+Declarations!$C$23*U_held -> 31.372438 | G19: =Declarations!$B$22*E18+Declarations!$C$22*F18+Declarations!$D$22*G18+Declarations!$D$23*U_held -> 17.733084 | H19: =Declarations!$B$20*H18+Declarations!$C$20*I18+Declarations!$D$20*J18+Declarations!$B$23*U_held -> 66.851947 | I19: =Declarations!$B$21*H18+Declarations!$C$21*I18+Declarations!$D$21*J18+Declarations!$C$23*U_held -> 54.961898 | J19: =Declarations!$B$22*H18+Declarations!$C$22*I18+Declarations!$D$22*J18+Declarations!$D$23*U_held -> 41.975379 | K19: =MAX(ABS(H19-B19-E19),ABS(I19-C19-F19),ABS(J19-D19-G19)) -> 0 | L19: =IF(F19>C19,A19,99) -> 13
A20: 14 | B20: =Declarations!$B$20*B19+Declarations!$C$20*C19+Declarations!$D$20*D19 -> 22.904767 | C20: =Declarations!$B$21*B19+Declarations!$C$21*C19+Declarations!$D$21*D19 -> 22.464963 | D20: =Declarations!$B$22*B19+Declarations!$C$22*C19+Declarations!$D$22*D19 -> 22.959743 | E20: =Declarations!$B$20*E19+Declarations!$C$20*F19+Declarations!$D$20*G19+Declarations!$B$23*U_held -> 44.81008 | F20: =Declarations!$B$21*E19+Declarations!$C$21*F19+Declarations!$D$21*G19+Declarations!$C$23*U_held -> 33.337845 | G20: =Declarations!$B$22*E19+Declarations!$C$22*F19+Declarations!$D$22*G19+Declarations!$D$23*U_held -> 19.459347 | H20: =Declarations!$B$20*H19+Declarations!$C$20*I19+Declarations!$D$20*J19+Declarations!$B$23*U_held -> 67.714847 | I20: =Declarations!$B$21*H19+Declarations!$C$21*I19+Declarations!$D$21*J19+Declarations!$C$23*U_held -> 55.802808 | J20: =Declarations!$B$22*H19+Declarations!$C$22*I19+Declarations!$D$22*J19+Declarations!$D$23*U_held -> 42.41909 | K20: =MAX(ABS(H20-B20-E20),ABS(I20-C20-F20),ABS(J20-D20-G20)) -> 0 | L20: =IF(F20>C20,A20,99) -> 14
A21: 15 | B21: =Declarations!$B$20*B20+Declarations!$C$20*C20+Declarations!$D$20*D20 -> 21.737539 | C21: =Declarations!$B$21*B20+Declarations!$C$21*C20+Declarations!$D$21*D20 -> 21.385695 | D21: =Declarations!$B$22*B20+Declarations!$C$22*C20+Declarations!$D$22*D20 -> 21.759529 | E21: =Declarations!$B$20*E20+Declarations!$C$20*F20+Declarations!$D$20*G20+Declarations!$B$23*U_held -> 46.795964 | F21: =Declarations!$B$21*E20+Declarations!$C$21*F20+Declarations!$D$21*G20+Declarations!$C$23*U_held -> 35.218177 | G21: =Declarations!$B$22*E20+Declarations!$C$22*F20+Declarations!$D$22*G20+Declarations!$D$23*U_held -> 21.141766 | H21: =Declarations!$B$20*H20+Declarations!$C$20*I20+Declarations!$D$20*J20+Declarations!$B$23*U_held -> 68.533503 | I21: =Declarations!$B$21*H20+Declarations!$C$21*I20+Declarations!$D$21*J20+Declarations!$C$23*U_held -> 56.603871 | J21: =Declarations!$B$22*H20+Declarations!$C$22*I20+Declarations!$D$22*J20+Declarations!$D$23*U_held -> 42.901295 | K21: =MAX(ABS(H21-B21-E21),ABS(I21-C21-F21),ABS(J21-D21-G21)) -> 0 | L21: =IF(F21>C21,A21,99) -> 15
A22: 16 | B22: =Declarations!$B$20*B21+Declarations!$C$20*C21+Declarations!$D$20*D21 -> 20.63307 | C22: =Declarations!$B$21*B21+Declarations!$C$21*C21+Declarations!$D$21*D21 -> 20.351595 | D22: =Declarations!$B$22*B21+Declarations!$C$22*C21+Declarations!$D$22*D21 -> 20.63307 | E22: =Declarations!$B$20*E21+Declarations!$C$20*F21+Declarations!$D$20*G21+Declarations!$B$23*U_held -> 48.677277 | F22: =Declarations!$B$21*E21+Declarations!$C$21*F21+Declarations!$D$21*G21+Declarations!$C$23*U_held -> 37.015046 | G22: =Declarations!$B$22*E21+Declarations!$C$22*F21+Declarations!$D$22*G21+Declarations!$D$23*U_held -> 22.775029 | H22: =Declarations!$B$20*H21+Declarations!$C$20*I21+Declarations!$D$20*J21+Declarations!$B$23*U_held -> 69.310346 | I22: =Declarations!$B$21*H21+Declarations!$C$21*I21+Declarations!$D$21*J21+Declarations!$C$23*U_held -> 57.366641 | J22: =Declarations!$B$22*H21+Declarations!$C$22*I21+Declarations!$D$22*J21+Declarations!$D$23*U_held -> 43.408098 | K22: =MAX(ABS(H22-B22-E22),ABS(I22-C22-F22),ABS(J22-D22-G22)) -> 0 | L22: =IF(F22>C22,A22,99) -> 16
A23: 17 | B23: =Declarations!$B$20*B22+Declarations!$C$20*C22+Declarations!$D$20*D22 -> 19.587342 | C23: =Declarations!$B$21*B22+Declarations!$C$21*C22+Declarations!$D$21*D22 -> 19.362162 | D23: =Declarations!$B$22*B22+Declarations!$C$22*C22+Declarations!$D$22*D22 -> 19.573269 | E23: =Declarations!$B$20*E22+Declarations!$C$20*F22+Declarations!$D$20*G22+Declarations!$B$23*U_held -> 50.460301 | F23: =Declarations!$B$21*E22+Declarations!$C$21*F22+Declarations!$D$21*G22+Declarations!$C$23*U_held -> 38.730517 | G23: =Declarations!$B$22*E22+Declarations!$C$22*F22+Declarations!$D$22*G22+Declarations!$D$23*U_held -> 24.355392 | H23: =Declarations!$B$20*H22+Declarations!$C$20*I22+Declarations!$D$20*J22+Declarations!$B$23*U_held -> 70.047643 | I23: =Declarations!$B$21*H22+Declarations!$C$21*I22+Declarations!$D$21*J22+Declarations!$C$23*U_held -> 58.092679 | J23: =Declarations!$B$22*H22+Declarations!$C$22*I22+Declarations!$D$22*J22+Declarations!$D$23*U_held -> 43.92866 | K23: =MAX(ABS(H23-B23-E23),ABS(I23-C23-F23),ABS(J23-D23-G23)) -> 0 | L23: =IF(F23>C23,A23,99) -> 17
A24: 18 | B24: =Declarations!$B$20*B23+Declarations!$C$20*C23+Declarations!$D$20*D23 -> 18.596716 | C24: =Declarations!$B$21*B23+Declarations!$C$21*C23+Declarations!$D$21*D23 -> 18.416572 | D24: =Declarations!$B$22*B23+Declarations!$C$22*C23+Declarations!$D$22*D23 -> 18.574198 | E24: =Declarations!$B$20*E23+Declarations!$C$20*F23+Declarations!$D$20*G23+Declarations!$B$23*U_held -> 52.150797 | F24: =Declarations!$B$21*E23+Declarations!$C$21*F23+Declarations!$D$21*G23+Declarations!$C$23*U_held -> 40.36697 | G24: =Declarations!$B$22*E23+Declarations!$C$22*F23+Declarations!$D$22*G23+Declarations!$D$23*U_held -> 25.88038 | H24: =Declarations!$B$20*H23+Declarations!$C$20*I23+Declarations!$D$20*J23+Declarations!$B$23*U_held -> 70.747513 | I24: =Declarations!$B$21*H23+Declarations!$C$21*I23+Declarations!$D$21*J23+Declarations!$C$23*U_held -> 58.783542 | J24: =Declarations!$B$22*H23+Declarations!$C$22*I23+Declarations!$D$22*J23+Declarations!$D$23*U_held -> 44.454578 | K24: =MAX(ABS(H24-B24-E24),ABS(I24-C24-F24),ABS(J24-D24-G24)) -> 0 | L24: =IF(F24>C24,A24,99) -> 18
A25: 19 | B25: =Declarations!$B$20*B24+Declarations!$C$20*C24+Declarations!$D$20*D24 -> 17.657873 | C25: =Declarations!$B$21*B24+Declarations!$C$21*C24+Declarations!$D$21*D24 -> 17.513758 | D25: =Declarations!$B$22*B24+Declarations!$C$22*C24+Declarations!$D$22*D24 -> 17.630852 | E25: =Declarations!$B$20*E24+Declarations!$C$20*F24+Declarations!$D$20*G24+Declarations!$B$23*U_held -> 53.754066 | F25: =Declarations!$B$21*E24+Declarations!$C$21*F24+Declarations!$D$21*G24+Declarations!$C$23*U_held -> 41.927004 | G25: =Declarations!$B$22*E24+Declarations!$C$22*F24+Declarations!$D$22*G24+Declarations!$D$23*U_held -> 27.348541 | H25: =Declarations!$B$20*H24+Declarations!$C$20*I24+Declarations!$D$20*J24+Declarations!$B$23*U_held -> 71.411939 | I25: =Declarations!$B$21*H24+Declarations!$C$21*I24+Declarations!$D$21*J24+Declarations!$C$23*U_held -> 59.440762 | J25: =Declarations!$B$22*H24+Declarations!$C$22*I24+Declarations!$D$22*J24+Declarations!$D$23*U_held -> 44.979392 | K25: =MAX(ABS(H25-B25-E25),ABS(I25-C25-F25),ABS(J25-D25-G25)) -> 0 | L25: =IF(F25>C25,A25,99) -> 19
A26: 20 | B26: =Declarations!$B$20*B25+Declarations!$C$20*C25+Declarations!$D$20*D25 -> 16.767774 | C26: =Declarations!$B$21*B25+Declarations!$C$21*C25+Declarations!$D$21*D25 -> 16.652482 | D26: =Declarations!$B$22*B25+Declarations!$C$22*C25+Declarations!$D$22*D25 -> 16.738951 | E26: =Declarations!$B$20*E25+Declarations!$C$20*F25+Declarations!$D$20*G25+Declarations!$B$23*U_held -> 55.275009 | F26: =Declarations!$B$21*E25+Declarations!$C$21*F25+Declarations!$D$21*G25+Declarations!$C$23*U_held -> 43.41336 | G26: =Declarations!$B$22*E25+Declarations!$C$22*F25+Declarations!$D$22*G25+Declarations!$D$23*U_held -> 28.759236 | H26: =Declarations!$B$20*H25+Declarations!$C$20*I25+Declarations!$D$20*J25+Declarations!$B$23*U_held -> 72.042783 | I26: =Declarations!$B$21*H25+Declarations!$C$21*I25+Declarations!$D$21*J25+Declarations!$C$23*U_held -> 60.065842 | J26: =Declarations!$B$22*H25+Declarations!$C$22*I25+Declarations!$D$22*J25+Declarations!$D$23*U_held -> 45.498187 | K26: =MAX(ABS(H26-B26-E26),ABS(I26-C26-F26),ABS(J26-D26-G26)) -> 0 | L26: =IF(F26>C26,A26,99) -> 20

Sheet PolicyMap
A1: Move the steady state: the policy map x* = (I - A)^(-1) B u and the spectral test (Theorem 7.3(ii); Theorem 7.4(i); Online Appendix 7.B.3; AXIOM Lab 1.7, step 2)
A3: I - A | B3: capability | C3: technology | D3: efficiency | F3: B | H3: Policy map (Equation 7.6) | I3: Value | J3: Reading
A4: capability | B4: =1-Declarations!$B$20 -> 0.1 | C4: =0-Declarations!$C$20 -> -0.05 | D4: =0-Declarations!$D$20 -> 0 | F4: =Declarations!$B$23 -> 0.6 | H4: det(I - A) | I4: =MDETERM(B4:D6) -> 0.002 | J4: nonzero: exactly one steady state for each held investment
A5: technology | B5: =0-Declarations!$B$21 -> -0.1 | C5: =1-Declarations!$C$21 -> 0.15 | D5: =0-Declarations!$D$21 -> 0 | F5: =Declarations!$C$23 -> 0.3 | H5: Per unit held: capability | I5: =MDETERM(B9:D11)/I4 -> 10.5 | J5: 10.5 (Cramer's rule)
A6: efficiency | B6: =0-Declarations!$B$22 -> -0.05 | C6: =0-Declarations!$C$22 -> -0.1 | D6: =1-Declarations!$D$22 -> 0.2 | F6: =Declarations!$D$23 -> 0 | H6: Per unit held: technology | I6: =MDETERM(B13:D15)/I4 -> 9 | J6: 9
H7: Per unit held: efficiency | I7: =MDETERM(B17:D19)/I4 -> 7.125 | J7: 7.125
A8: I - A with column 1 replaced by B | B8: capability | C8: technology | D8: efficiency | H8: Steady state at the held investment: capability | I8: =I5*U_held -> 84 | J8: 84
B9: =F4 -> 0.6 | C9: =C4 -> -0.05 | D9: =D4 -> 0 | H9: Steady state at the held investment: technology | I9: =I6*U_held -> 72 | J9: 72
B10: =F5 -> 0.3 | C10: =C5 -> 0.15 | D10: =D5 -> 0 | H10: Steady state at the held investment: efficiency | I10: =I7*U_held -> 57 | J10: 57, below today's 60
B11: =F6 -> 0 | C11: =C6 -> -0.1 | D11: =D6 -> 0.2
A12: I - A with column 2 replaced by B | B12: capability | C12: technology | D12: efficiency | H12: Spectral test (Theorem 7.4(i)) | I12: Value | J12: Reading
B13: =B4 -> 0.1 | C13: =F4 -> 0.6 | D13: =D4 -> 0 | H13: Efficiency feeds neither capability nor technology? | I13: =IF(AND(Declarations!$D$20=0,Declarations!$D$21=0),1,0) -> 1 | J13: 1: the eigenvalues are those of the top block and a33
B14: =B5 -> -0.1 | C14: =F5 -> 0.3 | D14: =D5 -> 0 | H14: Top block: trace | I14: =Declarations!$B$20+Declarations!$C$21 -> 1.75
B15: =B6 -> -0.05 | C15: =F6 -> 0 | D15: =D6 -> 0.2 | H15: Top block: determinant | I15: =Declarations!$B$20*Declarations!$C$21-Declarations!$C$20*Declarations!$B$21 -> 0.76
A16: I - A with column 3 replaced by B | B16: capability | C16: technology | D16: efficiency | H16: Eigenvalue 1 | I16: =(I14+SQRT(I14^2-4*I15))/2 -> 0.95 | J16: 0.95
B17: =B4 -> 0.1 | C17: =C4 -> -0.05 | D17: =F4 -> 0.6 | H17: Eigenvalue 2 | I17: =(I14-SQRT(I14^2-4*I15))/2 -> 0.8 | J17: 0.80
B18: =B5 -> -0.1 | C18: =C5 -> 0.15 | D18: =F5 -> 0.3 | H18: Eigenvalue 3, a33 | I18: =Declarations!$D$22 -> 0.8 | J18: 0.80
B19: =B6 -> -0.05 | C19: =C6 -> -0.1 | D19: =F6 -> 0 | H19: Spectral radius: the slowest eigenvalue | I19: =MAX(ABS(I16),ABS(I17),ABS(I18)) -> 0.95 | J19: inside the unit circle: shocks die out
H20: Half-life of a shock, ln 0.5 / ln(radius), years | I20: =LN(0.5)/LN(I19) -> 13.513407 | J20: 13.5 years
H21: Held investment at which capability's steady state reaches 100 | I21: =100/I5 -> 9.5238095 | J21: the index stops at 100
E22: Held investment | F22: 10 | H22: Held at 10 a year: first year capability passes 100 | I22: =MIN(F25:F105) -> 47 | J22: the linear law leaves the index
A24: Year | B24: Held: capability | C24: technology | D24: efficiency | F24: Passes 100? | H24: Policy sweep: held investment | I24: Steady state: capability | J24: technology | K24: efficiency
A25: 0 | B25: =Declarations!$B$24 -> 50 | C25: =Declarations!$C$24 -> 40 | D25: =Declarations!$D$24 -> 60 | F25: =IF(B25>100,A25,999) -> 999 | H25: 0 | I25: =$H25*$I$5 -> 0 | J25: =$H25*$I$6 -> 0 | K25: =$H25*$I$7 -> 0
A26: 1 | B26: =Declarations!$B$20*B25+Declarations!$C$20*C25+Declarations!$D$20*D25+Declarations!$B$23*$F$22 -> 53 | C26: =Declarations!$B$21*B25+Declarations!$C$21*C25+Declarations!$D$21*D25+Declarations!$C$23*$F$22 -> 42 | D26: =Declarations!$B$22*B25+Declarations!$C$22*C25+Declarations!$D$22*D25+Declarations!$D$23*$F$22 -> 54.5 | F26: =IF(B26>100,A26,999) -> 999 | H26: 4 | I26: =$H26*$I$5 -> 42 | J26: =$H26*$I$6 -> 36 | K26: =$H26*$I$7 -> 28.5
A27: 2 | B27: =Declarations!$B$20*B26+Declarations!$C$20*C26+Declarations!$D$20*D26+Declarations!$B$23*$F$22 -> 55.8 | C27: =Declarations!$B$21*B26+Declarations!$C$21*C26+Declarations!$D$21*D26+Declarations!$C$23*$F$22 -> 44 | D27: =Declarations!$B$22*B26+Declarations!$C$22*C26+Declarations!$D$22*D26+Declarations!$D$23*$F$22 -> 50.45 | F27: =IF(B27>100,A27,999) -> 999 | H27: 8 | I27: =$H27*$I$5 -> 84 | J27: =$H27*$I$6 -> 72 | K27: =$H27*$I$7 -> 57
A28: 3 | B28: =Declarations!$B$20*B27+Declarations!$C$20*C27+Declarations!$D$20*D27+Declarations!$B$23*$F$22 -> 58.42 | C28: =Declarations!$B$21*B27+Declarations!$C$21*C27+Declarations!$D$21*D27+Declarations!$C$23*$F$22 -> 45.98 | D28: =Declarations!$B$22*B27+Declarations!$C$22*C27+Declarations!$D$22*D27+Declarations!$D$23*$F$22 -> 47.55 | F28: =IF(B28>100,A28,999) -> 999 | H28: 9 | I28: =$H28*$I$5 -> 94.5 | J28: =$H28*$I$6 -> 81 | K28: =$H28*$I$7 -> 64.125
A29: 4 | B29: =Declarations!$B$20*B28+Declarations!$C$20*C28+Declarations!$D$20*D28+Declarations!$B$23*$F$22 -> 60.877 | C29: =Declarations!$B$21*B28+Declarations!$C$21*C28+Declarations!$D$21*D28+Declarations!$C$23*$F$22 -> 47.925 | D29: =Declarations!$B$22*B28+Declarations!$C$22*C28+Declarations!$D$22*D28+Declarations!$D$23*$F$22 -> 45.559 | F29: =IF(B29>100,A29,999) -> 999 | H29: 10 | I29: =$H29*$I$5 -> 105 | J29: =$H29*$I$6 -> 90 | K29: =$H29*$I$7 -> 71.25
A30: 5 | B30: =Declarations!$B$20*B29+Declarations!$C$20*C29+Declarations!$D$20*D29+Declarations!$B$23*$F$22 -> 63.18555 | C30: =Declarations!$B$21*B29+Declarations!$C$21*C29+Declarations!$D$21*D29+Declarations!$C$23*$F$22 -> 49.82395 | D30: =Declarations!$B$22*B29+Declarations!$C$22*C29+Declarations!$D$22*D29+Declarations!$D$23*$F$22 -> 44.28355 | F30: =IF(B30>100,A30,999) -> 999
A31: 6 | B31: =Declarations!$B$20*B30+Declarations!$C$20*C30+Declarations!$D$20*D30+Declarations!$B$23*$F$22 -> 65.358193 | C31: =Declarations!$B$21*B30+Declarations!$C$21*C30+Declarations!$D$21*D30+Declarations!$C$23*$F$22 -> 51.668912 | D31: =Declarations!$B$22*B30+Declarations!$C$22*C30+Declarations!$D$22*D30+Declarations!$D$23*$F$22 -> 43.568512 | F31: =IF(B31>100,A31,999) -> 999
A32: 7 | B32: =Declarations!$B$20*B31+Declarations!$C$20*C31+Declarations!$D$20*D31+Declarations!$B$23*$F$22 -> 67.405819 | C32: =Declarations!$B$21*B31+Declarations!$C$21*C31+Declarations!$D$21*D31+Declarations!$C$23*$F$22 -> 53.454395 | D32: =Declarations!$B$22*B31+Declarations!$C$22*C31+Declarations!$D$22*D31+Declarations!$D$23*$F$22 -> 43.289611 | F32: =IF(B32>100,A32,999) -> 999
A33: 8 | B33: =Declarations!$B$20*B32+Declarations!$C$20*C32+Declarations!$D$20*D32+Declarations!$B$23*$F$22 -> 69.337957 | C33: =Declarations!$B$21*B32+Declarations!$C$21*C32+Declarations!$D$21*D32+Declarations!$C$23*$F$22 -> 55.176818 | D33: =Declarations!$B$22*B32+Declarations!$C$22*C32+Declarations!$D$22*D32+Declarations!$D$23*$F$22 -> 43.347419 | F33: =IF(B33>100,A33,999) -> 999
A34: 9 | B34: =Declarations!$B$20*B33+Declarations!$C$20*C33+Declarations!$D$20*D33+Declarations!$B$23*$F$22 -> 71.163002 | C34: =Declarations!$B$21*B33+Declarations!$C$21*C33+Declarations!$D$21*D33+Declarations!$C$23*$F$22 -> 56.834091 | D34: =Declarations!$B$22*B33+Declarations!$C$22*C33+Declarations!$D$22*D33+Declarations!$D$23*$F$22 -> 43.662515 | F34: =IF(B34>100,A34,999) -> 999
A35: 10 | B35: =Declarations!$B$20*B34+Declarations!$C$20*C34+Declarations!$D$20*D34+Declarations!$B$23*$F$22 -> 72.888406 | C35: =Declarations!$B$21*B34+Declarations!$C$21*C34+Declarations!$D$21*D34+Declarations!$C$23*$F$22 -> 58.425277 | D35: =Declarations!$B$22*B34+Declarations!$C$22*C34+Declarations!$D$22*D34+Declarations!$D$23*$F$22 -> 44.171571 | F35: =IF(B35>100,A35,999) -> 999
A36: 11 | B36: =Declarations!$B$20*B35+Declarations!$C$20*C35+Declarations!$D$20*D35+Declarations!$B$23*$F$22 -> 74.52083 | C36: =Declarations!$B$21*B35+Declarations!$C$21*C35+Declarations!$D$21*D35+Declarations!$C$23*$F$22 -> 59.950326 | D36: =Declarations!$B$22*B35+Declarations!$C$22*C35+Declarations!$D$22*D35+Declarations!$D$23*$F$22 -> 44.824205 | F36: =IF(B36>100,A36,999) -> 999
A37: 12 | B37: =Declarations!$B$20*B36+Declarations!$C$20*C36+Declarations!$D$20*D36+Declarations!$B$23*$F$22 -> 76.066263 | C37: =Declarations!$B$21*B36+Declarations!$C$21*C36+Declarations!$D$21*D36+Declarations!$C$23*$F$22 -> 61.40986 | D37: =Declarations!$B$22*B36+Declarations!$C$22*C36+Declarations!$D$22*D36+Declarations!$D$23*$F$22 -> 45.580438 | F37: =IF(B37>100,A37,999) -> 999
A38: 13 | B38: =Declarations!$B$20*B37+Declarations!$C$20*C37+Declarations!$D$20*D37+Declarations!$B$23*$F$22 -> 77.53013 | C38: =Declarations!$B$21*B37+Declarations!$C$21*C37+Declarations!$D$21*D37+Declarations!$C$23*$F$22 -> 62.805007 | D38: =Declarations!$B$22*B37+Declarations!$C$22*C37+Declarations!$D$22*D37+Declarations!$D$23*$F$22 -> 46.40865 | F38: =IF(B38>100,A38,999) -> 999
A39: 14 | B39: =Declarations!$B$20*B38+Declarations!$C$20*C38+Declarations!$D$20*D38+Declarations!$B$23*$F$22 -> 78.917367 | C39: =Declarations!$B$21*B38+Declarations!$C$21*C38+Declarations!$D$21*D38+Declarations!$C$23*$F$22 -> 64.137269 | D39: =Declarations!$B$22*B38+Declarations!$C$22*C38+Declarations!$D$22*D38+Declarations!$D$23*$F$22 -> 47.283927 | F39: =IF(B39>100,A39,999) -> 999
A40: 15 | B40: =Declarations!$B$20*B39+Declarations!$C$20*C39+Declarations!$D$20*D39+Declarations!$B$23*$F$22 -> 80.232494 | C40: =Declarations!$B$21*B39+Declarations!$C$21*C39+Declarations!$D$21*D39+Declarations!$C$23*$F$22 -> 65.408416 | D40: =Declarations!$B$22*B39+Declarations!$C$22*C39+Declarations!$D$22*D39+Declarations!$D$23*$F$22 -> 48.186737 | F40: =IF(B40>100,A40,999) -> 999
A41: 16 | B41: =Declarations!$B$20*B40+Declarations!$C$20*C40+Declarations!$D$20*D40+Declarations!$B$23*$F$22 -> 81.479665 | C41: =Declarations!$B$21*B40+Declarations!$C$21*C40+Declarations!$D$21*D40+Declarations!$C$23*$F$22 -> 66.620403 | D41: =Declarations!$B$22*B40+Declarations!$C$22*C40+Declarations!$D$22*D40+Declarations!$D$23*$F$22 -> 49.101856 | F41: =IF(B41>100,A41,999) -> 999
... A105: 80 | B105: =Declarations!$B$20*B104+Declarations!$C$20*C104+Declarations!$D$20*D104+Declarations!$B$23*$F$22 -> 104.11918 | C105: =Declarations!$B$21*B104+Declarations!$C$21*C104+Declarations!$D$21*D104+Declarations!$C$23*$F$22 -> 89.11918 | D105: =Declarations!$B$22*B104+Declarations!$C$22*C104+Declarations!$D$22*D104+Declarations!$D$23*$F$22 -> 70.369181 | F105: =IF(B105>100,A105,999) -> 80

Sheet Disclosure
A1: Probe the disclosure: what the covenant package reveals (Theorem 7.2(iii); Equation 7.5; Online Appendix 7.B.2; AXIOM Lab 1.7, step 3)
