Workbook

Sheet README
B1: DCT Laboratory — Vol II, Ch 15: Enterprise Digital Twins and Autonomous Enterprise Transformation
B2: Seed 26215 · Companion to DCT_V2_Ch15_Lab.ipynb and AXIOM Lab 2.15 (module AXIOM-15). Money in $ million.
B4: Worked Example 15.1, Can a Digital Twin Replace the Engineering Office's Count?, with the book's declarations: Chapter 7's law and costs, an audited start at 58, the skills survey twice a year with an error of 2.5 points, the twin (a Kalman filter) running Chapter 7's target rule on its estimate, the monitor and the audit on an alarm, and a drift from quarter 8. Seeds as in Online Appendix Remark 15.B.1.
B5: Declarations: the law, the costs, the discount, the swings, the survey, the monitor, the drift, the seeds.
B6: Sync: the twin's error variance quarter by quarter for four surveys, the survey read as exact and no readings; the periodic fixed points in closed form; precisions add; a biased survey (Step 2; Theorem 15.1; Proposition 15.1).
B7: Program: one program from the audited 58 (Figure 15.1(a), seed 1503), run by formulas on the engine's draws.
B8: Decide: the design-path searches' best targets, Table 15.3's costs above the count and their yearly worth, the certification on fresh paths, and Theorem 15.2(iii)'s margins (Steps 3 and 6; Figure 15.2(a)).
B9: Readings: what better surveys are worth, and the readings study (Step 4; Figure 15.2(b)).
B10: Bias, Monitor, Drift: the twin that never questions its law, the cumulative sum and its threshold on a printed sample of innovations, the drift's costs and the detection delays (Step 5; Theorem 15.3; Figure 15.3).
B11: Envelope: the guardrail, the calendar of uncertainty, the loop's modes (Step 6; Proposition 15.3). Table15_3: the Worked Example's table, linked to the sheets.
B12: Engine values (green) are what needs simulation: costs on the design and fresh paths, shares below the floor, false-alarm rates, the drift's costs and delays, and the sample's innovations.
B13: Reference_Values and Checks: the engine's numbers and a PASS/FAIL comparison with this workbook's formulas.
... B19: Cross-sheet link: green.

Sheet Declarations
A1: Declarations (Worked Example 15.1, Step 1; Chapter 7's law and costs; the twin, its survey and its monitor; Online Appendix Remark 15.B.1). Money in $ million; capability in points.
A3: Quantity | B3: Value | C3: Source
A4: Discount rate a year | B4: 0.1 | C4: The board's 10 percent
A5: Discount factor a quarter, beta | B5: =(1+B4)^(-1/4) -> 0.97645409 | C5: beta = 1.1^(-1/4)
A6: Effective horizon 1/(1 - beta), quarters | B6: =1/(1-B5) -> 42.47022
A7: Capability kept each quarter, a | B7: 0.975 | C7: Chapter 7
A8: Cost of a point hired and trained, k | B8: 4 | C8: $4 million a point
A9: Hiring cap a quarter (points) | B9: 2.5
A10: Capability floor | B10: 55
A11: Cost of a point-quarter short | B11: 1.6 | C11: $1.6 million (Chapter 7)
A12: The audited start | B12: 58 | C12: Every design is priced from 58
A13: Chapter 7's target for planned capability | B13: 55.75 | C13: Worked Example 7.1, on the count
A14: Chapter 7's cost from 58 (its 0.05-point grid) | B14: 230.755 | C14: Worked Example 7.1
A15: The skills survey's error, sd (points) | B15: 2.5 | C15: 95 percent of readings within +/-5 (Volume I, Table 5.2)
A16: its variance r | B16: =B15^2 -> 6.25
A17: A survey twice as sharp, sd | B17: =B15/2 -> 1.25 | C17: 1.25 points
A18: its variance | B18: =B17^2 -> 1.5625
A19: The survey runs every (quarters) | B19: 2 | C19: Twice a year, at the start of quarters 2, 4, 6, ...
A20: A quarterly survey runs every (quarters) | B20: 1
A21: Quarters of present value | B21: 480 | C21: 120 years
A22: Long-run shares from quarter | B22: 40 | C22: Quarters 40-479
A23: The monitor's reference, kappa | B23: 0.5 | C23: Detects a shift of one standard deviation
A24: At most one false alarm in so many surveys | B24: 50 | C24: The threshold's calibration
A25: The drift begins at the start of quarter | B25: 8 | C25: A tighter labor market (Step 5)
A26: extra points lost each quarter | B26: 0.5
A27: Design paths | B27: 20000 | C27: Seed 1500
A28: Fresh paths (and drift paths) | B28: 100000 | C28: Seeds 1501 and 1507
A30: Swing w (points lost) | B30: Chance
A31: 1.5 | B31: 0.05
A32: 0.75 | B32: 0.2
A33: 0 | B33: 0.5
A34: -0.75 | B34: 0.2
A35: -1.5 | B35: 0.05
A36: Total | B36: =SUM(B31:B35) -> 1
A37: Mean swing | B37: =SUMPRODUCT(A31:A35,B31:B35) -> 0
A38: A swing's variance q | B38: =SUMPRODUCT(A31:A35,A31:A35,B31:B35)-B37^2 -> 0.45 | C38: 0.45
A39: its standard deviation | B39: =SQRT(B38) -> 0.67082039 | C39: 0.67 points (Section 15.2)
A40: c' = 0.975c + h - w; a quarter costs 4h + 1.6(55 - c)^+. The twin knows the law and its hires, not the swings: its filter uses the swings' mean 0 and variance q, and a variance of 0 at the audited start.
A42: Seeds (Online Appendix Remark 15.B.1)
A43: Design paths (20,000) | B43: 1500 | C43: Each design's best target
...

Sheet Sync
A1: Synchronize: the twin's error, quarter by quarter (Equation 15.1; Theorem 15.1(iii)-(iv); Proposition 15.1; Worked Example 15.1, Step 2; Figure 15.1(b); AXIOM Lab 2.15, step 1)
A2: Prior P- = a^2 P + q; at a survey the gain K = P-/(P- + r) and the posterior (1 - K) P-; no survey, no correction. The variances do not depend on the readings (Proposition 15.3(iii)). Quarter 0 is the audited start, variance 0.
B4: Twin, survey twice a year | G4: Twin, quarterly survey | L4: Twin, survey twice as sharp | Q4: Twin, both | V4: Survey read as exact | X4: No readings after the audit | AA4: Steady state (closed form) | AB4: Survey every k | AC4: Variance r | AD4: a^(2k) | AE4: c_k = q(1 - a^(2k))/(1 - a^2) | AF4: P just after a survey (fixed point) | AG4: Error just after (sd) | AH4: A quarter later (sd) | AI4: Just before the next (sd) | AJ4: Gain | AK4: The recursion at quarter 60 (sd)
A5: Quarter | B5: Survey (1 = yes) | C5: Prior P- | D5: Gain K | E5: Posterior P | F5: Error the twin decides with (sd) | G5: Survey (1 = yes) | H5: Prior P- | I5: Gain K | J5: Posterior P | K5: Error the twin decides with (sd) | L5: Survey (1 = yes) | M5: Prior P- | N5: Gain K | O5: Posterior P | P5: Error the twin decides with (sd) | Q5: Survey (1 = yes) | R5: Prior P- | S5: Gain K | T5: Posterior P | U5: Error the twin decides with (sd) | V5: Variance | W5: Error (sd) | X5: Variance | Y5: Error (sd)
A6: 0 | B6: =IF(AND($A6>0,MOD($A6,Every2)=0),1,0) -> 0 | C6: 0 | D6: =IF(B6=1,C6/(C6+R_s),0) -> 0 | E6: =(1-D6)*C6 -> 0 | F6: =SQRT(E6) -> 0 | G6: =IF(AND($A6>0,MOD($A6,Every1)=0),1,0) -> 0 | H6: 0 | I6: =IF(G6=1,H6/(H6+R_s),0) -> 0 | J6: =(1-I6)*H6 -> 0 | K6: =SQRT(J6) -> 0 | L6: =IF(AND($A6>0,MOD($A6,Every2)=0),1,0) -> 0 | M6: 0 | N6: =IF(L6=1,M6/(M6+R_sharp),0) -> 0 | O6: =(1-N6)*M6 -> 0 | P6: =SQRT(O6) -> 0 | Q6: =IF(AND($A6>0,MOD($A6,Every1)=0),1,0) -> 0 | R6: 0 | S6: =IF(Q6=1,R6/(R6+R_sharp),0) -> 0 | T6: =(1-S6)*R6 -> 0 | U6: =SQRT(T6) -> 0 | V6: 0 | W6: =SQRT(V6) -> 0 | X6: 0 | Y6: =SQRT(X6) -> 0 | AA6: Twin, survey twice a year | AB6: =Every2 -> 2 | AC6: =R_s -> 6.25 | AD6: =Alpha_keep^(2*AB6) -> 0.90368789 | AE6: =Q_var*(1-AD6)/(1-Alpha_keep^2) -> 0.87778125 | AF6: =(-(AE6+AC6-AC6*AD6)+SQRT((AE6+AC6-AC6*AD6)^2+4*AD6*AC6*AE6))/(2*AD6) -> 1.7776496 | AG6: =SQRT(AF6) -> 1.3332852 | AH6: =IF(AB6=2,SQRT(Alpha_keep^2*AF6+Q_var),"") -> 1.4628322 | AI6: =SQRT(AD6*AF6+AE6) -> 1.5761414 | AJ6: =(AD6*AF6+AE6)/(AD6*AF6+AE6+AC6) -> 0.28442393 | AK6: =F66 -> 1.3332852
A7: 1 | B7: =IF(AND($A7>0,MOD($A7,Every2)=0),1,0) -> 0 | C7: =Alpha_keep^2*E6+Q_var -> 0.45 | D7: =IF(B7=1,C7/(C7+R_s),0) -> 0 | E7: =(1-D7)*C7 -> 0.45 | F7: =SQRT(E7) -> 0.67082039 | G7: =IF(AND($A7>0,MOD($A7,Every1)=0),1,0) -> 1 | H7: =Alpha_keep^2*J6+Q_var -> 0.45 | I7: =IF(G7=1,H7/(H7+R_s),0) -> 0.067164179 | J7: =(1-I7)*H7 -> 0.41977612 | K7: =SQRT(J7) -> 0.64790132 | L7: =IF(AND($A7>0,MOD($A7,Every2)=0),1,0) -> 0 | M7: =Alpha_keep^2*O6+Q_var -> 0.45 | N7: =IF(L7=1,M7/(M7+R_sharp),0) -> 0 | O7: =(1-N7)*M7 -> 0.45 | P7: =SQRT(O7) -> 0.67082039 | Q7: =IF(AND($A7>0,MOD($A7,Every1)=0),1,0) -> 1 | R7: =Alpha_keep^2*T6+Q_var -> 0.45 | S7: =IF(Q7=1,R7/(R7+R_sharp),0) -> 0.22360248 | T7: =(1-S7)*R7 -> 0.34937888 | U7: =SQRT(T7) -> 0.5910828 | V7: =IF(MOD($A7,Every2)=0,R_s,Alpha_keep^2*V6+Q_var) -> 0.45 | W7: =SQRT(V7) -> 0.67082039 | X7: =Alpha_keep^2*X6+Q_var -> 0.45 | Y7: =SQRT(X7) -> 0.67082039 | AA7: Twin, quarterly survey | AB7: =Every1 -> 1 | AC7: =R_s -> 6.25 | AD7: =Alpha_keep^(2*AB7) -> 0.950625 | AE7: =Q_var*(1-AD7)/(1-Alpha_keep^2) -> 0.45 | AF7: =(-(AE7+AC7-AC7*AD7)+SQRT((AE7+AC7-AC7*AD7)^2+4*AD7*AC7*AE7))/(2*AD7) -> 1.3667259 | AG7: =SQRT(AF7) -> 1.1690705 | AH7: =IF(AB7=2,SQRT(Alpha_keep^2*AF7+Q_var),"") | AI7: =SQRT(AD7*AF7+AE7) -> 1.3225898 | AJ7: =(AD7*AF7+AE7)/(AD7*AF7+AE7+AC7) -> 0.21867615 | AK7: =K66 -> 1.1690705
A8: 2 | B8: =IF(AND($A8>0,MOD($A8,Every2)=0),1,0) -> 1 | C8: =Alpha_keep^2*E7+Q_var -> 0.87778125 | D8: =IF(B8=1,C8/(C8+R_s),0) -> 0.1231493 | E8: =(1-D8)*C8 -> 0.76968311 | F8: =SQRT(E8) -> 0.87731585 | G8: =IF(AND($A8>0,MOD($A8,Every1)=0),1,0) -> 1 | H8: =Alpha_keep^2*J7+Q_var -> 0.84904967 | I8: =IF(G8=1,H8/(H8+R_s),0) -> 0.11960047 | J8: =(1-I8)*H8 -> 0.74750293 | K8: =SQRT(J8) -> 0.86458252 | L8: =IF(AND($A8>0,MOD($A8,Every2)=0),1,0) -> 1 | M8: =Alpha_keep^2*O7+Q_var -> 0.87778125 | N8: =IF(L8=1,M8/(M8+R_sharp),0) -> 0.35970495 | O8: =(1-N8)*M8 -> 0.56203899 | P8: =SQRT(O8) -> 0.7496926 | Q8: =IF(AND($A8>0,MOD($A8,Every1)=0),1,0) -> 1 | R8: =Alpha_keep^2*T7+Q_var -> 0.7821283 | S8: =IF(Q8=1,R8/(R8+R_sharp),0) -> 0.33358307 | T8: =(1-S8)*R8 -> 0.52122354 | U8: =SQRT(T8) -> 0.72195813 | V8: =IF(MOD($A8,Every2)=0,R_s,Alpha_keep^2*V7+Q_var) -> 6.25 | W8: =SQRT(V8) -> 2.5 | X8: =Alpha_keep^2*X7+Q_var -> 0.87778125 | Y8: =SQRT(X8) -> 0.93689981 | AA8: Twin, survey twice as sharp | AB8: =Every2 -> 2 | AC8: =R_sharp -> 1.5625 | AD8: =Alpha_keep^(2*AB8) -> 0.90368789 | AE8: =Q_var*(1-AD8)/(1-Alpha_keep^2) -> 0.87778125 | AF8: =(-(AE8+AC8-AC8*AD8)+SQRT((AE8+AC8-AC8*AD8)^2+4*AD8*AC8*AE8))/(2*AD8) -> 0.788048 | AG8: =SQRT(AF8) -> 0.88772068 | AH8: =IF(AB8=2,SQRT(Alpha_keep^2*AF8+Q_var),"") -> 1.0950517 | AI8: =SQRT(AD8*AF8+AE8) -> 1.2609245 | AJ8: =(AD8*AF8+AE8)/(AD8*AF8+AE8+AC8) -> 0.50435072 | AK8: =P66 -> 0.88772068
A9: 3 | B9: =IF(AND($A9>0,MOD($A9,Every2)=0),1,0) -> 0 | C9: =Alpha_keep^2*E8+Q_var -> 1.18168 | D9: =IF(B9=1,C9/(C9+R_s),0) -> 0 | E9: =(1-D9)*C9 -> 1.18168 | F9: =SQRT(E9) -> 1.0870511 | G9: =IF(AND($A9>0,MOD($A9,Every1)=0),1,0) -> 1 | H9: =Alpha_keep^2*J8+Q_var -> 1.160595 | I9: =IF(G9=1,H9/(H9+R_s),0) -> 0.15661293 | J9: =(1-I9)*H9 -> 0.9788308 | K9: =SQRT(J9) -> 0.98935878 | L9: =IF(AND($A9>0,MOD($A9,Every2)=0),1,0) -> 0 | M9: =Alpha_keep^2*O8+Q_var -> 0.98428831 | N9: =IF(L9=1,M9/(M9+R_sharp),0) -> 0 | O9: =(1-N9)*M9 -> 0.98428831 | P9: =SQRT(O9) -> 0.99211305 | Q9: =IF(AND($A9>0,MOD($A9,Every1)=0),1,0) -> 1 | R9: =Alpha_keep^2*T8+Q_var -> 0.94548813 | S9: =IF(Q9=1,R9/(R9+R_sharp),0) -> 0.37699067 | T9: =(1-S9)*R9 -> 0.58904792 | U9: =SQRT(T9) -> 0.76749458 | V9: =IF(MOD($A9,Every2)=0,R_s,Alpha_keep^2*V8+Q_var) -> 6.3914063 | W9: =SQRT(V9) -> 2.5281231 | X9: =Alpha_keep^2*X8+Q_var -> 1.2844408 | Y9: =SQRT(X9) -> 1.1333317 | AA9: Twin, both | AB9: =Every1 -> 1 | AC9: =R_sharp -> 1.5625 | AD9: =Alpha_keep^(2*AB9) -> 0.950625 | AE9: =Q_var*(1-AD9)/(1-Alpha_keep^2) -> 0.45 | AF9: =(-(AE9+AC9-AC9*AD9)+SQRT((AE9+AC9-AC9*AD9)^2+4*AD9*AC9*AE9))/(2*AD9) -> 0.62635103 | AG9: =SQRT(AF9) -> 0.79142342 | AH9: =IF(AB9=2,SQRT(Alpha_keep^2*AF9+Q_var),"") | AI9: =SQRT(AD9*AF9+AE9) -> 1.0224602 | AJ9: =(AD9*AF9+AE9)/(AD9*AF9+AE9+AC9) -> 0.40086466 | AK9: =U66 -> 0.79142342
A10: 4 | B10: =IF(AND($A10>0,MOD($A10,Every2)=0),1,0) -> 1 | C10: =Alpha_keep^2*E9+Q_var -> 1.5733346 | D10: =IF(B10=1,C10/(C10+R_s),0) -> 0.20110792 | E10: =(1-D10)*C10 -> 1.2569245 | F10: =SQRT(E10) -> 1.1211264 | G10: =IF(AND($A10>0,MOD($A10,Every1)=0),1,0) -> 1 | H10: =Alpha_keep^2*J9+Q_var -> 1.380501 | I10: =IF(G10=1,H10/(H10+R_s),0) -> 0.18091879 | J10: =(1-I10)*H10 -> 1.1307425 | K10: =SQRT(J10) -> 1.0633637 | L10: =IF(AND($A10>0,MOD($A10,Every2)=0),1,0) -> 1 | M10: =Alpha_keep^2*O9+Q_var -> 1.3856891 | N10: =IF(L10=1,M10/(M10+R_sharp),0) -> 0.47001364 | O10: =(1-N10)*M10 -> 0.73439631 | P10: =SQRT(O10) -> 0.85696926 | Q10: =IF(AND($A10>0,MOD($A10,Every1)=0),1,0) -> 1 | R10: =Alpha_keep^2*T9+Q_var -> 1.0099637 | S10: =IF(Q10=1,R10/(R10+R_sharp),0) -> 0.39260561 | T10: =(1-S10)*R10 -> 0.61344627 | U10: =SQRT(T10) -> 0.78322811 | V10: =IF(MOD($A10,Every2)=0,R_s,Alpha_keep^2*V9+Q_var) -> 6.25 | W10: =SQRT(V10) -> 2.5 | X10: =Alpha_keep^2*X9+Q_var -> 1.6710215 | Y10: =SQRT(X10) -> 1.29268 | AA10: Survey read as exact | AB10: =Every2 -> 2 | AC10: =R_s -> 6.25 | AG10: =SQRT(AC10) -> 2.5 | AI10: =SQRT(Alpha_keep^2*AC10+Q_var) -> 2.5281231
A11: 5 | B11: =IF(AND($A11>0,MOD($A11,Every2)=0),1,0) -> 0 | C11: =Alpha_keep^2*E10+Q_var -> 1.6448639 | D11: =IF(B11=1,C11/(C11+R_s),0) -> 0 | E11: =(1-D11)*C11 -> 1.6448639 | F11: =SQRT(E11) -> 1.2825225 | G11: =IF(AND($A11>0,MOD($A11,Every1)=0),1,0) -> 1 | H11: =Alpha_keep^2*J10+Q_var -> 1.524912 | I11: =IF(G11=1,H11/(H11+R_s),0) -> 0.19613238 | J11: =(1-I11)*H11 -> 1.2258274 | K11: =SQRT(J11) -> 1.1071709 | L11: =IF(AND($A11>0,MOD($A11,Every2)=0),1,0) -> 0 | M11: =Alpha_keep^2*O10+Q_var -> 1.1481355 | N11: =IF(L11=1,M11/(M11+R_sharp),0) -> 0 | O11: =(1-N11)*M11 -> 1.1481355 | P11: =SQRT(O11) -> 1.0715108 | Q11: =IF(AND($A11>0,MOD($A11,Every1)=0),1,0) -> 1 | R11: =Alpha_keep^2*T10+Q_var -> 1.0331574 | S11: =IF(Q11=1,R11/(R11+R_sharp),0) -> 0.39803303 | T11: =(1-S11)*R11 -> 0.62192661 | U11: =SQRT(T11) -> 0.78862324 | V11: =IF(MOD($A11,Every2)=0,R_s,Alpha_keep^2*V10+Q_var) -> 6.3914063 | W11: =SQRT(V11) -> 2.5281231 | X11: =Alpha_keep^2*X10+Q_var -> 2.0385148 | Y11: =SQRT(X11) -> 1.4277657 | AA11: No readings: the limit sqrt(q/(1 - a^2)) | AG11: =SQRT(Q_var/(1-Alpha_keep^2)) -> 3.0189276 | AK11: =Y66 -> 2.9456998
A12: 6 | B12: =IF(AND($A12>0,MOD($A12,Every2)=0),1,0) -> 1 | C12: =Alpha_keep^2*E11+Q_var -> 2.0136487 | D12: =IF(B12=1,C12/(C12+R_s),0) -> 0.2436755 | E12: =(1-D12)*C12 -> 1.5229719 | F12: =SQRT(E12) -> 1.2340875 | G12: =IF(AND($A12>0,MOD($A12,Every1)=0),1,0) -> 1 | H12: =Alpha_keep^2*J11+Q_var -> 1.6153022 | I12: =IF(G12=1,H12/(H12+R_s),0) -> 0.20537064 | J12: =(1-I12)*H12 -> 1.2835665 | K12: =SQRT(J12) -> 1.132946 | L12: =IF(AND($A12>0,MOD($A12,Every2)=0),1,0) -> 1 | M12: =Alpha_keep^2*O11+Q_var -> 1.5414463 | N12: =IF(L12=1,M12/(M12+R_sharp),0) -> 0.49660856 | O12: =(1-N12)*M12 -> 0.77595087 | P12: =SQRT(O12) -> 0.88088074 | Q12: =IF(AND($A12>0,MOD($A12,Every1)=0),1,0) -> 1 | R12: =Alpha_keep^2*T11+Q_var -> 1.041219 | S12: =IF(Q12=1,R12/(R12+R_sharp),0) -> 0.39989684 | T12: =(1-S12)*R12 -> 0.62483881 | U12: =SQRT(T12) -> 0.79046746 | V12: =IF(MOD($A12,Every2)=0,R_s,Alpha_keep^2*V11+Q_var) -> 6.25 | W12: =SQRT(V12) -> 2.5 | X12: =Alpha_keep^2*X11+Q_var -> 2.3878632 | Y12: =SQRT(X12) -> 1.5452712 | AA12: Theorem 15.1(iii): the variance just after a survey solves P = r psi(P)/(psi(P) + r), psi(P) = a^(2k) P + c_k, a quadratic with one positive root; the recursion reaches it from any start.
A13: 7 | B13: =IF(AND($A13>0,MOD($A13,Every2)=0),1,0) -> 0 | C13: =Alpha_keep^2*E12+Q_var -> 1.8977751 | D13: =IF(B13=1,C13/(C13+R_s),0) -> 0 | E13: =(1-D13)*C13 -> 1.8977751 | F13: =SQRT(E13) -> 1.3775976 | G13: =IF(AND($A13>0,MOD($A13,Every1)=0),1,0) -> 1 | H13: =Alpha_keep^2*J12+Q_var -> 1.6701904 | I13: =IF(G13=1,H13/(H13+R_s),0) -> 0.21087756 | J13: =(1-I13)*H13 -> 1.3179847 | K13: =SQRT(J13) -> 1.1480352 | L13: =IF(AND($A13>0,MOD($A13,Every2)=0),1,0) -> 0 | M13: =Alpha_keep^2*O12+Q_var -> 1.1876383 | N13: =IF(L13=1,M13/(M13+R_sharp),0) -> 0 | O13: =(1-N13)*M13 -> 1.1876383 | P13: =SQRT(O13) -> 1.0897882 | Q13: =IF(AND($A13>0,MOD($A13,Every1)=0),1,0) -> 1 | R13: =Alpha_keep^2*T12+Q_var -> 1.0439874 | S13: =IF(Q13=1,R13/(R13+R_sharp),0) -> 0.40053422 | T13: =(1-S13)*R13 -> 0.62583472 | U13: =SQRT(T13) -> 0.79109716 | V13: =IF(MOD($A13,Every2)=0,R_s,Alpha_keep^2*V12+Q_var) -> 6.3914063 | W13: =SQRT(V13) -> 2.5281231 | X13: =Alpha_keep^2*X12+Q_var -> 2.7199624 | Y13: =SQRT(X13) -> 1.6492309
A14: 8 | B14: =IF(AND($A14>0,MOD($A14,Every2)=0),1,0) -> 1 | C14: =Alpha_keep^2*E13+Q_var -> 2.2540725 | D14: =IF(B14=1,C14/(C14+R_s),0) -> 0.265058 | E14: =(1-D14)*C14 -> 1.6566125 | F14: =SQRT(E14) -> 1.2870946 | G14: =IF(AND($A14>0,MOD($A14,Every1)=0),1,0) -> 1 | H14: =Alpha_keep^2*J13+Q_var -> 1.7029093 | I14: =IF(G14=1,H14/(H14+R_s),0) -> 0.21412406 | J14: =(1-I14)*H14 -> 1.3382754 | K14: =SQRT(J14) -> 1.1568385 | L14: =IF(AND($A14>0,MOD($A14,Every2)=0),1,0) -> 1 | M14: =Alpha_keep^2*O13+Q_var -> 1.5789987 | N14: =IF(L14=1,M14/(M14+R_sharp),0) -> 0.50262592 | O14: =(1-N14)*M14 -> 0.785353 | P14: =SQRT(O14) -> 0.88620145 | Q14: =IF(AND($A14>0,MOD($A14,Every1)=0),1,0) -> 1 | R14: =Alpha_keep^2*T13+Q_var -> 1.0449341 | S14: =IF(Q14=1,R14/(R14+R_sharp),0) -> 0.40075188 | T14: =(1-S14)*R14 -> 0.62617481 | U14: =SQRT(T14) -> 0.79131208 | V14: =IF(MOD($A14,Every2)=0,R_s,Alpha_keep^2*V13+Q_var) -> 6.25 | W14: =SQRT(V14) -> 2.5 | X14: =Alpha_keep^2*X13+Q_var -> 3.0356643 | Y14: =SQRT(X14) -> 1.7423158 | AA14: Proposition 15.1(i): precisions add (the twin, just before a survey)
A15: 9 | B15: =IF(AND($A15>0,MOD($A15,Every2)=0),1,0) -> 0 | C15: =Alpha_keep^2*E14+Q_var -> 2.0248173 | D15: =IF(B15=1,C15/(C15+R_s),0) -> 0 | E15: =(1-D15)*C15 -> 2.0248173 | F15: =SQRT(E15) -> 1.4229607 | G15: =IF(AND($A15>0,MOD($A15,Every1)=0),1,0) -> 1 | H15: =Alpha_keep^2*J14+Q_var -> 1.7221981 | I15: =IF(G15=1,H15/(H15+R_s),0) -> 0.2160255 | J15: =(1-I15)*H15 -> 1.3501594 | K15: =SQRT(J15) -> 1.1619636 | L15: =IF(AND($A15>0,MOD($A15,Every2)=0),1,0) -> 0 | M15: =Alpha_keep^2*O14+Q_var -> 1.1965762 | N15: =IF(L15=1,M15/(M15+R_sharp),0) -> 0 | O15: =(1-N15)*M15 -> 1.1965762 | P15: =SQRT(O15) -> 1.0938813 | Q15: =IF(AND($A15>0,MOD($A15,Every1)=0),1,0) -> 1 | R15: =Alpha_keep^2*T14+Q_var -> 1.0452574 | S15: =IF(Q15=1,R15/(R15+R_sharp),0) -> 0.40082617 | T15: =(1-S15)*R15 -> 0.6262909 | U15: =SQRT(T15) -> 0.79138543 | V15: =IF(MOD($A15,Every2)=0,R_s,Alpha_keep^2*V14+Q_var) -> 6.3914063 | W15: =SQRT(V15) -> 2.5281231 | X15: =Alpha_keep^2*X14+Q_var -> 3.3357784 | Y15: =SQRT(X15) -> 1.8264113 | AA15: The law's prediction: variance P- | AB15: =AI6^2 -> 2.4842216
A16: 10 | B16: =IF(AND($A16>0,MOD($A16,Every2)=0),1,0) -> 1 | C16: =Alpha_keep^2*E15+Q_var -> 2.3748419 | D16: =IF(B16=1,C16/(C16+R_s),0) -> 0.27534904 | E16: =(1-D16)*C16 -> 1.7209315 | F16: =SQRT(E16) -> 1.3118428 | G16: =IF(AND($A16>0,MOD($A16,Every1)=0),1,0) -> 1 | H16: =Alpha_keep^2*J15+Q_var -> 1.7334952 | I16: =IF(G16=1,H16/(H16+R_s),0) -> 0.21713488 | J16: =(1-I16)*H16 -> 1.357093 | K16: =SQRT(J16) -> 1.1649433 | L16: =IF(AND($A16>0,MOD($A16,Every2)=0),1,0) -> 1 | M16: =Alpha_keep^2*O15+Q_var -> 1.5874952 | N16: =IF(L16=1,M16/(M16+R_sharp),0) -> 0.50396751 | O16: =(1-N16)*M16 -> 0.78744923 | P16: =SQRT(O16) -> 0.88738336 | Q16: =IF(AND($A16>0,MOD($A16,Every1)=0),1,0) -> 1 | R16: =Alpha_keep^2*T15+Q_var -> 1.0453678 | S16: =IF(Q16=1,R16/(R16+R_sharp),0) -> 0.40085153 | T16: =(1-S16)*R16 -> 0.62633051 | U16: =SQRT(T16) -> 0.79141046 | V16: =IF(MOD($A16,Every2)=0,R_s,Alpha_keep^2*V15+Q_var) -> 6.25 | W16: =SQRT(V16) -> 2.5 | X16: =Alpha_keep^2*X15+Q_var -> 3.6210743 | Y16: =SQRT(X16) -> 1.9029121 | AA16: The survey: variance r | AB16: =R_s -> 6.25
A17: 11 | B17: =IF(AND($A17>0,MOD($A17,Every2)=0),1,0) -> 0 | C17: =Alpha_keep^2*E16+Q_var -> 2.0859605 | D17: =IF(B17=1,C17/(C17+R_s),0) -> 0 | E17: =(1-D17)*C17 -> 2.0859605 | F17: =SQRT(E17) -> 1.4442855 | G17: =IF(AND($A17>0,MOD($A17,Every1)=0),1,0) -> 1 | H17: =Alpha_keep^2*J16+Q_var -> 1.7400865 | I17: =IF(G17=1,H17/(H17+R_s),0) -> 0.21778068 | J17: =(1-I17)*H17 -> 1.3611293 | K17: =SQRT(J17) -> 1.1666745 | L17: =IF(AND($A17>0,MOD($A17,Every2)=0),1,0) -> 0 | M17: =Alpha_keep^2*O16+Q_var -> 1.1985689 | N17: =IF(L17=1,M17/(M17+R_sharp),0) -> 0 | O17: =(1-N17)*M17 -> 1.1985689 | P17: =SQRT(O17) -> 1.0947917 | Q17: =IF(AND($A17>0,MOD($A17,Every1)=0),1,0) -> 1 | R17: =Alpha_keep^2*T16+Q_var -> 1.0454054 | S17: =IF(Q17=1,R17/(R17+R_sharp),0) -> 0.40086018 | T17: =(1-S17)*R17 -> 0.62634403 | U17: =SQRT(T17) -> 0.791419 | V17: =IF(MOD($A17,Every2)=0,R_s,Alpha_keep^2*V16+Q_var) -> 6.3914063 | W17: =SQRT(V17) -> 2.5281231 | X17: =Alpha_keep^2*X16+Q_var -> 3.8922838 | Y17: =SQRT(X17) -> 1.9728872 | AA17: Combined by precisions: 1/(1/P- + 1/r) | AB17: =1/(1/AB15+1/AB16) -> 1.7776496
A18: 12 | B18: =IF(AND($A18>0,MOD($A18,Every2)=0),1,0) -> 1 | C18: =Alpha_keep^2*E17+Q_var -> 2.4329662 | D18: =IF(B18=1,C18/(C18+R_s),0) -> 0.28019989 | E18: =(1-D18)*C18 -> 1.7512493 | F18: =SQRT(E18) -> 1.3233478 | G18: =IF(AND($A18>0,MOD($A18,Every1)=0),1,0) -> 1 | H18: =Alpha_keep^2*J17+Q_var -> 1.7439235 | I18: =IF(G18=1,H18/(H18+R_s),0) -> 0.21815614 | J18: =(1-I18)*H18 -> 1.3634759 | K18: =SQRT(J18) -> 1.1676797 | L18: =IF(AND($A18>0,MOD($A18,Every2)=0),1,0) -> 1 | M18: =Alpha_keep^2*O17+Q_var -> 1.5893896 | N18: =IF(L18=1,M18/(M18+R_sharp),0) -> 0.50426563 | O18: =(1-N18)*M18 -> 0.78791504 | P18: =SQRT(O18) -> 0.88764579 | Q18: =IF(AND($A18>0,MOD($A18,Every1)=0),1,0) -> 1 | R18: =Alpha_keep^2*T17+Q_var -> 1.0454183 | S18: =IF(Q18=1,R18/(R18+R_sharp),0) -> 0.40086313 | T18: =(1-S18)*R18 -> 0.62634864 | U18: =SQRT(T18) -> 0.79142191 | V18: =IF(MOD($A18,Every2)=0,R_s,Alpha_keep^2*V17+Q_var) -> 6.25 | W18: =SQRT(V18) -> 2.5 | X18: =Alpha_keep^2*X17+Q_var -> 4.1501023 | Y18: =SQRT(X18) -> 2.03718 | AA18: The fixed point just after a survey | AB18: =AF6 -> 1.7776496
A19: 13 | B19: =IF(AND($A19>0,MOD($A19,Every2)=0),1,0) -> 0 | C19: =Alpha_keep^2*E18+Q_var -> 2.1147814 | D19: =IF(B19=1,C19/(C19+R_s),0) -> 0 | E19: =(1-D19)*C19 -> 2.1147814 | F19: =SQRT(E19) -> 1.4542288 | G19: =IF(AND($A19>0,MOD($A19,Every1)=0),1,0) -> 1 | H19: =Alpha_keep^2*J18+Q_var -> 1.7461543 | I19: =IF(G19=1,H19/(H19+R_s),0) -> 0.21837426 | J19: =(1-I19)*H19 -> 1.3648391 | K19: =SQRT(J19) -> 1.1682633 | L19: =IF(AND($A19>0,MOD($A19,Every2)=0),1,0) -> 0 | M19: =Alpha_keep^2*O18+Q_var -> 1.1990117 | N19: =IF(L19=1,M19/(M19+R_sharp),0) -> 0 | O19: =(1-N19)*M19 -> 1.1990117 | P19: =SQRT(O19) -> 1.0949939 | Q19: =IF(AND($A19>0,MOD($A19,Every1)=0),1,0) -> 1 | R19: =Alpha_keep^2*T18+Q_var -> 1.0454227 | S19: =IF(Q19=1,R19/(R19+R_sharp),0) -> 0.40086414 | T19: =(1-S19)*R19 -> 0.62635022 | U19: =SQRT(T19) -> 0.79142291 | V19: =IF(MOD($A19,Every2)=0,R_s,Alpha_keep^2*V18+Q_var) -> 6.3914063 | W19: =SQRT(V19) -> 2.5281231 | X19: =Alpha_keep^2*X18+Q_var -> 4.395191 | Y19: =SQRT(X19) -> 2.0964711 | AA19: The same (1 = yes) | AB19: =IF(ABS(AB17-AB18)<0.000000000001,1,0) -> 1
A20: 14 | B20: =IF(AND($A20>0,MOD($A20,Every2)=0),1,0) -> 1 | C20: =Alpha_keep^2*E19+Q_var -> 2.4603641 | D20: =IF(B20=1,C20/(C20+R_s),0) -> 0.28246398 | E20: =(1-D20)*C20 -> 1.7653998 | F20: =SQRT(E20) -> 1.3286835 | G20: =IF(AND($A20>0,MOD($A20,Every1)=0),1,0) -> 1 | H20: =Alpha_keep^2*J19+Q_var -> 1.7474502 | I20: =IF(G20=1,H20/(H20+R_s),0) -> 0.21850092 | J20: =(1-I20)*H20 -> 1.3656307 | K20: =SQRT(J20) -> 1.168602 | L20: =IF(AND($A20>0,MOD($A20,Every2)=0),1,0) -> 1 | M20: =Alpha_keep^2*O19+Q_var -> 1.5898105 | N20: =IF(L20=1,M20/(M20+R_sharp),0) -> 0.50433183 | O20: =(1-N20)*M20 -> 0.78801848 | P20: =SQRT(O20) -> 0.88770405 | Q20: =IF(AND($A20>0,MOD($A20,Every1)=0),1,0) -> 1 | R20: =Alpha_keep^2*T19+Q_var -> 1.0454242 | S20: =IF(Q20=1,R20/(R20+R_sharp),0) -> 0.40086448 | T20: =(1-S20)*R20 -> 0.62635075 | U20: =SQRT(T20) -> 0.79142325 | V20: =IF(MOD($A20,Every2)=0,R_s,Alpha_keep^2*V19+Q_var) -> 6.25 | W20: =SQRT(V20) -> 2.5 | X20: =Alpha_keep^2*X19+Q_var -> 4.6281784 | Y20: =SQRT(X20) -> 2.1513202
A21: 15 | B21: =IF(AND($A21>0,MOD($A21,Every2)=0),1,0) -> 0 | C21: =Alpha_keep^2*E20+Q_var -> 2.1282332 | D21: =IF(B21=1,C21/(C21+R_s),0) -> 0 | E21: =(1-D21)*C21 -> 2.1282332 | F21: =SQRT(E21) -> 1.4588465 | G21: =IF(AND($A21>0,MOD($A21,Every1)=0),1,0) -> 1 | H21: =Alpha_keep^2*J20+Q_var -> 1.7482027 | I21: =IF(G21=1,H21/(H21+R_s),0) -> 0.21857444 | J21: =(1-I21)*H21 -> 1.3660903 | K21: =SQRT(J21) -> 1.1687986 | L21: =IF(AND($A21>0,MOD($A21,Every2)=0),1,0) -> 0 | M21: =Alpha_keep^2*O20+Q_var -> 1.1991101 | N21: =IF(L21=1,M21/(M21+R_sharp),0) -> 0 | O21: =(1-N21)*M21 -> 1.1991101 | P21: =SQRT(O21) -> 1.0950388 | Q21: =IF(AND($A21>0,MOD($A21,Every1)=0),1,0) -> 1 | R21: =Alpha_keep^2*T20+Q_var -> 1.0454247 | S21: =IF(Q21=1,R21/(R21+R_sharp),0) -> 0.4008646 | T21: =(1-S21)*R21 -> 0.62635094 | U21: =SQRT(T21) -> 0.79142336 | V21: =IF(MOD($A21,Every2)=0,R_s,Alpha_keep^2*V20+Q_var) -> 6.3914063 | W21: =SQRT(V21) -> 2.5281231 | X21: =Alpha_keep^2*X20+Q_var -> 4.8496621 | Y21: =SQRT(X21) -> 2.2021948 | AA21: Proposition 15.1(ii)-(iii): what a reading is worth, and a bias that survives (try your own)
A22: 16 | B22: =IF(AND($A22>0,MOD($A22,Every2)=0),1,0) -> 1 | C22: =Alpha_keep^2*E21+Q_var -> 2.4731517 | D22: =IF(B22=1,C22/(C22+R_s),0) -> 0.28351584 | E22: =(1-D22)*C22 -> 1.771974 | F22: =SQRT(E22) -> 1.3311551 | G22: =IF(AND($A22>0,MOD($A22,Every1)=0),1,0) -> 1 | H22: =Alpha_keep^2*J21+Q_var -> 1.7486396 | I22: =IF(G22=1,H22/(H22+R_s),0) -> 0.21861712 | J22: =(1-I22)*H22 -> 1.366357 | K22: =SQRT(J22) -> 1.1689127 | L22: =IF(AND($A22>0,MOD($A22,Every2)=0),1,0) -> 1 | M22: =Alpha_keep^2*O21+Q_var -> 1.589904 | N22: =IF(L22=1,M22/(M22+R_sharp),0) -> 0.50434653 | O22: =(1-N22)*M22 -> 0.78804145 | P22: =SQRT(O22) -> 0.88771699 | Q22: =IF(AND($A22>0,MOD($A22,Every1)=0),1,0) -> 1 | R22: =Alpha_keep^2*T21+Q_var -> 1.0454249 | S22: =IF(Q22=1,R22/(R22+R_sharp),0) -> 0.40086464 | T22: =(1-S22)*R22 -> 0.626351 | U22: =SQRT(T22) -> 0.7914234 | V22: =IF(MOD($A22,Every2)=0,R_s,Alpha_keep^2*V21+Q_var) -> 6.25 | W22: =SQRT(V22) -> 2.5 | X22: =Alpha_keep^2*X21+Q_var -> 5.06021 | Y22: =SQRT(X22) -> 2.2494911 | AA22: Variance before a reading, P | AB22: 4
A23: 17 | B23: =IF(AND($A23>0,MOD($A23,Every2)=0),1,0) -> 0 | C23: =Alpha_keep^2*E22+Q_var -> 2.1344828 | D23: =IF(B23=1,C23/(C23+R_s),0) -> 0 | E23: =(1-D23)*C23 -> 2.1344828 | F23: =SQRT(E23) -> 1.4609869 | G23: =IF(AND($A23>0,MOD($A23,Every1)=0),1,0) -> 1 | H23: =Alpha_keep^2*J22+Q_var -> 1.7488931 | I23: =IF(G23=1,H23/(H23+R_s),0) -> 0.21864189 | J23: =(1-I23)*H23 -> 1.3665118 | K23: =SQRT(J23) -> 1.168979 | L23: =IF(AND($A23>0,MOD($A23,Every2)=0),1,0) -> 0 | M23: =Alpha_keep^2*O22+Q_var -> 1.1991319 | N23: =IF(L23=1,M23/(M23+R_sharp),0) -> 0 | O23: =(1-N23)*M23 -> 1.1991319 | P23: =SQRT(O23) -> 1.0950488 | Q23: =IF(AND($A23>0,MOD($A23,Every1)=0),1,0) -> 1 | R23: =Alpha_keep^2*T22+Q_var -> 1.0454249 | S23: =IF(Q23=1,R23/(R23+R_sharp),0) -> 0.40086465 | T23: =(1-S23)*R23 -> 0.62635102 | U23: =SQRT(T23) -> 0.79142341 | V23: =IF(MOD($A23,Every2)=0,R_s,Alpha_keep^2*V22+Q_var) -> 6.3914063 | W23: =SQRT(V23) -> 2.5281231 | X23: =Alpha_keep^2*X22+Q_var -> 5.2603622 | Y23: =SQRT(X23) -> 2.2935479 | AA23: The reading's variance | AB23: =R_s -> 6.25
A24: 18 | B24: =IF(AND($A24>0,MOD($A24,Every2)=0),1,0) -> 1 | C24: =Alpha_keep^2*E23+Q_var -> 2.4790927 | D24: =IF(B24=1,C24/(C24+R_s),0) -> 0.28400348 | E24: =(1-D24)*C24 -> 1.7750218 | F24: =SQRT(E24) -> 1.3322994 | G24: =IF(AND($A24>0,MOD($A24,Every1)=0),1,0) -> 1 | H24: =Alpha_keep^2*J23+Q_var -> 1.7490403 | I24: =IF(G24=1,H24/(H24+R_s),0) -> 0.21865627 | J24: =(1-I24)*H24 -> 1.3666017 | K24: =SQRT(J24) -> 1.1690174 | L24: =IF(AND($A24>0,MOD($A24,Every2)=0),1,0) -> 1 | M24: =Alpha_keep^2*O23+Q_var -> 1.5899248 | N24: =IF(L24=1,M24/(M24+R_sharp),0) -> 0.50434979 | O24: =(1-N24)*M24 -> 0.78804654 | P24: =SQRT(O24) -> 0.88771986 | Q24: =IF(AND($A24>0,MOD($A24,Every1)=0),1,0) -> 1 | R24: =Alpha_keep^2*T23+Q_var -> 1.0454249 | S24: =IF(Q24=1,R24/(R24+R_sharp),0) -> 0.40086466 | T24: =(1-S24)*R24 -> 0.62635103 | U24: =SQRT(T24) -> 0.79142342 | V24: =IF(MOD($A24,Every2)=0,R_s,Alpha_keep^2*V23+Q_var) -> 6.25 | W24: =SQRT(V24) -> 2.5 | X24: =Alpha_keep^2*X23+Q_var -> 5.4506318 | Y24: =SQRT(X24) -> 2.3346588 | AA24: Variance after, P r/(P + r) | AB24: =AB22*AB23/(AB22+AB23) -> 2.4390244
A25: 19 | B25: =IF(AND($A25>0,MOD($A25,Every2)=0),1,0) -> 0 | C25: =Alpha_keep^2*E24+Q_var -> 2.1373801 | D25: =IF(B25=1,C25/(C25+R_s),0) -> 0 | E25: =(1-D25)*C25 -> 2.1373801 | F25: =SQRT(E25) -> 1.4619781 | G25: =IF(AND($A25>0,MOD($A25,Every1)=0),1,0) -> 1 | H25: =Alpha_keep^2*J24+Q_var -> 1.7491257 | I25: =IF(G25=1,H25/(H25+R_s),0) -> 0.21866461 | J25: =(1-I25)*H25 -> 1.3666538 | K25: =SQRT(J25) -> 1.1690397 | L25: =IF(AND($A25>0,MOD($A25,Every2)=0),1,0) -> 0 | M25: =Alpha_keep^2*O24+Q_var -> 1.1991367 | N25: =IF(L25=1,M25/(M25+R_sharp),0) -> 0 | O25: =(1-N25)*M25 -> 1.1991367 | P25: =SQRT(O25) -> 1.095051 | Q25: =IF(AND($A25>0,MOD($A25,Every1)=0),1,0) -> 1 | R25: =Alpha_keep^2*T24+Q_var -> 1.0454249 | S25: =IF(Q25=1,R25/(R25+R_sharp),0) -> 0.40086466 | T25: =(1-S25)*R25 -> 0.62635103 | U25: =SQRT(T25) -> 0.79142342 | V25: =IF(MOD($A25,Every2)=0,R_s,Alpha_keep^2*V24+Q_var) -> 6.3914063 | W25: =SQRT(V25) -> 2.5281231 | X25: =Alpha_keep^2*X24+Q_var -> 5.6315068 | Y25: =SQRT(X25) -> 2.3730796 | AA25: Share of P the reading removes, P/(P + r) | AB25: =AB22/(AB22+AB23) -> 0.3902439 | AC25: Large when the twin knows little
A26: 20 | B26: =IF(AND($A26>0,MOD($A26,Every2)=0),1,0) -> 1 | C26: =Alpha_keep^2*E25+Q_var -> 2.4818469 | D26: =IF(B26=1,C26/(C26+R_s),0) -> 0.28422932 | E26: =(1-D26)*C26 -> 1.7764333 | F26: =SQRT(E26) -> 1.332829 | G26: =IF(AND($A26>0,MOD($A26,Every1)=0),1,0) -> 1 | H26: =Alpha_keep^2*J25+Q_var -> 1.7491753 | I26: =IF(G26=1,H26/(H26+R_s),0) -> 0.21866945 | J26: =(1-I26)*H26 -> 1.3666841 | K26: =SQRT(J26) -> 1.1690526 | L26: =IF(AND($A26>0,MOD($A26,Every2)=0),1,0) -> 1 | M26: =Alpha_keep^2*O25+Q_var -> 1.5899294 | N26: =IF(L26=1,M26/(M26+R_sharp),0) -> 0.50435051 | O26: =(1-N26)*M26 -> 0.78804768 | P26: =SQRT(O26) -> 0.88772049 | Q26: =IF(AND($A26>0,MOD($A26,Every1)=0),1,0) -> 1 | R26: =Alpha_keep^2*T25+Q_var -> 1.0454249 | S26: =IF(Q26=1,R26/(R26+R_sharp),0) -> 0.40086466 | T26: =(1-S26)*R26 -> 0.62635103 | U26: =SQRT(T26) -> 0.79142342 | V26: =IF(MOD($A26,Every2)=0,R_s,Alpha_keep^2*V25+Q_var) -> 6.25 | W26: =SQRT(V26) -> 2.5 | X26: =Alpha_keep^2*X25+Q_var -> 5.8034512 | Y26: =SQRT(X26) -> 2.4090353 | AA26: A survey biased by beta0 (points) | AB26: 1 | AC26: Illustration
A27: 21 | B27: =IF(AND($A27>0,MOD($A27,Every2)=0),1,0) -> 0 | C27: =Alpha_keep^2*E26+Q_var -> 2.1387219 | D27: =IF(B27=1,C27/(C27+R_s),0) -> 0 | E27: =(1-D27)*C27 -> 2.1387219 | F27: =SQRT(E27) -> 1.462437 | G27: =IF(AND($A27>0,MOD($A27,Every1)=0),1,0) -> 1 | H27: =Alpha_keep^2*J26+Q_var -> 1.7492041 | I27: =IF(G27=1,H27/(H27+R_s),0) -> 0.21867226 | J27: =(1-I27)*H27 -> 1.3667016 | K27: =SQRT(J27) -> 1.1690602 | L27: =IF(AND($A27>0,MOD($A27,Every2)=0),1,0) -> 0 | M27: =Alpha_keep^2*O26+Q_var -> 1.1991378 | N27: =IF(L27=1,M27/(M27+R_sharp),0) -> 0 | O27: =(1-N27)*M27 -> 1.1991378 | P27: =SQRT(O27) -> 1.0950515 | Q27: =IF(AND($A27>0,MOD($A27,Every1)=0),1,0) -> 1 | R27: =Alpha_keep^2*T26+Q_var -> 1.0454249 | S27: =IF(Q27=1,R27/(R27+R_sharp),0) -> 0.40086466 | T27: =(1-S27)*R27 -> 0.62635103 | U27: =SQRT(T27) -> 0.79142342 | V27: =IF(MOD($A27,Every2)=0,R_s,Alpha_keep^2*V26+Q_var) -> 6.3914063 | W27: =SQRT(V27) -> 2.5281231 | X27: =Alpha_keep^2*X26+Q_var -> 5.9669058 | Y27: =SQRT(X27) -> 2.4427251 | AA27: The twin's mean error just after a survey, K beta0/(1 - (1 - K) a^k), k = 2 | AB27: =AJ6*AB26/(1-(1-AJ6)*Alpha_keep^AB6) -> 0.88950442 | AC27: Online Appendix 15.B, Proposition 15.1(iii)
A28: 22 | B28: =IF(AND($A28>0,MOD($A28,Every2)=0),1,0) -> 1 | C28: =Alpha_keep^2*E27+Q_var -> 2.4831225 | D28: =IF(B28=1,C28/(C28+R_s),0) -> 0.28433387 | E28: =(1-D28)*C28 -> 1.7770867 | F28: =SQRT(E28) -> 1.3330741 | G28: =IF(AND($A28>0,MOD($A28,Every1)=0),1,0) -> 1 | H28: =Alpha_keep^2*J27+Q_var -> 1.7492208 | I28: =IF(G28=1,H28/(H28+R_s),0) -> 0.21867389 | J28: =(1-I28)*H28 -> 1.3667118 | K28: =SQRT(J28) -> 1.1690645 | L28: =IF(AND($A28>0,MOD($A28,Every2)=0),1,0) -> 1 | M28: =Alpha_keep^2*O27+Q_var -> 1.5899304 | N28: =IF(L28=1,M28/(M28+R_sharp),0) -> 0.50435067 | O28: =(1-N28)*M28 -> 0.78804793 | P28: =SQRT(O28) -> 0.88772064 | Q28: =IF(AND($A28>0,MOD($A28,Every1)=0),1,0) -> 1 | R28: =Alpha_keep^2*T27+Q_var -> 1.0454249 | S28: =IF(Q28=1,R28/(R28+R_sharp),0) -> 0.40086466 | T28: =(1-S28)*R28 -> 0.62635103 | U28: =SQRT(T28) -> 0.79142342 | V28: =IF(MOD($A28,Every2)=0,R_s,Alpha_keep^2*V27+Q_var) -> 6.25 | W28: =SQRT(V28) -> 2.5 | X28: =Alpha_keep^2*X27+Q_var -> 6.1222898 | Y28: =SQRT(X28) -> 2.4743261 | AA28: The innovations' mean, beta0 (1 - a^k)/(1 - (1 - K) a^k) | AB28: =AB26*(1-Alpha_keep^AB6)/(1-(1-AJ6)*Alpha_keep^AB6) -> 0.15441486 | AC28: Only part of the bias shows
A29: 23 | B29: =IF(AND($A29>0,MOD($A29,Every2)=0),1,0) -> 0 | C29: =Alpha_keep^2*E28+Q_var -> 2.139343 | D29: =IF(B29=1,C29/(C29+R_s),0) -> 0 | E29: =(1-D29)*C29 -> 2.139343 | F29: =SQRT(E29) -> 1.4626493 | G29: =IF(AND($A29>0,MOD($A29,Every1)=0),1,0) -> 1 | H29: =Alpha_keep^2*J28+Q_var -> 1.7492304 | I29: =IF(G29=1,H29/(H29+R_s),0) -> 0.21867484 | J29: =(1-I29)*H29 -> 1.3667178 | K29: =SQRT(J29) -> 1.169067 | L29: =IF(AND($A29>0,MOD($A29,Every2)=0),1,0) -> 0 | M29: =Alpha_keep^2*O28+Q_var -> 1.1991381 | N29: =IF(L29=1,M29/(M29+R_sharp),0) -> 0 | O29: =(1-N29)*M29 -> 1.1991381 | P29: =SQRT(O29) -> 1.0950516 | Q29: =IF(AND($A29>0,MOD($A29,Every1)=0),1,0) -> 1 | R29: =Alpha_keep^2*T28+Q_var -> 1.0454249 | S29: =IF(Q29=1,R29/(R29+R_sharp),0) -> 0.40086466 | T29: =(1-S29)*R29 -> 0.62635103 | U29: =SQRT(T29) -> 0.79142342 | V29: =IF(MOD($A29,Every2)=0,R_s,Alpha_keep^2*V28+Q_var) -> 6.3914063 | W29: =SQRT(V29) -> 2.5281231 | X29: =Alpha_keep^2*X28+Q_var -> 6.2700017 | Y29: =SQRT(X29) -> 2.5039972 | AA29: as a share of the bias | AB29: =AB28/AB26 -> 0.15441486 | AC29: An audit, an independent reading, finds the rest
A30: 24 | B30: =IF(AND($A30>0,MOD($A30,Every2)=0),1,0) -> 1 | C30: =Alpha_keep^2*E29+Q_var -> 2.4837129 | D30: =IF(B30=1,C30/(C30+R_s),0) -> 0.28438225 | E30: =(1-D30)*C30 -> 1.7773891 | F30: =SQRT(E30) -> 1.3331876 | G30: =IF(AND($A30>0,MOD($A30,Every1)=0),1,0) -> 1 | H30: =Alpha_keep^2*J29+Q_var -> 1.7492361 | I30: =IF(G30=1,H30/(H30+R_s),0) -> 0.21867539 | J30: =(1-I30)*H30 -> 1.3667212 | K30: =SQRT(J30) -> 1.1690685 | L30: =IF(AND($A30>0,MOD($A30,Every2)=0),1,0) -> 1 | M30: =Alpha_keep^2*O29+Q_var -> 1.5899306 | N30: =IF(L30=1,M30/(M30+R_sharp),0) -> 0.50435071 | O30: =(1-N30)*M30 -> 0.78804798 | P30: =SQRT(O30) -> 0.88772067 | Q30: =IF(AND($A30>0,MOD($A30,Every1)=0),1,0) -> 1 | R30: =Alpha_keep^2*T29+Q_var -> 1.0454249 | S30: =IF(Q30=1,R30/(R30+R_sharp),0) -> 0.40086466 | T30: =(1-S30)*R30 -> 0.62635103 | U30: =SQRT(T30) -> 0.79142342 | V30: =IF(MOD($A30,Every2)=0,R_s,Alpha_keep^2*V29+Q_var) -> 6.25 | W30: =SQRT(V30) -> 2.5 | X30: =Alpha_keep^2*X29+Q_var -> 6.4104204 | Y30: =SQRT(X30) -> 2.5318808
A31: 25 | B31: =IF(AND($A31>0,MOD($A31,Every2)=0),1,0) -> 0 | C31: =Alpha_keep^2*E30+Q_var -> 2.1396305 | D31: =IF(B31=1,C31/(C31+R_s),0) -> 0 | E31: =(1-D31)*C31 -> 2.1396305 | F31: =SQRT(E31) -> 1.4627476 | G31: =IF(AND($A31>0,MOD($A31,Every1)=0),1,0) -> 1 | H31: =Alpha_keep^2*J30+Q_var -> 1.7492393 | I31: =IF(G31=1,H31/(H31+R_s),0) -> 0.21867571 | J31: =(1-I31)*H31 -> 1.3667232 | K31: =SQRT(J31) -> 1.1690694 | L31: =IF(AND($A31>0,MOD($A31,Every2)=0),1,0) -> 0 | M31: =Alpha_keep^2*O30+Q_var -> 1.1991381 | N31: =IF(L31=1,M31/(M31+R_sharp),0) -> 0 | O31: =(1-N31)*M31 -> 1.1991381 | P31: =SQRT(O31) -> 1.0950516 | Q31: =IF(AND($A31>0,MOD($A31,Every1)=0),1,0) -> 1 | R31: =Alpha_keep^2*T30+Q_var -> 1.0454249 | S31: =IF(Q31=1,R31/(R31+R_sharp),0) -> 0.40086466 | T31: =(1-S31)*R31 -> 0.62635103 | U31: =SQRT(T31) -> 0.79142342 | V31: =IF(MOD($A31,Every2)=0,R_s,Alpha_keep^2*V30+Q_var) -> 6.3914063 | W31: =SQRT(V31) -> 2.5281231 | X31: =Alpha_keep^2*X30+Q_var -> 6.5439059 | Y31: =SQRT(X31) -> 2.5581059
A32: 26 | B32: =IF(AND($A32>0,MOD($A32,Every2)=0),1,0) -> 1 | C32: =Alpha_keep^2*E31+Q_var -> 2.4839862 | D32: =IF(B32=1,C32/(C32+R_s),0) -> 0.28440464 | E32: =(1-D32)*C32 -> 1.777529 | F32: =SQRT(E32) -> 1.33324 | G32: =IF(AND($A32>0,MOD($A32,Every1)=0),1,0) -> 1 | H32: =Alpha_keep^2*J31+Q_var -> 1.7492412 | I32: =IF(G32=1,H32/(H32+R_s),0) -> 0.21867589 | J32: =(1-I32)*H32 -> 1.3667243 | K32: =SQRT(J32) -> 1.1690699 | L32: =IF(AND($A32>0,MOD($A32,Every2)=0),1,0) -> 1 | M32: =Alpha_keep^2*O31+Q_var -> 1.5899307 | N32: =IF(L32=1,M32/(M32+R_sharp),0) -> 0.50435072 | O32: =(1-N32)*M32 -> 0.788048 | P32: =SQRT(O32) -> 0.88772067 | Q32: =IF(AND($A32>0,MOD($A32,Every1)=0),1,0) -> 1 | R32: =Alpha_keep^2*T31+Q_var -> 1.0454249 | S32: =IF(Q32=1,R32/(R32+R_sharp),0) -> 0.40086466 | T32: =(1-S32)*R32 -> 0.62635103 | U32: =SQRT(T32) -> 0.79142342 | V32: =IF(MOD($A32,Every2)=0,R_s,Alpha_keep^2*V31+Q_var) -> 6.25 | W32: =SQRT(V32) -> 2.5 | X32: =Alpha_keep^2*X31+Q_var -> 6.6708005 | Y32: =SQRT(X32) -> 2.5827893
A33: 27 | B33: =IF(AND($A33>0,MOD($A33,Every2)=0),1,0) -> 0 | C33: =Alpha_keep^2*E32+Q_var -> 2.1397635 | D33: =IF(B33=1,C33/(C33+R_s),0) -> 0 | E33: =(1-D33)*C33 -> 2.1397635 | F33: =SQRT(E33) -> 1.4627931 | G33: =IF(AND($A33>0,MOD($A33,Every1)=0),1,0) -> 1 | H33: =Alpha_keep^2*J32+Q_var -> 1.7492423 | I33: =IF(G33=1,H33/(H33+R_s),0) -> 0.218676 | J33: =(1-I33)*H33 -> 1.366725 | K33: =SQRT(J33) -> 1.1690701 | L33: =IF(AND($A33>0,MOD($A33,Every2)=0),1,0) -> 0 | M33: =Alpha_keep^2*O32+Q_var -> 1.1991381 | N33: =IF(L33=1,M33/(M33+R_sharp),0) -> 0 | O33: =(1-N33)*M33 -> 1.1991381 | P33: =SQRT(O33) -> 1.0950517 | Q33: =IF(AND($A33>0,MOD($A33,Every1)=0),1,0) -> 1 | R33: =Alpha_keep^2*T32+Q_var -> 1.045425 | S33: =IF(Q33=1,R33/(R33+R_sharp),0) -> 0.40086466 | T33: =(1-S33)*R33 -> 0.62635103 | U33: =SQRT(T33) -> 0.79142342 | V33: =IF(MOD($A33,Every2)=0,R_s,Alpha_keep^2*V32+Q_var) -> 6.3914063 | W33: =SQRT(V33) -> 2.5281231 | X33: =Alpha_keep^2*X32+Q_var -> 6.7914298 | Y33: =SQRT(X33) -> 2.6060372
A34: 28 | B34: =IF(AND($A34>0,MOD($A34,Every2)=0),1,0) -> 1 | C34: =Alpha_keep^2*E33+Q_var -> 2.4841127 | D34: =IF(B34=1,C34/(C34+R_s),0) -> 0.284415 | E34: =(1-D34)*C34 -> 1.7775938 | F34: =SQRT(E34) -> 1.3332643 | G34: =IF(AND($A34>0,MOD($A34,Every1)=0),1,0) -> 1 | H34: =Alpha_keep^2*J33+Q_var -> 1.749243 | I34: =IF(G34=1,H34/(H34+R_s),0) -> 0.21867606 | J34: =(1-I34)*H34 -> 1.3667254 | K34: =SQRT(J34) -> 1.1690703 | L34: =IF(AND($A34>0,MOD($A34,Every2)=0),1,0) -> 1 | M34: =Alpha_keep^2*O33+Q_var -> 1.5899307 | N34: =IF(L34=1,M34/(M34+R_sharp),0) -> 0.50435072 | O34: =(1-N34)*M34 -> 0.788048 | P34: =SQRT(O34) -> 0.88772068 | Q34: =IF(AND($A34>0,MOD($A34,Every1)=0),1,0) -> 1 | R34: =Alpha_keep^2*T33+Q_var -> 1.045425 | S34: =IF(Q34=1,R34/(R34+R_sharp),0) -> 0.40086466 | T34: =(1-S34)*R34 -> 0.62635103 | U34: =SQRT(T34) -> 0.79142342 | V34: =IF(MOD($A34,Every2)=0,R_s,Alpha_keep^2*V33+Q_var) -> 6.25 | W34: =SQRT(V34) -> 2.5 | X34: =Alpha_keep^2*X33+Q_var -> 6.9061029 | Y34: =SQRT(X34) -> 2.6279465
A35: 29 | B35: =IF(AND($A35>0,MOD($A35,Every2)=0),1,0) -> 0 | C35: =Alpha_keep^2*E34+Q_var -> 2.1398251 | D35: =IF(B35=1,C35/(C35+R_s),0) -> 0 | E35: =(1-D35)*C35 -> 2.1398251 | F35: =SQRT(E35) -> 1.4628141 | G35: =IF(AND($A35>0,MOD($A35,Every1)=0),1,0) -> 1 | H35: =Alpha_keep^2*J34+Q_var -> 1.7492433 | I35: =IF(G35=1,H35/(H35+R_s),0) -> 0.2186761 | J35: =(1-I35)*H35 -> 1.3667256 | K35: =SQRT(J35) -> 1.1690704 | L35: =IF(AND($A35>0,MOD($A35,Every2)=0),1,0) -> 0 | M35: =Alpha_keep^2*O34+Q_var -> 1.1991381 | N35: =IF(L35=1,M35/(M35+R_sharp),0) -> 0 | O35: =(1-N35)*M35 -> 1.1991381 | P35: =SQRT(O35) -> 1.0950517 | Q35: =IF(AND($A35>0,MOD($A35,Every1)=0),1,0) -> 1 | R35: =Alpha_keep^2*T34+Q_var -> 1.045425 | S35: =IF(Q35=1,R35/(R35+R_sharp),0) -> 0.40086466 | T35: =(1-S35)*R35 -> 0.62635103 | U35: =SQRT(T35) -> 0.79142342 | V35: =IF(MOD($A35,Every2)=0,R_s,Alpha_keep^2*V34+Q_var) -> 6.3914063 | W35: =SQRT(V35) -> 2.5281231 | X35: =Alpha_keep^2*X34+Q_var -> 7.0151141 | Y35: =SQRT(X35) -> 2.6486061
A36: 30 | B36: =IF(AND($A36>0,MOD($A36,Every2)=0),1,0) -> 1 | C36: =Alpha_keep^2*E35+Q_var -> 2.4841712 | D36: =IF(B36=1,C36/(C36+R_s),0) -> 0.2844198 | E36: =(1-D36)*C36 -> 1.7776237 | F36: =SQRT(E36) -> 1.3332756 | G36: =IF(AND($A36>0,MOD($A36,Every1)=0),1,0) -> 1 | H36: =Alpha_keep^2*J35+Q_var -> 1.7492435 | I36: =IF(G36=1,H36/(H36+R_s),0) -> 0.21867612 | J36: =(1-I36)*H36 -> 1.3667258 | K36: =SQRT(J36) -> 1.1690705 | L36: =IF(AND($A36>0,MOD($A36,Every2)=0),1,0) -> 1 | M36: =Alpha_keep^2*O35+Q_var -> 1.5899307 | N36: =IF(L36=1,M36/(M36+R_sharp),0) -> 0.50435072 | O36: =(1-N36)*M36 -> 0.788048 | P36: =SQRT(O36) -> 0.88772068 | Q36: =IF(AND($A36>0,MOD($A36,Every1)=0),1,0) -> 1 | R36: =Alpha_keep^2*T35+Q_var -> 1.045425 | S36: =IF(Q36=1,R36/(R36+R_sharp),0) -> 0.40086466 | T36: =(1-S36)*R36 -> 0.62635103 | U36: =SQRT(T36) -> 0.79142342 | V36: =IF(MOD($A36,Every2)=0,R_s,Alpha_keep^2*V35+Q_var) -> 6.25 | W36: =SQRT(V36) -> 2.5 | X36: =Alpha_keep^2*X35+Q_var -> 7.1187428 | Y36: =SQRT(X36) -> 2.6680972
A37: 31 | B37: =IF(AND($A37>0,MOD($A37,Every2)=0),1,0) -> 0 | C37: =Alpha_keep^2*E36+Q_var -> 2.1398536 | D37: =IF(B37=1,C37/(C37+R_s),0) -> 0 | E37: =(1-D37)*C37 -> 2.1398536 | F37: =SQRT(E37) -> 1.4628238 | G37: =IF(AND($A37>0,MOD($A37,Every1)=0),1,0) -> 1 | H37: =Alpha_keep^2*J36+Q_var -> 1.7492437 | I37: =IF(G37=1,H37/(H37+R_s),0) -> 0.21867613 | J37: =(1-I37)*H37 -> 1.3667258 | K37: =SQRT(J37) -> 1.1690705 | L37: =IF(AND($A37>0,MOD($A37,Every2)=0),1,0) -> 0 | M37: =Alpha_keep^2*O36+Q_var -> 1.1991381 | N37: =IF(L37=1,M37/(M37+R_sharp),0) -> 0 | O37: =(1-N37)*M37 -> 1.1991381 | P37: =SQRT(O37) -> 1.0950517 | Q37: =IF(AND($A37>0,MOD($A37,Every1)=0),1,0) -> 1 | R37: =Alpha_keep^2*T36+Q_var -> 1.045425 | S37: =IF(Q37=1,R37/(R37+R_sharp),0) -> 0.40086466 | T37: =(1-S37)*R37 -> 0.62635103 | U37: =SQRT(T37) -> 0.79142342 | V37: =IF(MOD($A37,Every2)=0,R_s,Alpha_keep^2*V36+Q_var) -> 6.3914063 | W37: =SQRT(V37) -> 2.5281231 | X37: =Alpha_keep^2*X36+Q_var -> 7.2172549 | Y37: =SQRT(X37) -> 2.6864949
A38: 32 | B38: =IF(AND($A38>0,MOD($A38,Every2)=0),1,0) -> 1 | C38: =Alpha_keep^2*E37+Q_var -> 2.4841983 | D38: =IF(B38=1,C38/(C38+R_s),0) -> 0.28442202 | E38: =(1-D38)*C38 -> 1.7776376 | F38: =SQRT(E38) -> 1.3332808 | G38: =IF(AND($A38>0,MOD($A38,Every1)=0),1,0) -> 1 | H38: =Alpha_keep^2*J37+Q_var -> 1.7492437 | I38: =IF(G38=1,H38/(H38+R_s),0) -> 0.21867614 | J38: =(1-I38)*H38 -> 1.3667259 | K38: =SQRT(J38) -> 1.1690705 | L38: =IF(AND($A38>0,MOD($A38,Every2)=0),1,0) -> 1 | M38: =Alpha_keep^2*O37+Q_var -> 1.5899307 | N38: =IF(L38=1,M38/(M38+R_sharp),0) -> 0.50435072 | O38: =(1-N38)*M38 -> 0.788048 | P38: =SQRT(O38) -> 0.88772068 | Q38: =IF(AND($A38>0,MOD($A38,Every1)=0),1,0) -> 1 | R38: =Alpha_keep^2*T37+Q_var -> 1.045425 | S38: =IF(Q38=1,R38/(R38+R_sharp),0) -> 0.40086466 | T38: =(1-S38)*R38 -> 0.62635103 | U38: =SQRT(T38) -> 0.79142342 | V38: =IF(MOD($A38,Every2)=0,R_s,Alpha_keep^2*V37+Q_var) -> 6.25 | W38: =SQRT(V38) -> 2.5 | X38: =Alpha_keep^2*X37+Q_var -> 7.3109029 | Y38: =SQRT(X38) -> 2.7038681
A39: 33 | B39: =IF(AND($A39>0,MOD($A39,Every2)=0),1,0) -> 0 | C39: =Alpha_keep^2*E38+Q_var -> 2.1398668 | D39: =IF(B39=1,C39/(C39+R_s),0) -> 0 | E39: =(1-D39)*C39 -> 2.1398668 | F39: =SQRT(E39) -> 1.4628283 | G39: =IF(AND($A39>0,MOD($A39,Every1)=0),1,0) -> 1 | H39: =Alpha_keep^2*J38+Q_var -> 1.7492438 | I39: =IF(G39=1,H39/(H39+R_s),0) -> 0.21867614 | J39: =(1-I39)*H39 -> 1.3667259 | K39: =SQRT(J39) -> 1.1690705 | L39: =IF(AND($A39>0,MOD($A39,Every2)=0),1,0) -> 0 | M39: =Alpha_keep^2*O38+Q_var -> 1.1991381 | N39: =IF(L39=1,M39/(M39+R_sharp),0) -> 0 | O39: =(1-N39)*M39 -> 1.1991381 | P39: =SQRT(O39) -> 1.0950517 | Q39: =IF(AND($A39>0,MOD($A39,Every1)=0),1,0) -> 1 | R39: =Alpha_keep^2*T38+Q_var -> 1.045425 | S39: =IF(Q39=1,R39/(R39+R_sharp),0) -> 0.40086466 | T39: =(1-S39)*R39 -> 0.62635103 | U39: =SQRT(T39) -> 0.79142342 | V39: =IF(MOD($A39,Every2)=0,R_s,Alpha_keep^2*V38+Q_var) -> 6.3914063 | W39: =SQRT(V39) -> 2.5281231 | X39: =Alpha_keep^2*X38+Q_var -> 7.3999271 | Y39: =SQRT(X39) -> 2.7202807
A40: 34 | B40: =IF(AND($A40>0,MOD($A40,Every2)=0),1,0) -> 1 | C40: =Alpha_keep^2*E39+Q_var -> 2.4842108 | D40: =IF(B40=1,C40/(C40+R_s),0) -> 0.28442304 | E40: =(1-D40)*C40 -> 1.777644 | F40: =SQRT(E40) -> 1.3332832 | G40: =IF(AND($A40>0,MOD($A40,Every1)=0),1,0) -> 1 | H40: =Alpha_keep^2*J39+Q_var -> 1.7492438 | I40: =IF(G40=1,H40/(H40+R_s),0) -> 0.21867615 | J40: =(1-I40)*H40 -> 1.3667259 | K40: =SQRT(J40) -> 1.1690705 | L40: =IF(AND($A40>0,MOD($A40,Every2)=0),1,0) -> 1 | M40: =Alpha_keep^2*O39+Q_var -> 1.5899307 | N40: =IF(L40=1,M40/(M40+R_sharp),0) -> 0.50435072 | O40: =(1-N40)*M40 -> 0.788048 | P40: =SQRT(O40) -> 0.88772068 | Q40: =IF(AND($A40>0,MOD($A40,Every1)=0),1,0) -> 1 | R40: =Alpha_keep^2*T39+Q_var -> 1.045425 | S40: =IF(Q40=1,R40/(R40+R_sharp),0) -> 0.40086466 | T40: =(1-S40)*R40 -> 0.62635103 | U40: =SQRT(T40) -> 0.79142342 | V40: =IF(MOD($A40,Every2)=0,R_s,Alpha_keep^2*V39+Q_var) -> 6.25 | W40: =SQRT(V40) -> 2.5 | X40: =Alpha_keep^2*X39+Q_var -> 7.4845557 | Y40: =SQRT(X40) -> 2.7357916
A41: 35 | B41: =IF(AND($A41>0,MOD($A41,Every2)=0),1,0) -> 0 | C41: =Alpha_keep^2*E40+Q_var -> 2.1398729 | D41: =IF(B41=1,C41/(C41+R_s),0) -> 0 | E41: =(1-D41)*C41 -> 2.1398729 | F41: =SQRT(E41) -> 1.4628304 | G41: =IF(AND($A41>0,MOD($A41,Every1)=0),1,0) -> 1 | H41: =Alpha_keep^2*J40+Q_var -> 1.7492438 | I41: =IF(G41=1,H41/(H41+R_s),0) -> 0.21867615 | J41: =(1-I41)*H41 -> 1.3667259 | K41: =SQRT(J41) -> 1.1690705 | L41: =IF(AND($A41>0,MOD($A41,Every2)=0),1,0) -> 0 | M41: =Alpha_keep^2*O40+Q_var -> 1.1991381 | N41: =IF(L41=1,M41/(M41+R_sharp),0) -> 0 | O41: =(1-N41)*M41 -> 1.1991381 | P41: =SQRT(O41) -> 1.0950517 | Q41: =IF(AND($A41>0,MOD($A41,Every1)=0),1,0) -> 1 | R41: =Alpha_keep^2*T40+Q_var -> 1.045425 | S41: =IF(Q41=1,R41/(R41+R_sharp),0) -> 0.40086466 | T41: =(1-S41)*R41 -> 0.62635103 | U41: =SQRT(T41) -> 0.79142342 | V41: =IF(MOD($A41,Every2)=0,R_s,Alpha_keep^2*V40+Q_var) -> 6.3914063 | W41: =SQRT(V41) -> 2.5281231 | X41: =Alpha_keep^2*X40+Q_var -> 7.5650058 | Y41: =SQRT(X41) -> 2.7504556
...

Sheet Decide
A1: Decide on the twin: each design's best target and its cost (Theorem 15.2; Proposition 15.2; Worked Example 15.1, Steps 3 and 6; Table 15.3; Figure 15.2(a); AXIOM Lab 2.15, step 2)
A2: Mean costs from 58 on the 20,000 design paths (seed 1500) for seven targets around the book's best, and the best target's cost on the 100,000 fresh paths (seed 1501), are the engine's; every design runs on the same draws. The best targets, costs above the count and their yearly worth are formulas.
A4: Design | B4: Survey | C4: The book's best (window centre) | D4: Target 1 | E4: Target 2 | F4: Target 3 | G4: Target 4 | H4: Target 5 | I4: Target 6 | J4: Target 7 | K4: Design-path cost 1 (engine) | L4: Design-path cost 2 (engine) | M4: Design-path cost 3 (engine) | N4: Design-path cost 4 (engine) | O4: Design-path cost 5 (engine) | P4: Design-path cost 6 (engine) | Q4: Design-path cost 7 (engine) | R4: Best target | S4: Its design-path cost | T4: Margin over 55 | U4: Inside the window (1 = yes)
A5: Count (Chapter 7) | B5: -- | C5: 55.75 | D5: =ROUND($C5+0.05*(0-3),2) -> 55.6 | E5: =ROUND($C5+0.05*(1-3),2) -> 55.65 | F5: =ROUND($C5+0.05*(2-3),2) -> 55.7 | G5: =ROUND($C5+0.05*(3-3),2) -> 55.75 | H5: =ROUND($C5+0.05*(4-3),2) -> 55.8 | I5: =ROUND($C5+0.05*(5-3),2) -> 55.85 | J5: =ROUND($C5+0.05*(6-3),2) -> 55.9 | K5: 231.93434 | L5: 231.52444 | M5: 231.12612 | N5: 230.74711 | O5: 230.94972 | P5: 231.15233 | Q5: 231.35565 | R5: =INDEX(D5:J5,MATCH(MIN(K5:Q5),K5:Q5,0)) -> 55.75 | S5: =MIN(K5:Q5) -> 230.74711 | T5: =R5-Floor_c -> 0.75 | U5: =IF(AND(R5>D5,R5<J5),1,0) -> 1
A6: Twin | B6: twice a year | C6: 56.7 | D6: =ROUND($C6+0.05*(0-3),2) -> 56.55 | E6: =ROUND($C6+0.05*(1-3),2) -> 56.6 | F6: =ROUND($C6+0.05*(2-3),2) -> 56.65 | G6: =ROUND($C6+0.05*(3-3),2) -> 56.7 | H6: =ROUND($C6+0.05*(4-3),2) -> 56.75 | I6: =ROUND($C6+0.05*(5-3),2) -> 56.8 | J6: =ROUND($C6+0.05*(6-3),2) -> 56.85 | K6: 241.95481 | L6: 241.89726 | M6: 241.86329 | N6: 241.85194 | O6: 241.86227 | P6: 241.89345 | Q6: 241.94486 | R6: =INDEX(D6:J6,MATCH(MIN(K6:Q6),K6:Q6,0)) -> 56.7 | S6: =MIN(K6:Q6) -> 241.85194 | T6: =R6-Floor_c -> 1.7 | U6: =IF(AND(R6>D6,R6<J6),1,0) -> 1
A7: Survey read as exact | B7: twice a year | C7: 57.35 | D7: =ROUND($C7+0.05*(0-3),2) -> 57.2 | E7: =ROUND($C7+0.05*(1-3),2) -> 57.25 | F7: =ROUND($C7+0.05*(2-3),2) -> 57.3 | G7: =ROUND($C7+0.05*(3-3),2) -> 57.35 | H7: =ROUND($C7+0.05*(4-3),2) -> 57.4 | I7: =ROUND($C7+0.05*(5-3),2) -> 57.45 | J7: =ROUND($C7+0.05*(6-3),2) -> 57.5 | K7: 246.77565 | L7: 246.73164 | M7: 246.70558 | N7: 246.69617 | O7: 246.70279 | P7: 246.72531 | Q7: 246.76318 | R7: =INDEX(D7:J7,MATCH(MIN(K7:Q7),K7:Q7,0)) -> 57.35 | S7: =MIN(K7:Q7) -> 246.69617 | T7: =R7-Floor_c -> 2.35 | U7: =IF(AND(R7>D7,R7<J7),1,0) -> 1
A8: Twin | B8: quarterly | C8: 56.5 | D8: =ROUND($C8+0.05*(0-3),2) -> 56.35 | E8: =ROUND($C8+0.05*(1-3),2) -> 56.4 | F8: =ROUND($C8+0.05*(2-3),2) -> 56.45 | G8: =ROUND($C8+0.05*(3-3),2) -> 56.5 | H8: =ROUND($C8+0.05*(4-3),2) -> 56.55 | I8: =ROUND($C8+0.05*(5-3),2) -> 56.6 | J8: =ROUND($C8+0.05*(6-3),2) -> 56.65 | K8: 239.50723 | L8: 239.43437 | M8: 239.38921 | N8: 239.3707 | O8: 239.3777 | P8: 239.41885 | Q8: 239.48318 | R8: =INDEX(D8:J8,MATCH(MIN(K8:Q8),K8:Q8,0)) -> 56.5 | S8: =MIN(K8:Q8) -> 239.3707 | T8: =R8-Floor_c -> 1.5 | U8: =IF(AND(R8>D8,R8<J8),1,0) -> 1
A9: Twin | B9: twice as sharp | C9: 56.4 | D9: =ROUND($C9+0.05*(0-3),2) -> 56.25 | E9: =ROUND($C9+0.05*(1-3),2) -> 56.3 | F9: =ROUND($C9+0.05*(2-3),2) -> 56.35 | G9: =ROUND($C9+0.05*(3-3),2) -> 56.4 | H9: =ROUND($C9+0.05*(4-3),2) -> 56.45 | I9: =ROUND($C9+0.05*(5-3),2) -> 56.5 | J9: =ROUND($C9+0.05*(6-3),2) -> 56.55 | K9: 237.84776 | L9: 237.79065 | M9: 237.76239 | N9: 237.7612 | O9: 237.78608 | P9: 237.83843 | Q9: 237.91829 | R9: =INDEX(D9:J9,MATCH(MIN(K9:Q9),K9:Q9,0)) -> 56.4 | S9: =MIN(K9:Q9) -> 237.7612 | T9: =R9-Floor_c -> 1.4 | U9: =IF(AND(R9>D9,R9<J9),1,0) -> 1
A10: Twin | B10: both | C10: 56.2 | D10: =ROUND($C10+0.05*(0-3),2) -> 56.05 | E10: =ROUND($C10+0.05*(1-3),2) -> 56.1 | F10: =ROUND($C10+0.05*(2-3),2) -> 56.15 | G10: =ROUND($C10+0.05*(3-3),2) -> 56.2 | H10: =ROUND($C10+0.05*(4-3),2) -> 56.25 | I10: =ROUND($C10+0.05*(5-3),2) -> 56.3 | J10: =ROUND($C10+0.05*(6-3),2) -> 56.35 | K10: 235.79247 | L10: 235.71695 | M10: 235.67584 | N10: 235.66761 | O10: 235.69055 | P10: 235.74263 | Q10: 235.82242 | R10: =INDEX(D10:J10,MATCH(MIN(K10:Q10),K10:Q10,0)) -> 56.2 | S10: =MIN(K10:Q10) -> 235.66761 | T10: =R10-Floor_c -> 1.2 | U10: =IF(AND(R10>D10,R10<J10),1,0) -> 1
A11: No readings after the audit | B11: none | C11: 57.8 | D11: =ROUND($C11+0.05*(0-3),2) -> 57.65 | E11: =ROUND($C11+0.05*(1-3),2) -> 57.7 | F11: =ROUND($C11+0.05*(2-3),2) -> 57.75 | G11: =ROUND($C11+0.05*(3-3),2) -> 57.8 | H11: =ROUND($C11+0.05*(4-3),2) -> 57.85 | I11: =ROUND($C11+0.05*(5-3),2) -> 57.9 | J11: =ROUND($C11+0.05*(6-3),2) -> 57.95 | K11: 256.2146 | L11: 256.17753 | M11: 256.15423 | N11: 256.14506 | O11: 256.15012 | P11: 256.16914 | Q11: 256.20106 | R11: =INDEX(D11:J11,MATCH(MIN(K11:Q11),K11:Q11,0)) -> 57.8 | S11: =MIN(K11:Q11) -> 256.14506 | T11: =R11-Floor_c -> 2.8 | U11: =IF(AND(R11>D11,R11<J11),1,0) -> 1
A14: Design (100,000 fresh paths) | B14: Survey | C14: Target | D14: Cost from 58 (engine) | E14: Standard error (engine) | F14: Above the count | G14: Below the floor (engine) | H14: Worth a year, 4(1 - beta) x above | I14: Decisions at a hiring limit (engine)
A15: Count (Chapter 7) | B15: -- | C15: =R5 -> 55.75 | D15: 230.84371 | E15: 0.039547474 | F15: =D15-$D$15 -> 0 | G15: 0.060240023 | H15: =F15*4*(1-Beta_q) -> 0 | I15: 0.098035818
A16: Twin | B16: twice a year | C16: =R6 -> 56.7 | D16: 241.94431 | E16: 0.04159791 | F16: =D16-$D$15 -> 11.100596 | G16: 0.13374932 | H16: =F16*4*(1-Beta_q) -> 1.0454945 | I16: 0.069679568
A17: Survey read as exact | B17: twice a year | C17: =R7 -> 57.35 | D17: 246.79345 | E17: 0.041305416 | F17: =D17-$D$15 -> 15.949739 | G17: 0.13253332 | H17: =F17*4*(1-Beta_q) -> 1.5022045 | I17: 0.55689134
A18: Twin | B18: quarterly | C18: =R8 -> 56.5 | D18: 239.47751 | E18: 0.04049514 | F18: =D18-$D$15 -> 8.6337998 | G18: 0.12964216 | H18: =F18*4*(1-Beta_q) -> 0.8131627 | I18: 0.047302477
A19: Twin | B19: twice as sharp | C19: =R9 -> 56.4 | D19: 237.84907 | E19: 0.039861352 | F19: =D19-$D$15 -> 7.0053579 | G19: 0.12090391 | H19: =F19*4*(1-Beta_q) -> 0.65979011 | I19: 0.08278825
A20: Twin | B20: both | C20: =R10 -> 56.2 | D20: 235.76493 | E20: 0.039611139 | F20: =D20-$D$15 -> 4.9212146 | G20: 0.12220405 | H20: =F20*4*(1-Beta_q) -> 0.46349791 | I20: 0.057182091
A21: No readings after the audit | B21: none | C21: =R11 -> 57.8 | D21: 256.27706 | E21: 0.063087675 | F21: =D21-$D$15 -> 25.433345 | G21: 0.17617077 | H21: =F21*4*(1-Beta_q) -> 2.3954051 | I21: 0
A22: Twin, Chapter 7's target | B22: twice a year | C22: =Target7 -> 55.75 | D22: 247.15716 | F22: =D22-$D$15 -> 16.313442 | G22: 0.3132032 | H22: =F22*4*(1-Beta_q) -> 1.5364594
A23: Survey read as exact, Chapter 7's target | B23: twice a year | C23: =Target7 -> 55.75 | D23: 258.35238 | F23: =D23-$D$15 -> 27.508661 | G23: 0.38606593 | H23: =F23*4*(1-Beta_q) -> 2.5908659
A24: Survey read as exact, the whole error guarded | B24: twice a year | C24: =Target7+5 -> 60.75 | D24: 265.23979 | F24: =D24-$D$15 -> 34.396076 | G24: 0.0021979091 | H24: =F24*4*(1-Beta_q) -> 3.2395477
A25: 60.75 guards the survey's whole error, the five planned points Chapter 7 priced.
A27: Theorem 15.2(i): count < both < quarterly, sharper < twin < survey as exact < no readings (1 = yes) | B27: =IF(AND(D15<D20,D20<MIN(D19,D18),MAX(D19,D18)<D16,D16<D17,D17<D21),1,0) -> 1 | C27: Readings never cost
A28: The twin costs less than the survey read as exact by | B28: =F17-F16 -> 4.8491427 | C28: $4.8 million (the abstract)
A29: Proposition 15.2(i): the twin's target on its design paths | B29: =S6 -> 241.85194 | C29: 241.85
A30: on the fresh paths | B30: =D16 -> 241.94431 | C30: 241.94
A31: the design paths' standard error (engine) | B31: 0.092789062
A32: the difference, in standard errors | B32: =(B30-B29)/SQRT(B31^2+E16^2) -> 0.90841493 | C32: Within the simulation's error (Step 6)
A35: Theorem 15.2(iii): the margin is the (1 - k/b)-quantile of the swing less the twin's error
A36: k: holding a planned point a quarter, 4(1 - a beta) | B36: =Cost_k*(1-Alpha_keep*Beta_q) -> 0.19182905 | C36: Chapter 7
A37: b: a point short next quarter, 1.6 beta | B37: =Short_p*Beta_q -> 1.5623265
A38: Critical ratio k/b | B38: =B36/B37 -> 0.12278422 | C38: 0.1228 (Chapter 7)
A39: 1 - k/b | B39: =1-B38 -> 0.87721578
A41: Swing w, ascending | B41: Chance | C41: P(w <= x)
A42: =SMALL(Loss_w,1) -> -1.5 | B42: =SUMPRODUCT((Loss_w=A42)*Loss_p) -> 0.05 | C42: =SUM($B$42:B42) -> 0.05
A43: =SMALL(Loss_w,2) -> -0.75 | B43: =SUMPRODUCT((Loss_w=A43)*Loss_p) -> 0.2 | C43: =SUM($B$42:B43) -> 0.25
A44: =SMALL(Loss_w,3) -> 0 | B44: =SUMPRODUCT((Loss_w=A44)*Loss_p) -> 0.5 | C44: =SUM($B$42:B44) -> 0.75
A45: =SMALL(Loss_w,4) -> 0.75 | B45: =SUMPRODUCT((Loss_w=A45)*Loss_p) -> 0.2 | C45: =SUM($B$42:B45) -> 0.95
A46: =SMALL(Loss_w,5) -> 1.5 | B46: =SUMPRODUCT((Loss_w=A46)*Loss_p) -> 0.05 | C46: =SUM($B$42:B46) -> 1
A48: On the count, the swing's (1 - k/b)-quantile: the margin | B48: =INDEX(A42:A46,COUNTIF(C42:C46,"<"&B39)+1) -> 0.75 | C48: 0.75: Chapter 7's margin
...

Sheet Program
A1: One program from the audited 58, run by the twin (Figure 15.1(a); seed 1503; Worked Example 15.1, Step 2; AXIOM Lab 2.15, step 1)
A2: The swings w and the survey's standard errors e are the engine's draws for seed 1503; everything else is a formula: capability, the readings z = c + 2.5 e, the filter, the twin's hires to its target, the costs, and the survey read as exact on the same readings and hires.
A4: Quarter | B4: Swing w (engine) | C4: Survey draw e (engine) | D4: Survey (1 = yes) | E4: Capability c | F4: Reading z | G4: Prior P- | H4: Gain K | I4: Posterior P | J4: Predicted estimate | K4: The twin's estimate | L4: Its error (sd) | M4: Hire h | N4: Quarter's cost | O4: Discount | P4: Present value | Q4: Survey read as exact | R4: Twin's error | S4: Survey-as-exact error
A5: 0 | B5: -0.75 | C5: 0.47995665 | D5: =IF(AND(A5>0,MOD(A5,Every2)=0),1,0) -> 0 | E5: =Start_c -> 58 | F5: =IF(D5=1,E5+SD_s*C5,"") | G5: 0 | H5: =IF(D5=1,G5/(G5+R_s),0) -> 0 | I5: =(1-H5)*G5 -> 0 | J5: =Start_c -> 58 | K5: =IF(D5=1,J5+H5*(F5-J5),J5) -> 58 | L5: =SQRT(I5) -> 0 | M5: =MIN(MAX($V$5-Alpha_keep*K5,0),Cap_h) -> 0.15 | N5: =Cost_k*M5+Short_p*MAX(Floor_c-E5,0) -> 0.6 | O5: =Beta_q^A5 -> 1 | P5: =N5*O5 -> 0.6 | Q5: =Start_c -> 58 | R5: =K5-E5 -> 0 | S5: =Q5-E5 -> 0 | U5: The twin's target (Decide) | V5: =Decide!R6 -> 56.7 | W5: 56.70
A6: 1 | B6: 0 | C6: -0.55002131 | D6: =IF(AND(A6>0,MOD(A6,Every2)=0),1,0) -> 0 | E6: =Alpha_keep*E5+M5-B5 -> 57.45 | F6: =IF(D6=1,E6+SD_s*C6,"") | G6: =Alpha_keep^2*I5+Q_var -> 0.45 | H6: =IF(D6=1,G6/(G6+R_s),0) -> 0 | I6: =(1-H6)*G6 -> 0.45 | J6: =Alpha_keep*K5+M5 -> 56.7 | K6: =IF(D6=1,J6+H6*(F6-J6),J6) -> 56.7 | L6: =SQRT(I6) -> 0.67082039 | M6: =MIN(MAX($V$5-Alpha_keep*K6,0),Cap_h) -> 1.4175 | N6: =Cost_k*M6+Short_p*MAX(Floor_c-E6,0) -> 5.67 | O6: =Beta_q^A6 -> 0.97645409 | P6: =N6*O6 -> 5.5364947 | Q6: =IF(D6=1,F6,Alpha_keep*Q5+M5) -> 56.7 | R6: =K6-E6 -> -0.75 | S6: =Q6-E6 -> -0.75 | U6: Present value of 25 quarters' costs | V6: =SUM(P5:P29) -> 107.4387
A7: 2 | B7: 0.75 | C7: 1.6331364 | D7: =IF(AND(A7>0,MOD(A7,Every2)=0),1,0) -> 1 | E7: =Alpha_keep*E6+M6-B6 -> 57.43125 | F7: =IF(D7=1,E7+SD_s*C7,"") -> 61.514091 | G7: =Alpha_keep^2*I6+Q_var -> 0.87778125 | H7: =IF(D7=1,G7/(G7+R_s),0) -> 0.1231493 | I7: =(1-H7)*G7 -> 0.76968311 | J7: =Alpha_keep*K6+M6 -> 56.7 | K7: =IF(D7=1,J7+H7*(F7-J7),J7) -> 57.292852 | L7: =SQRT(I7) -> 0.87731585 | M7: =MIN(MAX($V$5-Alpha_keep*K7,0),Cap_h) -> 0.83946938 | N7: =Cost_k*M7+Short_p*MAX(Floor_c-E7,0) -> 3.3578775 | O7: =Beta_q^A7 -> 0.95346259 | P7: =N7*O7 -> 3.2016106 | Q7: =IF(D7=1,F7,Alpha_keep*Q6+M6) -> 61.514091 | R7: =K7-E7 -> -0.13839808 | S7: =Q7-E7 -> 4.082841 | U7: The twin's estimate at quarter 24 | V7: =K29 -> 55.301895
A8: 3 | B8: -0.75 | C8: -0.22515684 | D8: =IF(AND(A8>0,MOD(A8,Every2)=0),1,0) -> 0 | E8: =Alpha_keep*E7+M7-B7 -> 56.084938 | F8: =IF(D8=1,E8+SD_s*C8,"") | G8: =Alpha_keep^2*I7+Q_var -> 1.18168 | H8: =IF(D8=1,G8/(G8+R_s),0) -> 0 | I8: =(1-H8)*G8 -> 1.18168 | J8: =Alpha_keep*K7+M7 -> 56.7 | K8: =IF(D8=1,J8+H8*(F8-J8),J8) -> 56.7 | L8: =SQRT(I8) -> 1.0870511 | M8: =MIN(MAX($V$5-Alpha_keep*K8,0),Cap_h) -> 1.4175 | N8: =Cost_k*M8+Short_p*MAX(Floor_c-E8,0) -> 5.67 | O8: =Beta_q^A8 -> 0.93101244 | P8: =N8*O8 -> 5.2788406 | Q8: =IF(D8=1,F8,Alpha_keep*Q7+M7) -> 60.815708 | R8: =K8-E8 -> 0.61506187 | S8: =Q8-E8 -> 4.7307699 | U8: Its error at quarter 24 (sd) | V8: =L29 -> 1.3331876
A9: 4 | B9: -0.75 | C9: -0.14443599 | D9: =IF(AND(A9>0,MOD(A9,Every2)=0),1,0) -> 1 | E9: =Alpha_keep*E8+M8-B8 -> 56.850315 | F9: =IF(D9=1,E9+SD_s*C9,"") -> 56.489225 | G9: =Alpha_keep^2*I8+Q_var -> 1.5733346 | H9: =IF(D9=1,G9/(G9+R_s),0) -> 0.20110792 | I9: =(1-H9)*G9 -> 1.2569245 | J9: =Alpha_keep*K8+M8 -> 56.7 | K9: =IF(D9=1,J9+H9*(F9-J9),J9) -> 56.657611 | L9: =SQRT(I9) -> 1.1211264 | M9: =MIN(MAX($V$5-Alpha_keep*K9,0),Cap_h) -> 1.4588289 | N9: =Cost_k*M9+Short_p*MAX(Floor_c-E9,0) -> 5.8353155 | O9: =Beta_q^A9 -> 0.90909091 | P9: =N9*O9 -> 5.3048322 | Q9: =IF(D9=1,F9,Alpha_keep*Q8+M8) -> 56.489225 | R9: =K9-E9 -> -0.19270326 | S9: =Q9-E9 -> -0.36108998 | U9: The twin's largest error | V9: =MAX(MAX(R5:R29),-MIN(R5:R29)) -> 3.2212689
