Workbook

Sheet README
B1: DCT Laboratory — Vol I, Ch 6: Enterprise Transformation Operators
B2: Seed 26106 · Companion to DCT_V1_Ch06_Lab.ipynb and AXIOM Lab 1.6 (module AXIOM-06). Money in $ million.
B4: Worked Example 6.1, Strategy or Trade? Meridian's Automation Playbook, with the book's declarations, and the five steps of AXIOM Lab 1.6, Sequencing Meridian's Moves.
B5: Declarations: Meridian today (Table 3.1), the board's floor (Table 5.4), the automation round (Worked Example 6.1), the sale (Worked Example 3.1), the digital build (Worked Example 1.1, computed with the Chapter 1 model), and the target.
B6: Operators: each move's domain and effect from today, Figure 6.1's states, and why the sale is a family of two (Definitions 6.1-6.4; Proposition 6.1; Theorem 6.1; lab step 1).
B7: Policy: the bank's rule of Online Appendix Example 6.B.1, a family made a closed-loop system (Theorem 6.1(iii)).
B8: Programs: all sixteen two-move sequences, seam by seam, and Section 6.5's sale, two rounds, then the build (Theorem 6.2(iii); Proposition 6.5; Figure 6.3; lab step 2).
B9: Playbook: the automation round year by year, savings paid out, recycled and short of plan, with Table 6.4, the nested domains and the sustainable core (Equation 6.2; Theorem 6.3; Figure 6.2; lab step 3).
B10: Reachability: every program of up to four moves, the reachable sets R_k to closure, targets and a cushion you can change, and complete goals with tolerances (Theorem 6.4; Remark 6.B.3; lab step 4).
B11: Stability: the drift bound and its worst case, and the playbook's steady states short of plan (Theorem 6.5; Equation 6.4; Figure 6.4; Remark 6.B.2; Worked Example 6.1, Step 4; lab step 5).
B12: Every result is a formula of the declarations. Reference_Values and Checks: the notebook engine's numbers and a PASS/FAIL comparison with this workbook's formulas.
B14: LEGEND
... B18: Cross-sheet link: green.

Sheet Declarations
A1: Declarations (Worked Example 6.1, Step 1; Worked Example 3.1; Figure 6.3). Money in $ million; indices from 0 to 100.
A3: Quantity | B3: Value | C3: Source
A4: Liquidity today | B4: 620 | C4: Table 3.1
A5: Technology platform today (index) | B5: 41 | C5: Table 3.1
A6: Workforce capability today (index) | B6: 58 | C6: Table 3.1
A7: Operational efficiency today (index) | B7: 71 | C7: Table 3.1
A8: The board's liquidity floor | B8: 350 | C8: Table 5.4
A10: Automation round: cost | B10: 120 | C10: Worked Example 6.1
A11: Automation round: the plants' technical ceiling on efficiency | B11: 85 | C11: Worked Example 6.1
A12: Automation round: share of the gap to the ceiling closed | B12: 0.5 | C12: Worked Example 6.1: half of the gap
A13: Workforce capability needed to staff the automated lines | B13: 55 | C13: Worked Example 6.1, Step 1
A14: Workforce capability added by a round's retraining | B14: 1 | C14: Worked Example 6.1
A15: Value of an efficiency point gained over today, a year | B15: 10 | C15: Worked Example 6.1: $10 million a year in lower costs
A16: Liquidity a round needs: floor + cost | B16: =B8+B10 -> 470 | C16: Worked Example 6.1, Step 1: $470 million, so the floor holds after the round
A18: Sale of part of Industrial Systems, engineers leave: net proceeds | B18: 112 | C18: Worked Example 3.1
A19: Sale, engineers kept: net proceeds | B19: 92 | C19: Worked Example 3.1: $20 million less
A20: Share of the technology position the unit takes | B20: 0.1 | C20: Worked Example 3.1
A21: Workforce capability lost if the engineers leave | B21: 5 | C21: Worked Example 3.1
A23: Digital build: liquidity change over five years | B23: =(G37-B37)*Liq_today/100 -> -35.367271 | C23: Worked Example 1.1; Table 1.9: computed below with the Chapter 1 model
A24: Digital build: technology change over five years (points) | B24: =G38-B38 -> 34.634669 | C24: Worked Example 1.1; Table 1.9
A25: Digital build: efficiency change over five years (points) | B25: =G39-B39 -> 2.598331 | C25: Worked Example 1.1; Table 1.9
A26: Digital build: low point below its starting liquidity | B26: =(100-B50)*Liq_today/100 -> 138.08206 | C26: Worked Example 1.1: cash bottoms around month 21
A27: Liquidity the build needs: floor + its low point | B27: =B8+B26 -> 488.08206 | C27: $488 million, so the floor holds at the build's low point
A28: Technology target | B28: 70 | C28: Figure 6.3: at least 70, with every constraint met
A29: Efficiency target | B29: 80 | C29: Figure 6.3: at least 80
A31: Move codes on the other sheets: 1 = S, sell, engineers leave; 2 = S*, sell, engineers kept; 3 = D, digital build; 4 = A, automation round.
A32: Domains: S and S* need the unit unsold; D needs the platform unbuilt, workforce capability of at least 55, and liquidity of at least floor + its low point, so the floor holds on the way; A needs workforce capability of at least 55 and liquidity of at least floor + cost.
A34: The digital build: Worked Example 1.1's program in the Chapter 1 model (Equation 1.B.1; Table 1.B.1, digital row). Liquidity is indexed to today = 100 = $620 million; the five-year changes add to the state the build starts from.
A36: Reading | B36: Start | C36: Target | D36: Rate k | E36: Dip depth | F36: Dip timing tau (years) | G36: Year 5 | H36: Change
A37: Liquidity (index) | B37: 100 | C37: 112 | D37: 0.35 | E37: -28 | F37: 2 | G37: =C37+(B37-C37)*EXP(-D37*5)+E37*(5/F37)*EXP(1-5/F37) -> 94.295601 | H37: =G37-B37 -> -5.7043985
A38: Technology platform | B38: 41 | C38: 78 | D38: 0.55 | E38: 0 | F38: 1 | G38: =C38+(B38-C38)*EXP(-D38*5)+E38*(5/F38)*EXP(1-5/F38) -> 75.634669 | H38: =G38-B38 -> 34.634669
A39: Operational efficiency | B39: 71 | C39: 77 | D39: 0.5 | E39: -9 | F39: 1.5 | G39: =C39+(B39-C39)*EXP(-D39*5)+E39*(5/F39)*EXP(1-5/F39) -> 73.598331 | H39: =G39-B39 -> 2.598331
A41: Low point of the liquidity index: Newton's method on its slope, from year 1.5
A42: Iteration | B42: Year t | C42: Slope | D42: Curvature
A43: 0 | B43: 1.5 | C43: =-$D$37*($B$37-$C$37)*EXP(-$D$37*B43)+($E$37/$F$37)*EXP(1-B43/$F$37)*(1-B43/$F$37) -> -2.0095564 | D43: =$D$37^2*($B$37-$C$37)*EXP(-$D$37*B43)+($E$37/$F$37^2)*EXP(1-B43/$F$37)*(B43/$F$37-2) -> 10.365636
A44: 1 | B44: =B43-C43/D43 -> 1.6938672 | C44: =-$D$37*($B$37-$C$37)*EXP(-$D$37*B44)+($E$37/$F$37)*EXP(1-B44/$F$37)*(1-B44/$F$37) -> -0.17583497 | D44: =$D$37^2*($B$37-$C$37)*EXP(-$D$37*B44)+($E$37/$F$37^2)*EXP(1-B44/$F$37)*(B44/$F$37-2) -> 8.5939652
A45: 2 | B45: =B44-C44/D44 -> 1.7143274 | C45: =-$D$37*($B$37-$C$37)*EXP(-$D$37*B45)+($E$37/$F$37)*EXP(1-B45/$F$37)*(1-B45/$F$37) -> -0.0017696753 | D45: =$D$37^2*($B$37-$C$37)*EXP(-$D$37*B45)+($E$37/$F$37^2)*EXP(1-B45/$F$37)*(B45/$F$37-2) -> 8.4214176
A46: 3 | B46: =B45-C45/D45 -> 1.7145376 | C46: =-$D$37*($B$37-$C$37)*EXP(-$D$37*B46)+($E$37/$F$37)*EXP(1-B46/$F$37)*(1-B46/$F$37) -> -1.8477513e-07 | D46: =$D$37^2*($B$37-$C$37)*EXP(-$D$37*B46)+($E$37/$F$37^2)*EXP(1-B46/$F$37)*(B46/$F$37-2) -> 8.419659
A47: 4 | B47: =B46-C46/D46 -> 1.7145376 | C47: =-$D$37*($B$37-$C$37)*EXP(-$D$37*B47)+($E$37/$F$37)*EXP(1-B47/$F$37)*(1-B47/$F$37) -> 0 | D47: =$D$37^2*($B$37-$C$37)*EXP(-$D$37*B47)+($E$37/$F$37^2)*EXP(1-B47/$F$37)*(B47/$F$37-2) -> 8.4196589
A48: 5 | B48: =B47-C47/D47 -> 1.7145376 | C48: =-$D$37*($B$37-$C$37)*EXP(-$D$37*B48)+($E$37/$F$37)*EXP(1-B48/$F$37)*(1-B48/$F$37) -> 0 | D48: =$D$37^2*($B$37-$C$37)*EXP(-$D$37*B48)+($E$37/$F$37^2)*EXP(1-B48/$F$37)*(B48/$F$37-2) -> 8.4196589
...

Sheet Operators
A1: Forge the operators: domains and effects from today's state (Definitions 6.1-6.4; Figure 6.1; AXIOM Lab 1.6, step 1)
B3: Liquidity | C3: Technology | D3: Workforce | E3: Efficiency | F3: Unit sold (1 = yes) | G3: Platform built (1 = yes)
A4: Meridian today | B4: =Liq_today -> 620 | C4: =Tech_today -> 41 | D4: =W_today -> 58 | E4: =Eff_today -> 71 | F4: 0 | G4: 0
A6: Move | B6: Liquidity after | C6: Technology after | D6: Workforce after | E6: Efficiency after | F6: In the domain today (1 = yes) | G6: Domain (preconditions) | H6: Why not
A7: S, sell, engineers leave (code 1) | B7: =IF(F7=1,CHOOSE(1,$B$4+Proc_S,$B$4+Proc_Sk,$B$4+D_dL,$B$4-Cost_A),"no result") -> 732 | C7: =IF(F7=1,CHOOSE(1,(1-Tech_share)*$C$4,(1-Tech_share)*$C$4,$C$4+D_dT,$C$4),"no result") -> 36.9 | D7: =IF(F7=1,CHOOSE(1,$D$4-W_lost,$D$4,$D$4,$D$4+W_gain),"no result") -> 53 | E7: =IF(F7=1,CHOOSE(1,$E$4,$E$4,$E$4+D_dE,$E$4+Close_A*(Ceil_E-$E$4)),"no result") -> 71 | F7: =IF(1<=2,1-$F$4,IF(1=3,IF(AND($G$4=0,$D$4>=W_min,$B$4-D_dip>=Floor_q),1,0),IF(AND($D$4>=W_min,$B$4>=Pre_A),1,0))) -> 1 | G7: ="the unit unsold" -> the unit unsold | H7: =IF($F$4=1,"the unit is already sold","")
A8: S*, sell, engineers kept (code 2) | B8: =IF(F8=1,CHOOSE(2,$B$4+Proc_S,$B$4+Proc_Sk,$B$4+D_dL,$B$4-Cost_A),"no result") -> 712 | C8: =IF(F8=1,CHOOSE(2,(1-Tech_share)*$C$4,(1-Tech_share)*$C$4,$C$4+D_dT,$C$4),"no result") -> 36.9 | D8: =IF(F8=1,CHOOSE(2,$D$4-W_lost,$D$4,$D$4,$D$4+W_gain),"no result") -> 58 | E8: =IF(F8=1,CHOOSE(2,$E$4,$E$4,$E$4+D_dE,$E$4+Close_A*(Ceil_E-$E$4)),"no result") -> 71 | F8: =IF(2<=2,1-$F$4,IF(2=3,IF(AND($G$4=0,$D$4>=W_min,$B$4-D_dip>=Floor_q),1,0),IF(AND($D$4>=W_min,$B$4>=Pre_A),1,0))) -> 1 | G8: ="the unit unsold" -> the unit unsold | H8: =IF($F$4=1,"the unit is already sold","")
A9: D, digital build (code 3) | B9: =IF(F9=1,CHOOSE(3,$B$4+Proc_S,$B$4+Proc_Sk,$B$4+D_dL,$B$4-Cost_A),"no result") -> 584.63273 | C9: =IF(F9=1,CHOOSE(3,(1-Tech_share)*$C$4,(1-Tech_share)*$C$4,$C$4+D_dT,$C$4),"no result") -> 75.634669 | D9: =IF(F9=1,CHOOSE(3,$D$4-W_lost,$D$4,$D$4,$D$4+W_gain),"no result") -> 58 | E9: =IF(F9=1,CHOOSE(3,$E$4,$E$4,$E$4+D_dE,$E$4+Close_A*(Ceil_E-$E$4)),"no result") -> 73.598331 | F9: =IF(3<=2,1-$F$4,IF(3=3,IF(AND($G$4=0,$D$4>=W_min,$B$4-D_dip>=Floor_q),1,0),IF(AND($D$4>=W_min,$B$4>=Pre_A),1,0))) -> 1 | G9: ="not built, workforce >= "&TEXT(W_min,"0")&", liquidity >= $"&TEXT(Pre_D,"0")&"m" -> not built, workforce >= 55, liquidity >= $488m | H9: =IF($G$4=1,"the platform is already built",IF($D$4<W_min,"workforce below "&TEXT(W_min,"0"),IF($B$4-D_dip<Floor_q,"its low point $"&TEXT($B$4-D_dip,"0")&"m is below the floor","")))
A10: A, automation round (code 4) | B10: =IF(F10=1,CHOOSE(4,$B$4+Proc_S,$B$4+Proc_Sk,$B$4+D_dL,$B$4-Cost_A),"no result") -> 500 | C10: =IF(F10=1,CHOOSE(4,(1-Tech_share)*$C$4,(1-Tech_share)*$C$4,$C$4+D_dT,$C$4),"no result") -> 41 | D10: =IF(F10=1,CHOOSE(4,$D$4-W_lost,$D$4,$D$4,$D$4+W_gain),"no result") -> 59 | E10: =IF(F10=1,CHOOSE(4,$E$4,$E$4,$E$4+D_dE,$E$4+Close_A*(Ceil_E-$E$4)),"no result") -> 78 | F10: =IF(4<=2,1-$F$4,IF(4=3,IF(AND($G$4=0,$D$4>=W_min,$B$4-D_dip>=Floor_q),1,0),IF(AND($D$4>=W_min,$B$4>=Pre_A),1,0))) -> 1 | G10: ="workforce >= "&TEXT(W_min,"0")&", liquidity >= $"&TEXT(Pre_A,"0")&"m" -> workforce >= 55, liquidity >= $470m | H10: =IF($D$4<W_min,"workforce below "&TEXT(W_min,"0"),IF($B$4<Pre_A,"liquidity below $"&TEXT(Pre_A,"0")&"m",""))
A11: Moves that can be taken today | F11: =SUM(F7:F10) -> 4
A12: The digital build's low point from today | B12: =B4-D_dip -> 481.91794 | C12: =IF(B12>=Floor_q,"$"&TEXT(B12-Floor_q,"0")&" million above the floor: the build can start today","below the floor: outside its domain the build has no result (Definition 6.3)") -> $132 million above the floor: the build can start today
A14: The round on Figure 6.1's plane | B14: Liquidity | C14: Efficiency | D14: In the domain (1 = yes) | E14: Liquidity after | F14: Efficiency after
A15: Meridian today | B15: 620 | C15: 71 | D15: =IF(AND(B15>=Pre_A,W_today>=W_min),1,0) -> 1 | E15: =IF(D15=1,B15-Cost_A,"no result") -> 500 | F15: =IF(D15=1,C15+Close_A*(Ceil_E-C15),"no result") -> 78
A16: a state in the domain | B16: 860 | C16: 67.5 | D16: =IF(AND(B16>=Pre_A,W_today>=W_min),1,0) -> 1 | E16: =IF(D16=1,B16-Cost_A,"no result") -> 740 | F16: =IF(D16=1,C16+Close_A*(Ceil_E-C16),"no result") -> 76.25
A17: a state in the domain | B17: 800 | C17: 81 | D17: =IF(AND(B17>=Pre_A,W_today>=W_min),1,0) -> 1 | E17: =IF(D17=1,B17-Cost_A,"no result") -> 680 | F17: =IF(D17=1,C17+Close_A*(Ceil_E-C17),"no result") -> 83
A18: a feasible state outside | B18: 410 | C18: 66.5 | D18: =IF(AND(B18>=Pre_A,W_today>=W_min),1,0) -> 0 | E18: =IF(D18=1,B18-Cost_A,"no result") -> no result | F18: =IF(D18=1,C18+Close_A*(Ceil_E-C18),"no result") -> no result
A19: Range: liquidity at least the floor, and efficiency (e + 85)/2, which stays below the ceiling of 85 whenever e does: the round can approach the ceiling but never deliver it.
A21: Record of 'sell part of Industrial Systems' (Proposition 6.1) | B21: Liquidity after | C21: Workforce after | D21: Same start?
A22: today, then the sale with the engineers leaving | B22: =CHOOSE(1,$B$4+Proc_S,$B$4+Proc_Sk,$B$4+D_dL,$B$4-Cost_A) -> 732 | C22: =CHOOSE(1,$D$4-W_lost,$D$4,$D$4,$D$4+W_gain) -> 53 | D22: yes
A23: today, then the sale keeping the engineers | B23: =CHOOSE(2,$B$4+Proc_S,$B$4+Proc_Sk,$B$4+D_dL,$B$4-Cost_A) -> 712 | C23: =CHOOSE(2,$D$4-W_lost,$D$4,$D$4,$D$4+W_gain) -> 58 | D23: yes
A24: Different outcomes from one start | B24: =IF(OR(B22<>B23,C22<>C23),2,1) -> 2
A25: One operator? | B25: =IF(B24=1,"yes","no: a family of two, one per decision about the engineers") -> no: a family of two, one per decision about the engineers
A27: Theorem 6.1(ii): the sale's proceeds rest on a buyer paying the assumed price, an assumption about the environment, not a commitment (Table 6.1: a buyer at the assumed price).

Sheet Policy
A1: A policy turns a family into a system: the bank's rule (Theorem 6.1(iii); Online Appendix Example 6.B.1)
A2: The family T_u(q, t) = (q - u, t + 0.05u) on the domain q - u >= 300; the rule u(q) = share x (q - 300) leaves the closed loop q' = (1 - share) q + share x 300, a contraction with L = 1 - share.
A3: Declaration | B3: Value | H3: Result | I3: Value
A4: Liquidity today ($ million) | B4: 900 | H4: Liquidity after one year | I4: =B13 -> 600
A5: Regulatory floor ($ million) | B5: 300 | H5: after two years | I5: =B14 -> 450
A6: Technology index today | B6: 41 | H6: after three years | I6: =B15 -> 375
A7: Technology points per $1 million invested | B7: 0.05 | H7: after four years | I7: =B16 -> 337.5
A8: The rule: share of the liquidity above the floor invested each year | B8: 0.5 | H8: Technology after one year | I8: =D13 -> 56
H9: after two years | I9: =D14 -> 63.5
H10: Total invested over 40 years (the initial slack) | I10: =SUM(C12:C52) -> 600
A11: Year | B11: Liquidity | C11: Invested u | D11: Technology | E11: Closed form: floor + (q0 - floor)(1 - share)^k | F11: In the domain (q - u >= floor) | H11: Technology after 40 years (limit 41 + 0.05 x 600 = 71) | I11: =D52 -> 71
A12: 0 | B12: =B4 -> 900 | C12: 0 | D12: =B6 -> 41 | E12: =$B$5+($B$4-$B$5)*(1-$B$8)^A12 -> 900
A13: 1 | B13: =B12-C13 -> 600 | C13: =$B$8*(B12-$B$5) -> 300 | D13: =D12+$B$7*C13 -> 56 | E13: =$B$5+($B$4-$B$5)*(1-$B$8)^A13 -> 600 | F13: =IF(B12-C13>=$B$5,1,0) -> 1
A14: 2 | B14: =B13-C14 -> 450 | C14: =$B$8*(B13-$B$5) -> 150 | D14: =D13+$B$7*C14 -> 63.5 | E14: =$B$5+($B$4-$B$5)*(1-$B$8)^A14 -> 450 | F14: =IF(B13-C14>=$B$5,1,0) -> 1
A15: 3 | B15: =B14-C15 -> 375 | C15: =$B$8*(B14-$B$5) -> 75 | D15: =D14+$B$7*C15 -> 67.25 | E15: =$B$5+($B$4-$B$5)*(1-$B$8)^A15 -> 375 | F15: =IF(B14-C15>=$B$5,1,0) -> 1
A16: 4 | B16: =B15-C16 -> 337.5 | C16: =$B$8*(B15-$B$5) -> 37.5 | D16: =D15+$B$7*C16 -> 69.125 | E16: =$B$5+($B$4-$B$5)*(1-$B$8)^A16 -> 337.5 | F16: =IF(B15-C16>=$B$5,1,0) -> 1
A17: 5 | B17: =B16-C17 -> 318.75 | C17: =$B$8*(B16-$B$5) -> 18.75 | D17: =D16+$B$7*C17 -> 70.0625 | E17: =$B$5+($B$4-$B$5)*(1-$B$8)^A17 -> 318.75 | F17: =IF(B16-C17>=$B$5,1,0) -> 1
A18: 6 | B18: =B17-C18 -> 309.375 | C18: =$B$8*(B17-$B$5) -> 9.375 | D18: =D17+$B$7*C18 -> 70.53125 | E18: =$B$5+($B$4-$B$5)*(1-$B$8)^A18 -> 309.375 | F18: =IF(B17-C18>=$B$5,1,0) -> 1
A19: 7 | B19: =B18-C19 -> 304.6875 | C19: =$B$8*(B18-$B$5) -> 4.6875 | D19: =D18+$B$7*C19 -> 70.765625 | E19: =$B$5+($B$4-$B$5)*(1-$B$8)^A19 -> 304.6875 | F19: =IF(B18-C19>=$B$5,1,0) -> 1
A20: 8 | B20: =B19-C20 -> 302.34375 | C20: =$B$8*(B19-$B$5) -> 2.34375 | D20: =D19+$B$7*C20 -> 70.882812 | E20: =$B$5+($B$4-$B$5)*(1-$B$8)^A20 -> 302.34375 | F20: =IF(B19-C20>=$B$5,1,0) -> 1
A21: 9 | B21: =B20-C21 -> 301.17188 | C21: =$B$8*(B20-$B$5) -> 1.171875 | D21: =D20+$B$7*C21 -> 70.941406 | E21: =$B$5+($B$4-$B$5)*(1-$B$8)^A21 -> 301.17188 | F21: =IF(B20-C21>=$B$5,1,0) -> 1
A22: 10 | B22: =B21-C22 -> 300.58594 | C22: =$B$8*(B21-$B$5) -> 0.5859375 | D22: =D21+$B$7*C22 -> 70.970703 | E22: =$B$5+($B$4-$B$5)*(1-$B$8)^A22 -> 300.58594 | F22: =IF(B21-C22>=$B$5,1,0) -> 1
A23: 11 | B23: =B22-C23 -> 300.29297 | C23: =$B$8*(B22-$B$5) -> 0.29296875 | D23: =D22+$B$7*C23 -> 70.985352 | E23: =$B$5+($B$4-$B$5)*(1-$B$8)^A23 -> 300.29297 | F23: =IF(B22-C23>=$B$5,1,0) -> 1
A24: 12 | B24: =B23-C24 -> 300.14648 | C24: =$B$8*(B23-$B$5) -> 0.14648438 | D24: =D23+$B$7*C24 -> 70.992676 | E24: =$B$5+($B$4-$B$5)*(1-$B$8)^A24 -> 300.14648 | F24: =IF(B23-C24>=$B$5,1,0) -> 1
... A52: 40 | B52: =B51-C52 -> 300 | C52: =$B$8*(B51-$B$5) -> 5.4569682e-10 | D52: =D51+$B$7*C52 -> 71 | E52: =$B$5+($B$4-$B$5)*(1-$B$8)^A52 -> 300 | F52: =IF(B51-C52>=$B$5,1,0) -> 1

Sheet Programs
A1: Compose programs: every two-move sequence from today, seam by seam (Theorem 6.2(iii); Proposition 6.5; Figure 6.3; AXIOM Lab 1.6, step 2)
A2: A program runs only if each step's result lies in the next step's domain (Definition 6.5). Codes: 1 = S, 2 = S*, 3 = D, 4 = A. A second sale or a second build is never possible. Grey: the state a move would produce if its preconditions were ignored; it has no result.
B3: Liquidity | C3: Technology | D3: Workforce | E3: Efficiency | F3: Unit sold | G3: Built
A4: Meridian today | B4: =Liq_today -> 620 | C4: =Tech_today -> 41 | D4: =W_today -> 58 | E4: =Eff_today -> 71 | F4: =Operators!F4 -> 0 | G4: =Operators!G4 -> 0
A6: First move | B6: Second move | C6: Code 1 | D6: Code 2 | E6: Step 1 runs | F6: Liquidity 1 | G6: Technology 1 | H6: Workforce 1 | I6: Efficiency 1 | J6: Sold 1 | K6: Step 2 runs | L6: Liquidity 2 | M6: Technology 2 | N6: Workforce 2 | O6: Efficiency 2 | P6: Sold 2 | Q6: Target met (technology and efficiency) | R6: Headroom over the floor | S6: Built 1 | T6: Built 2
A7: S | B7: S | C7: 1 | D7: 1 | E7: =IF(C7<=2,1-$F$4,IF(C7=3,IF(AND($G$4=0,$D$4>=W_min,$B$4-D_dip>=Floor_q),1,0),IF(AND($D$4>=W_min,$B$4>=Pre_A),1,0))) -> 1 | F7: =CHOOSE(C7,$B$4+Proc_S,$B$4+Proc_Sk,$B$4+D_dL,$B$4-Cost_A) -> 732 | G7: =CHOOSE(C7,(1-Tech_share)*$C$4,(1-Tech_share)*$C$4,$C$4+D_dT,$C$4) -> 36.9 | H7: =CHOOSE(C7,$D$4-W_lost,$D$4,$D$4,$D$4+W_gain) -> 53 | I7: =CHOOSE(C7,$E$4,$E$4,$E$4+D_dE,$E$4+Close_A*(Ceil_E-$E$4)) -> 71 | J7: =CHOOSE(C7,1,1,$F$4,$F$4) -> 1 | K7: =E7*IF(D7<=2,1-J7,IF(D7=3,IF(AND(S7=0,H7>=W_min,F7-D_dip>=Floor_q),1,0),IF(AND(H7>=W_min,F7>=Pre_A),1,0))) -> 0 | L7: =CHOOSE(D7,F7+Proc_S,F7+Proc_Sk,F7+D_dL,F7-Cost_A) -> 844 | M7: =CHOOSE(D7,(1-Tech_share)*G7,(1-Tech_share)*G7,G7+D_dT,G7) -> 33.21 | N7: =CHOOSE(D7,H7-W_lost,H7,H7,H7+W_gain) -> 48 | O7: =CHOOSE(D7,I7,I7,I7+D_dE,I7+Close_A*(Ceil_E-I7)) -> 71 | P7: =CHOOSE(D7,1,1,J7,J7) -> 1 | Q7: =IF(K7=1,IF(AND(M7>=Target_T,O7>=Target_E,L7>=Floor_q),1,0),0) -> 0 | R7: =IF(K7=1,L7-Floor_q,"") | S7: =CHOOSE(C7,$G$4,$G$4,1,$G$4) -> 0 | T7: =CHOOSE(D7,S7,S7,1,S7) -> 0
A8: S | B8: S* | C8: 1 | D8: 2 | E8: =IF(C8<=2,1-$F$4,IF(C8=3,IF(AND($G$4=0,$D$4>=W_min,$B$4-D_dip>=Floor_q),1,0),IF(AND($D$4>=W_min,$B$4>=Pre_A),1,0))) -> 1 | F8: =CHOOSE(C8,$B$4+Proc_S,$B$4+Proc_Sk,$B$4+D_dL,$B$4-Cost_A) -> 732 | G8: =CHOOSE(C8,(1-Tech_share)*$C$4,(1-Tech_share)*$C$4,$C$4+D_dT,$C$4) -> 36.9 | H8: =CHOOSE(C8,$D$4-W_lost,$D$4,$D$4,$D$4+W_gain) -> 53 | I8: =CHOOSE(C8,$E$4,$E$4,$E$4+D_dE,$E$4+Close_A*(Ceil_E-$E$4)) -> 71 | J8: =CHOOSE(C8,1,1,$F$4,$F$4) -> 1 | K8: =E8*IF(D8<=2,1-J8,IF(D8=3,IF(AND(S8=0,H8>=W_min,F8-D_dip>=Floor_q),1,0),IF(AND(H8>=W_min,F8>=Pre_A),1,0))) -> 0 | L8: =CHOOSE(D8,F8+Proc_S,F8+Proc_Sk,F8+D_dL,F8-Cost_A) -> 824 | M8: =CHOOSE(D8,(1-Tech_share)*G8,(1-Tech_share)*G8,G8+D_dT,G8) -> 33.21 | N8: =CHOOSE(D8,H8-W_lost,H8,H8,H8+W_gain) -> 53 | O8: =CHOOSE(D8,I8,I8,I8+D_dE,I8+Close_A*(Ceil_E-I8)) -> 71 | P8: =CHOOSE(D8,1,1,J8,J8) -> 1 | Q8: =IF(K8=1,IF(AND(M8>=Target_T,O8>=Target_E,L8>=Floor_q),1,0),0) -> 0 | R8: =IF(K8=1,L8-Floor_q,"") | S8: =CHOOSE(C8,$G$4,$G$4,1,$G$4) -> 0 | T8: =CHOOSE(D8,S8,S8,1,S8) -> 0
A9: S | B9: D | C9: 1 | D9: 3 | E9: =IF(C9<=2,1-$F$4,IF(C9=3,IF(AND($G$4=0,$D$4>=W_min,$B$4-D_dip>=Floor_q),1,0),IF(AND($D$4>=W_min,$B$4>=Pre_A),1,0))) -> 1 | F9: =CHOOSE(C9,$B$4+Proc_S,$B$4+Proc_Sk,$B$4+D_dL,$B$4-Cost_A) -> 732 | G9: =CHOOSE(C9,(1-Tech_share)*$C$4,(1-Tech_share)*$C$4,$C$4+D_dT,$C$4) -> 36.9 | H9: =CHOOSE(C9,$D$4-W_lost,$D$4,$D$4,$D$4+W_gain) -> 53 | I9: =CHOOSE(C9,$E$4,$E$4,$E$4+D_dE,$E$4+Close_A*(Ceil_E-$E$4)) -> 71 | J9: =CHOOSE(C9,1,1,$F$4,$F$4) -> 1 | K9: =E9*IF(D9<=2,1-J9,IF(D9=3,IF(AND(S9=0,H9>=W_min,F9-D_dip>=Floor_q),1,0),IF(AND(H9>=W_min,F9>=Pre_A),1,0))) -> 0 | L9: =CHOOSE(D9,F9+Proc_S,F9+Proc_Sk,F9+D_dL,F9-Cost_A) -> 696.63273 | M9: =CHOOSE(D9,(1-Tech_share)*G9,(1-Tech_share)*G9,G9+D_dT,G9) -> 71.534669 | N9: =CHOOSE(D9,H9-W_lost,H9,H9,H9+W_gain) -> 53 | O9: =CHOOSE(D9,I9,I9,I9+D_dE,I9+Close_A*(Ceil_E-I9)) -> 73.598331 | P9: =CHOOSE(D9,1,1,J9,J9) -> 1 | Q9: =IF(K9=1,IF(AND(M9>=Target_T,O9>=Target_E,L9>=Floor_q),1,0),0) -> 0 | R9: =IF(K9=1,L9-Floor_q,"") | S9: =CHOOSE(C9,$G$4,$G$4,1,$G$4) -> 0 | T9: =CHOOSE(D9,S9,S9,1,S9) -> 1
A10: S | B10: A | C10: 1 | D10: 4 | E10: =IF(C10<=2,1-$F$4,IF(C10=3,IF(AND($G$4=0,$D$4>=W_min,$B$4-D_dip>=Floor_q),1,0),IF(AND($D$4>=W_min,$B$4>=Pre_A),1,0))) -> 1 | F10: =CHOOSE(C10,$B$4+Proc_S,$B$4+Proc_Sk,$B$4+D_dL,$B$4-Cost_A) -> 732 | G10: =CHOOSE(C10,(1-Tech_share)*$C$4,(1-Tech_share)*$C$4,$C$4+D_dT,$C$4) -> 36.9 | H10: =CHOOSE(C10,$D$4-W_lost,$D$4,$D$4,$D$4+W_gain) -> 53 | I10: =CHOOSE(C10,$E$4,$E$4,$E$4+D_dE,$E$4+Close_A*(Ceil_E-$E$4)) -> 71 | J10: =CHOOSE(C10,1,1,$F$4,$F$4) -> 1 | K10: =E10*IF(D10<=2,1-J10,IF(D10=3,IF(AND(S10=0,H10>=W_min,F10-D_dip>=Floor_q),1,0),IF(AND(H10>=W_min,F10>=Pre_A),1,0))) -> 0 | L10: =CHOOSE(D10,F10+Proc_S,F10+Proc_Sk,F10+D_dL,F10-Cost_A) -> 612 | M10: =CHOOSE(D10,(1-Tech_share)*G10,(1-Tech_share)*G10,G10+D_dT,G10) -> 36.9 | N10: =CHOOSE(D10,H10-W_lost,H10,H10,H10+W_gain) -> 54 | O10: =CHOOSE(D10,I10,I10,I10+D_dE,I10+Close_A*(Ceil_E-I10)) -> 78 | P10: =CHOOSE(D10,1,1,J10,J10) -> 1 | Q10: =IF(K10=1,IF(AND(M10>=Target_T,O10>=Target_E,L10>=Floor_q),1,0),0) -> 0 | R10: =IF(K10=1,L10-Floor_q,"") | S10: =CHOOSE(C10,$G$4,$G$4,1,$G$4) -> 0 | T10: =CHOOSE(D10,S10,S10,1,S10) -> 0
A11: S* | B11: S | C11: 2 | D11: 1 | E11: =IF(C11<=2,1-$F$4,IF(C11=3,IF(AND($G$4=0,$D$4>=W_min,$B$4-D_dip>=Floor_q),1,0),IF(AND($D$4>=W_min,$B$4>=Pre_A),1,0))) -> 1 | F11: =CHOOSE(C11,$B$4+Proc_S,$B$4+Proc_Sk,$B$4+D_dL,$B$4-Cost_A) -> 712 | G11: =CHOOSE(C11,(1-Tech_share)*$C$4,(1-Tech_share)*$C$4,$C$4+D_dT,$C$4) -> 36.9 | H11: =CHOOSE(C11,$D$4-W_lost,$D$4,$D$4,$D$4+W_gain) -> 58 | I11: =CHOOSE(C11,$E$4,$E$4,$E$4+D_dE,$E$4+Close_A*(Ceil_E-$E$4)) -> 71 | J11: =CHOOSE(C11,1,1,$F$4,$F$4) -> 1 | K11: =E11*IF(D11<=2,1-J11,IF(D11=3,IF(AND(S11=0,H11>=W_min,F11-D_dip>=Floor_q),1,0),IF(AND(H11>=W_min,F11>=Pre_A),1,0))) -> 0 | L11: =CHOOSE(D11,F11+Proc_S,F11+Proc_Sk,F11+D_dL,F11-Cost_A) -> 824 | M11: =CHOOSE(D11,(1-Tech_share)*G11,(1-Tech_share)*G11,G11+D_dT,G11) -> 33.21 | N11: =CHOOSE(D11,H11-W_lost,H11,H11,H11+W_gain) -> 53 | O11: =CHOOSE(D11,I11,I11,I11+D_dE,I11+Close_A*(Ceil_E-I11)) -> 71 | P11: =CHOOSE(D11,1,1,J11,J11) -> 1 | Q11: =IF(K11=1,IF(AND(M11>=Target_T,O11>=Target_E,L11>=Floor_q),1,0),0) -> 0 | R11: =IF(K11=1,L11-Floor_q,"") | S11: =CHOOSE(C11,$G$4,$G$4,1,$G$4) -> 0 | T11: =CHOOSE(D11,S11,S11,1,S11) -> 0
A12: S* | B12: S* | C12: 2 | D12: 2 | E12: =IF(C12<=2,1-$F$4,IF(C12=3,IF(AND($G$4=0,$D$4>=W_min,$B$4-D_dip>=Floor_q),1,0),IF(AND($D$4>=W_min,$B$4>=Pre_A),1,0))) -> 1 | F12: =CHOOSE(C12,$B$4+Proc_S,$B$4+Proc_Sk,$B$4+D_dL,$B$4-Cost_A) -> 712 | G12: =CHOOSE(C12,(1-Tech_share)*$C$4,(1-Tech_share)*$C$4,$C$4+D_dT,$C$4) -> 36.9 | H12: =CHOOSE(C12,$D$4-W_lost,$D$4,$D$4,$D$4+W_gain) -> 58 | I12: =CHOOSE(C12,$E$4,$E$4,$E$4+D_dE,$E$4+Close_A*(Ceil_E-$E$4)) -> 71 | J12: =CHOOSE(C12,1,1,$F$4,$F$4) -> 1 | K12: =E12*IF(D12<=2,1-J12,IF(D12=3,IF(AND(S12=0,H12>=W_min,F12-D_dip>=Floor_q),1,0),IF(AND(H12>=W_min,F12>=Pre_A),1,0))) -> 0 | L12: =CHOOSE(D12,F12+Proc_S,F12+Proc_Sk,F12+D_dL,F12-Cost_A) -> 804 | M12: =CHOOSE(D12,(1-Tech_share)*G12,(1-Tech_share)*G12,G12+D_dT,G12) -> 33.21 | N12: =CHOOSE(D12,H12-W_lost,H12,H12,H12+W_gain) -> 58 | O12: =CHOOSE(D12,I12,I12,I12+D_dE,I12+Close_A*(Ceil_E-I12)) -> 71 | P12: =CHOOSE(D12,1,1,J12,J12) -> 1 | Q12: =IF(K12=1,IF(AND(M12>=Target_T,O12>=Target_E,L12>=Floor_q),1,0),0) -> 0 | R12: =IF(K12=1,L12-Floor_q,"") | S12: =CHOOSE(C12,$G$4,$G$4,1,$G$4) -> 0 | T12: =CHOOSE(D12,S12,S12,1,S12) -> 0
A13: S* | B13: D | C13: 2 | D13: 3 | E13: =IF(C13<=2,1-$F$4,IF(C13=3,IF(AND($G$4=0,$D$4>=W_min,$B$4-D_dip>=Floor_q),1,0),IF(AND($D$4>=W_min,$B$4>=Pre_A),1,0))) -> 1 | F13: =CHOOSE(C13,$B$4+Proc_S,$B$4+Proc_Sk,$B$4+D_dL,$B$4-Cost_A) -> 712 | G13: =CHOOSE(C13,(1-Tech_share)*$C$4,(1-Tech_share)*$C$4,$C$4+D_dT,$C$4) -> 36.9 | H13: =CHOOSE(C13,$D$4-W_lost,$D$4,$D$4,$D$4+W_gain) -> 58 | I13: =CHOOSE(C13,$E$4,$E$4,$E$4+D_dE,$E$4+Close_A*(Ceil_E-$E$4)) -> 71 | J13: =CHOOSE(C13,1,1,$F$4,$F$4) -> 1 | K13: =E13*IF(D13<=2,1-J13,IF(D13=3,IF(AND(S13=0,H13>=W_min,F13-D_dip>=Floor_q),1,0),IF(AND(H13>=W_min,F13>=Pre_A),1,0))) -> 1 | L13: =CHOOSE(D13,F13+Proc_S,F13+Proc_Sk,F13+D_dL,F13-Cost_A) -> 676.63273 | M13: =CHOOSE(D13,(1-Tech_share)*G13,(1-Tech_share)*G13,G13+D_dT,G13) -> 71.534669 | N13: =CHOOSE(D13,H13-W_lost,H13,H13,H13+W_gain) -> 58 | O13: =CHOOSE(D13,I13,I13,I13+D_dE,I13+Close_A*(Ceil_E-I13)) -> 73.598331 | P13: =CHOOSE(D13,1,1,J13,J13) -> 1 | Q13: =IF(K13=1,IF(AND(M13>=Target_T,O13>=Target_E,L13>=Floor_q),1,0),0) -> 0 | R13: =IF(K13=1,L13-Floor_q,"") -> 326.63273 | S13: =CHOOSE(C13,$G$4,$G$4,1,$G$4) -> 0 | T13: =CHOOSE(D13,S13,S13,1,S13) -> 1
A14: S* | B14: A | C14: 2 | D14: 4 | E14: =IF(C14<=2,1-$F$4,IF(C14=3,IF(AND($G$4=0,$D$4>=W_min,$B$4-D_dip>=Floor_q),1,0),IF(AND($D$4>=W_min,$B$4>=Pre_A),1,0))) -> 1 | F14: =CHOOSE(C14,$B$4+Proc_S,$B$4+Proc_Sk,$B$4+D_dL,$B$4-Cost_A) -> 712 | G14: =CHOOSE(C14,(1-Tech_share)*$C$4,(1-Tech_share)*$C$4,$C$4+D_dT,$C$4) -> 36.9 | H14: =CHOOSE(C14,$D$4-W_lost,$D$4,$D$4,$D$4+W_gain) -> 58 | I14: =CHOOSE(C14,$E$4,$E$4,$E$4+D_dE,$E$4+Close_A*(Ceil_E-$E$4)) -> 71 | J14: =CHOOSE(C14,1,1,$F$4,$F$4) -> 1 | K14: =E14*IF(D14<=2,1-J14,IF(D14=3,IF(AND(S14=0,H14>=W_min,F14-D_dip>=Floor_q),1,0),IF(AND(H14>=W_min,F14>=Pre_A),1,0))) -> 1 | L14: =CHOOSE(D14,F14+Proc_S,F14+Proc_Sk,F14+D_dL,F14-Cost_A) -> 592 | M14: =CHOOSE(D14,(1-Tech_share)*G14,(1-Tech_share)*G14,G14+D_dT,G14) -> 36.9 | N14: =CHOOSE(D14,H14-W_lost,H14,H14,H14+W_gain) -> 59 | O14: =CHOOSE(D14,I14,I14,I14+D_dE,I14+Close_A*(Ceil_E-I14)) -> 78 | P14: =CHOOSE(D14,1,1,J14,J14) -> 1 | Q14: =IF(K14=1,IF(AND(M14>=Target_T,O14>=Target_E,L14>=Floor_q),1,0),0) -> 0 | R14: =IF(K14=1,L14-Floor_q,"") -> 242 | S14: =CHOOSE(C14,$G$4,$G$4,1,$G$4) -> 0 | T14: =CHOOSE(D14,S14,S14,1,S14) -> 0
A15: D | B15: S | C15: 3 | D15: 1 | E15: =IF(C15<=2,1-$F$4,IF(C15=3,IF(AND($G$4=0,$D$4>=W_min,$B$4-D_dip>=Floor_q),1,0),IF(AND($D$4>=W_min,$B$4>=Pre_A),1,0))) -> 1 | F15: =CHOOSE(C15,$B$4+Proc_S,$B$4+Proc_Sk,$B$4+D_dL,$B$4-Cost_A) -> 584.63273 | G15: =CHOOSE(C15,(1-Tech_share)*$C$4,(1-Tech_share)*$C$4,$C$4+D_dT,$C$4) -> 75.634669 | H15: =CHOOSE(C15,$D$4-W_lost,$D$4,$D$4,$D$4+W_gain) -> 58 | I15: =CHOOSE(C15,$E$4,$E$4,$E$4+D_dE,$E$4+Close_A*(Ceil_E-$E$4)) -> 73.598331 | J15: =CHOOSE(C15,1,1,$F$4,$F$4) -> 0 | K15: =E15*IF(D15<=2,1-J15,IF(D15=3,IF(AND(S15=0,H15>=W_min,F15-D_dip>=Floor_q),1,0),IF(AND(H15>=W_min,F15>=Pre_A),1,0))) -> 1 | L15: =CHOOSE(D15,F15+Proc_S,F15+Proc_Sk,F15+D_dL,F15-Cost_A) -> 696.63273 | M15: =CHOOSE(D15,(1-Tech_share)*G15,(1-Tech_share)*G15,G15+D_dT,G15) -> 68.071202 | N15: =CHOOSE(D15,H15-W_lost,H15,H15,H15+W_gain) -> 53 | O15: =CHOOSE(D15,I15,I15,I15+D_dE,I15+Close_A*(Ceil_E-I15)) -> 73.598331 | P15: =CHOOSE(D15,1,1,J15,J15) -> 1 | Q15: =IF(K15=1,IF(AND(M15>=Target_T,O15>=Target_E,L15>=Floor_q),1,0),0) -> 0 | R15: =IF(K15=1,L15-Floor_q,"") -> 346.63273 | S15: =CHOOSE(C15,$G$4,$G$4,1,$G$4) -> 1 | T15: =CHOOSE(D15,S15,S15,1,S15) -> 1
A16: D | B16: S* | C16: 3 | D16: 2 | E16: =IF(C16<=2,1-$F$4,IF(C16=3,IF(AND($G$4=0,$D$4>=W_min,$B$4-D_dip>=Floor_q),1,0),IF(AND($D$4>=W_min,$B$4>=Pre_A),1,0))) -> 1 | F16: =CHOOSE(C16,$B$4+Proc_S,$B$4+Proc_Sk,$B$4+D_dL,$B$4-Cost_A) -> 584.63273 | G16: =CHOOSE(C16,(1-Tech_share)*$C$4,(1-Tech_share)*$C$4,$C$4+D_dT,$C$4) -> 75.634669 | H16: =CHOOSE(C16,$D$4-W_lost,$D$4,$D$4,$D$4+W_gain) -> 58 | I16: =CHOOSE(C16,$E$4,$E$4,$E$4+D_dE,$E$4+Close_A*(Ceil_E-$E$4)) -> 73.598331 | J16: =CHOOSE(C16,1,1,$F$4,$F$4) -> 0 | K16: =E16*IF(D16<=2,1-J16,IF(D16=3,IF(AND(S16=0,H16>=W_min,F16-D_dip>=Floor_q),1,0),IF(AND(H16>=W_min,F16>=Pre_A),1,0))) -> 1 | L16: =CHOOSE(D16,F16+Proc_S,F16+Proc_Sk,F16+D_dL,F16-Cost_A) -> 676.63273 | M16: =CHOOSE(D16,(1-Tech_share)*G16,(1-Tech_share)*G16,G16+D_dT,G16) -> 68.071202 | N16: =CHOOSE(D16,H16-W_lost,H16,H16,H16+W_gain) -> 58 | O16: =CHOOSE(D16,I16,I16,I16+D_dE,I16+Close_A*(Ceil_E-I16)) -> 73.598331 | P16: =CHOOSE(D16,1,1,J16,J16) -> 1 | Q16: =IF(K16=1,IF(AND(M16>=Target_T,O16>=Target_E,L16>=Floor_q),1,0),0) -> 0 | R16: =IF(K16=1,L16-Floor_q,"") -> 326.63273 | S16: =CHOOSE(C16,$G$4,$G$4,1,$G$4) -> 1 | T16: =CHOOSE(D16,S16,S16,1,S16) -> 1
A17: D | B17: D | C17: 3 | D17: 3 | E17: =IF(C17<=2,1-$F$4,IF(C17=3,IF(AND($G$4=0,$D$4>=W_min,$B$4-D_dip>=Floor_q),1,0),IF(AND($D$4>=W_min,$B$4>=Pre_A),1,0))) -> 1 | F17: =CHOOSE(C17,$B$4+Proc_S,$B$4+Proc_Sk,$B$4+D_dL,$B$4-Cost_A) -> 584.63273 | G17: =CHOOSE(C17,(1-Tech_share)*$C$4,(1-Tech_share)*$C$4,$C$4+D_dT,$C$4) -> 75.634669 | H17: =CHOOSE(C17,$D$4-W_lost,$D$4,$D$4,$D$4+W_gain) -> 58 | I17: =CHOOSE(C17,$E$4,$E$4,$E$4+D_dE,$E$4+Close_A*(Ceil_E-$E$4)) -> 73.598331 | J17: =CHOOSE(C17,1,1,$F$4,$F$4) -> 0 | K17: =E17*IF(D17<=2,1-J17,IF(D17=3,IF(AND(S17=0,H17>=W_min,F17-D_dip>=Floor_q),1,0),IF(AND(H17>=W_min,F17>=Pre_A),1,0))) -> 0 | L17: =CHOOSE(D17,F17+Proc_S,F17+Proc_Sk,F17+D_dL,F17-Cost_A) -> 549.26546 | M17: =CHOOSE(D17,(1-Tech_share)*G17,(1-Tech_share)*G17,G17+D_dT,G17) -> 110.26934 | N17: =CHOOSE(D17,H17-W_lost,H17,H17,H17+W_gain) -> 58 | O17: =CHOOSE(D17,I17,I17,I17+D_dE,I17+Close_A*(Ceil_E-I17)) -> 76.196662 | P17: =CHOOSE(D17,1,1,J17,J17) -> 0 | Q17: =IF(K17=1,IF(AND(M17>=Target_T,O17>=Target_E,L17>=Floor_q),1,0),0) -> 0 | R17: =IF(K17=1,L17-Floor_q,"") | S17: =CHOOSE(C17,$G$4,$G$4,1,$G$4) -> 1 | T17: =CHOOSE(D17,S17,S17,1,S17) -> 1
A18: D | B18: A | C18: 3 | D18: 4 | E18: =IF(C18<=2,1-$F$4,IF(C18=3,IF(AND($G$4=0,$D$4>=W_min,$B$4-D_dip>=Floor_q),1,0),IF(AND($D$4>=W_min,$B$4>=Pre_A),1,0))) -> 1 | F18: =CHOOSE(C18,$B$4+Proc_S,$B$4+Proc_Sk,$B$4+D_dL,$B$4-Cost_A) -> 584.63273 | G18: =CHOOSE(C18,(1-Tech_share)*$C$4,(1-Tech_share)*$C$4,$C$4+D_dT,$C$4) -> 75.634669 | H18: =CHOOSE(C18,$D$4-W_lost,$D$4,$D$4,$D$4+W_gain) -> 58 | I18: =CHOOSE(C18,$E$4,$E$4,$E$4+D_dE,$E$4+Close_A*(Ceil_E-$E$4)) -> 73.598331 | J18: =CHOOSE(C18,1,1,$F$4,$F$4) -> 0 | K18: =E18*IF(D18<=2,1-J18,IF(D18=3,IF(AND(S18=0,H18>=W_min,F18-D_dip>=Floor_q),1,0),IF(AND(H18>=W_min,F18>=Pre_A),1,0))) -> 1 | L18: =CHOOSE(D18,F18+Proc_S,F18+Proc_Sk,F18+D_dL,F18-Cost_A) -> 464.63273 | M18: =CHOOSE(D18,(1-Tech_share)*G18,(1-Tech_share)*G18,G18+D_dT,G18) -> 75.634669 | N18: =CHOOSE(D18,H18-W_lost,H18,H18,H18+W_gain) -> 59 | O18: =CHOOSE(D18,I18,I18,I18+D_dE,I18+Close_A*(Ceil_E-I18)) -> 79.299165 | P18: =CHOOSE(D18,1,1,J18,J18) -> 0 | Q18: =IF(K18=1,IF(AND(M18>=Target_T,O18>=Target_E,L18>=Floor_q),1,0),0) -> 0 | R18: =IF(K18=1,L18-Floor_q,"") -> 114.63273 | S18: =CHOOSE(C18,$G$4,$G$4,1,$G$4) -> 1 | T18: =CHOOSE(D18,S18,S18,1,S18) -> 1
... A22: A | B22: A | C22: 4 | D22: 4 | E22: =IF(C22<=2,1-$F$4,IF(C22=3,IF(AND($G$4=0,$D$4>=W_min,$B$4-D_dip>=Floor_q),1,0),IF(AND($D$4>=W_min,$B$4>=Pre_A),1,0))) -> 1 | F22: =CHOOSE(C22,$B$4+Proc_S,$B$4+Proc_Sk,$B$4+D_dL,$B$4-Cost_A) -> 500 | G22: =CHOOSE(C22,(1-Tech_share)*$C$4,(1-Tech_share)*$C$4,$C$4+D_dT,$C$4) -> 41 | H22: =CHOOSE(C22,$D$4-W_lost,$D$4,$D$4,$D$4+W_gain) -> 59 | I22: =CHOOSE(C22,$E$4,$E$4,$E$4+D_dE,$E$4+Close_A*(Ceil_E-$E$4)) -> 78 | J22: =CHOOSE(C22,1,1,$F$4,$F$4) -> 0 | K22: =E22*IF(D22<=2,1-J22,IF(D22=3,IF(AND(S22=0,H22>=W_min,F22-D_dip>=Floor_q),1,0),IF(AND(H22>=W_min,F22>=Pre_A),1,0))) -> 1 | L22: =CHOOSE(D22,F22+Proc_S,F22+Proc_Sk,F22+D_dL,F22-Cost_A) -> 380 | M22: =CHOOSE(D22,(1-Tech_share)*G22,(1-Tech_share)*G22,G22+D_dT,G22) -> 41 | N22: =CHOOSE(D22,H22-W_lost,H22,H22,H22+W_gain) -> 60 | O22: =CHOOSE(D22,I22,I22,I22+D_dE,I22+Close_A*(Ceil_E-I22)) -> 81.5 | P22: =CHOOSE(D22,1,1,J22,J22) -> 0 | Q22: =IF(K22=1,IF(AND(M22>=Target_T,O22>=Target_E,L22>=Floor_q),1,0),0) -> 0 | R22: =IF(K22=1,L22-Floor_q,"") -> 30 | S22: =CHOOSE(C22,$G$4,$G$4,1,$G$4) -> 0 | T22: =CHOOSE(D22,S22,S22,1,S22) -> 0
A25: Two-move programs that pass every seam | B25: =SUM(K7:K22) -> 9
A26: Programs that reach the target (technology >= 70 and efficiency >= 80) | B26: =SUM(Q7:Q22) -> 1 | C26: Automate, then build: the round's efficiency gain comes first and the build adds its own; built first, the round closes half of a smaller gap (Section 6.6; Theorem 6.2(iii)).
A27: Its liquidity | B27: =SUMIFS(L7:L22,Q7:Q22,1) -> 464.63273
A28: Its technology | B28: =SUMIFS(M7:M22,Q7:Q22,1) -> 75.634669
A29: Its headroom over the floor at the build's low point | B29: =SUMIFS(F7:F22,Q7:Q22,1)-D_dip-Floor_q -> 11.917941
A30: Its efficiency | B30: =SUMIFS(O7:O22,Q7:Q22,1) -> 80.598331
A31: The other order, D then A: efficiency | B31: =O18 -> 79.299165
A32: Section 6.5: sell keeping the engineers, two automation rounds, then the build (Proposition 6.5) | B32: Liquidity | C32: Technology | D32: Workforce | E32: Efficiency
A33: Today | B33: =B4 -> 620 | C33: =C4 -> 41 | D33: =D4 -> 58 | E33: =E4 -> 71
A34: After the sale, engineers kept | B34: =B33+Proc_Sk -> 712 | C34: =(1-Tech_share)*C33 -> 36.9 | D34: =D33 -> 58 | E34: =E33 -> 71
A35: After one automation round | B35: =B34-Cost_A -> 592 | C35: =C34 -> 36.9 | D35: =D34+W_gain -> 59 | E35: =E34+Close_A*(Ceil_E-E34) -> 78
A36: After a second round | B36: =B35-Cost_A -> 472 | C36: =C35 -> 36.9 | D36: =D35+W_gain -> 60 | E36: =E35+Close_A*(Ceil_E-E35) -> 81.5
A37: After the build (floor ignored) | B37: =B36+D_dL -> 436.63273 | C37: =C36+D_dT -> 71.534669 | D37: =D36 -> 60 | E37: =E36+D_dE -> 84.098331
A38: The build's low point on the way | B38: =B36-D_dip -> 333.91794
A39: Below the floor at the low point by | B39: =Floor_q-B38 -> 16.082059
A40: Above the floor at the end by | B40: =B37-Floor_q -> 86.632729
A41: A step that is not feasibility-preserving: no arithmetic on the end points certifies the path (Proposition 6.5).

Sheet Playbook
A1: Test the playbook: one automation round a year, savings paid out, recycled, or short of plan (Worked Example 6.1, Steps 2-4; Table 6.4; Equation 6.2; Theorem 6.3; AXIOM Lab 1.6, step 3)
A2: Round k is taken at the start of year k if liquidity is at least $470 million and workforce capability at least 55; its cost and the year's savings land by the year's end. Columns run every round, as if no precondition bound; 'Round k runs' applies Equation 6.2.
A3: Case | B3: Savings paid out | C3: Recycled, as designed | D3: Recycled, 1-point shortfall | E3: Recycled, 2-point shortfall
A4: Share of the savings kept in liquidity | B4: 0 | C4: 1 | D4: 1 | E4: 1
A5: Efficiency shortfall a round (points) | B5: 0 | C5: 0 | D5: 1 | E5: 2
A7: Rounds that run, of 40 | B7: =SUM(B34:B73) -> 2 | C7: =SUM(J34:J73) -> 40 | D7: =SUM(R34:R73) -> 40 | E7: =SUM(Z34:Z73) -> 4
A8: The round whose precondition fails | B8: =IF(B7=40,"none in 40 years",B7+1) -> 3 | C8: =IF(C7=40,"none in 40 years",C7+1) -> none in 40 years | D8: =IF(D7=40,"none in 40 years",D7+1) -> none in 40 years | E8: =IF(E7=40,"none in 40 years",E7+1) -> 5
A9: First year the savings exceed the round's cost | B9: =IF(COUNTIF(D34:D73,">"&Cost_A)=0,"never",_xlfn.MINIFS($A$34:$A$73,D34:D73,">"&Cost_A)) -> never | C9: =IF(COUNTIF(L34:L73,">"&Cost_A)=0,"never",_xlfn.MINIFS($A$34:$A$73,L34:L73,">"&Cost_A)) -> 3 | D9: =IF(COUNTIF(T34:T73,">"&Cost_A)=0,"never",_xlfn.MINIFS($A$34:$A$73,T34:T73,">"&Cost_A)) -> never | E9: =IF(COUNTIF(AB34:AB73,">"&Cost_A)=0,"never",_xlfn.MINIFS($A$34:$A$73,AB34:AB73,">"&Cost_A)) -> never
A10: Lowest liquidity at a year end while the playbook runs | B10: =_xlfn.MINIFS(F34:F73,B34:B73,1) -> 380 | C10: =_xlfn.MINIFS(N34:N73,J34:J73,1) -> 555 | D10: =_xlfn.MINIFS(V34:V73,R34:R73,1) -> 500 | E10: =_xlfn.MINIFS(AD34:AD73,Z34:Z73,1) -> 446.25
A11: Liquidity at the end of year 40, had every round run | B11: =F73 -> -4180 | C11: =N73 -> 1280 | D11: =V73 -> 500 | E11: =AD73 -> -280
A12: Savings less the round's cost in year 40, had every round run | B12: =E73 -> -120 | C12: =M73 -> 20 | D12: =U73 -> -1.0913936e-10 | E12: =AC73 -> -20
A13: Liquidity today that lets all 40 rounds run | B13: =I73 -> 5150 | C13: =Q73 -> 535 | D13: =Y73 -> 590 | E13: =AG73 -> 1350
A14: Increase from round 39 to round 40 | B14: =I73-I72 -> 120 | C14: =Q73-Q72 -> 0 | D14: =Y73-Y72 -> 2.1827873e-10 | E14: =AG73-AG72 -> 20
A15: Sustainable core: empty, or the liquidity today it starts from | B15: =IF(B14>0.000001,"empty","from "&TEXT(B13,"0.00")) -> empty | C15: =IF(C14>0.000001,"empty","from "&TEXT(C13,"0.00")) -> from 535.00 | D15: =IF(D14>0.000001,"empty","from "&TEXT(D13,"0.00")) -> from 590.00 | E15: =IF(E14>0.000001,"empty","from "&TEXT(E13,"0.00")) -> empty
A16: Meridian's margin over the liquidity 40 rounds need | B16: =Liq_today-B13 -> -4530 | C16: =Liq_today-C13 -> 85 | D16: =Liq_today-D13 -> 30 | E16: =Liq_today-E13 -> -730
A18: Table 6.4: recycled, as designed | B18: 0 | C18: 1 | D18: 2 | E18: 3 | F18: 4 | G18: 5 | H18: 6
A19: Efficiency (index) | B19: =K33 -> 71 | C19: =K34 -> 78 | D19: =K35 -> 81.5 | E19: =K36 -> 83.25 | F19: =K37 -> 84.125 | G19: =K38 -> 84.5625 | H19: =K39 -> 84.78125
A20: Savings this year | B20: -- | C20: =L34 -> 70 | D20: =L35 -> 105 | E20: =L36 -> 122.5 | F20: =L37 -> 131.25 | G20: =L38 -> 135.625 | H20: =L39 -> 137.8125
A21: Savings less the round's cost | B21: -- | C21: =M34 -> -50 | D21: =M35 -> -15 | E21: =M36 -> 2.5 | F21: =M37 -> 11.25 | G21: =M38 -> 15.625 | H21: =M39 -> 17.8125
A22: Liquidity at year end | B22: =N33 -> 620 | C22: =N34 -> 570 | D22: =N35 -> 555 | E22: =N36 -> 557.5 | F22: =N37 -> 568.75 | G22: =N38 -> 584.375 | H22: =N39 -> 602.1875
A24: Liquidity today that lets k rounds run (Equation 6.2) | B24: k = 1 | C24: k = 2 | D24: k = 3 | E24: k = 4 | F24: k = 5 | G24: k = 6 | H24: k = 7 | I24: k = 8 | J24: k = 9 | K24: k = 10
A25: Savings paid out | B25: =I34 -> 470 | C25: =I35 -> 590 | D25: =I36 -> 710 | E25: =I37 -> 830 | F25: =I38 -> 950 | G25: =I39 -> 1070 | H25: =I40 -> 1190 | I25: =I41 -> 1310 | J25: =I42 -> 1430 | K25: =I43 -> 1550
A26: Recycled, as designed | B26: =Q34 -> 470 | C26: =Q35 -> 520 | D26: =Q36 -> 535 | E26: =Q37 -> 535 | F26: =Q38 -> 535 | G26: =Q39 -> 535 | H26: =Q40 -> 535 | I26: =Q41 -> 535 | J26: =Q42 -> 535 | K26: =Q43 -> 535
A27: Recycled, 1-point shortfall | B27: =Y34 -> 470 | C27: =Y35 -> 530 | D27: =Y36 -> 560 | E27: =Y37 -> 575 | F27: =Y38 -> 582.5 | G27: =Y39 -> 586.25 | H27: =Y40 -> 588.125 | I27: =Y41 -> 589.0625 | J27: =Y42 -> 589.53125 | K27: =Y43 -> 589.76562
A28: Recycled, 2-point shortfall | B28: =AG34 -> 470 | C28: =AG35 -> 540 | D28: =AG36 -> 585 | E28: =AG37 -> 617.5 | F28: =AG38 -> 643.75 | G28: =AG39 -> 666.875 | H28: =AG40 -> 688.4375 | I28: =AG41 -> 709.21875 | J28: =AG42 -> 729.60938 | K28: =AG43 -> 749.80469
A29: Paid out: 470 + 120(k - 1), rising without bound, so no starting liquidity supports every round and the sustainable core is empty. Recycled: the requirement settles at $535 million after round 3.
A32: Year | B32: Savings paid out: round k runs | C32: Efficiency | D32: Savings | E32: Savings less cost | F32: Liquidity at year end | G32: Workforce | H32: Drop below today | I32: Liquidity today round k needs | J32: Recycled, as designed: round k runs | K32: Efficiency | L32: Savings | M32: Savings less cost | N32: Liquidity at year end | O32: Workforce | P32: Drop below today | Q32: Liquidity today round k needs | R32: Recycled, 1-point shortfall: round k runs | S32: Efficiency | T32: Savings | U32: Savings less cost | V32: Liquidity at year end | W32: Workforce | X32: Drop below today | Y32: Liquidity today round k needs | Z32: Recycled, 2-point shortfall: round k runs | AA32: Efficiency | AB32: Savings | AC32: Savings less cost | AD32: Liquidity at year end | AE32: Workforce | AF32: Drop below today | AG32: Liquidity today round k needs
A33: 0 | B33: 1 | C33: =Eff_today -> 71 | F33: =Liq_today -> 620 | G33: =W_today -> 58 | H33: =Liq_today-F33 -> 0 | J33: 1 | K33: =Eff_today -> 71 | N33: =Liq_today -> 620 | O33: =W_today -> 58 | P33: =Liq_today-N33 -> 0 | R33: 1 | S33: =Eff_today -> 71 | V33: =Liq_today -> 620 | W33: =W_today -> 58 | X33: =Liq_today-V33 -> 0 | Z33: 1 | AA33: =Eff_today -> 71 | AD33: =Liq_today -> 620 | AE33: =W_today -> 58 | AF33: =Liq_today-AD33 -> 0
A34: 1 | B34: =IF(AND(B33=1,F33>=Pre_A,G33>=W_min),1,0) -> 1 | C34: =C33+Close_A*(Ceil_E-C33)-$B$5 -> 78 | D34: =$B$4*Value_pt*(C34-Eff_today) -> 0 | E34: =D34-Cost_A -> -120 | F34: =F33+E34 -> 500 | G34: =G33+W_gain -> 59 | H34: =Liq_today-F34 -> 120 | I34: =Pre_A+MAX(H33:H33) -> 470 | J34: =IF(AND(J33=1,N33>=Pre_A,O33>=W_min),1,0) -> 1 | K34: =K33+Close_A*(Ceil_E-K33)-$C$5 -> 78 | L34: =$C$4*Value_pt*(K34-Eff_today) -> 70 | M34: =L34-Cost_A -> -50 | N34: =N33+M34 -> 570 | O34: =O33+W_gain -> 59 | P34: =Liq_today-N34 -> 50 | Q34: =Pre_A+MAX(P33:P33) -> 470 | R34: =IF(AND(R33=1,V33>=Pre_A,W33>=W_min),1,0) -> 1 | S34: =S33+Close_A*(Ceil_E-S33)-$D$5 -> 77 | T34: =$D$4*Value_pt*(S34-Eff_today) -> 60 | U34: =T34-Cost_A -> -60 | V34: =V33+U34 -> 560 | W34: =W33+W_gain -> 59 | X34: =Liq_today-V34 -> 60 | Y34: =Pre_A+MAX(X33:X33) -> 470 | Z34: =IF(AND(Z33=1,AD33>=Pre_A,AE33>=W_min),1,0) -> 1 | AA34: =AA33+Close_A*(Ceil_E-AA33)-$E$5 -> 76 | AB34: =$E$4*Value_pt*(AA34-Eff_today) -> 50 | AC34: =AB34-Cost_A -> -70 | AD34: =AD33+AC34 -> 550 | AE34: =AE33+W_gain -> 59 | AF34: =Liq_today-AD34 -> 70 | AG34: =Pre_A+MAX(AF33:AF33) -> 470
A35: 2 | B35: =IF(AND(B34=1,F34>=Pre_A,G34>=W_min),1,0) -> 1 | C35: =C34+Close_A*(Ceil_E-C34)-$B$5 -> 81.5 | D35: =$B$4*Value_pt*(C35-Eff_today) -> 0 | E35: =D35-Cost_A -> -120 | F35: =F34+E35 -> 380 | G35: =G34+W_gain -> 60 | H35: =Liq_today-F35 -> 240 | I35: =Pre_A+MAX(H33:H34) -> 590 | J35: =IF(AND(J34=1,N34>=Pre_A,O34>=W_min),1,0) -> 1 | K35: =K34+Close_A*(Ceil_E-K34)-$C$5 -> 81.5 | L35: =$C$4*Value_pt*(K35-Eff_today) -> 105 | M35: =L35-Cost_A -> -15 | N35: =N34+M35 -> 555 | O35: =O34+W_gain -> 60 | P35: =Liq_today-N35 -> 65 | Q35: =Pre_A+MAX(P33:P34) -> 520 | R35: =IF(AND(R34=1,V34>=Pre_A,W34>=W_min),1,0) -> 1 | S35: =S34+Close_A*(Ceil_E-S34)-$D$5 -> 80 | T35: =$D$4*Value_pt*(S35-Eff_today) -> 90 | U35: =T35-Cost_A -> -30 | V35: =V34+U35 -> 530 | W35: =W34+W_gain -> 60 | X35: =Liq_today-V35 -> 90 | Y35: =Pre_A+MAX(X33:X34) -> 530 | Z35: =IF(AND(Z34=1,AD34>=Pre_A,AE34>=W_min),1,0) -> 1 | AA35: =AA34+Close_A*(Ceil_E-AA34)-$E$5 -> 78.5 | AB35: =$E$4*Value_pt*(AA35-Eff_today) -> 75 | AC35: =AB35-Cost_A -> -45 | AD35: =AD34+AC35 -> 505 | AE35: =AE34+W_gain -> 60 | AF35: =Liq_today-AD35 -> 115 | AG35: =Pre_A+MAX(AF33:AF34) -> 540
A36: 3 | B36: =IF(AND(B35=1,F35>=Pre_A,G35>=W_min),1,0) -> 0 | C36: =C35+Close_A*(Ceil_E-C35)-$B$5 -> 83.25 | D36: =$B$4*Value_pt*(C36-Eff_today) -> 0 | E36: =D36-Cost_A -> -120 | F36: =F35+E36 -> 260 | G36: =G35+W_gain -> 61 | H36: =Liq_today-F36 -> 360 | I36: =Pre_A+MAX(H33:H35) -> 710 | J36: =IF(AND(J35=1,N35>=Pre_A,O35>=W_min),1,0) -> 1 | K36: =K35+Close_A*(Ceil_E-K35)-$C$5 -> 83.25 | L36: =$C$4*Value_pt*(K36-Eff_today) -> 122.5 | M36: =L36-Cost_A -> 2.5 | N36: =N35+M36 -> 557.5 | O36: =O35+W_gain -> 61 | P36: =Liq_today-N36 -> 62.5 | Q36: =Pre_A+MAX(P33:P35) -> 535 | R36: =IF(AND(R35=1,V35>=Pre_A,W35>=W_min),1,0) -> 1 | S36: =S35+Close_A*(Ceil_E-S35)-$D$5 -> 81.5 | T36: =$D$4*Value_pt*(S36-Eff_today) -> 105 | U36: =T36-Cost_A -> -15 | V36: =V35+U36 -> 515 | W36: =W35+W_gain -> 61 | X36: =Liq_today-V36 -> 105 | Y36: =Pre_A+MAX(X33:X35) -> 560 | Z36: =IF(AND(Z35=1,AD35>=Pre_A,AE35>=W_min),1,0) -> 1 | AA36: =AA35+Close_A*(Ceil_E-AA35)-$E$5 -> 79.75 | AB36: =$E$4*Value_pt*(AA36-Eff_today) -> 87.5 | AC36: =AB36-Cost_A -> -32.5 | AD36: =AD35+AC36 -> 472.5 | AE36: =AE35+W_gain -> 61 | AF36: =Liq_today-AD36 -> 147.5 | AG36: =Pre_A+MAX(AF33:AF35) -> 585
A37: 4 | B37: =IF(AND(B36=1,F36>=Pre_A,G36>=W_min),1,0) -> 0 | C37: =C36+Close_A*(Ceil_E-C36)-$B$5 -> 84.125 | D37: =$B$4*Value_pt*(C37-Eff_today) -> 0 | E37: =D37-Cost_A -> -120 | F37: =F36+E37 -> 140 | G37: =G36+W_gain -> 62 | H37: =Liq_today-F37 -> 480 | I37: =Pre_A+MAX(H33:H36) -> 830 | J37: =IF(AND(J36=1,N36>=Pre_A,O36>=W_min),1,0) -> 1 | K37: =K36+Close_A*(Ceil_E-K36)-$C$5 -> 84.125 | L37: =$C$4*Value_pt*(K37-Eff_today) -> 131.25 | M37: =L37-Cost_A -> 11.25 | N37: =N36+M37 -> 568.75 | O37: =O36+W_gain -> 62 | P37: =Liq_today-N37 -> 51.25 | Q37: =Pre_A+MAX(P33:P36) -> 535 | R37: =IF(AND(R36=1,V36>=Pre_A,W36>=W_min),1,0) -> 1 | S37: =S36+Close_A*(Ceil_E-S36)-$D$5 -> 82.25 | T37: =$D$4*Value_pt*(S37-Eff_today) -> 112.5 | U37: =T37-Cost_A -> -7.5 | V37: =V36+U37 -> 507.5 | W37: =W36+W_gain -> 62 | X37: =Liq_today-V37 -> 112.5 | Y37: =Pre_A+MAX(X33:X36) -> 575 | Z37: =IF(AND(Z36=1,AD36>=Pre_A,AE36>=W_min),1,0) -> 1 | AA37: =AA36+Close_A*(Ceil_E-AA36)-$E$5 -> 80.375 | AB37: =$E$4*Value_pt*(AA37-Eff_today) -> 93.75 | AC37: =AB37-Cost_A -> -26.25 | AD37: =AD36+AC37 -> 446.25 | AE37: =AE36+W_gain -> 62 | AF37: =Liq_today-AD37 -> 173.75 | AG37: =Pre_A+MAX(AF33:AF36) -> 617.5
A38: 5 | B38: =IF(AND(B37=1,F37>=Pre_A,G37>=W_min),1,0) -> 0 | C38: =C37+Close_A*(Ceil_E-C37)-$B$5 -> 84.5625 | D38: =$B$4*Value_pt*(C38-Eff_today) -> 0 | E38: =D38-Cost_A -> -120 | F38: =F37+E38 -> 20 | G38: =G37+W_gain -> 63 | H38: =Liq_today-F38 -> 600 | I38: =Pre_A+MAX(H33:H37) -> 950 | J38: =IF(AND(J37=1,N37>=Pre_A,O37>=W_min),1,0) -> 1 | K38: =K37+Close_A*(Ceil_E-K37)-$C$5 -> 84.5625 | L38: =$C$4*Value_pt*(K38-Eff_today) -> 135.625 | M38: =L38-Cost_A -> 15.625 | N38: =N37+M38 -> 584.375 | O38: =O37+W_gain -> 63 | P38: =Liq_today-N38 -> 35.625 | Q38: =Pre_A+MAX(P33:P37) -> 535 | R38: =IF(AND(R37=1,V37>=Pre_A,W37>=W_min),1,0) -> 1 | S38: =S37+Close_A*(Ceil_E-S37)-$D$5 -> 82.625 | T38: =$D$4*Value_pt*(S38-Eff_today) -> 116.25 | U38: =T38-Cost_A -> -3.75 | V38: =V37+U38 -> 503.75 | W38: =W37+W_gain -> 63 | X38: =Liq_today-V38 -> 116.25 | Y38: =Pre_A+MAX(X33:X37) -> 582.5 | Z38: =IF(AND(Z37=1,AD37>=Pre_A,AE37>=W_min),1,0) -> 0 | AA38: =AA37+Close_A*(Ceil_E-AA37)-$E$5 -> 80.6875 | AB38: =$E$4*Value_pt*(AA38-Eff_today) -> 96.875 | AC38: =AB38-Cost_A -> -23.125 | AD38: =AD37+AC38 -> 423.125 | AE38: =AE37+W_gain -> 63 | AF38: =Liq_today-AD38 -> 196.875 | AG38: =Pre_A+MAX(AF33:AF37) -> 643.75
A39: 6 | B39: =IF(AND(B38=1,F38>=Pre_A,G38>=W_min),1,0) -> 0 | C39: =C38+Close_A*(Ceil_E-C38)-$B$5 -> 84.78125 | D39: =$B$4*Value_pt*(C39-Eff_today) -> 0 | E39: =D39-Cost_A -> -120 | F39: =F38+E39 -> -100 | G39: =G38+W_gain -> 64 | H39: =Liq_today-F39 -> 720 | I39: =Pre_A+MAX(H33:H38) -> 1070 | J39: =IF(AND(J38=1,N38>=Pre_A,O38>=W_min),1,0) -> 1 | K39: =K38+Close_A*(Ceil_E-K38)-$C$5 -> 84.78125 | L39: =$C$4*Value_pt*(K39-Eff_today) -> 137.8125 | M39: =L39-Cost_A -> 17.8125 | N39: =N38+M39 -> 602.1875 | O39: =O38+W_gain -> 64 | P39: =Liq_today-N39 -> 17.8125 | Q39: =Pre_A+MAX(P33:P38) -> 535 | R39: =IF(AND(R38=1,V38>=Pre_A,W38>=W_min),1,0) -> 1 | S39: =S38+Close_A*(Ceil_E-S38)-$D$5 -> 82.8125 | T39: =$D$4*Value_pt*(S39-Eff_today) -> 118.125 | U39: =T39-Cost_A -> -1.875 | V39: =V38+U39 -> 501.875 | W39: =W38+W_gain -> 64 | X39: =Liq_today-V39 -> 118.125 | Y39: =Pre_A+MAX(X33:X38) -> 586.25 | Z39: =IF(AND(Z38=1,AD38>=Pre_A,AE38>=W_min),1,0) -> 0 | AA39: =AA38+Close_A*(Ceil_E-AA38)-$E$5 -> 80.84375 | AB39: =$E$4*Value_pt*(AA39-Eff_today) -> 98.4375 | AC39: =AB39-Cost_A -> -21.5625 | AD39: =AD38+AC39 -> 401.5625 | AE39: =AE38+W_gain -> 64 | AF39: =Liq_today-AD39 -> 218.4375 | AG39: =Pre_A+MAX(AF33:AF38) -> 666.875
A40: 7 | B40: =IF(AND(B39=1,F39>=Pre_A,G39>=W_min),1,0) -> 0 | C40: =C39+Close_A*(Ceil_E-C39)-$B$5 -> 84.890625 | D40: =$B$4*Value_pt*(C40-Eff_today) -> 0 | E40: =D40-Cost_A -> -120 | F40: =F39+E40 -> -220 | G40: =G39+W_gain -> 65 | H40: =Liq_today-F40 -> 840 | I40: =Pre_A+MAX(H33:H39) -> 1190 | J40: =IF(AND(J39=1,N39>=Pre_A,O39>=W_min),1,0) -> 1 | K40: =K39+Close_A*(Ceil_E-K39)-$C$5 -> 84.890625 | L40: =$C$4*Value_pt*(K40-Eff_today) -> 138.90625 | M40: =L40-Cost_A -> 18.90625 | N40: =N39+M40 -> 621.09375 | O40: =O39+W_gain -> 65 | P40: =Liq_today-N40 -> -1.09375 | Q40: =Pre_A+MAX(P33:P39) -> 535 | R40: =IF(AND(R39=1,V39>=Pre_A,W39>=W_min),1,0) -> 1 | S40: =S39+Close_A*(Ceil_E-S39)-$D$5 -> 82.90625 | T40: =$D$4*Value_pt*(S40-Eff_today) -> 119.0625 | U40: =T40-Cost_A -> -0.9375 | V40: =V39+U40 -> 500.9375 | W40: =W39+W_gain -> 65 | X40: =Liq_today-V40 -> 119.0625 | Y40: =Pre_A+MAX(X33:X39) -> 588.125 | Z40: =IF(AND(Z39=1,AD39>=Pre_A,AE39>=W_min),1,0) -> 0 | AA40: =AA39+Close_A*(Ceil_E-AA39)-$E$5 -> 80.921875 | AB40: =$E$4*Value_pt*(AA40-Eff_today) -> 99.21875 | AC40: =AB40-Cost_A -> -20.78125 | AD40: =AD39+AC40 -> 380.78125 | AE40: =AE39+W_gain -> 65 | AF40: =Liq_today-AD40 -> 239.21875 | AG40: =Pre_A+MAX(AF33:AF39) -> 688.4375
A41: 8 | B41: =IF(AND(B40=1,F40>=Pre_A,G40>=W_min),1,0) -> 0 | C41: =C40+Close_A*(Ceil_E-C40)-$B$5 -> 84.945312 | D41: =$B$4*Value_pt*(C41-Eff_today) -> 0 | E41: =D41-Cost_A -> -120 | F41: =F40+E41 -> -340 | G41: =G40+W_gain -> 66 | H41: =Liq_today-F41 -> 960 | I41: =Pre_A+MAX(H33:H40) -> 1310 | J41: =IF(AND(J40=1,N40>=Pre_A,O40>=W_min),1,0) -> 1 | K41: =K40+Close_A*(Ceil_E-K40)-$C$5 -> 84.945312 | L41: =$C$4*Value_pt*(K41-Eff_today) -> 139.45312 | M41: =L41-Cost_A -> 19.453125 | N41: =N40+M41 -> 640.54688 | O41: =O40+W_gain -> 66 | P41: =Liq_today-N41 -> -20.546875 | Q41: =Pre_A+MAX(P33:P40) -> 535 | R41: =IF(AND(R40=1,V40>=Pre_A,W40>=W_min),1,0) -> 1 | S41: =S40+Close_A*(Ceil_E-S40)-$D$5 -> 82.953125 | T41: =$D$4*Value_pt*(S41-Eff_today) -> 119.53125 | U41: =T41-Cost_A -> -0.46875 | V41: =V40+U41 -> 500.46875 | W41: =W40+W_gain -> 66 | X41: =Liq_today-V41 -> 119.53125 | Y41: =Pre_A+MAX(X33:X40) -> 589.0625 | Z41: =IF(AND(Z40=1,AD40>=Pre_A,AE40>=W_min),1,0) -> 0 | AA41: =AA40+Close_A*(Ceil_E-AA40)-$E$5 -> 80.960938 | AB41: =$E$4*Value_pt*(AA41-Eff_today) -> 99.609375 | AC41: =AB41-Cost_A -> -20.390625 | AD41: =AD40+AC41 -> 360.39062 | AE41: =AE40+W_gain -> 66 | AF41: =Liq_today-AD41 -> 259.60938 | AG41: =Pre_A+MAX(AF33:AF40) -> 709.21875
A42: 9 | B42: =IF(AND(B41=1,F41>=Pre_A,G41>=W_min),1,0) -> 0 | C42: =C41+Close_A*(Ceil_E-C41)-$B$5 -> 84.972656 | D42: =$B$4*Value_pt*(C42-Eff_today) -> 0 | E42: =D42-Cost_A -> -120 | F42: =F41+E42 -> -460 | G42: =G41+W_gain -> 67 | H42: =Liq_today-F42 -> 1080 | I42: =Pre_A+MAX(H33:H41) -> 1430 | J42: =IF(AND(J41=1,N41>=Pre_A,O41>=W_min),1,0) -> 1 | K42: =K41+Close_A*(Ceil_E-K41)-$C$5 -> 84.972656 | L42: =$C$4*Value_pt*(K42-Eff_today) -> 139.72656 | M42: =L42-Cost_A -> 19.726562 | N42: =N41+M42 -> 660.27344 | O42: =O41+W_gain -> 67 | P42: =Liq_today-N42 -> -40.273438 | Q42: =Pre_A+MAX(P33:P41) -> 535 | R42: =IF(AND(R41=1,V41>=Pre_A,W41>=W_min),1,0) -> 1 | S42: =S41+Close_A*(Ceil_E-S41)-$D$5 -> 82.976562 | T42: =$D$4*Value_pt*(S42-Eff_today) -> 119.76562 | U42: =T42-Cost_A -> -0.234375 | V42: =V41+U42 -> 500.23438 | W42: =W41+W_gain -> 67 | X42: =Liq_today-V42 -> 119.76562 | Y42: =Pre_A+MAX(X33:X41) -> 589.53125 | Z42: =IF(AND(Z41=1,AD41>=Pre_A,AE41>=W_min),1,0) -> 0 | AA42: =AA41+Close_A*(Ceil_E-AA41)-$E$5 -> 80.980469 | AB42: =$E$4*Value_pt*(AA42-Eff_today) -> 99.804688 | AC42: =AB42-Cost_A -> -20.195312 | AD42: =AD41+AC42 -> 340.19531 | AE42: =AE41+W_gain -> 67 | AF42: =Liq_today-AD42 -> 279.80469 | AG42: =Pre_A+MAX(AF33:AF41) -> 729.60938
A43: 10 | B43: =IF(AND(B42=1,F42>=Pre_A,G42>=W_min),1,0) -> 0 | C43: =C42+Close_A*(Ceil_E-C42)-$B$5 -> 84.986328 | D43: =$B$4*Value_pt*(C43-Eff_today) -> 0 | E43: =D43-Cost_A -> -120 | F43: =F42+E43 -> -580 | G43: =G42+W_gain -> 68 | H43: =Liq_today-F43 -> 1200 | I43: =Pre_A+MAX(H33:H42) -> 1550 | J43: =IF(AND(J42=1,N42>=Pre_A,O42>=W_min),1,0) -> 1 | K43: =K42+Close_A*(Ceil_E-K42)-$C$5 -> 84.986328 | L43: =$C$4*Value_pt*(K43-Eff_today) -> 139.86328 | M43: =L43-Cost_A -> 19.863281 | N43: =N42+M43 -> 680.13672 | O43: =O42+W_gain -> 68 | P43: =Liq_today-N43 -> -60.136719 | Q43: =Pre_A+MAX(P33:P42) -> 535 | R43: =IF(AND(R42=1,V42>=Pre_A,W42>=W_min),1,0) -> 1 | S43: =S42+Close_A*(Ceil_E-S42)-$D$5 -> 82.988281 | T43: =$D$4*Value_pt*(S43-Eff_today) -> 119.88281 | U43: =T43-Cost_A -> -0.1171875 | V43: =V42+U43 -> 500.11719 | W43: =W42+W_gain -> 68 | X43: =Liq_today-V43 -> 119.88281 | Y43: =Pre_A+MAX(X33:X42) -> 589.76562 | Z43: =IF(AND(Z42=1,AD42>=Pre_A,AE42>=W_min),1,0) -> 0 | AA43: =AA42+Close_A*(Ceil_E-AA42)-$E$5 -> 80.990234 | AB43: =$E$4*Value_pt*(AA43-Eff_today) -> 99.902344 | AC43: =AB43-Cost_A -> -20.097656 | AD43: =AD42+AC43 -> 320.09766 | AE43: =AE42+W_gain -> 68 | AF43: =Liq_today-AD43 -> 299.90234 | AG43: =Pre_A+MAX(AF33:AF42) -> 749.80469
A44: 11 | B44: =IF(AND(B43=1,F43>=Pre_A,G43>=W_min),1,0) -> 0 | C44: =C43+Close_A*(Ceil_E-C43)-$B$5 -> 84.993164 | D44: =$B$4*Value_pt*(C44-Eff_today) -> 0 | E44: =D44-Cost_A -> -120 | F44: =F43+E44 -> -700 | G44: =G43+W_gain -> 69 | H44: =Liq_today-F44 -> 1320 | I44: =Pre_A+MAX(H33:H43) -> 1670 | J44: =IF(AND(J43=1,N43>=Pre_A,O43>=W_min),1,0) -> 1 | K44: =K43+Close_A*(Ceil_E-K43)-$C$5 -> 84.993164 | L44: =$C$4*Value_pt*(K44-Eff_today) -> 139.93164 | M44: =L44-Cost_A -> 19.931641 | N44: =N43+M44 -> 700.06836 | O44: =O43+W_gain -> 69 | P44: =Liq_today-N44 -> -80.068359 | Q44: =Pre_A+MAX(P33:P43) -> 535 | R44: =IF(AND(R43=1,V43>=Pre_A,W43>=W_min),1,0) -> 1 | S44: =S43+Close_A*(Ceil_E-S43)-$D$5 -> 82.994141 | T44: =$D$4*Value_pt*(S44-Eff_today) -> 119.94141 | U44: =T44-Cost_A -> -0.05859375 | V44: =V43+U44 -> 500.05859 | W44: =W43+W_gain -> 69 | X44: =Liq_today-V44 -> 119.94141 | Y44: =Pre_A+MAX(X33:X43) -> 589.88281 | Z44: =IF(AND(Z43=1,AD43>=Pre_A,AE43>=W_min),1,0) -> 0 | AA44: =AA43+Close_A*(Ceil_E-AA43)-$E$5 -> 80.995117 | AB44: =$E$4*Value_pt*(AA44-Eff_today) -> 99.951172 | AC44: =AB44-Cost_A -> -20.048828 | AD44: =AD43+AC44 -> 300.04883 | AE44: =AE43+W_gain -> 69 | AF44: =Liq_today-AD44 -> 319.95117 | AG44: =Pre_A+MAX(AF33:AF43) -> 769.90234
A45: 12 | B45: =IF(AND(B44=1,F44>=Pre_A,G44>=W_min),1,0) -> 0 | C45: =C44+Close_A*(Ceil_E-C44)-$B$5 -> 84.996582 | D45: =$B$4*Value_pt*(C45-Eff_today) -> 0 | E45: =D45-Cost_A -> -120 | F45: =F44+E45 -> -820 | G45: =G44+W_gain -> 70 | H45: =Liq_today-F45 -> 1440 | I45: =Pre_A+MAX(H33:H44) -> 1790 | J45: =IF(AND(J44=1,N44>=Pre_A,O44>=W_min),1,0) -> 1 | K45: =K44+Close_A*(Ceil_E-K44)-$C$5 -> 84.996582 | L45: =$C$4*Value_pt*(K45-Eff_today) -> 139.96582 | M45: =L45-Cost_A -> 19.96582 | N45: =N44+M45 -> 720.03418 | O45: =O44+W_gain -> 70 | P45: =Liq_today-N45 -> -100.03418 | Q45: =Pre_A+MAX(P33:P44) -> 535 | R45: =IF(AND(R44=1,V44>=Pre_A,W44>=W_min),1,0) -> 1 | S45: =S44+Close_A*(Ceil_E-S44)-$D$5 -> 82.99707 | T45: =$D$4*Value_pt*(S45-Eff_today) -> 119.9707 | U45: =T45-Cost_A -> -0.029296875 | V45: =V44+U45 -> 500.0293 | W45: =W44+W_gain -> 70 | X45: =Liq_today-V45 -> 119.9707 | Y45: =Pre_A+MAX(X33:X44) -> 589.94141 | Z45: =IF(AND(Z44=1,AD44>=Pre_A,AE44>=W_min),1,0) -> 0 | AA45: =AA44+Close_A*(Ceil_E-AA44)-$E$5 -> 80.997559 | AB45: =$E$4*Value_pt*(AA45-Eff_today) -> 99.975586 | AC45: =AB45-Cost_A -> -20.024414 | AD45: =AD44+AC45 -> 280.02441 | AE45: =AE44+W_gain -> 70 | AF45: =Liq_today-AD45 -> 339.97559 | AG45: =Pre_A+MAX(AF33:AF44) -> 789.95117
...

Sheet Reachability
A1: Explore reachability: every program of up to four moves, grown breadth first (Theorem 6.4; Online Appendix Remark 6.B.3; AXIOM Lab 1.6, step 4)
A2: R_k: the states reached by programs of at most k moves (Definition 6.9). A row is a new state when its program runs and no earlier row reached the same state; grey rows do not run. Change the targets and the cushion to tighten or loosen the goal.
A3: Goal | B3: Value
A4: Technology target | B4: =Target_T -> 70
A5: Cushion over the floor required ($ million) | B5: 0
A6: Efficiency target | B6: =Target_E -> 80
A7: Depth k | B7: 0 | C7: 1 | D7: 2 | E7: 3 | F7: 4
A8: States in R_k | B8: =SUMPRODUCT(($B$35:$B$375<=0)*($R$35:$R$375=1)) -> 1 | C8: =SUMPRODUCT(($B$35:$B$375<=1)*($R$35:$R$375=1)) -> 5 | D8: =SUMPRODUCT(($B$35:$B$375<=2)*($R$35:$R$375=1)) -> 13 | E8: =SUMPRODUCT(($B$35:$B$375<=3)*($R$35:$R$375=1)) -> 21 | F8: =SUMPRODUCT(($B$35:$B$375<=4)*($R$35:$R$375=1)) -> 28
A9: Programs of length k that run | B9: =SUMIFS($L$35:$L$375,$B$35:$B$375,0) -> 1 | C9: =SUMIFS($L$35:$L$375,$B$35:$B$375,1) -> 4 | D9: =SUMIFS($L$35:$L$375,$B$35:$B$375,2) -> 9 | E9: =SUMIFS($L$35:$L$375,$B$35:$B$375,3) -> 12 | F9: =SUMIFS($L$35:$L$375,$B$35:$B$375,4) -> 11
A10: Highest technology in R_k | B10: =_xlfn.MAXIFS($N$35:$N$375,$L$35:$L$375,1,$B$35:$B$375,"<="&0) -> 41 | C10: =_xlfn.MAXIFS($N$35:$N$375,$L$35:$L$375,1,$B$35:$B$375,"<="&1) -> 75.634669 | D10: =_xlfn.MAXIFS($N$35:$N$375,$L$35:$L$375,1,$B$35:$B$375,"<="&2) -> 75.634669 | E10: =_xlfn.MAXIFS($N$35:$N$375,$L$35:$L$375,1,$B$35:$B$375,"<="&3) -> 75.634669 | F10: =_xlfn.MAXIFS($N$35:$N$375,$L$35:$L$375,1,$B$35:$B$375,"<="&4) -> 75.634669
A12: Programs of five moves that run (closure: R_5 = R_4 when zero) | B12: =SUM($T$35:$T$375) -> 0
A13: First depth at which the goal is met | B13: =IF(COUNTIFS($L$35:$L$375,1,$N$35:$N$375,">="&($B$4-0.000000001),$P$35:$P$375,">="&($B$6-0.000000001),$M$35:$M$375,">="&(Floor_q+$B$5-0.000000001))=0,"not reachable",_xlfn.MINIFS($B$35:$B$375,$L$35:$L$375,1,$N$35:$N$375,">="&($B$4-0.000000001),$P$35:$P$375,">="&($B$6-0.000000001),$M$35:$M$375,">="&(Floor_q+$B$5-0.000000001))) -> 2
A14: Programs that meet the goal | B14: =COUNTIFS($L$35:$L$375,1,$N$35:$N$375,">="&($B$4-0.000000001),$P$35:$P$375,">="&($B$6-0.000000001),$M$35:$M$375,">="&(Floor_q+$B$5-0.000000001)) -> 7
A15: Distinct states that meet the goal | B15: =SUMPRODUCT(($R$35:$R$375=1)*($N$35:$N$375>=$B$4-0.000000001)*($P$35:$P$375>=$B$6-0.000000001)*($M$35:$M$375>=Floor_q+$B$5-0.000000001)) -> 5
A16: Liquidity of the best state that meets the goal | B16: =IF(B14=0,"none",_xlfn.MAXIFS($M$35:$M$375,$L$35:$L$375,1,$N$35:$N$375,">="&($B$4-0.000000001),$P$35:$P$375,">="&($B$6-0.000000001),$M$35:$M$375,">="&(Floor_q+$B$5-0.000000001))) -> 556.63273
A17: Largest cushion with which the target stays reachable | B17: =_xlfn.MAXIFS($M$35:$M$375,$L$35:$L$375,1,$N$35:$N$375,">="&($B$4-0.000000001),$P$35:$P$375,">="&($B$6-0.000000001))-Floor_q -> 206.63273
A18: Highest technology the repertoire can reach | B18: =_xlfn.MAXIFS($N$35:$N$375,$L$35:$L$375,1) -> 75.634669
A19: Technology levels it can reach: distinct values | B19: =IF(COUNTIFS($L$35:$L$375,1,$N$35:$N$375,">="&36.85,$N$35:$N$375,"<"&36.95)>0,36.9,"") -> 36.9 | C19: =IF(COUNTIFS($L$35:$L$375,1,$N$35:$N$375,">="&40.95,$N$35:$N$375,"<"&41.05)>0,41,"") -> 41 | D19: =IF(COUNTIFS($L$35:$L$375,1,$N$35:$N$375,">="&68.05,$N$35:$N$375,"<"&68.15)>0,68.1,"") -> 68.1 | E19: =IF(COUNTIFS($L$35:$L$375,1,$N$35:$N$375,">="&71.45,$N$35:$N$375,"<"&71.55)>0,71.5,"") -> 71.5 | F19: =IF(COUNTIFS($L$35:$L$375,1,$N$35:$N$375,">="&75.55,$N$35:$N$375,"<"&75.65)>0,75.6,"") -> 75.6
A21: Complete goal: efficiency within eps of the ceiling of 85 (Remark 6.B.3) | B21: Tolerance eps | C21: Rounds needed | D21: Efficiency then | E21: One round fewer
A22: recycled rounds: efficiency 85 - 14 x 0.5^k never reaches 85 | B22: 2 | C22: =ROUNDUP(LN((Ceil_E-Eff_today)/B22)/LN(1/(1-Close_A)),0) -> 3 | D22: =Ceil_E-(Ceil_E-Eff_today)*(1-Close_A)^C22 -> 83.25 | E22: =Ceil_E-(Ceil_E-Eff_today)*(1-Close_A)^(C22-1) -> 81.5
A23: recycled rounds: efficiency 85 - 14 x 0.5^k never reaches 85 | B23: 1 | C23: =ROUNDUP(LN((Ceil_E-Eff_today)/B23)/LN(1/(1-Close_A)),0) -> 4 | D23: =Ceil_E-(Ceil_E-Eff_today)*(1-Close_A)^C23 -> 84.125 | E23: =Ceil_E-(Ceil_E-Eff_today)*(1-Close_A)^(C23-1) -> 83.25
