Workbook

Sheet README
B1: DCT Laboratory — Vol I, Ch 13: Unified Enterprise Transformation Architecture
B2: Seed 26113 · Companion to DCT_V1_Ch13_Lab.ipynb and AXIOM Lab 1.13 (module AXIOM-13). Money in $ million.
B4: Worked Example 13.1, Is the Same Cash Promised Twice?, with the book's declarations, and the five steps of AXIOM Lab 1.13, One Company, Five Ledgers.
B5: Declarations: the inputs of Worked Example 13.1, Chapter 1's model (Online Appendix 1.B.4), Figure 13.2's cycle.
B6: Assemble: Meridian's skeleton (Chapter 9), the layers' references, contracts and buffer identity, and the compatibility checks (C1)-(C5) at each attachment in two orders (lab step 1).
B7: Couplings: Figure 13.2's three-layer cycle quarter by quarter, and an interaction-matrix editor that finds rho(M) and its split by block by power iteration (lab step 2).
B8: Wavefront: distances on the skeleton by relaxation, the ledger clocks of the digital program and of a demand shock, the feedback core, and the ancestors of a tripwire (lab step 3).
B9: Ledgers: the program month by month in three ledgers, Figure 13.1 (lab step 5).
B10: JointCheck: the sign-offs, the joint check and the buffer line, Figure 13.3 (Worked Example 13.1, Steps 1-3; lab step 4).
B11: Repairs: Table 13.6 (Step 4). Decide: the separated verdicts against the unified one (Step 5; lab step 5).
B12: Only the breach odds and the average simulated low are the engine's (the book's 100,000 paths, seed 8; a fresh stream with the lab's seed 26113). Reference_Values and Checks: the notebook engine's numbers and a PASS/FAIL comparison with this workbook's formulas.
B14: LEGEND
... B18: Cross-sheet link: green.

Sheet Declarations
A1: Declarations (Worked Example 13.1, Step 1; Table 13.1). Money in $ million.
A3: Quantity | B3: Value | C3: Source
A4: Liquidity today ($ million) | B4: 620 | C4: Table 3.1; Worked Example 13.1, Step 1
A5: The board's liquidity floor ($ million) | B5: 350 | C5: Table 5.4; at treasury (Table 9.3)
A6: Cash above the floor ($ million) | B6: =B4-B5 -> 270 | C6: Worked Example 13.1: $270 million
A7: Liquidity per index point ($ million) | B7: =B4/100 -> 6.2 | C7: Chapter 1: index 100 = $620 million
A8: Phased build: trough depth (index points) | B8: 20 | C8: Chapter 8: depth 20 instead of 28
A9: Closure size: mean ($ million) | B9: 120 | C9: Chapter 8, Worked Example 8.1
A10: Closure size: standard deviation ($ million) | B10: 50 | C10: Chapter 8, Worked Example 8.1
A11: Closure law: gamma shape, (mean / sd)^2 | B11: =(B9/B10)^2 -> 5.76 | C11: 5.76
A12: Closure law: gamma scale, sd^2 / mean | B12: =B10^2/B9 -> 20.833333 | C12: 20.83
A13: The risk office's buffer: closure percentile | B13: 0.9 | C13: Chapter 12: the 90th-percentile closure
A14: The relaxed buffer: closure percentile | B14: 0.5 | C14: Worked Example 13.1, Step 4: the median closure
A15: Standby line: cover of any closure ($ million) | B15: 100 | C15: Chapter 8
A16: The board's appetite: breach probability at most | B16: 0.05 | C16: Chapter 8
A17: Strategic-risk ceiling | B17: 75 | C17: Table 9.3
A18: Workforce capability today | B18: 58 | C18: Table 3.1
A19: Capability floor for the digital build | B19: 55 | C19: Table 9.3 (engineering, Digital)
A20: Capability lost a quarter | B20: 0.025 | C20: Chapter 10
A21: Price of a capability point ($ million) | B21: 4 | C21: Chapter 10
A22: Capability rent ($ million a year), delta x 58 x 4 quarters x price | B22: =B20*B18*4*B21 -> 23.2 | C22: Table 13.1: $23 million a year
A23: Cycle: share of a loss each layer keeps a quarter, a | B23: 0.5 | C23: Figure 13.2
A24: Cycle: share passed on to the next layer, c | B24: 0.25 | C24: Figure 13.2: 0.25 (also 0.40)
A26: Chapter 1 model (Online Appendix 1.B.4) | B26: Today | C26: Target | D26: Speed a year | E26: Trough (signed) | F26: Trough time (years)
A27: Liquidity index (today = 100) | B27: 100 | C27: 112 | D27: 0.35 | E27: -28 | F27: 2
A28: Technology platform | B28: 41 | C28: 78 | D28: 0.55 | E28: 0 | F28: 1
A29: Operational efficiency | B29: 71 | C29: 77 | D29: 0.5 | E29: -9 | F29: 1.5
A30: Strategic risk | B30: 64 | C30: 51 | D30: 0.4 | E30: 14 | F30: 1.2
A31: x(t) = target + (today - target) e^(-speed t) + trough (t / trough time) e^(1 - t / trough time), t in years; technology has no trough. The digital program's paths, as in Chapters 1, 8 and 13.

Sheet Assemble
A1: Assemble: Meridian's unified architecture on one skeleton (Theorems 13.1 and 13.2(i); Definition 13.4; Table 13.1; AXIOM Lab 1.13, step 1)
A2: Attach the layers in two orders. Integration adjoins a declaration (Definition 13.3), so the result is the same; only the step at which (C4) fails moves.
A4: Component (Table 9.1) | B4: Name | D4: Arrow from | E4: to | F4: Type (Worked Example 9.1) | G4: Endpoints resolve | I4: Constraint (Table 9.3) | J4: Scope
A5: MKT | B5: market | D5: MKT | E5: IND | F5: demand | G5: =AND(COUNTIF(Comps,D5)=1,COUNTIF(Comps,E5)=1) -> TRUE | I5: Covenant: net leverage at most 4.5x | J5: TRS
A6: GOV | B6: governance | D6: MKT | E6: DIG | F6: demand | G6: =AND(COUNTIF(Comps,D6)=1,COUNTIF(Comps,E6)=1) -> TRUE | I6: Liquidity floor of $350 million | J6: TRS
A7: MAT | B7: Advanced Materials | D7: MKT | E7: MAT | F7: demand | G7: =AND(COUNTIF(Comps,D7)=1,COUNTIF(Comps,E7)=1) -> TRUE | I7: Plant capacity | J7: IND
A8: IND | B8: Industrial Systems | D8: IND | E8: TRS | F8: cash | G8: =AND(COUNTIF(Comps,D8)=1,COUNTIF(Comps,E8)=1) -> TRUE | I8: Strategic-risk ceiling of 75 | J8: IND, DIG, MAT
A9: DIG | B9: Digital Solutions | D9: DIG | E9: TRS | F9: cash | G9: =AND(COUNTIF(Comps,D9)=1,COUNTIF(Comps,E9)=1) -> TRUE | I9: Capability of at least 55 for the digital build | J9: ENG, DIG
A10: ENG | B10: shared engineering | D10: MAT | E10: TRS | F10: cash | G10: =AND(COUNTIF(Comps,D10)=1,COUNTIF(Comps,E10)=1) -> TRUE
A11: TRS | B11: treasury | D11: TRS | E11: IND | F11: funding | G11: =AND(COUNTIF(Comps,D11)=1,COUNTIF(Comps,E11)=1) -> TRUE
D12: TRS | E12: DIG | F12: funding | G12: =AND(COUNTIF(Comps,D12)=1,COUNTIF(Comps,E12)=1) -> TRUE
D13: ENG | E13: IND | F13: capability | G13: =AND(COUNTIF(Comps,D13)=1,COUNTIF(Comps,E13)=1) -> TRUE
D14: IND | E14: ENG | F14: capability | G14: =AND(COUNTIF(Comps,D14)=1,COUNTIF(Comps,E14)=1) -> TRUE
D15: ENG | E15: DIG | F15: capability | G15: =AND(COUNTIF(Comps,D15)=1,COUNTIF(Comps,E15)=1) -> TRUE
D16: DIG | E16: ENG | F16: capability | G16: =AND(COUNTIF(Comps,D16)=1,COUNTIF(Comps,E16)=1) -> TRUE
D17: GOV | E17: TRS | F17: policy | G17: =AND(COUNTIF(Comps,D17)=1,COUNTIF(Comps,E17)=1) -> TRUE
D18: GOV | E18: DIG | F18: policy | G18: =AND(COUNTIF(Comps,D18)=1,COUNTIF(Comps,E18)=1) -> TRUE
A21: Form of capital (Table 10.1) | C21: Performance dimension (Table 11.2)
A22: Financial | C22: Financial
A23: Human | C23: Operational
A24: Intellectual | C24: Strategic
A25: Technological | C25: Human
A26: Organizational | C26: Technological
A27: Relational | C27: Innovation
A28: Strategic | C28: Governance
A29: Governance | C29: Environmental
A30: Innovation | C30: Resilience
A31: Informational | C31: Sustainability
A33: Counts | B33: Value | C33: Book
A34: Components | B34: =COUNTA(A5:A11) -> 7 | C34: Table 13.1: seven
A35: Arrows | B35: =COUNTA(D5:D18) -> 14 | C35: Worked Example 9.1: fourteen
A36: Arrows whose endpoints resolve | B36: =COUNTIF(G5:G18,TRUE()) -> 14
A37: Forms of capital | B37: =COUNTA(A22:A31) -> 10 | C37: Table 13.1: ten forms
A38: Performance dimensions | B38: =COUNTA(C22:C31) -> 10 | C38: Table 13.1: ten dimensions
A39: Capability rent ($ million a year) | B39: =Rent_year -> 23.2 | C39: Table 13.1: $23 million
A42: Layer | B42: Carrier, support, write set or buffer | C42: Component | D42: Resolves (C1) | F42: Layer | G42: References | H42: Unresolved (C1)
A43: transformation | B43: digital build: write set | C43: DIG | D43: =COUNTIF(Comps,C43)=1 -> TRUE | F43: transformation | G43: =COUNTIF(Ref_layer,"transformation") -> 3 | H43: =COUNTIFS(Ref_layer,"transformation",Ref_ok,FALSE()) -> 0
A44: transformation | B44: digital build: write set | C44: ENG | D44: =COUNTIF(Comps,C44)=1 -> TRUE | F44: capital | G44: =COUNTIF(Ref_layer,"capital") -> 4 | H44: =COUNTIFS(Ref_layer,"capital",Ref_ok,FALSE()) -> 0
A45: transformation | B45: program draw D | C45: DIG | D45: =COUNTIF(Comps,C45)=1 -> TRUE | F45: performance | G45: =COUNTIF(Ref_layer,"performance") -> 10 | H45: =COUNTIFS(Ref_layer,"performance",Ref_ok,FALSE()) -> 0
A46: capital | B46: liquidity | C46: TRS | D46: =COUNTIF(Comps,C46)=1 -> TRUE | F46: risk | G46: =COUNTIF(Ref_layer,"risk") -> 16 | H46: =COUNTIFS(Ref_layer,"risk",Ref_ok,FALSE()) -> 0
...

Sheet Couplings
A1: Wire the couplings: every layer passes, the whole fails (Theorem 13.3(ii); Figure 13.2; Online Appendix 13.B.1; AXIOM Lab 1.13, step 2)
A2: Losses propagate as l(k+1) = M l(k), rows receiving. The total impact of a unit loss is finite exactly when rho(M) < 1.
A4: Figure 13.2's cycle: M (rows receive) | B4: from capital | C4: from performance | D4: from risk | H4: Cross-layer share c | I4: rho(M) = a + c | J4: Total impact | K4: Each layer alone
A5: to capital | B5: =A_keep -> 0.5 | C5: 0 | D5: =C_pass -> 0.25 | H5: 0 | I5: =A_keep+H5 -> 0.5 | J5: =IF(I5<1,1/(1-I5),"no finite bill") -> 2 | K5: =1/(1-A_keep) -> 2
A6: to performance | B6: =C_pass -> 0.25 | C6: =A_keep -> 0.5 | D6: 0 | H6: 0.1 | I6: =A_keep+H6 -> 0.6 | J6: =IF(I6<1,1/(1-I6),"no finite bill") -> 2.5 | K6: =1/(1-A_keep) -> 2
A7: to risk | B7: 0 | C7: =C_pass -> 0.25 | D7: =A_keep -> 0.5 | H7: 0.2 | I7: =A_keep+H7 -> 0.7 | J7: =IF(I7<1,1/(1-I7),"no finite bill") -> 3.3333333 | K7: =1/(1-A_keep) -> 2
A8: Column sums | B8: =SUM(B5:B7) -> 0.75 | C8: =SUM(C5:C7) -> 0.75 | D8: =SUM(D5:D7) -> 0.75 | H8: 0.25 | I8: =A_keep+H8 -> 0.75 | J8: =IF(I8<1,1/(1-I8),"no finite bill") -> 4 | K8: =1/(1-A_keep) -> 2
H9: 0.3 | I9: =A_keep+H9 -> 0.8 | J9: =IF(I9<1,1/(1-I9),"no finite bill") -> 5 | K9: =1/(1-A_keep) -> 2
A10: Each layer's own radius, a | B10: =A_keep -> 0.5 | C10: every layer passes its own test | H10: 0.4 | I10: =A_keep+H10 -> 0.9 | J10: =IF(I10<1,1/(1-I10),"no finite bill") -> 10 | K10: =1/(1-A_keep) -> 2
A11: Each layer alone: total impact of a unit shock, 1/(1 - a) | B11: =1/(1-A_keep) -> 2 | C11: Figure 13.2: 2 | H11: 0.45 | I11: =A_keep+H11 -> 0.95 | J11: =IF(I11<1,1/(1-I11),"no finite bill") -> 20 | K11: =1/(1-A_keep) -> 2
A12: rho(M): every column sums to a + c | B12: =IF(MAX(B8:D8)-MIN(B8:D8)<0.000000000001,B8,-1) -> 0.75 | C12: Online Appendix 13.B.1 | H12: 0.5 | I12: =A_keep+H12 -> 1 | J12: =IF(I12<1,1/(1-I12),"no finite bill") -> no finite bill | K12: =1/(1-A_keep) -> 2
A13: The whole: total impact, 1/(1 - a - c) | B13: =IF(B12<1,1/(1-B12),"no finite bill") -> 4 | C13: Figure 13.2: 4 at c = 0.25 | H13: 0.6 | I13: =A_keep+H13 -> 1.1 | J13: =IF(I13<1,1/(1-I13),"no finite bill") -> no finite bill | K13: =1/(1-A_keep) -> 2
A14: Diagonal blocks' part of rho(M) | B14: =(B5+C6+D7)/3 -> 0.5 | C14: uniform Perron vectors: exactly a | P14: The editor's spectral report | Q14: Value
A15: Cross-layer blocks' part of rho(M) | B15: =(SUM(B5:D7)-(B5+C6+D7))/3 -> 0.25 | C15: exactly c: the whole difference | P15: rho(M), by power iteration | Q15: =L103 -> 0.75
A16: Cumulative bill after 200 quarters (table below) | B16: =F220 -> 4 | C16: the series sums to 1/(1 - a - c) | P16: Layer radii: capital, performance, risk | Q16: =TEXT($I$18,"0.00")&", "&TEXT($J$19,"0.00")&", "&TEXT($K$20,"0.00") -> 0.50, 0.50, 0.50
H17: Interaction-matrix editor: enter any gains | I17: from capital | J17: from performance | K17: from risk | P17: Largest layer radius | Q17: =MAX($I$18,$J$19,$K$20) -> 0.5
H18: to capital | I18: 0.5 | J18: 0 | K18: 0.25 | P18: Diagonal blocks' part of rho(M) | Q18: =(M103*$I$18*I103+N103*$J$19*J103+O103*$K$20*K103)/(M103*I103+N103*J103+O103*K103) -> 0.5
A19: Quarter | B19: Loss at capital | C19: at performance | D19: at risk | E19: This quarter | F19: Cumulative bill | H19: to performance | I19: 0.25 | J19: 0.5 | K19: 0 | P19: Cross-layer blocks' part of rho(M) | Q19: =Q15-Q18 -> 0.25
A20: 0 | B20: 1 | C20: 0 | D20: 0 | E20: =SUM(B20:D20) -> 1 | F20: =E20 -> 1 | H20: to risk | I20: 0 | J20: 0.25 | K20: 0.5 | P20: Verdict | Q20: =IF(AND(Q17<1,Q15<1),"every layer stable, the whole stable",IF(Q17<1,"every layer stable, the whole NOT","a layer fails its own test")) -> every layer stable, the whole stable
A21: 1 | B21: =A_keep*B20+C_pass*D20 -> 0.5 | C21: =C_pass*B20+A_keep*C20 -> 0.25 | D21: =C_pass*C20+A_keep*D20 -> 0 | E21: =SUM(B21:D21) -> 0.75 | F21: =F20+E21 -> 1.75 | P21: Total impact of a unit loss at capital | Q21: =IF(Q15<1,(Q25+Q26+Q27)/Q24,"no finite bill") -> 4
A22: 2 | B22: =A_keep*B21+C_pass*D21 -> 0.25 | C22: =C_pass*B21+A_keep*C21 -> 0.25 | D22: =C_pass*C21+A_keep*D21 -> 0.0625 | E22: =SUM(B22:D22) -> 0.5625 | F22: =F21+E22 -> 2.3125 | H22: Iteration | I22: v capital | J22: v performance | K22: v risk | L22: rho estimate | M22: u capital | N22: u performance | O22: u risk
A23: 3 | B23: =A_keep*B22+C_pass*D22 -> 0.140625 | C23: =C_pass*B22+A_keep*C22 -> 0.1875 | D23: =C_pass*C22+A_keep*D22 -> 0.09375 | E23: =SUM(B23:D23) -> 0.421875 | F23: =F22+E23 -> 2.734375 | H23: 0 | I23: 0.33333333 | J23: 0.33333333 | K23: 0.33333333 | L23: =($I$18+$I$19+$I$20)*I23+($J$18+$J$19+$J$20)*J23+($K$18+$K$19+$K$20)*K23 -> 0.75 | M23: 0.33333333 | N23: 0.33333333 | O23: 0.33333333 | P23: The total impact: column 1 of (I - M)^-1 by cofactors
A24: 4 | B24: =A_keep*B23+C_pass*D23 -> 0.09375 | C24: =C_pass*B23+A_keep*C23 -> 0.12890625 | D24: =C_pass*C23+A_keep*D23 -> 0.09375 | E24: =SUM(B24:D24) -> 0.31640625 | F24: =F23+E24 -> 3.0507812 | H24: 1 | I24: =($I$18*I23+$J$18*J23+$K$18*K23)/(($I$18+$I$19+$I$20)*I23+($J$18+$J$19+$J$20)*J23+($K$18+$K$19+$K$20)*K23) -> 0.33333333 | J24: =($I$19*I23+$J$19*J23+$K$19*K23)/(($I$18+$I$19+$I$20)*I23+($J$18+$J$19+$J$20)*J23+($K$18+$K$19+$K$20)*K23) -> 0.33333333 | K24: =($I$20*I23+$J$20*J23+$K$20*K23)/(($I$18+$I$19+$I$20)*I23+($J$18+$J$19+$J$20)*J23+($K$18+$K$19+$K$20)*K23) -> 0.33333333 | L24: =($I$18+$I$19+$I$20)*I24+($J$18+$J$19+$J$20)*J24+($K$18+$K$19+$K$20)*K24 -> 0.75 | M24: =(M23*$I$18+N23*$I$19+O23*$I$20)/(($I$18+$J$18+$K$18)*M23+($I$19+$J$19+$K$19)*N23+($I$20+$J$20+$K$20)*O23) -> 0.33333333 | N24: =(M23*$J$18+N23*$J$19+O23*$J$20)/(($I$18+$J$18+$K$18)*M23+($I$19+$J$19+$K$19)*N23+($I$20+$J$20+$K$20)*O23) -> 0.33333333 | O24: =(M23*$K$18+N23*$K$19+O23*$K$20)/(($I$18+$J$18+$K$18)*M23+($I$19+$J$19+$K$19)*N23+($I$20+$J$20+$K$20)*O23) -> 0.33333333 | P24: det(I - M) | Q24: =(1-$I$18)*((1-$J$19)*(1-$K$20)-(0-$K$19)*(0-$J$20))-(0-$J$18)*((0-$I$19)*(1-$K$20)-(0-$K$19)*(0-$I$20))+(0-$K$18)*((0-$I$19)*(0-$J$20)-(1-$J$19)*(0-$I$20)) -> 0.109375
A25: 5 | B25: =A_keep*B24+C_pass*D24 -> 0.0703125 | C25: =C_pass*B24+A_keep*C24 -> 0.087890625 | D25: =C_pass*C24+A_keep*D24 -> 0.079101562 | E25: =SUM(B25:D25) -> 0.23730469 | F25: =F24+E25 -> 3.2880859 | H25: 2 | I25: =($I$18*I24+$J$18*J24+$K$18*K24)/(($I$18+$I$19+$I$20)*I24+($J$18+$J$19+$J$20)*J24+($K$18+$K$19+$K$20)*K24) -> 0.33333333 | J25: =($I$19*I24+$J$19*J24+$K$19*K24)/(($I$18+$I$19+$I$20)*I24+($J$18+$J$19+$J$20)*J24+($K$18+$K$19+$K$20)*K24) -> 0.33333333 | K25: =($I$20*I24+$J$20*J24+$K$20*K24)/(($I$18+$I$19+$I$20)*I24+($J$18+$J$19+$J$20)*J24+($K$18+$K$19+$K$20)*K24) -> 0.33333333 | L25: =($I$18+$I$19+$I$20)*I25+($J$18+$J$19+$J$20)*J25+($K$18+$K$19+$K$20)*K25 -> 0.75 | M25: =(M24*$I$18+N24*$I$19+O24*$I$20)/(($I$18+$J$18+$K$18)*M24+($I$19+$J$19+$K$19)*N24+($I$20+$J$20+$K$20)*O24) -> 0.33333333 | N25: =(M24*$J$18+N24*$J$19+O24*$J$20)/(($I$18+$J$18+$K$18)*M24+($I$19+$J$19+$K$19)*N24+($I$20+$J$20+$K$20)*O24) -> 0.33333333 | O25: =(M24*$K$18+N24*$K$19+O24*$K$20)/(($I$18+$J$18+$K$18)*M24+($I$19+$J$19+$K$19)*N24+($I$20+$J$20+$K$20)*O24) -> 0.33333333 | P25: Cofactor C11 of I - M | Q25: =(1-$J$19)*(1-$K$20)-(0-$K$19)*(0-$J$20) -> 0.25
A26: 6 | B26: =A_keep*B25+C_pass*D25 -> 0.054931641 | C26: =C_pass*B25+A_keep*C25 -> 0.061523438 | D26: =C_pass*C25+A_keep*D25 -> 0.061523438 | E26: =SUM(B26:D26) -> 0.17797852 | F26: =F25+E26 -> 3.4660645 | H26: 3 | I26: =($I$18*I25+$J$18*J25+$K$18*K25)/(($I$18+$I$19+$I$20)*I25+($J$18+$J$19+$J$20)*J25+($K$18+$K$19+$K$20)*K25) -> 0.33333333 | J26: =($I$19*I25+$J$19*J25+$K$19*K25)/(($I$18+$I$19+$I$20)*I25+($J$18+$J$19+$J$20)*J25+($K$18+$K$19+$K$20)*K25) -> 0.33333333 | K26: =($I$20*I25+$J$20*J25+$K$20*K25)/(($I$18+$I$19+$I$20)*I25+($J$18+$J$19+$J$20)*J25+($K$18+$K$19+$K$20)*K25) -> 0.33333333 | L26: =($I$18+$I$19+$I$20)*I26+($J$18+$J$19+$J$20)*J26+($K$18+$K$19+$K$20)*K26 -> 0.75 | M26: =(M25*$I$18+N25*$I$19+O25*$I$20)/(($I$18+$J$18+$K$18)*M25+($I$19+$J$19+$K$19)*N25+($I$20+$J$20+$K$20)*O25) -> 0.33333333 | N26: =(M25*$J$18+N25*$J$19+O25*$J$20)/(($I$18+$J$18+$K$18)*M25+($I$19+$J$19+$K$19)*N25+($I$20+$J$20+$K$20)*O25) -> 0.33333333 | O26: =(M25*$K$18+N25*$K$19+O25*$K$20)/(($I$18+$J$18+$K$18)*M25+($I$19+$J$19+$K$19)*N25+($I$20+$J$20+$K$20)*O25) -> 0.33333333 | P26: Cofactor C12 of I - M | Q26: =-((0-$I$19)*(1-$K$20)-(0-$K$19)*(0-$I$20)) -> 0.125
A27: 7 | B27: =A_keep*B26+C_pass*D26 -> 0.04284668 | C27: =C_pass*B26+A_keep*C26 -> 0.044494629 | D27: =C_pass*C26+A_keep*D26 -> 0.046142578 | E27: =SUM(B27:D27) -> 0.13348389 | F27: =F26+E27 -> 3.5995483 | H27: 4 | I27: =($I$18*I26+$J$18*J26+$K$18*K26)/(($I$18+$I$19+$I$20)*I26+($J$18+$J$19+$J$20)*J26+($K$18+$K$19+$K$20)*K26) -> 0.33333333 | J27: =($I$19*I26+$J$19*J26+$K$19*K26)/(($I$18+$I$19+$I$20)*I26+($J$18+$J$19+$J$20)*J26+($K$18+$K$19+$K$20)*K26) -> 0.33333333 | K27: =($I$20*I26+$J$20*J26+$K$20*K26)/(($I$18+$I$19+$I$20)*I26+($J$18+$J$19+$J$20)*J26+($K$18+$K$19+$K$20)*K26) -> 0.33333333 | L27: =($I$18+$I$19+$I$20)*I27+($J$18+$J$19+$J$20)*J27+($K$18+$K$19+$K$20)*K27 -> 0.75 | M27: =(M26*$I$18+N26*$I$19+O26*$I$20)/(($I$18+$J$18+$K$18)*M26+($I$19+$J$19+$K$19)*N26+($I$20+$J$20+$K$20)*O26) -> 0.33333333 | N27: =(M26*$J$18+N26*$J$19+O26*$J$20)/(($I$18+$J$18+$K$18)*M26+($I$19+$J$19+$K$19)*N26+($I$20+$J$20+$K$20)*O26) -> 0.33333333 | O27: =(M26*$K$18+N26*$K$19+O26*$K$20)/(($I$18+$J$18+$K$18)*M26+($I$19+$J$19+$K$19)*N26+($I$20+$J$20+$K$20)*O26) -> 0.33333333 | P27: Cofactor C13 of I - M | Q27: =(0-$I$19)*(0-$J$20)-(1-$J$19)*(0-$I$20) -> 0.0625
A28: 8 | B28: =A_keep*B27+C_pass*D27 -> 0.032958984 | C28: =C_pass*B27+A_keep*C27 -> 0.032958984 | D28: =C_pass*C27+A_keep*D27 -> 0.034194946 | E28: =SUM(B28:D28) -> 0.10011292 | F28: =F27+E28 -> 3.6996613 | H28: 5 | I28: =($I$18*I27+$J$18*J27+$K$18*K27)/(($I$18+$I$19+$I$20)*I27+($J$18+$J$19+$J$20)*J27+($K$18+$K$19+$K$20)*K27) -> 0.33333333 | J28: =($I$19*I27+$J$19*J27+$K$19*K27)/(($I$18+$I$19+$I$20)*I27+($J$18+$J$19+$J$20)*J27+($K$18+$K$19+$K$20)*K27) -> 0.33333333 | K28: =($I$20*I27+$J$20*J27+$K$20*K27)/(($I$18+$I$19+$I$20)*I27+($J$18+$J$19+$J$20)*J27+($K$18+$K$19+$K$20)*K27) -> 0.33333333 | L28: =($I$18+$I$19+$I$20)*I28+($J$18+$J$19+$J$20)*J28+($K$18+$K$19+$K$20)*K28 -> 0.75 | M28: =(M27*$I$18+N27*$I$19+O27*$I$20)/(($I$18+$J$18+$K$18)*M27+($I$19+$J$19+$K$19)*N27+($I$20+$J$20+$K$20)*O27) -> 0.33333333 | N28: =(M27*$J$18+N27*$J$19+O27*$J$20)/(($I$18+$J$18+$K$18)*M27+($I$19+$J$19+$K$19)*N27+($I$20+$J$20+$K$20)*O27) -> 0.33333333 | O28: =(M27*$K$18+N27*$K$19+O27*$K$20)/(($I$18+$J$18+$K$18)*M27+($I$19+$J$19+$K$19)*N27+($I$20+$J$20+$K$20)*O27) -> 0.33333333
A29: 9 | B29: =A_keep*B28+C_pass*D28 -> 0.025028229 | C29: =C_pass*B28+A_keep*C28 -> 0.024719238 | D29: =C_pass*C28+A_keep*D28 -> 0.025337219 | E29: =SUM(B29:D29) -> 0.075084686 | F29: =F28+E29 -> 3.7747459 | H29: 6 | I29: =($I$18*I28+$J$18*J28+$K$18*K28)/(($I$18+$I$19+$I$20)*I28+($J$18+$J$19+$J$20)*J28+($K$18+$K$19+$K$20)*K28) -> 0.33333333 | J29: =($I$19*I28+$J$19*J28+$K$19*K28)/(($I$18+$I$19+$I$20)*I28+($J$18+$J$19+$J$20)*J28+($K$18+$K$19+$K$20)*K28) -> 0.33333333 | K29: =($I$20*I28+$J$20*J28+$K$20*K28)/(($I$18+$I$19+$I$20)*I28+($J$18+$J$19+$J$20)*J28+($K$18+$K$19+$K$20)*K28) -> 0.33333333 | L29: =($I$18+$I$19+$I$20)*I29+($J$18+$J$19+$J$20)*J29+($K$18+$K$19+$K$20)*K29 -> 0.75 | M29: =(M28*$I$18+N28*$I$19+O28*$I$20)/(($I$18+$J$18+$K$18)*M28+($I$19+$J$19+$K$19)*N28+($I$20+$J$20+$K$20)*O28) -> 0.33333333 | N29: =(M28*$J$18+N28*$J$19+O28*$J$20)/(($I$18+$J$18+$K$18)*M28+($I$19+$J$19+$K$19)*N28+($I$20+$J$20+$K$20)*O28) -> 0.33333333 | O29: =(M28*$K$18+N28*$K$19+O28*$K$20)/(($I$18+$J$18+$K$18)*M28+($I$19+$J$19+$K$19)*N28+($I$20+$J$20+$K$20)*O28) -> 0.33333333 | P29: Power iteration: v' = Mv / sum(Mv) and u' = u'M / sum(u'M), from equal weights. Each block's part is u_l M_ll' v_l' / u'v; the diagonal and the cross-layer parts add up to rho(M).
A30: 10 | B30: =A_keep*B29+C_pass*D29 -> 0.018848419 | C30: =C_pass*B29+A_keep*C29 -> 0.018616676 | D30: =C_pass*C29+A_keep*D29 -> 0.018848419 | E30: =SUM(B30:D30) -> 0.056313515 | F30: =F29+E30 -> 3.8310595 | H30: 7 | I30: =($I$18*I29+$J$18*J29+$K$18*K29)/(($I$18+$I$19+$I$20)*I29+($J$18+$J$19+$J$20)*J29+($K$18+$K$19+$K$20)*K29) -> 0.33333333 | J30: =($I$19*I29+$J$19*J29+$K$19*K29)/(($I$18+$I$19+$I$20)*I29+($J$18+$J$19+$J$20)*J29+($K$18+$K$19+$K$20)*K29) -> 0.33333333 | K30: =($I$20*I29+$J$20*J29+$K$20*K29)/(($I$18+$I$19+$I$20)*I29+($J$18+$J$19+$J$20)*J29+($K$18+$K$19+$K$20)*K29) -> 0.33333333 | L30: =($I$18+$I$19+$I$20)*I30+($J$18+$J$19+$J$20)*J30+($K$18+$K$19+$K$20)*K30 -> 0.75 | M30: =(M29*$I$18+N29*$I$19+O29*$I$20)/(($I$18+$J$18+$K$18)*M29+($I$19+$J$19+$K$19)*N29+($I$20+$J$20+$K$20)*O29) -> 0.33333333 | N30: =(M29*$J$18+N29*$J$19+O29*$J$20)/(($I$18+$J$18+$K$18)*M29+($I$19+$J$19+$K$19)*N29+($I$20+$J$20+$K$20)*O29) -> 0.33333333 | O30: =(M29*$K$18+N29*$K$19+O29*$K$20)/(($I$18+$J$18+$K$18)*M29+($I$19+$J$19+$K$19)*N29+($I$20+$J$20+$K$20)*O29) -> 0.33333333
A31: 11 | B31: =A_keep*B30+C_pass*D30 -> 0.014136314 | C31: =C_pass*B30+A_keep*C30 -> 0.014020443 | D31: =C_pass*C30+A_keep*D30 -> 0.014078379 | E31: =SUM(B31:D31) -> 0.042235136 | F31: =F30+E31 -> 3.8732946 | H31: 8 | I31: =($I$18*I30+$J$18*J30+$K$18*K30)/(($I$18+$I$19+$I$20)*I30+($J$18+$J$19+$J$20)*J30+($K$18+$K$19+$K$20)*K30) -> 0.33333333 | J31: =($I$19*I30+$J$19*J30+$K$19*K30)/(($I$18+$I$19+$I$20)*I30+($J$18+$J$19+$J$20)*J30+($K$18+$K$19+$K$20)*K30) -> 0.33333333 | K31: =($I$20*I30+$J$20*J30+$K$20*K30)/(($I$18+$I$19+$I$20)*I30+($J$18+$J$19+$J$20)*J30+($K$18+$K$19+$K$20)*K30) -> 0.33333333 | L31: =($I$18+$I$19+$I$20)*I31+($J$18+$J$19+$J$20)*J31+($K$18+$K$19+$K$20)*K31 -> 0.75 | M31: =(M30*$I$18+N30*$I$19+O30*$I$20)/(($I$18+$J$18+$K$18)*M30+($I$19+$J$19+$K$19)*N30+($I$20+$J$20+$K$20)*O30) -> 0.33333333 | N31: =(M30*$J$18+N30*$J$19+O30*$J$20)/(($I$18+$J$18+$K$18)*M30+($I$19+$J$19+$K$19)*N30+($I$20+$J$20+$K$20)*O30) -> 0.33333333 | O31: =(M30*$K$18+N30*$K$19+O30*$K$20)/(($I$18+$J$18+$K$18)*M30+($I$19+$J$19+$K$19)*N30+($I$20+$J$20+$K$20)*O30) -> 0.33333333
A32: 12 | B32: =A_keep*B31+C_pass*D31 -> 0.010587752 | C32: =C_pass*B31+A_keep*C31 -> 0.0105443 | D32: =C_pass*C31+A_keep*D31 -> 0.0105443 | E32: =SUM(B32:D32) -> 0.031676352 | F32: =F31+E32 -> 3.9049709 | H32: 9 | I32: =($I$18*I31+$J$18*J31+$K$18*K31)/(($I$18+$I$19+$I$20)*I31+($J$18+$J$19+$J$20)*J31+($K$18+$K$19+$K$20)*K31) -> 0.33333333 | J32: =($I$19*I31+$J$19*J31+$K$19*K31)/(($I$18+$I$19+$I$20)*I31+($J$18+$J$19+$J$20)*J31+($K$18+$K$19+$K$20)*K31) -> 0.33333333 | K32: =($I$20*I31+$J$20*J31+$K$20*K31)/(($I$18+$I$19+$I$20)*I31+($J$18+$J$19+$J$20)*J31+($K$18+$K$19+$K$20)*K31) -> 0.33333333 | L32: =($I$18+$I$19+$I$20)*I32+($J$18+$J$19+$J$20)*J32+($K$18+$K$19+$K$20)*K32 -> 0.75 | M32: =(M31*$I$18+N31*$I$19+O31*$I$20)/(($I$18+$J$18+$K$18)*M31+($I$19+$J$19+$K$19)*N31+($I$20+$J$20+$K$20)*O31) -> 0.33333333 | N32: =(M31*$J$18+N31*$J$19+O31*$J$20)/(($I$18+$J$18+$K$18)*M31+($I$19+$J$19+$K$19)*N31+($I$20+$J$20+$K$20)*O31) -> 0.33333333 | O32: =(M31*$K$18+N31*$K$19+O31*$K$20)/(($I$18+$J$18+$K$18)*M31+($I$19+$J$19+$K$19)*N31+($I$20+$J$20+$K$20)*O31) -> 0.33333333
A33: 13 | B33: =A_keep*B32+C_pass*D32 -> 0.007929951 | C33: =C_pass*B32+A_keep*C32 -> 0.007919088 | D33: =C_pass*C32+A_keep*D32 -> 0.0079082251 | E33: =SUM(B33:D33) -> 0.023757264 | F33: =F32+E33 -> 3.9287282 | H33: 10 | I33: =($I$18*I32+$J$18*J32+$K$18*K32)/(($I$18+$I$19+$I$20)*I32+($J$18+$J$19+$J$20)*J32+($K$18+$K$19+$K$20)*K32) -> 0.33333333 | J33: =($I$19*I32+$J$19*J32+$K$19*K32)/(($I$18+$I$19+$I$20)*I32+($J$18+$J$19+$J$20)*J32+($K$18+$K$19+$K$20)*K32) -> 0.33333333 | K33: =($I$20*I32+$J$20*J32+$K$20*K32)/(($I$18+$I$19+$I$20)*I32+($J$18+$J$19+$J$20)*J32+($K$18+$K$19+$K$20)*K32) -> 0.33333333 | L33: =($I$18+$I$19+$I$20)*I33+($J$18+$J$19+$J$20)*J33+($K$18+$K$19+$K$20)*K33 -> 0.75 | M33: =(M32*$I$18+N32*$I$19+O32*$I$20)/(($I$18+$J$18+$K$18)*M32+($I$19+$J$19+$K$19)*N32+($I$20+$J$20+$K$20)*O32) -> 0.33333333 | N33: =(M32*$J$18+N32*$J$19+O32*$J$20)/(($I$18+$J$18+$K$18)*M32+($I$19+$J$19+$K$19)*N32+($I$20+$J$20+$K$20)*O32) -> 0.33333333 | O33: =(M32*$K$18+N32*$K$19+O32*$K$20)/(($I$18+$J$18+$K$18)*M32+($I$19+$J$19+$K$19)*N32+($I$20+$J$20+$K$20)*O32) -> 0.33333333
A34: 14 | B34: =A_keep*B33+C_pass*D33 -> 0.0059420317 | C34: =C_pass*B33+A_keep*C33 -> 0.0059420317 | D34: =C_pass*C33+A_keep*D33 -> 0.0059338845 | E34: =SUM(B34:D34) -> 0.017817948 | F34: =F33+E34 -> 3.9465462 | H34: 11 | I34: =($I$18*I33+$J$18*J33+$K$18*K33)/(($I$18+$I$19+$I$20)*I33+($J$18+$J$19+$J$20)*J33+($K$18+$K$19+$K$20)*K33) -> 0.33333333 | J34: =($I$19*I33+$J$19*J33+$K$19*K33)/(($I$18+$I$19+$I$20)*I33+($J$18+$J$19+$J$20)*J33+($K$18+$K$19+$K$20)*K33) -> 0.33333333 | K34: =($I$20*I33+$J$20*J33+$K$20*K33)/(($I$18+$I$19+$I$20)*I33+($J$18+$J$19+$J$20)*J33+($K$18+$K$19+$K$20)*K33) -> 0.33333333 | L34: =($I$18+$I$19+$I$20)*I34+($J$18+$J$19+$J$20)*J34+($K$18+$K$19+$K$20)*K34 -> 0.75 | M34: =(M33*$I$18+N33*$I$19+O33*$I$20)/(($I$18+$J$18+$K$18)*M33+($I$19+$J$19+$K$19)*N33+($I$20+$J$20+$K$20)*O33) -> 0.33333333 | N34: =(M33*$J$18+N33*$J$19+O33*$J$20)/(($I$18+$J$18+$K$18)*M33+($I$19+$J$19+$K$19)*N33+($I$20+$J$20+$K$20)*O33) -> 0.33333333 | O34: =(M33*$K$18+N33*$K$19+O33*$K$20)/(($I$18+$J$18+$K$18)*M33+($I$19+$J$19+$K$19)*N33+($I$20+$J$20+$K$20)*O33) -> 0.33333333
A35: 15 | B35: =A_keep*B34+C_pass*D34 -> 0.004454487 | C35: =C_pass*B34+A_keep*C34 -> 0.0044565238 | D35: =C_pass*C34+A_keep*D34 -> 0.0044524502 | E35: =SUM(B35:D35) -> 0.013363461 | F35: =F34+E35 -> 3.9599096 | H35: 12 | I35: =($I$18*I34+$J$18*J34+$K$18*K34)/(($I$18+$I$19+$I$20)*I34+($J$18+$J$19+$J$20)*J34+($K$18+$K$19+$K$20)*K34) -> 0.33333333 | J35: =($I$19*I34+$J$19*J34+$K$19*K34)/(($I$18+$I$19+$I$20)*I34+($J$18+$J$19+$J$20)*J34+($K$18+$K$19+$K$20)*K34) -> 0.33333333 | K35: =($I$20*I34+$J$20*J34+$K$20*K34)/(($I$18+$I$19+$I$20)*I34+($J$18+$J$19+$J$20)*J34+($K$18+$K$19+$K$20)*K34) -> 0.33333333 | L35: =($I$18+$I$19+$I$20)*I35+($J$18+$J$19+$J$20)*J35+($K$18+$K$19+$K$20)*K35 -> 0.75 | M35: =(M34*$I$18+N34*$I$19+O34*$I$20)/(($I$18+$J$18+$K$18)*M34+($I$19+$J$19+$K$19)*N34+($I$20+$J$20+$K$20)*O34) -> 0.33333333 | N35: =(M34*$J$18+N34*$J$19+O34*$J$20)/(($I$18+$J$18+$K$18)*M34+($I$19+$J$19+$K$19)*N34+($I$20+$J$20+$K$20)*O34) -> 0.33333333 | O35: =(M34*$K$18+N34*$K$19+O34*$K$20)/(($I$18+$J$18+$K$18)*M34+($I$19+$J$19+$K$19)*N34+($I$20+$J$20+$K$20)*O34) -> 0.33333333
A36: 16 | B36: =A_keep*B35+C_pass*D35 -> 0.0033403561 | C36: =C_pass*B35+A_keep*C35 -> 0.0033418837 | D36: =C_pass*C35+A_keep*D35 -> 0.0033403561 | E36: =SUM(B36:D36) -> 0.010022596 | F36: =F35+E36 -> 3.9699322 | H36: 13 | I36: =($I$18*I35+$J$18*J35+$K$18*K35)/(($I$18+$I$19+$I$20)*I35+($J$18+$J$19+$J$20)*J35+($K$18+$K$19+$K$20)*K35) -> 0.33333333 | J36: =($I$19*I35+$J$19*J35+$K$19*K35)/(($I$18+$I$19+$I$20)*I35+($J$18+$J$19+$J$20)*J35+($K$18+$K$19+$K$20)*K35) -> 0.33333333 | K36: =($I$20*I35+$J$20*J35+$K$20*K35)/(($I$18+$I$19+$I$20)*I35+($J$18+$J$19+$J$20)*J35+($K$18+$K$19+$K$20)*K35) -> 0.33333333 | L36: =($I$18+$I$19+$I$20)*I36+($J$18+$J$19+$J$20)*J36+($K$18+$K$19+$K$20)*K36 -> 0.75 | M36: =(M35*$I$18+N35*$I$19+O35*$I$20)/(($I$18+$J$18+$K$18)*M35+($I$19+$J$19+$K$19)*N35+($I$20+$J$20+$K$20)*O35) -> 0.33333333 | N36: =(M35*$J$18+N35*$J$19+O35*$J$20)/(($I$18+$J$18+$K$18)*M35+($I$19+$J$19+$K$19)*N35+($I$20+$J$20+$K$20)*O35) -> 0.33333333 | O36: =(M35*$K$18+N35*$K$19+O35*$K$20)/(($I$18+$J$18+$K$18)*M35+($I$19+$J$19+$K$19)*N35+($I$20+$J$20+$K$20)*O35) -> 0.33333333
A37: 17 | B37: =A_keep*B36+C_pass*D36 -> 0.002505267 | C37: =C_pass*B36+A_keep*C36 -> 0.0025060308 | D37: =C_pass*C36+A_keep*D36 -> 0.0025056489 | E37: =SUM(B37:D37) -> 0.0075169468 | F37: =F36+E37 -> 3.9774492 | H37: 14 | I37: =($I$18*I36+$J$18*J36+$K$18*K36)/(($I$18+$I$19+$I$20)*I36+($J$18+$J$19+$J$20)*J36+($K$18+$K$19+$K$20)*K36) -> 0.33333333 | J37: =($I$19*I36+$J$19*J36+$K$19*K36)/(($I$18+$I$19+$I$20)*I36+($J$18+$J$19+$J$20)*J36+($K$18+$K$19+$K$20)*K36) -> 0.33333333 | K37: =($I$20*I36+$J$20*J36+$K$20*K36)/(($I$18+$I$19+$I$20)*I36+($J$18+$J$19+$J$20)*J36+($K$18+$K$19+$K$20)*K36) -> 0.33333333 | L37: =($I$18+$I$19+$I$20)*I37+($J$18+$J$19+$J$20)*J37+($K$18+$K$19+$K$20)*K37 -> 0.75 | M37: =(M36*$I$18+N36*$I$19+O36*$I$20)/(($I$18+$J$18+$K$18)*M36+($I$19+$J$19+$K$19)*N36+($I$20+$J$20+$K$20)*O36) -> 0.33333333 | N37: =(M36*$J$18+N36*$J$19+O36*$J$20)/(($I$18+$J$18+$K$18)*M36+($I$19+$J$19+$K$19)*N36+($I$20+$J$20+$K$20)*O36) -> 0.33333333 | O37: =(M36*$K$18+N36*$K$19+O36*$K$20)/(($I$18+$J$18+$K$18)*M36+($I$19+$J$19+$K$19)*N36+($I$20+$J$20+$K$20)*O36) -> 0.33333333
A38: 18 | B38: =A_keep*B37+C_pass*D37 -> 0.0018790458 | C38: =C_pass*B37+A_keep*C37 -> 0.0018793322 | D38: =C_pass*C37+A_keep*D37 -> 0.0018793322 | E38: =SUM(B38:D38) -> 0.0056377101 | F38: =F37+E38 -> 3.9830869 | H38: 15 | I38: =($I$18*I37+$J$18*J37+$K$18*K37)/(($I$18+$I$19+$I$20)*I37+($J$18+$J$19+$J$20)*J37+($K$18+$K$19+$K$20)*K37) -> 0.33333333 | J38: =($I$19*I37+$J$19*J37+$K$19*K37)/(($I$18+$I$19+$I$20)*I37+($J$18+$J$19+$J$20)*J37+($K$18+$K$19+$K$20)*K37) -> 0.33333333 | K38: =($I$20*I37+$J$20*J37+$K$20*K37)/(($I$18+$I$19+$I$20)*I37+($J$18+$J$19+$J$20)*J37+($K$18+$K$19+$K$20)*K37) -> 0.33333333 | L38: =($I$18+$I$19+$I$20)*I38+($J$18+$J$19+$J$20)*J38+($K$18+$K$19+$K$20)*K38 -> 0.75 | M38: =(M37*$I$18+N37*$I$19+O37*$I$20)/(($I$18+$J$18+$K$18)*M37+($I$19+$J$19+$K$19)*N37+($I$20+$J$20+$K$20)*O37) -> 0.33333333 | N38: =(M37*$J$18+N37*$J$19+O37*$J$20)/(($I$18+$J$18+$K$18)*M37+($I$19+$J$19+$K$19)*N37+($I$20+$J$20+$K$20)*O37) -> 0.33333333 | O38: =(M37*$K$18+N37*$K$19+O37*$K$20)/(($I$18+$J$18+$K$18)*M37+($I$19+$J$19+$K$19)*N37+($I$20+$J$20+$K$20)*O37) -> 0.33333333
A39: 19 | B39: =A_keep*B38+C_pass*D38 -> 0.0014093559 | C39: =C_pass*B38+A_keep*C38 -> 0.0014094275 | D39: =C_pass*C38+A_keep*D38 -> 0.0014094991 | E39: =SUM(B39:D39) -> 0.0042282826 | F39: =F38+E39 -> 3.9873152 | H39: 16 | I39: =($I$18*I38+$J$18*J38+$K$18*K38)/(($I$18+$I$19+$I$20)*I38+($J$18+$J$19+$J$20)*J38+($K$18+$K$19+$K$20)*K38) -> 0.33333333 | J39: =($I$19*I38+$J$19*J38+$K$19*K38)/(($I$18+$I$19+$I$20)*I38+($J$18+$J$19+$J$20)*J38+($K$18+$K$19+$K$20)*K38) -> 0.33333333 | K39: =($I$20*I38+$J$20*J38+$K$20*K38)/(($I$18+$I$19+$I$20)*I38+($J$18+$J$19+$J$20)*J38+($K$18+$K$19+$K$20)*K38) -> 0.33333333 | L39: =($I$18+$I$19+$I$20)*I39+($J$18+$J$19+$J$20)*J39+($K$18+$K$19+$K$20)*K39 -> 0.75 | M39: =(M38*$I$18+N38*$I$19+O38*$I$20)/(($I$18+$J$18+$K$18)*M38+($I$19+$J$19+$K$19)*N38+($I$20+$J$20+$K$20)*O38) -> 0.33333333 | N39: =(M38*$J$18+N38*$J$19+O38*$J$20)/(($I$18+$J$18+$K$18)*M38+($I$19+$J$19+$K$19)*N38+($I$20+$J$20+$K$20)*O38) -> 0.33333333 | O39: =(M38*$K$18+N38*$K$19+O38*$K$20)/(($I$18+$J$18+$K$18)*M38+($I$19+$J$19+$K$19)*N38+($I$20+$J$20+$K$20)*O38) -> 0.33333333
A40: 20 | B40: =A_keep*B39+C_pass*D39 -> 0.0010570527 | C40: =C_pass*B39+A_keep*C39 -> 0.0010570527 | D40: =C_pass*C39+A_keep*D39 -> 0.0010571064 | E40: =SUM(B40:D40) -> 0.0031712119 | F40: =F39+E40 -> 3.9904864 | H40: 17 | I40: =($I$18*I39+$J$18*J39+$K$18*K39)/(($I$18+$I$19+$I$20)*I39+($J$18+$J$19+$J$20)*J39+($K$18+$K$19+$K$20)*K39) -> 0.33333333 | J40: =($I$19*I39+$J$19*J39+$K$19*K39)/(($I$18+$I$19+$I$20)*I39+($J$18+$J$19+$J$20)*J39+($K$18+$K$19+$K$20)*K39) -> 0.33333333 | K40: =($I$20*I39+$J$20*J39+$K$20*K39)/(($I$18+$I$19+$I$20)*I39+($J$18+$J$19+$J$20)*J39+($K$18+$K$19+$K$20)*K39) -> 0.33333333 | L40: =($I$18+$I$19+$I$20)*I40+($J$18+$J$19+$J$20)*J40+($K$18+$K$19+$K$20)*K40 -> 0.75 | M40: =(M39*$I$18+N39*$I$19+O39*$I$20)/(($I$18+$J$18+$K$18)*M39+($I$19+$J$19+$K$19)*N39+($I$20+$J$20+$K$20)*O39) -> 0.33333333 | N40: =(M39*$J$18+N39*$J$19+O39*$J$20)/(($I$18+$J$18+$K$18)*M39+($I$19+$J$19+$K$19)*N39+($I$20+$J$20+$K$20)*O39) -> 0.33333333 | O40: =(M39*$K$18+N39*$K$19+O39*$K$20)/(($I$18+$J$18+$K$18)*M39+($I$19+$J$19+$K$19)*N39+($I$20+$J$20+$K$20)*O39) -> 0.33333333
A41: 21 | B41: =A_keep*B40+C_pass*D40 -> 0.00079280298 | C41: =C_pass*B40+A_keep*C40 -> 0.00079278956 | D41: =C_pass*C40+A_keep*D40 -> 0.00079281641 | E41: =SUM(B41:D41) -> 0.002378409 | F41: =F40+E41 -> 3.9928648 | H41: 18 | I41: =($I$18*I40+$J$18*J40+$K$18*K40)/(($I$18+$I$19+$I$20)*I40+($J$18+$J$19+$J$20)*J40+($K$18+$K$19+$K$20)*K40) -> 0.33333333 | J41: =($I$19*I40+$J$19*J40+$K$19*K40)/(($I$18+$I$19+$I$20)*I40+($J$18+$J$19+$J$20)*J40+($K$18+$K$19+$K$20)*K40) -> 0.33333333 | K41: =($I$20*I40+$J$20*J40+$K$20*K40)/(($I$18+$I$19+$I$20)*I40+($J$18+$J$19+$J$20)*J40+($K$18+$K$19+$K$20)*K40) -> 0.33333333 | L41: =($I$18+$I$19+$I$20)*I41+($J$18+$J$19+$J$20)*J41+($K$18+$K$19+$K$20)*K41 -> 0.75 | M41: =(M40*$I$18+N40*$I$19+O40*$I$20)/(($I$18+$J$18+$K$18)*M40+($I$19+$J$19+$K$19)*N40+($I$20+$J$20+$K$20)*O40) -> 0.33333333 | N41: =(M40*$J$18+N40*$J$19+O40*$J$20)/(($I$18+$J$18+$K$18)*M40+($I$19+$J$19+$K$19)*N40+($I$20+$J$20+$K$20)*O40) -> 0.33333333 | O41: =(M40*$K$18+N40*$K$19+O40*$K$20)/(($I$18+$J$18+$K$18)*M40+($I$19+$J$19+$K$19)*N40+($I$20+$J$20+$K$20)*O40) -> 0.33333333
...

Sheet Wavefront
A1: Follow the wavefront: the ledger clocks (Proposition 13.2; Theorem 13.4(iii); Online Appendix 13.B.3; AXIOM Lab 1.13, step 3)
A2: Distances on the skeleton by relaxation: D(u,v) = min(D(u,v), min over arrows w -> v of D(u,w) + 1). 99 means never.
A4: Arrows (row sends, column receives) | B4: =INDEX(Comps,1) -> MKT | C4: =INDEX(Comps,2) -> GOV | D4: =INDEX(Comps,3) -> MAT | E4: =INDEX(Comps,4) -> IND | F4: =INDEX(Comps,5) -> DIG | G4: =INDEX(Comps,6) -> ENG | H4: =INDEX(Comps,7) -> TRS | J4: Arrows into (row receives from column) | K4: =INDEX(Comps,1) -> MKT | L4: =INDEX(Comps,2) -> GOV | M4: =INDEX(Comps,3) -> MAT | N4: =INDEX(Comps,4) -> IND | O4: =INDEX(Comps,5) -> DIG | P4: =INDEX(Comps,6) -> ENG | Q4: =INDEX(Comps,7) -> TRS
A5: =INDEX(Comps,1) -> MKT | B5: =COUNTIFS(Arr_from,$A5,Arr_to,B$4) -> 0 | C5: =COUNTIFS(Arr_from,$A5,Arr_to,C$4) -> 0 | D5: =COUNTIFS(Arr_from,$A5,Arr_to,D$4) -> 1 | E5: =COUNTIFS(Arr_from,$A5,Arr_to,E$4) -> 1 | F5: =COUNTIFS(Arr_from,$A5,Arr_to,F$4) -> 1 | G5: =COUNTIFS(Arr_from,$A5,Arr_to,G$4) -> 0 | H5: =COUNTIFS(Arr_from,$A5,Arr_to,H$4) -> 0 | J5: =INDEX(Comps,1) -> MKT | K5: =INDEX($B$5:$H$11,1,1) -> 0 | L5: =INDEX($B$5:$H$11,2,1) -> 0 | M5: =INDEX($B$5:$H$11,3,1) -> 0 | N5: =INDEX($B$5:$H$11,4,1) -> 0 | O5: =INDEX($B$5:$H$11,5,1) -> 0 | P5: =INDEX($B$5:$H$11,6,1) -> 0 | Q5: =INDEX($B$5:$H$11,7,1) -> 0
A6: =INDEX(Comps,2) -> GOV | B6: =COUNTIFS(Arr_from,$A6,Arr_to,B$4) -> 0 | C6: =COUNTIFS(Arr_from,$A6,Arr_to,C$4) -> 0 | D6: =COUNTIFS(Arr_from,$A6,Arr_to,D$4) -> 0 | E6: =COUNTIFS(Arr_from,$A6,Arr_to,E$4) -> 0 | F6: =COUNTIFS(Arr_from,$A6,Arr_to,F$4) -> 1 | G6: =COUNTIFS(Arr_from,$A6,Arr_to,G$4) -> 0 | H6: =COUNTIFS(Arr_from,$A6,Arr_to,H$4) -> 1 | J6: =INDEX(Comps,2) -> GOV | K6: =INDEX($B$5:$H$11,1,2) -> 0 | L6: =INDEX($B$5:$H$11,2,2) -> 0 | M6: =INDEX($B$5:$H$11,3,2) -> 0 | N6: =INDEX($B$5:$H$11,4,2) -> 0 | O6: =INDEX($B$5:$H$11,5,2) -> 0 | P6: =INDEX($B$5:$H$11,6,2) -> 0 | Q6: =INDEX($B$5:$H$11,7,2) -> 0
A7: =INDEX(Comps,3) -> MAT | B7: =COUNTIFS(Arr_from,$A7,Arr_to,B$4) -> 0 | C7: =COUNTIFS(Arr_from,$A7,Arr_to,C$4) -> 0 | D7: =COUNTIFS(Arr_from,$A7,Arr_to,D$4) -> 0 | E7: =COUNTIFS(Arr_from,$A7,Arr_to,E$4) -> 0 | F7: =COUNTIFS(Arr_from,$A7,Arr_to,F$4) -> 0 | G7: =COUNTIFS(Arr_from,$A7,Arr_to,G$4) -> 0 | H7: =COUNTIFS(Arr_from,$A7,Arr_to,H$4) -> 1 | J7: =INDEX(Comps,3) -> MAT | K7: =INDEX($B$5:$H$11,1,3) -> 1 | L7: =INDEX($B$5:$H$11,2,3) -> 0 | M7: =INDEX($B$5:$H$11,3,3) -> 0 | N7: =INDEX($B$5:$H$11,4,3) -> 0 | O7: =INDEX($B$5:$H$11,5,3) -> 0 | P7: =INDEX($B$5:$H$11,6,3) -> 0 | Q7: =INDEX($B$5:$H$11,7,3) -> 0
A8: =INDEX(Comps,4) -> IND | B8: =COUNTIFS(Arr_from,$A8,Arr_to,B$4) -> 0 | C8: =COUNTIFS(Arr_from,$A8,Arr_to,C$4) -> 0 | D8: =COUNTIFS(Arr_from,$A8,Arr_to,D$4) -> 0 | E8: =COUNTIFS(Arr_from,$A8,Arr_to,E$4) -> 0 | F8: =COUNTIFS(Arr_from,$A8,Arr_to,F$4) -> 0 | G8: =COUNTIFS(Arr_from,$A8,Arr_to,G$4) -> 1 | H8: =COUNTIFS(Arr_from,$A8,Arr_to,H$4) -> 1 | J8: =INDEX(Comps,4) -> IND | K8: =INDEX($B$5:$H$11,1,4) -> 1 | L8: =INDEX($B$5:$H$11,2,4) -> 0 | M8: =INDEX($B$5:$H$11,3,4) -> 0 | N8: =INDEX($B$5:$H$11,4,4) -> 0 | O8: =INDEX($B$5:$H$11,5,4) -> 0 | P8: =INDEX($B$5:$H$11,6,4) -> 1 | Q8: =INDEX($B$5:$H$11,7,4) -> 1
A9: =INDEX(Comps,5) -> DIG | B9: =COUNTIFS(Arr_from,$A9,Arr_to,B$4) -> 0 | C9: =COUNTIFS(Arr_from,$A9,Arr_to,C$4) -> 0 | D9: =COUNTIFS(Arr_from,$A9,Arr_to,D$4) -> 0 | E9: =COUNTIFS(Arr_from,$A9,Arr_to,E$4) -> 0 | F9: =COUNTIFS(Arr_from,$A9,Arr_to,F$4) -> 0 | G9: =COUNTIFS(Arr_from,$A9,Arr_to,G$4) -> 1 | H9: =COUNTIFS(Arr_from,$A9,Arr_to,H$4) -> 1 | J9: =INDEX(Comps,5) -> DIG | K9: =INDEX($B$5:$H$11,1,5) -> 1 | L9: =INDEX($B$5:$H$11,2,5) -> 1 | M9: =INDEX($B$5:$H$11,3,5) -> 0 | N9: =INDEX($B$5:$H$11,4,5) -> 0 | O9: =INDEX($B$5:$H$11,5,5) -> 0 | P9: =INDEX($B$5:$H$11,6,5) -> 1 | Q9: =INDEX($B$5:$H$11,7,5) -> 1
A10: =INDEX(Comps,6) -> ENG | B10: =COUNTIFS(Arr_from,$A10,Arr_to,B$4) -> 0 | C10: =COUNTIFS(Arr_from,$A10,Arr_to,C$4) -> 0 | D10: =COUNTIFS(Arr_from,$A10,Arr_to,D$4) -> 0 | E10: =COUNTIFS(Arr_from,$A10,Arr_to,E$4) -> 1 | F10: =COUNTIFS(Arr_from,$A10,Arr_to,F$4) -> 1 | G10: =COUNTIFS(Arr_from,$A10,Arr_to,G$4) -> 0 | H10: =COUNTIFS(Arr_from,$A10,Arr_to,H$4) -> 0 | J10: =INDEX(Comps,6) -> ENG | K10: =INDEX($B$5:$H$11,1,6) -> 0 | L10: =INDEX($B$5:$H$11,2,6) -> 0 | M10: =INDEX($B$5:$H$11,3,6) -> 0 | N10: =INDEX($B$5:$H$11,4,6) -> 1 | O10: =INDEX($B$5:$H$11,5,6) -> 1 | P10: =INDEX($B$5:$H$11,6,6) -> 0 | Q10: =INDEX($B$5:$H$11,7,6) -> 0
A11: =INDEX(Comps,7) -> TRS | B11: =COUNTIFS(Arr_from,$A11,Arr_to,B$4) -> 0 | C11: =COUNTIFS(Arr_from,$A11,Arr_to,C$4) -> 0 | D11: =COUNTIFS(Arr_from,$A11,Arr_to,D$4) -> 0 | E11: =COUNTIFS(Arr_from,$A11,Arr_to,E$4) -> 1 | F11: =COUNTIFS(Arr_from,$A11,Arr_to,F$4) -> 1 | G11: =COUNTIFS(Arr_from,$A11,Arr_to,G$4) -> 0 | H11: =COUNTIFS(Arr_from,$A11,Arr_to,H$4) -> 0 | J11: =INDEX(Comps,7) -> TRS | K11: =INDEX($B$5:$H$11,1,7) -> 0 | L11: =INDEX($B$5:$H$11,2,7) -> 1 | M11: =INDEX($B$5:$H$11,3,7) -> 1 | N11: =INDEX($B$5:$H$11,4,7) -> 1 | O11: =INDEX($B$5:$H$11,5,7) -> 1 | P11: =INDEX($B$5:$H$11,6,7) -> 0 | Q11: =INDEX($B$5:$H$11,7,7) -> 0
A14: Distance using at most 1 arrows | B14: =INDEX(Comps,1) -> MKT | C14: =INDEX(Comps,2) -> GOV | D14: =INDEX(Comps,3) -> MAT | E14: =INDEX(Comps,4) -> IND | F14: =INDEX(Comps,5) -> DIG | G14: =INDEX(Comps,6) -> ENG | H14: =INDEX(Comps,7) -> TRS
A15: =INDEX(Comps,1) -> MKT | B15: =IF($A15=B$14,0,IF(B5>0,1,99)) -> 0 | C15: =IF($A15=C$14,0,IF(C5>0,1,99)) -> 99 | D15: =IF($A15=D$14,0,IF(D5>0,1,99)) -> 1 | E15: =IF($A15=E$14,0,IF(E5>0,1,99)) -> 1 | F15: =IF($A15=F$14,0,IF(F5>0,1,99)) -> 1 | G15: =IF($A15=G$14,0,IF(G5>0,1,99)) -> 99 | H15: =IF($A15=H$14,0,IF(H5>0,1,99)) -> 99
A16: =INDEX(Comps,2) -> GOV | B16: =IF($A16=B$14,0,IF(B6>0,1,99)) -> 99 | C16: =IF($A16=C$14,0,IF(C6>0,1,99)) -> 0 | D16: =IF($A16=D$14,0,IF(D6>0,1,99)) -> 99 | E16: =IF($A16=E$14,0,IF(E6>0,1,99)) -> 99 | F16: =IF($A16=F$14,0,IF(F6>0,1,99)) -> 1 | G16: =IF($A16=G$14,0,IF(G6>0,1,99)) -> 99 | H16: =IF($A16=H$14,0,IF(H6>0,1,99)) -> 1
A17: =INDEX(Comps,3) -> MAT | B17: =IF($A17=B$14,0,IF(B7>0,1,99)) -> 99 | C17: =IF($A17=C$14,0,IF(C7>0,1,99)) -> 99 | D17: =IF($A17=D$14,0,IF(D7>0,1,99)) -> 0 | E17: =IF($A17=E$14,0,IF(E7>0,1,99)) -> 99 | F17: =IF($A17=F$14,0,IF(F7>0,1,99)) -> 99 | G17: =IF($A17=G$14,0,IF(G7>0,1,99)) -> 99 | H17: =IF($A17=H$14,0,IF(H7>0,1,99)) -> 1
A18: =INDEX(Comps,4) -> IND | B18: =IF($A18=B$14,0,IF(B8>0,1,99)) -> 99 | C18: =IF($A18=C$14,0,IF(C8>0,1,99)) -> 99 | D18: =IF($A18=D$14,0,IF(D8>0,1,99)) -> 99 | E18: =IF($A18=E$14,0,IF(E8>0,1,99)) -> 0 | F18: =IF($A18=F$14,0,IF(F8>0,1,99)) -> 99 | G18: =IF($A18=G$14,0,IF(G8>0,1,99)) -> 1 | H18: =IF($A18=H$14,0,IF(H8>0,1,99)) -> 1
A19: =INDEX(Comps,5) -> DIG | B19: =IF($A19=B$14,0,IF(B9>0,1,99)) -> 99 | C19: =IF($A19=C$14,0,IF(C9>0,1,99)) -> 99 | D19: =IF($A19=D$14,0,IF(D9>0,1,99)) -> 99 | E19: =IF($A19=E$14,0,IF(E9>0,1,99)) -> 99 | F19: =IF($A19=F$14,0,IF(F9>0,1,99)) -> 0 | G19: =IF($A19=G$14,0,IF(G9>0,1,99)) -> 1 | H19: =IF($A19=H$14,0,IF(H9>0,1,99)) -> 1
A20: =INDEX(Comps,6) -> ENG | B20: =IF($A20=B$14,0,IF(B10>0,1,99)) -> 99 | C20: =IF($A20=C$14,0,IF(C10>0,1,99)) -> 99 | D20: =IF($A20=D$14,0,IF(D10>0,1,99)) -> 99 | E20: =IF($A20=E$14,0,IF(E10>0,1,99)) -> 1 | F20: =IF($A20=F$14,0,IF(F10>0,1,99)) -> 1 | G20: =IF($A20=G$14,0,IF(G10>0,1,99)) -> 0 | H20: =IF($A20=H$14,0,IF(H10>0,1,99)) -> 99
A21: =INDEX(Comps,7) -> TRS | B21: =IF($A21=B$14,0,IF(B11>0,1,99)) -> 99 | C21: =IF($A21=C$14,0,IF(C11>0,1,99)) -> 99 | D21: =IF($A21=D$14,0,IF(D11>0,1,99)) -> 99 | E21: =IF($A21=E$14,0,IF(E11>0,1,99)) -> 1 | F21: =IF($A21=F$14,0,IF(F11>0,1,99)) -> 1 | G21: =IF($A21=G$14,0,IF(G11>0,1,99)) -> 99 | H21: =IF($A21=H$14,0,IF(H11>0,1,99)) -> 0
A23: Distance using at most 2 arrows | B23: =INDEX(Comps,1) -> MKT | C23: =INDEX(Comps,2) -> GOV | D23: =INDEX(Comps,3) -> MAT | E23: =INDEX(Comps,4) -> IND | F23: =INDEX(Comps,5) -> DIG | G23: =INDEX(Comps,6) -> ENG | H23: =INDEX(Comps,7) -> TRS
A24: =INDEX(Comps,1) -> MKT | B24: =MIN(B15,IF(COUNTIF($K$5:$Q$5,">0")=0,99,_xlfn.MINIFS($B$15:$H$15,$K$5:$Q$5,">0")+1)) -> 0 | C24: =MIN(C15,IF(COUNTIF($K$6:$Q$6,">0")=0,99,_xlfn.MINIFS($B$15:$H$15,$K$6:$Q$6,">0")+1)) -> 99 | D24: =MIN(D15,IF(COUNTIF($K$7:$Q$7,">0")=0,99,_xlfn.MINIFS($B$15:$H$15,$K$7:$Q$7,">0")+1)) -> 1 | E24: =MIN(E15,IF(COUNTIF($K$8:$Q$8,">0")=0,99,_xlfn.MINIFS($B$15:$H$15,$K$8:$Q$8,">0")+1)) -> 1 | F24: =MIN(F15,IF(COUNTIF($K$9:$Q$9,">0")=0,99,_xlfn.MINIFS($B$15:$H$15,$K$9:$Q$9,">0")+1)) -> 1 | G24: =MIN(G15,IF(COUNTIF($K$10:$Q$10,">0")=0,99,_xlfn.MINIFS($B$15:$H$15,$K$10:$Q$10,">0")+1)) -> 2 | H24: =MIN(H15,IF(COUNTIF($K$11:$Q$11,">0")=0,99,_xlfn.MINIFS($B$15:$H$15,$K$11:$Q$11,">0")+1)) -> 2
A25: =INDEX(Comps,2) -> GOV | B25: =MIN(B16,IF(COUNTIF($K$5:$Q$5,">0")=0,99,_xlfn.MINIFS($B$16:$H$16,$K$5:$Q$5,">0")+1)) -> 99 | C25: =MIN(C16,IF(COUNTIF($K$6:$Q$6,">0")=0,99,_xlfn.MINIFS($B$16:$H$16,$K$6:$Q$6,">0")+1)) -> 0 | D25: =MIN(D16,IF(COUNTIF($K$7:$Q$7,">0")=0,99,_xlfn.MINIFS($B$16:$H$16,$K$7:$Q$7,">0")+1)) -> 99 | E25: =MIN(E16,IF(COUNTIF($K$8:$Q$8,">0")=0,99,_xlfn.MINIFS($B$16:$H$16,$K$8:$Q$8,">0")+1)) -> 2 | F25: =MIN(F16,IF(COUNTIF($K$9:$Q$9,">0")=0,99,_xlfn.MINIFS($B$16:$H$16,$K$9:$Q$9,">0")+1)) -> 1 | G25: =MIN(G16,IF(COUNTIF($K$10:$Q$10,">0")=0,99,_xlfn.MINIFS($B$16:$H$16,$K$10:$Q$10,">0")+1)) -> 2 | H25: =MIN(H16,IF(COUNTIF($K$11:$Q$11,">0")=0,99,_xlfn.MINIFS($B$16:$H$16,$K$11:$Q$11,">0")+1)) -> 1
A26: =INDEX(Comps,3) -> MAT | B26: =MIN(B17,IF(COUNTIF($K$5:$Q$5,">0")=0,99,_xlfn.MINIFS($B$17:$H$17,$K$5:$Q$5,">0")+1)) -> 99 | C26: =MIN(C17,IF(COUNTIF($K$6:$Q$6,">0")=0,99,_xlfn.MINIFS($B$17:$H$17,$K$6:$Q$6,">0")+1)) -> 99 | D26: =MIN(D17,IF(COUNTIF($K$7:$Q$7,">0")=0,99,_xlfn.MINIFS($B$17:$H$17,$K$7:$Q$7,">0")+1)) -> 0 | E26: =MIN(E17,IF(COUNTIF($K$8:$Q$8,">0")=0,99,_xlfn.MINIFS($B$17:$H$17,$K$8:$Q$8,">0")+1)) -> 2 | F26: =MIN(F17,IF(COUNTIF($K$9:$Q$9,">0")=0,99,_xlfn.MINIFS($B$17:$H$17,$K$9:$Q$9,">0")+1)) -> 2 | G26: =MIN(G17,IF(COUNTIF($K$10:$Q$10,">0")=0,99,_xlfn.MINIFS($B$17:$H$17,$K$10:$Q$10,">0")+1)) -> 99 | H26: =MIN(H17,IF(COUNTIF($K$11:$Q$11,">0")=0,99,_xlfn.MINIFS($B$17:$H$17,$K$11:$Q$11,">0")+1)) -> 1
A27: =INDEX(Comps,4) -> IND | B27: =MIN(B18,IF(COUNTIF($K$5:$Q$5,">0")=0,99,_xlfn.MINIFS($B$18:$H$18,$K$5:$Q$5,">0")+1)) -> 99 | C27: =MIN(C18,IF(COUNTIF($K$6:$Q$6,">0")=0,99,_xlfn.MINIFS($B$18:$H$18,$K$6:$Q$6,">0")+1)) -> 99 | D27: =MIN(D18,IF(COUNTIF($K$7:$Q$7,">0")=0,99,_xlfn.MINIFS($B$18:$H$18,$K$7:$Q$7,">0")+1)) -> 99 | E27: =MIN(E18,IF(COUNTIF($K$8:$Q$8,">0")=0,99,_xlfn.MINIFS($B$18:$H$18,$K$8:$Q$8,">0")+1)) -> 0 | F27: =MIN(F18,IF(COUNTIF($K$9:$Q$9,">0")=0,99,_xlfn.MINIFS($B$18:$H$18,$K$9:$Q$9,">0")+1)) -> 2 | G27: =MIN(G18,IF(COUNTIF($K$10:$Q$10,">0")=0,99,_xlfn.MINIFS($B$18:$H$18,$K$10:$Q$10,">0")+1)) -> 1 | H27: =MIN(H18,IF(COUNTIF($K$11:$Q$11,">0")=0,99,_xlfn.MINIFS($B$18:$H$18,$K$11:$Q$11,">0")+1)) -> 1
A28: =INDEX(Comps,5) -> DIG | B28: =MIN(B19,IF(COUNTIF($K$5:$Q$5,">0")=0,99,_xlfn.MINIFS($B$19:$H$19,$K$5:$Q$5,">0")+1)) -> 99 | C28: =MIN(C19,IF(COUNTIF($K$6:$Q$6,">0")=0,99,_xlfn.MINIFS($B$19:$H$19,$K$6:$Q$6,">0")+1)) -> 99 | D28: =MIN(D19,IF(COUNTIF($K$7:$Q$7,">0")=0,99,_xlfn.MINIFS($B$19:$H$19,$K$7:$Q$7,">0")+1)) -> 99 | E28: =MIN(E19,IF(COUNTIF($K$8:$Q$8,">0")=0,99,_xlfn.MINIFS($B$19:$H$19,$K$8:$Q$8,">0")+1)) -> 2 | F28: =MIN(F19,IF(COUNTIF($K$9:$Q$9,">0")=0,99,_xlfn.MINIFS($B$19:$H$19,$K$9:$Q$9,">0")+1)) -> 0 | G28: =MIN(G19,IF(COUNTIF($K$10:$Q$10,">0")=0,99,_xlfn.MINIFS($B$19:$H$19,$K$10:$Q$10,">0")+1)) -> 1 | H28: =MIN(H19,IF(COUNTIF($K$11:$Q$11,">0")=0,99,_xlfn.MINIFS($B$19:$H$19,$K$11:$Q$11,">0")+1)) -> 1
A29: =INDEX(Comps,6) -> ENG | B29: =MIN(B20,IF(COUNTIF($K$5:$Q$5,">0")=0,99,_xlfn.MINIFS($B$20:$H$20,$K$5:$Q$5,">0")+1)) -> 99 | C29: =MIN(C20,IF(COUNTIF($K$6:$Q$6,">0")=0,99,_xlfn.MINIFS($B$20:$H$20,$K$6:$Q$6,">0")+1)) -> 99 | D29: =MIN(D20,IF(COUNTIF($K$7:$Q$7,">0")=0,99,_xlfn.MINIFS($B$20:$H$20,$K$7:$Q$7,">0")+1)) -> 99 | E29: =MIN(E20,IF(COUNTIF($K$8:$Q$8,">0")=0,99,_xlfn.MINIFS($B$20:$H$20,$K$8:$Q$8,">0")+1)) -> 1 | F29: =MIN(F20,IF(COUNTIF($K$9:$Q$9,">0")=0,99,_xlfn.MINIFS($B$20:$H$20,$K$9:$Q$9,">0")+1)) -> 1 | G29: =MIN(G20,IF(COUNTIF($K$10:$Q$10,">0")=0,99,_xlfn.MINIFS($B$20:$H$20,$K$10:$Q$10,">0")+1)) -> 0 | H29: =MIN(H20,IF(COUNTIF($K$11:$Q$11,">0")=0,99,_xlfn.MINIFS($B$20:$H$20,$K$11:$Q$11,">0")+1)) -> 2
A30: =INDEX(Comps,7) -> TRS | B30: =MIN(B21,IF(COUNTIF($K$5:$Q$5,">0")=0,99,_xlfn.MINIFS($B$21:$H$21,$K$5:$Q$5,">0")+1)) -> 99 | C30: =MIN(C21,IF(COUNTIF($K$6:$Q$6,">0")=0,99,_xlfn.MINIFS($B$21:$H$21,$K$6:$Q$6,">0")+1)) -> 99 | D30: =MIN(D21,IF(COUNTIF($K$7:$Q$7,">0")=0,99,_xlfn.MINIFS($B$21:$H$21,$K$7:$Q$7,">0")+1)) -> 99 | E30: =MIN(E21,IF(COUNTIF($K$8:$Q$8,">0")=0,99,_xlfn.MINIFS($B$21:$H$21,$K$8:$Q$8,">0")+1)) -> 1 | F30: =MIN(F21,IF(COUNTIF($K$9:$Q$9,">0")=0,99,_xlfn.MINIFS($B$21:$H$21,$K$9:$Q$9,">0")+1)) -> 1 | G30: =MIN(G21,IF(COUNTIF($K$10:$Q$10,">0")=0,99,_xlfn.MINIFS($B$21:$H$21,$K$10:$Q$10,">0")+1)) -> 2 | H30: =MIN(H21,IF(COUNTIF($K$11:$Q$11,">0")=0,99,_xlfn.MINIFS($B$21:$H$21,$K$11:$Q$11,">0")+1)) -> 0
A32: Distance using at most 3 arrows | B32: =INDEX(Comps,1) -> MKT | C32: =INDEX(Comps,2) -> GOV | D32: =INDEX(Comps,3) -> MAT | E32: =INDEX(Comps,4) -> IND | F32: =INDEX(Comps,5) -> DIG | G32: =INDEX(Comps,6) -> ENG | H32: =INDEX(Comps,7) -> TRS
A33: =INDEX(Comps,1) -> MKT | B33: =MIN(B24,IF(COUNTIF($K$5:$Q$5,">0")=0,99,_xlfn.MINIFS($B$24:$H$24,$K$5:$Q$5,">0")+1)) -> 0 | C33: =MIN(C24,IF(COUNTIF($K$6:$Q$6,">0")=0,99,_xlfn.MINIFS($B$24:$H$24,$K$6:$Q$6,">0")+1)) -> 99 | D33: =MIN(D24,IF(COUNTIF($K$7:$Q$7,">0")=0,99,_xlfn.MINIFS($B$24:$H$24,$K$7:$Q$7,">0")+1)) -> 1 | E33: =MIN(E24,IF(COUNTIF($K$8:$Q$8,">0")=0,99,_xlfn.MINIFS($B$24:$H$24,$K$8:$Q$8,">0")+1)) -> 1 | F33: =MIN(F24,IF(COUNTIF($K$9:$Q$9,">0")=0,99,_xlfn.MINIFS($B$24:$H$24,$K$9:$Q$9,">0")+1)) -> 1 | G33: =MIN(G24,IF(COUNTIF($K$10:$Q$10,">0")=0,99,_xlfn.MINIFS($B$24:$H$24,$K$10:$Q$10,">0")+1)) -> 2 | H33: =MIN(H24,IF(COUNTIF($K$11:$Q$11,">0")=0,99,_xlfn.MINIFS($B$24:$H$24,$K$11:$Q$11,">0")+1)) -> 2
A34: =INDEX(Comps,2) -> GOV | B34: =MIN(B25,IF(COUNTIF($K$5:$Q$5,">0")=0,99,_xlfn.MINIFS($B$25:$H$25,$K$5:$Q$5,">0")+1)) -> 99 | C34: =MIN(C25,IF(COUNTIF($K$6:$Q$6,">0")=0,99,_xlfn.MINIFS($B$25:$H$25,$K$6:$Q$6,">0")+1)) -> 0 | D34: =MIN(D25,IF(COUNTIF($K$7:$Q$7,">0")=0,99,_xlfn.MINIFS($B$25:$H$25,$K$7:$Q$7,">0")+1)) -> 99 | E34: =MIN(E25,IF(COUNTIF($K$8:$Q$8,">0")=0,99,_xlfn.MINIFS($B$25:$H$25,$K$8:$Q$8,">0")+1)) -> 2 | F34: =MIN(F25,IF(COUNTIF($K$9:$Q$9,">0")=0,99,_xlfn.MINIFS($B$25:$H$25,$K$9:$Q$9,">0")+1)) -> 1 | G34: =MIN(G25,IF(COUNTIF($K$10:$Q$10,">0")=0,99,_xlfn.MINIFS($B$25:$H$25,$K$10:$Q$10,">0")+1)) -> 2 | H34: =MIN(H25,IF(COUNTIF($K$11:$Q$11,">0")=0,99,_xlfn.MINIFS($B$25:$H$25,$K$11:$Q$11,">0")+1)) -> 1
A35: =INDEX(Comps,3) -> MAT | B35: =MIN(B26,IF(COUNTIF($K$5:$Q$5,">0")=0,99,_xlfn.MINIFS($B$26:$H$26,$K$5:$Q$5,">0")+1)) -> 99 | C35: =MIN(C26,IF(COUNTIF($K$6:$Q$6,">0")=0,99,_xlfn.MINIFS($B$26:$H$26,$K$6:$Q$6,">0")+1)) -> 99 | D35: =MIN(D26,IF(COUNTIF($K$7:$Q$7,">0")=0,99,_xlfn.MINIFS($B$26:$H$26,$K$7:$Q$7,">0")+1)) -> 0 | E35: =MIN(E26,IF(COUNTIF($K$8:$Q$8,">0")=0,99,_xlfn.MINIFS($B$26:$H$26,$K$8:$Q$8,">0")+1)) -> 2 | F35: =MIN(F26,IF(COUNTIF($K$9:$Q$9,">0")=0,99,_xlfn.MINIFS($B$26:$H$26,$K$9:$Q$9,">0")+1)) -> 2 | G35: =MIN(G26,IF(COUNTIF($K$10:$Q$10,">0")=0,99,_xlfn.MINIFS($B$26:$H$26,$K$10:$Q$10,">0")+1)) -> 3 | H35: =MIN(H26,IF(COUNTIF($K$11:$Q$11,">0")=0,99,_xlfn.MINIFS($B$26:$H$26,$K$11:$Q$11,">0")+1)) -> 1
A36: =INDEX(Comps,4) -> IND | B36: =MIN(B27,IF(COUNTIF($K$5:$Q$5,">0")=0,99,_xlfn.MINIFS($B$27:$H$27,$K$5:$Q$5,">0")+1)) -> 99 | C36: =MIN(C27,IF(COUNTIF($K$6:$Q$6,">0")=0,99,_xlfn.MINIFS($B$27:$H$27,$K$6:$Q$6,">0")+1)) -> 99 | D36: =MIN(D27,IF(COUNTIF($K$7:$Q$7,">0")=0,99,_xlfn.MINIFS($B$27:$H$27,$K$7:$Q$7,">0")+1)) -> 99 | E36: =MIN(E27,IF(COUNTIF($K$8:$Q$8,">0")=0,99,_xlfn.MINIFS($B$27:$H$27,$K$8:$Q$8,">0")+1)) -> 0 | F36: =MIN(F27,IF(COUNTIF($K$9:$Q$9,">0")=0,99,_xlfn.MINIFS($B$27:$H$27,$K$9:$Q$9,">0")+1)) -> 2 | G36: =MIN(G27,IF(COUNTIF($K$10:$Q$10,">0")=0,99,_xlfn.MINIFS($B$27:$H$27,$K$10:$Q$10,">0")+1)) -> 1 | H36: =MIN(H27,IF(COUNTIF($K$11:$Q$11,">0")=0,99,_xlfn.MINIFS($B$27:$H$27,$K$11:$Q$11,">0")+1)) -> 1
A37: =INDEX(Comps,5) -> DIG | B37: =MIN(B28,IF(COUNTIF($K$5:$Q$5,">0")=0,99,_xlfn.MINIFS($B$28:$H$28,$K$5:$Q$5,">0")+1)) -> 99 | C37: =MIN(C28,IF(COUNTIF($K$6:$Q$6,">0")=0,99,_xlfn.MINIFS($B$28:$H$28,$K$6:$Q$6,">0")+1)) -> 99 | D37: =MIN(D28,IF(COUNTIF($K$7:$Q$7,">0")=0,99,_xlfn.MINIFS($B$28:$H$28,$K$7:$Q$7,">0")+1)) -> 99 | E37: =MIN(E28,IF(COUNTIF($K$8:$Q$8,">0")=0,99,_xlfn.MINIFS($B$28:$H$28,$K$8:$Q$8,">0")+1)) -> 2 | F37: =MIN(F28,IF(COUNTIF($K$9:$Q$9,">0")=0,99,_xlfn.MINIFS($B$28:$H$28,$K$9:$Q$9,">0")+1)) -> 0 | G37: =MIN(G28,IF(COUNTIF($K$10:$Q$10,">0")=0,99,_xlfn.MINIFS($B$28:$H$28,$K$10:$Q$10,">0")+1)) -> 1 | H37: =MIN(H28,IF(COUNTIF($K$11:$Q$11,">0")=0,99,_xlfn.MINIFS($B$28:$H$28,$K$11:$Q$11,">0")+1)) -> 1
A38: =INDEX(Comps,6) -> ENG | B38: =MIN(B29,IF(COUNTIF($K$5:$Q$5,">0")=0,99,_xlfn.MINIFS($B$29:$H$29,$K$5:$Q$5,">0")+1)) -> 99 | C38: =MIN(C29,IF(COUNTIF($K$6:$Q$6,">0")=0,99,_xlfn.MINIFS($B$29:$H$29,$K$6:$Q$6,">0")+1)) -> 99 | D38: =MIN(D29,IF(COUNTIF($K$7:$Q$7,">0")=0,99,_xlfn.MINIFS($B$29:$H$29,$K$7:$Q$7,">0")+1)) -> 99 | E38: =MIN(E29,IF(COUNTIF($K$8:$Q$8,">0")=0,99,_xlfn.MINIFS($B$29:$H$29,$K$8:$Q$8,">0")+1)) -> 1 | F38: =MIN(F29,IF(COUNTIF($K$9:$Q$9,">0")=0,99,_xlfn.MINIFS($B$29:$H$29,$K$9:$Q$9,">0")+1)) -> 1 | G38: =MIN(G29,IF(COUNTIF($K$10:$Q$10,">0")=0,99,_xlfn.MINIFS($B$29:$H$29,$K$10:$Q$10,">0")+1)) -> 0 | H38: =MIN(H29,IF(COUNTIF($K$11:$Q$11,">0")=0,99,_xlfn.MINIFS($B$29:$H$29,$K$11:$Q$11,">0")+1)) -> 2
A39: =INDEX(Comps,7) -> TRS | B39: =MIN(B30,IF(COUNTIF($K$5:$Q$5,">0")=0,99,_xlfn.MINIFS($B$30:$H$30,$K$5:$Q$5,">0")+1)) -> 99 | C39: =MIN(C30,IF(COUNTIF($K$6:$Q$6,">0")=0,99,_xlfn.MINIFS($B$30:$H$30,$K$6:$Q$6,">0")+1)) -> 99 | D39: =MIN(D30,IF(COUNTIF($K$7:$Q$7,">0")=0,99,_xlfn.MINIFS($B$30:$H$30,$K$7:$Q$7,">0")+1)) -> 99 | E39: =MIN(E30,IF(COUNTIF($K$8:$Q$8,">0")=0,99,_xlfn.MINIFS($B$30:$H$30,$K$8:$Q$8,">0")+1)) -> 1 | F39: =MIN(F30,IF(COUNTIF($K$9:$Q$9,">0")=0,99,_xlfn.MINIFS($B$30:$H$30,$K$9:$Q$9,">0")+1)) -> 1 | G39: =MIN(G30,IF(COUNTIF($K$10:$Q$10,">0")=0,99,_xlfn.MINIFS($B$30:$H$30,$K$10:$Q$10,">0")+1)) -> 2 | H39: =MIN(H30,IF(COUNTIF($K$11:$Q$11,">0")=0,99,_xlfn.MINIFS($B$30:$H$30,$K$11:$Q$11,">0")+1)) -> 0
A41: Distance using at most 4 arrows | B41: =INDEX(Comps,1) -> MKT | C41: =INDEX(Comps,2) -> GOV | D41: =INDEX(Comps,3) -> MAT | E41: =INDEX(Comps,4) -> IND | F41: =INDEX(Comps,5) -> DIG | G41: =INDEX(Comps,6) -> ENG | H41: =INDEX(Comps,7) -> TRS
A42: =INDEX(Comps,1) -> MKT | B42: =MIN(B33,IF(COUNTIF($K$5:$Q$5,">0")=0,99,_xlfn.MINIFS($B$33:$H$33,$K$5:$Q$5,">0")+1)) -> 0 | C42: =MIN(C33,IF(COUNTIF($K$6:$Q$6,">0")=0,99,_xlfn.MINIFS($B$33:$H$33,$K$6:$Q$6,">0")+1)) -> 99 | D42: =MIN(D33,IF(COUNTIF($K$7:$Q$7,">0")=0,99,_xlfn.MINIFS($B$33:$H$33,$K$7:$Q$7,">0")+1)) -> 1 | E42: =MIN(E33,IF(COUNTIF($K$8:$Q$8,">0")=0,99,_xlfn.MINIFS($B$33:$H$33,$K$8:$Q$8,">0")+1)) -> 1 | F42: =MIN(F33,IF(COUNTIF($K$9:$Q$9,">0")=0,99,_xlfn.MINIFS($B$33:$H$33,$K$9:$Q$9,">0")+1)) -> 1 | G42: =MIN(G33,IF(COUNTIF($K$10:$Q$10,">0")=0,99,_xlfn.MINIFS($B$33:$H$33,$K$10:$Q$10,">0")+1)) -> 2 | H42: =MIN(H33,IF(COUNTIF($K$11:$Q$11,">0")=0,99,_xlfn.MINIFS($B$33:$H$33,$K$11:$Q$11,">0")+1)) -> 2
A43: =INDEX(Comps,2) -> GOV | B43: =MIN(B34,IF(COUNTIF($K$5:$Q$5,">0")=0,99,_xlfn.MINIFS($B$34:$H$34,$K$5:$Q$5,">0")+1)) -> 99 | C43: =MIN(C34,IF(COUNTIF($K$6:$Q$6,">0")=0,99,_xlfn.MINIFS($B$34:$H$34,$K$6:$Q$6,">0")+1)) -> 0 | D43: =MIN(D34,IF(COUNTIF($K$7:$Q$7,">0")=0,99,_xlfn.MINIFS($B$34:$H$34,$K$7:$Q$7,">0")+1)) -> 99 | E43: =MIN(E34,IF(COUNTIF($K$8:$Q$8,">0")=0,99,_xlfn.MINIFS($B$34:$H$34,$K$8:$Q$8,">0")+1)) -> 2 | F43: =MIN(F34,IF(COUNTIF($K$9:$Q$9,">0")=0,99,_xlfn.MINIFS($B$34:$H$34,$K$9:$Q$9,">0")+1)) -> 1 | G43: =MIN(G34,IF(COUNTIF($K$10:$Q$10,">0")=0,99,_xlfn.MINIFS($B$34:$H$34,$K$10:$Q$10,">0")+1)) -> 2 | H43: =MIN(H34,IF(COUNTIF($K$11:$Q$11,">0")=0,99,_xlfn.MINIFS($B$34:$H$34,$K$11:$Q$11,">0")+1)) -> 1
A44: =INDEX(Comps,3) -> MAT | B44: =MIN(B35,IF(COUNTIF($K$5:$Q$5,">0")=0,99,_xlfn.MINIFS($B$35:$H$35,$K$5:$Q$5,">0")+1)) -> 99 | C44: =MIN(C35,IF(COUNTIF($K$6:$Q$6,">0")=0,99,_xlfn.MINIFS($B$35:$H$35,$K$6:$Q$6,">0")+1)) -> 99 | D44: =MIN(D35,IF(COUNTIF($K$7:$Q$7,">0")=0,99,_xlfn.MINIFS($B$35:$H$35,$K$7:$Q$7,">0")+1)) -> 0 | E44: =MIN(E35,IF(COUNTIF($K$8:$Q$8,">0")=0,99,_xlfn.MINIFS($B$35:$H$35,$K$8:$Q$8,">0")+1)) -> 2 | F44: =MIN(F35,IF(COUNTIF($K$9:$Q$9,">0")=0,99,_xlfn.MINIFS($B$35:$H$35,$K$9:$Q$9,">0")+1)) -> 2 | G44: =MIN(G35,IF(COUNTIF($K$10:$Q$10,">0")=0,99,_xlfn.MINIFS($B$35:$H$35,$K$10:$Q$10,">0")+1)) -> 3 | H44: =MIN(H35,IF(COUNTIF($K$11:$Q$11,">0")=0,99,_xlfn.MINIFS($B$35:$H$35,$K$11:$Q$11,">0")+1)) -> 1
A45: =INDEX(Comps,4) -> IND | B45: =MIN(B36,IF(COUNTIF($K$5:$Q$5,">0")=0,99,_xlfn.MINIFS($B$36:$H$36,$K$5:$Q$5,">0")+1)) -> 99 | C45: =MIN(C36,IF(COUNTIF($K$6:$Q$6,">0")=0,99,_xlfn.MINIFS($B$36:$H$36,$K$6:$Q$6,">0")+1)) -> 99 | D45: =MIN(D36,IF(COUNTIF($K$7:$Q$7,">0")=0,99,_xlfn.MINIFS($B$36:$H$36,$K$7:$Q$7,">0")+1)) -> 99 | E45: =MIN(E36,IF(COUNTIF($K$8:$Q$8,">0")=0,99,_xlfn.MINIFS($B$36:$H$36,$K$8:$Q$8,">0")+1)) -> 0 | F45: =MIN(F36,IF(COUNTIF($K$9:$Q$9,">0")=0,99,_xlfn.MINIFS($B$36:$H$36,$K$9:$Q$9,">0")+1)) -> 2 | G45: =MIN(G36,IF(COUNTIF($K$10:$Q$10,">0")=0,99,_xlfn.MINIFS($B$36:$H$36,$K$10:$Q$10,">0")+1)) -> 1 | H45: =MIN(H36,IF(COUNTIF($K$11:$Q$11,">0")=0,99,_xlfn.MINIFS($B$36:$H$36,$K$11:$Q$11,">0")+1)) -> 1
A46: =INDEX(Comps,5) -> DIG | B46: =MIN(B37,IF(COUNTIF($K$5:$Q$5,">0")=0,99,_xlfn.MINIFS($B$37:$H$37,$K$5:$Q$5,">0")+1)) -> 99 | C46: =MIN(C37,IF(COUNTIF($K$6:$Q$6,">0")=0,99,_xlfn.MINIFS($B$37:$H$37,$K$6:$Q$6,">0")+1)) -> 99 | D46: =MIN(D37,IF(COUNTIF($K$7:$Q$7,">0")=0,99,_xlfn.MINIFS($B$37:$H$37,$K$7:$Q$7,">0")+1)) -> 99 | E46: =MIN(E37,IF(COUNTIF($K$8:$Q$8,">0")=0,99,_xlfn.MINIFS($B$37:$H$37,$K$8:$Q$8,">0")+1)) -> 2 | F46: =MIN(F37,IF(COUNTIF($K$9:$Q$9,">0")=0,99,_xlfn.MINIFS($B$37:$H$37,$K$9:$Q$9,">0")+1)) -> 0 | G46: =MIN(G37,IF(COUNTIF($K$10:$Q$10,">0")=0,99,_xlfn.MINIFS($B$37:$H$37,$K$10:$Q$10,">0")+1)) -> 1 | H46: =MIN(H37,IF(COUNTIF($K$11:$Q$11,">0")=0,99,_xlfn.MINIFS($B$37:$H$37,$K$11:$Q$11,">0")+1)) -> 1
...

Sheet Ledgers
A1: Run the program on one clock: three ledgers month by month (Proposition 13.2; Theorem 13.4; Figure 13.1; AXIOM Lab 1.13, step 5)
A2: Chapter 1's model (Declarations rows 27-30): capital (liquidity), performance (the CFO's scorecard, (L + T + E - R)/4), risk (strategic risk against the ceiling of 75, measured +/-6).
A4: Month | B4: Years | C4: Liquidity index | D4: Technology | E4: Efficiency | F4: Strategic risk | G4: Liquidity ($ million) | H4: CFO's scorecard | J4: The three clocks | K4: Value | L4: Book (Figure 13.1; Online Appendix 13.B.4)
A5: 0 | B5: =A5/12 -> 0 | C5: =Declarations!$C$27+(Declarations!$B$27-Declarations!$C$27)*EXP(-Declarations!$D$27*$B5)+Declarations!$E$27*($B5/Declarations!$F$27)*EXP(1-$B5/Declarations!$F$27) -> 100 | D5: =Declarations!$C$28+(Declarations!$B$28-Declarations!$C$28)*EXP(-Declarations!$D$28*$B5)+Declarations!$E$28*($B5/Declarations!$F$28)*EXP(1-$B5/Declarations!$F$28) -> 41 | E5: =Declarations!$C$29+(Declarations!$B$29-Declarations!$C$29)*EXP(-Declarations!$D$29*$B5)+Declarations!$E$29*($B5/Declarations!$F$29)*EXP(1-$B5/Declarations!$F$29) -> 71 | F5: =Declarations!$C$30+(Declarations!$B$30-Declarations!$C$30)*EXP(-Declarations!$D$30*$B5)+Declarations!$E$30*($B5/Declarations!$F$30)*EXP(1-$B5/Declarations!$F$30) -> 64 | G5: =Per_point*C5 -> 620 | H5: =(C5+D5+E5-F5)/4 -> 37 | J5: Scorecard today | K5: =H5 -> 37 | L5: 37.0
A6: 1 | B6: =A6/12 -> 0.083333333 | C6: =Declarations!$C$27+(Declarations!$B$27-Declarations!$C$27)*EXP(-Declarations!$D$27*$B6)+Declarations!$E$27*($B6/Declarations!$F$27)*EXP(1-$B6/Declarations!$F$27) -> 97.30304 | D6: =Declarations!$C$28+(Declarations!$B$28-Declarations!$C$28)*EXP(-Declarations!$D$28*$B6)+Declarations!$E$28*($B6/Declarations!$F$28)*EXP(1-$B6/Declarations!$F$28) -> 42.657557 | E6: =Declarations!$C$29+(Declarations!$B$29-Declarations!$C$29)*EXP(-Declarations!$D$29*$B6)+Declarations!$E$29*($B6/Declarations!$F$29)*EXP(1-$B6/Declarations!$F$29) -> 69.959171 | F6: =Declarations!$C$30+(Declarations!$B$30-Declarations!$C$30)*EXP(-Declarations!$D$30*$B6)+Declarations!$E$30*($B6/Declarations!$F$30)*EXP(1-$B6/Declarations!$F$30) -> 66.039285 | G6: =Per_point*C6 -> 603.27885 | H6: =(C6+D6+E6-F6)/4 -> 35.970121 | J6: Liquidity low ($ million) | K6: =MIN($G$5:$G$65) -> 481.95038 | L6: $482 million
A7: 2 | B7: =A7/12 -> 0.16666667 | C7: =Declarations!$C$27+(Declarations!$B$27-Declarations!$C$27)*EXP(-Declarations!$D$27*$B7)+Declarations!$E$27*($B7/Declarations!$F$27)*EXP(1-$B7/Declarations!$F$27) -> 94.844448 | D7: =Declarations!$C$28+(Declarations!$B$28-Declarations!$C$28)*EXP(-Declarations!$D$28*$B7)+Declarations!$E$28*($B7/Declarations!$F$28)*EXP(1-$B7/Declarations!$F$28) -> 44.240858 | E7: =Declarations!$C$29+(Declarations!$B$29-Declarations!$C$29)*EXP(-Declarations!$D$29*$B7)+Declarations!$E$29*($B7/Declarations!$F$29)*EXP(1-$B7/Declarations!$F$29) -> 69.047308 | F7: =Declarations!$C$30+(Declarations!$B$30-Declarations!$C$30)*EXP(-Declarations!$D$30*$B7)+Declarations!$E$30*($B7/Declarations!$F$30)*EXP(1-$B7/Declarations!$F$30) -> 67.761734 | G7: =Per_point*C7 -> 588.03558 | H7: =(C7+D7+E7-F7)/4 -> 35.09272 | J7: Month of the liquidity low | K7: =INDEX($A$5:$A$65,MATCH(K6,$G$5:$G$65,0)) -> 21 | L7: month 21
A8: 3 | B8: =A8/12 -> 0.25 | C8: =Declarations!$C$27+(Declarations!$B$27-Declarations!$C$27)*EXP(-Declarations!$D$27*$B8)+Declarations!$E$27*($B8/Declarations!$F$27)*EXP(1-$B8/Declarations!$F$27) -> 92.60931 | D8: =Declarations!$C$28+(Declarations!$B$28-Declarations!$C$28)*EXP(-Declarations!$D$28*$B8)+Declarations!$E$28*($B8/Declarations!$F$28)*EXP(1-$B8/Declarations!$F$28) -> 45.753229 | E8: =Declarations!$C$29+(Declarations!$B$29-Declarations!$C$29)*EXP(-Declarations!$D$29*$B8)+Declarations!$E$29*($B8/Declarations!$F$29)*EXP(1-$B8/Declarations!$F$29) -> 68.253555 | F8: =Declarations!$C$30+(Declarations!$B$30-Declarations!$C$30)*EXP(-Declarations!$D$30*$B8)+Declarations!$E$30*($B8/Declarations!$F$30)*EXP(1-$B8/Declarations!$F$30) -> 69.200179 | G8: =Per_point*C8 -> 574.17772 | H8: =(C8+D8+E8-F8)/4 -> 34.353979 | J8: Scorecard low | K8: =MIN($H$5:$H$65) -> 32.106467 | L8: 32.1
