Workbook

Sheet README
B1: DCT Laboratory — Vol II, Ch 11: Distributionally Robust Enterprise Optimization
B2: Seed 26211 · Companion to DCT_V2_Ch11_Lab.ipynb and AXIOM Lab 2.11 (module AXIOM-11). Money in $ million.
B4: Worked Example 11.1, How Much Should Meridian Trust Its Law?, with the book's declarations: Chapter 9's law, levers and floor; the treasury's record (two closures in twenty years) and the engineering office's (forty quarters of deviations). Chances are simulated on Chapter 9's 100,000 paths (seed 8) and checked on its 100,000 fresh paths (seed 26209); a higher rate adds closures from seeds 1108 and 26208 (Online Appendix Remark 11.B.1).
B5: Declarations: the law, the levers and their prices, the records.
B6: Records: Garwood's bound for the rate and the chi-square bounds for the spread, Bonferroni's confidence, Garwood's exact coverage, and Volume I's package under the laws the records allow (Proposition 11.2; Step 1).
B7: Family: the cheapest package at each declaration's worst law, its cost, the price of ambiguity and the value of a longer record; the family's package on the 49-law grid (Theorem 11.1(iv); Step 2).
B8: Divergence and KL_Bisection: the radii of the records' doubts, kl(q || p), the law's appetite alpha'(d) and the worst chance q*(p, d) by bisection, the ball's packages, and a ball of any radius (Theorem 11.2; Figure 11.1; Step 3).
B9: Wasserstein: the thinnest-margin requirement eps / 0.05, the ball's packages, and the radius that holds the spread's doubt (Theorem 11.3; Figure 11.2(a); Step 3).
B10: Records1000: designs on 200 records of 1,000 paths with margins and radii, and reliability per dollar (Figure 11.2(b); Step 4).
B11: Moments: Cantelli's bounds quarter by quarter, the 4.36 multiplier and the moment package's delay and cost (Proposition 11.1; Section 11.4).
B12: PriceTheDoubt: Table 11.3, every declaration's package, its chances under the law and the records' worst law, the fresh paths' gaps and the standard errors (Step 5).
B13: Engine values (green) are what needs the simulated paths: chances, the designs' lines and delays, the margins' means and spreads, the records of 1,000 paths. Everything else is a formula.
... B20: Cross-sheet link: green.

Sheet Declarations
A1: Declarations (Worked Example 11.1, Step 1; Chapter 9's law and levers; the records behind the law). Money in $ million.
A3: Quantity | B3: Value | C3: Source
A4: Years in the program, H | B4: 3 | C4: Twelve quarters
A5: Quarters in the program | B5: 12
A6: Paths (the book's, seed 8; fresh, seed 26209) | B6: 100000 | C6: Chapter 9's law
A7: Floor | B7: 350 | C7: The board's floor, in every quarter
A8: Persistence of a deviation a quarter | B8: 0.6 | C8: E' = 0.6 E + w (Volume I, Chapter 8)
A9: Declared spread of the innovations w, a quarter | B9: 50 | C9: The engineering office's record
A10: Declared rate of funding-window closures, a year | B10: 0.1 | C10: The treasury's record
A11: Closure size: mean | B11: 120 | C11: Gamma-distributed, never recovered
A12: Closure size: standard deviation | B12: 50
A13: Line fees over the program, per $ of line | B13: 0.03 | C13: The treasury
A14: A quarter of delay | B14: 8 | C14: The transformation office
A15: The draw's depth (index points) | B15: 28 | C15: Deepest at two years
A16: Depth cut by a quarter of delay (points) | B16: 4
A17: $ million per index point | B17: =620/100 -> 6.2 | C17: Index 100 = $620 million
A18: The draw is deepest at (years) | B18: 2 | C18: Shape S(t) = (t/2) e^(1 - t/2)
A19: The appetite | B19: 0.05 | C19: At most a 5 percent chance of a breach in some quarter
A20: The extra stream's rate ceiling (a year) | B20: 0.4 | C20: Online Appendix Remark 11.B.1: a higher rate adds closures from an extra stream at 0.40 - 0.10, thinned
A22: The records (Worked Example 11.1, Step 1; Proposition 11.2)
A23: The treasury's record: closures | B23: 2 | C23: Two closures...
A24: in years of history | B24: 20 | C24: ...in twenty years: the declared 0.10 a year
A25: The engineering office's record: quarters of deviations | B25: 40
A26: innovations (the persistence 0.6 taken as known) | B26: =B25-1 -> 39 | C26: 39 innovations
A27: their root-mean-square | B27: 50 | C27: The declared spread
A28: Confidence of each bound | B28: 0.95 | C28: One-sided, 95 percent each
A29: Twice the record: closures | B29: 4 | C29: Four closures in forty years, the same estimate
A30: in years | B30: 40
A31: quarters of deviations | B31: 80 | C31: Eighty quarters
A32: innovations | B32: =B31-1 -> 79 | C32: 79 innovations

Sheet Records
A1: Read the records: confidence bounds for the rate and the spread (Proposition 11.2(i)-(iii); Worked Example 11.1, Step 1; AXIOM Lab 2.11, step 1)
A2: Rate: n closures in T years give the one-sided bound chi2_(conf)(2n + 2) / (2T) (Garwood). Spread: n Gaussian innovations of root-mean-square s give s sqrt(n / chi2_(1-conf)(n)) above and s sqrt(n / chi2_(conf)(n)) below.
A3: Quantity | B3: Value | C3: Reading
A4: Rate: the record's estimate (closures a year) | B4: =NCl/TYrs -> 0.1 | C4: 0.10
A5: Rate: upper 95% bound (Garwood) | B5: =_xlfn.CHISQ.INV(Conf,2*NCl+2)/(2*TYrs) -> 0.31478968 | C5: 0.3148: Section 11.1's 0.315
A6: the same from the right tail | B6: =_xlfn.CHISQ.INV.RT(1-Conf,2*NCl+2)/(2*TYrs) -> 0.31478968
A7: Rate: lower 95% bound | B7: =_xlfn.CHISQ.INV(1-Conf,2*NCl)/(2*TYrs) -> 0.017768076 | C7: 0.0178
A8: Spread: lower 95% bound | B8: =RMS*SQRT(NInn/_xlfn.CHISQ.INV(Conf,NInn)) -> 42.268464 | C8: $42.27 million
A9: Spread: upper 95% bound | B9: =RMS*SQRT(NInn/_xlfn.CHISQ.INV(1-Conf,NInn)) -> 61.599147 | C9: $61.60 million
A10: The records' family holds the true law with at least (Bonferroni) | B10: =1-2*(1-Conf) -> 0.9 | C10: 90 percent: Proposition 11.2(iii)
A11: The corner's spread, as a multiple of the declared | B11: =B9/Sig0 -> 1.2319829 | C11: 1.232
A12: Twice the record: rate, upper bound | B12: =_xlfn.CHISQ.INV(Conf,2*NCl2+2)/(2*TYrs2) -> 0.22883798 | C12: 0.2288 (Step 5's 0.229)
A13: Twice the record: spread, upper bound | B13: =RMS*SQRT(NInn2/_xlfn.CHISQ.INV(1-Conf,NInn2)) -> 57.602817 | C13: $57.60 million
A14: Twice the record: spread, lower bound | B14: =RMS*SQRT(NInn2/_xlfn.CHISQ.INV(Conf,NInn2)) -> 44.275554 | C14: $44.28 million
A16: Garwood's bound errs on the safe side: the chance it holds the true rate, exactly (Proposition 11.2(i))
A17: Closures n in the record | B17: Its upper bound | C17: P(n) at a true rate of 0.10 | D17: P(n) at 0.20 | E17: P(n) at the bound
A18: 0 | B18: =_xlfn.CHISQ.INV(Conf,2*A18+2)/(2*TYrs) -> 0.14978661 | C18: =_xlfn.POISSON.DIST(A18,Lam0*TYrs,FALSE()) -> 0.13533528 | D18: =_xlfn.POISSON.DIST(A18,0.2*TYrs,FALSE()) -> 0.018315639 | E18: =_xlfn.POISSON.DIST(A18,LamU*TYrs,FALSE()) -> 0.0018440452
A19: 1 | B19: =_xlfn.CHISQ.INV(Conf,2*A19+2)/(2*TYrs) -> 0.23719323 | C19: =_xlfn.POISSON.DIST(A19,Lam0*TYrs,FALSE()) -> 0.27067057 | D19: =_xlfn.POISSON.DIST(A19,0.2*TYrs,FALSE()) -> 0.073262556 | E19: =_xlfn.POISSON.DIST(A19,LamU*TYrs,FALSE()) -> 0.011609728
A20: 2 | B20: =_xlfn.CHISQ.INV(Conf,2*A20+2)/(2*TYrs) -> 0.31478968 | C20: =_xlfn.POISSON.DIST(A20,Lam0*TYrs,FALSE()) -> 0.27067057 | D20: =_xlfn.POISSON.DIST(A20,0.2*TYrs,FALSE()) -> 0.14652511 | E20: =_xlfn.POISSON.DIST(A20,LamU*TYrs,FALSE()) -> 0.036546227
A21: 3 | B21: =_xlfn.CHISQ.INV(Conf,2*A21+2)/(2*TYrs) -> 0.38768283 | C21: =_xlfn.POISSON.DIST(A21,Lam0*TYrs,FALSE()) -> 0.18044704 | D21: =_xlfn.POISSON.DIST(A21,0.2*TYrs,FALSE()) -> 0.19536681 | E21: =_xlfn.POISSON.DIST(A21,LamU*TYrs,FALSE()) -> 0.076695833
A22: 4 | B22: =_xlfn.CHISQ.INV(Conf,2*A22+2)/(2*TYrs) -> 0.45767595 | C22: =_xlfn.POISSON.DIST(A22,Lam0*TYrs,FALSE()) -> 0.090223522 | D22: =_xlfn.POISSON.DIST(A22,0.2*TYrs,FALSE()) -> 0.19536681 | E22: =_xlfn.POISSON.DIST(A22,LamU*TYrs,FALSE()) -> 0.12071528
A23: 5 | B23: =_xlfn.CHISQ.INV(Conf,2*A23+2)/(2*TYrs) -> 0.52565175 | C23: =_xlfn.POISSON.DIST(A23,Lam0*TYrs,FALSE()) -> 0.036089409 | D23: =_xlfn.POISSON.DIST(A23,0.2*TYrs,FALSE()) -> 0.15629345 | E23: =_xlfn.POISSON.DIST(A23,LamU*TYrs,FALSE()) -> 0.1519997
A24: 6 | B24: =_xlfn.CHISQ.INV(Conf,2*A24+2)/(2*TYrs) -> 0.59211978 | C24: =_xlfn.POISSON.DIST(A24,Lam0*TYrs,FALSE()) -> 0.012029803 | D24: =_xlfn.POISSON.DIST(A24,0.2*TYrs,FALSE()) -> 0.10419563 | E24: =_xlfn.POISSON.DIST(A24,LamU*TYrs,FALSE()) -> 0.15949313
A25: 7 | B25: =_xlfn.CHISQ.INV(Conf,2*A25+2)/(2*TYrs) -> 0.65740569 | C25: =_xlfn.POISSON.DIST(A25,Lam0*TYrs,FALSE()) -> 0.0034370866 | D25: =_xlfn.POISSON.DIST(A25,0.2*TYrs,FALSE()) -> 0.059540363 | E25: =_xlfn.POISSON.DIST(A25,LamU*TYrs,FALSE()) -> 0.14344797
A26: 8 | B26: =_xlfn.CHISQ.INV(Conf,2*A26+2)/(2*TYrs) -> 0.72173249 | C26: =_xlfn.POISSON.DIST(A26,Lam0*TYrs,FALSE()) -> 0.00085927164 | D26: =_xlfn.POISSON.DIST(A26,0.2*TYrs,FALSE()) -> 0.029770181 | E26: =_xlfn.POISSON.DIST(A26,LamU*TYrs,FALSE()) -> 0.11288985
A27: 9 | B27: =_xlfn.CHISQ.INV(Conf,2*A27+2)/(2*TYrs) -> 0.78526082 | C27: =_xlfn.POISSON.DIST(A27,Lam0*TYrs,FALSE()) -> 0.00019094925 | D27: =_xlfn.POISSON.DIST(A27,0.2*TYrs,FALSE()) -> 0.013231192 | E27: =_xlfn.POISSON.DIST(A27,LamU*TYrs,FALSE()) -> 0.078970136
A28: 10 | B28: =_xlfn.CHISQ.INV(Conf,2*A28+2)/(2*TYrs) -> 0.84811096 | C28: =_xlfn.POISSON.DIST(A28,Lam0*TYrs,FALSE()) -> 3.8189851e-05 | D28: =_xlfn.POISSON.DIST(A28,0.2*TYrs,FALSE()) -> 0.0052924767 | E28: =_xlfn.POISSON.DIST(A28,LamU*TYrs,FALSE()) -> 0.049717968
A29: 11 | B29: =_xlfn.CHISQ.INV(Conf,2*A29+2)/(2*TYrs) -> 0.91037571 | C29: =_xlfn.POISSON.DIST(A29,Lam0*TYrs,FALSE()) -> 6.9436092e-06 | D29: =_xlfn.POISSON.DIST(A29,0.2*TYrs,FALSE()) -> 0.001924537 | E29: =_xlfn.POISSON.DIST(A29,LamU*TYrs,FALSE()) -> 0.028455824
... A33: 15 | B33: =_xlfn.CHISQ.INV(Conf,2*A33+2)/(2*TYrs) -> 1.1548565 | C33: =_xlfn.POISSON.DIST(A33,Lam0*TYrs,FALSE()) -> 3.3912621e-09 | D33: =_xlfn.POISSON.DIST(A33,0.2*TYrs,FALSE()) -> 1.5039117e-05 | E33: =_xlfn.POISSON.DIST(A33,LamU*TYrs,FALSE()) -> 0.0013646749
A35: Chance the bound holds a true rate of 0.10 | B35: =1-SUMPRODUCT(($B$18:$B$33<Lam0)*C18:C33) -> 1
A36: Chance the bound holds a true rate of 0.20 | B36: =1-SUMPRODUCT(($B$18:$B$33<0.2)*D18:D33) -> 0.98168436
A37: Chance the bound holds a true rate of the bound, 0.3148 | B37: =1-SUMPRODUCT(($B$18:$B$33<LamU)*E18:E33) -> 0.98654623
A38: Simulated records under the declared law (engine, the lab's seed 26211): the rate's bound holds | B38: 1 | C38: 100,000 records; with no closure at all the bound is 0.150
A39: the spread's bound holds | B39: 0.94986 | C39: 95 percent: Proposition 11.2(ii)
A40: both hold | B40: 0.94986 | C40: At least 90 percent (Bonferroni)
A42: Volume I's package ($170 million line, 0.668 quarter) under the laws the records allow (engine)
A43: Rate a year (spread $50m) | B43: Chance of a breach (engine) | D43: Spread (rate 0.10) | E43: Chance of a breach (engine)
A44: 0 | B44: 0.04471 | D44: 40 | E44: 0.01034
A45: =LamL -> 0.017768076 | B45: 0.04567 | D45: =SigL -> 42.268464 | E45: 0.01591
A46: 0.05 | B46: 0.04732 | D46: 45 | E46: 0.02515
...

Sheet Family
A1: Price the family: the cheapest package at each declaration's worst law (Theorem 11.1(iv); Proposition 11.2(iii); Worked Example 11.1, Step 2; AXIOM Lab 2.11, step 2)
A2: Lines and delays are Chapter 9's design at each law (engine: the line on a $5 million grid, the delay the least that keeps 5 percent on the simulated paths); costs, the price of ambiguity and the value of a longer record are formulas.
A4: Declaration | B4: Rate a year | C4: Spread | D4: Volume I's package at the law (engine) | E4: fresh (engine) | F4: Line (engine) | G4: Delay (engine) | H4: Fees | I4: Delay cost | J4: Cost | K4: Fresh paths at its law (engine) | L4: Under the declared law (engine) | M4: fresh (engine) | N4: Extra over Volume I's package
A5: Volume I's package (one law) | B5: =Lam0 -> 0.1 | C5: =Sig0 -> 50 | D5: 0.05 | E5: 0.04907 | F5: 170 | G5: 0.66757636 | H5: =Fee*F5 -> 5.1 | I5: =VQ*G5 -> 5.3406109 | J5: =H5+I5 -> 10.440611 | K5: 0.04907 | L5: 0.05 | M5: 0.04907 | N5: =J5-$J$5 -> 0
A6: Closures' doubt (rate at its bound) | B6: =LamU -> 0.31478968 | C6: =Sig0 -> 50 | D6: 0.0616 | E6: 0.06064 | F6: 210 | G6: 0.66716792 | H6: =Fee*F6 -> 6.3 | I6: =VQ*G6 -> 5.3373433 | J6: =H6+I6 -> 11.637343 | K6: 0.04883 | L6: 0.04631 | M6: 0.04534 | N6: =J6-$J$5 -> 1.1967324
A7: Spread's doubt (spread at its bound) | B7: =Lam0 -> 0.1 | C7: =SigU -> 61.599147 | D7: 0.14427 | E7: 0.14443 | F7: 170 | G7: 2.218368 | H7: =Fee*F7 -> 5.1 | I7: =VQ*G7 -> 17.746944 | J7: =H7+I7 -> 22.846944 | K7: 0.04914 | L7: 0.01063 | M7: 0.01032 | N7: =J7-$J$5 -> 12.406333
A8: The records' family (both: the corner) | B8: =LamU -> 0.31478968 | C8: =SigU -> 61.599147 | D8: 0.15789 | E8: 0.15835 | F8: 200 | G8: 2.2504041 | H8: =Fee*F8 -> 6 | I8: =VQ*G8 -> 18.003233 | J8: =H8+I8 -> 24.003233 | K8: 0.04905 | L8: 0.00894 | M8: 0.0086 | N8: =J8-$J$5 -> 13.562622
A9: Records twice as long | B9: =LamU2 -> 0.22883798 | C9: =SigU2 -> 57.602817 | D9: 0.11598 | E9: 0.11429 | F9: 195 | G9: 1.6900824 | H9: =Fee*F9 -> 5.85 | I9: =VQ*G9 -> 13.520659 | J9: =H9+I9 -> 19.370659 | K9: 0.04871 | L9: 0.01664 | M9: 0.01622 | N9: =J9-$J$5 -> 8.9300482
A11: The price of ambiguity: the records' family less one law | B11: =J8-J5 -> 13.562622 | C11: $13.56 million (Step 5)
A12: of which the spread's doubt alone | B12: =J7-J5 -> 12.406333 | C12: Most of it: the spread is what costs
A13: and the closures' doubt alone | B13: =J6-J5 -> 1.1967324
A14: The value of a record twice as long | B14: =J8-J9 -> 4.6325741 | C14: $4.63 million on this program alone
A16: The records' family's package ($200 million line, 2.250 quarters) across the family: 49 laws (engine)
A17: Rows: seven rates from 0 to the bound; columns: seven spreads from the lower bound to the upper (Online Appendix Remark 11.B.1). The chance rises with both: the worst law is the corner.
A18: Rate \ spread | B18: =SigL+(SigU-SigL)*0/6 -> 42.268464 | C18: =SigL+(SigU-SigL)*1/6 -> 45.490244 | D18: =SigL+(SigU-SigL)*2/6 -> 48.712025 | E18: =SigL+(SigU-SigL)*3/6 -> 51.933805 | F18: =SigL+(SigU-SigL)*4/6 -> 55.155586 | G18: =SigL+(SigU-SigL)*5/6 -> 58.377366 | H18: =SigL+(SigU-SigL)*6/6 -> 61.599147
A19: =LamU*0/6 -> 0 | B19: 0.00098 | C19: 0.00256 | D19: 0.00613 | E19: 0.0112 | F19: 0.01925 | G19: 0.03049 | H19: 0.04505
A20: =LamU*1/6 -> 0.052464947 | B20: 0.00123 | C20: 0.00292 | D20: 0.00655 | E20: 0.0118 | F20: 0.01991 | G20: 0.03116 | H20: 0.04587
A21: =LamU*2/6 -> 0.10492989 | B21: 0.00163 | C21: 0.0034 | D21: 0.00718 | E21: 0.01251 | F21: 0.02063 | G21: 0.03194 | H21: 0.04669
A22: =LamU*3/6 -> 0.15739484 | B22: 0.00189 | C22: 0.00369 | D22: 0.00759 | E22: 0.01298 | F22: 0.02131 | G22: 0.03271 | H22: 0.04746
A23: =LamU*4/6 -> 0.20985979 | B23: 0.00219 | C23: 0.00408 | D23: 0.00805 | E23: 0.01356 | F23: 0.02196 | G23: 0.03343 | H23: 0.04822
A24: =LamU*5/6 -> 0.26232473 | B24: 0.00257 | C24: 0.00453 | D24: 0.00856 | E24: 0.01413 | F24: 0.02266 | G24: 0.03415 | H24: 0.04903
A25: =LamU*6/6 -> 0.31478968 | B25: 0.00292 | C25: 0.00491 | D25: 0.00901 | E25: 0.0147 | F25: 0.02342 | G25: 0.03501 | H25: 0.05
A27: The largest chance on the grid | B27: =MAX(B19:H25) -> 0.05 | C27: 5.00 percent
A28: at the corner? (1 = yes) | B28: =IF(MAX(B19:H25)=H25,1,0) -> 1 | C28: The corner: both bounds

Sheet Divergence
A1: Try balls: Kullback-Leibler families (Theorem 11.2; Figure 11.1; Worked Example 11.1, Step 3; AXIOM Lab 2.11, step 3)
A2: kl(q || p) = q ln(q/p) + (1 - q) ln((1 - q)/(1 - p)). The ball of radius d keeps 5 percent exactly when the law keeps alpha'(d), kl(0.05 || alpha') = d; the ball's package is Chapter 9's design at that appetite.
A4: The radius that holds each doubt (Theorem 11.2(iii)) | B4: Radius d | C4: alpha'(d) by bisection | D4: alpha'(d) (engine) | E4: Reading | L4: Explore: a ball of any radius
A5: Closures at the bound over the program: H (l' ln(l'/l) - l' + l) | B5: =H_yrs*(LamU*LN(LamU/Lam0)-LamU+Lam0) -> 0.43857157 | C5: =KL_Bisection!B71 -> 2.9265667e-06 | D5: 2.9265667e-06 | E5: 0.439: 3 in a million | L5: Radius d (change it) | M5: 0.01
A6: Spread at the bound, twelve innovations: n (ln(1/c) + (c^2 - 1)/2) | B6: =NQ*(LN(1/Records!B11)+(Records!B11^2-1)/2) -> 0.60319157 | C6: =KL_Bisection!D71 -> 1.0875871e-07 | D6: 1.0875871e-07 | E6: 0.603 | L6: The law must keep alpha'(d) | M6: =KL_Bisection!AP71 -> 0.024981145
A7: Both: divergences add over independent parts | B7: =B5+B6 -> 1.0417631 | C7: =KL_Bisection!F71 -> 1.6868595e-11 | D7: 1.6868595e-11 | E7: 1.042: 2 in 100 billion | L7: Volume I's package (5% under the law) breaches on up to q*(5%, d) | M7: =KL_Bisection!AR71 -> 0.083648267
L8: Check: kl(0.05 || alpha') - d | M8: =(Alpha)*LN((Alpha)/(M6))+(1-(Alpha))*LN((1-(Alpha))/(1-(M6)))-M5 -> 5.0306981e-17
A9: The levers' floor: the fewest paths a $400m line and 7 quarters leave breached (engine) | B9: 1 | E9: One path in 100,000
A10: as a chance | B10: =B9/NPaths -> 1e-05 | L10: Change d in M5: the bisection on KL_Bisection recomputes alpha'(d) and q*(5%, d). For d = 0.01 the law must keep 2.50 percent: a $175 million line and 1.354 quarters, $16.08 million (engine, row 29).
A11: the ball is beyond the levers from kl(0.05 || that chance) | B11: =(Alpha)*LN((Alpha)/(B10))+(1-(Alpha))*LN((1-(Alpha))/(1-(B10))) -> 0.37714053 | E11: 0.377 (Online Appendix 11.B.2; Figure 11.1(b): 0.38)
A13: The worst chance of Volume I's package over the ball (it keeps 5.00 percent under the law)
A14: Radius d | B14: q* by bisection | C14: q* (engine) | D14: kl(q* engine || 0.05) - d
A15: 0.001 | B15: =KL_Bisection!AB71 -> 0.060040821 | C15: 0.060040821 | D15: =(C15)*LN((C15)/(Alpha))+(1-(C15))*LN((1-(C15))/(1-(Alpha)))-A15 -> 1.1275703e-17
A16: 0.003 | B16: =KL_Bisection!AD71 -> 0.067751818 | C16: 0.067751818 | D16: =(C16)*LN((C16)/(Alpha))+(1-(C16))*LN((1-(C16))/(1-(Alpha)))-A16 -> -2.8622937e-17
A17: 0.01 | B17: =KL_Bisection!AF71 -> 0.083648267 | C17: 0.083648267 | D17: =(C17)*LN((C17)/(Alpha))+(1-(C17))*LN((1-(C17))/(1-(Alpha)))-A17 -> -3.989864e-17
A18: 0.03 | B18: =KL_Bisection!AH71 -> 0.11154805 | C18: 0.11154805 | D18: =(C18)*LN((C18)/(Alpha))+(1-(C18))*LN((1-(C18))/(1-(Alpha)))-A18 -> 0
A19: 0.1 | B19: =KL_Bisection!AJ71 -> 0.17294935 | C19: 0.17294935 | D19: =(C19)*LN((C19)/(Alpha))+(1-(C19))*LN((1-(C19))/(1-(Alpha)))-A19 -> 0
A20: 0.3 | B20: =KL_Bisection!AL71 -> 0.2885192 | C20: 0.2885192 | D20: =(C20)*LN((C20)/(Alpha))+(1-(C20))*LN((1-(C20))/(1-(Alpha)))-A20 -> 0
A21: 1 | B21: =KL_Bisection!AN71 -> 0.55551415 | C21: 0.55551415 | D21: =(C21)*LN((C21)/(Alpha))+(1-(C21))*LN((1-(C21))/(1-(Alpha)))-A21 -> 0
A23: Keeping 5 percent over the ball: Chapter 9's design at the law's appetite alpha'(d) (engine) and its cost
A24: Radius d | B24: alpha' by bisection | C24: alpha' (engine) | D24: kl(0.05 || alpha' engine) - d | E24: Line (engine) | F24: Delay (engine) | G24: Cost | H24: Under the law (engine) | I24: Fresh paths (engine) | J24: Extra over Volume I's
A25: 0 | B25: =Alpha -> 0.05 | C25: 0.05 | E25: 170 | F25: 0.66757636 | G25: =Fee*E25+VQ*F25 -> 10.440611 | H25: 0.05 | I25: 0.04907 | J25: =G25-$G$25 -> 0
A26: 0.001 | B26: =KL_Bisection!H71 -> 0.040848256 | C26: 0.040848256 | D26: =(Alpha)*LN((Alpha)/(C26))+(1-(Alpha))*LN((1-(Alpha))/(1-(C26)))-A26 -> -5.6378513e-17 | E26: 160 | F26: 0.92428019 | G26: =Fee*E26+VQ*F26 -> 12.194242 | H26: 0.04084 | I26: 0.04049 | J26: =G26-$G$25 -> 1.7536307
A27: 0.002 | B27: =KL_Bisection!J71 -> 0.037401261 | C27: 0.037401261 | D27: =(Alpha)*LN((Alpha)/(C27))+(1-(Alpha))*LN((1-(Alpha))/(1-(C27)))-A27 -> 5.7245875e-17 | E27: 165 | F27: 0.99808349 | G27: =Fee*E27+VQ*F27 -> 12.934668 | H27: 0.0374 | I27: 0.0368 | J27: =G27-$G$25 -> 2.494057
A28: 0.005 | B28: =KL_Bisection!L71 -> 0.031142017 | C28: 0.031142017 | D28: =(Alpha)*LN((Alpha)/(C28))+(1-(Alpha))*LN((1-(Alpha))/(1-(C28)))-A28 -> -5.1174343e-17 | E28: 170 | F28: 1.1621673 | G28: =Fee*E28+VQ*F28 -> 14.397338 | H28: 0.03114 | I28: 0.03093 | J28: =G28-$G$25 -> 3.9567275
A29: 0.01 | B29: =KL_Bisection!N71 -> 0.024981145 | C29: 0.024981145 | D29: =(Alpha)*LN((Alpha)/(C29))+(1-(Alpha))*LN((1-(Alpha))/(1-(C29)))-A29 -> 0 | E29: 175 | F29: 1.3539024 | G29: =Fee*E29+VQ*F29 -> 16.081219 | H29: 0.02498 | I29: 0.02515 | J29: =G29-$G$25 -> 5.640608
A30: 0.02 | B30: =KL_Bisection!P71 -> 0.017786384 | C30: 0.017786384 | D30: =(Alpha)*LN((Alpha)/(C30))+(1-(Alpha))*LN((1-(Alpha))/(1-(C30)))-A30 -> 0 | E30: 180 | F30: 1.6708183 | G30: =Fee*E30+VQ*F30 -> 18.766546 | H30: 0.01778 | I30: 0.01745 | J30: =G30-$G$25 -> 8.3259354
A31: 0.03 | B31: =KL_Bisection!R71 -> 0.013373251 | C31: 0.013373251 | D31: =(Alpha)*LN((Alpha)/(C31))+(1-(Alpha))*LN((1-(Alpha))/(1-(C31)))-A31 -> 0 | E31: 175 | F31: 1.9552346 | G31: =Fee*E31+VQ*F31 -> 20.891877 | H31: 0.01337 | I31: 0.01302 | J31: =G31-$G$25 -> 10.451266
A32: 0.05 | B32: =KL_Bisection!T71 -> 0.0081010838 | C32: 0.0081010838 | D32: =(Alpha)*LN((Alpha)/(C32))+(1-(Alpha))*LN((1-(Alpha))/(1-(C32)))-A32 -> 0 | E32: 195 | F32: 2.3562579 | G32: =Fee*E32+VQ*F32 -> 24.700063 | H32: 0.0081 | I32: 0.00792 | J32: =G32-$G$25 -> 14.259452
A33: 0.075 | B33: =KL_Bisection!V71 -> 0.0045949388 | C33: 0.0045949388 | D33: =(Alpha)*LN((Alpha)/(C33))+(1-(Alpha))*LN((1-(Alpha))/(1-(C33)))-A33 -> 0 | E33: 215 | F33: 2.7372767 | G33: =Fee*E33+VQ*F33 -> 28.348214 | H33: 0.00459 | I33: 0.00457 | J33: =G33-$G$25 -> 17.907603
A34: 0.1 | B34: =KL_Bisection!X71 -> 0.0026874158 | C34: 0.0026874158 | D34: =(Alpha)*LN((Alpha)/(C34))+(1-(Alpha))*LN((1-(Alpha))/(1-(C34)))-A34 -> 0 | E34: 200 | F34: 3.1731757 | G34: =Fee*E34+VQ*F34 -> 31.385406 | H34: 0.00268 | I34: 0.00299 | J34: =G34-$G$25 -> 20.944795
A35: 0.15 | B35: =KL_Bisection!Z71 -> 0.00095660434 | C35: 0.00095660434 | D35: =(Alpha)*LN((Alpha)/(C35))+(1-(Alpha))*LN((1-(Alpha))/(1-(C35)))-A35 -> 0 | E35: 240 | F35: 3.8507391 | G35: =Fee*E35+VQ*F35 -> 38.005913 | H35: 0.00095 | I35: 0.00106 | J35: =G35-$G$25 -> 27.565302

Sheet KL_Bisection
A1: Theorem 11.2(ii) by bisection: the law's appetite alpha'(d), kl(0.05 || alpha') = d, and the worst chance q*(p, d), kl(q* || p) = d
A2: Each problem takes two columns (low and high end of the bracket) and 60 halvings. alpha' is bracketed in ln p between ln(1E-30) and ln(0.05): kl(0.05 || p) falls as p rises. q* is bracketed between p and 1: kl(q || p) rises with q.
A4: Problem | B4: closures' doubt | D4: spread's doubt | F4: both doubts | H4: design d = 0.001 | J4: design d = 0.002 | L4: design d = 0.005 | N4: design d = 0.01 | P4: design d = 0.02 | R4: design d = 0.03 | T4: design d = 0.05 | V4: design d = 0.075 | X4: design d = 0.1 | Z4: design d = 0.15 | AB4: Volume I's package, d = 0.001 | AD4: Volume I's package, d = 0.003 | AF4: Volume I's package, d = 0.01 | AH4: Volume I's package, d = 0.03 | AJ4: Volume I's package, d = 0.1 | AL4: Volume I's package, d = 0.3 | AN4: Volume I's package, d = 1 | AP4: the input d | AR4: the input d
B5: alpha' | D5: alpha' | F5: alpha' | H5: alpha' | J5: alpha' | L5: alpha' | N5: alpha' | P5: alpha' | R5: alpha' | T5: alpha' | V5: alpha' | X5: alpha' | Z5: alpha' | AB5: q* | AD5: q* | AF5: q* | AH5: q* | AJ5: q* | AL5: q* | AN5: q* | AP5: alpha' | AR5: q*
A6: d | B6: =Divergence!B5 -> 0.43857157 | D6: =Divergence!B6 -> 0.60319157 | F6: =Divergence!B7 -> 1.0417631 | H6: 0.001 | J6: 0.002 | L6: 0.005 | N6: 0.01 | P6: 0.02 | R6: 0.03 | T6: 0.05 | V6: 0.075 | X6: 0.1 | Z6: 0.15 | AB6: 0.001 | AD6: 0.003 | AF6: 0.01 | AH6: 0.03 | AJ6: 0.1 | AL6: 0.3 | AN6: 1 | AP6: =Divergence!M5 -> 0.01 | AR6: =Divergence!M5 -> 0.01
A7: chance p | B7: =Alpha -> 0.05 | D7: =Alpha -> 0.05 | F7: =Alpha -> 0.05 | H7: =Alpha -> 0.05 | J7: =Alpha -> 0.05 | L7: =Alpha -> 0.05 | N7: =Alpha -> 0.05 | P7: =Alpha -> 0.05 | R7: =Alpha -> 0.05 | T7: =Alpha -> 0.05 | V7: =Alpha -> 0.05 | X7: =Alpha -> 0.05 | Z7: =Alpha -> 0.05 | AB7: =Alpha -> 0.05 | AD7: =Alpha -> 0.05 | AF7: =Alpha -> 0.05 | AH7: =Alpha -> 0.05 | AJ7: =Alpha -> 0.05 | AL7: =Alpha -> 0.05 | AN7: =Alpha -> 0.05 | AP7: =Alpha -> 0.05 | AR7: =Alpha -> 0.05
A9: halving 0 | B9: =LN(1E-030) -> -69.077553 | C9: =LN(B7) -> -2.9957323 | D9: =LN(1E-030) -> -69.077553 | E9: =LN(D7) -> -2.9957323 | F9: =LN(1E-030) -> -69.077553 | G9: =LN(F7) -> -2.9957323 | H9: =LN(1E-030) -> -69.077553 | I9: =LN(H7) -> -2.9957323 | J9: =LN(1E-030) -> -69.077553 | K9: =LN(J7) -> -2.9957323 | L9: =LN(1E-030) -> -69.077553 | M9: =LN(L7) -> -2.9957323 | N9: =LN(1E-030) -> -69.077553 | O9: =LN(N7) -> -2.9957323 | P9: =LN(1E-030) -> -69.077553 | Q9: =LN(P7) -> -2.9957323 | R9: =LN(1E-030) -> -69.077553 | S9: =LN(R7) -> -2.9957323 | T9: =LN(1E-030) -> -69.077553 | U9: =LN(T7) -> -2.9957323 | V9: =LN(1E-030) -> -69.077553 | W9: =LN(V7) -> -2.9957323 | X9: =LN(1E-030) -> -69.077553 | Y9: =LN(X7) -> -2.9957323 | Z9: =LN(1E-030) -> -69.077553 | AA9: =LN(Z7) -> -2.9957323 | AB9: =AB7 -> 0.05 | AC9: =1-1E-015 -> 1 | AD9: =AD7 -> 0.05 | AE9: =1-1E-015 -> 1 | AF9: =AF7 -> 0.05 | AG9: =1-1E-015 -> 1 | AH9: =AH7 -> 0.05 | AI9: =1-1E-015 -> 1 | AJ9: =AJ7 -> 0.05 | AK9: =1-1E-015 -> 1 | AL9: =AL7 -> 0.05 | AM9: =1-1E-015 -> 1 | AN9: =AN7 -> 0.05 | AO9: =1-1E-015 -> 1 | AP9: =LN(1E-030) -> -69.077553 | AQ9: =LN(AP7) -> -2.9957323 | AR9: =AR7 -> 0.05 | AS9: =1-1E-015 -> 1
B10: =IF(B$7*LN(B$7)-B$7*((B9+C9)/2)+(1-B$7)*LN(1-B$7)-(1-B$7)*LN(1-EXP(((B9+C9)/2)))-B$6>0,((B9+C9)/2),B9) -> -36.036643 | C10: =IF(B$7*LN(B$7)-B$7*((B9+C9)/2)+(1-B$7)*LN(1-B$7)-(1-B$7)*LN(1-EXP(((B9+C9)/2)))-B$6>0,C9,((B9+C9)/2)) -> -2.9957323 | D10: =IF(D$7*LN(D$7)-D$7*((D9+E9)/2)+(1-D$7)*LN(1-D$7)-(1-D$7)*LN(1-EXP(((D9+E9)/2)))-D$6>0,((D9+E9)/2),D9) -> -36.036643 | E10: =IF(D$7*LN(D$7)-D$7*((D9+E9)/2)+(1-D$7)*LN(1-D$7)-(1-D$7)*LN(1-EXP(((D9+E9)/2)))-D$6>0,E9,((D9+E9)/2)) -> -2.9957323 | F10: =IF(F$7*LN(F$7)-F$7*((F9+G9)/2)+(1-F$7)*LN(1-F$7)-(1-F$7)*LN(1-EXP(((F9+G9)/2)))-F$6>0,((F9+G9)/2),F9) -> -36.036643 | G10: =IF(F$7*LN(F$7)-F$7*((F9+G9)/2)+(1-F$7)*LN(1-F$7)-(1-F$7)*LN(1-EXP(((F9+G9)/2)))-F$6>0,G9,((F9+G9)/2)) -> -2.9957323 | H10: =IF(H$7*LN(H$7)-H$7*((H9+I9)/2)+(1-H$7)*LN(1-H$7)-(1-H$7)*LN(1-EXP(((H9+I9)/2)))-H$6>0,((H9+I9)/2),H9) -> -36.036643 | I10: =IF(H$7*LN(H$7)-H$7*((H9+I9)/2)+(1-H$7)*LN(1-H$7)-(1-H$7)*LN(1-EXP(((H9+I9)/2)))-H$6>0,I9,((H9+I9)/2)) -> -2.9957323 | J10: =IF(J$7*LN(J$7)-J$7*((J9+K9)/2)+(1-J$7)*LN(1-J$7)-(1-J$7)*LN(1-EXP(((J9+K9)/2)))-J$6>0,((J9+K9)/2),J9) -> -36.036643 | K10: =IF(J$7*LN(J$7)-J$7*((J9+K9)/2)+(1-J$7)*LN(1-J$7)-(1-J$7)*LN(1-EXP(((J9+K9)/2)))-J$6>0,K9,((J9+K9)/2)) -> -2.9957323 | L10: =IF(L$7*LN(L$7)-L$7*((L9+M9)/2)+(1-L$7)*LN(1-L$7)-(1-L$7)*LN(1-EXP(((L9+M9)/2)))-L$6>0,((L9+M9)/2),L9) -> -36.036643 | M10: =IF(L$7*LN(L$7)-L$7*((L9+M9)/2)+(1-L$7)*LN(1-L$7)-(1-L$7)*LN(1-EXP(((L9+M9)/2)))-L$6>0,M9,((L9+M9)/2)) -> -2.9957323 | N10: =IF(N$7*LN(N$7)-N$7*((N9+O9)/2)+(1-N$7)*LN(1-N$7)-(1-N$7)*LN(1-EXP(((N9+O9)/2)))-N$6>0,((N9+O9)/2),N9) -> -36.036643 | O10: =IF(N$7*LN(N$7)-N$7*((N9+O9)/2)+(1-N$7)*LN(1-N$7)-(1-N$7)*LN(1-EXP(((N9+O9)/2)))-N$6>0,O9,((N9+O9)/2)) -> -2.9957323 | P10: =IF(P$7*LN(P$7)-P$7*((P9+Q9)/2)+(1-P$7)*LN(1-P$7)-(1-P$7)*LN(1-EXP(((P9+Q9)/2)))-P$6>0,((P9+Q9)/2),P9) -> -36.036643 | Q10: =IF(P$7*LN(P$7)-P$7*((P9+Q9)/2)+(1-P$7)*LN(1-P$7)-(1-P$7)*LN(1-EXP(((P9+Q9)/2)))-P$6>0,Q9,((P9+Q9)/2)) -> -2.9957323 | R10: =IF(R$7*LN(R$7)-R$7*((R9+S9)/2)+(1-R$7)*LN(1-R$7)-(1-R$7)*LN(1-EXP(((R9+S9)/2)))-R$6>0,((R9+S9)/2),R9) -> -36.036643 | S10: =IF(R$7*LN(R$7)-R$7*((R9+S9)/2)+(1-R$7)*LN(1-R$7)-(1-R$7)*LN(1-EXP(((R9+S9)/2)))-R$6>0,S9,((R9+S9)/2)) -> -2.9957323 | T10: =IF(T$7*LN(T$7)-T$7*((T9+U9)/2)+(1-T$7)*LN(1-T$7)-(1-T$7)*LN(1-EXP(((T9+U9)/2)))-T$6>0,((T9+U9)/2),T9) -> -36.036643 | U10: =IF(T$7*LN(T$7)-T$7*((T9+U9)/2)+(1-T$7)*LN(1-T$7)-(1-T$7)*LN(1-EXP(((T9+U9)/2)))-T$6>0,U9,((T9+U9)/2)) -> -2.9957323 | V10: =IF(V$7*LN(V$7)-V$7*((V9+W9)/2)+(1-V$7)*LN(1-V$7)-(1-V$7)*LN(1-EXP(((V9+W9)/2)))-V$6>0,((V9+W9)/2),V9) -> -36.036643 | W10: =IF(V$7*LN(V$7)-V$7*((V9+W9)/2)+(1-V$7)*LN(1-V$7)-(1-V$7)*LN(1-EXP(((V9+W9)/2)))-V$6>0,W9,((V9+W9)/2)) -> -2.9957323 | X10: =IF(X$7*LN(X$7)-X$7*((X9+Y9)/2)+(1-X$7)*LN(1-X$7)-(1-X$7)*LN(1-EXP(((X9+Y9)/2)))-X$6>0,((X9+Y9)/2),X9) -> -36.036643 | Y10: =IF(X$7*LN(X$7)-X$7*((X9+Y9)/2)+(1-X$7)*LN(1-X$7)-(1-X$7)*LN(1-EXP(((X9+Y9)/2)))-X$6>0,Y9,((X9+Y9)/2)) -> -2.9957323 | Z10: =IF(Z$7*LN(Z$7)-Z$7*((Z9+AA9)/2)+(1-Z$7)*LN(1-Z$7)-(1-Z$7)*LN(1-EXP(((Z9+AA9)/2)))-Z$6>0,((Z9+AA9)/2),Z9) -> -36.036643 | AA10: =IF(Z$7*LN(Z$7)-Z$7*((Z9+AA9)/2)+(1-Z$7)*LN(1-Z$7)-(1-Z$7)*LN(1-EXP(((Z9+AA9)/2)))-Z$6>0,AA9,((Z9+AA9)/2)) -> -2.9957323 | AB10: =IF((((AB9+AC9)/2))*LN((((AB9+AC9)/2))/(AB$7))+(1-(((AB9+AC9)/2)))*LN((1-(((AB9+AC9)/2)))/(1-(AB$7)))-AB$6<0,((AB9+AC9)/2),AB9) -> 0.05 | AC10: =IF((((AB9+AC9)/2))*LN((((AB9+AC9)/2))/(AB$7))+(1-(((AB9+AC9)/2)))*LN((1-(((AB9+AC9)/2)))/(1-(AB$7)))-AB$6<0,AC9,((AB9+AC9)/2)) -> 0.525 | AD10: =IF((((AD9+AE9)/2))*LN((((AD9+AE9)/2))/(AD$7))+(1-(((AD9+AE9)/2)))*LN((1-(((AD9+AE9)/2)))/(1-(AD$7)))-AD$6<0,((AD9+AE9)/2),AD9) -> 0.05 | AE10: =IF((((AD9+AE9)/2))*LN((((AD9+AE9)/2))/(AD$7))+(1-(((AD9+AE9)/2)))*LN((1-(((AD9+AE9)/2)))/(1-(AD$7)))-AD$6<0,AE9,((AD9+AE9)/2)) -> 0.525 | AF10: =IF((((AF9+AG9)/2))*LN((((AF9+AG9)/2))/(AF$7))+(1-(((AF9+AG9)/2)))*LN((1-(((AF9+AG9)/2)))/(1-(AF$7)))-AF$6<0,((AF9+AG9)/2),AF9) -> 0.05 | AG10: =IF((((AF9+AG9)/2))*LN((((AF9+AG9)/2))/(AF$7))+(1-(((AF9+AG9)/2)))*LN((1-(((AF9+AG9)/2)))/(1-(AF$7)))-AF$6<0,AG9,((AF9+AG9)/2)) -> 0.525 | AH10: =IF((((AH9+AI9)/2))*LN((((AH9+AI9)/2))/(AH$7))+(1-(((AH9+AI9)/2)))*LN((1-(((AH9+AI9)/2)))/(1-(AH$7)))-AH$6<0,((AH9+AI9)/2),AH9) -> 0.05 | AI10: =IF((((AH9+AI9)/2))*LN((((AH9+AI9)/2))/(AH$7))+(1-(((AH9+AI9)/2)))*LN((1-(((AH9+AI9)/2)))/(1-(AH$7)))-AH$6<0,AI9,((AH9+AI9)/2)) -> 0.525 | AJ10: =IF((((AJ9+AK9)/2))*LN((((AJ9+AK9)/2))/(AJ$7))+(1-(((AJ9+AK9)/2)))*LN((1-(((AJ9+AK9)/2)))/(1-(AJ$7)))-AJ$6<0,((AJ9+AK9)/2),AJ9) -> 0.05 | AK10: =IF((((AJ9+AK9)/2))*LN((((AJ9+AK9)/2))/(AJ$7))+(1-(((AJ9+AK9)/2)))*LN((1-(((AJ9+AK9)/2)))/(1-(AJ$7)))-AJ$6<0,AK9,((AJ9+AK9)/2)) -> 0.525 | AL10: =IF((((AL9+AM9)/2))*LN((((AL9+AM9)/2))/(AL$7))+(1-(((AL9+AM9)/2)))*LN((1-(((AL9+AM9)/2)))/(1-(AL$7)))-AL$6<0,((AL9+AM9)/2),AL9) -> 0.05 | AM10: =IF((((AL9+AM9)/2))*LN((((AL9+AM9)/2))/(AL$7))+(1-(((AL9+AM9)/2)))*LN((1-(((AL9+AM9)/2)))/(1-(AL$7)))-AL$6<0,AM9,((AL9+AM9)/2)) -> 0.525 | AN10: =IF((((AN9+AO9)/2))*LN((((AN9+AO9)/2))/(AN$7))+(1-(((AN9+AO9)/2)))*LN((1-(((AN9+AO9)/2)))/(1-(AN$7)))-AN$6<0,((AN9+AO9)/2),AN9) -> 0.525 | AO10: =IF((((AN9+AO9)/2))*LN((((AN9+AO9)/2))/(AN$7))+(1-(((AN9+AO9)/2)))*LN((1-(((AN9+AO9)/2)))/(1-(AN$7)))-AN$6<0,AO9,((AN9+AO9)/2)) -> 1 | AP10: =IF(AP$7*LN(AP$7)-AP$7*((AP9+AQ9)/2)+(1-AP$7)*LN(1-AP$7)-(1-AP$7)*LN(1-EXP(((AP9+AQ9)/2)))-AP$6>0,((AP9+AQ9)/2),AP9) -> -36.036643 | AQ10: =IF(AP$7*LN(AP$7)-AP$7*((AP9+AQ9)/2)+(1-AP$7)*LN(1-AP$7)-(1-AP$7)*LN(1-EXP(((AP9+AQ9)/2)))-AP$6>0,AQ9,((AP9+AQ9)/2)) -> -2.9957323 | AR10: =IF((((AR9+AS9)/2))*LN((((AR9+AS9)/2))/(AR$7))+(1-(((AR9+AS9)/2)))*LN((1-(((AR9+AS9)/2)))/(1-(AR$7)))-AR$6<0,((AR9+AS9)/2),AR9) -> 0.05 | AS10: =IF((((AR9+AS9)/2))*LN((((AR9+AS9)/2))/(AR$7))+(1-(((AR9+AS9)/2)))*LN((1-(((AR9+AS9)/2)))/(1-(AR$7)))-AR$6<0,AS9,((AR9+AS9)/2)) -> 0.525
B11: =IF(B$7*LN(B$7)-B$7*((B10+C10)/2)+(1-B$7)*LN(1-B$7)-(1-B$7)*LN(1-EXP(((B10+C10)/2)))-B$6>0,((B10+C10)/2),B10) -> -19.516187 | C11: =IF(B$7*LN(B$7)-B$7*((B10+C10)/2)+(1-B$7)*LN(1-B$7)-(1-B$7)*LN(1-EXP(((B10+C10)/2)))-B$6>0,C10,((B10+C10)/2)) -> -2.9957323 | D11: =IF(D$7*LN(D$7)-D$7*((D10+E10)/2)+(1-D$7)*LN(1-D$7)-(1-D$7)*LN(1-EXP(((D10+E10)/2)))-D$6>0,((D10+E10)/2),D10) -> -19.516187 | E11: =IF(D$7*LN(D$7)-D$7*((D10+E10)/2)+(1-D$7)*LN(1-D$7)-(1-D$7)*LN(1-EXP(((D10+E10)/2)))-D$6>0,E10,((D10+E10)/2)) -> -2.9957323 | F11: =IF(F$7*LN(F$7)-F$7*((F10+G10)/2)+(1-F$7)*LN(1-F$7)-(1-F$7)*LN(1-EXP(((F10+G10)/2)))-F$6>0,((F10+G10)/2),F10) -> -36.036643 | G11: =IF(F$7*LN(F$7)-F$7*((F10+G10)/2)+(1-F$7)*LN(1-F$7)-(1-F$7)*LN(1-EXP(((F10+G10)/2)))-F$6>0,G10,((F10+G10)/2)) -> -19.516187 | H11: =IF(H$7*LN(H$7)-H$7*((H10+I10)/2)+(1-H$7)*LN(1-H$7)-(1-H$7)*LN(1-EXP(((H10+I10)/2)))-H$6>0,((H10+I10)/2),H10) -> -19.516187 | I11: =IF(H$7*LN(H$7)-H$7*((H10+I10)/2)+(1-H$7)*LN(1-H$7)-(1-H$7)*LN(1-EXP(((H10+I10)/2)))-H$6>0,I10,((H10+I10)/2)) -> -2.9957323 | J11: =IF(J$7*LN(J$7)-J$7*((J10+K10)/2)+(1-J$7)*LN(1-J$7)-(1-J$7)*LN(1-EXP(((J10+K10)/2)))-J$6>0,((J10+K10)/2),J10) -> -19.516187 | K11: =IF(J$7*LN(J$7)-J$7*((J10+K10)/2)+(1-J$7)*LN(1-J$7)-(1-J$7)*LN(1-EXP(((J10+K10)/2)))-J$6>0,K10,((J10+K10)/2)) -> -2.9957323 | L11: =IF(L$7*LN(L$7)-L$7*((L10+M10)/2)+(1-L$7)*LN(1-L$7)-(1-L$7)*LN(1-EXP(((L10+M10)/2)))-L$6>0,((L10+M10)/2),L10) -> -19.516187 | M11: =IF(L$7*LN(L$7)-L$7*((L10+M10)/2)+(1-L$7)*LN(1-L$7)-(1-L$7)*LN(1-EXP(((L10+M10)/2)))-L$6>0,M10,((L10+M10)/2)) -> -2.9957323 | N11: =IF(N$7*LN(N$7)-N$7*((N10+O10)/2)+(1-N$7)*LN(1-N$7)-(1-N$7)*LN(1-EXP(((N10+O10)/2)))-N$6>0,((N10+O10)/2),N10) -> -19.516187 | O11: =IF(N$7*LN(N$7)-N$7*((N10+O10)/2)+(1-N$7)*LN(1-N$7)-(1-N$7)*LN(1-EXP(((N10+O10)/2)))-N$6>0,O10,((N10+O10)/2)) -> -2.9957323 | P11: =IF(P$7*LN(P$7)-P$7*((P10+Q10)/2)+(1-P$7)*LN(1-P$7)-(1-P$7)*LN(1-EXP(((P10+Q10)/2)))-P$6>0,((P10+Q10)/2),P10) -> -19.516187 | Q11: =IF(P$7*LN(P$7)-P$7*((P10+Q10)/2)+(1-P$7)*LN(1-P$7)-(1-P$7)*LN(1-EXP(((P10+Q10)/2)))-P$6>0,Q10,((P10+Q10)/2)) -> -2.9957323 | R11: =IF(R$7*LN(R$7)-R$7*((R10+S10)/2)+(1-R$7)*LN(1-R$7)-(1-R$7)*LN(1-EXP(((R10+S10)/2)))-R$6>0,((R10+S10)/2),R10) -> -19.516187 | S11: =IF(R$7*LN(R$7)-R$7*((R10+S10)/2)+(1-R$7)*LN(1-R$7)-(1-R$7)*LN(1-EXP(((R10+S10)/2)))-R$6>0,S10,((R10+S10)/2)) -> -2.9957323 | T11: =IF(T$7*LN(T$7)-T$7*((T10+U10)/2)+(1-T$7)*LN(1-T$7)-(1-T$7)*LN(1-EXP(((T10+U10)/2)))-T$6>0,((T10+U10)/2),T10) -> -19.516187 | U11: =IF(T$7*LN(T$7)-T$7*((T10+U10)/2)+(1-T$7)*LN(1-T$7)-(1-T$7)*LN(1-EXP(((T10+U10)/2)))-T$6>0,U10,((T10+U10)/2)) -> -2.9957323 | V11: =IF(V$7*LN(V$7)-V$7*((V10+W10)/2)+(1-V$7)*LN(1-V$7)-(1-V$7)*LN(1-EXP(((V10+W10)/2)))-V$6>0,((V10+W10)/2),V10) -> -19.516187 | W11: =IF(V$7*LN(V$7)-V$7*((V10+W10)/2)+(1-V$7)*LN(1-V$7)-(1-V$7)*LN(1-EXP(((V10+W10)/2)))-V$6>0,W10,((V10+W10)/2)) -> -2.9957323 | X11: =IF(X$7*LN(X$7)-X$7*((X10+Y10)/2)+(1-X$7)*LN(1-X$7)-(1-X$7)*LN(1-EXP(((X10+Y10)/2)))-X$6>0,((X10+Y10)/2),X10) -> -19.516187 | Y11: =IF(X$7*LN(X$7)-X$7*((X10+Y10)/2)+(1-X$7)*LN(1-X$7)-(1-X$7)*LN(1-EXP(((X10+Y10)/2)))-X$6>0,Y10,((X10+Y10)/2)) -> -2.9957323 | Z11: =IF(Z$7*LN(Z$7)-Z$7*((Z10+AA10)/2)+(1-Z$7)*LN(1-Z$7)-(1-Z$7)*LN(1-EXP(((Z10+AA10)/2)))-Z$6>0,((Z10+AA10)/2),Z10) -> -19.516187 | AA11: =IF(Z$7*LN(Z$7)-Z$7*((Z10+AA10)/2)+(1-Z$7)*LN(1-Z$7)-(1-Z$7)*LN(1-EXP(((Z10+AA10)/2)))-Z$6>0,AA10,((Z10+AA10)/2)) -> -2.9957323 | AB11: =IF((((AB10+AC10)/2))*LN((((AB10+AC10)/2))/(AB$7))+(1-(((AB10+AC10)/2)))*LN((1-(((AB10+AC10)/2)))/(1-(AB$7)))-AB$6<0,((AB10+AC10)/2),AB10) -> 0.05 | AC11: =IF((((AB10+AC10)/2))*LN((((AB10+AC10)/2))/(AB$7))+(1-(((AB10+AC10)/2)))*LN((1-(((AB10+AC10)/2)))/(1-(AB$7)))-AB$6<0,AC10,((AB10+AC10)/2)) -> 0.2875 | AD11: =IF((((AD10+AE10)/2))*LN((((AD10+AE10)/2))/(AD$7))+(1-(((AD10+AE10)/2)))*LN((1-(((AD10+AE10)/2)))/(1-(AD$7)))-AD$6<0,((AD10+AE10)/2),AD10) -> 0.05 | AE11: =IF((((AD10+AE10)/2))*LN((((AD10+AE10)/2))/(AD$7))+(1-(((AD10+AE10)/2)))*LN((1-(((AD10+AE10)/2)))/(1-(AD$7)))-AD$6<0,AE10,((AD10+AE10)/2)) -> 0.2875 | AF11: =IF((((AF10+AG10)/2))*LN((((AF10+AG10)/2))/(AF$7))+(1-(((AF10+AG10)/2)))*LN((1-(((AF10+AG10)/2)))/(1-(AF$7)))-AF$6<0,((AF10+AG10)/2),AF10) -> 0.05 | AG11: =IF((((AF10+AG10)/2))*LN((((AF10+AG10)/2))/(AF$7))+(1-(((AF10+AG10)/2)))*LN((1-(((AF10+AG10)/2)))/(1-(AF$7)))-AF$6<0,AG10,((AF10+AG10)/2)) -> 0.2875 | AH11: =IF((((AH10+AI10)/2))*LN((((AH10+AI10)/2))/(AH$7))+(1-(((AH10+AI10)/2)))*LN((1-(((AH10+AI10)/2)))/(1-(AH$7)))-AH$6<0,((AH10+AI10)/2),AH10) -> 0.05 | AI11: =IF((((AH10+AI10)/2))*LN((((AH10+AI10)/2))/(AH$7))+(1-(((AH10+AI10)/2)))*LN((1-(((AH10+AI10)/2)))/(1-(AH$7)))-AH$6<0,AI10,((AH10+AI10)/2)) -> 0.2875 | AJ11: =IF((((AJ10+AK10)/2))*LN((((AJ10+AK10)/2))/(AJ$7))+(1-(((AJ10+AK10)/2)))*LN((1-(((AJ10+AK10)/2)))/(1-(AJ$7)))-AJ$6<0,((AJ10+AK10)/2),AJ10) -> 0.05 | AK11: =IF((((AJ10+AK10)/2))*LN((((AJ10+AK10)/2))/(AJ$7))+(1-(((AJ10+AK10)/2)))*LN((1-(((AJ10+AK10)/2)))/(1-(AJ$7)))-AJ$6<0,AK10,((AJ10+AK10)/2)) -> 0.2875 | AL11: =IF((((AL10+AM10)/2))*LN((((AL10+AM10)/2))/(AL$7))+(1-(((AL10+AM10)/2)))*LN((1-(((AL10+AM10)/2)))/(1-(AL$7)))-AL$6<0,((AL10+AM10)/2),AL10) -> 0.2875 | AM11: =IF((((AL10+AM10)/2))*LN((((AL10+AM10)/2))/(AL$7))+(1-(((AL10+AM10)/2)))*LN((1-(((AL10+AM10)/2)))/(1-(AL$7)))-AL$6<0,AM10,((AL10+AM10)/2)) -> 0.525 | AN11: =IF((((AN10+AO10)/2))*LN((((AN10+AO10)/2))/(AN$7))+(1-(((AN10+AO10)/2)))*LN((1-(((AN10+AO10)/2)))/(1-(AN$7)))-AN$6<0,((AN10+AO10)/2),AN10) -> 0.525 | AO11: =IF((((AN10+AO10)/2))*LN((((AN10+AO10)/2))/(AN$7))+(1-(((AN10+AO10)/2)))*LN((1-(((AN10+AO10)/2)))/(1-(AN$7)))-AN$6<0,AO10,((AN10+AO10)/2)) -> 0.7625 | AP11: =IF(AP$7*LN(AP$7)-AP$7*((AP10+AQ10)/2)+(1-AP$7)*LN(1-AP$7)-(1-AP$7)*LN(1-EXP(((AP10+AQ10)/2)))-AP$6>0,((AP10+AQ10)/2),AP10) -> -19.516187 | AQ11: =IF(AP$7*LN(AP$7)-AP$7*((AP10+AQ10)/2)+(1-AP$7)*LN(1-AP$7)-(1-AP$7)*LN(1-EXP(((AP10+AQ10)/2)))-AP$6>0,AQ10,((AP10+AQ10)/2)) -> -2.9957323 | AR11: =IF((((AR10+AS10)/2))*LN((((AR10+AS10)/2))/(AR$7))+(1-(((AR10+AS10)/2)))*LN((1-(((AR10+AS10)/2)))/(1-(AR$7)))-AR$6<0,((AR10+AS10)/2),AR10) -> 0.05 | AS11: =IF((((AR10+AS10)/2))*LN((((AR10+AS10)/2))/(AR$7))+(1-(((AR10+AS10)/2)))*LN((1-(((AR10+AS10)/2)))/(1-(AR$7)))-AR$6<0,AS10,((AR10+AS10)/2)) -> 0.2875
B12: =IF(B$7*LN(B$7)-B$7*((B11+C11)/2)+(1-B$7)*LN(1-B$7)-(1-B$7)*LN(1-EXP(((B11+C11)/2)))-B$6>0,((B11+C11)/2),B11) -> -19.516187 | C12: =IF(B$7*LN(B$7)-B$7*((B11+C11)/2)+(1-B$7)*LN(1-B$7)-(1-B$7)*LN(1-EXP(((B11+C11)/2)))-B$6>0,C11,((B11+C11)/2)) -> -11.25596 | D12: =IF(D$7*LN(D$7)-D$7*((D11+E11)/2)+(1-D$7)*LN(1-D$7)-(1-D$7)*LN(1-EXP(((D11+E11)/2)))-D$6>0,((D11+E11)/2),D11) -> -19.516187 | E12: =IF(D$7*LN(D$7)-D$7*((D11+E11)/2)+(1-D$7)*LN(1-D$7)-(1-D$7)*LN(1-EXP(((D11+E11)/2)))-D$6>0,E11,((D11+E11)/2)) -> -11.25596 | F12: =IF(F$7*LN(F$7)-F$7*((F11+G11)/2)+(1-F$7)*LN(1-F$7)-(1-F$7)*LN(1-EXP(((F11+G11)/2)))-F$6>0,((F11+G11)/2),F11) -> -27.776415 | G12: =IF(F$7*LN(F$7)-F$7*((F11+G11)/2)+(1-F$7)*LN(1-F$7)-(1-F$7)*LN(1-EXP(((F11+G11)/2)))-F$6>0,G11,((F11+G11)/2)) -> -19.516187 | H12: =IF(H$7*LN(H$7)-H$7*((H11+I11)/2)+(1-H$7)*LN(1-H$7)-(1-H$7)*LN(1-EXP(((H11+I11)/2)))-H$6>0,((H11+I11)/2),H11) -> -11.25596 | I12: =IF(H$7*LN(H$7)-H$7*((H11+I11)/2)+(1-H$7)*LN(1-H$7)-(1-H$7)*LN(1-EXP(((H11+I11)/2)))-H$6>0,I11,((H11+I11)/2)) -> -2.9957323 | J12: =IF(J$7*LN(J$7)-J$7*((J11+K11)/2)+(1-J$7)*LN(1-J$7)-(1-J$7)*LN(1-EXP(((J11+K11)/2)))-J$6>0,((J11+K11)/2),J11) -> -11.25596 | K12: =IF(J$7*LN(J$7)-J$7*((J11+K11)/2)+(1-J$7)*LN(1-J$7)-(1-J$7)*LN(1-EXP(((J11+K11)/2)))-J$6>0,K11,((J11+K11)/2)) -> -2.9957323 | L12: =IF(L$7*LN(L$7)-L$7*((L11+M11)/2)+(1-L$7)*LN(1-L$7)-(1-L$7)*LN(1-EXP(((L11+M11)/2)))-L$6>0,((L11+M11)/2),L11) -> -11.25596 | M12: =IF(L$7*LN(L$7)-L$7*((L11+M11)/2)+(1-L$7)*LN(1-L$7)-(1-L$7)*LN(1-EXP(((L11+M11)/2)))-L$6>0,M11,((L11+M11)/2)) -> -2.9957323 | N12: =IF(N$7*LN(N$7)-N$7*((N11+O11)/2)+(1-N$7)*LN(1-N$7)-(1-N$7)*LN(1-EXP(((N11+O11)/2)))-N$6>0,((N11+O11)/2),N11) -> -11.25596 | O12: =IF(N$7*LN(N$7)-N$7*((N11+O11)/2)+(1-N$7)*LN(1-N$7)-(1-N$7)*LN(1-EXP(((N11+O11)/2)))-N$6>0,O11,((N11+O11)/2)) -> -2.9957323 | P12: =IF(P$7*LN(P$7)-P$7*((P11+Q11)/2)+(1-P$7)*LN(1-P$7)-(1-P$7)*LN(1-EXP(((P11+Q11)/2)))-P$6>0,((P11+Q11)/2),P11) -> -11.25596 | Q12: =IF(P$7*LN(P$7)-P$7*((P11+Q11)/2)+(1-P$7)*LN(1-P$7)-(1-P$7)*LN(1-EXP(((P11+Q11)/2)))-P$6>0,Q11,((P11+Q11)/2)) -> -2.9957323 | R12: =IF(R$7*LN(R$7)-R$7*((R11+S11)/2)+(1-R$7)*LN(1-R$7)-(1-R$7)*LN(1-EXP(((R11+S11)/2)))-R$6>0,((R11+S11)/2),R11) -> -11.25596 | S12: =IF(R$7*LN(R$7)-R$7*((R11+S11)/2)+(1-R$7)*LN(1-R$7)-(1-R$7)*LN(1-EXP(((R11+S11)/2)))-R$6>0,S11,((R11+S11)/2)) -> -2.9957323 | T12: =IF(T$7*LN(T$7)-T$7*((T11+U11)/2)+(1-T$7)*LN(1-T$7)-(1-T$7)*LN(1-EXP(((T11+U11)/2)))-T$6>0,((T11+U11)/2),T11) -> -11.25596 | U12: =IF(T$7*LN(T$7)-T$7*((T11+U11)/2)+(1-T$7)*LN(1-T$7)-(1-T$7)*LN(1-EXP(((T11+U11)/2)))-T$6>0,U11,((T11+U11)/2)) -> -2.9957323 | V12: =IF(V$7*LN(V$7)-V$7*((V11+W11)/2)+(1-V$7)*LN(1-V$7)-(1-V$7)*LN(1-EXP(((V11+W11)/2)))-V$6>0,((V11+W11)/2),V11) -> -11.25596 | W12: =IF(V$7*LN(V$7)-V$7*((V11+W11)/2)+(1-V$7)*LN(1-V$7)-(1-V$7)*LN(1-EXP(((V11+W11)/2)))-V$6>0,W11,((V11+W11)/2)) -> -2.9957323 | X12: =IF(X$7*LN(X$7)-X$7*((X11+Y11)/2)+(1-X$7)*LN(1-X$7)-(1-X$7)*LN(1-EXP(((X11+Y11)/2)))-X$6>0,((X11+Y11)/2),X11) -> -11.25596 | Y12: =IF(X$7*LN(X$7)-X$7*((X11+Y11)/2)+(1-X$7)*LN(1-X$7)-(1-X$7)*LN(1-EXP(((X11+Y11)/2)))-X$6>0,Y11,((X11+Y11)/2)) -> -2.9957323 | Z12: =IF(Z$7*LN(Z$7)-Z$7*((Z11+AA11)/2)+(1-Z$7)*LN(1-Z$7)-(1-Z$7)*LN(1-EXP(((Z11+AA11)/2)))-Z$6>0,((Z11+AA11)/2),Z11) -> -11.25596 | AA12: =IF(Z$7*LN(Z$7)-Z$7*((Z11+AA11)/2)+(1-Z$7)*LN(1-Z$7)-(1-Z$7)*LN(1-EXP(((Z11+AA11)/2)))-Z$6>0,AA11,((Z11+AA11)/2)) -> -2.9957323 | AB12: =IF((((AB11+AC11)/2))*LN((((AB11+AC11)/2))/(AB$7))+(1-(((AB11+AC11)/2)))*LN((1-(((AB11+AC11)/2)))/(1-(AB$7)))-AB$6<0,((AB11+AC11)/2),AB11) -> 0.05 | AC12: =IF((((AB11+AC11)/2))*LN((((AB11+AC11)/2))/(AB$7))+(1-(((AB11+AC11)/2)))*LN((1-(((AB11+AC11)/2)))/(1-(AB$7)))-AB$6<0,AC11,((AB11+AC11)/2)) -> 0.16875 | AD12: =IF((((AD11+AE11)/2))*LN((((AD11+AE11)/2))/(AD$7))+(1-(((AD11+AE11)/2)))*LN((1-(((AD11+AE11)/2)))/(1-(AD$7)))-AD$6<0,((AD11+AE11)/2),AD11) -> 0.05 | AE12: =IF((((AD11+AE11)/2))*LN((((AD11+AE11)/2))/(AD$7))+(1-(((AD11+AE11)/2)))*LN((1-(((AD11+AE11)/2)))/(1-(AD$7)))-AD$6<0,AE11,((AD11+AE11)/2)) -> 0.16875 | AF12: =IF((((AF11+AG11)/2))*LN((((AF11+AG11)/2))/(AF$7))+(1-(((AF11+AG11)/2)))*LN((1-(((AF11+AG11)/2)))/(1-(AF$7)))-AF$6<0,((AF11+AG11)/2),AF11) -> 0.05 | AG12: =IF((((AF11+AG11)/2))*LN((((AF11+AG11)/2))/(AF$7))+(1-(((AF11+AG11)/2)))*LN((1-(((AF11+AG11)/2)))/(1-(AF$7)))-AF$6<0,AG11,((AF11+AG11)/2)) -> 0.16875 | AH12: =IF((((AH11+AI11)/2))*LN((((AH11+AI11)/2))/(AH$7))+(1-(((AH11+AI11)/2)))*LN((1-(((AH11+AI11)/2)))/(1-(AH$7)))-AH$6<0,((AH11+AI11)/2),AH11) -> 0.05 | AI12: =IF((((AH11+AI11)/2))*LN((((AH11+AI11)/2))/(AH$7))+(1-(((AH11+AI11)/2)))*LN((1-(((AH11+AI11)/2)))/(1-(AH$7)))-AH$6<0,AI11,((AH11+AI11)/2)) -> 0.16875 | AJ12: =IF((((AJ11+AK11)/2))*LN((((AJ11+AK11)/2))/(AJ$7))+(1-(((AJ11+AK11)/2)))*LN((1-(((AJ11+AK11)/2)))/(1-(AJ$7)))-AJ$6<0,((AJ11+AK11)/2),AJ11) -> 0.16875 | AK12: =IF((((AJ11+AK11)/2))*LN((((AJ11+AK11)/2))/(AJ$7))+(1-(((AJ11+AK11)/2)))*LN((1-(((AJ11+AK11)/2)))/(1-(AJ$7)))-AJ$6<0,AK11,((AJ11+AK11)/2)) -> 0.2875 | AL12: =IF((((AL11+AM11)/2))*LN((((AL11+AM11)/2))/(AL$7))+(1-(((AL11+AM11)/2)))*LN((1-(((AL11+AM11)/2)))/(1-(AL$7)))-AL$6<0,((AL11+AM11)/2),AL11) -> 0.2875 | AM12: =IF((((AL11+AM11)/2))*LN((((AL11+AM11)/2))/(AL$7))+(1-(((AL11+AM11)/2)))*LN((1-(((AL11+AM11)/2)))/(1-(AL$7)))-AL$6<0,AM11,((AL11+AM11)/2)) -> 0.40625 | AN12: =IF((((AN11+AO11)/2))*LN((((AN11+AO11)/2))/(AN$7))+(1-(((AN11+AO11)/2)))*LN((1-(((AN11+AO11)/2)))/(1-(AN$7)))-AN$6<0,((AN11+AO11)/2),AN11) -> 0.525 | AO12: =IF((((AN11+AO11)/2))*LN((((AN11+AO11)/2))/(AN$7))+(1-(((AN11+AO11)/2)))*LN((1-(((AN11+AO11)/2)))/(1-(AN$7)))-AN$6<0,AO11,((AN11+AO11)/2)) -> 0.64375 | AP12: =IF(AP$7*LN(AP$7)-AP$7*((AP11+AQ11)/2)+(1-AP$7)*LN(1-AP$7)-(1-AP$7)*LN(1-EXP(((AP11+AQ11)/2)))-AP$6>0,((AP11+AQ11)/2),AP11) -> -11.25596 | AQ12: =IF(AP$7*LN(AP$7)-AP$7*((AP11+AQ11)/2)+(1-AP$7)*LN(1-AP$7)-(1-AP$7)*LN(1-EXP(((AP11+AQ11)/2)))-AP$6>0,AQ11,((AP11+AQ11)/2)) -> -2.9957323 | AR12: =IF((((AR11+AS11)/2))*LN((((AR11+AS11)/2))/(AR$7))+(1-(((AR11+AS11)/2)))*LN((1-(((AR11+AS11)/2)))/(1-(AR$7)))-AR$6<0,((AR11+AS11)/2),AR11) -> 0.05 | AS12: =IF((((AR11+AS11)/2))*LN((((AR11+AS11)/2))/(AR$7))+(1-(((AR11+AS11)/2)))*LN((1-(((AR11+AS11)/2)))/(1-(AR$7)))-AR$6<0,AS11,((AR11+AS11)/2)) -> 0.16875
B13: =IF(B$7*LN(B$7)-B$7*((B12+C12)/2)+(1-B$7)*LN(1-B$7)-(1-B$7)*LN(1-EXP(((B12+C12)/2)))-B$6>0,((B12+C12)/2),B12) -> -15.386074 | C13: =IF(B$7*LN(B$7)-B$7*((B12+C12)/2)+(1-B$7)*LN(1-B$7)-(1-B$7)*LN(1-EXP(((B12+C12)/2)))-B$6>0,C12,((B12+C12)/2)) -> -11.25596 | D13: =IF(D$7*LN(D$7)-D$7*((D12+E12)/2)+(1-D$7)*LN(1-D$7)-(1-D$7)*LN(1-EXP(((D12+E12)/2)))-D$6>0,((D12+E12)/2),D12) -> -19.516187 | E13: =IF(D$7*LN(D$7)-D$7*((D12+E12)/2)+(1-D$7)*LN(1-D$7)-(1-D$7)*LN(1-EXP(((D12+E12)/2)))-D$6>0,E12,((D12+E12)/2)) -> -15.386074 | F13: =IF(F$7*LN(F$7)-F$7*((F12+G12)/2)+(1-F$7)*LN(1-F$7)-(1-F$7)*LN(1-EXP(((F12+G12)/2)))-F$6>0,((F12+G12)/2),F12) -> -27.776415 | G13: =IF(F$7*LN(F$7)-F$7*((F12+G12)/2)+(1-F$7)*LN(1-F$7)-(1-F$7)*LN(1-EXP(((F12+G12)/2)))-F$6>0,G12,((F12+G12)/2)) -> -23.646301 | H13: =IF(H$7*LN(H$7)-H$7*((H12+I12)/2)+(1-H$7)*LN(1-H$7)-(1-H$7)*LN(1-EXP(((H12+I12)/2)))-H$6>0,((H12+I12)/2),H12) -> -7.1258461 | I13: =IF(H$7*LN(H$7)-H$7*((H12+I12)/2)+(1-H$7)*LN(1-H$7)-(1-H$7)*LN(1-EXP(((H12+I12)/2)))-H$6>0,I12,((H12+I12)/2)) -> -2.9957323 | J13: =IF(J$7*LN(J$7)-J$7*((J12+K12)/2)+(1-J$7)*LN(1-J$7)-(1-J$7)*LN(1-EXP(((J12+K12)/2)))-J$6>0,((J12+K12)/2),J12) -> -7.1258461 | K13: =IF(J$7*LN(J$7)-J$7*((J12+K12)/2)+(1-J$7)*LN(1-J$7)-(1-J$7)*LN(1-EXP(((J12+K12)/2)))-J$6>0,K12,((J12+K12)/2)) -> -2.9957323 | L13: =IF(L$7*LN(L$7)-L$7*((L12+M12)/2)+(1-L$7)*LN(1-L$7)-(1-L$7)*LN(1-EXP(((L12+M12)/2)))-L$6>0,((L12+M12)/2),L12) -> -7.1258461 | M13: =IF(L$7*LN(L$7)-L$7*((L12+M12)/2)+(1-L$7)*LN(1-L$7)-(1-L$7)*LN(1-EXP(((L12+M12)/2)))-L$6>0,M12,((L12+M12)/2)) -> -2.9957323 | N13: =IF(N$7*LN(N$7)-N$7*((N12+O12)/2)+(1-N$7)*LN(1-N$7)-(1-N$7)*LN(1-EXP(((N12+O12)/2)))-N$6>0,((N12+O12)/2),N12) -> -7.1258461 | O13: =IF(N$7*LN(N$7)-N$7*((N12+O12)/2)+(1-N$7)*LN(1-N$7)-(1-N$7)*LN(1-EXP(((N12+O12)/2)))-N$6>0,O12,((N12+O12)/2)) -> -2.9957323 | P13: =IF(P$7*LN(P$7)-P$7*((P12+Q12)/2)+(1-P$7)*LN(1-P$7)-(1-P$7)*LN(1-EXP(((P12+Q12)/2)))-P$6>0,((P12+Q12)/2),P12) -> -7.1258461 | Q13: =IF(P$7*LN(P$7)-P$7*((P12+Q12)/2)+(1-P$7)*LN(1-P$7)-(1-P$7)*LN(1-EXP(((P12+Q12)/2)))-P$6>0,Q12,((P12+Q12)/2)) -> -2.9957323 | R13: =IF(R$7*LN(R$7)-R$7*((R12+S12)/2)+(1-R$7)*LN(1-R$7)-(1-R$7)*LN(1-EXP(((R12+S12)/2)))-R$6>0,((R12+S12)/2),R12) -> -7.1258461 | S13: =IF(R$7*LN(R$7)-R$7*((R12+S12)/2)+(1-R$7)*LN(1-R$7)-(1-R$7)*LN(1-EXP(((R12+S12)/2)))-R$6>0,S12,((R12+S12)/2)) -> -2.9957323 | T13: =IF(T$7*LN(T$7)-T$7*((T12+U12)/2)+(1-T$7)*LN(1-T$7)-(1-T$7)*LN(1-EXP(((T12+U12)/2)))-T$6>0,((T12+U12)/2),T12) -> -7.1258461 | U13: =IF(T$7*LN(T$7)-T$7*((T12+U12)/2)+(1-T$7)*LN(1-T$7)-(1-T$7)*LN(1-EXP(((T12+U12)/2)))-T$6>0,U12,((T12+U12)/2)) -> -2.9957323 | V13: =IF(V$7*LN(V$7)-V$7*((V12+W12)/2)+(1-V$7)*LN(1-V$7)-(1-V$7)*LN(1-EXP(((V12+W12)/2)))-V$6>0,((V12+W12)/2),V12) -> -7.1258461 | W13: =IF(V$7*LN(V$7)-V$7*((V12+W12)/2)+(1-V$7)*LN(1-V$7)-(1-V$7)*LN(1-EXP(((V12+W12)/2)))-V$6>0,W12,((V12+W12)/2)) -> -2.9957323 | X13: =IF(X$7*LN(X$7)-X$7*((X12+Y12)/2)+(1-X$7)*LN(1-X$7)-(1-X$7)*LN(1-EXP(((X12+Y12)/2)))-X$6>0,((X12+Y12)/2),X12) -> -7.1258461 | Y13: =IF(X$7*LN(X$7)-X$7*((X12+Y12)/2)+(1-X$7)*LN(1-X$7)-(1-X$7)*LN(1-EXP(((X12+Y12)/2)))-X$6>0,Y12,((X12+Y12)/2)) -> -2.9957323 | Z13: =IF(Z$7*LN(Z$7)-Z$7*((Z12+AA12)/2)+(1-Z$7)*LN(1-Z$7)-(1-Z$7)*LN(1-EXP(((Z12+AA12)/2)))-Z$6>0,((Z12+AA12)/2),Z12) -> -7.1258461 | AA13: =IF(Z$7*LN(Z$7)-Z$7*((Z12+AA12)/2)+(1-Z$7)*LN(1-Z$7)-(1-Z$7)*LN(1-EXP(((Z12+AA12)/2)))-Z$6>0,AA12,((Z12+AA12)/2)) -> -2.9957323 | AB13: =IF((((AB12+AC12)/2))*LN((((AB12+AC12)/2))/(AB$7))+(1-(((AB12+AC12)/2)))*LN((1-(((AB12+AC12)/2)))/(1-(AB$7)))-AB$6<0,((AB12+AC12)/2),AB12) -> 0.05 | AC13: =IF((((AB12+AC12)/2))*LN((((AB12+AC12)/2))/(AB$7))+(1-(((AB12+AC12)/2)))*LN((1-(((AB12+AC12)/2)))/(1-(AB$7)))-AB$6<0,AC12,((AB12+AC12)/2)) -> 0.109375 | AD13: =IF((((AD12+AE12)/2))*LN((((AD12+AE12)/2))/(AD$7))+(1-(((AD12+AE12)/2)))*LN((1-(((AD12+AE12)/2)))/(1-(AD$7)))-AD$6<0,((AD12+AE12)/2),AD12) -> 0.05 | AE13: =IF((((AD12+AE12)/2))*LN((((AD12+AE12)/2))/(AD$7))+(1-(((AD12+AE12)/2)))*LN((1-(((AD12+AE12)/2)))/(1-(AD$7)))-AD$6<0,AE12,((AD12+AE12)/2)) -> 0.109375 | AF13: =IF((((AF12+AG12)/2))*LN((((AF12+AG12)/2))/(AF$7))+(1-(((AF12+AG12)/2)))*LN((1-(((AF12+AG12)/2)))/(1-(AF$7)))-AF$6<0,((AF12+AG12)/2),AF12) -> 0.05 | AG13: =IF((((AF12+AG12)/2))*LN((((AF12+AG12)/2))/(AF$7))+(1-(((AF12+AG12)/2)))*LN((1-(((AF12+AG12)/2)))/(1-(AF$7)))-AF$6<0,AG12,((AF12+AG12)/2)) -> 0.109375 | AH13: =IF((((AH12+AI12)/2))*LN((((AH12+AI12)/2))/(AH$7))+(1-(((AH12+AI12)/2)))*LN((1-(((AH12+AI12)/2)))/(1-(AH$7)))-AH$6<0,((AH12+AI12)/2),AH12) -> 0.109375 | AI13: =IF((((AH12+AI12)/2))*LN((((AH12+AI12)/2))/(AH$7))+(1-(((AH12+AI12)/2)))*LN((1-(((AH12+AI12)/2)))/(1-(AH$7)))-AH$6<0,AI12,((AH12+AI12)/2)) -> 0.16875 | AJ13: =IF((((AJ12+AK12)/2))*LN((((AJ12+AK12)/2))/(AJ$7))+(1-(((AJ12+AK12)/2)))*LN((1-(((AJ12+AK12)/2)))/(1-(AJ$7)))-AJ$6<0,((AJ12+AK12)/2),AJ12) -> 0.16875 | AK13: =IF((((AJ12+AK12)/2))*LN((((AJ12+AK12)/2))/(AJ$7))+(1-(((AJ12+AK12)/2)))*LN((1-(((AJ12+AK12)/2)))/(1-(AJ$7)))-AJ$6<0,AK12,((AJ12+AK12)/2)) -> 0.228125 | AL13: =IF((((AL12+AM12)/2))*LN((((AL12+AM12)/2))/(AL$7))+(1-(((AL12+AM12)/2)))*LN((1-(((AL12+AM12)/2)))/(1-(AL$7)))-AL$6<0,((AL12+AM12)/2),AL12) -> 0.2875 | AM13: =IF((((AL12+AM12)/2))*LN((((AL12+AM12)/2))/(AL$7))+(1-(((AL12+AM12)/2)))*LN((1-(((AL12+AM12)/2)))/(1-(AL$7)))-AL$6<0,AM12,((AL12+AM12)/2)) -> 0.346875 | AN13: =IF((((AN12+AO12)/2))*LN((((AN12+AO12)/2))/(AN$7))+(1-(((AN12+AO12)/2)))*LN((1-(((AN12+AO12)/2)))/(1-(AN$7)))-AN$6<0,((AN12+AO12)/2),AN12) -> 0.525 | AO13: =IF((((AN12+AO12)/2))*LN((((AN12+AO12)/2))/(AN$7))+(1-(((AN12+AO12)/2)))*LN((1-(((AN12+AO12)/2)))/(1-(AN$7)))-AN$6<0,AO12,((AN12+AO12)/2)) -> 0.584375 | AP13: =IF(AP$7*LN(AP$7)-AP$7*((AP12+AQ12)/2)+(1-AP$7)*LN(1-AP$7)-(1-AP$7)*LN(1-EXP(((AP12+AQ12)/2)))-AP$6>0,((AP12+AQ12)/2),AP12) -> -7.1258461 | AQ13: =IF(AP$7*LN(AP$7)-AP$7*((AP12+AQ12)/2)+(1-AP$7)*LN(1-AP$7)-(1-AP$7)*LN(1-EXP(((AP12+AQ12)/2)))-AP$6>0,AQ12,((AP12+AQ12)/2)) -> -2.9957323 | AR13: =IF((((AR12+AS12)/2))*LN((((AR12+AS12)/2))/(AR$7))+(1-(((AR12+AS12)/2)))*LN((1-(((AR12+AS12)/2)))/(1-(AR$7)))-AR$6<0,((AR12+AS12)/2),AR12) -> 0.05 | AS13: =IF((((AR12+AS12)/2))*LN((((AR12+AS12)/2))/(AR$7))+(1-(((AR12+AS12)/2)))*LN((1-(((AR12+AS12)/2)))/(1-(AR$7)))-AR$6<0,AS12,((AR12+AS12)/2)) -> 0.109375
B14: =IF(B$7*LN(B$7)-B$7*((B13+C13)/2)+(1-B$7)*LN(1-B$7)-(1-B$7)*LN(1-EXP(((B13+C13)/2)))-B$6>0,((B13+C13)/2),B13) -> -13.321017 | C14: =IF(B$7*LN(B$7)-B$7*((B13+C13)/2)+(1-B$7)*LN(1-B$7)-(1-B$7)*LN(1-EXP(((B13+C13)/2)))-B$6>0,C13,((B13+C13)/2)) -> -11.25596 | D14: =IF(D$7*LN(D$7)-D$7*((D13+E13)/2)+(1-D$7)*LN(1-D$7)-(1-D$7)*LN(1-EXP(((D13+E13)/2)))-D$6>0,((D13+E13)/2),D13) -> -17.451131 | E14: =IF(D$7*LN(D$7)-D$7*((D13+E13)/2)+(1-D$7)*LN(1-D$7)-(1-D$7)*LN(1-EXP(((D13+E13)/2)))-D$6>0,E13,((D13+E13)/2)) -> -15.386074 | F14: =IF(F$7*LN(F$7)-F$7*((F13+G13)/2)+(1-F$7)*LN(1-F$7)-(1-F$7)*LN(1-EXP(((F13+G13)/2)))-F$6>0,((F13+G13)/2),F13) -> -25.711358 | G14: =IF(F$7*LN(F$7)-F$7*((F13+G13)/2)+(1-F$7)*LN(1-F$7)-(1-F$7)*LN(1-EXP(((F13+G13)/2)))-F$6>0,G13,((F13+G13)/2)) -> -23.646301 | H14: =IF(H$7*LN(H$7)-H$7*((H13+I13)/2)+(1-H$7)*LN(1-H$7)-(1-H$7)*LN(1-EXP(((H13+I13)/2)))-H$6>0,((H13+I13)/2),H13) -> -5.0607892 | I14: =IF(H$7*LN(H$7)-H$7*((H13+I13)/2)+(1-H$7)*LN(1-H$7)-(1-H$7)*LN(1-EXP(((H13+I13)/2)))-H$6>0,I13,((H13+I13)/2)) -> -2.9957323 | J14: =IF(J$7*LN(J$7)-J$7*((J13+K13)/2)+(1-J$7)*LN(1-J$7)-(1-J$7)*LN(1-EXP(((J13+K13)/2)))-J$6>0,((J13+K13)/2),J13) -> -5.0607892 | K14: =IF(J$7*LN(J$7)-J$7*((J13+K13)/2)+(1-J$7)*LN(1-J$7)-(1-J$7)*LN(1-EXP(((J13+K13)/2)))-J$6>0,K13,((J13+K13)/2)) -> -2.9957323 | L14: =IF(L$7*LN(L$7)-L$7*((L13+M13)/2)+(1-L$7)*LN(1-L$7)-(1-L$7)*LN(1-EXP(((L13+M13)/2)))-L$6>0,((L13+M13)/2),L13) -> -5.0607892 | M14: =IF(L$7*LN(L$7)-L$7*((L13+M13)/2)+(1-L$7)*LN(1-L$7)-(1-L$7)*LN(1-EXP(((L13+M13)/2)))-L$6>0,M13,((L13+M13)/2)) -> -2.9957323 | N14: =IF(N$7*LN(N$7)-N$7*((N13+O13)/2)+(1-N$7)*LN(1-N$7)-(1-N$7)*LN(1-EXP(((N13+O13)/2)))-N$6>0,((N13+O13)/2),N13) -> -5.0607892 | O14: =IF(N$7*LN(N$7)-N$7*((N13+O13)/2)+(1-N$7)*LN(1-N$7)-(1-N$7)*LN(1-EXP(((N13+O13)/2)))-N$6>0,O13,((N13+O13)/2)) -> -2.9957323 | P14: =IF(P$7*LN(P$7)-P$7*((P13+Q13)/2)+(1-P$7)*LN(1-P$7)-(1-P$7)*LN(1-EXP(((P13+Q13)/2)))-P$6>0,((P13+Q13)/2),P13) -> -5.0607892 | Q14: =IF(P$7*LN(P$7)-P$7*((P13+Q13)/2)+(1-P$7)*LN(1-P$7)-(1-P$7)*LN(1-EXP(((P13+Q13)/2)))-P$6>0,Q13,((P13+Q13)/2)) -> -2.9957323 | R14: =IF(R$7*LN(R$7)-R$7*((R13+S13)/2)+(1-R$7)*LN(1-R$7)-(1-R$7)*LN(1-EXP(((R13+S13)/2)))-R$6>0,((R13+S13)/2),R13) -> -5.0607892 | S14: =IF(R$7*LN(R$7)-R$7*((R13+S13)/2)+(1-R$7)*LN(1-R$7)-(1-R$7)*LN(1-EXP(((R13+S13)/2)))-R$6>0,S13,((R13+S13)/2)) -> -2.9957323 | T14: =IF(T$7*LN(T$7)-T$7*((T13+U13)/2)+(1-T$7)*LN(1-T$7)-(1-T$7)*LN(1-EXP(((T13+U13)/2)))-T$6>0,((T13+U13)/2),T13) -> -5.0607892 | U14: =IF(T$7*LN(T$7)-T$7*((T13+U13)/2)+(1-T$7)*LN(1-T$7)-(1-T$7)*LN(1-EXP(((T13+U13)/2)))-T$6>0,U13,((T13+U13)/2)) -> -2.9957323 | V14: =IF(V$7*LN(V$7)-V$7*((V13+W13)/2)+(1-V$7)*LN(1-V$7)-(1-V$7)*LN(1-EXP(((V13+W13)/2)))-V$6>0,((V13+W13)/2),V13) -> -7.1258461 | W14: =IF(V$7*LN(V$7)-V$7*((V13+W13)/2)+(1-V$7)*LN(1-V$7)-(1-V$7)*LN(1-EXP(((V13+W13)/2)))-V$6>0,W13,((V13+W13)/2)) -> -5.0607892 | X14: =IF(X$7*LN(X$7)-X$7*((X13+Y13)/2)+(1-X$7)*LN(1-X$7)-(1-X$7)*LN(1-EXP(((X13+Y13)/2)))-X$6>0,((X13+Y13)/2),X13) -> -7.1258461 | Y14: =IF(X$7*LN(X$7)-X$7*((X13+Y13)/2)+(1-X$7)*LN(1-X$7)-(1-X$7)*LN(1-EXP(((X13+Y13)/2)))-X$6>0,Y13,((X13+Y13)/2)) -> -5.0607892 | Z14: =IF(Z$7*LN(Z$7)-Z$7*((Z13+AA13)/2)+(1-Z$7)*LN(1-Z$7)-(1-Z$7)*LN(1-EXP(((Z13+AA13)/2)))-Z$6>0,((Z13+AA13)/2),Z13) -> -7.1258461 | AA14: =IF(Z$7*LN(Z$7)-Z$7*((Z13+AA13)/2)+(1-Z$7)*LN(1-Z$7)-(1-Z$7)*LN(1-EXP(((Z13+AA13)/2)))-Z$6>0,AA13,((Z13+AA13)/2)) -> -5.0607892 | AB14: =IF((((AB13+AC13)/2))*LN((((AB13+AC13)/2))/(AB$7))+(1-(((AB13+AC13)/2)))*LN((1-(((AB13+AC13)/2)))/(1-(AB$7)))-AB$6<0,((AB13+AC13)/2),AB13) -> 0.05 | AC14: =IF((((AB13+AC13)/2))*LN((((AB13+AC13)/2))/(AB$7))+(1-(((AB13+AC13)/2)))*LN((1-(((AB13+AC13)/2)))/(1-(AB$7)))-AB$6<0,AC13,((AB13+AC13)/2)) -> 0.0796875 | AD14: =IF((((AD13+AE13)/2))*LN((((AD13+AE13)/2))/(AD$7))+(1-(((AD13+AE13)/2)))*LN((1-(((AD13+AE13)/2)))/(1-(AD$7)))-AD$6<0,((AD13+AE13)/2),AD13) -> 0.05 | AE14: =IF((((AD13+AE13)/2))*LN((((AD13+AE13)/2))/(AD$7))+(1-(((AD13+AE13)/2)))*LN((1-(((AD13+AE13)/2)))/(1-(AD$7)))-AD$6<0,AE13,((AD13+AE13)/2)) -> 0.0796875 | AF14: =IF((((AF13+AG13)/2))*LN((((AF13+AG13)/2))/(AF$7))+(1-(((AF13+AG13)/2)))*LN((1-(((AF13+AG13)/2)))/(1-(AF$7)))-AF$6<0,((AF13+AG13)/2),AF13) -> 0.0796875 | AG14: =IF((((AF13+AG13)/2))*LN((((AF13+AG13)/2))/(AF$7))+(1-(((AF13+AG13)/2)))*LN((1-(((AF13+AG13)/2)))/(1-(AF$7)))-AF$6<0,AG13,((AF13+AG13)/2)) -> 0.109375 | AH14: =IF((((AH13+AI13)/2))*LN((((AH13+AI13)/2))/(AH$7))+(1-(((AH13+AI13)/2)))*LN((1-(((AH13+AI13)/2)))/(1-(AH$7)))-AH$6<0,((AH13+AI13)/2),AH13) -> 0.109375 | AI14: =IF((((AH13+AI13)/2))*LN((((AH13+AI13)/2))/(AH$7))+(1-(((AH13+AI13)/2)))*LN((1-(((AH13+AI13)/2)))/(1-(AH$7)))-AH$6<0,AI13,((AH13+AI13)/2)) -> 0.1390625 | AJ14: =IF((((AJ13+AK13)/2))*LN((((AJ13+AK13)/2))/(AJ$7))+(1-(((AJ13+AK13)/2)))*LN((1-(((AJ13+AK13)/2)))/(1-(AJ$7)))-AJ$6<0,((AJ13+AK13)/2),AJ13) -> 0.16875 | AK14: =IF((((AJ13+AK13)/2))*LN((((AJ13+AK13)/2))/(AJ$7))+(1-(((AJ13+AK13)/2)))*LN((1-(((AJ13+AK13)/2)))/(1-(AJ$7)))-AJ$6<0,AK13,((AJ13+AK13)/2)) -> 0.1984375 | AL14: =IF((((AL13+AM13)/2))*LN((((AL13+AM13)/2))/(AL$7))+(1-(((AL13+AM13)/2)))*LN((1-(((AL13+AM13)/2)))/(1-(AL$7)))-AL$6<0,((AL13+AM13)/2),AL13) -> 0.2875 | AM14: =IF((((AL13+AM13)/2))*LN((((AL13+AM13)/2))/(AL$7))+(1-(((AL13+AM13)/2)))*LN((1-(((AL13+AM13)/2)))/(1-(AL$7)))-AL$6<0,AM13,((AL13+AM13)/2)) -> 0.3171875 | AN14: =IF((((AN13+AO13)/2))*LN((((AN13+AO13)/2))/(AN$7))+(1-(((AN13+AO13)/2)))*LN((1-(((AN13+AO13)/2)))/(1-(AN$7)))-AN$6<0,((AN13+AO13)/2),AN13) -> 0.5546875 | AO14: =IF((((AN13+AO13)/2))*LN((((AN13+AO13)/2))/(AN$7))+(1-(((AN13+AO13)/2)))*LN((1-(((AN13+AO13)/2)))/(1-(AN$7)))-AN$6<0,AO13,((AN13+AO13)/2)) -> 0.584375 | AP14: =IF(AP$7*LN(AP$7)-AP$7*((AP13+AQ13)/2)+(1-AP$7)*LN(1-AP$7)-(1-AP$7)*LN(1-EXP(((AP13+AQ13)/2)))-AP$6>0,((AP13+AQ13)/2),AP13) -> -5.0607892 | AQ14: =IF(AP$7*LN(AP$7)-AP$7*((AP13+AQ13)/2)+(1-AP$7)*LN(1-AP$7)-(1-AP$7)*LN(1-EXP(((AP13+AQ13)/2)))-AP$6>0,AQ13,((AP13+AQ13)/2)) -> -2.9957323 | AR14: =IF((((AR13+AS13)/2))*LN((((AR13+AS13)/2))/(AR$7))+(1-(((AR13+AS13)/2)))*LN((1-(((AR13+AS13)/2)))/(1-(AR$7)))-AR$6<0,((AR13+AS13)/2),AR13) -> 0.0796875 | AS14: =IF((((AR13+AS13)/2))*LN((((AR13+AS13)/2))/(AR$7))+(1-(((AR13+AS13)/2)))*LN((1-(((AR13+AS13)/2)))/(1-(AR$7)))-AR$6<0,AS13,((AR13+AS13)/2)) -> 0.109375
