Workbook

Sheet README
B1: DCT Laboratory — Vol I, Ch 5: Enterprise State Representation
B2: Seed 26105 · Companion to DCT_V1_Ch05_Lab.ipynb and AXIOM Lab 1.5 (module AXIOM-05). Money in $ million; liquidity also as an index, today = 100 = $620 million.
B4: Worked Example 5.1, Where Does the Turnaround Settle?, with the book's declarations, and the five steps of AXIOM Lab 1.5, Meridian's Room to Maneuver.
B5: Declarations: Meridian's declared state (Table 5.2), the walls with numbers (Table 5.4), Chapter 1's model (Online Appendix 1.B.4, Table 1.B.1) and its scorecard.
B6: State: the eight readings with their types, tags and scaled errors; the attrition rate's switch from parameter to state variable (lab step 1).
B7: Walls: slack on every wall today, at the digital low point (Newton's method) and at its tightest along each option's five-year path, month by month (Proposition 5.5; Figure 5.4; lab step 2).
B8: Blend: two configurations under a capacity budget and a minimum efficient scale (Theorem 5.2(iii); Figure 5.1), and a covenant written weakly and strictly (Theorem 5.5).
B9: PathSampling: the digital liquidity path stepped quarterly and half-yearly with its exact flow map, its two phases joined, and the steps undone (Propositions 5.3-5.4; Figure 5.2; lab step 3).
B10: Turnaround: the annual map, the contraction constant, the day-one bound and Table 5.5, and the same map from two other starting states (Theorem 5.4(i); Equation 5.1; Worked Example 5.1; lab step 4).
B11: Equilibria: the start-up, the unstable middle and the service operation of Online Appendix 5.B.4-5.B.7.
B12: Profiles: today and the Year-5 states on Chapter 3's scale, the distance readout, and the volume of a ball in a cube (Figure 5.5; Section 5.8; lab step 5).
B13: Every result is a formula of the declarations. Reference_Values and Checks: the notebook engine's numbers and a PASS/FAIL comparison with this workbook's formulas.
... B19: Cross-sheet link: green.

Sheet Declarations
A1: Declarations (Tables 5.2 and 5.4; Chapter 1's model, Online Appendix 1.B.4). Money in $ million; liquidity also as an index, today = 100.
A3: x | B3: Reading | C3: Today | D3: Unit | E3: Type (Table 5.1) | F3: Measured by | G3: Error as printed | H3: Error in the reading's unit | I3: Chapter 3 scale | J3: Tag (Part III)
A4: x1 | B4: liquidity | C4: 100 | D4: index, today = 100 = $620 million (US$ billion in Table 5.2) | E4: stock | F4: treasury systems | G4: +/-1% | H4: =0.01*C4 -> 1 | I4: =C4 -> 100 | J4: ECA
A5: x2 | B5: net leverage | C5: 3.4 | D5: ND/EBITDA | E5: ratio | F5: audited accounts | G5: +/-2% | H5: =0.02*C5 -> 0.068 | I5: =C5 -> 3.4 | J5: ECA
A6: x3 | B6: workforce capability | C6: 58 | D6: 0-100 | E6: index | F6: skills survey | G6: +/-5 | H6: 5 | I6: 100 | J6: ECA
A7: x4 | B7: technology platform | C7: 41 | D7: 0-100 | E7: index | F7: architecture audit | G7: +/-4 | H7: 4 | I7: 100 | J7: ECA
A8: x5 | B8: operational efficiency | C8: 71 | D8: 0-100 | E8: index | F8: cost benchmarking | G8: +/-3 | H8: 3 | I8: 100 | J8: EPA
A9: x6 | B9: ROIC | C9: 0.083 | D9: ratio | E9: ratio | F9: audited accounts | G9: +/-0.4 pp | H9: 0.004 | I9: =C9 -> 0.083 | J9: EPA
A10: x7 | B10: strategic risk (lower is better) | C10: 64 | D10: 0-100 | E10: index | F10: risk committee | G10: +/-6 | H10: 6 | I10: 100 | J10: ERRA
A11: x8 | B11: market share | C11: 0.19 | D11: ratio | E11: ratio | F11: industry data | G11: +/-0.8 pp | H11: 0.008 | I11: =C11 -> 0.19 | J11: EPA
A13: Quantity | C13: Value | E13: Declared in
A14: Liquidity today ($ million) | C14: 620 | E14: Table 5.2; Chapter 3, Table 3.1: $0.62 billion
A15: $ million per liquidity point | C15: =C14/C4 -> 6.2 | E15: today = 100 = $620 million
A16: Board liquidity floor ($ million) | C16: 350 | E16: Table 5.4: policy, $0.35 billion
A17: The floor as a liquidity index | C17: =C16/C15 -> 56.451613
A18: Loan covenant: net leverage at most | C18: 4.5 | E18: Table 5.4: regulatory and contractual
A19: Strategic-risk ceiling | C19: 75 | E19: Table 5.4: policy
A20: Indices: lowest | C20: 0 | E20: Table 5.4: definitional
A21: Indices: highest | C21: 100 | E21: Table 5.4: definitional
A22: Shares: lowest | C22: 0 | E22: Table 5.4: definitional
A23: Shares: highest | C23: 1 | E23: Table 5.4: definitional
A24: The restructuring's sale closes at t (years) | C24: 1 | E24: Online Appendix 1.B.4
A26: Option | B26: Reading | C26: Target | D26: Speed k (a year) | E26: Trough (sign x depth) | F26: Trough time tau | G26: Jump at the sale
A27: Digital | B27: liquidity | C27: 112 | D27: 0.35 | E27: -28 | F27: 2 | G27: 0
B28: technology | C28: 78 | D28: 0.55 | E28: 0 | F28: 1 | G28: 0
B29: efficiency | C29: 77 | D29: 0.5 | E29: -9 | F29: 1.5 | G29: 0
B30: strategic risk | C30: 51 | D30: 0.4 | E30: 14 | F30: 1.2 | G30: 0
A31: Restructuring | B31: liquidity | C31: 104 | D31: 0.3 | E31: 0 | F31: 1 | G31: 18
B32: technology | C32: 38 | D32: 0.25 | E32: 0 | F32: 1 | G32: 0
B33: efficiency | C33: 74 | D33: 0.45 | E33: 0 | F33: 1 | G33: 0
B34: strategic risk | C34: 56 | D34: 0.35 | E34: 0 | F34: 1 | G34: -8
A35: Turnaround | B35: liquidity | C35: 106 | D35: 0.45 | E35: 0 | F35: 1 | G35: 0
B36: technology | C36: 33 | D36: 0.2 | E36: 0 | F36: 1 | G36: 0
B37: efficiency | C37: 79 | D37: 0.6 | E37: 0 | F37: 1 | G37: 0
B38: strategic risk | C38: 67 | D38: 0.3 | E38: 0 | F38: 1 | G38: 0
A39: Table 1.B.1 (Online Appendix 1.B.4), Equation 1.B.1; a blank trough is 0 (its time is then unused). The turnaround is Worked Example 5.1's: targets 106, 33, 79, 67.
A41: Chapter 1's scorecard | C41: Weight
A42: liquidity | C42: 0.25
A43: technology platform | C43: 0.25
A44: operational efficiency | C44: 0.25
...

Sheet State
A1: Declare the state: Meridian's eight readings (Tables 5.1-5.2; Definitions 5.2-5.3; AXIOM Lab 1.5, step 1)
A2: Chapter 3's scale divides indices by their range of 100 and the other readings by today's value; the scaled error puts the error bars on one footing.
A3: x | B3: Reading | C3: Today | D3: Type (Table 5.1) | E3: Tag (Part III) | F3: Error in the reading's unit | G3: Chapter 3 scale | H3: Scaled error
A4: x1 | B4: =Declarations!B4 -> liquidity | C4: =Declarations!C4 -> 100 | D4: =Declarations!E4 -> stock | E4: =Declarations!J4 -> ECA | F4: =Declarations!H4 -> 1 | G4: =Declarations!I4 -> 100 | H4: =F4/G4 -> 0.01
A5: x2 | B5: =Declarations!B5 -> net leverage | C5: =Declarations!C5 -> 3.4 | D5: =Declarations!E5 -> ratio | E5: =Declarations!J5 -> ECA | F5: =Declarations!H5 -> 0.068 | G5: =Declarations!I5 -> 3.4 | H5: =F5/G5 -> 0.02
A6: x3 | B6: =Declarations!B6 -> workforce capability | C6: =Declarations!C6 -> 58 | D6: =Declarations!E6 -> index | E6: =Declarations!J6 -> ECA | F6: =Declarations!H6 -> 5 | G6: =Declarations!I6 -> 100 | H6: =F6/G6 -> 0.05
A7: x4 | B7: =Declarations!B7 -> technology platform | C7: =Declarations!C7 -> 41 | D7: =Declarations!E7 -> index | E7: =Declarations!J7 -> ECA | F7: =Declarations!H7 -> 4 | G7: =Declarations!I7 -> 100 | H7: =F7/G7 -> 0.04
A8: x5 | B8: =Declarations!B8 -> operational efficiency | C8: =Declarations!C8 -> 71 | D8: =Declarations!E8 -> index | E8: =Declarations!J8 -> EPA | F8: =Declarations!H8 -> 3 | G8: =Declarations!I8 -> 100 | H8: =F8/G8 -> 0.03
A9: x6 | B9: =Declarations!B9 -> ROIC | C9: =Declarations!C9 -> 0.083 | D9: =Declarations!E9 -> ratio | E9: =Declarations!J9 -> EPA | F9: =Declarations!H9 -> 0.004 | G9: =Declarations!I9 -> 0.083 | H9: =F9/G9 -> 0.048192771
A10: x7 | B10: =Declarations!B10 -> strategic risk (lower is better) | C10: =Declarations!C10 -> 64 | D10: =Declarations!E10 -> index | E10: =Declarations!J10 -> ERRA | F10: =Declarations!H10 -> 6 | G10: =Declarations!I10 -> 100 | H10: =F10/G10 -> 0.06
A11: x8 | B11: =Declarations!B11 -> market share | C11: =Declarations!C11 -> 0.19 | D11: =Declarations!E11 -> ratio | E11: =Declarations!J11 -> EPA | F11: =Declarations!H11 -> 0.008 | G11: =Declarations!I11 -> 0.19 | H11: =F11/G11 -> 0.042105263
A13: Readings in the declared state | B13: =COUNTA(B4:B11) -> 8
A14: Stocks | B14: =COUNTIF(D4:D11,"stock") -> 1
A15: Ratios | B15: =COUNTIF(D4:D11,"ratio") -> 3
A16: Indices | B16: =COUNTIF(D4:D11,"index") -> 4
A17: Capital readings (ECA) | B17: =COUNTIF(E4:E11,"ECA") -> 4
A18: Performance readings (EPA) | B18: =COUNTIF(E4:E11,"EPA") -> 3
A19: Risk readings (ERRA) | B19: =COUNTIF(E4:E11,"ERRA") -> 1
A20: Widest scaled error | B20: =MAX(H4:H11) -> 0.06 | C20: =INDEX(B4:B11,MATCH(B20,H4:H11,0)) -> strategic risk (lower is better)
A21: Second widest scaled error | B21: =LARGE(H4:H11,2) -> 0.05 | C21: =INDEX(B4:B11,MATCH(B21,H4:H11,0)) -> workforce capability
A23: The switch: promote the attrition rate to a state variable | B23: Value
A24: Dimension before the switch | B24: =B13 -> 8
A25: Dimension after the switch | B25: =B13+1 -> 9
A26: Attrition a year: declared lowest | B26: =Attr_lo -> 0.06
A27: Attrition a year: declared highest | B27: =Attr_hi -> 0.11
A28: Chapter 1's model reads no attrition rate, so the eight readings' paths are the same from either end of its range (Walls), and the ninth coordinate stays where it starts: at a five-year horizon it is a parameter (Table 5.1). By Theorem 5.1 it earns a place in the state only in a model whose future depends on it.

Sheet Walls
A1: Build the walls: slack on every wall of Table 5.4, today, at the digital low point and along each option's path (Proposition 5.5; Figure 5.4; AXIOM Lab 1.5, step 2)
A2: Slack is the room left before a wall, in the wall's unit; zero means the wall binds. Chapter 1's model moves liquidity, technology, efficiency and strategic risk; leverage, workforce, ROIC and market share stay at today's values, so the covenant's slack is held.
A4: Wall (Table 5.4) | B4: Type | C4: Unit | D4: Today | E4: Digital low point | F4: Tightest: digital | G4: Month | H4: Tightest: restructuring | I4: Month | J4: Tightest: turnaround | K4: Month
A5: Liquidity at least zero | B5: physical | C5: $ million | D5: =Liq_today*USD_pt -> 620 | E5: =$J$21 -> 481.91794 | F5: =MIN($O$45:$O$105) -> 481.95038 | G5: =INDEX($A$45:$A$105,MATCH(F5,$O$45:$O$105,0)) -> 21 | H5: =MIN($S$45:$S$105) -> 620 | I5: =INDEX($A$45:$A$105,MATCH(H5,$S$45:$S$105,0)) -> 0 | J5: =MIN($W$45:$W$105) -> 620 | K5: =INDEX($A$45:$A$105,MATCH(J5,$W$45:$W$105,0)) -> 0
A6: Board floor: liquidity at least $350 million | B6: policy | C6: $ million | D6: =Liq_today*USD_pt-Floor_usd -> 270 | E6: =$J$21-Floor_usd -> 131.91794 | F6: =MIN($P$45:$P$105) -> 131.95038 | G6: =INDEX($A$45:$A$105,MATCH(F6,$P$45:$P$105,0)) -> 21 | H6: =MIN($T$45:$T$105) -> 270 | I6: =INDEX($A$45:$A$105,MATCH(H6,$T$45:$T$105,0)) -> 0 | J6: =MIN($X$45:$X$105) -> 270 | K6: =INDEX($A$45:$A$105,MATCH(J6,$X$45:$X$105,0)) -> 0
A7: Covenant: net leverage at most 4.5 | B7: regulatory and contractual | C7: turns | D7: =Covenant-Lev_today -> 1.1 | E7: =Covenant-Lev_today -> 1.1 | F7: =D7 -> 1.1 | G7: held | H7: =D7 -> 1.1 | I7: held | J7: =D7 -> 1.1 | K7: held
A8: Risk ceiling: strategic risk at most 75 | B8: policy | C8: points | D8: =Risk_ceiling-Risk_today -> 11 | E8: =Risk_ceiling-(Declarations!$C$30+(Declarations!$C$10-Declarations!$C$30)*EXP(-Declarations!$D$30*$B$19)+IF(Declarations!$E$30=0,0,Declarations!$E$30*($B$19/Declarations!$F$30)*EXP(1-$B$19/Declarations!$F$30))+IF($B$19>=T_sale,Declarations!$G$30,0)) -> 4.4242054 | F8: =MIN($Q$45:$Q$105) -> 1.4479365 | G8: =INDEX($A$45:$A$105,MATCH(F8,$Q$45:$Q$105,0)) -> 11 | H8: =MIN($U$45:$U$105) -> 11 | I8: =INDEX($A$45:$A$105,MATCH(H8,$U$45:$U$105,0)) -> 0 | J8: =MIN($Y$45:$Y$105) -> 8.6693905 | K8: =INDEX($A$45:$A$105,MATCH(J8,$Y$45:$Y$105,0)) -> 60
A9: Indices between 0 and 100 | B9: definitional | C9: points | D9: =MIN(Wf_today-Idx_lo,Idx_hi-Wf_today,Tech_today-Idx_lo,Idx_hi-Tech_today,Eff_today-Idx_lo,Idx_hi-Eff_today,Risk_today-Idx_lo,Idx_hi-Risk_today) -> 29 | E9: =MIN(Wf_today-Idx_lo,Idx_hi-Wf_today,(Declarations!$C$28+(Declarations!$C$7-Declarations!$C$28)*EXP(-Declarations!$D$28*$B$19)+IF(Declarations!$E$28=0,0,Declarations!$E$28*($B$19/Declarations!$F$28)*EXP(1-$B$19/Declarations!$F$28))+IF($B$19>=T_sale,Declarations!$G$28,0))-Idx_lo,Idx_hi-(Declarations!$C$28+(Declarations!$C$7-Declarations!$C$28)*EXP(-Declarations!$D$28*$B$19)+IF(Declarations!$E$28=0,0,Declarations!$E$28*($B$19/Declarations!$F$28)*EXP(1-$B$19/Declarations!$F$28))+IF($B$19>=T_sale,Declarations!$G$28,0)),(Declarations!$C$29+(Declarations!$C$8-Declarations!$C$29)*EXP(-Declarations!$D$29*$B$19)+IF(Declarations!$E$29=0,0,Declarations!$E$29*($B$19/Declarations!$F$29)*EXP(1-$B$19/Declarations!$F$29))+IF($B$19>=T_sale,Declarations!$G$29,0))-Idx_lo,Idx_hi-(Declarations!$C$29+(Declarations!$C$8-Declarations!$C$29)*EXP(-Declarations!$D$29*$B$19)+IF(Declarations!$E$29=0,0,Declarations!$E$29*($B$19/Declarations!$F$29)*EXP(1-$B$19/Declarations!$F$29))+IF($B$19>=T_sale,Declarations!$G$29,0)),(Declarations!$C$30+(Declarations!$C$10-Declarations!$C$30)*EXP(-Declarations!$D$30*$B$19)+IF(Declarations!$E$30=0,0,Declarations!$E$30*($B$19/Declarations!$F$30)*EXP(1-$B$19/Declarations!$F$30))+IF($B$19>=T_sale,Declarations!$G$30,0))-Idx_lo,Idx_hi-(Declarations!$C$30+(Declarations!$C$10-Declarations!$C$30)*EXP(-Declarations!$D$30*$B$19)+IF(Declarations!$E$30=0,0,Declarations!$E$30*($B$19/Declarations!$F$30)*EXP(1-$B$19/Declarations!$F$30))+IF($B$19>=T_sale,Declarations!$G$30,0))) -> 29.424205 | F9: =MIN($R$45:$R$105) -> 24.365331 | G9: =INDEX($A$45:$A$105,MATCH(F9,$R$45:$R$105,0)) -> 60 | H9: =MIN($V$45:$V$105) -> 26.316198 | I9: =INDEX($A$45:$A$105,MATCH(H9,$V$45:$V$105,0)) -> 60 | J9: =MIN($Z$45:$Z$105) -> 21.398297 | K9: =INDEX($A$45:$A$105,MATCH(J9,$Z$45:$Z$105,0)) -> 60
A10: Shares between 0 and 1 | B10: definitional | C10: share | D10: =MIN(Share_today-Shr_lo,Shr_hi-Share_today) -> 0.19 | E10: =MIN(Share_today-Shr_lo,Shr_hi-Share_today) -> 0.19 | F10: =D10 -> 0.19 | G10: held | H10: =D10 -> 0.19 | I10: held | J10: =D10 -> 0.19 | K10: held
A11: Walls binding (slack zero) | D11: =SUMPRODUCT(--(ABS(D5:D10)<0.000000001)) -> 0 | E11: =SUMPRODUCT(--(ABS(E5:E10)<0.000000001)) -> 0
A13: The digital low point: Newton's method on the slope of liquidity | B13: t (years) | C13: slope x'(t) | D13: curvature x''(t) | E13: reading x(t)
A14: iteration 0 (start: month 21) | B14: 1.75 | C14: =-Declarations!$D$27*(Declarations!$C$4-Declarations!$C$27)*EXP(-Declarations!$D$27*B14)+(Declarations!$E$27/Declarations!$F$27)*EXP(1-B14/Declarations!$F$27)*(1-B14/Declarations!$F$27) -> 0.2933658 | D14: =Declarations!$D$27^2*(Declarations!$C$4-Declarations!$C$27)*EXP(-Declarations!$D$27*B14)-(Declarations!$E$27/Declarations!$F$27^2)*EXP(1-B14/Declarations!$F$27)*(2-B14/Declarations!$F$27) -> 8.1268126 | E14: =Declarations!$C$27+(Declarations!$C$4-Declarations!$C$27)*EXP(-Declarations!$D$27*B14)+IF(Declarations!$E$27=0,0,Declarations!$E$27*(B14/Declarations!$F$27)*EXP(1-B14/Declarations!$F$27))+IF(B14>=T_sale,Declarations!$G$27,0) -> 77.733933
A15: iteration 1 | B15: =B14-C14/D14 -> 1.7139015 | C15: =-Declarations!$D$27*(Declarations!$C$4-Declarations!$C$27)*EXP(-Declarations!$D$27*B15)+(Declarations!$E$27/Declarations!$F$27)*EXP(1-B15/Declarations!$F$27)*(1-B15/Declarations!$F$27) -> -0.0053575547 | D15: =Declarations!$D$27^2*(Declarations!$C$4-Declarations!$C$27)*EXP(-Declarations!$D$27*B15)-(Declarations!$E$27/Declarations!$F$27^2)*EXP(1-B15/Declarations!$F$27)*(2-B15/Declarations!$F$27) -> 8.424983 | E15: =Declarations!$C$27+(Declarations!$C$4-Declarations!$C$27)*EXP(-Declarations!$D$27*B15)+IF(Declarations!$E$27=0,0,Declarations!$E$27*(B15/Declarations!$F$27)*EXP(1-B15/Declarations!$F$27))+IF(B15>=T_sale,Declarations!$G$27,0) -> 77.728702
A16: iteration 2 | B16: =B15-C15/D15 -> 1.7145374 | C16: =-Declarations!$D$27*(Declarations!$C$4-Declarations!$C$27)*EXP(-Declarations!$D$27*B16)+(Declarations!$E$27/Declarations!$F$27)*EXP(1-B16/Declarations!$F$27)*(1-B16/Declarations!$F$27) -> -1.6924427e-06 | D16: =Declarations!$D$27^2*(Declarations!$C$4-Declarations!$C$27)*EXP(-Declarations!$D$27*B16)-(Declarations!$E$27/Declarations!$F$27^2)*EXP(1-B16/Declarations!$F$27)*(2-B16/Declarations!$F$27) -> 8.4196605 | E16: =Declarations!$C$27+(Declarations!$C$4-Declarations!$C$27)*EXP(-Declarations!$D$27*B16)+IF(Declarations!$E$27=0,0,Declarations!$E$27*(B16/Declarations!$F$27)*EXP(1-B16/Declarations!$F$27))+IF(B16>=T_sale,Declarations!$G$27,0) -> 77.7287
A17: iteration 3 | B17: =B16-C16/D16 -> 1.7145376 | C17: =-Declarations!$D$27*(Declarations!$C$4-Declarations!$C$27)*EXP(-Declarations!$D$27*B17)+(Declarations!$E$27/Declarations!$F$27)*EXP(1-B17/Declarations!$F$27)*(1-B17/Declarations!$F$27) -> -1.7008617e-13 | D17: =Declarations!$D$27^2*(Declarations!$C$4-Declarations!$C$27)*EXP(-Declarations!$D$27*B17)-(Declarations!$E$27/Declarations!$F$27^2)*EXP(1-B17/Declarations!$F$27)*(2-B17/Declarations!$F$27) -> 8.4196589 | E17: =Declarations!$C$27+(Declarations!$C$4-Declarations!$C$27)*EXP(-Declarations!$D$27*B17)+IF(Declarations!$E$27=0,0,Declarations!$E$27*(B17/Declarations!$F$27)*EXP(1-B17/Declarations!$F$27))+IF(B17>=T_sale,Declarations!$G$27,0) -> 77.7287
A18: iteration 4 | B18: =B17-C17/D17 -> 1.7145376 | C18: =-Declarations!$D$27*(Declarations!$C$4-Declarations!$C$27)*EXP(-Declarations!$D$27*B18)+(Declarations!$E$27/Declarations!$F$27)*EXP(1-B18/Declarations!$F$27)*(1-B18/Declarations!$F$27) -> 0 | D18: =Declarations!$D$27^2*(Declarations!$C$4-Declarations!$C$27)*EXP(-Declarations!$D$27*B18)-(Declarations!$E$27/Declarations!$F$27^2)*EXP(1-B18/Declarations!$F$27)*(2-B18/Declarations!$F$27) -> 8.4196589 | E18: =Declarations!$C$27+(Declarations!$C$4-Declarations!$C$27)*EXP(-Declarations!$D$27*B18)+IF(Declarations!$E$27=0,0,Declarations!$E$27*(B18/Declarations!$F$27)*EXP(1-B18/Declarations!$F$27))+IF(B18>=T_sale,Declarations!$G$27,0) -> 77.7287
A19: iteration 5 | B19: =B18-C18/D18 -> 1.7145376 | C19: =-Declarations!$D$27*(Declarations!$C$4-Declarations!$C$27)*EXP(-Declarations!$D$27*B19)+(Declarations!$E$27/Declarations!$F$27)*EXP(1-B19/Declarations!$F$27)*(1-B19/Declarations!$F$27) -> 0 | D19: =Declarations!$D$27^2*(Declarations!$C$4-Declarations!$C$27)*EXP(-Declarations!$D$27*B19)-(Declarations!$E$27/Declarations!$F$27^2)*EXP(1-B19/Declarations!$F$27)*(2-B19/Declarations!$F$27) -> 8.4196589 | E19: =Declarations!$C$27+(Declarations!$C$4-Declarations!$C$27)*EXP(-Declarations!$D$27*B19)+IF(Declarations!$E$27=0,0,Declarations!$E$27*(B19/Declarations!$F$27)*EXP(1-B19/Declarations!$F$27))+IF(B19>=T_sale,Declarations!$G$27,0) -> 77.7287 | G19: Time of the low point (years) | J19: =B19 -> 1.7145376
G20: Low point (liquidity index) | J20: =E19 -> 77.7287
G21: Low point ($ million) | J21: =E19*USD_pt -> 481.91794
G22: Low point (month) | J22: =12*B19 -> 20.574451
G23: Slack above the floor at the low point ($ million) | J23: =J21-Floor_usd -> 131.91794
G24: Highest floor the digital program can meet ($ million) | J24: =J21 -> 481.91794
G25: Lowest monthly reading (index) | J25: =MIN($C$45:$C$105) -> 77.733933
G26: Its month | J26: =INDEX($A$45:$A$105,MATCH(J25,$C$45:$C$105,0)) -> 21
A28: The digital strategic-risk peak: Newton's method on the slope of strategic risk | B28: t (years) | C28: slope x'(t) | D28: curvature x''(t) | E28: reading x(t)
A29: iteration 0 (start: month 11) | B29: 0.9 | C29: =-Declarations!$D$30*(Declarations!$C$10-Declarations!$C$30)*EXP(-Declarations!$D$30*B29)+(Declarations!$E$30/Declarations!$F$30)*EXP(1-B29/Declarations!$F$30)*(1-B29/Declarations!$F$30) -> 0.11715724 | D29: =Declarations!$D$30^2*(Declarations!$C$10-Declarations!$C$30)*EXP(-Declarations!$D$30*B29)-(Declarations!$E$30/Declarations!$F$30^2)*EXP(1-B29/Declarations!$F$30)*(2-B29/Declarations!$F$30) -> -14.153309 | E29: =Declarations!$C$30+(Declarations!$C$10-Declarations!$C$30)*EXP(-Declarations!$D$30*B29)+IF(Declarations!$E$30=0,0,Declarations!$E$30*(B29/Declarations!$F$30)*EXP(1-B29/Declarations!$F$30))+IF(B29>=T_sale,Declarations!$G$30,0) -> 73.552059
A30: iteration 1 | B30: =B29-C29/D29 -> 0.90827773 | C30: =-Declarations!$D$30*(Declarations!$C$10-Declarations!$C$30)*EXP(-Declarations!$D$30*B30)+(Declarations!$E$30/Declarations!$F$30)*EXP(1-B30/Declarations!$F$30)*(1-B30/Declarations!$F$30) -> 0.00077940056 | D30: =Declarations!$D$30^2*(Declarations!$C$10-Declarations!$C$30)*EXP(-Declarations!$D$30*B30)-(Declarations!$E$30/Declarations!$F$30^2)*EXP(1-B30/Declarations!$F$30)*(2-B30/Declarations!$F$30) -> -13.965314 | E30: =Declarations!$C$30+(Declarations!$C$10-Declarations!$C$30)*EXP(-Declarations!$D$30*B30)+IF(Declarations!$E$30=0,0,Declarations!$E$30*(B30/Declarations!$F$30)*EXP(1-B30/Declarations!$F$30))+IF(B30>=T_sale,Declarations!$G$30,0) -> 73.552546
A31: iteration 2 | B31: =B30-C30/D30 -> 0.90833354 | C31: =-Declarations!$D$30*(Declarations!$C$10-Declarations!$C$30)*EXP(-Declarations!$D$30*B31)+(Declarations!$E$30/Declarations!$F$30)*EXP(1-B31/Declarations!$F$30)*(1-B31/Declarations!$F$30) -> 3.5189375e-08 | D31: =Declarations!$D$30^2*(Declarations!$C$10-Declarations!$C$30)*EXP(-Declarations!$D$30*B31)-(Declarations!$E$30/Declarations!$F$30^2)*EXP(1-B31/Declarations!$F$30)*(2-B31/Declarations!$F$30) -> -13.964053 | E31: =Declarations!$C$30+(Declarations!$C$10-Declarations!$C$30)*EXP(-Declarations!$D$30*B31)+IF(Declarations!$E$30=0,0,Declarations!$E$30*(B31/Declarations!$F$30)*EXP(1-B31/Declarations!$F$30))+IF(B31>=T_sale,Declarations!$G$30,0) -> 73.552546
A32: iteration 3 | B32: =B31-C31/D31 -> 0.90833354 | C32: =-Declarations!$D$30*(Declarations!$C$10-Declarations!$C$30)*EXP(-Declarations!$D$30*B32)+(Declarations!$E$30/Declarations!$F$30)*EXP(1-B32/Declarations!$F$30)*(1-B32/Declarations!$F$30) -> 0 | D32: =Declarations!$D$30^2*(Declarations!$C$10-Declarations!$C$30)*EXP(-Declarations!$D$30*B32)-(Declarations!$E$30/Declarations!$F$30^2)*EXP(1-B32/Declarations!$F$30)*(2-B32/Declarations!$F$30) -> -13.964053 | E32: =Declarations!$C$30+(Declarations!$C$10-Declarations!$C$30)*EXP(-Declarations!$D$30*B32)+IF(Declarations!$E$30=0,0,Declarations!$E$30*(B32/Declarations!$F$30)*EXP(1-B32/Declarations!$F$30))+IF(B32>=T_sale,Declarations!$G$30,0) -> 73.552546
A33: iteration 4 | B33: =B32-C32/D32 -> 0.90833354 | C33: =-Declarations!$D$30*(Declarations!$C$10-Declarations!$C$30)*EXP(-Declarations!$D$30*B33)+(Declarations!$E$30/Declarations!$F$30)*EXP(1-B33/Declarations!$F$30)*(1-B33/Declarations!$F$30) -> 0 | D33: =Declarations!$D$30^2*(Declarations!$C$10-Declarations!$C$30)*EXP(-Declarations!$D$30*B33)-(Declarations!$E$30/Declarations!$F$30^2)*EXP(1-B33/Declarations!$F$30)*(2-B33/Declarations!$F$30) -> -13.964053 | E33: =Declarations!$C$30+(Declarations!$C$10-Declarations!$C$30)*EXP(-Declarations!$D$30*B33)+IF(Declarations!$E$30=0,0,Declarations!$E$30*(B33/Declarations!$F$30)*EXP(1-B33/Declarations!$F$30))+IF(B33>=T_sale,Declarations!$G$30,0) -> 73.552546
A34: iteration 5 | B34: =B33-C33/D33 -> 0.90833354 | C34: =-Declarations!$D$30*(Declarations!$C$10-Declarations!$C$30)*EXP(-Declarations!$D$30*B34)+(Declarations!$E$30/Declarations!$F$30)*EXP(1-B34/Declarations!$F$30)*(1-B34/Declarations!$F$30) -> 0 | D34: =Declarations!$D$30^2*(Declarations!$C$10-Declarations!$C$30)*EXP(-Declarations!$D$30*B34)-(Declarations!$E$30/Declarations!$F$30^2)*EXP(1-B34/Declarations!$F$30)*(2-B34/Declarations!$F$30) -> -13.964053 | E34: =Declarations!$C$30+(Declarations!$C$10-Declarations!$C$30)*EXP(-Declarations!$D$30*B34)+IF(Declarations!$E$30=0,0,Declarations!$E$30*(B34/Declarations!$F$30)*EXP(1-B34/Declarations!$F$30))+IF(B34>=T_sale,Declarations!$G$30,0) -> 73.552546 | G34: Time of the peak (years) | J34: =B34 -> 0.90833354
G35: Strategic-risk peak | J35: =E34 -> 73.552546
G36: Its month | J36: =12*B34 -> 10.900002
G37: Margin under the risk ceiling | J37: =Risk_ceiling-E34 -> 1.4474538
G38: Highest monthly reading | J38: =MAX($F$45:$F$105) -> 73.552064
G39: Its month | J39: =INDEX($A$45:$A$105,MATCH(J38,$F$45:$F$105,0)) -> 11
A41: Section 5.7: in Figure 5.4's projection the floor is the wall the digital program approaches most closely. Off that projection the risk ceiling comes closer: strategic risk peaks 1.4 points under 75 in month 11 (Chapter 1, Table 1.5; Worked Example 16.1), inside the risk committee's +/-6 reading error.
A44: Month | B44: t (years) | C44: Digital: liquidity | D44: technology | E44: efficiency | F44: strategic risk | G44: Restructuring: liquidity | H44: technology | I44: efficiency | J44: strategic risk | K44: Turnaround: liquidity | L44: technology | M44: efficiency | N44: strategic risk | O44: Digital: liquidity ($m) | P44: floor slack ($m) | Q44: risk-ceiling slack | R44: index slack | S44: Restructuring: liquidity ($m) | T44: floor slack ($m) | U44: risk-ceiling slack | V44: index slack | W44: Turnaround: liquidity ($m) | X44: floor slack ($m) | Y44: risk-ceiling slack | Z44: index slack
A45: 0 | B45: =A45/12 -> 0 | C45: =Declarations!$C$27+(Declarations!$C$4-Declarations!$C$27)*EXP(-Declarations!$D$27*$B45)+IF(Declarations!$E$27=0,0,Declarations!$E$27*($B45/Declarations!$F$27)*EXP(1-$B45/Declarations!$F$27))+IF($B45>=T_sale,Declarations!$G$27,0) -> 100 | D45: =Declarations!$C$28+(Declarations!$C$7-Declarations!$C$28)*EXP(-Declarations!$D$28*$B45)+IF(Declarations!$E$28=0,0,Declarations!$E$28*($B45/Declarations!$F$28)*EXP(1-$B45/Declarations!$F$28))+IF($B45>=T_sale,Declarations!$G$28,0) -> 41 | E45: =Declarations!$C$29+(Declarations!$C$8-Declarations!$C$29)*EXP(-Declarations!$D$29*$B45)+IF(Declarations!$E$29=0,0,Declarations!$E$29*($B45/Declarations!$F$29)*EXP(1-$B45/Declarations!$F$29))+IF($B45>=T_sale,Declarations!$G$29,0) -> 71 | F45: =Declarations!$C$30+(Declarations!$C$10-Declarations!$C$30)*EXP(-Declarations!$D$30*$B45)+IF(Declarations!$E$30=0,0,Declarations!$E$30*($B45/Declarations!$F$30)*EXP(1-$B45/Declarations!$F$30))+IF($B45>=T_sale,Declarations!$G$30,0) -> 64 | G45: =Declarations!$C$31+(Declarations!$C$4-Declarations!$C$31)*EXP(-Declarations!$D$31*$B45)+IF(Declarations!$E$31=0,0,Declarations!$E$31*($B45/Declarations!$F$31)*EXP(1-$B45/Declarations!$F$31))+IF($B45>=T_sale,Declarations!$G$31,0) -> 100 | H45: =Declarations!$C$32+(Declarations!$C$7-Declarations!$C$32)*EXP(-Declarations!$D$32*$B45)+IF(Declarations!$E$32=0,0,Declarations!$E$32*($B45/Declarations!$F$32)*EXP(1-$B45/Declarations!$F$32))+IF($B45>=T_sale,Declarations!$G$32,0) -> 41 | I45: =Declarations!$C$33+(Declarations!$C$8-Declarations!$C$33)*EXP(-Declarations!$D$33*$B45)+IF(Declarations!$E$33=0,0,Declarations!$E$33*($B45/Declarations!$F$33)*EXP(1-$B45/Declarations!$F$33))+IF($B45>=T_sale,Declarations!$G$33,0) -> 71 | J45: =Declarations!$C$34+(Declarations!$C$10-Declarations!$C$34)*EXP(-Declarations!$D$34*$B45)+IF(Declarations!$E$34=0,0,Declarations!$E$34*($B45/Declarations!$F$34)*EXP(1-$B45/Declarations!$F$34))+IF($B45>=T_sale,Declarations!$G$34,0) -> 64 | K45: =Declarations!$C$35+(Declarations!$C$4-Declarations!$C$35)*EXP(-Declarations!$D$35*$B45)+IF(Declarations!$E$35=0,0,Declarations!$E$35*($B45/Declarations!$F$35)*EXP(1-$B45/Declarations!$F$35))+IF($B45>=T_sale,Declarations!$G$35,0) -> 100 | L45: =Declarations!$C$36+(Declarations!$C$7-Declarations!$C$36)*EXP(-Declarations!$D$36*$B45)+IF(Declarations!$E$36=0,0,Declarations!$E$36*($B45/Declarations!$F$36)*EXP(1-$B45/Declarations!$F$36))+IF($B45>=T_sale,Declarations!$G$36,0) -> 41 | M45: =Declarations!$C$37+(Declarations!$C$8-Declarations!$C$37)*EXP(-Declarations!$D$37*$B45)+IF(Declarations!$E$37=0,0,Declarations!$E$37*($B45/Declarations!$F$37)*EXP(1-$B45/Declarations!$F$37))+IF($B45>=T_sale,Declarations!$G$37,0) -> 71 | N45: =Declarations!$C$38+(Declarations!$C$10-Declarations!$C$38)*EXP(-Declarations!$D$38*$B45)+IF(Declarations!$E$38=0,0,Declarations!$E$38*($B45/Declarations!$F$38)*EXP(1-$B45/Declarations!$F$38))+IF($B45>=T_sale,Declarations!$G$38,0) -> 64 | O45: =C45*USD_pt -> 620 | P45: =C45*USD_pt-Floor_usd -> 270 | Q45: =Risk_ceiling-F45 -> 11 | R45: =MIN(Wf_today-Idx_lo,Idx_hi-Wf_today,D45-Idx_lo,Idx_hi-D45,E45-Idx_lo,Idx_hi-E45,F45-Idx_lo,Idx_hi-F45) -> 29 | S45: =G45*USD_pt -> 620 | T45: =G45*USD_pt-Floor_usd -> 270 | U45: =Risk_ceiling-J45 -> 11 | V45: =MIN(Wf_today-Idx_lo,Idx_hi-Wf_today,H45-Idx_lo,Idx_hi-H45,I45-Idx_lo,Idx_hi-I45,J45-Idx_lo,Idx_hi-J45) -> 29 | W45: =K45*USD_pt -> 620 | X45: =K45*USD_pt-Floor_usd -> 270 | Y45: =Risk_ceiling-N45 -> 11 | Z45: =MIN(Wf_today-Idx_lo,Idx_hi-Wf_today,L45-Idx_lo,Idx_hi-L45,M45-Idx_lo,Idx_hi-M45,N45-Idx_lo,Idx_hi-N45) -> 29
A46: 1 | B46: =A46/12 -> 0.083333333 | C46: =Declarations!$C$27+(Declarations!$C$4-Declarations!$C$27)*EXP(-Declarations!$D$27*$B46)+IF(Declarations!$E$27=0,0,Declarations!$E$27*($B46/Declarations!$F$27)*EXP(1-$B46/Declarations!$F$27))+IF($B46>=T_sale,Declarations!$G$27,0) -> 97.30304 | D46: =Declarations!$C$28+(Declarations!$C$7-Declarations!$C$28)*EXP(-Declarations!$D$28*$B46)+IF(Declarations!$E$28=0,0,Declarations!$E$28*($B46/Declarations!$F$28)*EXP(1-$B46/Declarations!$F$28))+IF($B46>=T_sale,Declarations!$G$28,0) -> 42.657557 | E46: =Declarations!$C$29+(Declarations!$C$8-Declarations!$C$29)*EXP(-Declarations!$D$29*$B46)+IF(Declarations!$E$29=0,0,Declarations!$E$29*($B46/Declarations!$F$29)*EXP(1-$B46/Declarations!$F$29))+IF($B46>=T_sale,Declarations!$G$29,0) -> 69.959171 | F46: =Declarations!$C$30+(Declarations!$C$10-Declarations!$C$30)*EXP(-Declarations!$D$30*$B46)+IF(Declarations!$E$30=0,0,Declarations!$E$30*($B46/Declarations!$F$30)*EXP(1-$B46/Declarations!$F$30))+IF($B46>=T_sale,Declarations!$G$30,0) -> 66.039285 | G46: =Declarations!$C$31+(Declarations!$C$4-Declarations!$C$31)*EXP(-Declarations!$D$31*$B46)+IF(Declarations!$E$31=0,0,Declarations!$E$31*($B46/Declarations!$F$31)*EXP(1-$B46/Declarations!$F$31))+IF($B46>=T_sale,Declarations!$G$31,0) -> 100.09876 | H46: =Declarations!$C$32+(Declarations!$C$7-Declarations!$C$32)*EXP(-Declarations!$D$32*$B46)+IF(Declarations!$E$32=0,0,Declarations!$E$32*($B46/Declarations!$F$32)*EXP(1-$B46/Declarations!$F$32))+IF($B46>=T_sale,Declarations!$G$32,0) -> 40.938147 | I46: =Declarations!$C$33+(Declarations!$C$8-Declarations!$C$33)*EXP(-Declarations!$D$33*$B46)+IF(Declarations!$E$33=0,0,Declarations!$E$33*($B46/Declarations!$F$33)*EXP(1-$B46/Declarations!$F$33))+IF($B46>=T_sale,Declarations!$G$33,0) -> 71.110417 | J46: =Declarations!$C$34+(Declarations!$C$10-Declarations!$C$34)*EXP(-Declarations!$D$34*$B46)+IF(Declarations!$E$34=0,0,Declarations!$E$34*($B46/Declarations!$F$34)*EXP(1-$B46/Declarations!$F$34))+IF($B46>=T_sale,Declarations!$G$34,0) -> 63.770037 | K46: =Declarations!$C$35+(Declarations!$C$4-Declarations!$C$35)*EXP(-Declarations!$D$35*$B46)+IF(Declarations!$E$35=0,0,Declarations!$E$35*($B46/Declarations!$F$35)*EXP(1-$B46/Declarations!$F$35))+IF($B46>=T_sale,Declarations!$G$35,0) -> 100.22083 | L46: =Declarations!$C$36+(Declarations!$C$7-Declarations!$C$36)*EXP(-Declarations!$D$36*$B46)+IF(Declarations!$E$36=0,0,Declarations!$E$36*($B46/Declarations!$F$36)*EXP(1-$B46/Declarations!$F$36))+IF($B46>=T_sale,Declarations!$G$36,0) -> 40.867772 | M46: =Declarations!$C$37+(Declarations!$C$8-Declarations!$C$37)*EXP(-Declarations!$D$37*$B46)+IF(Declarations!$E$37=0,0,Declarations!$E$37*($B46/Declarations!$F$37)*EXP(1-$B46/Declarations!$F$37))+IF($B46>=T_sale,Declarations!$G$37,0) -> 71.390165 | N46: =Declarations!$C$38+(Declarations!$C$10-Declarations!$C$38)*EXP(-Declarations!$D$38*$B46)+IF(Declarations!$E$38=0,0,Declarations!$E$38*($B46/Declarations!$F$38)*EXP(1-$B46/Declarations!$F$38))+IF($B46>=T_sale,Declarations!$G$38,0) -> 64.07407 | O46: =C46*USD_pt -> 603.27885 | P46: =C46*USD_pt-Floor_usd -> 253.27885 | Q46: =Risk_ceiling-F46 -> 8.9607152 | R46: =MIN(Wf_today-Idx_lo,Idx_hi-Wf_today,D46-Idx_lo,Idx_hi-D46,E46-Idx_lo,Idx_hi-E46,F46-Idx_lo,Idx_hi-F46) -> 30.040829 | S46: =G46*USD_pt -> 620.61231 | T46: =G46*USD_pt-Floor_usd -> 270.61231 | U46: =Risk_ceiling-J46 -> 11.229963 | V46: =MIN(Wf_today-Idx_lo,Idx_hi-Wf_today,H46-Idx_lo,Idx_hi-H46,I46-Idx_lo,Idx_hi-I46,J46-Idx_lo,Idx_hi-J46) -> 28.889583 | W46: =K46*USD_pt -> 621.36917 | X46: =K46*USD_pt-Floor_usd -> 271.36917 | Y46: =Risk_ceiling-N46 -> 10.92593 | Z46: =MIN(Wf_today-Idx_lo,Idx_hi-Wf_today,L46-Idx_lo,Idx_hi-L46,M46-Idx_lo,Idx_hi-M46,N46-Idx_lo,Idx_hi-N46) -> 28.609835
...

Sheet Blend
A1: A wall that is not convex: blending two configurations (Theorem 5.2(iii); Figure 5.1; Theorem 5.5; AXIOM Lab 1.5, step 2)
A3: Configuration | B3: Legacy platform | C3: New platform
A4: A | B4: 80 | C4: 10
A5: B | B5: 0 | C5: 90
A6: Capacity budget: legacy + new at most | B6: 100
A7: Minimum efficient scale: legacy 0 or at least | B7: 60
A9: Weight on A | B9: Legacy | C9: New | D9: Budget slack | E9: Minimum-scale g = min(legacy, 60 - legacy) | F9: Under the budget alone | G9: With the minimum scale
A10: 0 | B10: =A10*$B$4+(1-A10)*$B$5 -> 0 | C10: =A10*$C$4+(1-A10)*$C$5 -> 90 | D10: =$B$6-B10-C10 -> 10 | E10: =MIN(B10,$B$7-B10) -> 0 | F10: =IF(AND(D10>=-0.000000001,B10>=0,C10>=0),"feasible","infeasible") -> feasible | G10: =IF(AND(F10="feasible",E10<=0.000000001),"feasible","infeasible") -> feasible
A11: 0.05 | B11: =A11*$B$4+(1-A11)*$B$5 -> 4 | C11: =A11*$C$4+(1-A11)*$C$5 -> 86 | D11: =$B$6-B11-C11 -> 10 | E11: =MIN(B11,$B$7-B11) -> 4 | F11: =IF(AND(D11>=-0.000000001,B11>=0,C11>=0),"feasible","infeasible") -> feasible | G11: =IF(AND(F11="feasible",E11<=0.000000001),"feasible","infeasible") -> infeasible
A12: 0.1 | B12: =A12*$B$4+(1-A12)*$B$5 -> 8 | C12: =A12*$C$4+(1-A12)*$C$5 -> 82 | D12: =$B$6-B12-C12 -> 10 | E12: =MIN(B12,$B$7-B12) -> 8 | F12: =IF(AND(D12>=-0.000000001,B12>=0,C12>=0),"feasible","infeasible") -> feasible | G12: =IF(AND(F12="feasible",E12<=0.000000001),"feasible","infeasible") -> infeasible
A13: 0.15 | B13: =A13*$B$4+(1-A13)*$B$5 -> 12 | C13: =A13*$C$4+(1-A13)*$C$5 -> 78 | D13: =$B$6-B13-C13 -> 10 | E13: =MIN(B13,$B$7-B13) -> 12 | F13: =IF(AND(D13>=-0.000000001,B13>=0,C13>=0),"feasible","infeasible") -> feasible | G13: =IF(AND(F13="feasible",E13<=0.000000001),"feasible","infeasible") -> infeasible
A14: 0.2 | B14: =A14*$B$4+(1-A14)*$B$5 -> 16 | C14: =A14*$C$4+(1-A14)*$C$5 -> 74 | D14: =$B$6-B14-C14 -> 10 | E14: =MIN(B14,$B$7-B14) -> 16 | F14: =IF(AND(D14>=-0.000000001,B14>=0,C14>=0),"feasible","infeasible") -> feasible | G14: =IF(AND(F14="feasible",E14<=0.000000001),"feasible","infeasible") -> infeasible
A15: 0.25 | B15: =A15*$B$4+(1-A15)*$B$5 -> 20 | C15: =A15*$C$4+(1-A15)*$C$5 -> 70 | D15: =$B$6-B15-C15 -> 10 | E15: =MIN(B15,$B$7-B15) -> 20 | F15: =IF(AND(D15>=-0.000000001,B15>=0,C15>=0),"feasible","infeasible") -> feasible | G15: =IF(AND(F15="feasible",E15<=0.000000001),"feasible","infeasible") -> infeasible
A16: 0.3 | B16: =A16*$B$4+(1-A16)*$B$5 -> 24 | C16: =A16*$C$4+(1-A16)*$C$5 -> 66 | D16: =$B$6-B16-C16 -> 10 | E16: =MIN(B16,$B$7-B16) -> 24 | F16: =IF(AND(D16>=-0.000000001,B16>=0,C16>=0),"feasible","infeasible") -> feasible | G16: =IF(AND(F16="feasible",E16<=0.000000001),"feasible","infeasible") -> infeasible
A17: 0.35 | B17: =A17*$B$4+(1-A17)*$B$5 -> 28 | C17: =A17*$C$4+(1-A17)*$C$5 -> 62 | D17: =$B$6-B17-C17 -> 10 | E17: =MIN(B17,$B$7-B17) -> 28 | F17: =IF(AND(D17>=-0.000000001,B17>=0,C17>=0),"feasible","infeasible") -> feasible | G17: =IF(AND(F17="feasible",E17<=0.000000001),"feasible","infeasible") -> infeasible
A18: 0.4 | B18: =A18*$B$4+(1-A18)*$B$5 -> 32 | C18: =A18*$C$4+(1-A18)*$C$5 -> 58 | D18: =$B$6-B18-C18 -> 10 | E18: =MIN(B18,$B$7-B18) -> 28 | F18: =IF(AND(D18>=-0.000000001,B18>=0,C18>=0),"feasible","infeasible") -> feasible | G18: =IF(AND(F18="feasible",E18<=0.000000001),"feasible","infeasible") -> infeasible
A19: 0.45 | B19: =A19*$B$4+(1-A19)*$B$5 -> 36 | C19: =A19*$C$4+(1-A19)*$C$5 -> 54 | D19: =$B$6-B19-C19 -> 10 | E19: =MIN(B19,$B$7-B19) -> 24 | F19: =IF(AND(D19>=-0.000000001,B19>=0,C19>=0),"feasible","infeasible") -> feasible | G19: =IF(AND(F19="feasible",E19<=0.000000001),"feasible","infeasible") -> infeasible
A20: 0.5 | B20: =A20*$B$4+(1-A20)*$B$5 -> 40 | C20: =A20*$C$4+(1-A20)*$C$5 -> 50 | D20: =$B$6-B20-C20 -> 10 | E20: =MIN(B20,$B$7-B20) -> 20 | F20: =IF(AND(D20>=-0.000000001,B20>=0,C20>=0),"feasible","infeasible") -> feasible | G20: =IF(AND(F20="feasible",E20<=0.000000001),"feasible","infeasible") -> infeasible
A21: 0.55 | B21: =A21*$B$4+(1-A21)*$B$5 -> 44 | C21: =A21*$C$4+(1-A21)*$C$5 -> 46 | D21: =$B$6-B21-C21 -> 10 | E21: =MIN(B21,$B$7-B21) -> 16 | F21: =IF(AND(D21>=-0.000000001,B21>=0,C21>=0),"feasible","infeasible") -> feasible | G21: =IF(AND(F21="feasible",E21<=0.000000001),"feasible","infeasible") -> infeasible
... A30: 1 | B30: =A30*$B$4+(1-A30)*$B$5 -> 80 | C30: =A30*$C$4+(1-A30)*$C$5 -> 10 | D30: =$B$6-B30-C30 -> 10 | E30: =MIN(B30,$B$7-B30) -> -20 | F30: =IF(AND(D30>=-0.000000001,B30>=0,C30>=0),"feasible","infeasible") -> feasible | G30: =IF(AND(F30="feasible",E30<=0.000000001),"feasible","infeasible") -> feasible
A32: Blends feasible under the budget alone (of 21) | B32: =COUNTIF(F10:F30,"feasible") -> 21
A33: Blends feasible with the minimum scale (of 21) | B33: =COUNTIF(G10:G30,"feasible") -> 7
A34: Minimum-scale g at the 50/50 blend (legacy 40, new 50) | B34: =E20 -> 20
A35: Smallest positive weight on A that is feasible: 60 / 80 | B35: =B7/B4 -> 0.75
A36: Both pure configurations are feasible; the 50/50 blend runs legacy at 40, too small to run economically and too large to have been shut (Section 5.4).
A38: Theorem 5.5: k | B38: Leverage 4.5 - 1/k | C38: Weak covenant (at most 4.5) | D38: Strict covenant (below 4.5)
A39: 1 | B39: =Covenant-1/A39 -> 3.5 | C39: =IF(B39<=Covenant,"feasible","infeasible") -> feasible | D39: =IF(B39<Covenant,"feasible","infeasible") -> feasible
A40: 2 | B40: =Covenant-1/A40 -> 4 | C40: =IF(B40<=Covenant,"feasible","infeasible") -> feasible | D40: =IF(B40<Covenant,"feasible","infeasible") -> feasible
A41: 3 | B41: =Covenant-1/A41 -> 4.1666667 | C41: =IF(B41<=Covenant,"feasible","infeasible") -> feasible | D41: =IF(B41<Covenant,"feasible","infeasible") -> feasible
A42: 4 | B42: =Covenant-1/A42 -> 4.25 | C42: =IF(B42<=Covenant,"feasible","infeasible") -> feasible | D42: =IF(B42<Covenant,"feasible","infeasible") -> feasible
A43: 5 | B43: =Covenant-1/A43 -> 4.3 | C43: =IF(B43<=Covenant,"feasible","infeasible") -> feasible | D43: =IF(B43<Covenant,"feasible","infeasible") -> feasible
A44: 6 | B44: =Covenant-1/A44 -> 4.3333333 | C44: =IF(B44<=Covenant,"feasible","infeasible") -> feasible | D44: =IF(B44<Covenant,"feasible","infeasible") -> feasible
A45: the limit | B45: =Covenant -> 4.5 | C45: =IF(B45<=Covenant,"feasible","infeasible") -> feasible | D45: =IF(B45<Covenant,"feasible","infeasible") -> infeasible
A46: Written strictly, the covenant excludes the state in which it binds: feasible states converge to an infeasible limit, and no feasible state is the most levered (Theorem 5.5(iii)).

Sheet PathSampling
A1: Sample a path: the digital program's liquidity quarter by quarter and half-year by half-year (Definition 5.6; Propositions 5.3-5.4; Figure 5.2; AXIOM Lab 1.5, step 3)
A2: Equation 1.B.1 as a system in three numbers, (x, z1, z2): z2 is the trough term, z1 drives it, and x - z2 relaxes toward the target. The step over a spacing d is exact: y = x - z2 becomes T + (y - T)e^(-kd); z1 becomes z1 e^(-d/tau); z2 becomes (z2 + d z1)e^(-d/tau); x is the new y plus the new z2.
A4: Parameter | B4: Value | I4: Proposition 5.3 | J4: Value
A5: Target T | B5: =Declarations!C27 -> 112 | I5: Phases join at year 2 (liquidity index) | J5: =C23 -> 78.040976
A6: Speed k (a year) | B6: =Declarations!D27 -> 0.35 | I6: Largest |quarterly steps - closed form| | J6: =MAX(G15:G35) -> 0
A7: Trough (sign x depth) D | B7: =Declarations!E27 -> -28 | I7: Largest |half-yearly - two quarterly steps| | J7: =MAX(O15:O25) -> 0
A8: Trough time tau (years) | B8: =Declarations!F27 -> 2 | I8: Largest |build + scale-up - whole path| | J8: =MAX(G39:G51) -> 0
A9: Liquidity today (index) | B9: =Liq_today -> 100 | I9: Twenty quarters back: today's liquidity | J9: =C75 -> 100
A10: z1 at the start, D e / tau | B10: =B7*EXP(1)/B8 -> -38.055946 | I10: Lowest quarterly reading (index) | J10: =MIN(C15:C35) -> 77.733933
A11: A quarter (years) | B11: 0.25
A12: A half-year (years) | B12: 0.5
A14: Quarter | B14: t (years) | C14: x: liquidity | D14: z1 | E14: z2 | F14: Chapter 1's closed form | G14: |difference| | I14: Half-year | J14: t (years) | K14: x: liquidity | L14: z1 | M14: z2 | N14: Two quarterly steps: x | O14: |difference|
A15: 0 | B15: =A15*$B$11 -> 0 | C15: =B9 -> 100 | D15: =B10 -> -38.055946 | E15: 0 | F15: =Declarations!$C$27+(Declarations!$C$4-Declarations!$C$27)*EXP(-Declarations!$D$27*B15)+IF(Declarations!$E$27=0,0,Declarations!$E$27*(B15/Declarations!$F$27)*EXP(1-B15/Declarations!$F$27))+IF(B15>=T_sale,Declarations!$G$27,0) -> 100 | G15: =ABS(C15-F15) -> 0 | I15: 0 | J15: =I15*$B$12 -> 0 | K15: =B9 -> 100 | L15: =B10 -> -38.055946 | M15: 0 | N15: =INDEX($C$15:$C$35,2*I15+1) -> 100 | O15: =MAX(ABS(K15-N15),ABS(L15-INDEX($D$15:$D$35,2*I15+1)),ABS(M15-INDEX($E$15:$E$35,2*I15+1))) -> 0
A16: 1 | B16: =A16*$B$11 -> 0.25 | C16: =$B$5+(C15-E15-$B$5)*EXP(-$B$6*$B$11)+(E15+$B$11*D15)*EXP(-$B$11/$B$8) -> 92.60931 | D16: =D15*EXP(-$B$11/$B$8) -> -33.584254 | E16: =(E15+$B$11*D15)*EXP(-$B$11/$B$8) -> -8.3960635 | F16: =Declarations!$C$27+(Declarations!$C$4-Declarations!$C$27)*EXP(-Declarations!$D$27*B16)+IF(Declarations!$E$27=0,0,Declarations!$E$27*(B16/Declarations!$F$27)*EXP(1-B16/Declarations!$F$27))+IF(B16>=T_sale,Declarations!$G$27,0) -> 92.60931 | G16: =ABS(C16-F16) -> 0 | I16: 1 | J16: =I16*$B$12 -> 0.5 | K16: =$B$5+(K15-M15-$B$5)*EXP(-$B$6*$B$12)+(M15+$B$12*L15)*EXP(-$B$12/$B$8) -> 87.107516 | L16: =L15*EXP(-$B$12/$B$8) -> -29.638 | M16: =(M15+$B$12*L15)*EXP(-$B$12/$B$8) -> -14.819 | N16: =INDEX($C$15:$C$35,2*I16+1) -> 87.107516 | O16: =MAX(ABS(K16-N16),ABS(L16-INDEX($D$15:$D$35,2*I16+1)),ABS(M16-INDEX($E$15:$E$35,2*I16+1))) -> 0
A17: 2 | B17: =A17*$B$11 -> 0.5 | C17: =$B$5+(C16-E16-$B$5)*EXP(-$B$6*$B$11)+(E16+$B$11*D16)*EXP(-$B$11/$B$8) -> 87.107516 | D17: =D16*EXP(-$B$11/$B$8) -> -29.638 | E17: =(E16+$B$11*D16)*EXP(-$B$11/$B$8) -> -14.819 | F17: =Declarations!$C$27+(Declarations!$C$4-Declarations!$C$27)*EXP(-Declarations!$D$27*B17)+IF(Declarations!$E$27=0,0,Declarations!$E$27*(B17/Declarations!$F$27)*EXP(1-B17/Declarations!$F$27))+IF(B17>=T_sale,Declarations!$G$27,0) -> 87.107516 | G17: =ABS(C17-F17) -> 0 | I17: 2 | J17: =I17*$B$12 -> 1 | K17: =$B$5+(K16-M16-$B$5)*EXP(-$B$6*$B$12)+(M16+$B$12*L16)*EXP(-$B$12/$B$8) -> 80.461645 | L17: =L16*EXP(-$B$12/$B$8) -> -23.082098 | M17: =(M16+$B$12*L16)*EXP(-$B$12/$B$8) -> -23.082098 | N17: =INDEX($C$15:$C$35,2*I17+1) -> 80.461645 | O17: =MAX(ABS(K17-N17),ABS(L17-INDEX($D$15:$D$35,2*I17+1)),ABS(M17-INDEX($E$15:$E$35,2*I17+1))) -> 0
A18: 3 | B18: =A18*$B$11 -> 0.75 | C18: =$B$5+(C17-E17-$B$5)*EXP(-$B$6*$B$11)+(E17+$B$11*D17)*EXP(-$B$11/$B$8) -> 83.153901 | D18: =D17*EXP(-$B$11/$B$8) -> -26.155443 | E18: =(E17+$B$11*D17)*EXP(-$B$11/$B$8) -> -19.616583 | F18: =Declarations!$C$27+(Declarations!$C$4-Declarations!$C$27)*EXP(-Declarations!$D$27*B18)+IF(Declarations!$E$27=0,0,Declarations!$E$27*(B18/Declarations!$F$27)*EXP(1-B18/Declarations!$F$27))+IF(B18>=T_sale,Declarations!$G$27,0) -> 83.153901 | G18: =ABS(C18-F18) -> 0 | I18: 3 | J18: =I18*$B$12 -> 1.5 | K18: =$B$5+(K17-M17-$B$5)*EXP(-$B$6*$B$12)+(M17+$B$12*L17)*EXP(-$B$12/$B$8) -> 77.936802 | L18: =L17*EXP(-$B$12/$B$8) -> -17.976356 | M18: =(M17+$B$12*L17)*EXP(-$B$12/$B$8) -> -26.964534 | N18: =INDEX($C$15:$C$35,2*I18+1) -> 77.936802 | O18: =MAX(ABS(K18-N18),ABS(L18-INDEX($D$15:$D$35,2*I18+1)),ABS(M18-INDEX($E$15:$E$35,2*I18+1))) -> 0
A19: 4 | B19: =A19*$B$11 -> 1 | C19: =$B$5+(C18-E18-$B$5)*EXP(-$B$6*$B$11)+(E18+$B$11*D18)*EXP(-$B$11/$B$8) -> 80.461645 | D19: =D18*EXP(-$B$11/$B$8) -> -23.082098 | E19: =(E18+$B$11*D18)*EXP(-$B$11/$B$8) -> -23.082098 | F19: =Declarations!$C$27+(Declarations!$C$4-Declarations!$C$27)*EXP(-Declarations!$D$27*B19)+IF(Declarations!$E$27=0,0,Declarations!$E$27*(B19/Declarations!$F$27)*EXP(1-B19/Declarations!$F$27))+IF(B19>=T_sale,Declarations!$G$27,0) -> 80.461645 | G19: =ABS(C19-F19) -> 0 | I19: 4 | J19: =I19*$B$12 -> 2 | K19: =$B$5+(K18-M18-$B$5)*EXP(-$B$6*$B$12)+(M18+$B$12*L18)*EXP(-$B$12/$B$8) -> 78.040976 | L19: =L18*EXP(-$B$12/$B$8) -> -14 | M19: =(M18+$B$12*L18)*EXP(-$B$12/$B$8) -> -28 | N19: =INDEX($C$15:$C$35,2*I19+1) -> 78.040976 | O19: =MAX(ABS(K19-N19),ABS(L19-INDEX($D$15:$D$35,2*I19+1)),ABS(M19-INDEX($E$15:$E$35,2*I19+1))) -> 0
A20: 5 | B20: =A20*$B$11 -> 1.25 | C20: =$B$5+(C19-E19-$B$5)*EXP(-$B$6*$B$11)+(E19+$B$11*D19)*EXP(-$B$11/$B$8) -> 78.789868 | D20: =D19*EXP(-$B$11/$B$8) -> -20.36988 | E20: =(E19+$B$11*D19)*EXP(-$B$11/$B$8) -> -25.46235 | F20: =Declarations!$C$27+(Declarations!$C$4-Declarations!$C$27)*EXP(-Declarations!$D$27*B20)+IF(Declarations!$E$27=0,0,Declarations!$E$27*(B20/Declarations!$F$27)*EXP(1-B20/Declarations!$F$27))+IF(B20>=T_sale,Declarations!$G$27,0) -> 78.789868 | G20: =ABS(C20-F20) -> 0 | I20: 5 | J20: =I20*$B$12 -> 2.5 | K20: =$B$5+(K19-M19-$B$5)*EXP(-$B$6*$B$12)+(M19+$B$12*L19)*EXP(-$B$12/$B$8) -> 79.739628 | L20: =L19*EXP(-$B$12/$B$8) -> -10.903211 | M20: =(M19+$B$12*L19)*EXP(-$B$12/$B$8) -> -27.258027 | N20: =INDEX($C$15:$C$35,2*I20+1) -> 79.739628 | O20: =MAX(ABS(K20-N20),ABS(L20-INDEX($D$15:$D$35,2*I20+1)),ABS(M20-INDEX($E$15:$E$35,2*I20+1))) -> 0
A21: 6 | B21: =A21*$B$11 -> 1.5 | C21: =$B$5+(C20-E20-$B$5)*EXP(-$B$6*$B$11)+(E20+$B$11*D20)*EXP(-$B$11/$B$8) -> 77.936802 | D21: =D20*EXP(-$B$11/$B$8) -> -17.976356 | E21: =(E20+$B$11*D20)*EXP(-$B$11/$B$8) -> -26.964534 | F21: =Declarations!$C$27+(Declarations!$C$4-Declarations!$C$27)*EXP(-Declarations!$D$27*B21)+IF(Declarations!$E$27=0,0,Declarations!$E$27*(B21/Declarations!$F$27)*EXP(1-B21/Declarations!$F$27))+IF(B21>=T_sale,Declarations!$G$27,0) -> 77.936802 | G21: =ABS(C21-F21) -> 0 | I21: 6 | J21: =I21*$B$12 -> 3 | K21: =$B$5+(K20-M20-$B$5)*EXP(-$B$6*$B$12)+(M20+$B$12*L20)*EXP(-$B$12/$B$8) -> 82.326459 | L21: =L20*EXP(-$B$12/$B$8) -> -8.4914292 | M21: =(M20+$B$12*L20)*EXP(-$B$12/$B$8) -> -25.474288 | N21: =INDEX($C$15:$C$35,2*I21+1) -> 82.326459 | O21: =MAX(ABS(K21-N21),ABS(L21-INDEX($D$15:$D$35,2*I21+1)),ABS(M21-INDEX($E$15:$E$35,2*I21+1))) -> 0
A22: 7 | B22: =A22*$B$11 -> 1.75 | C22: =$B$5+(C21-E21-$B$5)*EXP(-$B$6*$B$11)+(E21+$B$11*D21)*EXP(-$B$11/$B$8) -> 77.733933 | D22: =D21*EXP(-$B$11/$B$8) -> -15.864078 | E22: =(E21+$B$11*D21)*EXP(-$B$11/$B$8) -> -27.762137 | F22: =Declarations!$C$27+(Declarations!$C$4-Declarations!$C$27)*EXP(-Declarations!$D$27*B22)+IF(Declarations!$E$27=0,0,Declarations!$E$27*(B22/Declarations!$F$27)*EXP(1-B22/Declarations!$F$27))+IF(B22>=T_sale,Declarations!$G$27,0) -> 77.733933 | G22: =ABS(C22-F22) -> 0 | I22: 7 | J22: =I22*$B$12 -> 3.5 | K22: =$B$5+(K21-M21-$B$5)*EXP(-$B$6*$B$12)+(M21+$B$12*L21)*EXP(-$B$12/$B$8) -> 85.328947 | L22: =L21*EXP(-$B$12/$B$8) -> -6.6131317 | M22: =(M21+$B$12*L21)*EXP(-$B$12/$B$8) -> -23.145961 | N22: =INDEX($C$15:$C$35,2*I22+1) -> 85.328947 | O22: =MAX(ABS(K22-N22),ABS(L22-INDEX($D$15:$D$35,2*I22+1)),ABS(M22-INDEX($E$15:$E$35,2*I22+1))) -> 0
A23: 8 | B23: =A23*$B$11 -> 2 | C23: =$B$5+(C22-E22-$B$5)*EXP(-$B$6*$B$11)+(E22+$B$11*D22)*EXP(-$B$11/$B$8) -> 78.040976 | D23: =D22*EXP(-$B$11/$B$8) -> -14 | E23: =(E22+$B$11*D22)*EXP(-$B$11/$B$8) -> -28 | F23: =Declarations!$C$27+(Declarations!$C$4-Declarations!$C$27)*EXP(-Declarations!$D$27*B23)+IF(Declarations!$E$27=0,0,Declarations!$E$27*(B23/Declarations!$F$27)*EXP(1-B23/Declarations!$F$27))+IF(B23>=T_sale,Declarations!$G$27,0) -> 78.040976 | G23: =ABS(C23-F23) -> 0 | I23: 8 | J23: =I23*$B$12 -> 4 | K23: =$B$5+(K22-M22-$B$5)*EXP(-$B$6*$B$12)+(M22+$B$12*L22)*EXP(-$B$12/$B$8) -> 88.439588 | L23: =L22*EXP(-$B$12/$B$8) -> -5.1503122 | M23: =(M22+$B$12*L22)*EXP(-$B$12/$B$8) -> -20.601249 | N23: =INDEX($C$15:$C$35,2*I23+1) -> 88.439588 | O23: =MAX(ABS(K23-N23),ABS(L23-INDEX($D$15:$D$35,2*I23+1)),ABS(M23-INDEX($E$15:$E$35,2*I23+1))) -> 0
A24: 9 | B24: =A24*$B$11 -> 2.25 | C24: =$B$5+(C23-E23-$B$5)*EXP(-$B$6*$B$11)+(E23+$B$11*D23)*EXP(-$B$11/$B$8) -> 78.741578 | D24: =D23*EXP(-$B$11/$B$8) -> -12.354957 | E24: =(E23+$B$11*D23)*EXP(-$B$11/$B$8) -> -27.798652 | F24: =Declarations!$C$27+(Declarations!$C$4-Declarations!$C$27)*EXP(-Declarations!$D$27*B24)+IF(Declarations!$E$27=0,0,Declarations!$E$27*(B24/Declarations!$F$27)*EXP(1-B24/Declarations!$F$27))+IF(B24>=T_sale,Declarations!$G$27,0) -> 78.741578 | G24: =ABS(C24-F24) -> 0 | I24: 9 | J24: =I24*$B$12 -> 4.5 | K24: =$B$5+(K23-M23-$B$5)*EXP(-$B$6*$B$12)+(M23+$B$12*L23)*EXP(-$B$12/$B$8) -> 91.466107 | L24: =L23*EXP(-$B$12/$B$8) -> -4.0110672 | M24: =(M23+$B$12*L23)*EXP(-$B$12/$B$8) -> -18.049802 | N24: =INDEX($C$15:$C$35,2*I24+1) -> 91.466107 | O24: =MAX(ABS(K24-N24),ABS(L24-INDEX($D$15:$D$35,2*I24+1)),ABS(M24-INDEX($E$15:$E$35,2*I24+1))) -> 0
A25: 10 | B25: =A25*$B$11 -> 2.5 | C25: =$B$5+(C24-E24-$B$5)*EXP(-$B$6*$B$11)+(E24+$B$11*D24)*EXP(-$B$11/$B$8) -> 79.739628 | D25: =D24*EXP(-$B$11/$B$8) -> -10.903211 | E25: =(E24+$B$11*D24)*EXP(-$B$11/$B$8) -> -27.258027 | F25: =Declarations!$C$27+(Declarations!$C$4-Declarations!$C$27)*EXP(-Declarations!$D$27*B25)+IF(Declarations!$E$27=0,0,Declarations!$E$27*(B25/Declarations!$F$27)*EXP(1-B25/Declarations!$F$27))+IF(B25>=T_sale,Declarations!$G$27,0) -> 79.739628 | G25: =ABS(C25-F25) -> 0 | I25: 10 | J25: =I25*$B$12 -> 5 | K25: =$B$5+(K24-M24-$B$5)*EXP(-$B$6*$B$12)+(M24+$B$12*L24)*EXP(-$B$12/$B$8) -> 94.295601 | L25: =L24*EXP(-$B$12/$B$8) -> -3.1238222 | M25: =(M24+$B$12*L24)*EXP(-$B$12/$B$8) -> -15.619111 | N25: =INDEX($C$15:$C$35,2*I25+1) -> 94.295601 | O25: =MAX(ABS(K25-N25),ABS(L25-INDEX($D$15:$D$35,2*I25+1)),ABS(M25-INDEX($E$15:$E$35,2*I25+1))) -> 0
A26: 11 | B26: =A26*$B$11 -> 2.75 | C26: =$B$5+(C25-E25-$B$5)*EXP(-$B$6*$B$11)+(E25+$B$11*D25)*EXP(-$B$11/$B$8) -> 80.956121 | D26: =D25*EXP(-$B$11/$B$8) -> -9.6220499 | E26: =(E25+$B$11*D25)*EXP(-$B$11/$B$8) -> -26.460637 | F26: =Declarations!$C$27+(Declarations!$C$4-Declarations!$C$27)*EXP(-Declarations!$D$27*B26)+IF(Declarations!$E$27=0,0,Declarations!$E$27*(B26/Declarations!$F$27)*EXP(1-B26/Declarations!$F$27))+IF(B26>=T_sale,Declarations!$G$27,0) -> 80.956121 | G26: =ABS(C26-F26) -> 0
A27: 12 | B27: =A27*$B$11 -> 3 | C27: =$B$5+(C26-E26-$B$5)*EXP(-$B$6*$B$11)+(E26+$B$11*D26)*EXP(-$B$11/$B$8) -> 82.326459 | D27: =D26*EXP(-$B$11/$B$8) -> -8.4914292 | E27: =(E26+$B$11*D26)*EXP(-$B$11/$B$8) -> -25.474288 | F27: =Declarations!$C$27+(Declarations!$C$4-Declarations!$C$27)*EXP(-Declarations!$D$27*B27)+IF(Declarations!$E$27=0,0,Declarations!$E$27*(B27/Declarations!$F$27)*EXP(1-B27/Declarations!$F$27))+IF(B27>=T_sale,Declarations!$G$27,0) -> 82.326459 | G27: =ABS(C27-F27) -> 0
A28: 13 | B28: =A28*$B$11 -> 3.25 | C28: =$B$5+(C27-E27-$B$5)*EXP(-$B$6*$B$11)+(E27+$B$11*D27)*EXP(-$B$11/$B$8) -> 83.79817 | D28: =D27*EXP(-$B$11/$B$8) -> -7.49366 | E28: =(E27+$B$11*D27)*EXP(-$B$11/$B$8) -> -24.354395 | F28: =Declarations!$C$27+(Declarations!$C$4-Declarations!$C$27)*EXP(-Declarations!$D$27*B28)+IF(Declarations!$E$27=0,0,Declarations!$E$27*(B28/Declarations!$F$27)*EXP(1-B28/Declarations!$F$27))+IF(B28>=T_sale,Declarations!$G$27,0) -> 83.79817 | G28: =ABS(C28-F28) -> 0
A29: 14 | B29: =A29*$B$11 -> 3.5 | C29: =$B$5+(C28-E28-$B$5)*EXP(-$B$6*$B$11)+(E28+$B$11*D28)*EXP(-$B$11/$B$8) -> 85.328947 | D29: =D28*EXP(-$B$11/$B$8) -> -6.6131317 | E29: =(E28+$B$11*D28)*EXP(-$B$11/$B$8) -> -23.145961 | F29: =Declarations!$C$27+(Declarations!$C$4-Declarations!$C$27)*EXP(-Declarations!$D$27*B29)+IF(Declarations!$E$27=0,0,Declarations!$E$27*(B29/Declarations!$F$27)*EXP(1-B29/Declarations!$F$27))+IF(B29>=T_sale,Declarations!$G$27,0) -> 85.328947 | G29: =ABS(C29-F29) -> 0
A30: 15 | B30: =A30*$B$11 -> 3.75 | C30: =$B$5+(C29-E29-$B$5)*EXP(-$B$6*$B$11)+(E29+$B$11*D29)*EXP(-$B$11/$B$8) -> 86.884988 | D30: =D29*EXP(-$B$11/$B$8) -> -5.8360683 | E30: =(E29+$B$11*D29)*EXP(-$B$11/$B$8) -> -21.885256 | F30: =Declarations!$C$27+(Declarations!$C$4-Declarations!$C$27)*EXP(-Declarations!$D$27*B30)+IF(Declarations!$E$27=0,0,Declarations!$E$27*(B30/Declarations!$F$27)*EXP(1-B30/Declarations!$F$27))+IF(B30>=T_sale,Declarations!$G$27,0) -> 86.884988 | G30: =ABS(C30-F30) -> 0
A31: 16 | B31: =A31*$B$11 -> 4 | C31: =$B$5+(C30-E30-$B$5)*EXP(-$B$6*$B$11)+(E30+$B$11*D30)*EXP(-$B$11/$B$8) -> 88.439588 | D31: =D30*EXP(-$B$11/$B$8) -> -5.1503122 | E31: =(E30+$B$11*D30)*EXP(-$B$11/$B$8) -> -20.601249 | F31: =Declarations!$C$27+(Declarations!$C$4-Declarations!$C$27)*EXP(-Declarations!$D$27*B31)+IF(Declarations!$E$27=0,0,Declarations!$E$27*(B31/Declarations!$F$27)*EXP(1-B31/Declarations!$F$27))+IF(B31>=T_sale,Declarations!$G$27,0) -> 88.439588 | G31: =ABS(C31-F31) -> 0
A32: 17 | B32: =A32*$B$11 -> 4.25 | C32: =$B$5+(C31-E31-$B$5)*EXP(-$B$6*$B$11)+(E31+$B$11*D31)*EXP(-$B$11/$B$8) -> 89.971937 | D32: =D31*EXP(-$B$11/$B$8) -> -4.5451345 | E32: =(E31+$B$11*D31)*EXP(-$B$11/$B$8) -> -19.316822 | F32: =Declarations!$C$27+(Declarations!$C$4-Declarations!$C$27)*EXP(-Declarations!$D$27*B32)+IF(Declarations!$E$27=0,0,Declarations!$E$27*(B32/Declarations!$F$27)*EXP(1-B32/Declarations!$F$27))+IF(B32>=T_sale,Declarations!$G$27,0) -> 89.971937 | G32: =ABS(C32-F32) -> 0
A33: 18 | B33: =A33*$B$11 -> 4.5 | C33: =$B$5+(C32-E32-$B$5)*EXP(-$B$6*$B$11)+(E32+$B$11*D32)*EXP(-$B$11/$B$8) -> 91.466107 | D33: =D32*EXP(-$B$11/$B$8) -> -4.0110672 | E33: =(E32+$B$11*D32)*EXP(-$B$11/$B$8) -> -18.049802 | F33: =Declarations!$C$27+(Declarations!$C$4-Declarations!$C$27)*EXP(-Declarations!$D$27*B33)+IF(Declarations!$E$27=0,0,Declarations!$E$27*(B33/Declarations!$F$27)*EXP(1-B33/Declarations!$F$27))+IF(B33>=T_sale,Declarations!$G$27,0) -> 91.466107 | G33: =ABS(C33-F33) -> 0
A34: 19 | B34: =A34*$B$11 -> 4.75 | C34: =$B$5+(C33-E33-$B$5)*EXP(-$B$6*$B$11)+(E33+$B$11*D33)*EXP(-$B$11/$B$8) -> 92.910196 | D34: =D33*EXP(-$B$11/$B$8) -> -3.5397543 | E34: =(E33+$B$11*D33)*EXP(-$B$11/$B$8) -> -16.813833 | F34: =Declarations!$C$27+(Declarations!$C$4-Declarations!$C$27)*EXP(-Declarations!$D$27*B34)+IF(Declarations!$E$27=0,0,Declarations!$E$27*(B34/Declarations!$F$27)*EXP(1-B34/Declarations!$F$27))+IF(B34>=T_sale,Declarations!$G$27,0) -> 92.910196 | G34: =ABS(C34-F34) -> 0
A35: 20 | B35: =A35*$B$11 -> 5 | C35: =$B$5+(C34-E34-$B$5)*EXP(-$B$6*$B$11)+(E34+$B$11*D34)*EXP(-$B$11/$B$8) -> 94.295601 | D35: =D34*EXP(-$B$11/$B$8) -> -3.1238222 | E35: =(E34+$B$11*D34)*EXP(-$B$11/$B$8) -> -15.619111 | F35: =Declarations!$C$27+(Declarations!$C$4-Declarations!$C$27)*EXP(-Declarations!$D$27*B35)+IF(Declarations!$E$27=0,0,Declarations!$E$27*(B35/Declarations!$F$27)*EXP(1-B35/Declarations!$F$27))+IF(B35>=T_sale,Declarations!$G$27,0) -> 94.295601 | G35: =ABS(C35-F35) -> 0
A38: Phase 2 from the build's end: quarter | B38: t (years) | C38: x: liquidity | D38: z1 | E38: z2 | F38: Whole path: x | G38: |difference|
A39: 8 | B39: =A39*$B$11 -> 2 | C39: =C23 -> 78.040976 | D39: =D23 -> -14 | E39: =E23 -> -28 | F39: =INDEX($C$15:$C$35,A39+1) -> 78.040976 | G39: =ABS(C39-F39) -> 0
A40: 9 | B40: =A40*$B$11 -> 2.25 | C40: =$B$5+(C39-E39-$B$5)*EXP(-$B$6*$B$11)+(E39+$B$11*D39)*EXP(-$B$11/$B$8) -> 78.741578 | D40: =D39*EXP(-$B$11/$B$8) -> -12.354957 | E40: =(E39+$B$11*D39)*EXP(-$B$11/$B$8) -> -27.798652 | F40: =INDEX($C$15:$C$35,A40+1) -> 78.741578 | G40: =ABS(C40-F40) -> 0
A41: 10 | B41: =A41*$B$11 -> 2.5 | C41: =$B$5+(C40-E40-$B$5)*EXP(-$B$6*$B$11)+(E40+$B$11*D40)*EXP(-$B$11/$B$8) -> 79.739628 | D41: =D40*EXP(-$B$11/$B$8) -> -10.903211 | E41: =(E40+$B$11*D40)*EXP(-$B$11/$B$8) -> -27.258027 | F41: =INDEX($C$15:$C$35,A41+1) -> 79.739628 | G41: =ABS(C41-F41) -> 0
A42: 11 | B42: =A42*$B$11 -> 2.75 | C42: =$B$5+(C41-E41-$B$5)*EXP(-$B$6*$B$11)+(E41+$B$11*D41)*EXP(-$B$11/$B$8) -> 80.956121 | D42: =D41*EXP(-$B$11/$B$8) -> -9.6220499 | E42: =(E41+$B$11*D41)*EXP(-$B$11/$B$8) -> -26.460637 | F42: =INDEX($C$15:$C$35,A42+1) -> 80.956121 | G42: =ABS(C42-F42) -> 0
A43: 12 | B43: =A43*$B$11 -> 3 | C43: =$B$5+(C42-E42-$B$5)*EXP(-$B$6*$B$11)+(E42+$B$11*D42)*EXP(-$B$11/$B$8) -> 82.326459 | D43: =D42*EXP(-$B$11/$B$8) -> -8.4914292 | E43: =(E42+$B$11*D42)*EXP(-$B$11/$B$8) -> -25.474288 | F43: =INDEX($C$15:$C$35,A43+1) -> 82.326459 | G43: =ABS(C43-F43) -> 0
A44: 13 | B44: =A44*$B$11 -> 3.25 | C44: =$B$5+(C43-E43-$B$5)*EXP(-$B$6*$B$11)+(E43+$B$11*D43)*EXP(-$B$11/$B$8) -> 83.79817 | D44: =D43*EXP(-$B$11/$B$8) -> -7.49366 | E44: =(E43+$B$11*D43)*EXP(-$B$11/$B$8) -> -24.354395 | F44: =INDEX($C$15:$C$35,A44+1) -> 83.79817 | G44: =ABS(C44-F44) -> 0
...

Sheet Turnaround
A1: Find the steady state: the turnaround's annual map, the day-one bound and Table 5.5 (Theorem 5.4(i); Equation 5.1; Worked Example 5.1; AXIOM Lab 1.5, step 4)
B3: Liquidity (index) | C3: Technology | D3: Efficiency | E3: Strategic risk | J3: Convergence budget | K3: Value | L3: Worked Example 5.1
A4: Target: the steady state | B4: =Declarations!C35 -> 106 | C4: =Declarations!C36 -> 33 | D4: =Declarations!C37 -> 79 | E4: =Declarations!C38 -> 67 | J4: First year the day-one bound is below one point | K4: =COUNTIF(G16:G56,">=1") -> 15 | L4: Step 3: year 15
A5: Speed a year (Chapter 1's model) | B5: =Declarations!D35 -> 0.45 | C5: =Declarations!D36 -> 0.2 | D5: =Declarations!D37 -> 0.6 | E5: =Declarations!D38 -> 0.3 | J5: First year the largest gap is below one point | K5: =COUNTIF(F16:F56,">=1") -> 11 | L5: Step 4: year 11
A6: Factor: next year's gap / this year's | B6: =EXP(-B5) -> 0.63762815 | C6: =EXP(-C5) -> 0.81873075 | D6: =EXP(-D5) -> 0.54881164 | E6: =EXP(-E5) -> 0.74081822 | J6: Scorecard at the steady state | K6: =W_L*B4+W_T*C4+W_E*D4+W_R*E4 -> 37.75 | L6: Table 5.5: 37.8
A7: Share of the gap closed a year | B7: =1-B6 -> 0.36237185 | C7: =1-C6 -> 0.18126925 | D7: =1-D6 -> 0.45118836 | E7: =1-E6 -> 0.25918178 | J7: Scorecard's peak, years 0-15 | K7: =MAX(H16:H31) -> 38.445169 | L7: about 38.4 in years 3-5
A8: Today | B8: =Liq_today -> 100 | C8: =Tech_today -> 41 | D8: =Eff_today -> 71 | E8: =Risk_today -> 64 | J8: Its year | K8: =INDEX(A16:A31,MATCH(K7,H16:H31,0)) -> 4
A10: Contraction constant L, the largest factor | B10: =MAX(B6:E6) -> 0.81873075 | J10: Table 5.5 (Worked Example 5.1) | P10: Steady state
A11: Set by | B11: =INDEX(B3:E3,MATCH(B10,B6:E6,0)) -> Technology | J11: Year | K11: 0 | L11: 1 | M11: 3 | N11: 5 | O11: 11
A12: Largest first-year move | B12: =MAX(ABS(B17-B16),ABS(C17-C16),ABS(D17-D16),ABS(E17-E16)) -> 3.6095069 | J12: Liquidity (index) | K12: =INDEX($B$16:$B$56,K$11+1) -> 100 | L12: =INDEX($B$16:$B$56,L$11+1) -> 102.17423 | M12: =INDEX($B$16:$B$56,M$11+1) -> 104.44456 | N12: =INDEX($B$16:$B$56,N$11+1) -> 105.3676 | O12: =INDEX($B$16:$B$56,O$11+1) -> 105.9575 | P12: =B4 -> 106
A13: Day-one bound coefficient: move / (1 - L) | B13: =B12/(1-B10) -> 19.912406 | J13: Technology | K13: =INDEX($C$16:$C$56,K$11+1) -> 41 | L13: =INDEX($C$16:$C$56,L$11+1) -> 39.549846 | M13: =INDEX($C$16:$C$56,M$11+1) -> 37.390493 | N13: =INDEX($C$16:$C$56,N$11+1) -> 35.943036 | O13: =INDEX($C$16:$C$56,O$11+1) -> 33.886425 | P13: =C4 -> 33
J14: Efficiency | K14: =INDEX($D$16:$D$56,K$11+1) -> 71 | L14: =INDEX($D$16:$D$56,L$11+1) -> 74.609507 | M14: =INDEX($D$16:$D$56,M$11+1) -> 77.677609 | N14: =INDEX($D$16:$D$56,N$11+1) -> 78.601703 | O14: =INDEX($D$16:$D$56,O$11+1) -> 78.989117 | P14: =D4 -> 79
A15: Year | B15: Liquidity | C15: Technology | D15: Efficiency | E15: Strategic risk | F15: Largest gap | G15: Day-one bound | H15: Scorecard | J15: Strategic risk | K15: =INDEX($E$16:$E$56,K$11+1) -> 64 | L15: =INDEX($E$16:$E$56,L$11+1) -> 64.777545 | M15: =INDEX($E$16:$E$56,M$11+1) -> 65.780291 | N15: =INDEX($E$16:$E$56,N$11+1) -> 66.33061 | O15: =INDEX($E$16:$E$56,O$11+1) -> 66.88935 | P15: =E4 -> 67
A16: 0 | B16: =B$8 -> 100 | C16: =C$8 -> 41 | D16: =D$8 -> 71 | E16: =E$8 -> 64 | F16: =MAX(ABS(B16-B$4),ABS(C16-C$4),ABS(D16-D$4),ABS(E16-E$4)) -> 8 | G16: =$B$13*$B$10^A16 -> 19.912406 | H16: =W_L*B16+W_T*C16+W_E*D16+W_R*E16 -> 37 | J16: Largest gap to steady state | K16: =INDEX($F$16:$F$56,K$11+1) -> 8 | L16: =INDEX($F$16:$F$56,L$11+1) -> 6.549846 | M16: =INDEX($F$16:$F$56,M$11+1) -> 4.3904931 | N16: =INDEX($F$16:$F$56,N$11+1) -> 2.9430355 | O16: =INDEX($F$16:$F$56,O$11+1) -> 0.88642527 | P16: 0
