Workbook

Sheet README
B1: DCT Laboratory — Vol II, Ch 2: The General Enterprise Optimization Problem Revisited
B2: Seed 26202 · Companion to DCT_V2_Ch02_Lab.ipynb and AXIOM Lab 2.2 (module AXIOM-02). Money in $ million, undiscounted.
B4: Worked Example 2.1, Can Meridian Automate and Pay Out at Once?, with the book's declarations.
B5: Declarations: the automation program of Volume I, Worked Example 6.1, the two pledges, the board's two conditions, and the five commitments with their owners and codes.
B6: Instance: the instance card (Table 2.6), the decision-variable editor, which refuses savings as a decision, and the phantom lever: six-round savings carried into a three-round plan.
B7: JointPlan: one forward pass of the joint plan, which dies in year 3, the COO's plan with all savings kept, and the reachable sets of Theorem 2.3(iii).
B8: Schedules: all 64 schedules of rounds, run forward with no payout and with the half payout.
B9: DiagnoseClash: the deletion filter in both orders, every minimal infeasible set, and the groups of commitments whose removal restores feasibility (Theorem 2.3).
B10: Repairs: the largest payout share with six rounds, the most rounds with the half payout, both pledges without the board's conditions, Online Appendix 2.B.4 year by year, and Table 2.7.
B11: Optimizer: the plan for each credit beyond year 6, the thresholds 2.9, 10.7, 25.4 and 53.9 years, the Mayer rewrite and restatements that change nothing (Theorem 2.1).
B12: StandardForm: one schedule's linear program as emitted for a solver, and the price of its end condition in millions and in billions.
B13: Quantifiers: Table 2.4, one commitment under four quantifiers, and the price of the board's appetite. True odds come from the notebook's engine (Volume I's Chapter 8 model, 100,000 paths, seed 8).
... B20: Cross-sheet link: green.

Sheet Declarations
A1: Declarations (Worked Example 2.1, the situation). Money in $ million; amounts undiscounted.
A3: Quantity | B3: Value | C3: Source
A4: Cost of an automation round | B4: 120 | C4: Volume I, Worked Example 6.1
A5: Efficiency ceiling | B5: 85 | C5: A round closes half the gap to 85
A6: Share of the gap a round closes | B6: 0.5
A7: Savings a year per efficiency point above today's | B7: 10 | C7: $10 million a year a point
A8: Efficiency today | B8: 71
A9: Liquidity today | B9: 620
A10: Workforce capability today | B10: 58
A11: Capability a round adds | B11: 1 | C11: Each round raises capability by one point
A12: Capability a round needs | B12: 55 | C12: The admissible-decision block (HR)
A13: The board's liquidity floor | B13: 350 | C13: After paying for a round and at every year end
A14: Liquidity a round needs to start | B14: =Floor_liq+Round_cost -> 470 | C14: So that the floor holds after paying for it: $470 million
A15: The board's end condition: liquidity at the end of year 6 | B15: =Liq_start -> 470 | C15: The $470 million another round would need
A16: The CFO's pledge: share of each year's savings paid out | B16: 0.5 | C16: Half of each year's savings
A18: Commitment | B18: Code | C18: Owner | D18: What it requires
A19: floor | B19: 1 | C19: the board | D19: liquidity of at least $350 million after paying for a round and at every year end
A20: capability | B20: 2 | C20: HR | D20: capability of at least 55 when a round starts
A21: six rounds | B21: 4 | C21: the COO | D21: a round every year for six years
A22: half payout | B22: 8 | C22: the CFO | D22: half of each year's savings paid out
A23: end condition | B23: 16 | C23: the board | D23: at least $470 million at the end of year 6
A25: A set of commitments is written as the sum of its codes: {floor, six rounds, half payout} = 1 + 4 + 8 = 13. A schedule of rounds is written as the years of its rounds: years 1, 2 and 4 = 124.

Sheet Instance
A1: Build the instance: the card, the decision-variable editor, a phantom lever (Table 2.6; Proposition 2.2; AXIOM Lab 2.2, step 1)
A3: Block | B3: Meridian's declaration | C3: Owner
A4: Decisions | B4: round in year k, z_k in {0, 1}; payout p_k >= 0 | C4: COO; CFO
A5: Dynamics | B5: each round closes half the efficiency gap to 85 and adds a point of capability; savings $10 million per point above 71; liquidity q_k = q_k-1 - 120 z_k + S_k - p_k | C5: COO; treasury
A6: Admissible decisions | B6: a round needs capability of at least 55 | C6: HR
A7: Path commitments | B7: liquidity of at least $350 million after paying for a round and at year end; a round every year; half of each year's savings paid out | C7: board; COO; CFO
A8: Start and end | B8: $620 million, efficiency 71, capability 58; at least $470 million at the end of year 6 | C8: treasury; board
A9: Uncertainty | B9: none declared (Volume I's point estimates) | C9: --
A11: Quantity | B11: Declared as (decision or induced) | C11: Computed by the dynamics? | D11: How the dynamics compute it | E11: The decision-variable editor
A12: Round in year k, z_k | B12: decision | C12: no | E12: =IF(B12="decision",IF(C12="yes","REFUSED: induced by the dynamics; a lever on it would be a phantom lever","accepted as a decision"),IF(C12="yes","induced: computed by the dynamics","REFUSED: nothing computes it, so it must be declared a decision")) -> accepted as a decision
A13: Payout in year k, p_k | B13: decision | C13: no | E13: =IF(B13="decision",IF(C13="yes","REFUSED: induced by the dynamics; a lever on it would be a phantom lever","accepted as a decision"),IF(C13="yes","induced: computed by the dynamics","REFUSED: nothing computes it, so it must be declared a decision")) -> accepted as a decision
A14: Efficiency e_k | B14: induced | C14: yes | D14: e_k = e_k-1 + z_k (85 - e_k-1) / 2 | E14: =IF(B14="decision",IF(C14="yes","REFUSED: induced by the dynamics; a lever on it would be a phantom lever","accepted as a decision"),IF(C14="yes","induced: computed by the dynamics","REFUSED: nothing computes it, so it must be declared a decision")) -> induced: computed by the dynamics
A15: Capability w_k | B15: induced | C15: yes | D15: w_k = w_k-1 + z_k | E15: =IF(B15="decision",IF(C15="yes","REFUSED: induced by the dynamics; a lever on it would be a phantom lever","accepted as a decision"),IF(C15="yes","induced: computed by the dynamics","REFUSED: nothing computes it, so it must be declared a decision")) -> induced: computed by the dynamics
A16: Savings S_k | B16: decision | C16: yes | D16: S_k = 10 (e_k - 71) | E16: =IF(B16="decision",IF(C16="yes","REFUSED: induced by the dynamics; a lever on it would be a phantom lever","accepted as a decision"),IF(C16="yes","induced: computed by the dynamics","REFUSED: nothing computes it, so it must be declared a decision")) -> REFUSED: induced by the dynamics; a lever on it would be a phantom lever
A17: Liquidity q_k | B17: induced | C17: yes | D17: q_k = q_k-1 - 120 z_k + S_k - p_k | E17: =IF(B17="decision",IF(C17="yes","REFUSED: induced by the dynamics; a lever on it would be a phantom lever","accepted as a decision"),IF(C17="yes","induced: computed by the dynamics","REFUSED: nothing computes it, so it must be declared a decision")) -> induced: computed by the dynamics
A18: Entries the editor refuses | B18: =COUNTIF(E12:E17,"REFUSED*") -> 1
A19: AXIOM Lab 2.2, step 1: savings are entered as a decision (B16) and refused. Declare them induced and the editor accepts the card.
A21: A phantom lever: savings are induced by the rounds (Proposition 2.2)
A22: Plan | B22: Row | C22: Year 1 | D22: Year 2 | E22: Year 3 | F22: Year 4 | G22: Year 5 | H22: Year 6 | I22: Six years
A23: Six rounds (the CFO's spreadsheet) | B23: round (1 = yes) | C23: 1 | D23: 1 | E23: 1 | F23: 1 | G23: 1 | H23: 1
B24: efficiency | C24: =IF(C23=1,Eff_0+Gap_closed*(Eff_ceiling-Eff_0),Eff_0) -> 78 | D24: =IF(D23=1,C24+Gap_closed*(Eff_ceiling-C24),C24) -> 81.5 | E24: =IF(E23=1,D24+Gap_closed*(Eff_ceiling-D24),D24) -> 83.25 | F24: =IF(F23=1,E24+Gap_closed*(Eff_ceiling-E24),E24) -> 84.125 | G24: =IF(G23=1,F24+Gap_closed*(Eff_ceiling-F24),F24) -> 84.5625 | H24: =IF(H23=1,G24+Gap_closed*(Eff_ceiling-G24),G24) -> 84.78125
B25: savings | C25: =Sav_point*(C24-Eff_0) -> 70 | D25: =Sav_point*(D24-Eff_0) -> 105 | E25: =Sav_point*(E24-Eff_0) -> 122.5 | F25: =Sav_point*(F24-Eff_0) -> 131.25 | G25: =Sav_point*(G24-Eff_0) -> 135.625 | H25: =Sav_point*(H24-Eff_0) -> 137.8125 | I25: =SUM(C25:H25) -> 702.1875
A27: Rounds in years 1, 2 and 4 | B27: round (1 = yes) | C27: 1 | D27: 1 | E27: 0 | F27: 1 | G27: 0 | H27: 0
B28: efficiency | C28: =IF(C27=1,Eff_0+Gap_closed*(Eff_ceiling-Eff_0),Eff_0) -> 78 | D28: =IF(D27=1,C28+Gap_closed*(Eff_ceiling-C28),C28) -> 81.5 | E28: =IF(E27=1,D28+Gap_closed*(Eff_ceiling-D28),D28) -> 81.5 | F28: =IF(F27=1,E28+Gap_closed*(Eff_ceiling-E28),E28) -> 83.25 | G28: =IF(G27=1,F28+Gap_closed*(Eff_ceiling-F28),F28) -> 83.25 | H28: =IF(H27=1,G28+Gap_closed*(Eff_ceiling-G28),G28) -> 83.25
B29: savings | C29: =Sav_point*(C28-Eff_0) -> 70 | D29: =Sav_point*(D28-Eff_0) -> 105 | E29: =Sav_point*(E28-Eff_0) -> 105 | F29: =Sav_point*(F28-Eff_0) -> 122.5 | G29: =Sav_point*(G28-Eff_0) -> 122.5 | H29: =Sav_point*(H28-Eff_0) -> 122.5 | I29: =SUM(C29:H29) -> 647.5
A31: Six-round savings over six years (the spreadsheet's) | B31: =I25 -> 702.1875
A32: Savings of rounds in years 1, 2 and 4 | B32: =I29 -> 647.5
A33: Carried into the three-round plan, the spreadsheet overstates its savings by | B33: =B31-B32 -> 54.6875
A34: A plan's savings must be computed from its own rounds, never carried over from another plan: a lever on savings is a lever the company does not have.

Sheet JointPlan
A1: Check the joint plan by simulation (Worked Example 2.1, Step 2; Theorem 2.3(iii); AXIOM Lab 2.2, step 2)
A2: One forward pass of the declared dynamics under the plan. The rounds are the COO's pledge; change them, or the share paid out, and the pass recomputes.
A4: The joint plan: a round every year, half of each year's savings paid out
A5: Year | B5: Round (1 = yes) | C5: Liquidity at the start | D5: After paying for the round | E5: Capability before the round | F5: Efficiency | G5: Savings | H5: Paid out | I5: Liquidity at year end | J5: Floor kept? | K5: Capability kept? | M5: Reading | N5: Value
A6: 1 | B6: 1 | C6: =Liq_0 -> 620 | D6: =C6-Round_cost*B6 -> 500 | E6: =Cap_0 -> 58 | F6: =IF(B6=1,Eff_0+Gap_closed*(Eff_ceiling-Eff_0),Eff_0) -> 78 | G6: =Sav_point*(F6-Eff_0) -> 70 | H6: =Pledge_share*G6 -> 35 | I6: =D6+G6-H6 -> 535 | J6: =IF(AND(OR(B6=0,D6>=Floor_liq-0.000000001),I6>=Floor_liq-0.000000001),"yes","no") -> yes | K6: =IF(OR(B6=0,E6>=Cap_min),"yes","no") -> yes | M6: Liquidity at the end of year 1 | N6: =I6 -> 535
A7: 2 | B7: 1 | C7: =I6 -> 535 | D7: =C7-Round_cost*B7 -> 415 | E7: =E6+Cap_step*B6 -> 59 | F7: =IF(B7=1,F6+Gap_closed*(Eff_ceiling-F6),F6) -> 81.5 | G7: =Sav_point*(F7-Eff_0) -> 105 | H7: =Pledge_share*G7 -> 52.5 | I7: =D7+G7-H7 -> 467.5 | J7: =IF(AND(OR(B7=0,D7>=Floor_liq-0.000000001),I7>=Floor_liq-0.000000001),"yes","no") -> yes | K7: =IF(OR(B7=0,E7>=Cap_min),"yes","no") -> yes | M7: Liquidity at the end of year 2 | N7: =I7 -> 467.5
A8: 3 | B8: 1 | C8: =I7 -> 467.5 | D8: =C8-Round_cost*B8 -> 347.5 | E8: =E7+Cap_step*B7 -> 60 | F8: =IF(B8=1,F7+Gap_closed*(Eff_ceiling-F7),F7) -> 83.25 | G8: =Sav_point*(F8-Eff_0) -> 122.5 | H8: =Pledge_share*G8 -> 61.25 | I8: =D8+G8-H8 -> 408.75 | J8: =IF(AND(OR(B8=0,D8>=Floor_liq-0.000000001),I8>=Floor_liq-0.000000001),"yes","no") -> no | K8: =IF(OR(B8=0,E8>=Cap_min),"yes","no") -> yes | M8: Liquidity after paying for round 3 | N8: =D8 -> 347.5
A9: 4 | B9: 1 | C9: =I8 -> 408.75 | D9: =C9-Round_cost*B9 -> 288.75 | E9: =E8+Cap_step*B8 -> 61 | F9: =IF(B9=1,F8+Gap_closed*(Eff_ceiling-F8),F8) -> 84.125 | G9: =Sav_point*(F9-Eff_0) -> 131.25 | H9: =Pledge_share*G9 -> 65.625 | I9: =D9+G9-H9 -> 354.375 | J9: =IF(AND(OR(B9=0,D9>=Floor_liq-0.000000001),I9>=Floor_liq-0.000000001),"yes","no") -> no | K9: =IF(OR(B9=0,E9>=Cap_min),"yes","no") -> yes | M9: The joint plan dies in year (the first year the floor breaks) | N9: =IF(COUNTIF(J6:J11,"no")=0,0,MATCH("no",J6:J11,0)) -> 3
A10: 5 | B10: 1 | C10: =I9 -> 354.375 | D10: =C10-Round_cost*B10 -> 234.375 | E10: =E9+Cap_step*B9 -> 62 | F10: =IF(B10=1,F9+Gap_closed*(Eff_ceiling-F9),F9) -> 84.5625 | G10: =Sav_point*(F10-Eff_0) -> 135.625 | H10: =Pledge_share*G10 -> 67.8125 | I10: =D10+G10-H10 -> 302.1875 | J10: =IF(AND(OR(B10=0,D10>=Floor_liq-0.000000001),I10>=Floor_liq-0.000000001),"yes","no") -> no | K10: =IF(OR(B10=0,E10>=Cap_min),"yes","no") -> yes | M10: By the end of year 2 the payouts have taken | N10: =SUM(H6:H7) -> 87.5
A11: 6 | B11: 1 | C11: =I10 -> 302.1875 | D11: =C11-Round_cost*B11 -> 182.1875 | E11: =E10+Cap_step*B10 -> 63 | F11: =IF(B11=1,F10+Gap_closed*(Eff_ceiling-F10),F10) -> 84.78125 | G11: =Sav_point*(F11-Eff_0) -> 137.8125 | H11: =Pledge_share*G11 -> 68.90625 | I11: =D11+G11-H11 -> 251.09375 | J11: =IF(AND(OR(B11=0,D11>=Floor_liq-0.000000001),I11>=Floor_liq-0.000000001),"yes","no") -> no | K11: =IF(OR(B11=0,E11>=Cap_min),"yes","no") -> yes | M11: Round 3 misses the liquidity it needs by | N11: =Liq_start-I7 -> 2.5
A12: Round 3 cannot start, so the joint plan dies in year 3. The later rows run both pledges on regardless: that is repair (c), which gives up the floor and the end condition. | M12: The COO's plan with savings kept: liquidity at the end of year 6 | N12: =I21 -> 602.1875
M13: ... its first year breaking the floor (0 = none) | N13: =IF(COUNTIF(J16:J21,"no")=0,0,MATCH("no",J16:J21,0)) -> 0
A14: The COO's plan with all savings kept | M14: ... the end condition kept? | N14: =IF(I21>=End_liq,"yes","no") -> yes
A15: Year | B15: Round (1 = yes) | C15: Liquidity at the start | D15: After paying for the round | E15: Capability before the round | F15: Efficiency | G15: Savings | H15: Paid out | I15: Liquidity at year end | J15: Floor kept? | K15: Capability kept?
A16: 1 | B16: 1 | C16: =Liq_0 -> 620 | D16: =C16-Round_cost*B16 -> 500 | E16: =Cap_0 -> 58 | F16: =IF(B16=1,Eff_0+Gap_closed*(Eff_ceiling-Eff_0),Eff_0) -> 78 | G16: =Sav_point*(F16-Eff_0) -> 70 | H16: =0*G16 -> 0 | I16: =D16+G16-H16 -> 570 | J16: =IF(AND(OR(B16=0,D16>=Floor_liq-0.000000001),I16>=Floor_liq-0.000000001),"yes","no") -> yes | K16: =IF(OR(B16=0,E16>=Cap_min),"yes","no") -> yes
A17: 2 | B17: 1 | C17: =I16 -> 570 | D17: =C17-Round_cost*B17 -> 450 | E17: =E16+Cap_step*B16 -> 59 | F17: =IF(B17=1,F16+Gap_closed*(Eff_ceiling-F16),F16) -> 81.5 | G17: =Sav_point*(F17-Eff_0) -> 105 | H17: =0*G17 -> 0 | I17: =D17+G17-H17 -> 555 | J17: =IF(AND(OR(B17=0,D17>=Floor_liq-0.000000001),I17>=Floor_liq-0.000000001),"yes","no") -> yes | K17: =IF(OR(B17=0,E17>=Cap_min),"yes","no") -> yes
A18: 3 | B18: 1 | C18: =I17 -> 555 | D18: =C18-Round_cost*B18 -> 435 | E18: =E17+Cap_step*B17 -> 60 | F18: =IF(B18=1,F17+Gap_closed*(Eff_ceiling-F17),F17) -> 83.25 | G18: =Sav_point*(F18-Eff_0) -> 122.5 | H18: =0*G18 -> 0 | I18: =D18+G18-H18 -> 557.5 | J18: =IF(AND(OR(B18=0,D18>=Floor_liq-0.000000001),I18>=Floor_liq-0.000000001),"yes","no") -> yes | K18: =IF(OR(B18=0,E18>=Cap_min),"yes","no") -> yes
A19: 4 | B19: 1 | C19: =I18 -> 557.5 | D19: =C19-Round_cost*B19 -> 437.5 | E19: =E18+Cap_step*B18 -> 61 | F19: =IF(B19=1,F18+Gap_closed*(Eff_ceiling-F18),F18) -> 84.125 | G19: =Sav_point*(F19-Eff_0) -> 131.25 | H19: =0*G19 -> 0 | I19: =D19+G19-H19 -> 568.75 | J19: =IF(AND(OR(B19=0,D19>=Floor_liq-0.000000001),I19>=Floor_liq-0.000000001),"yes","no") -> yes | K19: =IF(OR(B19=0,E19>=Cap_min),"yes","no") -> yes
A20: 5 | B20: 1 | C20: =I19 -> 568.75 | D20: =C20-Round_cost*B20 -> 448.75 | E20: =E19+Cap_step*B19 -> 62 | F20: =IF(B20=1,F19+Gap_closed*(Eff_ceiling-F19),F19) -> 84.5625 | G20: =Sav_point*(F20-Eff_0) -> 135.625 | H20: =0*G20 -> 0 | I20: =D20+G20-H20 -> 584.375 | J20: =IF(AND(OR(B20=0,D20>=Floor_liq-0.000000001),I20>=Floor_liq-0.000000001),"yes","no") -> yes | K20: =IF(OR(B20=0,E20>=Cap_min),"yes","no") -> yes
A21: 6 | B21: 1 | C21: =I20 -> 584.375 | D21: =C21-Round_cost*B21 -> 464.375 | E21: =E20+Cap_step*B20 -> 63 | F21: =IF(B21=1,F20+Gap_closed*(Eff_ceiling-F20),F20) -> 84.78125 | G21: =Sav_point*(F21-Eff_0) -> 137.8125 | H21: =0*G21 -> 0 | I21: =D21+G21-H21 -> 602.1875 | J21: =IF(AND(OR(B21=0,D21>=Floor_liq-0.000000001),I21>=Floor_liq-0.000000001),"yes","no") -> yes | K21: =IF(OR(B21=0,E21>=Cap_min),"yes","no") -> yes
A25: Theorem 2.3(iii): the year-end liquidity some plan can reach under six rounds and at least half paid out, keeping every commitment so far: all five commitments in force
A26: Floor in force (1 = yes) | D26: 1 | E26: End condition in force (1 = yes) | H26: 1
A27: Year | B27: Efficiency | C27: Savings | D27: Lowest level that can start the round | E27: Highest level at the start | F27: Round can start? (1 = yes) | G27: Lowest year-end level | H27: Highest year-end level | I27: Set not empty? (1 = yes)
A28: 0 | B28: =Eff_0 -> 71 | G28: =Liq_0 -> 620 | H28: =Liq_0 -> 620 | I28: 1
A29: 1 | B29: =B28+Gap_closed*(Eff_ceiling-B28) -> 78 | C29: =Sav_point*(B29-Eff_0) -> 70 | D29: =IF($D$26=1,MAX(G28,Liq_start),G28) -> 620 | E29: =H28 -> 620 | F29: =IF(AND(I28=1,D29<=E29),1,0) -> 1 | G29: =IF($D$26=1,Floor_liq,-1000000000) -> 350 | H29: =E29-Round_cost+(1-Pledge_share)*C29 -> 535 | I29: =IF(AND(F29=1,G29<=H29),1,0) -> 1
A30: 2 | B30: =B29+Gap_closed*(Eff_ceiling-B29) -> 81.5 | C30: =Sav_point*(B30-Eff_0) -> 105 | D30: =IF($D$26=1,MAX(G29,Liq_start),G29) -> 470 | E30: =H29 -> 535 | F30: =IF(AND(I29=1,D30<=E30),1,0) -> 1 | G30: =IF($D$26=1,Floor_liq,-1000000000) -> 350 | H30: =E30-Round_cost+(1-Pledge_share)*C30 -> 467.5 | I30: =IF(AND(F30=1,G30<=H30),1,0) -> 1
A31: 3 | B31: =B30+Gap_closed*(Eff_ceiling-B30) -> 83.25 | C31: =Sav_point*(B31-Eff_0) -> 122.5 | D31: =IF($D$26=1,MAX(G30,Liq_start),G30) -> 470 | E31: =H30 -> 467.5 | F31: =IF(AND(I30=1,D31<=E31),1,0) -> 0 | G31: =IF($D$26=1,Floor_liq,-1000000000) -> 350 | H31: =E31-Round_cost+(1-Pledge_share)*C31 -> 408.75 | I31: =IF(AND(F31=1,G31<=H31),1,0) -> 0
A32: 4 | B32: =B31+Gap_closed*(Eff_ceiling-B31) -> 84.125 | C32: =Sav_point*(B32-Eff_0) -> 131.25 | D32: =IF($D$26=1,MAX(G31,Liq_start),G31) -> 470 | E32: =H31 -> 408.75 | F32: =IF(AND(I31=1,D32<=E32),1,0) -> 0 | G32: =IF($D$26=1,Floor_liq,-1000000000) -> 350 | H32: =E32-Round_cost+(1-Pledge_share)*C32 -> 354.375 | I32: =IF(AND(F32=1,G32<=H32),1,0) -> 0
A33: 5 | B33: =B32+Gap_closed*(Eff_ceiling-B32) -> 84.5625 | C33: =Sav_point*(B33-Eff_0) -> 135.625 | D33: =IF($D$26=1,MAX(G32,Liq_start),G32) -> 470 | E33: =H32 -> 354.375 | F33: =IF(AND(I32=1,D33<=E33),1,0) -> 0 | G33: =IF($D$26=1,Floor_liq,-1000000000) -> 350 | H33: =E33-Round_cost+(1-Pledge_share)*C33 -> 302.1875 | I33: =IF(AND(F33=1,G33<=H33),1,0) -> 0
A34: 6 | B34: =B33+Gap_closed*(Eff_ceiling-B33) -> 84.78125 | C34: =Sav_point*(B34-Eff_0) -> 137.8125 | D34: =IF($D$26=1,MAX(G33,Liq_start),G33) -> 470 | E34: =H33 -> 302.1875 | F34: =IF(AND(I33=1,D34<=E34),1,0) -> 0 | G34: =IF($H$26=1,MAX(IF($D$26=1,Floor_liq,-1000000000),End_liq),IF($D$26=1,Floor_liq,-1000000000)) -> 470 | H34: =E34-Round_cost+(1-Pledge_share)*C34 -> 251.09375 | I34: =IF(AND(F34=1,G34<=H34),1,0) -> 0
A35: The first year whose set is empty: the plan dies (grey: no plan reaches these years keeping every commitment) | I35: =IF(COUNTIF(I29:I34,0)=0,0,MATCH(0,I29:I34,0)) -> 3
A37: Theorem 2.3(iii): the year-end liquidity some plan can reach under six rounds and at least half paid out, keeping every commitment so far: the floor dropped (the pledges and the end condition)
A38: Floor in force (1 = yes) | D38: 0 | E38: End condition in force (1 = yes) | H38: 1
A39: Year | B39: Efficiency | C39: Savings | D39: Lowest level that can start the round | E39: Highest level at the start | F39: Round can start? (1 = yes) | G39: Lowest year-end level | H39: Highest year-end level | I39: Set not empty? (1 = yes)
A40: 0 | B40: =Eff_0 -> 71 | G40: =Liq_0 -> 620 | H40: =Liq_0 -> 620 | I40: 1
A41: 1 | B41: =B40+Gap_closed*(Eff_ceiling-B40) -> 78 | C41: =Sav_point*(B41-Eff_0) -> 70 | D41: =IF($D$38=1,MAX(G40,Liq_start),G40) -> 620 | E41: =H40 -> 620 | F41: =IF(AND(I40=1,D41<=E41),1,0) -> 1 | G41: =IF($D$38=1,Floor_liq,-1000000000) -> -1000000000 | H41: =E41-Round_cost+(1-Pledge_share)*C41 -> 535 | I41: =IF(AND(F41=1,G41<=H41),1,0) -> 1
A42: 2 | B42: =B41+Gap_closed*(Eff_ceiling-B41) -> 81.5 | C42: =Sav_point*(B42-Eff_0) -> 105 | D42: =IF($D$38=1,MAX(G41,Liq_start),G41) -> -1000000000 | E42: =H41 -> 535 | F42: =IF(AND(I41=1,D42<=E42),1,0) -> 1 | G42: =IF($D$38=1,Floor_liq,-1000000000) -> -1000000000 | H42: =E42-Round_cost+(1-Pledge_share)*C42 -> 467.5 | I42: =IF(AND(F42=1,G42<=H42),1,0) -> 1
A43: 3 | B43: =B42+Gap_closed*(Eff_ceiling-B42) -> 83.25 | C43: =Sav_point*(B43-Eff_0) -> 122.5 | D43: =IF($D$38=1,MAX(G42,Liq_start),G42) -> -1000000000 | E43: =H42 -> 467.5 | F43: =IF(AND(I42=1,D43<=E43),1,0) -> 1 | G43: =IF($D$38=1,Floor_liq,-1000000000) -> -1000000000 | H43: =E43-Round_cost+(1-Pledge_share)*C43 -> 408.75 | I43: =IF(AND(F43=1,G43<=H43),1,0) -> 1
A44: 4 | B44: =B43+Gap_closed*(Eff_ceiling-B43) -> 84.125 | C44: =Sav_point*(B44-Eff_0) -> 131.25 | D44: =IF($D$38=1,MAX(G43,Liq_start),G43) -> -1000000000 | E44: =H43 -> 408.75 | F44: =IF(AND(I43=1,D44<=E44),1,0) -> 1 | G44: =IF($D$38=1,Floor_liq,-1000000000) -> -1000000000 | H44: =E44-Round_cost+(1-Pledge_share)*C44 -> 354.375 | I44: =IF(AND(F44=1,G44<=H44),1,0) -> 1
A45: 5 | B45: =B44+Gap_closed*(Eff_ceiling-B44) -> 84.5625 | C45: =Sav_point*(B45-Eff_0) -> 135.625 | D45: =IF($D$38=1,MAX(G44,Liq_start),G44) -> -1000000000 | E45: =H44 -> 354.375 | F45: =IF(AND(I44=1,D45<=E45),1,0) -> 1 | G45: =IF($D$38=1,Floor_liq,-1000000000) -> -1000000000 | H45: =E45-Round_cost+(1-Pledge_share)*C45 -> 302.1875 | I45: =IF(AND(F45=1,G45<=H45),1,0) -> 1
...

Sheet Schedules
A1: The 64 schedules of rounds, each run forward with no payout and with the half payout
A2: Row by row: the rounds (z_k = 1 in a round year), efficiency, savings, liquidity, and whether the board's conditions hold. The DiagnoseClash, Repairs and Optimizer sheets read this table.
A4: credit (years): | BG4: 0 | BH4: 5 | BI4: 10 | BJ4: 20 | BK4: 40 | BL4: 60
A5: Schedule | B5: z1 | C5: z2 | D5: z3 | E5: z4 | F5: z5 | G5: z6 | H5: Rounds | I5: Years of the rounds | J5: Efficiency, year 1 | K5: Efficiency, year 2 | L5: Efficiency, year 3 | M5: Efficiency, year 4 | N5: Efficiency, year 5 | O5: Efficiency, year 6 | P5: Savings, year 1 | Q5: Savings, year 2 | R5: Savings, year 3 | S5: Savings, year 4 | T5: Savings, year 5 | U5: Savings, year 6 | V5: Savings over six years | W5: Capability kept (1 = yes) | X5: Year-end liquidity 1, no payout | Y5: Year-end liquidity 2, no payout | Z5: Year-end liquidity 3, no payout | AA5: Year-end liquidity 4, no payout | AB5: Year-end liquidity 5, no payout | AC5: Year-end liquidity 6, no payout | AD5: After paying for round 1, no payout | AE5: After paying for round 2, no payout | AF5: After paying for round 3, no payout | AG5: After paying for round 4, no payout | AH5: After paying for round 5, no payout | AI5: After paying for round 6, no payout | AJ5: Floor kept, no payout | AK5: End condition kept, no payout | AL5: Board's conditions kept, no payout | AM5: Year-end liquidity 1, half paid out | AN5: Year-end liquidity 2, half paid out | AO5: Year-end liquidity 3, half paid out | AP5: Year-end liquidity 4, half paid out | AQ5: Year-end liquidity 5, half paid out | AR5: Year-end liquidity 6, half paid out | AS5: After paying for round 1, half paid out | AT5: After paying for round 2, half paid out | AU5: After paying for round 3, half paid out | AV5: After paying for round 4, half paid out | AW5: After paying for round 5, half paid out | AX5: After paying for round 6, half paid out | AY5: Floor kept, half paid out | AZ5: End condition kept, half paid out | BA5: Board's conditions kept, half paid out | BB5: Paid out under the half payout | BC5: Rank for repair (b): rounds, then paid out | BD5: Year-6 savings | BE5: Payouts + year-6 liquidity: the no-payout year-6 liquidity | BF5: Best six-year payout, the board's conditions kept | BG5: Value, credit 0 years | BH5: Value, credit 5 years | BI5: Value, credit 10 years | BJ5: Value, credit 20 years | BK5: Value, credit 40 years | BL5: Value, credit 60 years | BM5: Rounds in years 1 to n? (1 = yes) | BN5: Value in $ thousands (credit 0) | BO5: Value + 100 (credit 0) | BP5: ln(value) (credit 0)
A6: 0 | B6: =MOD(INT($A6/32),2) -> 0 | C6: =MOD(INT($A6/16),2) -> 0 | D6: =MOD(INT($A6/8),2) -> 0 | E6: =MOD(INT($A6/4),2) -> 0 | F6: =MOD(INT($A6/2),2) -> 0 | G6: =MOD(INT($A6/1),2) -> 0 | H6: =SUM(B6:G6) -> 0 | I6: =IF(H6=0,0,VALUE(IF(B6=1,"1","")&IF(C6=1,"2","")&IF(D6=1,"3","")&IF(E6=1,"4","")&IF(F6=1,"5","")&IF(G6=1,"6",""))) -> 0 | J6: =IF(B6=1,Eff_0+Gap_closed*(Eff_ceiling-Eff_0),Eff_0) -> 71 | K6: =IF(C6=1,J6+Gap_closed*(Eff_ceiling-J6),J6) -> 71 | L6: =IF(D6=1,K6+Gap_closed*(Eff_ceiling-K6),K6) -> 71 | M6: =IF(E6=1,L6+Gap_closed*(Eff_ceiling-L6),L6) -> 71 | N6: =IF(F6=1,M6+Gap_closed*(Eff_ceiling-M6),M6) -> 71 | O6: =IF(G6=1,N6+Gap_closed*(Eff_ceiling-N6),N6) -> 71 | P6: =Sav_point*(J6-Eff_0) -> 0 | Q6: =Sav_point*(K6-Eff_0) -> 0 | R6: =Sav_point*(L6-Eff_0) -> 0 | S6: =Sav_point*(M6-Eff_0) -> 0 | T6: =Sav_point*(N6-Eff_0) -> 0 | U6: =Sav_point*(O6-Eff_0) -> 0 | V6: =SUM(P6:U6) -> 0 | W6: =IF(AND(H6>0,Cap_0<Cap_min),0,1) -> 1 | X6: =Liq_0-Round_cost*B6+1*P6 -> 620 | Y6: =X6-Round_cost*C6+1*Q6 -> 620 | Z6: =Y6-Round_cost*D6+1*R6 -> 620 | AA6: =Z6-Round_cost*E6+1*S6 -> 620 | AB6: =AA6-Round_cost*F6+1*T6 -> 620 | AC6: =AB6-Round_cost*G6+1*U6 -> 620 | AD6: =IF(B6=1,Liq_0-Round_cost,1000000000) -> 1000000000 | AE6: =IF(C6=1,X6-Round_cost,1000000000) -> 1000000000 | AF6: =IF(D6=1,Y6-Round_cost,1000000000) -> 1000000000 | AG6: =IF(E6=1,Z6-Round_cost,1000000000) -> 1000000000 | AH6: =IF(F6=1,AA6-Round_cost,1000000000) -> 1000000000 | AI6: =IF(G6=1,AB6-Round_cost,1000000000) -> 1000000000 | AJ6: =IF(AND(MIN(X6:AC6)>=Floor_liq-0.000000001,MIN(AD6:AI6)>=Floor_liq-0.000000001),1,0) -> 1 | AK6: =IF(AC6>=End_liq-0.000000001,1,0) -> 1 | AL6: =AJ6*AK6*W6 -> 1 | AM6: =Liq_0-Round_cost*B6+(1-Pledge_share)*P6 -> 620 | AN6: =AM6-Round_cost*C6+(1-Pledge_share)*Q6 -> 620 | AO6: =AN6-Round_cost*D6+(1-Pledge_share)*R6 -> 620 | AP6: =AO6-Round_cost*E6+(1-Pledge_share)*S6 -> 620 | AQ6: =AP6-Round_cost*F6+(1-Pledge_share)*T6 -> 620 | AR6: =AQ6-Round_cost*G6+(1-Pledge_share)*U6 -> 620 | AS6: =IF(B6=1,Liq_0-Round_cost,1000000000) -> 1000000000 | AT6: =IF(C6=1,AM6-Round_cost,1000000000) -> 1000000000 | AU6: =IF(D6=1,AN6-Round_cost,1000000000) -> 1000000000 | AV6: =IF(E6=1,AO6-Round_cost,1000000000) -> 1000000000 | AW6: =IF(F6=1,AP6-Round_cost,1000000000) -> 1000000000 | AX6: =IF(G6=1,AQ6-Round_cost,1000000000) -> 1000000000 | AY6: =IF(AND(MIN(AM6:AR6)>=Floor_liq-0.000000001,MIN(AS6:AX6)>=Floor_liq-0.000000001),1,0) -> 1 | AZ6: =IF(AR6>=End_liq-0.000000001,1,0) -> 1 | BA6: =AY6*AZ6*W6 -> 1 | BB6: =Pledge_share*V6 -> 0 | BC6: =IF(BA6=1,H6*10000+BB6,-1) -> 0 | BD6: =U6 -> 0 | BE6: =AC6 -> 620 | BF6: =IF(AL6=1,AC6-End_liq,-1000000000) -> 150 | BG6: =IF(AL6=1,BF6+BG$4*BD6,-1000000000) -> 150 | BH6: =IF(AL6=1,BF6+BH$4*BD6,-1000000000) -> 150 | BI6: =IF(AL6=1,BF6+BI$4*BD6,-1000000000) -> 150 | BJ6: =IF(AL6=1,BF6+BJ$4*BD6,-1000000000) -> 150 | BK6: =IF(AL6=1,BF6+BK$4*BD6,-1000000000) -> 150 | BL6: =IF(AL6=1,BF6+BL$4*BD6,-1000000000) -> 150 | BM6: =IF(H6=0,1,IF(I6=VALUE(LEFT("123456",H6)),1,0)) -> 1 | BN6: =IF(BG6>0,1000*BG6,-1000000000000) -> 150000 | BO6: =IF(BG6>0,BG6+100,-1000000000) -> 250 | BP6: =IF(BG6>0,LN(BG6),-1000000000) -> 5.0106353
A7: 1 | B7: =MOD(INT($A7/32),2) -> 0 | C7: =MOD(INT($A7/16),2) -> 0 | D7: =MOD(INT($A7/8),2) -> 0 | E7: =MOD(INT($A7/4),2) -> 0 | F7: =MOD(INT($A7/2),2) -> 0 | G7: =MOD(INT($A7/1),2) -> 1 | H7: =SUM(B7:G7) -> 1 | I7: =IF(H7=0,0,VALUE(IF(B7=1,"1","")&IF(C7=1,"2","")&IF(D7=1,"3","")&IF(E7=1,"4","")&IF(F7=1,"5","")&IF(G7=1,"6",""))) -> 6 | J7: =IF(B7=1,Eff_0+Gap_closed*(Eff_ceiling-Eff_0),Eff_0) -> 71 | K7: =IF(C7=1,J7+Gap_closed*(Eff_ceiling-J7),J7) -> 71 | L7: =IF(D7=1,K7+Gap_closed*(Eff_ceiling-K7),K7) -> 71 | M7: =IF(E7=1,L7+Gap_closed*(Eff_ceiling-L7),L7) -> 71 | N7: =IF(F7=1,M7+Gap_closed*(Eff_ceiling-M7),M7) -> 71 | O7: =IF(G7=1,N7+Gap_closed*(Eff_ceiling-N7),N7) -> 78 | P7: =Sav_point*(J7-Eff_0) -> 0 | Q7: =Sav_point*(K7-Eff_0) -> 0 | R7: =Sav_point*(L7-Eff_0) -> 0 | S7: =Sav_point*(M7-Eff_0) -> 0 | T7: =Sav_point*(N7-Eff_0) -> 0 | U7: =Sav_point*(O7-Eff_0) -> 70 | V7: =SUM(P7:U7) -> 70 | W7: =IF(AND(H7>0,Cap_0<Cap_min),0,1) -> 1 | X7: =Liq_0-Round_cost*B7+1*P7 -> 620 | Y7: =X7-Round_cost*C7+1*Q7 -> 620 | Z7: =Y7-Round_cost*D7+1*R7 -> 620 | AA7: =Z7-Round_cost*E7+1*S7 -> 620 | AB7: =AA7-Round_cost*F7+1*T7 -> 620 | AC7: =AB7-Round_cost*G7+1*U7 -> 570 | AD7: =IF(B7=1,Liq_0-Round_cost,1000000000) -> 1000000000 | AE7: =IF(C7=1,X7-Round_cost,1000000000) -> 1000000000 | AF7: =IF(D7=1,Y7-Round_cost,1000000000) -> 1000000000 | AG7: =IF(E7=1,Z7-Round_cost,1000000000) -> 1000000000 | AH7: =IF(F7=1,AA7-Round_cost,1000000000) -> 1000000000 | AI7: =IF(G7=1,AB7-Round_cost,1000000000) -> 500 | AJ7: =IF(AND(MIN(X7:AC7)>=Floor_liq-0.000000001,MIN(AD7:AI7)>=Floor_liq-0.000000001),1,0) -> 1 | AK7: =IF(AC7>=End_liq-0.000000001,1,0) -> 1 | AL7: =AJ7*AK7*W7 -> 1 | AM7: =Liq_0-Round_cost*B7+(1-Pledge_share)*P7 -> 620 | AN7: =AM7-Round_cost*C7+(1-Pledge_share)*Q7 -> 620 | AO7: =AN7-Round_cost*D7+(1-Pledge_share)*R7 -> 620 | AP7: =AO7-Round_cost*E7+(1-Pledge_share)*S7 -> 620 | AQ7: =AP7-Round_cost*F7+(1-Pledge_share)*T7 -> 620 | AR7: =AQ7-Round_cost*G7+(1-Pledge_share)*U7 -> 535 | AS7: =IF(B7=1,Liq_0-Round_cost,1000000000) -> 1000000000 | AT7: =IF(C7=1,AM7-Round_cost,1000000000) -> 1000000000 | AU7: =IF(D7=1,AN7-Round_cost,1000000000) -> 1000000000 | AV7: =IF(E7=1,AO7-Round_cost,1000000000) -> 1000000000 | AW7: =IF(F7=1,AP7-Round_cost,1000000000) -> 1000000000 | AX7: =IF(G7=1,AQ7-Round_cost,1000000000) -> 500 | AY7: =IF(AND(MIN(AM7:AR7)>=Floor_liq-0.000000001,MIN(AS7:AX7)>=Floor_liq-0.000000001),1,0) -> 1 | AZ7: =IF(AR7>=End_liq-0.000000001,1,0) -> 1 | BA7: =AY7*AZ7*W7 -> 1 | BB7: =Pledge_share*V7 -> 35 | BC7: =IF(BA7=1,H7*10000+BB7,-1) -> 10035 | BD7: =U7 -> 70 | BE7: =AC7 -> 570 | BF7: =IF(AL7=1,AC7-End_liq,-1000000000) -> 100 | BG7: =IF(AL7=1,BF7+BG$4*BD7,-1000000000) -> 100 | BH7: =IF(AL7=1,BF7+BH$4*BD7,-1000000000) -> 450 | BI7: =IF(AL7=1,BF7+BI$4*BD7,-1000000000) -> 800 | BJ7: =IF(AL7=1,BF7+BJ$4*BD7,-1000000000) -> 1500 | BK7: =IF(AL7=1,BF7+BK$4*BD7,-1000000000) -> 2900 | BL7: =IF(AL7=1,BF7+BL$4*BD7,-1000000000) -> 4300 | BM7: =IF(H7=0,1,IF(I7=VALUE(LEFT("123456",H7)),1,0)) -> 0 | BN7: =IF(BG7>0,1000*BG7,-1000000000000) -> 100000 | BO7: =IF(BG7>0,BG7+100,-1000000000) -> 200 | BP7: =IF(BG7>0,LN(BG7),-1000000000) -> 4.6051702
A8: 2 | B8: =MOD(INT($A8/32),2) -> 0 | C8: =MOD(INT($A8/16),2) -> 0 | D8: =MOD(INT($A8/8),2) -> 0 | E8: =MOD(INT($A8/4),2) -> 0 | F8: =MOD(INT($A8/2),2) -> 1 | G8: =MOD(INT($A8/1),2) -> 0 | H8: =SUM(B8:G8) -> 1 | I8: =IF(H8=0,0,VALUE(IF(B8=1,"1","")&IF(C8=1,"2","")&IF(D8=1,"3","")&IF(E8=1,"4","")&IF(F8=1,"5","")&IF(G8=1,"6",""))) -> 5 | J8: =IF(B8=1,Eff_0+Gap_closed*(Eff_ceiling-Eff_0),Eff_0) -> 71 | K8: =IF(C8=1,J8+Gap_closed*(Eff_ceiling-J8),J8) -> 71 | L8: =IF(D8=1,K8+Gap_closed*(Eff_ceiling-K8),K8) -> 71 | M8: =IF(E8=1,L8+Gap_closed*(Eff_ceiling-L8),L8) -> 71 | N8: =IF(F8=1,M8+Gap_closed*(Eff_ceiling-M8),M8) -> 78 | O8: =IF(G8=1,N8+Gap_closed*(Eff_ceiling-N8),N8) -> 78 | P8: =Sav_point*(J8-Eff_0) -> 0 | Q8: =Sav_point*(K8-Eff_0) -> 0 | R8: =Sav_point*(L8-Eff_0) -> 0 | S8: =Sav_point*(M8-Eff_0) -> 0 | T8: =Sav_point*(N8-Eff_0) -> 70 | U8: =Sav_point*(O8-Eff_0) -> 70 | V8: =SUM(P8:U8) -> 140 | W8: =IF(AND(H8>0,Cap_0<Cap_min),0,1) -> 1 | X8: =Liq_0-Round_cost*B8+1*P8 -> 620 | Y8: =X8-Round_cost*C8+1*Q8 -> 620 | Z8: =Y8-Round_cost*D8+1*R8 -> 620 | AA8: =Z8-Round_cost*E8+1*S8 -> 620 | AB8: =AA8-Round_cost*F8+1*T8 -> 570 | AC8: =AB8-Round_cost*G8+1*U8 -> 640 | AD8: =IF(B8=1,Liq_0-Round_cost,1000000000) -> 1000000000 | AE8: =IF(C8=1,X8-Round_cost,1000000000) -> 1000000000 | AF8: =IF(D8=1,Y8-Round_cost,1000000000) -> 1000000000 | AG8: =IF(E8=1,Z8-Round_cost,1000000000) -> 1000000000 | AH8: =IF(F8=1,AA8-Round_cost,1000000000) -> 500 | AI8: =IF(G8=1,AB8-Round_cost,1000000000) -> 1000000000 | AJ8: =IF(AND(MIN(X8:AC8)>=Floor_liq-0.000000001,MIN(AD8:AI8)>=Floor_liq-0.000000001),1,0) -> 1 | AK8: =IF(AC8>=End_liq-0.000000001,1,0) -> 1 | AL8: =AJ8*AK8*W8 -> 1 | AM8: =Liq_0-Round_cost*B8+(1-Pledge_share)*P8 -> 620 | AN8: =AM8-Round_cost*C8+(1-Pledge_share)*Q8 -> 620 | AO8: =AN8-Round_cost*D8+(1-Pledge_share)*R8 -> 620 | AP8: =AO8-Round_cost*E8+(1-Pledge_share)*S8 -> 620 | AQ8: =AP8-Round_cost*F8+(1-Pledge_share)*T8 -> 535 | AR8: =AQ8-Round_cost*G8+(1-Pledge_share)*U8 -> 570 | AS8: =IF(B8=1,Liq_0-Round_cost,1000000000) -> 1000000000 | AT8: =IF(C8=1,AM8-Round_cost,1000000000) -> 1000000000 | AU8: =IF(D8=1,AN8-Round_cost,1000000000) -> 1000000000 | AV8: =IF(E8=1,AO8-Round_cost,1000000000) -> 1000000000 | AW8: =IF(F8=1,AP8-Round_cost,1000000000) -> 500 | AX8: =IF(G8=1,AQ8-Round_cost,1000000000) -> 1000000000 | AY8: =IF(AND(MIN(AM8:AR8)>=Floor_liq-0.000000001,MIN(AS8:AX8)>=Floor_liq-0.000000001),1,0) -> 1 | AZ8: =IF(AR8>=End_liq-0.000000001,1,0) -> 1 | BA8: =AY8*AZ8*W8 -> 1 | BB8: =Pledge_share*V8 -> 70 | BC8: =IF(BA8=1,H8*10000+BB8,-1) -> 10070 | BD8: =U8 -> 70 | BE8: =AC8 -> 640 | BF8: =IF(AL8=1,AC8-End_liq,-1000000000) -> 170 | BG8: =IF(AL8=1,BF8+BG$4*BD8,-1000000000) -> 170 | BH8: =IF(AL8=1,BF8+BH$4*BD8,-1000000000) -> 520 | BI8: =IF(AL8=1,BF8+BI$4*BD8,-1000000000) -> 870 | BJ8: =IF(AL8=1,BF8+BJ$4*BD8,-1000000000) -> 1570 | BK8: =IF(AL8=1,BF8+BK$4*BD8,-1000000000) -> 2970 | BL8: =IF(AL8=1,BF8+BL$4*BD8,-1000000000) -> 4370 | BM8: =IF(H8=0,1,IF(I8=VALUE(LEFT("123456",H8)),1,0)) -> 0 | BN8: =IF(BG8>0,1000*BG8,-1000000000000) -> 170000 | BO8: =IF(BG8>0,BG8+100,-1000000000) -> 270 | BP8: =IF(BG8>0,LN(BG8),-1000000000) -> 5.1357984
A9: 3 | B9: =MOD(INT($A9/32),2) -> 0 | C9: =MOD(INT($A9/16),2) -> 0 | D9: =MOD(INT($A9/8),2) -> 0 | E9: =MOD(INT($A9/4),2) -> 0 | F9: =MOD(INT($A9/2),2) -> 1 | G9: =MOD(INT($A9/1),2) -> 1 | H9: =SUM(B9:G9) -> 2 | I9: =IF(H9=0,0,VALUE(IF(B9=1,"1","")&IF(C9=1,"2","")&IF(D9=1,"3","")&IF(E9=1,"4","")&IF(F9=1,"5","")&IF(G9=1,"6",""))) -> 56 | J9: =IF(B9=1,Eff_0+Gap_closed*(Eff_ceiling-Eff_0),Eff_0) -> 71 | K9: =IF(C9=1,J9+Gap_closed*(Eff_ceiling-J9),J9) -> 71 | L9: =IF(D9=1,K9+Gap_closed*(Eff_ceiling-K9),K9) -> 71 | M9: =IF(E9=1,L9+Gap_closed*(Eff_ceiling-L9),L9) -> 71 | N9: =IF(F9=1,M9+Gap_closed*(Eff_ceiling-M9),M9) -> 78 | O9: =IF(G9=1,N9+Gap_closed*(Eff_ceiling-N9),N9) -> 81.5 | P9: =Sav_point*(J9-Eff_0) -> 0 | Q9: =Sav_point*(K9-Eff_0) -> 0 | R9: =Sav_point*(L9-Eff_0) -> 0 | S9: =Sav_point*(M9-Eff_0) -> 0 | T9: =Sav_point*(N9-Eff_0) -> 70 | U9: =Sav_point*(O9-Eff_0) -> 105 | V9: =SUM(P9:U9) -> 175 | W9: =IF(AND(H9>0,Cap_0<Cap_min),0,1) -> 1 | X9: =Liq_0-Round_cost*B9+1*P9 -> 620 | Y9: =X9-Round_cost*C9+1*Q9 -> 620 | Z9: =Y9-Round_cost*D9+1*R9 -> 620 | AA9: =Z9-Round_cost*E9+1*S9 -> 620 | AB9: =AA9-Round_cost*F9+1*T9 -> 570 | AC9: =AB9-Round_cost*G9+1*U9 -> 555 | AD9: =IF(B9=1,Liq_0-Round_cost,1000000000) -> 1000000000 | AE9: =IF(C9=1,X9-Round_cost,1000000000) -> 1000000000 | AF9: =IF(D9=1,Y9-Round_cost,1000000000) -> 1000000000 | AG9: =IF(E9=1,Z9-Round_cost,1000000000) -> 1000000000 | AH9: =IF(F9=1,AA9-Round_cost,1000000000) -> 500 | AI9: =IF(G9=1,AB9-Round_cost,1000000000) -> 450 | AJ9: =IF(AND(MIN(X9:AC9)>=Floor_liq-0.000000001,MIN(AD9:AI9)>=Floor_liq-0.000000001),1,0) -> 1 | AK9: =IF(AC9>=End_liq-0.000000001,1,0) -> 1 | AL9: =AJ9*AK9*W9 -> 1 | AM9: =Liq_0-Round_cost*B9+(1-Pledge_share)*P9 -> 620 | AN9: =AM9-Round_cost*C9+(1-Pledge_share)*Q9 -> 620 | AO9: =AN9-Round_cost*D9+(1-Pledge_share)*R9 -> 620 | AP9: =AO9-Round_cost*E9+(1-Pledge_share)*S9 -> 620 | AQ9: =AP9-Round_cost*F9+(1-Pledge_share)*T9 -> 535 | AR9: =AQ9-Round_cost*G9+(1-Pledge_share)*U9 -> 467.5 | AS9: =IF(B9=1,Liq_0-Round_cost,1000000000) -> 1000000000 | AT9: =IF(C9=1,AM9-Round_cost,1000000000) -> 1000000000 | AU9: =IF(D9=1,AN9-Round_cost,1000000000) -> 1000000000 | AV9: =IF(E9=1,AO9-Round_cost,1000000000) -> 1000000000 | AW9: =IF(F9=1,AP9-Round_cost,1000000000) -> 500 | AX9: =IF(G9=1,AQ9-Round_cost,1000000000) -> 415 | AY9: =IF(AND(MIN(AM9:AR9)>=Floor_liq-0.000000001,MIN(AS9:AX9)>=Floor_liq-0.000000001),1,0) -> 1 | AZ9: =IF(AR9>=End_liq-0.000000001,1,0) -> 0 | BA9: =AY9*AZ9*W9 -> 0 | BB9: =Pledge_share*V9 -> 87.5 | BC9: =IF(BA9=1,H9*10000+BB9,-1) -> -1 | BD9: =U9 -> 105 | BE9: =AC9 -> 555 | BF9: =IF(AL9=1,AC9-End_liq,-1000000000) -> 85 | BG9: =IF(AL9=1,BF9+BG$4*BD9,-1000000000) -> 85 | BH9: =IF(AL9=1,BF9+BH$4*BD9,-1000000000) -> 610 | BI9: =IF(AL9=1,BF9+BI$4*BD9,-1000000000) -> 1135 | BJ9: =IF(AL9=1,BF9+BJ$4*BD9,-1000000000) -> 2185 | BK9: =IF(AL9=1,BF9+BK$4*BD9,-1000000000) -> 4285 | BL9: =IF(AL9=1,BF9+BL$4*BD9,-1000000000) -> 6385 | BM9: =IF(H9=0,1,IF(I9=VALUE(LEFT("123456",H9)),1,0)) -> 0 | BN9: =IF(BG9>0,1000*BG9,-1000000000000) -> 85000 | BO9: =IF(BG9>0,BG9+100,-1000000000) -> 185 | BP9: =IF(BG9>0,LN(BG9),-1000000000) -> 4.4426513
A10: 4 | B10: =MOD(INT($A10/32),2) -> 0 | C10: =MOD(INT($A10/16),2) -> 0 | D10: =MOD(INT($A10/8),2) -> 0 | E10: =MOD(INT($A10/4),2) -> 1 | F10: =MOD(INT($A10/2),2) -> 0 | G10: =MOD(INT($A10/1),2) -> 0 | H10: =SUM(B10:G10) -> 1 | I10: =IF(H10=0,0,VALUE(IF(B10=1,"1","")&IF(C10=1,"2","")&IF(D10=1,"3","")&IF(E10=1,"4","")&IF(F10=1,"5","")&IF(G10=1,"6",""))) -> 4 | J10: =IF(B10=1,Eff_0+Gap_closed*(Eff_ceiling-Eff_0),Eff_0) -> 71 | K10: =IF(C10=1,J10+Gap_closed*(Eff_ceiling-J10),J10) -> 71 | L10: =IF(D10=1,K10+Gap_closed*(Eff_ceiling-K10),K10) -> 71 | M10: =IF(E10=1,L10+Gap_closed*(Eff_ceiling-L10),L10) -> 78 | N10: =IF(F10=1,M10+Gap_closed*(Eff_ceiling-M10),M10) -> 78 | O10: =IF(G10=1,N10+Gap_closed*(Eff_ceiling-N10),N10) -> 78 | P10: =Sav_point*(J10-Eff_0) -> 0 | Q10: =Sav_point*(K10-Eff_0) -> 0 | R10: =Sav_point*(L10-Eff_0) -> 0 | S10: =Sav_point*(M10-Eff_0) -> 70 | T10: =Sav_point*(N10-Eff_0) -> 70 | U10: =Sav_point*(O10-Eff_0) -> 70 | V10: =SUM(P10:U10) -> 210 | W10: =IF(AND(H10>0,Cap_0<Cap_min),0,1) -> 1 | X10: =Liq_0-Round_cost*B10+1*P10 -> 620 | Y10: =X10-Round_cost*C10+1*Q10 -> 620 | Z10: =Y10-Round_cost*D10+1*R10 -> 620 | AA10: =Z10-Round_cost*E10+1*S10 -> 570 | AB10: =AA10-Round_cost*F10+1*T10 -> 640 | AC10: =AB10-Round_cost*G10+1*U10 -> 710 | AD10: =IF(B10=1,Liq_0-Round_cost,1000000000) -> 1000000000 | AE10: =IF(C10=1,X10-Round_cost,1000000000) -> 1000000000 | AF10: =IF(D10=1,Y10-Round_cost,1000000000) -> 1000000000 | AG10: =IF(E10=1,Z10-Round_cost,1000000000) -> 500 | AH10: =IF(F10=1,AA10-Round_cost,1000000000) -> 1000000000 | AI10: =IF(G10=1,AB10-Round_cost,1000000000) -> 1000000000 | AJ10: =IF(AND(MIN(X10:AC10)>=Floor_liq-0.000000001,MIN(AD10:AI10)>=Floor_liq-0.000000001),1,0) -> 1 | AK10: =IF(AC10>=End_liq-0.000000001,1,0) -> 1 | AL10: =AJ10*AK10*W10 -> 1 | AM10: =Liq_0-Round_cost*B10+(1-Pledge_share)*P10 -> 620 | AN10: =AM10-Round_cost*C10+(1-Pledge_share)*Q10 -> 620 | AO10: =AN10-Round_cost*D10+(1-Pledge_share)*R10 -> 620 | AP10: =AO10-Round_cost*E10+(1-Pledge_share)*S10 -> 535 | AQ10: =AP10-Round_cost*F10+(1-Pledge_share)*T10 -> 570 | AR10: =AQ10-Round_cost*G10+(1-Pledge_share)*U10 -> 605 | AS10: =IF(B10=1,Liq_0-Round_cost,1000000000) -> 1000000000 | AT10: =IF(C10=1,AM10-Round_cost,1000000000) -> 1000000000 | AU10: =IF(D10=1,AN10-Round_cost,1000000000) -> 1000000000 | AV10: =IF(E10=1,AO10-Round_cost,1000000000) -> 500 | AW10: =IF(F10=1,AP10-Round_cost,1000000000) -> 1000000000 | AX10: =IF(G10=1,AQ10-Round_cost,1000000000) -> 1000000000 | AY10: =IF(AND(MIN(AM10:AR10)>=Floor_liq-0.000000001,MIN(AS10:AX10)>=Floor_liq-0.000000001),1,0) -> 1 | AZ10: =IF(AR10>=End_liq-0.000000001,1,0) -> 1 | BA10: =AY10*AZ10*W10 -> 1 | BB10: =Pledge_share*V10 -> 105 | BC10: =IF(BA10=1,H10*10000+BB10,-1) -> 10105 | BD10: =U10 -> 70 | BE10: =AC10 -> 710 | BF10: =IF(AL10=1,AC10-End_liq,-1000000000) -> 240 | BG10: =IF(AL10=1,BF10+BG$4*BD10,-1000000000) -> 240 | BH10: =IF(AL10=1,BF10+BH$4*BD10,-1000000000) -> 590 | BI10: =IF(AL10=1,BF10+BI$4*BD10,-1000000000) -> 940 | BJ10: =IF(AL10=1,BF10+BJ$4*BD10,-1000000000) -> 1640 | BK10: =IF(AL10=1,BF10+BK$4*BD10,-1000000000) -> 3040 | BL10: =IF(AL10=1,BF10+BL$4*BD10,-1000000000) -> 4440 | BM10: =IF(H10=0,1,IF(I10=VALUE(LEFT("123456",H10)),1,0)) -> 0 | BN10: =IF(BG10>0,1000*BG10,-1000000000000) -> 240000 | BO10: =IF(BG10>0,BG10+100,-1000000000) -> 340 | BP10: =IF(BG10>0,LN(BG10),-1000000000) -> 5.4806389
A11: 5 | B11: =MOD(INT($A11/32),2) -> 0 | C11: =MOD(INT($A11/16),2) -> 0 | D11: =MOD(INT($A11/8),2) -> 0 | E11: =MOD(INT($A11/4),2) -> 1 | F11: =MOD(INT($A11/2),2) -> 0 | G11: =MOD(INT($A11/1),2) -> 1 | H11: =SUM(B11:G11) -> 2 | I11: =IF(H11=0,0,VALUE(IF(B11=1,"1","")&IF(C11=1,"2","")&IF(D11=1,"3","")&IF(E11=1,"4","")&IF(F11=1,"5","")&IF(G11=1,"6",""))) -> 46 | J11: =IF(B11=1,Eff_0+Gap_closed*(Eff_ceiling-Eff_0),Eff_0) -> 71 | K11: =IF(C11=1,J11+Gap_closed*(Eff_ceiling-J11),J11) -> 71 | L11: =IF(D11=1,K11+Gap_closed*(Eff_ceiling-K11),K11) -> 71 | M11: =IF(E11=1,L11+Gap_closed*(Eff_ceiling-L11),L11) -> 78 | N11: =IF(F11=1,M11+Gap_closed*(Eff_ceiling-M11),M11) -> 78 | O11: =IF(G11=1,N11+Gap_closed*(Eff_ceiling-N11),N11) -> 81.5 | P11: =Sav_point*(J11-Eff_0) -> 0 | Q11: =Sav_point*(K11-Eff_0) -> 0 | R11: =Sav_point*(L11-Eff_0) -> 0 | S11: =Sav_point*(M11-Eff_0) -> 70 | T11: =Sav_point*(N11-Eff_0) -> 70 | U11: =Sav_point*(O11-Eff_0) -> 105 | V11: =SUM(P11:U11) -> 245 | W11: =IF(AND(H11>0,Cap_0<Cap_min),0,1) -> 1 | X11: =Liq_0-Round_cost*B11+1*P11 -> 620 | Y11: =X11-Round_cost*C11+1*Q11 -> 620 | Z11: =Y11-Round_cost*D11+1*R11 -> 620 | AA11: =Z11-Round_cost*E11+1*S11 -> 570 | AB11: =AA11-Round_cost*F11+1*T11 -> 640 | AC11: =AB11-Round_cost*G11+1*U11 -> 625 | AD11: =IF(B11=1,Liq_0-Round_cost,1000000000) -> 1000000000 | AE11: =IF(C11=1,X11-Round_cost,1000000000) -> 1000000000 | AF11: =IF(D11=1,Y11-Round_cost,1000000000) -> 1000000000 | AG11: =IF(E11=1,Z11-Round_cost,1000000000) -> 500 | AH11: =IF(F11=1,AA11-Round_cost,1000000000) -> 1000000000 | AI11: =IF(G11=1,AB11-Round_cost,1000000000) -> 520 | AJ11: =IF(AND(MIN(X11:AC11)>=Floor_liq-0.000000001,MIN(AD11:AI11)>=Floor_liq-0.000000001),1,0) -> 1 | AK11: =IF(AC11>=End_liq-0.000000001,1,0) -> 1 | AL11: =AJ11*AK11*W11 -> 1 | AM11: =Liq_0-Round_cost*B11+(1-Pledge_share)*P11 -> 620 | AN11: =AM11-Round_cost*C11+(1-Pledge_share)*Q11 -> 620 | AO11: =AN11-Round_cost*D11+(1-Pledge_share)*R11 -> 620 | AP11: =AO11-Round_cost*E11+(1-Pledge_share)*S11 -> 535 | AQ11: =AP11-Round_cost*F11+(1-Pledge_share)*T11 -> 570 | AR11: =AQ11-Round_cost*G11+(1-Pledge_share)*U11 -> 502.5 | AS11: =IF(B11=1,Liq_0-Round_cost,1000000000) -> 1000000000 | AT11: =IF(C11=1,AM11-Round_cost,1000000000) -> 1000000000 | AU11: =IF(D11=1,AN11-Round_cost,1000000000) -> 1000000000 | AV11: =IF(E11=1,AO11-Round_cost,1000000000) -> 500 | AW11: =IF(F11=1,AP11-Round_cost,1000000000) -> 1000000000 | AX11: =IF(G11=1,AQ11-Round_cost,1000000000) -> 450 | AY11: =IF(AND(MIN(AM11:AR11)>=Floor_liq-0.000000001,MIN(AS11:AX11)>=Floor_liq-0.000000001),1,0) -> 1 | AZ11: =IF(AR11>=End_liq-0.000000001,1,0) -> 1 | BA11: =AY11*AZ11*W11 -> 1 | BB11: =Pledge_share*V11 -> 122.5 | BC11: =IF(BA11=1,H11*10000+BB11,-1) -> 20122.5 | BD11: =U11 -> 105 | BE11: =AC11 -> 625 | BF11: =IF(AL11=1,AC11-End_liq,-1000000000) -> 155 | BG11: =IF(AL11=1,BF11+BG$4*BD11,-1000000000) -> 155 | BH11: =IF(AL11=1,BF11+BH$4*BD11,-1000000000) -> 680 | BI11: =IF(AL11=1,BF11+BI$4*BD11,-1000000000) -> 1205 | BJ11: =IF(AL11=1,BF11+BJ$4*BD11,-1000000000) -> 2255 | BK11: =IF(AL11=1,BF11+BK$4*BD11,-1000000000) -> 4355 | BL11: =IF(AL11=1,BF11+BL$4*BD11,-1000000000) -> 6455 | BM11: =IF(H11=0,1,IF(I11=VALUE(LEFT("123456",H11)),1,0)) -> 0 | BN11: =IF(BG11>0,1000*BG11,-1000000000000) -> 155000 | BO11: =IF(BG11>0,BG11+100,-1000000000) -> 255 | BP11: =IF(BG11>0,LN(BG11),-1000000000) -> 5.0434251
A12: 6 | B12: =MOD(INT($A12/32),2) -> 0 | C12: =MOD(INT($A12/16),2) -> 0 | D12: =MOD(INT($A12/8),2) -> 0 | E12: =MOD(INT($A12/4),2) -> 1 | F12: =MOD(INT($A12/2),2) -> 1 | G12: =MOD(INT($A12/1),2) -> 0 | H12: =SUM(B12:G12) -> 2 | I12: =IF(H12=0,0,VALUE(IF(B12=1,"1","")&IF(C12=1,"2","")&IF(D12=1,"3","")&IF(E12=1,"4","")&IF(F12=1,"5","")&IF(G12=1,"6",""))) -> 45 | J12: =IF(B12=1,Eff_0+Gap_closed*(Eff_ceiling-Eff_0),Eff_0) -> 71 | K12: =IF(C12=1,J12+Gap_closed*(Eff_ceiling-J12),J12) -> 71 | L12: =IF(D12=1,K12+Gap_closed*(Eff_ceiling-K12),K12) -> 71 | M12: =IF(E12=1,L12+Gap_closed*(Eff_ceiling-L12),L12) -> 78 | N12: =IF(F12=1,M12+Gap_closed*(Eff_ceiling-M12),M12) -> 81.5 | O12: =IF(G12=1,N12+Gap_closed*(Eff_ceiling-N12),N12) -> 81.5 | P12: =Sav_point*(J12-Eff_0) -> 0 | Q12: =Sav_point*(K12-Eff_0) -> 0 | R12: =Sav_point*(L12-Eff_0) -> 0 | S12: =Sav_point*(M12-Eff_0) -> 70 | T12: =Sav_point*(N12-Eff_0) -> 105 | U12: =Sav_point*(O12-Eff_0) -> 105 | V12: =SUM(P12:U12) -> 280 | W12: =IF(AND(H12>0,Cap_0<Cap_min),0,1) -> 1 | X12: =Liq_0-Round_cost*B12+1*P12 -> 620 | Y12: =X12-Round_cost*C12+1*Q12 -> 620 | Z12: =Y12-Round_cost*D12+1*R12 -> 620 | AA12: =Z12-Round_cost*E12+1*S12 -> 570 | AB12: =AA12-Round_cost*F12+1*T12 -> 555 | AC12: =AB12-Round_cost*G12+1*U12 -> 660 | AD12: =IF(B12=1,Liq_0-Round_cost,1000000000) -> 1000000000 | AE12: =IF(C12=1,X12-Round_cost,1000000000) -> 1000000000 | AF12: =IF(D12=1,Y12-Round_cost,1000000000) -> 1000000000 | AG12: =IF(E12=1,Z12-Round_cost,1000000000) -> 500 | AH12: =IF(F12=1,AA12-Round_cost,1000000000) -> 450 | AI12: =IF(G12=1,AB12-Round_cost,1000000000) -> 1000000000 | AJ12: =IF(AND(MIN(X12:AC12)>=Floor_liq-0.000000001,MIN(AD12:AI12)>=Floor_liq-0.000000001),1,0) -> 1 | AK12: =IF(AC12>=End_liq-0.000000001,1,0) -> 1 | AL12: =AJ12*AK12*W12 -> 1 | AM12: =Liq_0-Round_cost*B12+(1-Pledge_share)*P12 -> 620 | AN12: =AM12-Round_cost*C12+(1-Pledge_share)*Q12 -> 620 | AO12: =AN12-Round_cost*D12+(1-Pledge_share)*R12 -> 620 | AP12: =AO12-Round_cost*E12+(1-Pledge_share)*S12 -> 535 | AQ12: =AP12-Round_cost*F12+(1-Pledge_share)*T12 -> 467.5 | AR12: =AQ12-Round_cost*G12+(1-Pledge_share)*U12 -> 520 | AS12: =IF(B12=1,Liq_0-Round_cost,1000000000) -> 1000000000 | AT12: =IF(C12=1,AM12-Round_cost,1000000000) -> 1000000000 | AU12: =IF(D12=1,AN12-Round_cost,1000000000) -> 1000000000 | AV12: =IF(E12=1,AO12-Round_cost,1000000000) -> 500 | AW12: =IF(F12=1,AP12-Round_cost,1000000000) -> 415 | AX12: =IF(G12=1,AQ12-Round_cost,1000000000) -> 1000000000 | AY12: =IF(AND(MIN(AM12:AR12)>=Floor_liq-0.000000001,MIN(AS12:AX12)>=Floor_liq-0.000000001),1,0) -> 1 | AZ12: =IF(AR12>=End_liq-0.000000001,1,0) -> 1 | BA12: =AY12*AZ12*W12 -> 1 | BB12: =Pledge_share*V12 -> 140 | BC12: =IF(BA12=1,H12*10000+BB12,-1) -> 20140 | BD12: =U12 -> 105 | BE12: =AC12 -> 660 | BF12: =IF(AL12=1,AC12-End_liq,-1000000000) -> 190 | BG12: =IF(AL12=1,BF12+BG$4*BD12,-1000000000) -> 190 | BH12: =IF(AL12=1,BF12+BH$4*BD12,-1000000000) -> 715 | BI12: =IF(AL12=1,BF12+BI$4*BD12,-1000000000) -> 1240 | BJ12: =IF(AL12=1,BF12+BJ$4*BD12,-1000000000) -> 2290 | BK12: =IF(AL12=1,BF12+BK$4*BD12,-1000000000) -> 4390 | BL12: =IF(AL12=1,BF12+BL$4*BD12,-1000000000) -> 6490 | BM12: =IF(H12=0,1,IF(I12=VALUE(LEFT("123456",H12)),1,0)) -> 0 | BN12: =IF(BG12>0,1000*BG12,-1000000000000) -> 190000 | BO12: =IF(BG12>0,BG12+100,-1000000000) -> 290 | BP12: =IF(BG12>0,LN(BG12),-1000000000) -> 5.2470241
A13: 7 | B13: =MOD(INT($A13/32),2) -> 0 | C13: =MOD(INT($A13/16),2) -> 0 | D13: =MOD(INT($A13/8),2) -> 0 | E13: =MOD(INT($A13/4),2) -> 1 | F13: =MOD(INT($A13/2),2) -> 1 | G13: =MOD(INT($A13/1),2) -> 1 | H13: =SUM(B13:G13) -> 3 | I13: =IF(H13=0,0,VALUE(IF(B13=1,"1","")&IF(C13=1,"2","")&IF(D13=1,"3","")&IF(E13=1,"4","")&IF(F13=1,"5","")&IF(G13=1,"6",""))) -> 456 | J13: =IF(B13=1,Eff_0+Gap_closed*(Eff_ceiling-Eff_0),Eff_0) -> 71 | K13: =IF(C13=1,J13+Gap_closed*(Eff_ceiling-J13),J13) -> 71 | L13: =IF(D13=1,K13+Gap_closed*(Eff_ceiling-K13),K13) -> 71 | M13: =IF(E13=1,L13+Gap_closed*(Eff_ceiling-L13),L13) -> 78 | N13: =IF(F13=1,M13+Gap_closed*(Eff_ceiling-M13),M13) -> 81.5 | O13: =IF(G13=1,N13+Gap_closed*(Eff_ceiling-N13),N13) -> 83.25 | P13: =Sav_point*(J13-Eff_0) -> 0 | Q13: =Sav_point*(K13-Eff_0) -> 0 | R13: =Sav_point*(L13-Eff_0) -> 0 | S13: =Sav_point*(M13-Eff_0) -> 70 | T13: =Sav_point*(N13-Eff_0) -> 105 | U13: =Sav_point*(O13-Eff_0) -> 122.5 | V13: =SUM(P13:U13) -> 297.5 | W13: =IF(AND(H13>0,Cap_0<Cap_min),0,1) -> 1 | X13: =Liq_0-Round_cost*B13+1*P13 -> 620 | Y13: =X13-Round_cost*C13+1*Q13 -> 620 | Z13: =Y13-Round_cost*D13+1*R13 -> 620 | AA13: =Z13-Round_cost*E13+1*S13 -> 570 | AB13: =AA13-Round_cost*F13+1*T13 -> 555 | AC13: =AB13-Round_cost*G13+1*U13 -> 557.5 | AD13: =IF(B13=1,Liq_0-Round_cost,1000000000) -> 1000000000 | AE13: =IF(C13=1,X13-Round_cost,1000000000) -> 1000000000 | AF13: =IF(D13=1,Y13-Round_cost,1000000000) -> 1000000000 | AG13: =IF(E13=1,Z13-Round_cost,1000000000) -> 500 | AH13: =IF(F13=1,AA13-Round_cost,1000000000) -> 450 | AI13: =IF(G13=1,AB13-Round_cost,1000000000) -> 435 | AJ13: =IF(AND(MIN(X13:AC13)>=Floor_liq-0.000000001,MIN(AD13:AI13)>=Floor_liq-0.000000001),1,0) -> 1 | AK13: =IF(AC13>=End_liq-0.000000001,1,0) -> 1 | AL13: =AJ13*AK13*W13 -> 1 | AM13: =Liq_0-Round_cost*B13+(1-Pledge_share)*P13 -> 620 | AN13: =AM13-Round_cost*C13+(1-Pledge_share)*Q13 -> 620 | AO13: =AN13-Round_cost*D13+(1-Pledge_share)*R13 -> 620 | AP13: =AO13-Round_cost*E13+(1-Pledge_share)*S13 -> 535 | AQ13: =AP13-Round_cost*F13+(1-Pledge_share)*T13 -> 467.5 | AR13: =AQ13-Round_cost*G13+(1-Pledge_share)*U13 -> 408.75 | AS13: =IF(B13=1,Liq_0-Round_cost,1000000000) -> 1000000000 | AT13: =IF(C13=1,AM13-Round_cost,1000000000) -> 1000000000 | AU13: =IF(D13=1,AN13-Round_cost,1000000000) -> 1000000000 | AV13: =IF(E13=1,AO13-Round_cost,1000000000) -> 500 | AW13: =IF(F13=1,AP13-Round_cost,1000000000) -> 415 | AX13: =IF(G13=1,AQ13-Round_cost,1000000000) -> 347.5 | AY13: =IF(AND(MIN(AM13:AR13)>=Floor_liq-0.000000001,MIN(AS13:AX13)>=Floor_liq-0.000000001),1,0) -> 0 | AZ13: =IF(AR13>=End_liq-0.000000001,1,0) -> 0 | BA13: =AY13*AZ13*W13 -> 0 | BB13: =Pledge_share*V13 -> 148.75 | BC13: =IF(BA13=1,H13*10000+BB13,-1) -> -1 | BD13: =U13 -> 122.5 | BE13: =AC13 -> 557.5 | BF13: =IF(AL13=1,AC13-End_liq,-1000000000) -> 87.5 | BG13: =IF(AL13=1,BF13+BG$4*BD13,-1000000000) -> 87.5 | BH13: =IF(AL13=1,BF13+BH$4*BD13,-1000000000) -> 700 | BI13: =IF(AL13=1,BF13+BI$4*BD13,-1000000000) -> 1312.5 | BJ13: =IF(AL13=1,BF13+BJ$4*BD13,-1000000000) -> 2537.5 | BK13: =IF(AL13=1,BF13+BK$4*BD13,-1000000000) -> 4987.5 | BL13: =IF(AL13=1,BF13+BL$4*BD13,-1000000000) -> 7437.5 | BM13: =IF(H13=0,1,IF(I13=VALUE(LEFT("123456",H13)),1,0)) -> 0 | BN13: =IF(BG13>0,1000*BG13,-1000000000000) -> 87500 | BO13: =IF(BG13>0,BG13+100,-1000000000) -> 187.5 | BP13: =IF(BG13>0,LN(BG13),-1000000000) -> 4.4716388
A14: 8 | B14: =MOD(INT($A14/32),2) -> 0 | C14: =MOD(INT($A14/16),2) -> 0 | D14: =MOD(INT($A14/8),2) -> 1 | E14: =MOD(INT($A14/4),2) -> 0 | F14: =MOD(INT($A14/2),2) -> 0 | G14: =MOD(INT($A14/1),2) -> 0 | H14: =SUM(B14:G14) -> 1 | I14: =IF(H14=0,0,VALUE(IF(B14=1,"1","")&IF(C14=1,"2","")&IF(D14=1,"3","")&IF(E14=1,"4","")&IF(F14=1,"5","")&IF(G14=1,"6",""))) -> 3 | J14: =IF(B14=1,Eff_0+Gap_closed*(Eff_ceiling-Eff_0),Eff_0) -> 71 | K14: =IF(C14=1,J14+Gap_closed*(Eff_ceiling-J14),J14) -> 71 | L14: =IF(D14=1,K14+Gap_closed*(Eff_ceiling-K14),K14) -> 78 | M14: =IF(E14=1,L14+Gap_closed*(Eff_ceiling-L14),L14) -> 78 | N14: =IF(F14=1,M14+Gap_closed*(Eff_ceiling-M14),M14) -> 78 | O14: =IF(G14=1,N14+Gap_closed*(Eff_ceiling-N14),N14) -> 78 | P14: =Sav_point*(J14-Eff_0) -> 0 | Q14: =Sav_point*(K14-Eff_0) -> 0 | R14: =Sav_point*(L14-Eff_0) -> 70 | S14: =Sav_point*(M14-Eff_0) -> 70 | T14: =Sav_point*(N14-Eff_0) -> 70 | U14: =Sav_point*(O14-Eff_0) -> 70 | V14: =SUM(P14:U14) -> 280 | W14: =IF(AND(H14>0,Cap_0<Cap_min),0,1) -> 1 | X14: =Liq_0-Round_cost*B14+1*P14 -> 620 | Y14: =X14-Round_cost*C14+1*Q14 -> 620 | Z14: =Y14-Round_cost*D14+1*R14 -> 570 | AA14: =Z14-Round_cost*E14+1*S14 -> 640 | AB14: =AA14-Round_cost*F14+1*T14 -> 710 | AC14: =AB14-Round_cost*G14+1*U14 -> 780 | AD14: =IF(B14=1,Liq_0-Round_cost,1000000000) -> 1000000000 | AE14: =IF(C14=1,X14-Round_cost,1000000000) -> 1000000000 | AF14: =IF(D14=1,Y14-Round_cost,1000000000) -> 500 | AG14: =IF(E14=1,Z14-Round_cost,1000000000) -> 1000000000 | AH14: =IF(F14=1,AA14-Round_cost,1000000000) -> 1000000000 | AI14: =IF(G14=1,AB14-Round_cost,1000000000) -> 1000000000 | AJ14: =IF(AND(MIN(X14:AC14)>=Floor_liq-0.000000001,MIN(AD14:AI14)>=Floor_liq-0.000000001),1,0) -> 1 | AK14: =IF(AC14>=End_liq-0.000000001,1,0) -> 1 | AL14: =AJ14*AK14*W14 -> 1 | AM14: =Liq_0-Round_cost*B14+(1-Pledge_share)*P14 -> 620 | AN14: =AM14-Round_cost*C14+(1-Pledge_share)*Q14 -> 620 | AO14: =AN14-Round_cost*D14+(1-Pledge_share)*R14 -> 535 | AP14: =AO14-Round_cost*E14+(1-Pledge_share)*S14 -> 570 | AQ14: =AP14-Round_cost*F14+(1-Pledge_share)*T14 -> 605 | AR14: =AQ14-Round_cost*G14+(1-Pledge_share)*U14 -> 640 | AS14: =IF(B14=1,Liq_0-Round_cost,1000000000) -> 1000000000 | AT14: =IF(C14=1,AM14-Round_cost,1000000000) -> 1000000000 | AU14: =IF(D14=1,AN14-Round_cost,1000000000) -> 500 | AV14: =IF(E14=1,AO14-Round_cost,1000000000) -> 1000000000 | AW14: =IF(F14=1,AP14-Round_cost,1000000000) -> 1000000000 | AX14: =IF(G14=1,AQ14-Round_cost,1000000000) -> 1000000000 | AY14: =IF(AND(MIN(AM14:AR14)>=Floor_liq-0.000000001,MIN(AS14:AX14)>=Floor_liq-0.000000001),1,0) -> 1 | AZ14: =IF(AR14>=End_liq-0.000000001,1,0) -> 1 | BA14: =AY14*AZ14*W14 -> 1 | BB14: =Pledge_share*V14 -> 140 | BC14: =IF(BA14=1,H14*10000+BB14,-1) -> 10140 | BD14: =U14 -> 70 | BE14: =AC14 -> 780 | BF14: =IF(AL14=1,AC14-End_liq,-1000000000) -> 310 | BG14: =IF(AL14=1,BF14+BG$4*BD14,-1000000000) -> 310 | BH14: =IF(AL14=1,BF14+BH$4*BD14,-1000000000) -> 660 | BI14: =IF(AL14=1,BF14+BI$4*BD14,-1000000000) -> 1010 | BJ14: =IF(AL14=1,BF14+BJ$4*BD14,-1000000000) -> 1710 | BK14: =IF(AL14=1,BF14+BK$4*BD14,-1000000000) -> 3110 | BL14: =IF(AL14=1,BF14+BL$4*BD14,-1000000000) -> 4510 | BM14: =IF(H14=0,1,IF(I14=VALUE(LEFT("123456",H14)),1,0)) -> 0 | BN14: =IF(BG14>0,1000*BG14,-1000000000000) -> 310000 | BO14: =IF(BG14>0,BG14+100,-1000000000) -> 410 | BP14: =IF(BG14>0,LN(BG14),-1000000000) -> 5.7365723
A15: 9 | B15: =MOD(INT($A15/32),2) -> 0 | C15: =MOD(INT($A15/16),2) -> 0 | D15: =MOD(INT($A15/8),2) -> 1 | E15: =MOD(INT($A15/4),2) -> 0 | F15: =MOD(INT($A15/2),2) -> 0 | G15: =MOD(INT($A15/1),2) -> 1 | H15: =SUM(B15:G15) -> 2 | I15: =IF(H15=0,0,VALUE(IF(B15=1,"1","")&IF(C15=1,"2","")&IF(D15=1,"3","")&IF(E15=1,"4","")&IF(F15=1,"5","")&IF(G15=1,"6",""))) -> 36 | J15: =IF(B15=1,Eff_0+Gap_closed*(Eff_ceiling-Eff_0),Eff_0) -> 71 | K15: =IF(C15=1,J15+Gap_closed*(Eff_ceiling-J15),J15) -> 71 | L15: =IF(D15=1,K15+Gap_closed*(Eff_ceiling-K15),K15) -> 78 | M15: =IF(E15=1,L15+Gap_closed*(Eff_ceiling-L15),L15) -> 78 | N15: =IF(F15=1,M15+Gap_closed*(Eff_ceiling-M15),M15) -> 78 | O15: =IF(G15=1,N15+Gap_closed*(Eff_ceiling-N15),N15) -> 81.5 | P15: =Sav_point*(J15-Eff_0) -> 0 | Q15: =Sav_point*(K15-Eff_0) -> 0 | R15: =Sav_point*(L15-Eff_0) -> 70 | S15: =Sav_point*(M15-Eff_0) -> 70 | T15: =Sav_point*(N15-Eff_0) -> 70 | U15: =Sav_point*(O15-Eff_0) -> 105 | V15: =SUM(P15:U15) -> 315 | W15: =IF(AND(H15>0,Cap_0<Cap_min),0,1) -> 1 | X15: =Liq_0-Round_cost*B15+1*P15 -> 620 | Y15: =X15-Round_cost*C15+1*Q15 -> 620 | Z15: =Y15-Round_cost*D15+1*R15 -> 570 | AA15: =Z15-Round_cost*E15+1*S15 -> 640 | AB15: =AA15-Round_cost*F15+1*T15 -> 710 | AC15: =AB15-Round_cost*G15+1*U15 -> 695 | AD15: =IF(B15=1,Liq_0-Round_cost,1000000000) -> 1000000000 | AE15: =IF(C15=1,X15-Round_cost,1000000000) -> 1000000000 | AF15: =IF(D15=1,Y15-Round_cost,1000000000) -> 500 | AG15: =IF(E15=1,Z15-Round_cost,1000000000) -> 1000000000 | AH15: =IF(F15=1,AA15-Round_cost,1000000000) -> 1000000000 | AI15: =IF(G15=1,AB15-Round_cost,1000000000) -> 590 | AJ15: =IF(AND(MIN(X15:AC15)>=Floor_liq-0.000000001,MIN(AD15:AI15)>=Floor_liq-0.000000001),1,0) -> 1 | AK15: =IF(AC15>=End_liq-0.000000001,1,0) -> 1 | AL15: =AJ15*AK15*W15 -> 1 | AM15: =Liq_0-Round_cost*B15+(1-Pledge_share)*P15 -> 620 | AN15: =AM15-Round_cost*C15+(1-Pledge_share)*Q15 -> 620 | AO15: =AN15-Round_cost*D15+(1-Pledge_share)*R15 -> 535 | AP15: =AO15-Round_cost*E15+(1-Pledge_share)*S15 -> 570 | AQ15: =AP15-Round_cost*F15+(1-Pledge_share)*T15 -> 605 | AR15: =AQ15-Round_cost*G15+(1-Pledge_share)*U15 -> 537.5 | AS15: =IF(B15=1,Liq_0-Round_cost,1000000000) -> 1000000000 | AT15: =IF(C15=1,AM15-Round_cost,1000000000) -> 1000000000 | AU15: =IF(D15=1,AN15-Round_cost,1000000000) -> 500 | AV15: =IF(E15=1,AO15-Round_cost,1000000000) -> 1000000000 | AW15: =IF(F15=1,AP15-Round_cost,1000000000) -> 1000000000 | AX15: =IF(G15=1,AQ15-Round_cost,1000000000) -> 485 | AY15: =IF(AND(MIN(AM15:AR15)>=Floor_liq-0.000000001,MIN(AS15:AX15)>=Floor_liq-0.000000001),1,0) -> 1 | AZ15: =IF(AR15>=End_liq-0.000000001,1,0) -> 1 | BA15: =AY15*AZ15*W15 -> 1 | BB15: =Pledge_share*V15 -> 157.5 | BC15: =IF(BA15=1,H15*10000+BB15,-1) -> 20157.5 | BD15: =U15 -> 105 | BE15: =AC15 -> 695 | BF15: =IF(AL15=1,AC15-End_liq,-1000000000) -> 225 | BG15: =IF(AL15=1,BF15+BG$4*BD15,-1000000000) -> 225 | BH15: =IF(AL15=1,BF15+BH$4*BD15,-1000000000) -> 750 | BI15: =IF(AL15=1,BF15+BI$4*BD15,-1000000000) -> 1275 | BJ15: =IF(AL15=1,BF15+BJ$4*BD15,-1000000000) -> 2325 | BK15: =IF(AL15=1,BF15+BK$4*BD15,-1000000000) -> 4425 | BL15: =IF(AL15=1,BF15+BL$4*BD15,-1000000000) -> 6525 | BM15: =IF(H15=0,1,IF(I15=VALUE(LEFT("123456",H15)),1,0)) -> 0 | BN15: =IF(BG15>0,1000*BG15,-1000000000000) -> 225000 | BO15: =IF(BG15>0,BG15+100,-1000000000) -> 325 | BP15: =IF(BG15>0,LN(BG15),-1000000000) -> 5.4161004
