Workbook

Sheet README
B1: DCT Laboratory — Vol II, Ch 9: Stochastic Enterprise Optimization
B2: Seed 26209 · Companion to DCT_V2_Ch09_Lab.ipynb and AXIOM Lab 2.9 (module AXIOM-09). Money in $ million.
B4: Worked Example 9.1, Can a Rule Replace the Committed Delay?, with the book's declarations: Volume I, Chapter 8's law for the digital program on the book's 100,000 paths (seed 8), every answer judged on 100,000 fresh paths (seed 26209, the lab's); and Chapter 8's hiring loop with human resources' record (Sections 9.2-9.3).
B5: Declarations: the law, the levers and their prices, the appetite; the hiring loop's declarations.
B6: Plan: the plan's liquidity and the draw quarter by quarter, the share of the draw still ahead, and the Gaussian chance of a breach in each quarter with their sum (Proposition 9.2(i); Figure 9.1).
B7: Packages: Volume I's package from the critical delays of each line (the quantile form), its standard error on fresh paths, the appetite read quarter by quarter, and the CVaR package (Proposition 9.2).
B8: Samples: the margin bounds of Theorem 9.3(iv) (Chernoff and Hoeffding), standard errors, and the sample-size study of Figure 9.2.
B9: Rules: rules that read cash once or every quarter, their costs from lines, delays and shares slowed, and Table 9.3 (Steps 3-4; Figure 9.3(a)).
B10: Information: the clairvoyant's bound, the early warning's allotment and value, and the law with persistent surprises (Proposition 9.3; Step 5; Figure 9.3(b)).
B11: Hiring: certainty equivalence, caution, vigilance, robustness and the value ledger in closed form (Theorems 9.1-9.2; Proposition 9.1).
B12: Engine values (green) are what needs the simulated paths: critical delays, chances, shares slowed, the rules' triggers, the sample-size study. Everything else is a formula.
B13: Reference_Values and Checks: the engine's numbers and a PASS/FAIL comparison with this workbook's formulas.
... B19: Cross-sheet link: green.

Sheet Declarations
A1: Declarations (Worked Example 9.1, Step 1; Chapter 8's hiring loop with HR's record). Money in $ million.
A3: Quantity | B3: Value | C3: Source
A4: Liquidity today | B4: 620 | C4: Meridian's state (Volume I, Chapter 1)
A5: $ million per index point | B5: =B4/100 -> 6.2 | C5: Index 100 = $620 million
A6: Plan without the draw: long-run index | B6: 112 | C6: The Chapter 1 plan relaxes from 100 toward 112
A7: at the rate (a year) | B7: 0.35
A8: The draw's depth (index points) | B8: 28 | C8: The digital program's draw, deepest at two years
A9: The draw is deepest at (years) | B9: 2 | C9: Shape S(t) = (t/2) e^(1 - t/2)
A10: Floor | B10: 350 | C10: The board's floor
A11: Persistence of a surprise a quarter | B11: 0.6 | C11: E' = 0.6 E + w (Volume I, Chapter 8)
A12: Standard deviation of w, a quarter | B12: 50
A13: Funding-window closures a year | B13: 0.1 | C13: About once a decade
A14: Closure size: mean | B14: 120 | C14: Gamma-distributed, never recovered
A15: Closure size: standard deviation | B15: 50
A16: Line fees over the program, per $ of line | B16: 0.03 | C16: About 1 percent a year for three years
A17: A quarter of delay | B17: 8 | C17: The transformation office (Volume I, Worked Example 15.1)
A18: Depth cut by a quarter of delay (points) | B18: 4 | C18: Two quarters of phasing: depth 20
A19: The appetite | B19: 0.05 | C19: At most a 5 percent chance of a breach in some quarter
A20: Paths (the book's, seed 8; fresh, seed 26209) | B20: 100000 | C20: Volume I, Chapter 8's law
A22: Chapter 8's hiring loop, read without the delay, with human resources' record (Online Appendix 9.B.3)
A23: Share of a gap carried over a quarter | B23: 0.9 | C23: Retraining and internal moves close 10 percent
A24: a: the gap closes on its own, a year | B24: =-4*LN(B23) -> 0.42144206 | C24: 4 ln(10/9)
A25: b: share of approvals that become engineers | B25: 0.6
A26: Cost of a gap of 100 engineers, a year | B26: 32 | C26: The program office
A27: q = that cost / 100^2 | B27: =B26/100^2 -> 0.0032
A28: Premium for approving 400 a year, a year | B28: 20 | C28: Human resources
A29: r = that premium / 400^2 | B29: =B28/400^2 -> 0.000125
A30: Hurdle rate a year | B30: 0.1
A31: rho = ln(1 + hurdle rate) | B31: =LN(1+B30) -> 0.09531018
A32: Gap today (engineers) | B32: -100 | C32: 100 short
A33: sigma: departures and early or late starts, sd over a year | B33: 15 | C33: HR's record
A34: A quarter's cohort: standard deviation of its yield | B34: 0.2 | C34: 20 points around 60 percent
A35: s = that sd x sqrt(1/4) | B35: =B34*SQRT(1/4) -> 0.1 | C35: The yield of a quarter's approvals has sd 2s
A36: c: noise that grows with the gap (vigilance) | B36: 0.5 | C36: Theorem 9.2(iv)
A37: Volume I's cautious gain, a year | B37: 2 | C37: Half the gap a quarter
A38: beta = 2a + rho | B38: =2*B24+B31 -> 0.93819431 | C38: Online Appendix 9.B.3: 0.938194

Sheet Plan
A1: The plan, the draw, and the chances quarter by quarter (Section 9.4; Figure 9.1; AXIOM Lab 2.9, step 1)
A2: E_k is Gaussian with mean 0 and variance 50^2 (1 - 0.6^(2k)) / (1 - 0.6^2) (Volume I, Theorem 8.3), so each quarter's chance of a breach from the surprises alone is a formula; the chance over the program needs the paths.
A4: Quarter k | B4: t (years) | C4: Plan index without the draw | D4: Without the draw ($m) | E4: The draw's shape S | F4: $m per point of depth | G4: Planned liquidity ($m) | H4: Draw still ahead, 1 - S | I4: Variance of E_k | J4: Gaussian chance, surprises only | K4: Simulated, surprises only (engine) | L4: Simulated, full law under Volume I's package (engine)
A5: 1 | B5: =A5/4 -> 0.25 | C5: =Xinf+(100-Xinf)*EXP(-Krel*B5) -> 101.00537 | D5: =PerPt*C5 -> 626.23332 | E5: =(B5/Tpk)*EXP(1-B5/Tpk) -> 0.29985941 | F5: =PerPt*E5 -> 1.8591284 | G5: =D5-Depth0*F5 -> 574.17772 | H5: =1-E5 -> 0.70014059 | I5: =SDW^2*(1-AE^(2*A5))/(1-AE^2) -> 2500 | J5: =NORMSDIST((FloorL-G5)/SQRT(I5)) -> 3.6704931e-06 | K5: 0 | L5: 0
A6: 2 | B6: =A6/4 -> 0.5 | C6: =Xinf+(100-Xinf)*EXP(-Krel*B6) -> 101.92652 | D6: =PerPt*C6 -> 631.9444 | E6: =(B6/Tpk)*EXP(1-B6/Tpk) -> 0.52925 | F6: =PerPt*E6 -> 3.28135 | G6: =D6-Depth0*F6 -> 540.0666 | H6: =1-E6 -> 0.47075 | I6: =SDW^2*(1-AE^(2*A6))/(1-AE^2) -> 3400 | J6: =NORMSDIST((FloorL-G6)/SQRT(I6)) -> 0.00055781723 | K6: 0.00058 | L6: 0.00041
A7: 3 | B7: =A7/4 -> 0.75 | C7: =Xinf+(100-Xinf)*EXP(-Krel*B7) -> 102.77048 | D7: =PerPt*C7 -> 637.177 | E7: =(B7/Tpk)*EXP(1-B7/Tpk) -> 0.70059223 | F7: =PerPt*E7 -> 4.3436719 | G7: =D7-Depth0*F7 -> 515.55419 | H7: =1-E7 -> 0.29940777 | I7: =SDW^2*(1-AE^(2*A7))/(1-AE^2) -> 3724 | J7: =NORMSDIST((FloorL-G7)/SQRT(I7)) -> 0.0033347643 | K7: 0.00312 | L7: 0.00182
A8: 4 | B8: =A8/4 -> 1 | C8: =Xinf+(100-Xinf)*EXP(-Krel*B8) -> 103.54374 | D8: =PerPt*C8 -> 641.97121 | E8: =(B8/Tpk)*EXP(1-B8/Tpk) -> 0.82436064 | F8: =PerPt*E8 -> 5.1110359 | G8: =D8-Depth0*F8 -> 498.8622 | H8: =1-E8 -> 0.17563936 | I8: =SDW^2*(1-AE^(2*A8))/(1-AE^2) -> 3840.64 | J8: =NORMSDIST((FloorL-G8)/SQRT(I8)) -> 0.0081516673 | K8: 0.00796 | L8: 0.00467
A9: 5 | B9: =A9/4 -> 1.25 | C9: =Xinf+(100-Xinf)*EXP(-Krel*B9) -> 104.25222 | D9: =PerPt*C9 -> 646.36375 | E9: =(B9/Tpk)*EXP(1-B9/Tpk) -> 0.90936963 | F9: =PerPt*E9 -> 5.6380917 | G9: =D9-Depth0*F9 -> 488.49718 | H9: =1-E9 -> 0.090630366 | I9: =SDW^2*(1-AE^(2*A9))/(1-AE^2) -> 3882.6304 | J9: =NORMSDIST((FloorL-G9)/SQRT(I9)) -> 0.013118526 | K9: 0.013 | L9: 0.00745
A10: 6 | B10: =A10/4 -> 1.5 | C10: =Xinf+(100-Xinf)*EXP(-Krel*B10) -> 104.90134 | D10: =PerPt*C10 -> 650.38828 | E10: =(B10/Tpk)*EXP(1-B10/Tpk) -> 0.96301906 | F10: =PerPt*E10 -> 5.9707182 | G10: =D10-Depth0*F10 -> 483.20817 | H10: =1-E10 -> 0.036980937 | I10: =SDW^2*(1-AE^(2*A10))/(1-AE^2) -> 3897.7469 | J10: =NORMSDIST((FloorL-G10)/SQRT(I10)) -> 0.016435546 | K10: 0.01623 | L10: 0.00913
A11: 7 | B11: =A11/4 -> 1.75 | C11: =Xinf+(100-Xinf)*EXP(-Krel*B11) -> 105.49607 | D11: =PerPt*C11 -> 654.07563 | E11: =(B11/Tpk)*EXP(1-B11/Tpk) -> 0.9915049 | F11: =PerPt*E11 -> 6.1473304 | G11: =D11-Depth0*F11 -> 481.95038 | H11: =1-E11 -> 0.0084951036 | I11: =SDW^2*(1-AE^(2*A11))/(1-AE^2) -> 3903.1889 | J11: =NORMSDIST((FloorL-G11)/SQRT(I11)) -> 0.017341774 | K11: 0.01689 | L11: 0.00971
A12: 8 | B12: =A12/4 -> 2 | C12: =Xinf+(100-Xinf)*EXP(-Krel*B12) -> 106.04098 | D12: =PerPt*C12 -> 657.45405 | E12: =(B12/Tpk)*EXP(1-B12/Tpk) -> 1 | F12: =PerPt*E12 -> 6.2 | G12: =D12-Depth0*F12 -> 483.85405 | H12: =1-E12 -> 0 | I12: =SDW^2*(1-AE^(2*A12))/(1-AE^2) -> 3905.148 | J12: =NORMSDIST((FloorL-G12)/SQRT(I12)) -> 0.016098068 | K12: 0.01568 | L12: 0.00938
A13: 9 | B13: =A13/4 -> 2.25 | C13: =Xinf+(100-Xinf)*EXP(-Krel*B13) -> 106.54023 | D13: =PerPt*C13 -> 660.54943 | E13: =(B13/Tpk)*EXP(1-B13/Tpk) -> 0.99280902 | F13: =PerPt*E13 -> 6.1554159 | G13: =D13-Depth0*F13 -> 488.19778 | H13: =1-E13 -> 0.0071909846 | I13: =SDW^2*(1-AE^(2*A13))/(1-AE^2) -> 3905.8533 | J13: =NORMSDIST((FloorL-G13)/SQRT(I13)) -> 0.013508338 | K13: 0.01371 | L13: 0.00848
A14: 10 | B14: =A14/4 -> 2.5 | C14: =Xinf+(100-Xinf)*EXP(-Krel*B14) -> 106.99766 | D14: =PerPt*C14 -> 663.38547 | E14: =(B14/Tpk)*EXP(1-B14/Tpk) -> 0.97350098 | F14: =PerPt*E14 -> 6.0357061 | G14: =D14-Depth0*F14 -> 494.3857 | H14: =1-E14 -> 0.026499021 | I14: =SDW^2*(1-AE^(2*A14))/(1-AE^2) -> 3906.1072 | J14: =NORMSDIST((FloorL-G14)/SQRT(I14)) -> 0.010438172 | K14: 0.01077 | L14: 0.0066
A15: 11 | B15: =A15/4 -> 2.75 | C15: =Xinf+(100-Xinf)*EXP(-Krel*B15) -> 107.41676 | D15: =PerPt*C15 -> 665.9839 | E15: =(B15/Tpk)*EXP(1-B15/Tpk) -> 0.94502276 | F15: =PerPt*E15 -> 5.8591411 | G15: =D15-Depth0*F15 -> 501.92795 | H15: =1-E15 -> 0.054977242 | I15: =SDW^2*(1-AE^(2*A15))/(1-AE^2) -> 3906.1986 | J15: =NORMSDIST((FloorL-G15)/SQRT(I15)) -> 0.0075314512 | K15: 0.00788 | L15: 0.00516
A16: 12 | B16: =A16/4 -> 3 | C16: =Xinf+(100-Xinf)*EXP(-Krel*B16) -> 107.80075 | D16: =PerPt*C16 -> 668.36463 | E16: =(B16/Tpk)*EXP(1-B16/Tpk) -> 0.90979599 | F16: =PerPt*E16 -> 5.6407351 | G16: =D16-Depth0*F16 -> 510.42405 | H16: =1-E16 -> 0.09020401 | I16: =SDW^2*(1-AE^(2*A16))/(1-AE^2) -> 3906.2315 | J16: =NORMSDIST((FloorL-G16)/SQRT(I16)) -> 0.0051322252 | K16: 0.00492 | L16: 0.00393
A19: Planned liquidity at its low point | B19: =MIN(G5:G16) -> 481.95038 | C19: $482 million
A20: in quarter | B20: =INDEX(A5:A16,MATCH(B19,G5:G16,0)) -> 7 | C20: 7
A21: A quarter of committed delay lifts the deepest point by | B21: =DPQ*MAX(F5:F16) -> 24.8 | C21: $24.8 million, 'up to $25 million'
A22: Surprises only: the worst quarter, Gaussian | B22: =MAX(J5:J16) -> 0.017341774 | C22: 1.73% (simulated 1.69%)
A23: Surprises only: sum over the quarters, Gaussian | B23: =SUM(J5:J16) -> 0.11165202 | C23: 11.2 percent: the union bound of Proposition 9.2(i)
A24: Surprises only: the worst quarter, simulated | B24: =MAX(K5:K16) -> 0.01689
A25: Surprises only: some quarter (engine) | B25: 0.08403 | C25: 8.4 percent
A26: Between the worst quarter and the sum? | B26: =AND(B25>=B24,B25<=B23) -> 1 | C26: Proposition 9.2(i)
A27: Full law, Volume I's package: some quarter (engine) | B27: 0.05 | C27: 5.0 percent
A28: Full law, Volume I's package: the worst quarter | B28: =MAX(L5:L16) -> 0.00971 | C28: Under 1 percent
A29: No levers, full law: some quarter (engine) | B29: 0.24622 | C29: 24.6 percent, though the average path's trough is $460 million
A30: The average path's trough (engine) | B30: 459.94151

Sheet Packages
A1: Committed packages: the quantile, quarter by quarter, and CVaR (Proposition 9.2; Section 9.4; Worked Example 9.1, Step 2)
A2: For each line, the delay that keeps the appetite is the 95th percentile of the delays the paths need (engine); the cost of a package is 0.03 l + 8 phi.
A4: Line | B4: Delay that meets 5% (engine) | C4: Fees | D4: Delay cost | E4: Cost | F4: The cheapest line on the grid | G4: =INDEX(A5:A25,MATCH(MIN(E5:E25),E5:E25,0)) -> 170 | H4: Volume I's package: $170 million
A5: 120 | B5: 1.0037717 | C5: =Fee*A5 -> 3.6 | D5: =VQ*B5 -> 8.0301737 | E5: =C5+D5 -> 11.630174 | F5: Its delay (quarters) | G5: =INDEX(B5:B25,MATCH(G4,A5:A25,0)) -> 0.66757636 | H5: 0.6676
A6: 125 | B6: 0.95008855 | C6: =Fee*A6 -> 3.75 | D6: =VQ*B6 -> 7.6007084 | E6: =C6+D6 -> 11.350708 | F6: Fees | G6: =Fee*G4 -> 5.1 | H6: $5.10 million
A7: 130 | B7: 0.90665529 | C7: =Fee*A7 -> 3.9 | D7: =VQ*B7 -> 7.2532424 | E7: =C7+D7 -> 11.153242 | F7: Delay cost | G7: =VQ*G5 -> 5.3406109 | H7: $5.34 million
A8: 135 | B8: 0.87143216 | C8: =Fee*A8 -> 4.05 | D8: =VQ*B8 -> 6.9714573 | E8: =C8+D8 -> 11.021457 | F8: Cost | G8: =G6+G7 -> 10.440611 | H8: $10.44 million
A9: 140 | B9: 0.8311562 | C9: =Fee*A9 -> 4.2 | D9: =VQ*B9 -> 6.6492496 | E9: =C9+D9 -> 10.84925 | F9: Chance on the book's paths (engine) | G9: 0.05 | H9: 5.000%
A10: 145 | B10: 0.79394866 | C10: =Fee*A10 -> 4.35 | D10: =VQ*B10 -> 6.3515892 | E10: =C10+D10 -> 10.701589 | F10: Chance on the fresh paths (engine) | G10: 0.04907 | H10: 4.907%
A11: 150 | B11: 0.75960632 | C11: =Fee*A11 -> 4.5 | D11: =VQ*B11 -> 6.0768506 | E11: =C11+D11 -> 10.576851 | F11: Standard error of 5% on 100,000 paths | G11: =SQRT(Alpha*(1-Alpha)/NPaths) -> 0.00068920244 | H11: 0.069 points
A12: 155 | B12: 0.73042901 | C12: =Fee*A12 -> 4.65 | D12: =VQ*B12 -> 5.8434321 | E12: =C12+D12 -> 10.493432 | F12: Fresh chance below 5%, in standard errors | G12: =(Alpha-G10)/G11 -> 1.3493858 | H12: 'within 1.3 standard errors'
A13: 160 | B13: 0.70663854 | C13: =Fee*A13 -> 4.8 | D13: =VQ*B13 -> 5.6531083 | E13: =C13+D13 -> 10.453108
A14: 165 | B14: 0.68675628 | C14: =Fee*A14 -> 4.95 | D14: =VQ*B14 -> 5.4940502 | E14: =C14+D14 -> 10.44405 | F14: Designed on the fresh paths: line (engine) | G14: 165 | H14: $165 million
A15: 170 | B15: 0.66757636 | C15: =Fee*A15 -> 5.1 | D15: =VQ*B15 -> 5.3406109 | E15: =C15+D15 -> 10.440611 | F15: delay (engine) | G15: 0.665764 | H15: 0.6658
A16: 175 | B16: 0.6548157 | C16: =Fee*A16 -> 5.25 | D16: =VQ*B16 -> 5.2385256 | E16: =C16+D16 -> 10.488526 | F16: cost | G16: =Fee*G14+VQ*G15 -> 10.276112 | H16: $10.28 million
A17: 180 | B17: 0.6393381 | C17: =Fee*A17 -> 5.4 | D17: =VQ*B17 -> 5.1147048 | E17: =C17+D17 -> 10.514705 | F17: differs from the book's package by | G17: =G8-G16 -> 0.1644989 | H17: Costs that differ by less than about $0.2 million cannot be told apart
A18: 185 | B18: 0.62677102 | C18: =Fee*A18 -> 5.55 | D18: =VQ*B18 -> 5.0141681 | E18: =C18+D18 -> 10.564168
A19: 190 | B19: 0.6133335 | C19: =Fee*A19 -> 5.7 | D19: =VQ*B19 -> 4.906668 | E19: =C19+D19 -> 10.606668 | F19: Read quarter by quarter: line (engine) | G19: 60 | H19: 5 percent in each quarter
A20: 195 | B20: 0.60392968 | C20: =Fee*A20 -> 5.85 | D20: =VQ*B20 -> 4.8314375 | E20: =C20+D20 -> 10.681437 | F20: delay (engine) | G20: 0.0075646215 | H20: 0.008
A21: 200 | B21: 0.59925612 | C21: =Fee*A21 -> 6 | D21: =VQ*B21 -> 4.7940489 | E21: =C21+D21 -> 10.794049 | F21: cost | G21: =Fee*G19+VQ*G20 -> 1.860517 | H21: $1.86 million
A22: 205 | B22: 0.59312373 | C22: =Fee*A22 -> 6.15 | D22: =VQ*B22 -> 4.7449899 | E22: =C22+D22 -> 10.89499 | F22: chance of a breach in some quarter (engine) | G22: 0.1669 | H22: 16.69% (fresh 16.39%)
A23: 210 | B23: 0.58839324 | C23: =Fee*A23 -> 6.3 | D23: =VQ*B23 -> 4.7071459 | E23: =C23+D23 -> 11.007146
A24: 215 | B24: 0.58183111 | C24: =Fee*A24 -> 6.45 | D24: =VQ*B24 -> 4.6546489 | E24: =C24+D24 -> 11.104649 | F24: CVaR, the convex safe version: line (engine) | G24: 185 | H24: $185 million
A25: 220 | B25: 0.57863971 | C25: =Fee*A25 -> 6.6 | D25: =VQ*B25 -> 4.6291177 | E25: =C25+D25 -> 11.229118 | F25: delay (engine, by bisection) | G25: 1.5955265 | H25: 1.596
F26: cost | G26: =Fee*G24+VQ*G25 -> 18.314212 | H26: $18.31 million
F27: chance of a breach (engine) | G27: 0.01885 | H27: 1.9 percent (fresh 1.85%)
F28: Convexity buys tractability and gives up | G28: =G26-G8 -> 7.873601 | H28: $7.9 million
F30: A nonconvex quantile (Online Appendix 9.B): chance of 1 | G30: 0.04 | H30: c = z1 x1 + z2 x2, x_i independent, 1 with chance 0.04
F31: chance that c > 0 at the midpoint (0.5, 0.5) | G31: =1-(1-G30)^2 -> 0.0784 | H31: 0.0784
F32: 95th percentile at (1, 0) and (0, 1) | G32: =IF(G30>Alpha,1,0) -> 0 | H32: 0
F33: 95th percentile at their midpoint | G33: =IF(G31>Alpha,0.5,0) -> 0.5 | H33: 0.5: not convex

Sheet Samples
A1: The sample is part of the answer (Theorem 9.3; Figure 9.2; AXIOM Lab 2.9, step 2)
A2: Theorem 9.3(iv), Equation 9.5: a package whose true chance exceeds 5 percent passes a test at 5% - delta on N paths with probability at most e^(-N kappa), kappa = a ln(a/alpha) + (1 - a) ln((1 - a)/(1 - alpha)), a = alpha - delta; Hoeffding's bound is e^(-2 N delta^2), and kappa >= 2 delta^2 (Pinsker).
A4: Paths N | B4: Margin delta | C4: a = alpha - delta | D4: kappa (Chernoff) | E4: e^(-N kappa) | F4: Hoeffding e^(-2N delta^2) | G4: 2 delta^2 | H4: kappa >= 2 delta^2?
A5: 100000 | B5: 0.0025 | C5: =Alpha-B5 -> 0.0475 | D5: =C5*LN(C5/Alpha)+(1-C5)*LN((1-C5)/(1-Alpha)) -> 6.6855109e-05 | E5: =EXP(-A5*D5) -> 0.0012488766 | F5: =EXP(-2*A5*B5^2) -> 0.2865048 | G5: =2*B5^2 -> 1.25e-05 | H5: =D5>=G5 -> TRUE
A6: 10000 | B6: 0.0025 | C6: =Alpha-B6 -> 0.0475 | D6: =C6*LN(C6/Alpha)+(1-C6)*LN((1-C6)/(1-Alpha)) -> 6.6855109e-05 | E6: =EXP(-A6*D6) -> 0.51245054 | F6: =EXP(-2*A6*B6^2) -> 0.8824969 | G6: =2*B6^2 -> 1.25e-05 | H6: =D6>=G6 -> TRUE
A7: 1000 | B7: 0.01 | C7: =Alpha-B7 -> 0.04 | D7: =C7*LN(C7/Alpha)+(1-C7)*LN((1-C7)/(1-Alpha)) -> 0.0011267058 | E7: =EXP(-A7*D7) -> 0.32409914 | F7: =EXP(-2*A7*B7^2) -> 0.81873075 | G7: =2*B7^2 -> 0.0002 | H7: =D7>=G7 -> TRUE
A8: 1000 | B8: 0.02 | C8: =Alpha-B8 -> 0.03 | D8: =C8*LN(C8/Alpha)+(1-C8)*LN((1-C8)/(1-Alpha)) -> 0.0048842956 | E8: =EXP(-A8*D8) -> 0.0075644504 | F8: =EXP(-2*A8*B8^2) -> 0.44932896 | G8: =2*B8^2 -> 0.0008 | H8: =D8>=G8 -> TRUE
A11: Standard error of an estimated 5 percent chance
A12: Paths N | B12: Standard error (points)
A13: 1000 | B13: =100*SQRT(Alpha*(1-Alpha)/A13) -> 0.68920244
A14: 10000 | B14: =100*SQRT(Alpha*(1-Alpha)/A14) -> 0.21794495
A15: 100000 | B15: =100*SQRT(Alpha*(1-Alpha)/A15) -> 0.068920244
A18: Packages designed on small samples, judged on the fresh 100,000 paths (engine: 200 samples of 1,000 paths, seeds 900000-900199; 100 of 10,000, seeds 900000-900099)
A19: Paths | B19: Margin | C19: Aimed at | D19: Designs | E19: Meet 5% (engine) | F19: Mean true chance (engine) | G19: 90th percentile (engine) | H19: Mean cost (engine) | I19: Cost against the book's package
A20: 1000 | B20: 0 | C20: =Alpha-B20 -> 0.05 | D20: 200 | E20: 0.385 | F20: 0.0520926 | G20: 0.062296 | H20: 10.185045 | I20: =H20-Packages!$G$8 -> -0.25556626
A21: 1000 | B21: 0.01 | C21: =Alpha-B21 -> 0.04 | D21: 200 | E21: 0.87 | F21: 0.04210155 | G21: 0.050855 | H21: 12.086363 | I21: =H21-Packages!$G$8 -> 1.6457522
A22: 1000 | B22: 0.02 | C22: =Alpha-B22 -> 0.03 | D22: 200 | E22: 1 | F22: 0.0322493 | G22: 0.038511 | H22: 14.32758 | I22: =H22-Packages!$G$8 -> 3.886969
A23: 10000 | B23: 0 | C23: =Alpha-B23 -> 0.05 | D23: 100 | E23: 0.69 | F23: 0.0488074 | G23: 0.051513 | H23: 10.52592 | I23: =H23-Packages!$G$8 -> 0.085308654
A24: 10000 | B24: 0.0025 | C24: =Alpha-B24 -> 0.0475 | D24: 100 | E24: 0.97 | F24: 0.0463912 | G24: 0.048912 | H24: 10.972412 | I24: =H24-Packages!$G$8 -> 0.53180135
A26: Designed on 1,000 paths and aimed at the appetite, packages look cheaper than the book's and buy too little: an optimistic answer (Theorem 9.3(iii)). The board's test of record is the check on fresh paths.

Sheet Rules
A1: Rules that read cash: one reading, every reading, and Table 9.3 (Worked Example 9.1, Steps 3-4; Figure 9.3(a); AXIOM Lab 2.9, step 3)
A2: A slowdown of phi' quarters decided at the end of quarter k costs 8 phi' (1 - S_k) on each path it slows. Which paths a rule slows, and what that does to the chance of a breach, needs the paths (engine); the costs are formulas.
A4: Quarter read | B4: Draw still ahead | C4: Slow only: line (engine) | D4: Slowdown | E4: Trigger ($m, engine) | F4: Share slowed (engine) | G4: Cost | H4: Commit and slow: line (engine) | I4: Committed | J4: Slowdown | K4: Trigger ($m, engine) | L4: Share slowed (engine) | M4: Cost | N4: Saves against the package
A5: 1 | B5: =Plan!H5 -> 0.70014059 | C5: 170 | D5: 1 | E5: 683.45019 | F5: 0.98516 | G5: =Fee*C5+VQ*D5*B5*F5 -> 10.618004 | H5: 165 | I5: 0.6 | J5: 0.25 | K5: 572.12819 | L5: 0.44904 | M5: =Fee*H5+VQ*I5+VQ*J5*B5*L5 -> 10.378782 | N5: =Packages!$G$8-M5 -> 0.061828632
A6: 2 | B6: =Plan!H6 -> 0.47075 | C6: 165 | D6: 1.75 | E6: 615.03437 | F6: 0.90121 | G6: =Fee*C6+VQ*D6*B6*F6 -> 10.889424 | H6: 165 | I6: 0.6 | J6: 1.25 | K6: 478.16922 | L6: 0.11639 | M6: =Fee*H6+VQ*I6+VQ*J6*B6*L6 -> 10.297906 | N6: =Packages!$G$8-M6 -> 0.14270497
A7: 3 | B7: =Plan!H7 -> 0.29940777 | C7: 175 | D7: 4 | E7: 537.90721 | F7: 0.64256 | G7: =Fee*C7+VQ*D7*B7*F7 -> 11.406399 | H7: 165 | I7: 0.55 | J7: 2.5 | K7: 460.77477 | L7: 0.14753 | M7: =Fee*H7+VQ*I7+VQ*J7*B7*L7 -> 10.233433 | N7: =Packages!$G$8-M7 -> 0.20717834
A8: 4 | B8: =Plan!H8 -> 0.17563936 | C8: 180 | D8: 6.5 | E8: 541.88817 | F8: 0.75611 | G8: =Fee*C8+VQ*D8*B8*F8 -> 12.305739 | H8: 165 | I8: 0.6 | J8: 4 | K8: 430.06803 | L8: 0.09881 | M8: =Fee*H8+VQ*I8+VQ*J8*B8*L8 -> 10.305358 | N8: =Packages!$G$8-M8 -> 0.13525327
A9: 5 | B9: =Plan!H9 -> 0.090630366 | C9: none | D9: none | E9: none | F9: none | G9: none | H9: 160 | I9: 0.65 | J9: 7 | K9: 409.25481 | L9: 0.06871 | M9: =Fee*H9+VQ*I9+VQ*J9*B9*L9 -> 10.348724 | N9: =Packages!$G$8-M9 -> 0.091886995
A10: 6 | B10: =Plan!H10 -> 0.036980937 | C10: none | D10: none | E10: none | F10: none | G10: none | H10: 170 | I10: 0.65 | J10: 5.75 | K10: 407.865 | L10: 0.07575 | M10: =Fee*H10+VQ*I10+VQ*J10*B10*L10 -> 10.42886 | N10: =Packages!$G$8-M10 -> 0.011750815
A12: The best quarter to read (least cost of committing and slowing) | B12: =INDEX(A5:A10,MATCH(MIN(M5:M10),M5:M10,0)) -> 3 | C12: Quarter 3: earlier says too little, later leaves too little of the draw to cut
A13: Its cost | B13: =MIN(M5:M10) -> 10.233433 | C13: $10.23 million
A14: It saves against Volume I's package | B14: =Packages!G8-B13 -> 0.20717834 | C14: $0.21 million
A16: Every reading: slow by 1.25 quarters the first time cash falls more than the margin below the committed plan
A17: Quarter first slowed | B17: Share of paths (engine) | C17: Draw still ahead | D17: Share x draw ahead
A18: 1 | B18: 0.07348 | C18: =Plan!H5 -> 0.70014059 | D18: =B18*C18 -> 0.05144633
A19: 2 | B19: 0.07879 | C19: =Plan!H6 -> 0.47075 | D19: =B19*C19 -> 0.037090392
A20: 3 | B20: 0.06821 | C20: =Plan!H7 -> 0.29940777 | D20: =B20*C20 -> 0.020422604
A21: 4 | B21: 0.0611 | C21: =Plan!H8 -> 0.17563936 | D21: =B21*C21 -> 0.010731565
A22: 5 | B22: 0.05325 | C22: =Plan!H9 -> 0.090630366 | D22: =B22*C22 -> 0.004826067
A24: Line (engine search) | B24: 165 | C24: $165 million
A25: Committed delay (engine search) | B25: 0.5 | C25: Half a quarter
A26: Slowdown (engine search) | B26: 1.25 | C26: 1.25 quarters
A27: Margin below the plan's path (engine, by bisection) | B27: 72.630873 | C27: $73 million
A28: Share of paths slowed | B28: =SUM(B18:B22) -> 0.33483 | C28: A third
A29: Contingent delay on average (quarters) | B29: =B26*SUM(D18:D22) -> 0.1556462 | C29: 0.16 quarter
A30: Cost | B30: =Fee*B24+VQ*B25+VQ*B29 -> 10.19517 | C30: $10.20 million
A31: Saves against Volume I's package | B31: =Packages!G8-B30 -> 0.24544131 | C31: $0.25 million
A32: as a share of it | B32: =B31/Packages!G8 -> 0.023508328 | C32: 2 percent
A33: On the fresh paths: chance (engine) | B33: 0.04948 | C33: 4.95%
A34: On the fresh paths: cost (engine) | B34: 10.213352 | C34: $10.21 million
A36: Table 9.3: ways of keeping Meridian's appetite, designed on the book's 100,000 paths
A37: Way | B37: Line | C37: Committed delay | D37: Slowdown | E37: Paths slowed | F37: Cost | G37: Fresh: chance (engine) | H37: Fresh: cost (engine)
A38: Volume I's package | B38: =Packages!G4 -> 170 | C38: =Packages!G5 -> 0.66757636 | D38: -- | E38: -- | F38: =Packages!G8 -> 10.440611 | G38: 0.04907 | H38: =Packages!G8 -> 10.440611
A39: Slow only, reading quarter 1 | B39: =C5 -> 170 | C39: 0 | D39: =D5 -> 1 | E39: =F5 -> 0.98516 | F39: =G5 -> 10.618004 | G39: 0.04899 | H39: 10.620076
A40: Slow only, reading quarter 3 | B40: =C7 -> 175 | C40: 0 | D40: =D7 -> 4 | E40: =F7 -> 0.64256 | F40: =G7 -> 11.406399 | G40: 0.04954 | H40: 11.410902
A41: Commit and slow, quarter 3 | B41: =H7 -> 165 | C41: =I7 -> 0.55 | D41: =J7 -> 2.5 | E41: =L7 -> 0.14753 | F41: =M7 -> 10.233433 | G41: 0.04961 | H41: 10.240379
A42: Commit and slow, every quarter | B42: =B24 -> 165 | C42: =B25 -> 0.5 | D42: =B26 -> 1.25 | E42: =B28 -> 0.33483 | F42: =B30 -> 10.19517 | G42: 0.04948 | H42: 10.213352
A43: Early warning of closures | B43: 0, 215 | C43: 0.61, 0.50 | D43: -- | E43: -- | F43: =Information!B21 -> 6.3226291
A44: Every path's future | F44: =Information!B5 -> 0.4366984

Sheet Information
A1: Price information: the clairvoyant, an early warning, and a law that persists (Proposition 9.3; Worked Example 9.1, Step 5; Figure 9.3(b); AXIOM Lab 2.9, step 4)
A3: Quantity | B3: Value | C3: Reading
A4: Volume I's package | B4: =Packages!G8 -> 10.440611 | C4: Nothing is read
A5: Clairvoyant: each path's cheapest safe package, the costliest 5% let go (engine) | B5: 0.4366984 | C5: $0.44 million (Proposition 9.3(iii))
A6: Expected value of perfect information | B6: =B4-B5 -> 10.003912 | C6: $10.0 million: the most any information could save with these levers
A7: Paths given a package (engine) | B7: 0.19622 | C7: 19.6%
A8: Paths that need no lever | B8: =1-B7 -> 0.80378 | C8: Four paths in five
A9: Paths given some of the line (engine) | B9: 0.16287 | C9: One in six
A11: Early warning: paths that see a closure during the program (engine) | B11: 0.25912 | C11: 26 percent
A12: share with no closure ahead | B12: =1-B11 -> 0.74088
A13: No closure ahead: line (engine) | B13: 0 | C13: No line
A14: delay (engine) | B14: 0.60835428 | C14: 0.61 quarter
A15: chance allotted | B15: 0.0475 | C15: 4.75%, on a grid of a quarter of a point
A16: cost | B16: =Fee*B13+VQ*B14 -> 4.8668342 | C16: $4.87 million
A17: Closure ahead: line (engine) | B17: 215 | C17: $215 million
A18: delay (engine) | B18: 0.50438261 | C18: Half a quarter
A19: chance allotted, so that the overall chance is 5% | B19: =(Alpha-B12*B15)/B11 -> 0.05714804 | C19: 5.71%: more of the appetite where the closure is coming (Proposition 9.3(ii))
A20: cost | B20: =Fee*B17+VQ*B18 -> 10.485061 | C20: $10.49 million
A21: Expected cost with the warning | B21: =B12*B16+B11*B20 -> 6.3226291 | C21: $6.32 million
A22: The warning is worth | B22: =B4-B21 -> 4.1179818 | C22: $4.1 million
A23: Reading cash every quarter is worth | B23: =Rules!B31 -> 0.24544131 | C23: $0.25 million
A25: Persistence 0.85, surprises only: some quarter (engine) | B25: 0.21009 | C25: 21.0 percent (8.4 at 0.6)
A26: Persistence 0.85: committed line (engine) | B26: 165 | C26: $165 million
A27: committed delay (engine) | B27: 2.9033037 | C27: Almost three quarters
A28: cost | B28: =Fee*B26+VQ*B27 -> 28.17643 | C28: $28.2 million
A29: Persistence 0.85: reading cash every quarter, cost (engine) | B29: 25.881497 | C29: Line 160, 1.9 committed, slowdown 5.0
A30: saves | B30: =B28-B29 -> 2.2949331 | C30: $2.3 million
A31: as a share of the package | B31: =B30/B28 -> 0.081448685 | C31: 8 percent: cash says more when surprises persist
A33: Figure 9.3(b): the least cost by what the decision can see
A34: What the decision can see | B34: Least cost
A35: Nothing (committed) | B35: =B4 -> 10.440611
A36: Cash, every quarter | B36: =Rules!B30 -> 10.19517
A37: Warning of closures | B37: =B21 -> 6.3226291
A38: Every path's future | B38: =B5 -> 0.4366984

Sheet Hiring
A1: Chapter 8's hiring loop with outside events (Theorems 9.1-9.2; Proposition 9.1; Online Appendix 9.B.3; AXIOM Lab 2.9, step 5)
A2: dd = (-a d + b v) dt + sigma dW1 + s v dW2. Certainty equivalence: the Riccati root of Chapter 8, and the departures cost sigma^2 p / rho. Caution: r b K^2 + (r beta + q s^2) K - q b = 0. Vigilance: (b^2/r) p^2 + (beta - c^2) p - q = 0. Robustness: (b^2/r - 2 theta sigma^2) p^2 + beta p - q = 0, smallest positive root.
A4: Quantity | B4: Value | C4: Reading
A5: Riccati root p (certainty equivalence) | B5: =(-(Beta)+SQRT((Beta)^2+4*(Bh^2/Rh)*(Qh)))/(2*(Bh^2/Rh)) -> 0.00090372174 | C5: 0.00090372: departures leave the rule unchanged
A6: Gain K = b p / r, a year | B6: =Bh*B5/Rh -> 4.3378644 | C6: 4.34 a year
A7: Departures cost sigma^2 p, a year | B7: =Sig^2*B5 -> 0.20333739 | C7: $0.20 million a year
A8: in present value, sigma^2 p / rho | B8: =B7/Rho -> 2.1334279 | C8: $2.13 million, whatever HR decides
A9: Least cost from 100 short with departures | B9: =B5*D0h^2+B8 -> 11.170645 | C9: 9.037 + 2.133 = 11.171
A11: Caution: an uncertain yield of approvals (Theorem 9.2(iii))
A12: Yield noise s | B12: r b | C12: r beta + q s^2 | D12: q b | E12: Gain K | F12: p = q/(bK + beta) | G12: Least cost p(d0^2 + sigma^2/rho) | H12: Certainty-equivalent gain's cost | I12: Ignoring the uncertainty costs
A13: =Sy -> 0.1 | B13: =Rh*Bh -> 7.5e-05 | C13: =Rh*Beta+Qh*A13^2 -> 0.00014927429 | D13: =Qh*Bh -> 0.00192 | E13: =(-C13+SQRT(C13^2+4*B13*D13))/(2*B13) -> 4.161421 | F13: =Qh/(Bh*E13+Beta) -> 0.00093157389 | G13: =F13*(D0h^2+Sig^2/Rho) -> 11.514918 | H13: =(Qh+Rh*$B$6^2)*(D0h^2+Sig^2/Rho)/(2*(Ah+Bh*$B$6)+Rho-A13^2*$B$6^2) -> 11.523597 | I13: =H13-G13 -> 0.0086789225
A14: =2*Sy -> 0.2 | B14: =Rh*Bh -> 7.5e-05 | C14: =Rh*Beta+Qh*A14^2 -> 0.00024527429 | D14: =Qh*Bh -> 0.00192 | E14: =(-C14+SQRT(C14^2+4*B14*D14))/(2*B14) -> 3.6821452 | F14: =Qh/(Bh*E14+Beta) -> 0.0010166859 | G14: =F14*(D0h^2+Sig^2/Rho) -> 12.566963 | H14: =(Qh+Rh*$B$6^2)*(D0h^2+Sig^2/Rho)/(2*(Ah+Bh*$B$6)+Rho-A14^2*$B$6^2) -> 12.730287 | I14: =H14-G14 -> 0.16332448
A17: Vigilance: p with noise c d dW (Theorem 9.2(iv)) | B17: =(-(Beta-Cv^2)+SQRT((Beta-Cv^2)^2+4*(Bh^2/Rh)*(Qh)))/(2*(Bh^2/Rh)) -> 0.00094136401 | C17: 0.00094136
A18: gain b p / r | B18: =Bh*B17/Rh -> 4.5185472 | C18: 4.52: close a gap faster when it breeds its own volatility
A20: Robustness: guarding against a misjudged drift at the penalty h^2/(2 theta) a year (Proposition 9.1(ii))
A21: theta | B21: b^2/r - 2 theta sigma^2 | C21: Discriminant | D21: p (smallest positive root) | E21: p x 1e4 | F21: Gain K
A22: 0 | B22: =Bh^2/Rh-2*A22*Sig^2 -> 2880 | C22: =Beta^2+4*B22*Qh -> 37.744209 | D22: =2*Qh/(Beta+SQRT(C22)) -> 0.00090372174 | E22: =10000*D22 -> 9.0372174 | F22: =Bh*D22/Rh -> 4.3378644
A23: 1 | B23: =Bh^2/Rh-2*A23*Sig^2 -> 2430 | C23: =Beta^2+4*B23*Qh -> 31.984209 | D23: =2*Qh/(Beta+SQRT(C23)) -> 0.00097063045 | E23: =10000*D23 -> 9.7063045 | F23: =Bh*D23/Rh -> 4.6590262
A24: 2 | B24: =Bh^2/Rh-2*A24*Sig^2 -> 1980 | C24: =Beta^2+4*B24*Qh -> 26.224209 | D24: =2*Qh/(Beta+SQRT(C24)) -> 0.0010562534 | E24: =10000*D24 -> 10.562534 | F24: =Bh*D24/Rh -> 5.0700163
A25: 3 | B25: =Bh^2/Rh-2*A25*Sig^2 -> 1530 | C25: =Beta^2+4*B25*Qh -> 20.464209 | D25: =2*Qh/(Beta+SQRT(C25)) -> 0.0011717464 | E25: =10000*D25 -> 11.717464 | F25: =Bh*D25/Rh -> 5.6243828
A26: 6 | B26: =Bh^2/Rh-2*A26*Sig^2 -> 180 | C26: =Beta^2+4*B26*Qh -> 3.1842086 | D26: =2*Qh/(Beta+SQRT(C26)) -> 0.0023506688 | E26: =10000*D26 -> 23.506688 | F26: =Bh*D26/Rh -> 11.28321
A27: 6.5 | B27: =Bh^2/Rh-2*A27*Sig^2 -> -45 | C27: =Beta^2+4*B27*Qh -> 0.30420855 | D27: =2*Qh/(Beta+SQRT(C27)) -> 0.0042960362 | E27: =10000*D27 -> 42.960362 | F27: =Bh*D27/Rh -> 20.620974
A29: b^2/r - 2 theta sigma^2 turns negative at theta | B29: =Bh^2/(2*Rh*Sig^2) -> 6.4 | C29: 6.4: the robust rule continues past it
A30: Breakdown point theta-bar = (b^2/r + beta^2/(4q)) / (2 sigma^2) | B30: =(Bh^2/Rh+Beta^2/(4*Qh))/(2*Sig^2) -> 6.552814 | C30: 6.553: past it no linear rule has a finite worst case
A31: At the breakdown, p -> 2q/beta | B31: =2*Qh/Beta -> 0.0068216146 | C31: 0.006822
A32: and K -> | B32: =Bh*B31/Rh -> 32.74375 | C32: 32.7
A34: The value ledger (Theorem 9.1(iii)): E M_t, booked with the best rule's value p d^2 + sigma^2 p / rho
A35: Rule | B35: Gain K | C35: g = a + bK | D35: q + r K^2 | E35: m = sigma^2/(2g) | F35: Years t | G35: E d_t^2 | H35: Value earned to t | I35: Expected ledger E M_t
A36: Best rule | B36: =$B$6 -> 4.3378644 | C36: =Ah+Bh*B36 -> 3.0241607 | D36: =Qh+Rh*B36^2 -> 0.0055521334 | E36: =Sig^2/(2*C36) -> 37.200404 | F36: 0 | G36: =D0h^2*EXP(-2*C36*F36)+E36*(1-EXP(-2*C36*F36)) -> 10000 | H36: =D36*((D0h^2-E36)*(1-EXP(-(2*C36+Rho)*F36))/(2*C36+Rho)+E36*(1-EXP(-Rho*F36))/Rho) -> 0 | I36: =H36+EXP(-Rho*F36)*($B$5*G36+Sig^2*$B$5/Rho) -> 11.170645
A37: Best rule | B37: =$B$6 -> 4.3378644 | C37: =Ah+Bh*B37 -> 3.0241607 | D37: =Qh+Rh*B37^2 -> 0.0055521334 | E37: =Sig^2/(2*C37) -> 37.200404 | F37: 1 | G37: =D0h^2*EXP(-2*C37*F37)+E37*(1-EXP(-2*C37*F37)) -> 60.730777 | H37: =D37*((D0h^2-E37)*(1-EXP(-(2*C37+Rho)*F37))/(2*C37+Rho)+E37*(1-EXP(-Rho*F37))/Rho) -> 9.1812711 | I37: =H37+EXP(-Rho*F37)*($B$5*G37+Sig^2*$B$5/Rho) -> 11.170645
A38: Best rule | B38: =$B$6 -> 4.3378644 | C38: =Ah+Bh*B38 -> 3.0241607 | D38: =Qh+Rh*B38^2 -> 0.0055521334 | E38: =Sig^2/(2*C38) -> 37.200404 | F38: 2 | G38: =D0h^2*EXP(-2*C38*F38)+E38*(1-EXP(-2*C38*F38)) -> 37.255979 | H38: =D38*((D0h^2-E38)*(1-EXP(-(2*C38+Rho)*F38))/(2*C38+Rho)+E38*(1-EXP(-Rho*F38))/Rho) -> 9.3796561 | I38: =H38+EXP(-Rho*F38)*($B$5*G38+Sig^2*$B$5/Rho) -> 11.170645
A39: Best rule | B39: =$B$6 -> 4.3378644 | C39: =Ah+Bh*B39 -> 3.0241607 | D39: =Qh+Rh*B39^2 -> 0.0055521334 | E39: =Sig^2/(2*C39) -> 37.200404 | F39: 5 | G39: =D0h^2*EXP(-2*C39*F39)+E39*(1-EXP(-2*C39*F39)) -> 37.200404 | H39: =D39*((D0h^2-E39)*(1-EXP(-(2*C39+Rho)*F39))/(2*C39+Rho)+E39*(1-EXP(-Rho*F39))/Rho) -> 9.8250798 | I39: =H39+EXP(-Rho*F39)*($B$5*G39+Sig^2*$B$5/Rho) -> 11.170645
A40: Best rule: the limit, the rule's own cost | B40: =$B$6 -> 4.3378644 | C40: =Ah+Bh*B40 -> 3.0241607 | D40: =Qh+Rh*B40^2 -> 0.0055521334 | E40: =Sig^2/(2*C40) -> 37.200404 | I40: =D40*((D0h^2-E40)/(2*C40+Rho)+E40/Rho) -> 11.170645
A41: Volume I's cautious gain | B41: =Kcaut -> 2 | C41: =Ah+Bh*B41 -> 1.6214421 | D41: =Qh+Rh*B41^2 -> 0.0037 | E41: =Sig^2/(2*C41) -> 69.382683 | F41: 0 | G41: =D0h^2*EXP(-2*C41*F41)+E41*(1-EXP(-2*C41*F41)) -> 10000 | H41: =D41*((D0h^2-E41)*(1-EXP(-(2*C41+Rho)*F41))/(2*C41+Rho)+E41*(1-EXP(-Rho*F41))/Rho) -> 0 | I41: =H41+EXP(-Rho*F41)*($B$5*G41+Sig^2*$B$5/Rho) -> 11.170645
A42: Volume I's cautious gain | B42: =Kcaut -> 2 | C42: =Ah+Bh*B42 -> 1.6214421 | D42: =Qh+Rh*B42^2 -> 0.0037 | E42: =Sig^2/(2*C42) -> 69.382683 | F42: 1 | G42: =D0h^2*EXP(-2*C42*F42)+E42*(1-EXP(-2*C42*F42)) -> 457.18425 | H42: =D42*((D0h^2-E42)*(1-EXP(-(2*C42+Rho)*F42))/(2*C42+Rho)+E42*(1-EXP(-Rho*F42))/Rho) -> 10.861038 | I42: =H42+EXP(-Rho*F42)*($B$5*G42+Sig^2*$B$5/Rho) -> 13.176125
A43: Volume I's cautious gain | B43: =Kcaut -> 2 | C43: =Ah+Bh*B43 -> 1.6214421 | D43: =Qh+Rh*B43^2 -> 0.0037 | E43: =Sig^2/(2*C43) -> 69.382683 | F43: 2 | G43: =D0h^2*EXP(-2*C43*F43)+E43*(1-EXP(-2*C43*F43)) -> 84.526762 | H43: =D43*((D0h^2-E43)*(1-EXP(-(2*C43+Rho)*F43))/(2*C43+Rho)+E43*(1-EXP(-Rho*F43))/Rho) -> 11.460525 | I43: =H43+EXP(-Rho*F43)*($B$5*G43+Sig^2*$B$5/Rho) -> 13.28682
A44: Volume I's cautious gain | B44: =Kcaut -> 2 | C44: =Ah+Bh*B44 -> 1.6214421 | D44: =Qh+Rh*B44^2 -> 0.0037 | E44: =Sig^2/(2*C44) -> 69.382683 | F44: 5 | G44: =D0h^2*EXP(-2*C44*F44)+E44*(1-EXP(-2*C44*F44)) -> 69.383584 | H44: =D44*((D0h^2-E44)*(1-EXP(-(2*C44+Rho)*F44))/(2*C44+Rho)+E44*(1-EXP(-Rho*F44))/Rho) -> 12.027974 | I44: =H44+EXP(-Rho*F44)*($B$5*G44+Sig^2*$B$5/Rho) -> 13.391598
A45: Volume I's cautious gain: the limit, the rule's own cost | B45: =Kcaut -> 2 | C45: =Ah+Bh*B45 -> 1.6214421 | D45: =Qh+Rh*B45^2 -> 0.0037 | E45: =Sig^2/(2*C45) -> 69.382683 | I45: =D45*((D0h^2-E45)/(2*C45+Rho)+E45/Rho) -> 13.700412
A47: Along the best rule the expected ledger stays at the least cost: no drift. Under the cautious gain it drifts up toward that rule's own cost, revealing a rule that is not the declared one.

Sheet Reference_Values
A1: Checkpoint | B1: Engine value | C1: Meaning (where in the book)
A2: Planned liquidity at its low point | B2: 481.95038 | C2: Volume I, Chapter 8: $482 million in quarter 7
A3: A quarter of delay lifts the deepest point by | B3: 24.8 | C3: $24.8 million
A4: Gaussian chance, quarter 7 | B4: 0.017341774 | C4: Online Appendix 9.B.2: 1.73%
A5: Gaussian chance, quarter 12 | B5: 0.0051322252 | C5: 0.51%
A6: Sum over the quarters, Gaussian | B6: 0.11165202 | C6: Figure 9.1: 11.2%
A7: Draw still ahead after quarter 3 | B7: 0.29940777 | C7: 29.9%
A8: Draw still ahead after quarter 6 | B8: 0.036980937 | C8: 3.7%
A9: Committed package: the cheapest line | B9: 170 | C9: $170 million
A10: Committed package: fees | B10: 5.1 | C10: $5.10 million
A11: Committed package: delay cost | B11: 5.3406109 | C11: $5.34 million
A12: Committed package: cost | B12: 10.440611 | C12: $10.44 million
A13: Standard error of 5% on 100,000 paths | B13: 0.00068920244 | C13: 0.069 points
... A88: Ledger, cautious gain, its limit | B88: 13.700412 | C88: 13.700, the rule's own cost

Sheet Checks
A1: Checkpoint | B1: Workbook formula value | C1: Engine value | D1: |diff| | E1: Tolerance | F1: Status
A2: Planned liquidity at its low point | B2: =Plan!B19 -> 481.95038 | C2: =Reference_Values!B2 -> 481.95038 | D2: =ABS(B2-C2) -> 0 | E2: 1e-09 | F2: =IF(D2<=E2,"PASS","FAIL") -> PASS
A3: A quarter of delay lifts the deepest point by | B3: =Plan!B21 -> 24.8 | C3: =Reference_Values!B3 -> 24.8 | D3: =ABS(B3-C3) -> 0 | E3: 1e-09 | F3: =IF(D3<=E3,"PASS","FAIL") -> PASS
A4: Gaussian chance, quarter 7 | B4: =Plan!J11 -> 0.017341774 | C4: =Reference_Values!B4 -> 0.017341774 | D4: =ABS(B4-C4) -> 0 | E4: 1e-12 | F4: =IF(D4<=E4,"PASS","FAIL") -> PASS
A5: Gaussian chance, quarter 12 | B5: =Plan!J16 -> 0.0051322252 | C5: =Reference_Values!B5 -> 0.0051322252 | D5: =ABS(B5-C5) -> 0 | E5: 1e-12 | F5: =IF(D5<=E5,"PASS","FAIL") -> PASS
A6: Sum over the quarters, Gaussian | B6: =Plan!B23 -> 0.11165202 | C6: =Reference_Values!B6 -> 0.11165202 | D6: =ABS(B6-C6) -> 0 | E6: 1e-12 | F6: =IF(D6<=E6,"PASS","FAIL") -> PASS
A7: Draw still ahead after quarter 3 | B7: =Plan!H7 -> 0.29940777 | C7: =Reference_Values!B7 -> 0.29940777 | D7: =ABS(B7-C7) -> 0 | E7: 1e-12 | F7: =IF(D7<=E7,"PASS","FAIL") -> PASS
A8: Draw still ahead after quarter 6 | B8: =Plan!H10 -> 0.036980937 | C8: =Reference_Values!B8 -> 0.036980937 | D8: =ABS(B8-C8) -> 0 | E8: 1e-12 | F8: =IF(D8<=E8,"PASS","FAIL") -> PASS
A9: Committed package: the cheapest line | B9: =Packages!G4 -> 170 | C9: =Reference_Values!B9 -> 170 | D9: =ABS(B9-C9) -> 0 | E9: 0 | F9: =IF(D9<=E9,"PASS","FAIL") -> PASS
A10: Committed package: fees | B10: =Packages!G6 -> 5.1 | C10: =Reference_Values!B10 -> 5.1 | D10: =ABS(B10-C10) -> 0 | E10: 1e-09 | F10: =IF(D10<=E10,"PASS","FAIL") -> PASS
A11: Committed package: delay cost | B11: =Packages!G7 -> 5.3406109 | C11: =Reference_Values!B11 -> 5.3406109 | D11: =ABS(B11-C11) -> 0 | E11: 1e-09 | F11: =IF(D11<=E11,"PASS","FAIL") -> PASS
A12: Committed package: cost | B12: =Packages!G8 -> 10.440611 | C12: =Reference_Values!B12 -> 10.440611 | D12: =ABS(B12-C12) -> 0 | E12: 1e-09 | F12: =IF(D12<=E12,"PASS","FAIL") -> PASS
A13: Standard error of 5% on 100,000 paths | B13: =Packages!G11 -> 0.00068920244 | C13: =Reference_Values!B13 -> 0.00068920244 | D13: =ABS(B13-C13) -> 0 | E13: 1e-12 | F13: =IF(D13<=E13,"PASS","FAIL") -> PASS
A14: Fresh chance below 5%, standard errors | B14: =Packages!G12 -> 1.3493858 | C14: =Reference_Values!B14 -> 1.3493858 | D14: =ABS(B14-C14) -> 0 | E14: 1e-09 | F14: =IF(D14<=E14,"PASS","FAIL") -> PASS
A15: Designed on the fresh paths: cost | B15: =Packages!G16 -> 10.276112 | C15: =Reference_Values!B15 -> 10.276112 | D15: =ABS(B15-C15) -> 0 | E15: 1e-09 | F15: =IF(D15<=E15,"PASS","FAIL") -> PASS
A16: Read quarter by quarter: cost | B16: =Packages!G21 -> 1.860517 | C16: =Reference_Values!B16 -> 1.860517 | D16: =ABS(B16-C16) -> 0 | E16: 1e-09 | F16: =IF(D16<=E16,"PASS","FAIL") -> PASS
A17: CVaR package: cost | B17: =Packages!G26 -> 18.314212 | C17: =Reference_Values!B17 -> 18.314212 | D17: =ABS(B17-C17) -> 0 | E17: 1e-09 | F17: =IF(D17<=E17,"PASS","FAIL") -> PASS
A18: Convexity gives up | B18: =Packages!G28 -> 7.873601 | C18: =Reference_Values!B18 -> 7.873601 | D18: =ABS(B18-C18) -> 0 | E18: 1e-09 | F18: =IF(D18<=E18,"PASS","FAIL") -> PASS
A19: A nonconvex quantile: chance at the midpoint | B19: =Packages!G31 -> 0.0784 | C19: =Reference_Values!B19 -> 0.0784 | D19: =ABS(B19-C19) -> 0 | E19: 1e-12 | F19: =IF(D19<=E19,"PASS","FAIL") -> PASS
A20: kappa at a quarter-point margin | B20: =Samples!D5 -> 6.6855109e-05 | C20: =Reference_Values!B20 -> 6.6855109e-05 | D20: =ABS(B20-C20) -> 0 | E20: 1e-15 | F20: =IF(D20<=E20,"PASS","FAIL") -> PASS
A21: Chernoff bound, quarter point, 100,000 paths | B21: =Samples!E5 -> 0.0012488766 | C21: =Reference_Values!B21 -> 0.0012488766 | D21: =ABS(B21-C21) -> 0 | E21: 1e-12 | F21: =IF(D21<=E21,"PASS","FAIL") -> PASS
A22: Chernoff bound, quarter point, 10,000 paths | B22: =Samples!E6 -> 0.51245054 | C22: =Reference_Values!B22 -> 0.51245054 | D22: =ABS(B22-C22) -> 0 | E22: 1e-12 | F22: =IF(D22<=E22,"PASS","FAIL") -> PASS
A23: Hoeffding bound, quarter point, 100,000 paths | B23: =Samples!F5 -> 0.2865048 | C23: =Reference_Values!B23 -> 0.2865048 | D23: =ABS(B23-C23) -> 0 | E23: 1e-12 | F23: =IF(D23<=E23,"PASS","FAIL") -> PASS
A24: Hoeffding bound, quarter point, 10,000 paths | B24: =Samples!F6 -> 0.8824969 | C24: =Reference_Values!B24 -> 0.8824969 | D24: =ABS(B24-C24) -> 0 | E24: 1e-12 | F24: =IF(D24<=E24,"PASS","FAIL") -> PASS
A25: kappa at one point | B25: =Samples!D7 -> 0.0011267058 | C25: =Reference_Values!B25 -> 0.0011267058 | D25: =ABS(B25-C25) -> 0 | E25: 1e-15 | F25: =IF(D25<=E25,"PASS","FAIL") -> PASS
A26: Chernoff bound, one point, 1,000 paths | B26: =Samples!E7 -> 0.32409914 | C26: =Reference_Values!B26 -> 0.32409914 | D26: =ABS(B26-C26) -> 0 | E26: 1e-12 | F26: =IF(D26<=E26,"PASS","FAIL") -> PASS
A27: Chernoff bound, two points, 1,000 paths | B27: =Samples!E8 -> 0.0075644504 | C27: =Reference_Values!B27 -> 0.0075644504 | D27: =ABS(B27-C27) -> 0 | E27: 1e-12 | F27: =IF(D27<=E27,"PASS","FAIL") -> PASS
A28: Slow only, quarter 1: cost | B28: =Rules!G5 -> 10.618004 | C28: =Reference_Values!B28 -> 10.618004 | D28: =ABS(B28-C28) -> 0 | E28: 1e-09 | F28: =IF(D28<=E28,"PASS","FAIL") -> PASS
A29: Slow only, quarter 2: cost | B29: =Rules!G6 -> 10.889424 | C29: =Reference_Values!B29 -> 10.889424 | D29: =ABS(B29-C29) -> 0 | E29: 1e-09 | F29: =IF(D29<=E29,"PASS","FAIL") -> PASS
A30: Slow only, quarter 3: cost | B30: =Rules!G7 -> 11.406399 | C30: =Reference_Values!B30 -> 11.406399 | D30: =ABS(B30-C30) -> 0 | E30: 1e-09 | F30: =IF(D30<=E30,"PASS","FAIL") -> PASS
A31: Slow only, quarter 4: cost | B31: =Rules!G8 -> 12.305739 | C31: =Reference_Values!B31 -> 12.305739 | D31: =ABS(B31-C31) -> 0 | E31: 1e-09 | F31: =IF(D31<=E31,"PASS","FAIL") -> PASS
A32: Commit and slow, quarter 1: cost | B32: =Rules!M5 -> 10.378782 | C32: =Reference_Values!B32 -> 10.378782 | D32: =ABS(B32-C32) -> 0 | E32: 1e-09 | F32: =IF(D32<=E32,"PASS","FAIL") -> PASS
A33: Commit and slow, quarter 2: cost | B33: =Rules!M6 -> 10.297906 | C33: =Reference_Values!B33 -> 10.297906 | D33: =ABS(B33-C33) -> 0 | E33: 1e-09 | F33: =IF(D33<=E33,"PASS","FAIL") -> PASS
A34: Commit and slow, quarter 3: cost | B34: =Rules!M7 -> 10.233433 | C34: =Reference_Values!B34 -> 10.233433 | D34: =ABS(B34-C34) -> 0 | E34: 1e-09 | F34: =IF(D34<=E34,"PASS","FAIL") -> PASS
A35: Commit and slow, quarter 4: cost | B35: =Rules!M8 -> 10.305358 | C35: =Reference_Values!B35 -> 10.305358 | D35: =ABS(B35-C35) -> 0 | E35: 1e-09 | F35: =IF(D35<=E35,"PASS","FAIL") -> PASS
A36: Commit and slow, quarter 5: cost | B36: =Rules!M9 -> 10.348724 | C36: =Reference_Values!B36 -> 10.348724 | D36: =ABS(B36-C36) -> 0 | E36: 1e-09 | F36: =IF(D36<=E36,"PASS","FAIL") -> PASS
A37: Commit and slow, quarter 6: cost | B37: =Rules!M10 -> 10.42886 | C37: =Reference_Values!B37 -> 10.42886 | D37: =ABS(B37-C37) -> 0 | E37: 1e-09 | F37: =IF(D37<=E37,"PASS","FAIL") -> PASS
A38: The best quarter to read | B38: =Rules!B12 -> 3 | C38: =Reference_Values!B38 -> 3 | D38: =ABS(B38-C38) -> 0 | E38: 0 | F38: =IF(D38<=E38,"PASS","FAIL") -> PASS
A39: Quarter 3 rule saves against the package | B39: =Rules!B14 -> 0.20717834 | C39: =Reference_Values!B39 -> 0.20717834 | D39: =ABS(B39-C39) -> 1.7208457e-15 | E39: 1e-09 | F39: =IF(D39<=E39,"PASS","FAIL") -> PASS
A40: Every quarter: contingent delay | B40: =Rules!B29 -> 0.1556462 | C40: =Reference_Values!B40 -> 0.1556462 | D40: =ABS(B40-C40) -> 0 | E40: 1e-09 | F40: =IF(D40<=E40,"PASS","FAIL") -> PASS
...
