Workbook

Sheet README
B1: DCT Laboratory — Vol II, Ch 16: Enterprise Applications and Integrated Transformation Case Studies
B2: Seed 26216 · Companion to DCT_V2_Ch16_Lab.ipynb and AXIOM Lab 2.16 (module AXIOM-16). Money in $ million.
B4: Worked Example 16.1, Can Meridian Run Its Whole Program?, with the book's declarations: the build's law and levers (Volume I's law on Chapter 9's 100,000 paths, seed 8; fresh paths seed 26209), the sale with the engineers kept, Chapter 5's automation program, Chapter 11's family of laws (seed 1108), Volume I's feedback core; the new declarations put them on one account (Online Appendix Remark 16.B.1).
B5: Declarations: the inputs, the plan's shapes, the closure buffer (the 90th-percentile closure), the seeds.
B6: Chapter5: Chapter 5's plan on its own account, its war chest and payouts, worth $1,021.93m.
B7: OneAccount: the one account by quarter in closed form (Volume I's plan, the automation program's cash, the sale), the planned margins, and the joint check at quarter 9 against the room of 270 or 362 (Step 2).
B8: Programs: every program's war chest and payouts after the build and its value, payouts at 10 percent plus the year-6 savings forever less the levers 0.03 l + 8 phi; the eight timings of the rounds, no sale, the sale after the build, a dollar of room, the trigger's other branch, Chapter 5's year-1 payout released (Steps 3-4).
B9: Prices: the value of the sale, the appetite's price, each lever's cost per point of chance, the payouts' prices, a dollar of room, capability, holding the payouts (Step 4; Figure 16.2).
B10: Trigger: round 3 on a trigger at 33 triggers and the best one (Step 5; Figure 16.3(b)); Proposition 16.2.
B11: Certify: the margins and their certified region, the records' corner and the price of ambiguity, the triggers (Step 6; Figure 16.3(a)). Core: the feedback core's phases, closed form and power iteration.
B12: Table16_3: the Worked Example's table, linked to the sheets.
B13: Engine values (green) are what needs the 100,000 paths: breach chances, cheapest packages, the trigger rule's packages and shares, the certified region's edges.
... B20: Cross-sheet link: green.

Sheet Declarations
A1: Declarations (Worked Example 16.1, Step 1; Table 16.1; Online Appendix Remark 16.B.1). Money in $ million.
A3: Quantity | B3: Value | C3: Source
A4: The board's hurdle rate a year, r | B4: 0.1 | C4: Chapter 5
A5: A year's discount, beta = 1/(1 + r) | B5: =1/(1+B4) -> 0.90909091
A6: A dollar a year of savings from year 6 on, beta^6 / r | B6: =B5^6/B4 -> 5.6447393 | C6: $5.645 (Step 1; Chapter 12)
A7: Liquidity today | B7: 620 | C7: Volume I
A8: The board's floor | B8: 350
A9: Room above the floor | B9: =B7-B8 -> 270 | C9: $270m
A10: The sale's proceeds with the shared engineering team | B10: 112 | C10: Volume I, Worked Example 3.1
A11: The buyer's discount if Meridian keeps the team | B11: 20 | C11: Chapters 6-7 priced the team at $23.8m
A12: The sale's proceeds with the engineers kept, G | B12: =B10-B11 -> 92 | C12: $92m, at the start
A13: Cost of an automation round | B13: 120 | C13: Volume I, Worked Example 6.1
A14: Efficiency today | B14: 71
A15: Efficiency ceiling | B15: 85
A16: Share of the gap to the ceiling a round closes | B16: 0.5 | C16: A round halves the gap
A17: Savings a point of efficiency, a year | B17: 10
A18: Cash before a round | B18: 470 | C18: Chapter 5's commitments
A19: Cash at the end of year 6 | B19: 470 | C19: The board's end condition
A20: Line fees over the program, per $ of line | B20: 0.03 | C20: Volume I, Worked Example 15.1
A21: A quarter of delay | B21: 8 | C21: The transformation office
A22: The draw's depth with no delay (index points) | B22: 28
A23: Points of depth a quarter of delay removes | B23: 4 | C23: Depth 28 - 4 phi
A24: The board's appetite | B24: 0.05 | C24: At most a 5% chance below the floor in a quarter of 12
A25: Volume I's package: line | B25: 170 | C25: As Chapter 9 designed it on the book's paths
A26: Volume I's package: delay (quarters) | B26: 0.66757636 | C26: 0.668 quarter
A27: Volume I's package: levers, 0.03 l + 8 phi | B27: =B20*B25+B21*B26 -> 10.440611 | C27: $10.44m
A28: Liquidity at index 100 ($ billion) | B28: 0.62 | C28: Volume I, Chapter 1
A29: The plan without the draw: index today | B29: 100 | C29: relax(100, 112, 0.35, t)
A30: its long-run index | B30: 112
A31: its speed a year | B31: 0.35
A32: The draw's deepest point (years) | B32: 2 | C32: trough(D, 2, t) = D (t/2) e^(1 - t/2)
A33: The draw at its deepest, $m a point of depth | B33: =1000*B28/100 -> 6.2 | C33: $6.2m (Remark 16.B.1)
A34: The plan without the draw, long run | B34: =1000*B28*B30/100 -> 694.4 | C34: Toward $694m (Remark 16.B.1)
A35: Closure sizes: mean | B35: 120 | C35: Volume I, Chapter 8
A36: standard deviation | B36: 50
A37: gamma shape, (mean / sd)^2 | B37: =(B35/B36)^2 -> 5.76
A38: gamma scale, sd^2 / mean | B38: =B36^2/B35 -> 20.833333
A39: Volume I's closure buffer: the 90th-percentile closure | B39: =GAMMAINV(0.9,B37,B38) -> 186.86698 | C39: $186.9m (Volume I, Chapter 13)
A40: Closures a year | B40: 0.1
A41: Persistence of execution deviations | B41: 0.6 | C41: E' = 0.6 E + w
...

Sheet Chapter5
A1: Chapter 5's automation program on its own account: the war chest and the payouts (Worked Example 16.1, Step 1; Chapter 5)
A2: Efficiency e_k = e_(k-1) + z_k (85 - e_(k-1))/2; savings S_k = 10 (e_k - 71); the war chest W_6 = 470, W_(k-1) = max{W_k + 120 z_k - S_k, 470 if z_k, 350 (from year 1)}; pay out everything above it. Value: payouts at 10 percent plus the year-6 savings forever.
A4: Year | B4: Round z (1 = yes) | C4: Efficiency | D4: Savings | E4: War chest | F4: Cash before the payout | G4: Payout | H4: Year-end cash | I4: beta^k | J4: PV of the payout | K4: Commitments kept
A5: 0 | C5: =Eff_0 -> 71 | E5: =MAX(E6+Round_cost*B6-D6,IF(B6=1,Pre_cash,-1000000000),-1000000000) -> 535 | H5: =Liq_today -> 620
A6: 1 | B6: 1 | C6: =IF(B6=1,C5+Gap_share*(Eff_ceil-C5),C5) -> 78 | D6: =Save_pt*(C6-Eff_0) -> 70 | E6: =MAX(E7+Round_cost*B7-D7,IF(B7=1,Pre_cash,-1000000000),Floor_cash) -> 485 | F6: =H5-Round_cost*B6+D6 -> 570 | G6: =MAX(0,F6-E6) -> 85 | H6: =F6-G6 -> 485 | I6: =Beta_y^A6 -> 0.90909091 | J6: =I6*G6 -> 77.272727 | K6: =IF(AND(H6>=Floor_cash-0.000000001,IF(B6=1,H5>=Pre_cash-0.000000001,TRUE())),1,0) -> 1
A7: 2 | B7: 1 | C7: =IF(B7=1,C6+Gap_share*(Eff_ceil-C6),C6) -> 81.5 | D7: =Save_pt*(C7-Eff_0) -> 105 | E7: =MAX(E8+Round_cost*B8-D8,IF(B8=1,Pre_cash,-1000000000),Floor_cash) -> 470 | F7: =H6-Round_cost*B7+D7 -> 470 | G7: =MAX(0,F7-E7) -> 0 | H7: =F7-G7 -> 470 | I7: =Beta_y^A7 -> 0.82644628 | J7: =I7*G7 -> 0 | K7: =IF(AND(H7>=Floor_cash-0.000000001,IF(B7=1,H6>=Pre_cash-0.000000001,TRUE())),1,0) -> 1
A8: 3 | B8: 1 | C8: =IF(B8=1,C7+Gap_share*(Eff_ceil-C7),C7) -> 83.25 | D8: =Save_pt*(C8-Eff_0) -> 122.5 | E8: =MAX(E9+Round_cost*B9-D9,IF(B9=1,Pre_cash,-1000000000),Floor_cash) -> 350 | F8: =H7-Round_cost*B8+D8 -> 472.5 | G8: =MAX(0,F8-E8) -> 122.5 | H8: =F8-G8 -> 350 | I8: =Beta_y^A8 -> 0.7513148 | J8: =I8*G8 -> 92.036063 | K8: =IF(AND(H8>=Floor_cash-0.000000001,IF(B8=1,H7>=Pre_cash-0.000000001,TRUE())),1,0) -> 1
A9: 4 | B9: 0 | C9: =IF(B9=1,C8+Gap_share*(Eff_ceil-C8),C8) -> 83.25 | D9: =Save_pt*(C9-Eff_0) -> 122.5 | E9: =MAX(E10+Round_cost*B10-D10,IF(B10=1,Pre_cash,-1000000000),Floor_cash) -> 350 | F9: =H8-Round_cost*B9+D9 -> 472.5 | G9: =MAX(0,F9-E9) -> 122.5 | H9: =F9-G9 -> 350 | I9: =Beta_y^A9 -> 0.68301346 | J9: =I9*G9 -> 83.669148 | K9: =IF(AND(H9>=Floor_cash-0.000000001,IF(B9=1,H8>=Pre_cash-0.000000001,TRUE())),1,0) -> 1
A10: 5 | B10: 0 | C10: =IF(B10=1,C9+Gap_share*(Eff_ceil-C9),C9) -> 83.25 | D10: =Save_pt*(C10-Eff_0) -> 122.5 | E10: =MAX(E11+Round_cost*B11-D11,IF(B11=1,Pre_cash,-1000000000),Floor_cash) -> 350 | F10: =H9-Round_cost*B10+D10 -> 472.5 | G10: =MAX(0,F10-E10) -> 122.5 | H10: =F10-G10 -> 350 | I10: =Beta_y^A10 -> 0.62092132 | J10: =I10*G10 -> 76.062862 | K10: =IF(AND(H10>=Floor_cash-0.000000001,IF(B10=1,H9>=Pre_cash-0.000000001,TRUE())),1,0) -> 1
A11: 6 | B11: 0 | C11: =IF(B11=1,C10+Gap_share*(Eff_ceil-C10),C10) -> 83.25 | D11: =Save_pt*(C11-Eff_0) -> 122.5 | E11: =MAX(End_cash,Floor_cash) -> 470 | F11: =H10-Round_cost*B11+D11 -> 472.5 | G11: =MAX(0,F11-E11) -> 2.5 | H11: =F11-G11 -> 470 | I11: =Beta_y^A11 -> 0.56447393 | J11: =I11*G11 -> 1.4111848 | K11: =IF(AND(H11>=Floor_cash-0.000000001,IF(B11=1,H10>=Pre_cash-0.000000001,TRUE())),1,0) -> 1
A13: Payouts at 10 percent | B13: =SUM(J6:J11) -> 330.45199 | C13: $330.45m
A14: The year-6 savings forever, beta^6 S_6 / r | B14: =I11*D11/R_hurdle -> 691.48056 | C14: $691.48m
A15: Value of Chapter 5's plan alone | B15: =B13+B14 -> 1021.9325 | C15: $1,021.93m (Worked Example 5.1)
A16: Every commitment kept (1 = yes) | B16: =IF(AND(SUM(K6:K11)=6,H11>=End_cash-0.000000001),1,0) -> 1 | C16: Floor at year ends, 470 before a round, 470 in year 6
A18: The rounds (column B) are Chapter 5's best plan; change them to see another schedule's war chest.

Sheet OneAccount
A1: One account, quarter by quarter, and the joint check at the binding quarter (Theorem 16.1(i); Worked Example 16.1, Steps 1-2; Figure 16.1)
A2: Volume I's plan: the plan without the draw 1000 x 0.62 x relax(100, 112, 0.35, t)/100 less the depth times the draw's shape 1000 x 0.62 x (t/2) e^(1 - t/2)/100. The automation program's cash: a round at the start of its year, savings evenly over the year, payouts at year ends counted from the next quarter. With no deviations and no closures; the breach chances on the paths are the engine's.
A4: Quarter | B4: Years in | C4: Plan without the draw | D4: Draw per point of depth | E4: Year | F4: Quarter of the year | G4: Volume I's plan (its package) | H4: Automation cash: pieces | I4: One account: pieces, with the sale | J4: Margin: pieces, with the sale | K4: Margin: pieces, without the sale | L4: The program's plan (its package) | M4: Automation cash: program | N4: One account: program | O4: Margin: program
A5: 1 | B5: =A5/4 -> 0.25 | C5: =1000*Idx_bn*(Rel_inf+(Rel_0-Rel_inf)*EXP(-Rel_k*B5))/100 -> 626.23332 | D5: =1000*Idx_bn*(B5/Tau_draw)*EXP(1-B5/Tau_draw)/100 -> 1.8591284 | E5: =INT((A5-1)/4)+1 -> 1 | F5: =MOD(A5-1,4)+1 -> 1 | G5: =C5-(Depth_0-Depth_pq*Pkg_delay)*D5 -> 579.14216 | H5: =INDEX($E$21:$E$23,E5)-Round_cost*INDEX($B$22:$B$24,E5)+F5*INDEX($C$22:$C$24,E5)/4 -> -102.5 | I5: =G5+H5+Sale_G -> 568.64216 | J5: =I5-Floor_cash -> 218.64216 | K5: =G5+H5-Floor_cash -> 126.64216 | L5: =C5-(Depth_0-Depth_pq*$B$28)*D5 -> 589.58233 | M5: =INDEX($G$21:$G$23,E5)-Round_cost*INDEX($B$22:$B$24,E5)+F5*INDEX($C$22:$C$24,E5)/4 -> -102.5 | N5: =L5+M5+Sale_G -> 579.08233 | O5: =N5-Floor_cash -> 229.08233
A6: 2 | B6: =A6/4 -> 0.5 | C6: =1000*Idx_bn*(Rel_inf+(Rel_0-Rel_inf)*EXP(-Rel_k*B6))/100 -> 631.9444 | D6: =1000*Idx_bn*(B6/Tau_draw)*EXP(1-B6/Tau_draw)/100 -> 3.28135 | E6: =INT((A6-1)/4)+1 -> 1 | F6: =MOD(A6-1,4)+1 -> 2 | G6: =C6-(Depth_0-Depth_pq*Pkg_delay)*D6 -> 548.8288 | H6: =INDEX($E$21:$E$23,E6)-Round_cost*INDEX($B$22:$B$24,E6)+F6*INDEX($C$22:$C$24,E6)/4 -> -85 | I6: =G6+H6+Sale_G -> 555.8288 | J6: =I6-Floor_cash -> 205.8288 | K6: =G6+H6-Floor_cash -> 113.8288 | L6: =C6-(Depth_0-Depth_pq*$B$28)*D6 -> 567.25563 | M6: =INDEX($G$21:$G$23,E6)-Round_cost*INDEX($B$22:$B$24,E6)+F6*INDEX($C$22:$C$24,E6)/4 -> -85 | N6: =L6+M6+Sale_G -> 574.25563 | O6: =N6-Floor_cash -> 224.25563
A7: 3 | B7: =A7/4 -> 0.75 | C7: =1000*Idx_bn*(Rel_inf+(Rel_0-Rel_inf)*EXP(-Rel_k*B7))/100 -> 637.177 | D7: =1000*Idx_bn*(B7/Tau_draw)*EXP(1-B7/Tau_draw)/100 -> 4.3436719 | E7: =INT((A7-1)/4)+1 -> 1 | F7: =MOD(A7-1,4)+1 -> 3 | G7: =C7-(Depth_0-Depth_pq*Pkg_delay)*D7 -> 527.15312 | H7: =INDEX($E$21:$E$23,E7)-Round_cost*INDEX($B$22:$B$24,E7)+F7*INDEX($C$22:$C$24,E7)/4 -> -67.5 | I7: =G7+H7+Sale_G -> 551.65312 | J7: =I7-Floor_cash -> 201.65312 | K7: =G7+H7-Floor_cash -> 109.65312 | L7: =C7-(Depth_0-Depth_pq*$B$28)*D7 -> 551.54555 | M7: =INDEX($G$21:$G$23,E7)-Round_cost*INDEX($B$22:$B$24,E7)+F7*INDEX($C$22:$C$24,E7)/4 -> -67.5 | N7: =L7+M7+Sale_G -> 576.04555 | O7: =N7-Floor_cash -> 226.04555
A8: 4 | B8: =A8/4 -> 1 | C8: =1000*Idx_bn*(Rel_inf+(Rel_0-Rel_inf)*EXP(-Rel_k*B8))/100 -> 641.97121 | D8: =1000*Idx_bn*(B8/Tau_draw)*EXP(1-B8/Tau_draw)/100 -> 5.1110359 | E8: =INT((A8-1)/4)+1 -> 1 | F8: =MOD(A8-1,4)+1 -> 4 | G8: =C8-(Depth_0-Depth_pq*Pkg_delay)*D8 -> 512.51023 | H8: =INDEX($E$21:$E$23,E8)-Round_cost*INDEX($B$22:$B$24,E8)+F8*INDEX($C$22:$C$24,E8)/4 -> -50 | I8: =G8+H8+Sale_G -> 554.51023 | J8: =I8-Floor_cash -> 204.51023 | K8: =G8+H8-Floor_cash -> 112.51023 | L8: =C8-(Depth_0-Depth_pq*$B$28)*D8 -> 541.21189 | M8: =INDEX($G$21:$G$23,E8)-Round_cost*INDEX($B$22:$B$24,E8)+F8*INDEX($C$22:$C$24,E8)/4 -> -50 | N8: =L8+M8+Sale_G -> 583.21189 | O8: =N8-Floor_cash -> 233.21189
A9: 5 | B9: =A9/4 -> 1.25 | C9: =1000*Idx_bn*(Rel_inf+(Rel_0-Rel_inf)*EXP(-Rel_k*B9))/100 -> 646.36375 | D9: =1000*Idx_bn*(B9/Tau_draw)*EXP(1-B9/Tau_draw)/100 -> 5.6380917 | E9: =INT((A9-1)/4)+1 -> 2 | F9: =MOD(A9-1,4)+1 -> 1 | G9: =C9-(Depth_0-Depth_pq*Pkg_delay)*D9 -> 503.55261 | H9: =INDEX($E$21:$E$23,E9)-Round_cost*INDEX($B$22:$B$24,E9)+F9*INDEX($C$22:$C$24,E9)/4 -> -228.75 | I9: =G9+H9+Sale_G -> 366.80261 | J9: =I9-Floor_cash -> 16.802608 | K9: =G9+H9-Floor_cash -> -75.197392 | L9: =C9-(Depth_0-Depth_pq*$B$28)*D9 -> 535.21401 | M9: =INDEX($G$21:$G$23,E9)-Round_cost*INDEX($B$22:$B$24,E9)+F9*INDEX($C$22:$C$24,E9)/4 -> -143.75 | N9: =L9+M9+Sale_G -> 483.46401 | O9: =N9-Floor_cash -> 133.46401
A10: 6 | B10: =A10/4 -> 1.5 | C10: =1000*Idx_bn*(Rel_inf+(Rel_0-Rel_inf)*EXP(-Rel_k*B10))/100 -> 650.38828 | D10: =1000*Idx_bn*(B10/Tau_draw)*EXP(1-B10/Tau_draw)/100 -> 5.9707182 | E10: =INT((A10-1)/4)+1 -> 2 | F10: =MOD(A10-1,4)+1 -> 2 | G10: =C10-(Depth_0-Depth_pq*Pkg_delay)*D10 -> 499.15181 | H10: =INDEX($E$21:$E$23,E10)-Round_cost*INDEX($B$22:$B$24,E10)+F10*INDEX($C$22:$C$24,E10)/4 -> -202.5 | I10: =G10+H10+Sale_G -> 388.65181 | J10: =I10-Floor_cash -> 38.651813 | K10: =G10+H10-Floor_cash -> -53.348187 | L10: =C10-(Depth_0-Depth_pq*$B$28)*D10 -> 532.68112 | M10: =INDEX($G$21:$G$23,E10)-Round_cost*INDEX($B$22:$B$24,E10)+F10*INDEX($C$22:$C$24,E10)/4 -> -117.5 | N10: =L10+M10+Sale_G -> 507.18112 | O10: =N10-Floor_cash -> 157.18112
A11: 7 | B11: =A11/4 -> 1.75 | C11: =1000*Idx_bn*(Rel_inf+(Rel_0-Rel_inf)*EXP(-Rel_k*B11))/100 -> 654.07563 | D11: =1000*Idx_bn*(B11/Tau_draw)*EXP(1-B11/Tau_draw)/100 -> 6.1473304 | E11: =INT((A11-1)/4)+1 -> 2 | F11: =MOD(A11-1,4)+1 -> 3 | G11: =C11-(Depth_0-Depth_pq*Pkg_delay)*D11 -> 498.36563 | H11: =INDEX($E$21:$E$23,E11)-Round_cost*INDEX($B$22:$B$24,E11)+F11*INDEX($C$22:$C$24,E11)/4 -> -176.25 | I11: =G11+H11+Sale_G -> 414.11563 | J11: =I11-Floor_cash -> 64.115632 | K11: =G11+H11-Floor_cash -> -27.884368 | L11: =C11-(Depth_0-Depth_pq*$B$28)*D11 -> 532.88673 | M11: =INDEX($G$21:$G$23,E11)-Round_cost*INDEX($B$22:$B$24,E11)+F11*INDEX($C$22:$C$24,E11)/4 -> -91.25 | N11: =L11+M11+Sale_G -> 533.63673 | O11: =N11-Floor_cash -> 183.63673
A12: 8 | B12: =A12/4 -> 2 | C12: =1000*Idx_bn*(Rel_inf+(Rel_0-Rel_inf)*EXP(-Rel_k*B12))/100 -> 657.45405 | D12: =1000*Idx_bn*(B12/Tau_draw)*EXP(1-B12/Tau_draw)/100 -> 6.2 | E12: =INT((A12-1)/4)+1 -> 2 | F12: =MOD(A12-1,4)+1 -> 4 | G12: =C12-(Depth_0-Depth_pq*Pkg_delay)*D12 -> 500.40995 | H12: =INDEX($E$21:$E$23,E12)-Round_cost*INDEX($B$22:$B$24,E12)+F12*INDEX($C$22:$C$24,E12)/4 -> -150 | I12: =G12+H12+Sale_G -> 442.40995 | J12: =I12-Floor_cash -> 92.409947 | K12: =G12+H12-Floor_cash -> 0.40994716 | L12: =C12-(Depth_0-Depth_pq*$B$28)*D12 -> 535.22682 | M12: =INDEX($G$21:$G$23,E12)-Round_cost*INDEX($B$22:$B$24,E12)+F12*INDEX($C$22:$C$24,E12)/4 -> -65 | N12: =L12+M12+Sale_G -> 562.22682 | O12: =N12-Floor_cash -> 212.22682
A13: 9 | B13: =A13/4 -> 2.25 | C13: =1000*Idx_bn*(Rel_inf+(Rel_0-Rel_inf)*EXP(-Rel_k*B13))/100 -> 660.54943 | D13: =1000*Idx_bn*(B13/Tau_draw)*EXP(1-B13/Tau_draw)/100 -> 6.1554159 | E13: =INT((A13-1)/4)+1 -> 3 | F13: =MOD(A13-1,4)+1 -> 1 | G13: =C13-(Depth_0-Depth_pq*Pkg_delay)*D13 -> 504.63462 | H13: =INDEX($E$21:$E$23,E13)-Round_cost*INDEX($B$22:$B$24,E13)+F13*INDEX($C$22:$C$24,E13)/4 -> -239.375 | I13: =G13+H13+Sale_G -> 357.25962 | J13: =I13-Floor_cash -> 7.259622 | K13: =G13+H13-Floor_cash -> -84.740378 | L13: =C13-(Depth_0-Depth_pq*$B$28)*D13 -> 539.20113 | M13: =INDEX($G$21:$G$23,E13)-Round_cost*INDEX($B$22:$B$24,E13)+F13*INDEX($C$22:$C$24,E13)/4 -> -154.375 | N13: =L13+M13+Sale_G -> 476.82613 | O13: =N13-Floor_cash -> 126.82613
A14: 10 | B14: =A14/4 -> 2.5 | C14: =1000*Idx_bn*(Rel_inf+(Rel_0-Rel_inf)*EXP(-Rel_k*B14))/100 -> 663.38547 | D14: =1000*Idx_bn*(B14/Tau_draw)*EXP(1-B14/Tau_draw)/100 -> 6.0357061 | E14: =INT((A14-1)/4)+1 -> 3 | F14: =MOD(A14-1,4)+1 -> 2 | G14: =C14-(Depth_0-Depth_pq*Pkg_delay)*D14 -> 510.50287 | H14: =INDEX($E$21:$E$23,E14)-Round_cost*INDEX($B$22:$B$24,E14)+F14*INDEX($C$22:$C$24,E14)/4 -> -208.75 | I14: =G14+H14+Sale_G -> 393.75287 | J14: =I14-Floor_cash -> 43.752875 | K14: =G14+H14-Floor_cash -> -48.247125 | L14: =C14-(Depth_0-Depth_pq*$B$28)*D14 -> 544.39713 | M14: =INDEX($G$21:$G$23,E14)-Round_cost*INDEX($B$22:$B$24,E14)+F14*INDEX($C$22:$C$24,E14)/4 -> -123.75 | N14: =L14+M14+Sale_G -> 512.64713 | O14: =N14-Floor_cash -> 162.64713
A15: 11 | B15: =A15/4 -> 2.75 | C15: =1000*Idx_bn*(Rel_inf+(Rel_0-Rel_inf)*EXP(-Rel_k*B15))/100 -> 665.9839 | D15: =1000*Idx_bn*(B15/Tau_draw)*EXP(1-B15/Tau_draw)/100 -> 5.8591411 | E15: =INT((A15-1)/4)+1 -> 3 | F15: =MOD(A15-1,4)+1 -> 3 | G15: =C15-(Depth_0-Depth_pq*Pkg_delay)*D15 -> 517.57364 | H15: =INDEX($E$21:$E$23,E15)-Round_cost*INDEX($B$22:$B$24,E15)+F15*INDEX($C$22:$C$24,E15)/4 -> -178.125 | I15: =G15+H15+Sale_G -> 431.44864 | J15: =I15-Floor_cash -> 81.448644 | K15: =G15+H15-Floor_cash -> -10.551356 | L15: =C15-(Depth_0-Depth_pq*$B$28)*D15 -> 550.47638 | M15: =INDEX($G$21:$G$23,E15)-Round_cost*INDEX($B$22:$B$24,E15)+F15*INDEX($C$22:$C$24,E15)/4 -> -93.125 | N15: =L15+M15+Sale_G -> 549.35138 | O15: =N15-Floor_cash -> 199.35138
A16: 12 | B16: =A16/4 -> 3 | C16: =1000*Idx_bn*(Rel_inf+(Rel_0-Rel_inf)*EXP(-Rel_k*B16))/100 -> 668.36463 | D16: =1000*Idx_bn*(B16/Tau_draw)*EXP(1-B16/Tau_draw)/100 -> 5.6407351 | E16: =INT((A16-1)/4)+1 -> 3 | F16: =MOD(A16-1,4)+1 -> 4 | G16: =C16-(Depth_0-Depth_pq*Pkg_delay)*D16 -> 525.48653 | H16: =INDEX($E$21:$E$23,E16)-Round_cost*INDEX($B$22:$B$24,E16)+F16*INDEX($C$22:$C$24,E16)/4 -> -147.5 | I16: =G16+H16+Sale_G -> 469.98653 | J16: =I16-Floor_cash -> 119.98653 | K16: =G16+H16-Floor_cash -> 27.986533 | L16: =C16-(Depth_0-Depth_pq*$B$28)*D16 -> 557.16278 | M16: =INDEX($G$21:$G$23,E16)-Round_cost*INDEX($B$22:$B$24,E16)+F16*INDEX($C$22:$C$24,E16)/4 -> -62.5 | N16: =L16+M16+Sale_G -> 586.66278 | O16: =N16-Floor_cash -> 236.66278
A20: Year | B20: Round z | C20: Savings | D20: Pieces: payout | E20: Pieces: cash so far | F20: Program: payout | G20: Program: cash so far
A21: 0 | E21: 0 | G21: 0
A22: 1 | B22: =Chapter5!B6 -> 1 | C22: =Chapter5!D6 -> 70 | D22: =Chapter5!G6 -> 85 | E22: =E21-Round_cost*B22+C22-D22 -> -135 | F22: 0 | G22: =G21-Round_cost*B22+C22-F22 -> -50 | H22: The year-3 payout is made at the end of the build: it counts from quarter 13, after the window.
A23: 2 | B23: =Chapter5!B7 -> 1 | C23: =Chapter5!D7 -> 105 | D23: =Chapter5!G7 -> 0 | E23: =E22-Round_cost*B23+C23-D23 -> -150 | F23: 0 | G23: =G22-Round_cost*B23+C23-F23 -> -65
A24: 3 | B24: =Chapter5!B8 -> 1 | C24: =Chapter5!D8 -> 122.5 | D24: 0 | E24: =E23-Round_cost*B24+C24-D24 -> -147.5 | F24: 0 | G24: =G23-Round_cost*B24+C24-F24 -> -62.5
A27: The program's line (engine) | B27: 160 | C27: Worked Example 16.1, Step 4
A28: The program's delay (engine) | B28: 2.0714825 | C28: 2.071 quarters
A30: Joint check at the binding quarter | B30: Binding quarter | C30: The build's draw | D30: Rounds less savings | E30: Payouts made | F30: Closure buffer | G30: Claims | H30: Room | I30: Left
A31: Pieces, no sale | B31: =MATCH(MIN(K5:K16),K5:K16,0) -> 9 | C31: =Liq_today-INDEX(G5:G16,B31) -> 115.36538 | D31: =-(INDEX(H5:H16,B31)+E31) -> 154.375 | E31: =IF(B31>=5,Chapter5!G6,0)+IF(B31>=9,Chapter5!G7,0) -> 85 | F31: =MAX(P90_closure-Pkg_line,0) -> 16.866976 | G31: =C31+D31+E31+F31 -> 371.60735 | H31: =Room_0+0 -> 270 | I31: =H31-G31 -> -101.60735
A32: Pieces, with the sale | B32: =MATCH(MIN(J5:J16),J5:J16,0) -> 9 | C32: =Liq_today-INDEX(G5:G16,B32) -> 115.36538 | D32: =-(INDEX(H5:H16,B32)+E32) -> 154.375 | E32: =IF(B32>=5,Chapter5!G6,0)+IF(B32>=9,Chapter5!G7,0) -> 85 | F32: =MAX(P90_closure-Pkg_line,0) -> 16.866976 | G32: =C32+D32+E32+F32 -> 371.60735 | H32: =Room_0+Sale_G -> 362 | I32: =H32-G32 -> -9.6073544
A33: Program | B33: =MATCH(MIN(O5:O16),O5:O16,0) -> 9 | C33: =Liq_today-INDEX(L5:L16,B33) -> 80.798874 | D33: =-(INDEX(M5:M16,B33)+E33) -> 154.375 | E33: =IF(B33>=5,OneAccount!$F$22,0)+IF(B33>=9,OneAccount!$F$23,0) -> 0 | F33: =MAX(P90_closure-$B$27,0) -> 26.866976 | G33: =C33+D33+E33+F33 -> 262.04085 | H33: =Room_0+Sale_G -> 362 | I33: =H33-G33 -> 99.959149
A34: With no deviations and no closures the pieces' plan keeps 7.3 above the floor at quarter 9; the closure buffer (the 90th-percentile closure less the line) takes their claims past the room.
A36: The build alone (Volume I's joint check) | B36: Value | C36: Note
A37: Its deepest quarter | B37: =MATCH(MIN(G5:G16),G5:G16,0) -> 7 | C37: Quarter 7
A38: Its deepest draw | B38: =Liq_today-MIN(G5:G16) -> 121.63437 | C38: $121.6m
A39: The closure buffer the line leaves uncovered | B39: =MAX(P90_closure-Pkg_line,0) -> 16.866976 | C39: $16.9m
A40: Draw and buffer, against the room of 270 | B40: =B38+B39 -> 138.50134 | C40: Fits: Volume I, Worked Example 16.1
A42: Year end | B42: Volume I's plan, depth 28 | C42: Note
A43: 0 | B43: =1000*Idx_bn*((Rel_inf+(Rel_0-Rel_inf)*EXP(-Rel_k*A43))-Depth_0*(A43/Tau_draw)*EXP(1-A43/Tau_draw))/100 -> 620 | C43: After the build the plan continues by its own shapes, the delayed spending caught up (depth 28).
A44: 1 | B44: =1000*Idx_bn*((Rel_inf+(Rel_0-Rel_inf)*EXP(-Rel_k*A44))-Depth_0*(A44/Tau_draw)*EXP(1-A44/Tau_draw))/100 -> 498.8622
A45: 2 | B45: =1000*Idx_bn*((Rel_inf+(Rel_0-Rel_inf)*EXP(-Rel_k*A45))-Depth_0*(A45/Tau_draw)*EXP(1-A45/Tau_draw))/100 -> 483.85405
A46: 3 | B46: =1000*Idx_bn*((Rel_inf+(Rel_0-Rel_inf)*EXP(-Rel_k*A46))-Depth_0*(A46/Tau_draw)*EXP(1-A46/Tau_draw))/100 -> 510.42405
A47: 4 | B47: =1000*Idx_bn*((Rel_inf+(Rel_0-Rel_inf)*EXP(-Rel_k*A47))-Depth_0*(A47/Tau_draw)*EXP(1-A47/Tau_draw))/100 -> 548.32544
A48: 5 | B48: =1000*Idx_bn*((Rel_inf+(Rel_0-Rel_inf)*EXP(-Rel_k*A48))-Depth_0*(A48/Tau_draw)*EXP(1-A48/Tau_draw))/100 -> 584.63273
A49: 6 | B49: =1000*Idx_bn*((Rel_inf+(Rel_0-Rel_inf)*EXP(-Rel_k*A49))-Depth_0*(A49/Tau_draw)*EXP(1-A49/Tau_draw))/100 -> 614.80663

Sheet Programs
A1: Every program on one account: the war chest and payouts after the build, the levers and the value (Worked Example 16.1, Steps 3-4; Theorem 16.2; Table 16.3; Figure 16.2(a))
A2: Payouts in years 1-2 are the book's (each program's best, from the book's search); after the build each year pays out everything above the war chest on Volume I's planned path. The package (line, delay) is the engine's cheapest for the appetite on the book's 100,000 paths; the levers and the value are formulas.
A3: Program | B3: Rounds (years) | C3: Sale at the start | D3: Sale in year 4 | E3: Payout y1 | F3: Payout y2 | G3: Line (engine) | H3: Delay (engine) | I3: Levers | J3: Payout y3 | K3: Payout y4 | L3: Payout y5 | M3: Payout y6 | N3: Before the levers | O3: Value | P3: Below the best | Q3: Kept (1 = yes)
A4: Rounds in years 1, 2, 3 | B4: 1, 2, 3 | C4: =O23 -> 92 | D4: =O24 -> 0 | E4: =H25 -> 0 | F4: =H26 -> 0 | G4: =O25 -> 160 | H4: =O26 -> 2.0714825 | I4: =O27 -> 21.37186 | J4: =H27 -> 189.92405 | K4: =H28 -> 160.4014 | L4: =H29 -> 158.80729 | M4: =H30 -> 32.673897 | N4: =O28 -> 1060.78 | O4: =O29 -> 1039.4082 | P4: =$O$4-O4 -> 0 | Q4: =O30 -> 1
A5: Rounds in years 1, 2, 4 | B5: 1, 2, 4 | C5: =O35 -> 92 | D5: =O36 -> 0 | E5: =H37 -> 0 | F5: =H38 -> 77 | G5: =O37 -> 160 | H5: =O38 -> 1.4770281 | I5: =O39 -> 16.616225 | J5: =H39 -> 95.424048 | K5: =H40 -> 160.4014 | L5: =H41 -> 158.80729 | M5: =H42 -> 32.673897 | N5: =O40 -> 1053.4171 | O5: =O41 -> 1036.8009 | P5: =$O$4-O5 -> 2.6072499 | Q5: =O42 -> 1
A6: Rounds in years 1, 3, 4 | B6: 1, 3, 4 | C6: =O47 -> 92 | D6: =O48 -> 0 | E6: =H49 -> 35 | F6: =H50 -> 0 | G6: =O49 -> 140 | H6: =O50 -> 0.011534323 | I6: =O51 -> 4.2922746 | J6: =H51 -> 102.42405 | K6: =H52 -> 160.4014 | L6: =H53 -> 158.80729 | M6: =H54 -> 32.673897 | N6: =O52 -> 1026.8582 | O6: =O53 -> 1022.5659 | P6: =$O$4-O6 -> 16.842278 | Q6: =O54 -> 1
A7: Rounds in years 1, 4, 5 | B7: 1, 4, 5 | C7: =O59 -> 92 | D7: =O60 -> 0 | E7: =H61 -> 61 | F7: =H62 -> 65 | G7: =O61 -> 140 | H7: =O62 -> 0 | I7: =O63 -> 4.2 | J7: =H63 -> 96.424048 | K7: =H64 -> 22.901396 | L7: =H65 -> 158.80729 | M7: =H66 -> 32.673897 | N7: =O64 -> 1005.7913 | O7: =O65 -> 1001.5913 | P7: =$O$4-O7 -> 37.816871 | Q7: =O66 -> 1
A8: Rounds in years 2, 3, 4 | B8: 2, 3, 4 | C8: =O71 -> 92 | D8: =O72 -> 0 | E8: =H73 -> 0 | F8: =H74 -> 0 | G8: =O73 -> 170 | H8: =O74 -> 1.2585203 | I8: =O75 -> 15.168162 | J8: =H75 -> 67.424048 | K8: =H76 -> 160.4014 | L8: =H77 -> 158.80729 | M8: =H78 -> 32.673897 | N8: =O76 -> 968.74395 | O8: =O77 -> 953.57579 | P8: =$O$4-O8 -> 85.832365 | Q8: =O78 -> 1
A9: Rounds in years 2, 4, 5 | B9: 2, 4, 5 | C9: =O83 -> 92 | D9: =O84 -> 0 | E9: =H85 -> 0 | F9: =H86 -> 48 | G9: =O85 -> 155 | H9: =O86 -> 0.006246131 | I9: =O87 -> 4.699969 | J9: =H87 -> 104.42405 | K9: =H88 -> 22.901396 | L9: =H89 -> 158.80729 | M9: =H90 -> 32.673897 | N9: =O88 -> 942.29767 | O9: =O89 -> 937.5977 | P9: =$O$4-O9 -> 101.81045 | Q9: =O90 -> 1
A10: Rounds in years 3, 4, 5 | B10: 3, 4, 5 | C10: =O95 -> 92 | D10: =O96 -> 0 | E10: =H97 -> 8 | F10: =H98 -> 0 | G10: =O97 -> 140 | H10: =O98 -> 0 | I10: =O99 -> 4.2 | J10: =H99 -> 74.424048 | K10: =H100 -> 22.901396 | L10: =H101 -> 158.80729 | M10: =H102 -> 32.673897 | N10: =O100 -> 887.36153 | O10: =O101 -> 883.16153 | P10: =$O$4-O10 -> 156.24662 | Q10: =O102 -> 1
A11: Rounds in years 4, 5, 6 | B11: 4, 5, 6 | C11: =O107 -> 92 | D11: =O108 -> 0 | E11: =H109 -> 64 | F11: =H110 -> 20 | G11: =O109 -> 135 | H11: =O110 -> 0 | I11: =O111 -> 4.05 | J11: =H111 -> 36.325444 | K11: =H112 -> 0 | L11: =H113 -> 21.307285 | M11: =H114 -> 32.673897 | N11: =O112 -> 825.15686 | O11: =O113 -> 821.10686 | P11: =$O$4-O11 -> 218.30129 | Q11: =O114 -> 1
A12: No sale | B12: 1, 2, 3 | C12: =O119 -> 0 | D12: =O120 -> 0 | E12: =H121 -> 0 | F12: =H122 -> 0 | G12: =O121 -> 165 | H12: =O122 -> 5.970015 | I12: =O123 -> 52.71012 | J12: =H123 -> 97.924048 | K12: =H124 -> 160.4014 | L12: =H125 -> 158.80729 | M12: =H126 -> 32.673897 | N12: =O124 -> 991.65906 | O12: =O125 -> 938.94894 | P12: =$O$4-O12 -> 100.45922 | Q12: =O126 -> 1
A13: Sale after the build | B13: 1, 2, 3 | C13: =O131 -> 0 | D13: =O132 -> 92 | E13: =H133 -> 0 | F13: =H134 -> 0 | G13: =O133 -> 165 | H13: =O134 -> 5.970015 | I13: =O135 -> 52.71012 | J13: =H135 -> 97.924048 | K13: =H136 -> 252.4014 | L13: =H137 -> 158.80729 | M13: =H138 -> 32.673897 | N13: =O136 -> 1054.4963 | O13: =O137 -> 1001.7862 | P13: =$O$4-O13 -> 37.621984 | Q13: =O138 -> 1
A14: One more dollar of room at the start | B14: 1, 2, 3 | C14: =O143 -> 93 | D14: =O144 -> 0 | E14: =H145 -> 0 | F14: =H146 -> 0 | G14: =O145 -> 160 | H14: =O146 -> 2.0293931 | I14: =O147 -> 21.035145 | J14: =H147 -> 190.92405 | K14: =H148 -> 160.4014 | L14: =H149 -> 158.80729 | M14: =H150 -> 32.673897 | N14: =O148 -> 1061.5313 | O14: =O149 -> 1040.4962 | P14: =$O$4-O14 -> -1.0880297 | Q14: =O150 -> 1
A15: Round 3 in year 4, payouts held (the trigger's other branch) | B15: 1, 2, 4 | C15: =O155 -> 92 | D15: =O156 -> 0 | E15: =H157 -> 0 | F15: =H158 -> 0 | G15: =O157 -> 0 | H15: =O158 -> 0 | I15: – | J15: =H159 -> 172.42405 | K15: =H160 -> 160.4014 | L15: =H161 -> 158.80729 | M15: =H162 -> 32.673897 | N15: =O160 -> 1047.632 | O15: – | P15: – | Q15: =O162 -> 1
A16: Chapter 5's year-1 payout released | B16: 1, 2, 3 | C16: =O167 -> 92 | D16: =O168 -> 0 | E16: =H169 -> 85 | F16: =H170 -> 0 | G16: =O169 -> 165 | H16: =O170 -> 5.6336263 | I16: =O171 -> 50.01901 | J16: =H171 -> 104.92405 | K16: =H172 -> 160.4014 | L16: =H173 -> 158.80729 | M16: =H174 -> 32.673897 | N16: =O172 -> 1074.191 | O16: =O173 -> 1024.172 | P16: =$O$4-O16 -> 15.236181 | Q16: =O174 -> 1
A17: The round-3 branch's levers are not needed: under the trigger rule one package covers both branches (sheet Trigger), so only its value before the levers is used.
A22: Rounds in years 1, 2, 3
A23: Year | B23: Round z | C23: Efficiency | D23: Savings | E23: Volume I's plan | F23: War chest | G23: Cash before the payout | H23: Payout | I23: Cash after the payout | J23: beta^k | K23: PV of the payout | L23: Commitments kept | N23: Sale at the start, G | O23: =Sale_G -> 92
A24: 0 | C24: =Eff_0 -> 71 | E24: =INDEX(Plan_years,A24+1) -> 620 | N24: Sale in year 4, after the build | O24: 0
A25: 1 | B25: 1 | C25: =IF(B25=1,C24+Gap_share*(Eff_ceil-C24),C24) -> 78 | D25: =Save_pt*(C25-Eff_0) -> 70 | E25: =INDEX(Plan_years,A25+1) -> 498.8622 | H25: 0 | J25: =Beta_y^A25 -> 0.90909091 | K25: =J25*H25 -> 0 | N25: Line (engine) | O25: 160
A26: 2 | B26: 1 | C26: =IF(B26=1,C25+Gap_share*(Eff_ceil-C25),C25) -> 81.5 | D26: =Save_pt*(C26-Eff_0) -> 105 | E26: =INDEX(Plan_years,A26+1) -> 483.85405 | H26: 0 | J26: =Beta_y^A26 -> 0.82644628 | K26: =J26*H26 -> 0 | N26: Delay, quarters (engine) | O26: 2.0714825
A27: 3 | B27: 1 | C27: =IF(B27=1,C26+Gap_share*(Eff_ceil-C26),C26) -> 83.25 | D27: =Save_pt*(C27-Eff_0) -> 122.5 | E27: =INDEX(Plan_years,A27+1) -> 510.42405 | F27: =MAX(IF(B28=1,MAX((F28+Round_cost*B28-D28-(E28-E27)-$O$24),Pre_cash),(F28+Round_cost*B28-D28-(E28-E27)-$O$24)),Floor_cash) -> 350 | G27: =E27+$O$23+SUMPRODUCT(-Round_cost*B25:B27+D25:D27)-H25-H26 -> 539.92405 | H27: =MAX(0,G27-F27) -> 189.92405 | I27: =G27-H27 -> 350 | J27: =Beta_y^A27 -> 0.7513148 | K27: =J27*H27 -> 142.69275 | L27: =IF(AND(I27>=Floor_cash-0.000000001),1,0) -> 1 | N27: Levers, 0.03 l + 8 phi | O27: =Fee_line*O25+Cost_delay*O26 -> 21.37186
A28: 4 | B28: 0 | C28: =IF(B28=1,C27+Gap_share*(Eff_ceil-C27),C27) -> 83.25 | D28: =Save_pt*(C28-Eff_0) -> 122.5 | E28: =INDEX(Plan_years,A28+1) -> 548.32544 | F28: =MAX(IF(B29=1,MAX((F29+Round_cost*B29-D29-(E29-E28)),Pre_cash),(F29+Round_cost*B29-D29-(E29-E28))),Floor_cash) -> 350 | G28: =I27-Round_cost*B28+D28+(E28-E27)+$O$24 -> 510.4014 | H28: =MAX(0,G28-F28) -> 160.4014 | I28: =G28-H28 -> 350 | J28: =Beta_y^A28 -> 0.68301346 | K28: =J28*H28 -> 109.55631 | L28: =IF(AND(I28>=Floor_cash-0.000000001,IF(B28=1,I27>=Pre_cash-0.000000001,TRUE())),1,0) -> 1 | N28: Payouts and savings, before the levers | O28: =SUM(K25:K30)+J30*D30/R_hurdle -> 1060.78
A29: 5 | B29: 0 | C29: =IF(B29=1,C28+Gap_share*(Eff_ceil-C28),C28) -> 83.25 | D29: =Save_pt*(C29-Eff_0) -> 122.5 | E29: =INDEX(Plan_years,A29+1) -> 584.63273 | F29: =MAX(IF(B30=1,MAX((F30+Round_cost*B30-D30-(E30-E29)),Pre_cash),(F30+Round_cost*B30-D30-(E30-E29))),Floor_cash) -> 350 | G29: =I28-Round_cost*B29+D29+(E29-E28) -> 508.80729 | H29: =MAX(0,G29-F29) -> 158.80729 | I29: =G29-H29 -> 350 | J29: =Beta_y^A29 -> 0.62092132 | K29: =J29*H29 -> 98.60683 | L29: =IF(AND(I29>=Floor_cash-0.000000001,IF(B29=1,I28>=Pre_cash-0.000000001,TRUE())),1,0) -> 1 | N29: Value | O29: =O28-O27 -> 1039.4082
A30: 6 | B30: 0 | C30: =IF(B30=1,C29+Gap_share*(Eff_ceil-C29),C29) -> 83.25 | D30: =Save_pt*(C30-Eff_0) -> 122.5 | E30: =INDEX(Plan_years,A30+1) -> 614.80663 | F30: =End_cash -> 470 | G30: =I29-Round_cost*B30+D30+(E30-E29) -> 502.6739 | H30: =MAX(0,G30-F30) -> 32.673897 | I30: =G30-H30 -> 470 | J30: =Beta_y^A30 -> 0.56447393 | K30: =J30*H30 -> 18.443563 | L30: =IF(AND(I30>=Floor_cash-0.000000001,IF(B30=1,I29>=Pre_cash-0.000000001,TRUE()),I30>=End_cash-0.000000001),1,0) -> 1 | N30: Commitments after the build kept (1 = yes) | O30: =IF(SUM(L27:L30)=4,1,0) -> 1
A34: Rounds in years 1, 2, 4
A35: Year | B35: Round z | C35: Efficiency | D35: Savings | E35: Volume I's plan | F35: War chest | G35: Cash before the payout | H35: Payout | I35: Cash after the payout | J35: beta^k | K35: PV of the payout | L35: Commitments kept | N35: Sale at the start, G | O35: =Sale_G -> 92
A36: 0 | C36: =Eff_0 -> 71 | E36: =INDEX(Plan_years,A36+1) -> 620 | N36: Sale in year 4, after the build | O36: 0
A37: 1 | B37: 1 | C37: =IF(B37=1,C36+Gap_share*(Eff_ceil-C36),C36) -> 78 | D37: =Save_pt*(C37-Eff_0) -> 70 | E37: =INDEX(Plan_years,A37+1) -> 498.8622 | H37: 0 | J37: =Beta_y^A37 -> 0.90909091 | K37: =J37*H37 -> 0 | N37: Line (engine) | O37: 160
A38: 2 | B38: 1 | C38: =IF(B38=1,C37+Gap_share*(Eff_ceil-C37),C37) -> 81.5 | D38: =Save_pt*(C38-Eff_0) -> 105 | E38: =INDEX(Plan_years,A38+1) -> 483.85405 | H38: 77 | J38: =Beta_y^A38 -> 0.82644628 | K38: =J38*H38 -> 63.636364 | N38: Delay, quarters (engine) | O38: 1.4770281
A39: 3 | B39: 0 | C39: =IF(B39=1,C38+Gap_share*(Eff_ceil-C38),C38) -> 81.5 | D39: =Save_pt*(C39-Eff_0) -> 105 | E39: =INDEX(Plan_years,A39+1) -> 510.42405 | F39: =MAX(IF(B40=1,MAX((F40+Round_cost*B40-D40-(E40-E39)-$O$36),Pre_cash),(F40+Round_cost*B40-D40-(E40-E39)-$O$36)),Floor_cash) -> 470 | G39: =E39+$O$35+SUMPRODUCT(-Round_cost*B37:B39+D37:D39)-H37-H38 -> 565.42405 | H39: =MAX(0,G39-F39) -> 95.424048 | I39: =G39-H39 -> 470 | J39: =Beta_y^A39 -> 0.7513148 | K39: =J39*H39 -> 71.693499 | L39: =IF(AND(I39>=Floor_cash-0.000000001),1,0) -> 1 | N39: Levers, 0.03 l + 8 phi | O39: =Fee_line*O37+Cost_delay*O38 -> 16.616225
A40: 4 | B40: 1 | C40: =IF(B40=1,C39+Gap_share*(Eff_ceil-C39),C39) -> 83.25 | D40: =Save_pt*(C40-Eff_0) -> 122.5 | E40: =INDEX(Plan_years,A40+1) -> 548.32544 | F40: =MAX(IF(B41=1,MAX((F41+Round_cost*B41-D41-(E41-E40)),Pre_cash),(F41+Round_cost*B41-D41-(E41-E40))),Floor_cash) -> 350 | G40: =I39-Round_cost*B40+D40+(E40-E39)+$O$36 -> 510.4014 | H40: =MAX(0,G40-F40) -> 160.4014 | I40: =G40-H40 -> 350 | J40: =Beta_y^A40 -> 0.68301346 | K40: =J40*H40 -> 109.55631 | L40: =IF(AND(I40>=Floor_cash-0.000000001,IF(B40=1,I39>=Pre_cash-0.000000001,TRUE())),1,0) -> 1 | N40: Payouts and savings, before the levers | O40: =SUM(K37:K42)+J42*D42/R_hurdle -> 1053.4171
A41: 5 | B41: 0 | C41: =IF(B41=1,C40+Gap_share*(Eff_ceil-C40),C40) -> 83.25 | D41: =Save_pt*(C41-Eff_0) -> 122.5 | E41: =INDEX(Plan_years,A41+1) -> 584.63273 | F41: =MAX(IF(B42=1,MAX((F42+Round_cost*B42-D42-(E42-E41)),Pre_cash),(F42+Round_cost*B42-D42-(E42-E41))),Floor_cash) -> 350 | G41: =I40-Round_cost*B41+D41+(E41-E40) -> 508.80729 | H41: =MAX(0,G41-F41) -> 158.80729 | I41: =G41-H41 -> 350 | J41: =Beta_y^A41 -> 0.62092132 | K41: =J41*H41 -> 98.60683 | L41: =IF(AND(I41>=Floor_cash-0.000000001,IF(B41=1,I40>=Pre_cash-0.000000001,TRUE())),1,0) -> 1 | N41: Value | O41: =O40-O39 -> 1036.8009
A42: 6 | B42: 0 | C42: =IF(B42=1,C41+Gap_share*(Eff_ceil-C41),C41) -> 83.25 | D42: =Save_pt*(C42-Eff_0) -> 122.5 | E42: =INDEX(Plan_years,A42+1) -> 614.80663 | F42: =End_cash -> 470 | G42: =I41-Round_cost*B42+D42+(E42-E41) -> 502.6739 | H42: =MAX(0,G42-F42) -> 32.673897 | I42: =G42-H42 -> 470 | J42: =Beta_y^A42 -> 0.56447393 | K42: =J42*H42 -> 18.443563 | L42: =IF(AND(I42>=Floor_cash-0.000000001,IF(B42=1,I41>=Pre_cash-0.000000001,TRUE()),I42>=End_cash-0.000000001),1,0) -> 1 | N42: Commitments after the build kept (1 = yes) | O42: =IF(SUM(L39:L42)=4,1,0) -> 1
A46: Rounds in years 1, 3, 4
A47: Year | B47: Round z | C47: Efficiency | D47: Savings | E47: Volume I's plan | F47: War chest | G47: Cash before the payout | H47: Payout | I47: Cash after the payout | J47: beta^k | K47: PV of the payout | L47: Commitments kept | N47: Sale at the start, G | O47: =Sale_G -> 92
A48: 0 | C48: =Eff_0 -> 71 | E48: =INDEX(Plan_years,A48+1) -> 620 | N48: Sale in year 4, after the build | O48: 0
A49: 1 | B49: 1 | C49: =IF(B49=1,C48+Gap_share*(Eff_ceil-C48),C48) -> 78 | D49: =Save_pt*(C49-Eff_0) -> 70 | E49: =INDEX(Plan_years,A49+1) -> 498.8622 | H49: 35 | J49: =Beta_y^A49 -> 0.90909091 | K49: =J49*H49 -> 31.818182 | N49: Line (engine) | O49: 140
A50: 2 | B50: 0 | C50: =IF(B50=1,C49+Gap_share*(Eff_ceil-C49),C49) -> 78 | D50: =Save_pt*(C50-Eff_0) -> 70 | E50: =INDEX(Plan_years,A50+1) -> 483.85405 | H50: 0 | J50: =Beta_y^A50 -> 0.82644628 | K50: =J50*H50 -> 0 | N50: Delay, quarters (engine) | O50: 0.011534323
...

Sheet Prices
A1: Internal prices at the best program, and the value of the sale (Theorem 16.1(iii); Proposition 16.3; Worked Example 16.1, Steps 3-4; Figure 16.2(b))
A2: Each lever's cost per point of chance: what $5m more line or 0.05 quarter more delay costs, over the points of chance it buys on the book's paths; paying $5m early: what it earns, beta - beta^3 or beta^2 - beta^3 a dollar, over the points it spends. The chances and the re-optimized packages are the engine's.
A3: The best program | B3: Value | C3: Note
A4: Levers: a $160m line and 2.071 quarters | B4: =Programs!O27 -> 21.37186 | C4: $21.37m
A5: Payouts at 10 percent | B5: =SUM(Programs!K25:K30) -> 369.29945 | C5: 0, 0, 189.9, 160.4, 158.8, 32.7
A6: The year-6 savings forever | B6: =Programs!J30*Programs!D30/R_hurdle -> 691.48056
A7: Value | B7: =B5+B6-B4 -> 1039.4082 | C7: $1,039.41m
A9: The sale (Theorem 16.2(ii)) | B9: Value | C9: Note
A10: No sale: value | B10: =Programs!O125 -> 938.94894 | C10: $938.95m
A11: No sale: levers | B11: =Programs!O123 -> 52.71012 | C11: $52.71m
A12: Sale after the build: value | B12: =Programs!O137 -> 1001.7862 | C12: $1,001.79m
A13: The sale first is worth (the best less no sale) | B13: =B7-B10 -> 100.45922 | C13: $100.5m
A14: its proceeds paid out at the end of year 3, 92 beta^3 | B14: =Sale_G*Beta_y^3 -> 69.120962 | C14: $69.1m
A15: the levers it makes unnecessary | B15: =B11-B4 -> 31.33826 | C15: $31.3m
A16: together | B16: =B14+B15 -> 100.45922 | C16: More than its $92m of proceeds
A17: The sale first beats the sale after the build by | B17: =B7-B12 -> 37.621984 | C17: $37.6m
A18: a year later, 92 (beta^3 - beta^4), plus the levers | B18: =Sale_G*(Beta_y^3-Beta_y^4)+B15 -> 37.621984
A20: The appetite's price | B20: Line (engine) | C20: Delay (engine) | D20: Levers | E20: Value
A21: 0.045 | B21: 165 | C21: 2.1755945 | D21: =Fee_line*B21+Cost_delay*C21 -> 22.354756 | E21: =Programs!O28-D21 -> 1038.4253
A22: 0.055 | B22: 170 | C22: 1.9283346 | D22: =Fee_line*B22+Cost_delay*C22 -> 20.526677 | E22: =Programs!O28-D22 -> 1040.2533
A23: The appetite's price, $m a percentage point | E23: =(E22-E21)/((A22-A21)*100) -> 1.8280788
A25: Volume I's price, the build alone | B25: Line (engine) | C25: Delay (engine) | D25: Levers | E25: Note
A26: 0.045 | B26: 165 | C26: 0.80481304 | D26: =Fee_line*B26+Cost_delay*C26 -> 11.388504
A27: 0.055 | B27: 165 | C27: 0.57893619 | D27: =Fee_line*B27+Cost_delay*C27 -> 9.5814895
A28: Volume I's price for the build alone, $m a point | D28: =(D26-D27)/((A27-A26)*100) -> 1.8070148 | E28: $1.81m (Section 16.1)
A30: Levers and payouts at the best program | B30: Value | C30: Note
A31: Chance of a breach at the best program (engine) | B31: 0.05 | C31: 5.00%
A32: with $5m more line (engine) | B32: 0.04915
A33: with 0.05 quarter more delay (engine) | B33: 0.04825
A34: paying $5m in year 1 instead of year 3 (engine) | B34: 0.06018
A35: paying $5m in year 2 instead of year 3 (engine) | B35: 0.05561
A36: Step: line | B36: 5
A37: Step: delay | B37: 0.05
A38: Step: payout | B38: 5
A39: The line buys a point of chance for | B39: =Fee_line*B36/(100*(B31-B32)) -> 1.7647059 | C39: $1.76m
A40: The delay buys a point of chance for | B40: =Cost_delay*B37/(100*(B31-B33)) -> 2.2857143 | C40: $2.29m
A41: beta - beta^3: a dollar paid in year 1 rather than year 3 earns | B41: =Beta_y-Beta_y^3 -> 0.15777611 | C41: 0.158
A42: points of chance it spends | B42: =100*(B34-B31)/B38 -> 0.2036 | C42: 0.204
A43: Paying in year 1 earns, a point of chance | B43: =B38*B41/(100*(B34-B31)) -> 0.77493177 | C43: $0.77m
A44: beta^2 - beta^3: paid in year 2 rather than year 3 | B44: =Beta_y^2-Beta_y^3 -> 0.07513148
...

Sheet Trigger
A1: Round 3 on a trigger (Theorem 16.2(iii); Worked Example 16.1, Step 5; Figure 16.3(b)) and waiting under irreversibility (Proposition 16.2)
A2: Round 3 runs in year 3 if cash after the year-2 payout is at least the trigger, else in year 4. For each trigger the engine finds the cheapest package keeping the appetite under the rule and the share of paths that run round 3 in year 3; the value is that share times the year-3 program's value, plus the rest times the year-4 program's, less the levers.
A3: Round 3 in year 3: value before the levers | B3: =Programs!O28 -> 1060.78 | C3: Payouts held in years 1-2
A4: Round 3 in year 4: value before the levers | B4: =Programs!O160 -> 1047.632
A6: Trigger | B6: Line (engine) | C6: Delay (engine) | D6: Year 3 on, share of paths (engine) | E6: Breach (engine) | F6: Levers | G6: Value
A7: 380 | B7: 165 | C7: 2.040013 | D7: 0.99723 | E7: 0.05 | F7: =Fee_line*B7+Cost_delay*C7 -> 21.270104 | G7: =D7*$B$3+(1-D7)*$B$4-F7 -> 1039.4735
A8: 390 | B8: 155 | C8: 2.0654673 | D8: 0.99556 | E8: 0.05 | F8: =Fee_line*B8+Cost_delay*C8 -> 21.173739 | G8: =D8*$B$3+(1-D8)*$B$4-F8 -> 1039.5479
A9: 400 | B9: 165 | C9: 2.0146525 | D9: 0.99373 | E9: 0.05 | F9: =Fee_line*B9+Cost_delay*C9 -> 21.06722 | G9: =D9*$B$3+(1-D9)*$B$4-F9 -> 1039.6304
A10: 410 | B10: 155 | C10: 2.0361575 | D10: 0.99012 | E10: 0.05 | F10: =Fee_line*B10+Cost_delay*C10 -> 20.93926 | G10: =D10*$B$3+(1-D10)*$B$4-F10 -> 1039.7109
A11: 420 | B11: 155 | C11: 2.0103069 | D11: 0.98525 | E11: 0.05 | F11: =Fee_line*B11+Cost_delay*C11 -> 20.732455 | G11: =D11*$B$3+(1-D11)*$B$4-F11 -> 1039.8536
A12: 430 | B12: 150 | C12: 2.0005512 | D12: 0.97806 | E12: 0.05 | F12: =Fee_line*B12+Cost_delay*C12 -> 20.50441 | G12: =D12*$B$3+(1-D12)*$B$4-F12 -> 1039.9871
A13: 440 | B13: 150 | C13: 1.9568187 | D13: 0.96761 | E13: 0.05 | F13: =Fee_line*B13+Cost_delay*C13 -> 20.15455 | G13: =D13*$B$3+(1-D13)*$B$4-F13 -> 1040.1996
A14: 450 | B14: 155 | C14: 1.8885492 | D14: 0.95314 | E14: 0.05 | F14: =Fee_line*B14+Cost_delay*C14 -> 19.758393 | G14: =D14*$B$3+(1-D14)*$B$4-F14 -> 1040.4055
A15: 460 | B15: 150 | C15: 1.8541987 | D15: 0.93227 | E15: 0.05 | F15: =Fee_line*B15+Cost_delay*C15 -> 19.333589 | G15: =D15*$B$3+(1-D15)*$B$4-F15 -> 1040.5559
A16: 470 | B16: 155 | C16: 1.7829938 | D16: 0.90719 | E16: 0.05 | F16: =Fee_line*B16+Cost_delay*C16 -> 18.91395 | G16: =D16*$B$3+(1-D16)*$B$4-F16 -> 1040.6458
A17: 480 | B17: 150 | C17: 1.7361731 | D17: 0.87371 | E17: 0.05 | F17: =Fee_line*B17+Cost_delay*C17 -> 18.389385 | G17: =D17*$B$3+(1-D17)*$B$4-F17 -> 1040.7302
A18: 490 | B18: 155 | C18: 1.6423944 | D18: 0.83 | E18: 0.05 | F18: =Fee_line*B18+Cost_delay*C18 -> 17.789155 | G18: =D18*$B$3+(1-D18)*$B$4-F18 -> 1040.7557
... A39: 700 | B39: 150 | C39: 1.254017 | D39: 0.00546 | E39: 0.05 | F39: =Fee_line*B39+Cost_delay*C39 -> 14.532136 | G39: =D39*$B$3+(1-D39)*$B$4-F39 -> 1033.1717
A41: The best trigger's value | B41: =MAX(G7:G39) -> 1040.7557 | C41: $1,040.76m
A42: The best trigger | B42: =INDEX(A7:A39,MATCH(B41,G7:G39,0)) -> 490 | C42: $490m
A43: its line | B43: =INDEX(B7:B39,MATCH(B41,G7:G39,0)) -> 155 | C43: $155m
A44: its delay | B44: =INDEX(C7:C39,MATCH(B41,G7:G39,0)) -> 1.6423944 | C44: 1.642 quarters
A45: its levers | B45: =INDEX(F7:F39,MATCH(B41,G7:G39,0)) -> 17.789155 | C45: $17.79m
A46: share of paths running round 3 in year 3 | B46: =INDEX(D7:D39,MATCH(B41,G7:G39,0)) -> 0.83 | C46: 83.0%
A47: Committed to year 3 (the best program) | B47: =Programs!O29 -> 1039.4082 | C47: $1,039.41m
A48: Committed to year 4 | B48: =Programs!O41 -> 1036.8009 | C48: $1,036.80m
A49: The trigger is worth more than committing to year 3 by | B49: =B41-B47 -> 1.3475432 | C49: $1.35m
A50: and more than committing to year 4 by | B50: =B41-B48 -> 3.9547932
A51: Theorem 16.2(iii): the rule beats both timings (1 = yes) | B51: =IF(B41>MAX(B47,B48),1,0) -> 1 | C51: Strictly: the best timing depends on the reading
A53: Proposition 16.2 on Chapter 7's generic project (Online Appendix 7.B) | B53: Value | C53: Note
A54: Cost c | B54: 100
A55: Worth next year if good | B55: 150 | C55: Equal odds
A56: Worth next year if bad | B56: 60
A57: Chance of good | B57: 0.5
A58: Discount rate a year | B58: 0.1
A59: Cost of waiting, d | B59: 0
A60: Started now, E V - c | B60: =B57*B55+(1-B57)*B56-B54 -> 5 | C60: 5.00
A61: Started next year only if it pays, beta E(V - c)^+ - d | B61: =(B57*MAX(B55-B54,0)+(1-B57)*MAX(B56-B54,0))/(1+B58)-B59 -> 22.727273 | C61: 22.73
A62: Expected loss waiting avoids, E(c - V)^+ | B62: =B57*MAX(B54-B55,0)+(1-B57)*MAX(B54-B56,0) -> 20 | C62: 20
A63: What waiting costs, (1 - beta) E(V - c)^+ + d | B63: =(1-1/(1+B58))*(B57*MAX(B55-B54,0)+(1-B57)*MAX(B56-B54,0))+B59 -> 2.2727273 | C63: 2.27
...

Sheet Certify
A1: Certify: no slack, what a margin buys, the records' corner and the price of ambiguity (Theorem 16.3; Worked Example 16.1, Step 6; Figure 16.3(a))
A2: The program re-designed for a smaller appetite (schedule held, payouts re-optimized: held at every design) keeps the board's 5% along Chapter 11's family up to the closure rate and the spread shown, each edge by bisection on the book's paths (engine). Levers and values are formulas.
A4: Design appetite | B4: Line (engine) | C4: Delay (engine) | D4: Levers | E4: Value | F4: The margin's cost | G4: Breach at the declared law (engine) | H4: Closure rate certified (engine) | I4: At the family's ceiling, 0.40 (engine) | J4: Spread certified (engine) | K4: Breach at the records' corner (engine)
A5: 0.05 | B5: 160 | C5: 2.0714825 | D5: =Fee_line*B5+Cost_delay*C5 -> 21.37186 | E5: =Programs!O28-D5 -> 1039.4082 | F5: =$E$5-E5 -> 0 | G5: 0.05 | H5: 0.100062 | I5: 0 | J5: 50 | K5: 0.13878
A6: 0.045 | B6: 165 | C6: 2.1755945 | D6: =Fee_line*B6+Cost_delay*C6 -> 22.354756 | E6: =Programs!O28-D6 -> 1038.4253 | F6: =$E$5-E6 -> 0.98289616 | G6: 0.045 | H6: 0.19170445 | I6: 0 | J6: 51.049385 | K6: 0.12821
A7: 0.04 | B7: 165 | C7: 2.3108602 | D7: =Fee_line*B7+Cost_delay*C7 -> 23.436882 | E7: =Programs!O28-D7 -> 1037.3431 | F7: =$E$5-E7 -> 2.0650222 | G7: 0.04 | H7: 0.2984342 | I7: 0 | J7: 52.186734 | K7: 0.1185
A8: 0.035 | B8: 165 | C8: 2.4622866 | D8: =Fee_line*B8+Cost_delay*C8 -> 24.648293 | E8: =Programs!O28-D8 -> 1036.1317 | F8: =$E$5-E8 -> 3.2764329 | G8: 0.035 | H8: 0.4 | I8: 1 | J8: 53.487764 | K8: 0.10836
A9: 0.03 | B9: 170 | C9: 2.6153856 | D9: =Fee_line*B9+Cost_delay*C9 -> 26.023085 | E9: =Programs!O28-D9 -> 1034.7569 | F9: =$E$5-E9 -> 4.651225 | G9: 0.03 | H9: 0.4 | I9: 1 | J9: 54.957755 | K9: 0.09688
A10: 0.025 | B10: 170 | C10: 2.8004933 | D10: =Fee_line*B10+Cost_delay*C10 -> 27.503946 | E10: =Programs!O28-D10 -> 1033.2761 | F10: =$E$5-E10 -> 6.1320866 | G10: 0.025 | H10: 0.4 | I10: 1 | J10: 56.544584 | K10: 0.08646
A11: 0.02 | B11: 165 | C11: 3.0433671 | D11: =Fee_line*B11+Cost_delay*C11 -> 29.296937 | E11: =Programs!O28-D11 -> 1031.4831 | F11: =$E$5-E11 -> 7.9250771 | G11: 0.02 | H11: 0.4 | I11: 1 | J11: 58.448311 | K11: 0.07578
A13: The records (Chapter 11) | B13: Value | C13: Note
A14: The treasury: closures in its record | B14: 2 | C14: Twenty years
A15: years of record | B15: 20
A16: the rate's one-sided 95% bound (Garwood) | B16: =CHIINV(0.05,2*B14+2)/(2*B15) -> 0.31478968 | C16: 0.315 a year
A17: The engineering office: innovations in its record | B17: 39 | C17: Forty quarters
A18: the spread's one-sided 95% bound | B18: =Sig_0*SQRT(B17/CHIINV(0.95,B17)) -> 61.599147 | C18: $61.6m
A19: a record twice as long (79 innovations) | B19: =Sig_0*SQRT(79/CHIINV(0.95,79)) -> 57.602817 | C19: $57.6m
A20: The records' corner: the spread as the book prints it | B20: 61.6 | C20: Remark 16.B.1
A22: At the records' corner | B22: Value | C22: Note
A23: The program re-designed there: line (engine) | B23: 200 | C23: $200m
A24: delay (engine) | B24: 3.4395066 | C24: 3.440 quarters
A25: levers | B25: =Fee_line*B23+Cost_delay*B24 -> 33.516053 | C25: $33.52m
A26: value | B26: =Programs!O28-B25 -> 1027.264 | C26: $1,027.26m
A27: The program's price of ambiguity | B27: =B25-Programs!O27 -> 12.144193 | C27: Printed $12.14m (33.516 less 21.372)
A28: Chapter 11's package for the build alone at its corner: line (engine) | B28: 200 | C28: Worked Example 11.1
A29: delay (engine) | B29: 2.2504041
A30: levers | B30: =Fee_line*B28+Cost_delay*B29 -> 24.003233 | C30: $24.00m
A31: Chapter 11's price of ambiguity for the build alone | B31: =B30-Pkg_cost -> 13.562622 | C31: $13.56m
A33: Triggers (Theorem 16.3(iii)) | B33: Value | C33: Note
A34: Re-certify when the closure rate's estimate passes (4% design) | B34: =H7 -> 0.2984342 | C34: 0.30 a year
A35: or the spread's estimate passes (4% design) | B35: =J7 -> 52.186734 | C35: $52.2m
A36: or the twin's monitor alarms (Chapter 15) | B36: monitor
A37: The spread is guarded worst: certified to, against the record's bound | B37: =J7/B18 -> 0.84719897 | C37: Discussion question (3)

Sheet Core
A1: The feedback core's phases (Proposition 16.1; Volume I, Worked Example 14.1; Section 16.2)
A2: Volume I's register: engineering links e, treasury links t, the new Digital-Industrial link h; the spectral radius rho = (h + sqrt(h^2 + 8(e^2 + t^2)))/2, checked below by power iteration on the register plus the identity (the largest eigenvalue of M + I is rho + 1, and the iteration settles fast even when the register is bipartite). The board's rule: deviations halve within a year, rho <= 0.5^(1/4).
A3: The register's ceiling per link | B3: 0.4 | C3: Volume I, Chapter 12
A4: The board's rule, 0.5^(1/4) | B4: =0.5^(1/4) -> 0.84089642 | C4: Half-life at most four quarters
A5: Every existing link trimmed to, sqrt((rule^2 - h rule)/4) with h at the ceiling | B5: =SQRT((B4^2-B3*B4)/4) -> 0.30444549 | C5: 0.304
A6: The new link run light, (rule^2 - 2(e^2 + t^2))/rule | B6: =(B4^2-2*(B3^2+B3^2))/B4 -> 0.079803862 | C6: 0.080
A8: Phase | B8: e | C8: t | D8: h | E8: Radius, closed form | F8: Half-life (quarters) | G8: Stable (1 = yes) | H8: Within the board's rule (1 = yes) | I8: Radius by power iteration
A9: Today | B9: =$B$3 -> 0.4 | C9: =$B$3 -> 0.4 | D9: 0 | E9: =(D9+SQRT(D9^2+8*(B9^2+C9^2)))/2 -> 0.8 | F9: =IF(E9<1,LN(2)/LN(1/E9),"none") -> 3.1062837 | G9: =IF(E9<1,1,0) -> 1 | H9: =IF(E9<=$B$4+0.000000001,1,0) -> 1 | I9: =P52/P51-1 -> 0.8
A10: Phase two: the link added, not repaired | B10: =$B$3 -> 0.4 | C10: =$B$3 -> 0.4 | D10: =$B$3 -> 0.4 | E10: =(D10+SQRT(D10^2+8*(B10^2+C10^2)))/2 -> 1.0246211 | F10: =IF(E10<1,LN(2)/LN(1/E10),"none") -> none | G10: =IF(E10<1,1,0) -> 0 | H10: =IF(E10<=$B$4+0.000000001,1,0) -> 0 | I10: =P90/P89-1 -> 1.0246211
A11: Phase two: the link run light | B11: =$B$3 -> 0.4 | C11: =$B$3 -> 0.4 | D11: =$B$6 -> 0.079803862 | E11: =(D11+SQRT(D11^2+8*(B11^2+C11^2)))/2 -> 0.84089642 | F11: =IF(E11<1,LN(2)/LN(1/E11),"none") -> 4 | G11: =IF(E11<1,1,0) -> 1 | H11: =IF(E11<=$B$4+0.000000001,1,0) -> 1 | I11: =P128/P127-1 -> 0.84089642
A12: Phase two: every link trimmed | B12: =$B$5 -> 0.30444549 | C12: =$B$5 -> 0.30444549 | D12: =$B$3 -> 0.4 | E12: =(D12+SQRT(D12^2+8*(B12^2+C12^2)))/2 -> 0.84089642 | F12: =IF(E12<1,LN(2)/LN(1/E12),"none") -> 4 | G12: =IF(E12<1,1,0) -> 1 | H12: =IF(E12<=$B$4+0.000000001,1,0) -> 1 | I12: =P166/P165-1 -> 0.84089642
A13: Trim first, the link later: after the trim | B13: =$B$5 -> 0.30444549 | C13: =$B$5 -> 0.30444549 | D13: 0 | E13: =(D13+SQRT(D13^2+8*(B13^2+C13^2)))/2 -> 0.60889097 | F13: =IF(E13<1,LN(2)/LN(1/E13),"none") -> 1.3971472 | G13: =IF(E13<1,1,0) -> 1 | H13: =IF(E13<=$B$4+0.000000001,1,0) -> 1 | I13: =P204/P203-1 -> 0.60889097
A15: Proposition 16.1(ii): today and the end state are stable, the phase between is not if the link lands first; (iii) the register is symmetric, so phases each within the rule stay stable however they alternate.
K16: Today: the register (rows receive, columns pass on)
L17: Industrial | M17: Digital | N17: Engineering | O17: Treasury
K18: Industrial | L18: 0 | M18: =$D$9 -> 0 | N18: =$B$9 -> 0.4 | O18: =$C$9 -> 0.4
K19: Digital | L19: =$D$9 -> 0 | M19: 0 | N19: =$B$9 -> 0.4 | O19: =$C$9 -> 0.4
K20: Engineering | L20: =$B$9 -> 0.4 | M20: =$B$9 -> 0.4 | N20: 0 | O20: 0
K21: Treasury | L21: =$C$9 -> 0.4 | M21: =$C$9 -> 0.4 | N21: 0 | O21: 0
K23: Iteration | L23: Industrial | M23: Digital | N23: Engineering | O23: Treasury | P23: Sum
K24: 0 | L24: 1 | M24: 1 | N24: 1 | O24: 1 | P24: =SUM(L24:O24) -> 4
K25: 1 | L25: =SUMPRODUCT($L$18:$O$18,L24:O24)+L24 -> 1.8 | M25: =SUMPRODUCT($L$19:$O$19,L24:O24)+M24 -> 1.8 | N25: =SUMPRODUCT($L$20:$O$20,L24:O24)+N24 -> 1.8 | O25: =SUMPRODUCT($L$21:$O$21,L24:O24)+O24 -> 1.8 | P25: =SUM(L25:O25) -> 7.2
K26: 2 | L26: =SUMPRODUCT($L$18:$O$18,L25:O25)+L25 -> 3.24 | M26: =SUMPRODUCT($L$19:$O$19,L25:O25)+M25 -> 3.24 | N26: =SUMPRODUCT($L$20:$O$20,L25:O25)+N25 -> 3.24 | O26: =SUMPRODUCT($L$21:$O$21,L25:O25)+O25 -> 3.24 | P26: =SUM(L26:O26) -> 12.96
K27: 3 | L27: =SUMPRODUCT($L$18:$O$18,L26:O26)+L26 -> 5.832 | M27: =SUMPRODUCT($L$19:$O$19,L26:O26)+M26 -> 5.832 | N27: =SUMPRODUCT($L$20:$O$20,L26:O26)+N26 -> 5.832 | O27: =SUMPRODUCT($L$21:$O$21,L26:O26)+O26 -> 5.832 | P27: =SUM(L27:O27) -> 23.328
K28: 4 | L28: =SUMPRODUCT($L$18:$O$18,L27:O27)+L27 -> 10.4976 | M28: =SUMPRODUCT($L$19:$O$19,L27:O27)+M27 -> 10.4976 | N28: =SUMPRODUCT($L$20:$O$20,L27:O27)+N27 -> 10.4976 | O28: =SUMPRODUCT($L$21:$O$21,L27:O27)+O27 -> 10.4976 | P28: =SUM(L28:O28) -> 41.9904
K29: 5 | L29: =SUMPRODUCT($L$18:$O$18,L28:O28)+L28 -> 18.89568 | M29: =SUMPRODUCT($L$19:$O$19,L28:O28)+M28 -> 18.89568 | N29: =SUMPRODUCT($L$20:$O$20,L28:O28)+N28 -> 18.89568 | O29: =SUMPRODUCT($L$21:$O$21,L28:O28)+O28 -> 18.89568 | P29: =SUM(L29:O29) -> 75.58272
K30: 6 | L30: =SUMPRODUCT($L$18:$O$18,L29:O29)+L29 -> 34.012224 | M30: =SUMPRODUCT($L$19:$O$19,L29:O29)+M29 -> 34.012224 | N30: =SUMPRODUCT($L$20:$O$20,L29:O29)+N29 -> 34.012224 | O30: =SUMPRODUCT($L$21:$O$21,L29:O29)+O29 -> 34.012224 | P30: =SUM(L30:O30) -> 136.0489
K31: 7 | L31: =SUMPRODUCT($L$18:$O$18,L30:O30)+L30 -> 61.222003 | M31: =SUMPRODUCT($L$19:$O$19,L30:O30)+M30 -> 61.222003 | N31: =SUMPRODUCT($L$20:$O$20,L30:O30)+N30 -> 61.222003 | O31: =SUMPRODUCT($L$21:$O$21,L30:O30)+O30 -> 61.222003 | P31: =SUM(L31:O31) -> 244.88801
K32: 8 | L32: =SUMPRODUCT($L$18:$O$18,L31:O31)+L31 -> 110.19961 | M32: =SUMPRODUCT($L$19:$O$19,L31:O31)+M31 -> 110.19961 | N32: =SUMPRODUCT($L$20:$O$20,L31:O31)+N31 -> 110.19961 | O32: =SUMPRODUCT($L$21:$O$21,L31:O31)+O31 -> 110.19961 | P32: =SUM(L32:O32) -> 440.79842
K33: 9 | L33: =SUMPRODUCT($L$18:$O$18,L32:O32)+L32 -> 198.35929 | M33: =SUMPRODUCT($L$19:$O$19,L32:O32)+M32 -> 198.35929 | N33: =SUMPRODUCT($L$20:$O$20,L32:O32)+N32 -> 198.35929 | O33: =SUMPRODUCT($L$21:$O$21,L32:O32)+O32 -> 198.35929 | P33: =SUM(L33:O33) -> 793.43716
K34: 10 | L34: =SUMPRODUCT($L$18:$O$18,L33:O33)+L33 -> 357.04672 | M34: =SUMPRODUCT($L$19:$O$19,L33:O33)+M33 -> 357.04672 | N34: =SUMPRODUCT($L$20:$O$20,L33:O33)+N33 -> 357.04672 | O34: =SUMPRODUCT($L$21:$O$21,L33:O33)+O33 -> 357.04672 | P34: =SUM(L34:O34) -> 1428.1869
K35: 11 | L35: =SUMPRODUCT($L$18:$O$18,L34:O34)+L34 -> 642.6841 | M35: =SUMPRODUCT($L$19:$O$19,L34:O34)+M34 -> 642.6841 | N35: =SUMPRODUCT($L$20:$O$20,L34:O34)+N34 -> 642.6841 | O35: =SUMPRODUCT($L$21:$O$21,L34:O34)+O34 -> 642.6841 | P35: =SUM(L35:O35) -> 2570.7364
K36: 12 | L36: =SUMPRODUCT($L$18:$O$18,L35:O35)+L35 -> 1156.8314 | M36: =SUMPRODUCT($L$19:$O$19,L35:O35)+M35 -> 1156.8314 | N36: =SUMPRODUCT($L$20:$O$20,L35:O35)+N35 -> 1156.8314 | O36: =SUMPRODUCT($L$21:$O$21,L35:O35)+O35 -> 1156.8314 | P36: =SUM(L36:O36) -> 4627.3255
... K52: 28 | L52: =SUMPRODUCT($L$18:$O$18,L51:O51)+L51 -> 14048506 | M52: =SUMPRODUCT($L$19:$O$19,L51:O51)+M51 -> 14048506 | N52: =SUMPRODUCT($L$20:$O$20,L51:O51)+N51 -> 14048506 | O52: =SUMPRODUCT($L$21:$O$21,L51:O51)+O51 -> 14048506 | P52: =SUM(L52:O52) -> 56194024
K54: Phase two: the link added, not repaired: the register (rows receive, columns pass on)
L55: Industrial | M55: Digital | N55: Engineering | O55: Treasury
K56: Industrial | L56: 0 | M56: =$D$10 -> 0.4 | N56: =$B$10 -> 0.4 | O56: =$C$10 -> 0.4
K57: Digital | L57: =$D$10 -> 0.4 | M57: 0 | N57: =$B$10 -> 0.4 | O57: =$C$10 -> 0.4
K58: Engineering | L58: =$B$10 -> 0.4 | M58: =$B$10 -> 0.4 | N58: 0 | O58: 0
K59: Treasury | L59: =$C$10 -> 0.4 | M59: =$C$10 -> 0.4 | N59: 0 | O59: 0
...

Sheet Table16_3
A1: Table 16.3: programs on one account (Worked Example 16.1)
A2: Levers: the line's fees and the delay's cost; value: payouts at 10 percent plus the year-6 savings forever, less the levers; breach: the chance of liquidity below $350m in some quarter of the build, on the book's 100,000 paths (engine).
A4: Program | B4: Rounds (years) | C4: Line | D4: Delay (q) | E4: Levers | F4: Value | G4: Breach (%)
A5: Pieces as certified | B5: 1-3 | C5: =Pkg_line -> 170 | D5: =Pkg_delay -> 0.66757636 | E5: =Pkg_cost -> 10.440611 | F5: – | G5: 74.331
A6: levers to keep them | B6: 1-3 | C6: 165 | D6: 5.6336263 | E6: =Fee_line*C6+Cost_delay*D6 -> 50.01901 | F6: – | G6: 5
A7: Best program | B7: 1-3 | C7: =Programs!O25 -> 160 | D7: =Programs!O26 -> 2.0714825 | E7: =Programs!O27 -> 21.37186 | F7: =Programs!O29 -> 1039.4082 | G7: 5
A8: Round 3 in year 4 | B8: 1, 2, 4 | C8: =Programs!O37 -> 160 | D8: =Programs!O38 -> 1.4770281 | E8: =Programs!O39 -> 16.616225 | F8: =Programs!O41 -> 1036.8009 | G8: 5
A9: Round 3 on a trigger | B9: 1, 2, 3 or 4 | C9: =Trigger!B43 -> 155 | D9: =Trigger!B44 -> 1.6423944 | E9: =Trigger!B45 -> 17.789155 | F9: =Trigger!B41 -> 1040.7557 | G9: 5
A10: Sale after the build | B10: 1-3 | C10: =Programs!O133 -> 165 | D10: =Programs!O134 -> 5.970015 | E10: =Programs!O135 -> 52.71012 | F10: =Programs!O137 -> 1001.7862 | G10: 5
A11: No sale | B11: 1-3 | C11: =Programs!O121 -> 165 | D11: =Programs!O122 -> 5.970015 | E11: =Programs!O123 -> 52.71012 | F11: =Programs!O125 -> 938.94894 | G11: 5
A12: Designed for 4% | B12: 1-3 | C12: =Certify!B7 -> 165 | D12: =Certify!C7 -> 2.3108602 | E12: =Certify!D7 -> 23.436882 | F12: =Certify!E7 -> 1037.3431 | G12: 4
A13: At the records' corner | B13: 1-3 | C13: =Certify!B23 -> 200 | D13: =Certify!B24 -> 3.4395066 | E13: =Certify!B25 -> 33.516053 | F13: =Certify!B26 -> 1027.264 | G13: 5

Sheet Reference_Values
A1: Checkpoint | B1: Engine value | C1: Meaning (where in the book)
A2: The sale's proceeds with the engineers kept | B2: 92 | C2: $92m (Step 1)
A3: A dollar a year of savings, beta^6 / r | B3: 5.6447393 | C3: $5.645 (Step 1)
A4: Chapter 5's plan alone: value | B4: 1021.9325 | C4: $1,021.93m
A5: Chapter 5's plan alone: payout in year 1 | B5: 85 | C5: 85, 0, 122.5, 122.5, 122.5, 2.5
A6: Chapter 5's plan alone: payout in year 2 | B6: 0 | C6: 85, 0, 122.5, 122.5, 122.5, 2.5
A7: Chapter 5's plan alone: payout in year 3 | B7: 122.5 | C7: 85, 0, 122.5, 122.5, 122.5, 2.5
A8: Chapter 5's plan alone: payout in year 4 | B8: 122.5 | C8: 85, 0, 122.5, 122.5, 122.5, 2.5
A9: Chapter 5's plan alone: payout in year 5 | B9: 122.5 | C9: 85, 0, 122.5, 122.5, 122.5, 2.5
A10: Chapter 5's plan alone: payout in year 6 | B10: 2.5 | C10: 85, 0, 122.5, 122.5, 122.5, 2.5
A11: The draw at its deepest, a point of depth | B11: 6.2 | C11: $6.2m, quarter 8
A12: The plan without the draw, long run | B12: 694.4 | C12: Toward $694m
A13: Volume I's package: levers | B13: 10.440611 | C13: $10.44m
... A121: Core phase 5: power iteration agrees with the closed form | B121: 0 | C121: Volume I's register plus the identity, 28 iterations

Sheet Checks
A1: Checkpoint | B1: Workbook formula value | C1: Engine value | D1: |diff| | E1: Tolerance | F1: Status
A2: The sale's proceeds with the engineers kept | B2: =Sale_G -> 92 | C2: =Reference_Values!B2 -> 92 | D2: =ABS(B2-C2) -> 0 | E2: 0 | F2: =IF(D2<=E2,"PASS","FAIL") -> PASS
A3: A dollar a year of savings, beta^6 / r | B3: =Sav_price -> 5.6447393 | C3: =Reference_Values!B3 -> 5.6447393 | D3: =ABS(B3-C3) -> 0 | E3: 1e-12 | F3: =IF(D3<=E3,"PASS","FAIL") -> PASS
A4: Chapter 5's plan alone: value | B4: =Chapter5!B15 -> 1021.9325 | C4: =Reference_Values!B4 -> 1021.9325 | D4: =ABS(B4-C4) -> 0 | E4: 1e-09 | F4: =IF(D4<=E4,"PASS","FAIL") -> PASS
A5: Chapter 5's plan alone: payout in year 1 | B5: =Chapter5!G6 -> 85 | C5: =Reference_Values!B5 -> 85 | D5: =ABS(B5-C5) -> 0 | E5: 1e-09 | F5: =IF(D5<=E5,"PASS","FAIL") -> PASS
