Workbook

Sheet README
B1: DCT Laboratory — Vol II, Ch 1: Introduction to Enterprise Optimization
B2: Seed 26201 · Companion to DCT_V2_Ch01_Lab.ipynb and AXIOM Lab 2.1 (module AXIOM-01). Money in $ million.
B4: Worked Example 1.1, Can Meridian Sign Volume I's Answer?, with the book's declarations.
B5: Declarations: the inputs of Step 1 and Meridian's state. CanonicalForm: the formulation assistant, which refuses when a term has no declared price or owner.
B6: Gates: the four readiness gates of Theorem 1.5, Volume I's joint check from the plan's path, and the minimal infeasible set when the standby line is removed.
B7: Continuous: the cheapest package along the 5 percent curve, at $8m, $4m and $16m a quarter of delay.
B8: LumpyGrid: the 63 packages of $50 million tranches and whole quarters, the cheapest feasible one and the two roundings. FinerLines: Table 1.3 and the least line for each number of quarters.
B9: Reweight: rescaling changes no rank; reweighting moves the continuous answer, not the lumpy one.
B10: Commitments: the covenant, the capability floor and the joint check added to the appetite. ErrorBars: the sampling error of every breach odds, and fresh paths drawn with the lab's seed.
B11: TwoChannelBudget: Online Appendix Example 1.B.2, a budget of 100 between two channels, and its price.
B12: Breach odds come from the notebook's engine (Volume I's Chapter 8 model on the book's 100,000 paths); everything else is a formula.
B13: Reference_Values and Checks: the engine's numbers and a PASS/FAIL comparison with this workbook's formulas.
... B19: Cross-sheet link: green.

Sheet Declarations
A1: Declarations (Worked Example 1.1, Step 1). Money in $ million.
A3: Quantity | B3: Value | C3: Source
A4: Standby line fees a year, share of the line | B4: 0.01 | C4: About 1 percent a year (treasury)
A5: Length of the digital program (years) | B5: 3 | C5: Three years, twelve quarters
A6: Line fees over the program, per $ of line | B6: =B4*B5 -> 0.03 | C6: A line of l costs 0.03 l
A7: Value of a quarter of delay | B7: 8 | C7: Digital Solutions' contribution (the transformation office)
A8: The board's appetite: largest breach odds | B8: 0.05 | C8: At most a 5 percent chance of breaching the floor
A9: Line tranche | B9: 50 | C9: The bank writes committed lines in tranches of $50 million
A10: Largest line | B10: 400 | C10: The box: 0 <= l <= 400
A11: Longest delay (quarters) | B11: 6 | C11: The box: 0 <= phi <= 6; the program office plans whole quarters
A12: Simulated paths | B12: 100000 | C12: Volume I's Chapter 8 model (seed 8): the engine's breach odds
A13: Liquidity today | B13: 620 | C13: Meridian's liquidity, $620 million
A14: Liquidity index today | B14: 100 | C14: Volume I's plan is written as an index, today = 100
A15: Liquidity per index point | B15: =B13/B14 -> 6.2 | C15: $6.2 million
A16: The board's floor | B16: 350 | C16: Liquidity must stay above $350 million
A17: Cash above the floor | B17: =B13-B16 -> 270 | C17: $270 million
A18: Index the plan relaxes to | B18: 112 | C18: Volume I's digital-program plan
A19: Relaxation rate of the plan, a year | B19: 0.35
A20: Depth of the plan's trough (index points) | B20: 28 | C20: Low point in quarter 7
A21: Years to the trough's deepest point | B21: 2
A22: Depth cut by a quarter of delay | B22: 4 | C22: Phasing: depth 28 - 4 phi
A23: Funding-window closure: mean size | B23: 120 | C23: Closures 0.10 a year, never recovered
A24: Funding-window closure: standard deviation | B24: 50 | C24: Gamma-distributed sizes
A25: A 90th-percentile closure | B25: =GAMMAINV(0.9,(B23/B24)^2,B24^2/B23) -> 186.86698 | C25: The cash buffer of Volume I's joint check
A26: Revenue | B26: 4200
A27: EBITDA margin | B27: 0.118
A28: EBITDA | B28: =B26*B27 -> 495.6
A29: Net leverage today (net debt / EBITDA) | B29: 3.4
A30: Net debt | B30: =B29*B28 -> 1685.04
A31: Covenant: net leverage at most | B31: 4.5 | C31: The loan covenant
A32: Workforce capability | B32: 58 | C32: Stays at 58 through the digital program
A33: Capability floor of the digital build | B33: 55
A34: Strength of each of the core's four two-way links | B34: 0.4 | C34: The feedback core (Volume I)
A35: Tax rate (any rate leaves every package in place) | B35: 0.25 | C35: For the after-tax view
A37: Meridian's state (Volume I, Chapter 3) | B37: Reading
A38: Liquidity ($ million) | B38: 620
A39: Net leverage (net debt / EBITDA) | B39: 3.4
A40: Workforce capability | B40: 58
A41: Technology platform | B41: 41
A42: Operational efficiency | B42: 71
...

Sheet CanonicalForm
A1: Formulate: the canonical form (Equation 1.1; Worked Example 1.1, Step 1; AXIOM Lab 2.1, step 1)
A2: The formulation assistant emits the canonical form only when every term has a declared price or limit and an owner (Proposition 1.1). Delete the delay's owner (E6) or price (F6) and watch it refuse.
A4: Term | B4: Symbol | C4: Unit | D4: Range | E4: Owner | F4: Price or limit | G4: Declared?
A5: Standby line | B5: l | C5: $ million | D5: ="0 to "&Line_max -> 0 to 400 | E5: treasury | F5: =Fee -> 0.03 | G5: =IF(AND(LEN(E5)>0,LEN(F5)>0),"yes","no") -> yes
A6: Delay of the build | B6: phi | C6: quarters | D6: ="0 to "&Delay_max -> 0 to 6 | E6: transformation office | F6: =Vq -> 8 | G6: =IF(AND(LEN(E6)>0,LEN(F6)>0),"yes","no") -> yes
A7: The board's appetite | B7: P | C7: breach odds | D7: ="at most "&TEXT(Appetite,"0%") -> at most 5% | E7: the board | F7: =Appetite -> 0.05 | G7: =IF(AND(LEN(E7)>0,LEN(F7)>0),"yes","no") -> yes
A8: State map | B8: x = f(l, phi) | E8: Volume I, Chapter 8 | F8: 100,000 paths | G8: yes
A10: The assistant's verdict | B10: =IF(COUNTIF(G5:G7,"no")>0,"Refuses: a term has no declared price or owner (Proposition 1.1)","Emits the canonical form below") -> Emits the canonical form below
B12: =IF(LEFT($B$10,5)="Emits","maximize -("&F5&" l + "&F6&" phi) the package's cost in $ million, with its sign reversed","") -> maximize -(0.03 l + 8 phi) the package's cost in $ million, with its sign reversed
B13: =IF(LEFT($B$10,5)="Emits","over 0 <= l <= "&Line_max&" ($ million, "&E5&"), 0 <= phi <= "&Delay_max&" (quarters, "&E6&")","") -> over 0 <= l <= 400 ($ million, treasury), 0 <= phi <= 6 (quarters, transformation office)
B14: =IF(LEFT($B$10,5)="Emits","subject to x = f(l, phi): Volume I's Chapter 8 liquidity model, "&TEXT(Paths_N,"#,##0")&" paths","") -> subject to x = f(l, phi): Volume I's Chapter 8 liquidity model, 100,000 paths
B15: =IF(LEFT($B$10,5)="Emits"," P(liquidity below "&Floor_liq&" in some quarter) - "&F7&" <= 0 ("&E7&")","") -> P(liquidity below 350 in some quarter) - 0.05 <= 0 (the board)

Sheet Gates
A1: Run the gates (Theorem 1.5; Worked Example 1.1, Step 2; AXIOM Lab 2.1, step 2)
A3: Volume I's package: line ($ million) | B3: =Continuous!H6 -> 170
A4: Delay (quarters): the least that meets the appetite with that line | B4: =Continuous!H7 -> 0.66757636
A5: Depth of the trough with that delay | B5: =Depth0-Depth_q*B4 -> 25.329695
A7: Gate | B7: Test | C7: Value | D7: Limit | E7: Verdict
A8: (R1) declaration completeness | B8: Every term declared, with a price and an owner (CanonicalForm) | E8: =IF(LEFT(CanonicalForm!B10,5)="Emits","pass","FAIL") -> pass
A9: (R2) unified consistency | B9: Draw + closure buffer within the cash above the floor ($ million) | C9: =B16 -> 138.50134 | D9: =Pool -> 270 | E9: =IF(C9<=D9,"pass","FAIL") -> pass
A10: (R3) analytical panel | B10: Feedback core's spectral radius within the board's rule: halve within a year | C10: =SQRT(8*(Link^2+Link^2))/2 -> 0.8 | D10: =0.5^(1/4) -> 0.84089642 | E10: =IF(C10<=D10,"pass","FAIL") -> pass
A11: (R4) feasibility over the horizon | B11: Breach odds within the appetite (engine) | C11: =Continuous!H17 -> 0.05 | D11: =Appetite -> 0.05 | E11: =IF(AND(C11<=D11,C12<=D12),"pass","FAIL") -> pass
B12: Leverage with the line fully drawn, within the covenant | C12: =(Net_debt+B3)/Ebitda -> 3.7430186 | D12: =Covenant -> 4.5
A13: Four two-way links of strength e, and no Digital-Industrial link, give a spectral radius of sqrt(8(e^2 + e^2))/2 = 2e = 0.80 (Section 1.1).
A15: (R2) Volume I's joint check with the package
A16: Claims: deepest draw + closure buffer | B16: =B17+B18 -> 138.50134
A17: Deepest draw on the cash above the floor | B17: =Liq0-MIN(E32:E44) -> 121.63437
A18: Cash buffer for a 90th-percentile closure, net of the line | B18: =MAX(P90-B3,0) -> 16.866976
A20: The line removed from the decision inventory
A21: Claims: the draw and a full closure buffer | B21: =B17+P90 -> 308.50134
A22: Verdict | B22: =IF(B21<=Pool,"(R2) passes","(R2) fails") -> (R2) fails
A23: Minimal infeasible set: drop one commitment | B23: Owner | C23: Claims left | D23: Room | E23: The rest can hold?
A24: Program draw | B24: the transformation office | C24: =P90 -> 186.86698 | D24: =Pool -> 270 | E24: =IF(ISNUMBER(D24),IF(C24<=D24,"yes","no"),"yes") -> yes
A25: Closure buffer | B25: treasury | C25: =B17 -> 121.63437 | D25: =Pool -> 270 | E25: =IF(ISNUMBER(D25),IF(C25<=D25,"yes","no"),"yes") -> yes
A26: Floor | B26: the board | C26: =B21 -> 308.50134 | D26: no limit | E26: =IF(ISNUMBER(D26),IF(C26<=D26,"yes","no"),"yes") -> yes
A27: Named: every commitment whose removal lets the rest hold | C27: =IF(COUNTIF(E24:E26,"yes")=3,"program draw, closure buffer, floor","check") -> program draw, closure buffer, floor
A28: Volume I's declaration before its levers: claims | B28: =Liq0-MIN(F32:F44)+P90 -> 324.91659
A29: Short of the room by | B29: =B28-Pool -> 54.916594
A31: Quarter | B31: Years | C31: Plan without the trough | D31: Trough per point of depth | E31: Plan with the package's delay | F31: Plan as first declared (depth 28)
A32: 0 | B32: =A32/4 -> 0 | C32: =Per_point*(Plan_target-(Plan_target-Index0)*EXP(-Plan_rate*B32)) -> 620 | D32: =Per_point*(B32/Trough_tau)*EXP(1-B32/Trough_tau) -> 0 | E32: =C32-$B$5*D32 -> 620 | F32: =C32-Depth0*D32 -> 620
A33: 1 | B33: =A33/4 -> 0.25 | C33: =Per_point*(Plan_target-(Plan_target-Index0)*EXP(-Plan_rate*B33)) -> 626.23332 | D33: =Per_point*(B33/Trough_tau)*EXP(1-B33/Trough_tau) -> 1.8591284 | E33: =C33-$B$5*D33 -> 579.14216 | F33: =C33-Depth0*D33 -> 574.17772
A34: 2 | B34: =A34/4 -> 0.5 | C34: =Per_point*(Plan_target-(Plan_target-Index0)*EXP(-Plan_rate*B34)) -> 631.9444 | D34: =Per_point*(B34/Trough_tau)*EXP(1-B34/Trough_tau) -> 3.28135 | E34: =C34-$B$5*D34 -> 548.8288 | F34: =C34-Depth0*D34 -> 540.0666
A35: 3 | B35: =A35/4 -> 0.75 | C35: =Per_point*(Plan_target-(Plan_target-Index0)*EXP(-Plan_rate*B35)) -> 637.177 | D35: =Per_point*(B35/Trough_tau)*EXP(1-B35/Trough_tau) -> 4.3436719 | E35: =C35-$B$5*D35 -> 527.15312 | F35: =C35-Depth0*D35 -> 515.55419
A36: 4 | B36: =A36/4 -> 1 | C36: =Per_point*(Plan_target-(Plan_target-Index0)*EXP(-Plan_rate*B36)) -> 641.97121 | D36: =Per_point*(B36/Trough_tau)*EXP(1-B36/Trough_tau) -> 5.1110359 | E36: =C36-$B$5*D36 -> 512.51023 | F36: =C36-Depth0*D36 -> 498.8622
A37: 5 | B37: =A37/4 -> 1.25 | C37: =Per_point*(Plan_target-(Plan_target-Index0)*EXP(-Plan_rate*B37)) -> 646.36375 | D37: =Per_point*(B37/Trough_tau)*EXP(1-B37/Trough_tau) -> 5.6380917 | E37: =C37-$B$5*D37 -> 503.55261 | F37: =C37-Depth0*D37 -> 488.49718
A38: 6 | B38: =A38/4 -> 1.5 | C38: =Per_point*(Plan_target-(Plan_target-Index0)*EXP(-Plan_rate*B38)) -> 650.38828 | D38: =Per_point*(B38/Trough_tau)*EXP(1-B38/Trough_tau) -> 5.9707182 | E38: =C38-$B$5*D38 -> 499.15181 | F38: =C38-Depth0*D38 -> 483.20817
A39: 7 | B39: =A39/4 -> 1.75 | C39: =Per_point*(Plan_target-(Plan_target-Index0)*EXP(-Plan_rate*B39)) -> 654.07563 | D39: =Per_point*(B39/Trough_tau)*EXP(1-B39/Trough_tau) -> 6.1473304 | E39: =C39-$B$5*D39 -> 498.36563 | F39: =C39-Depth0*D39 -> 481.95038
A40: 8 | B40: =A40/4 -> 2 | C40: =Per_point*(Plan_target-(Plan_target-Index0)*EXP(-Plan_rate*B40)) -> 657.45405 | D40: =Per_point*(B40/Trough_tau)*EXP(1-B40/Trough_tau) -> 6.2 | E40: =C40-$B$5*D40 -> 500.40995 | F40: =C40-Depth0*D40 -> 483.85405
A41: 9 | B41: =A41/4 -> 2.25 | C41: =Per_point*(Plan_target-(Plan_target-Index0)*EXP(-Plan_rate*B41)) -> 660.54943 | D41: =Per_point*(B41/Trough_tau)*EXP(1-B41/Trough_tau) -> 6.1554159 | E41: =C41-$B$5*D41 -> 504.63462 | F41: =C41-Depth0*D41 -> 488.19778
A42: 10 | B42: =A42/4 -> 2.5 | C42: =Per_point*(Plan_target-(Plan_target-Index0)*EXP(-Plan_rate*B42)) -> 663.38547 | D42: =Per_point*(B42/Trough_tau)*EXP(1-B42/Trough_tau) -> 6.0357061 | E42: =C42-$B$5*D42 -> 510.50287 | F42: =C42-Depth0*D42 -> 494.3857
A43: 11 | B43: =A43/4 -> 2.75 | C43: =Per_point*(Plan_target-(Plan_target-Index0)*EXP(-Plan_rate*B43)) -> 665.9839 | D43: =Per_point*(B43/Trough_tau)*EXP(1-B43/Trough_tau) -> 5.8591411 | E43: =C43-$B$5*D43 -> 517.57364 | F43: =C43-Depth0*D43 -> 501.92795
A44: 12 | B44: =A44/4 -> 3 | C44: =Per_point*(Plan_target-(Plan_target-Index0)*EXP(-Plan_rate*B44)) -> 668.36463 | D44: =Per_point*(B44/Trough_tau)*EXP(1-B44/Trough_tau) -> 5.6407351 | E44: =C44-$B$5*D44 -> 525.48653 | F44: =C44-Depth0*D44 -> 510.42405

Sheet Continuous
A1: Solve with continuous levers (Theorem 1.2; Worked Example 1.1, Step 3)
A2: Column B is the engine's least delay that meets the appetite with each line on Volume I's $5 million grid: the 5 percent curve of Figure 1.4. The formulas price every point of the curve and find the cheapest.
B3: value of a quarter: | C3: =Vq -> 8 | D3: 4 | E3: 16
A4: Line ($ million) | B4: Least delay meeting the appetite (engine) | C4: Cost | D4: Cost | E4: Cost | G4: Best package | H4: At the declared value | I4: At $4m a quarter | J4: At $16m a quarter
A5: 0 | B5: 5.0946732 | C5: =Fee*$A5+C$3*$B5 -> 40.757385 | D5: =Fee*$A5+D$3*$B5 -> 20.378693 | E5: =Fee*$A5+E$3*$B5 -> 81.514771 | G5: Cheapest cost on the curve | H5: =MIN(C5:C85) -> 10.440611 | I5: =MIN(D5:D85) -> 7.5246248 | J5: =MIN(E5:E85) -> 15.512875
A6: =A5+5 -> 5 | B6: 4.8306695 | C6: =Fee*$A6+C$3*$B6 -> 38.795356 | D6: =Fee*$A6+D$3*$B6 -> 19.472678 | E6: =Fee*$A6+E$3*$B6 -> 77.440712 | G6: Its line ($ million) | H6: =INDEX($A$5:$A$85,MATCH(H5,C5:C85,0)) -> 170 | I6: =INDEX($A$5:$A$85,MATCH(I5,D5:D85,0)) -> 140 | J6: =INDEX($A$5:$A$85,MATCH(J5,E5:E85,0)) -> 195
A7: =A6+5 -> 10 | B7: 4.579809 | C7: =Fee*$A7+C$3*$B7 -> 36.938472 | D7: =Fee*$A7+D$3*$B7 -> 18.619236 | E7: =Fee*$A7+E$3*$B7 -> 73.576945 | G7: Its delay (quarters) | H7: =INDEX($B$5:$B$85,MATCH(H5,C5:C85,0)) -> 0.66757636 | I7: =INDEX($B$5:$B$85,MATCH(I5,D5:D85,0)) -> 0.8311562 | J7: =INDEX($B$5:$B$85,MATCH(J5,E5:E85,0)) -> 0.60392968
A8: =A7+5 -> 15 | B8: 4.3286508 | C8: =Fee*$A8+C$3*$B8 -> 35.079207 | D8: =Fee*$A8+D$3*$B8 -> 17.764603 | E8: =Fee*$A8+E$3*$B8 -> 69.708413 | G8: Its delay in months | H8: =3*H7 -> 2.0027291 | I8: =3*I7 -> 2.4934686 | J8: =3*J7 -> 1.8117891
A9: =A8+5 -> 20 | B9: 4.0686784 | C9: =Fee*$A9+C$3*$B9 -> 33.149427 | D9: =Fee*$A9+D$3*$B9 -> 16.874714 | E9: =Fee*$A9+E$3*$B9 -> 65.698854 | G9: Line fees | H9: =Fee*H6 -> 5.1 | I9: =Fee*I6 -> 4.2 | J9: =Fee*J6 -> 5.85
A10: =A9+5 -> 25 | B10: 3.8169899 | C10: =Fee*$A10+C$3*$B10 -> 31.28592 | D10: =Fee*$A10+D$3*$B10 -> 16.01796 | E10: =Fee*$A10+E$3*$B10 -> 61.821839 | G10: Cost of the delay | H10: =C3*H7 -> 5.3406109 | I10: =D3*I7 -> 3.3246248 | J10: =E3*J7 -> 9.6628749
A11: =A10+5 -> 30 | B11: 3.5787587 | C11: =Fee*$A11+C$3*$B11 -> 29.530069 | D11: =Fee*$A11+D$3*$B11 -> 15.215035 | E11: =Fee*$A11+E$3*$B11 -> 58.160139
A12: =A11+5 -> 35 | B12: 3.3470376 | C12: =Fee*$A12+C$3*$B12 -> 27.826301 | D12: =Fee*$A12+D$3*$B12 -> 14.43815 | E12: =Fee*$A12+E$3*$B12 -> 54.602602 | G12: Lines within $0.5 million of the best: from | H12: =_xlfn.MINIFS(A5:A85,C5:C85,"<="&(H5+0.5)) -> 140
A13: =A12+5 -> 40 | B13: 3.1066048 | C13: =Fee*$A13+C$3*$B13 -> 26.052838 | D13: =Fee*$A13+D$3*$B13 -> 13.626419 | E13: =Fee*$A13+E$3*$B13 -> 50.905677 | G13: to | H13: =_xlfn.MAXIFS(A5:A85,C5:C85,"<="&(H5+0.5)) -> 205
A14: =A13+5 -> 45 | B14: 2.9025087 | C14: =Fee*$A14+C$3*$B14 -> 24.57007 | D14: =Fee*$A14+D$3*$B14 -> 12.960035 | E14: =Fee*$A14+E$3*$B14 -> 47.79014 | G14: Delay alone: quarters (no line) | H14: =INDEX(B5:B85,MATCH(0,A5:A85,0)) -> 5.0946732
A15: =A14+5 -> 50 | B15: 2.7009762 | C15: =Fee*$A15+C$3*$B15 -> 23.107809 | D15: =Fee*$A15+D$3*$B15 -> 12.303905 | E15: =Fee*$A15+E$3*$B15 -> 44.715619 | G15: Delay alone: cost | H15: =Vq*H14 -> 40.757385
A16: =A15+5 -> 55 | B16: 2.5121212 | C16: =Fee*$A16+C$3*$B16 -> 21.74697 | D16: =Fee*$A16+D$3*$B16 -> 11.698485 | E16: =Fee*$A16+E$3*$B16 -> 41.84394 | G16: The line alone: lowest breach odds (engine, a $400m line) | H16: 0.08404
A17: =A16+5 -> 60 | B17: 2.3303361 | C17: =Fee*$A17+C$3*$B17 -> 20.442689 | D17: =Fee*$A17+D$3*$B17 -> 11.121344 | E17: =Fee*$A17+E$3*$B17 -> 39.085378 | G17: Breach odds of the best package (engine) | H17: 0.05
A18: =A17+5 -> 65 | B18: 2.1535969 | C18: =Fee*$A18+C$3*$B18 -> 19.178775 | D18: =Fee*$A18+D$3*$B18 -> 10.564388 | E18: =Fee*$A18+E$3*$B18 -> 36.407551 | G18: Reweighting moves the line by ($ million, $4m to $16m a quarter) | H18: =J6-I6 -> 55
A19: =A18+5 -> 70 | B19: 1.997326 | C19: =Fee*$A19+C$3*$B19 -> 18.078608 | D19: =Fee*$A19+D$3*$B19 -> 10.089304 | E19: =Fee*$A19+E$3*$B19 -> 34.057216
A20: =A19+5 -> 75 | B20: 1.8511258 | C20: =Fee*$A20+C$3*$B20 -> 17.059006 | D20: =Fee*$A20+D$3*$B20 -> 9.6545031 | E20: =Fee*$A20+E$3*$B20 -> 31.868012
A21: =A20+5 -> 80 | B21: 1.7187291 | C21: =Fee*$A21+C$3*$B21 -> 16.149832 | D21: =Fee*$A21+D$3*$B21 -> 9.2749162 | E21: =Fee*$A21+E$3*$B21 -> 29.899665
A22: =A21+5 -> 85 | B22: 1.5973554 | C22: =Fee*$A22+C$3*$B22 -> 15.328844 | D22: =Fee*$A22+D$3*$B22 -> 8.9394218 | E22: =Fee*$A22+E$3*$B22 -> 28.107687
A23: =A22+5 -> 90 | B23: 1.4819733 | C23: =Fee*$A23+C$3*$B23 -> 14.555787 | D23: =Fee*$A23+D$3*$B23 -> 8.6278933 | E23: =Fee*$A23+E$3*$B23 -> 26.411573
A24: =A23+5 -> 95 | B24: 1.3778721 | C24: =Fee*$A24+C$3*$B24 -> 13.872977 | D24: =Fee*$A24+D$3*$B24 -> 8.3614883 | E24: =Fee*$A24+E$3*$B24 -> 24.895953
A25: =A24+5 -> 100 | B25: 1.2871114 | C25: =Fee*$A25+C$3*$B25 -> 13.296891 | D25: =Fee*$A25+D$3*$B25 -> 8.1484455 | E25: =Fee*$A25+E$3*$B25 -> 23.593782
A26: =A25+5 -> 105 | B26: 1.2117094 | C26: =Fee*$A26+C$3*$B26 -> 12.843675 | D26: =Fee*$A26+D$3*$B26 -> 7.9968375 | E26: =Fee*$A26+E$3*$B26 -> 22.53735
A27: =A26+5 -> 110 | B27: 1.1254172 | C27: =Fee*$A27+C$3*$B27 -> 12.303337 | D27: =Fee*$A27+D$3*$B27 -> 7.8016687 | E27: =Fee*$A27+E$3*$B27 -> 21.306675
A28: =A27+5 -> 115 | B28: 1.0644007 | C28: =Fee*$A28+C$3*$B28 -> 11.965205 | D28: =Fee*$A28+D$3*$B28 -> 7.7076027 | E28: =Fee*$A28+E$3*$B28 -> 20.480411
A29: =A28+5 -> 120 | B29: 1.0037717 | C29: =Fee*$A29+C$3*$B29 -> 11.630174 | D29: =Fee*$A29+D$3*$B29 -> 7.6150869 | E29: =Fee*$A29+E$3*$B29 -> 19.660347
A30: =A29+5 -> 125 | B30: 0.95008855 | C30: =Fee*$A30+C$3*$B30 -> 11.350708 | D30: =Fee*$A30+D$3*$B30 -> 7.5503542 | E30: =Fee*$A30+E$3*$B30 -> 18.951417
... A85: =A84+5 -> 400 | B85: 0.55460771 | C85: =Fee*$A85+C$3*$B85 -> 16.436862 | D85: =Fee*$A85+D$3*$B85 -> 14.218431 | E85: =Fee*$A85+E$3*$B85 -> 20.873723

Sheet LumpyGrid
A1: Make the levers lumpy: 63 packages (Theorem 1.3; Worked Example 1.1, Step 4; AXIOM Lab 2.1, step 3)
A2: Every package of $50 million tranches (0 to 400) and whole quarters (0 to 6), with the engine's breach odds on the book's paths. Cost, feasibility, the cheapest feasible package and the roundings are formulas.
A4: Package | B4: Line ($ million) | C4: Delay (quarters) | D4: Breach odds (engine) | E4: Cost ($ million) | F4: Meets the appetite (1 = yes) | G4: Cheapest feasible (1 = yes) | I4: Summary | J4: Value
A5: 1 | B5: =Tranche*INT((A5-1)/7) -> 0 | C5: =MOD(A5-1,7) -> 0 | D5: 0.24622 | E5: =Fee*B5+Vq*C5 -> 0 | F5: =IF(D5<=Appetite,1,0) -> 0 | G5: =IF(AND(F5=1,ABS(E5-$J$7)<0.000000001),1,0) -> 0 | I5: Packages | J5: =COUNT(B5:B67) -> 63
A6: 2 | B6: =Tranche*INT((A6-1)/7) -> 0 | C6: =MOD(A6-1,7) -> 1 | D6: 0.17731 | E6: =Fee*B6+Vq*C6 -> 8 | F6: =IF(D6<=Appetite,1,0) -> 0 | G6: =IF(AND(F6=1,ABS(E6-$J$7)<0.000000001),1,0) -> 0 | I6: Packages that meet the appetite | J6: =SUM(F5:F67) -> 46
A7: 3 | B7: =Tranche*INT((A7-1)/7) -> 0 | C7: =MOD(A7-1,7) -> 2 | D7: 0.13068 | E7: =Fee*B7+Vq*C7 -> 16 | F7: =IF(D7<=Appetite,1,0) -> 0 | G7: =IF(AND(F7=1,ABS(E7-$J$7)<0.000000001),1,0) -> 0 | I7: Cheapest that meets it: cost | J7: =_xlfn.MINIFS(E5:E67,F5:F67,1) -> 12.5
A8: 4 | B8: =Tranche*INT((A8-1)/7) -> 0 | C8: =MOD(A8-1,7) -> 3 | D8: 0.09687 | E8: =Fee*B8+Vq*C8 -> 24 | F8: =IF(D8<=Appetite,1,0) -> 0 | G8: =IF(AND(F8=1,ABS(E8-$J$7)<0.000000001),1,0) -> 0 | I8: its line ($ million) | J8: =INDEX(B5:B67,MATCH(1,G5:G67,0)) -> 150
A9: 5 | B9: =Tranche*INT((A9-1)/7) -> 0 | C9: =MOD(A9-1,7) -> 4 | D9: 0.07118 | E9: =Fee*B9+Vq*C9 -> 32 | F9: =IF(D9<=Appetite,1,0) -> 0 | G9: =IF(AND(F9=1,ABS(E9-$J$7)<0.000000001),1,0) -> 0 | I9: its delay (quarters) | J9: =INDEX(C5:C67,MATCH(1,G5:G67,0)) -> 1
A10: 6 | B10: =Tranche*INT((A10-1)/7) -> 0 | C10: =MOD(A10-1,7) -> 5 | D10: 0.05167 | E10: =Fee*B10+Vq*C10 -> 40 | F10: =IF(D10<=Appetite,1,0) -> 0 | G10: =IF(AND(F10=1,ABS(E10-$J$7)<0.000000001),1,0) -> 0 | I10: its breach odds | J10: =INDEX(D5:D67,MATCH(1,G5:G67,0)) -> 0.04003
A11: 7 | B11: =Tranche*INT((A11-1)/7) -> 0 | C11: =MOD(A11-1,7) -> 6 | D11: 0.03668 | E11: =Fee*B11+Vq*C11 -> 48 | F11: =IF(D11<=Appetite,1,0) -> 1 | G11: =IF(AND(F11=1,ABS(E11-$J$7)<0.000000001),1,0) -> 0
A12: 8 | B12: =Tranche*INT((A12-1)/7) -> 50 | C12: =MOD(A12-1,7) -> 0 | D12: 0.18073 | E12: =Fee*B12+Vq*C12 -> 1.5 | F12: =IF(D12<=Appetite,1,0) -> 0 | G12: =IF(AND(F12=1,ABS(E12-$J$7)<0.000000001),1,0) -> 0 | I12: Continuous best: line | J12: =Continuous!H6 -> 170
A13: 9 | B13: =Tranche*INT((A13-1)/7) -> 50 | C13: =MOD(A13-1,7) -> 1 | D13: 0.11089 | E13: =Fee*B13+Vq*C13 -> 9.5 | F13: =IF(D13<=Appetite,1,0) -> 0 | G13: =IF(AND(F13=1,ABS(E13-$J$7)<0.000000001),1,0) -> 0 | I13: Continuous best: delay | J13: =Continuous!H7 -> 0.66757636
A14: 10 | B14: =Tranche*INT((A14-1)/7) -> 50 | C14: =MOD(A14-1,7) -> 2 | D14: 0.06903 | E14: =Fee*B14+Vq*C14 -> 17.5 | F14: =IF(D14<=Appetite,1,0) -> 0 | G14: =IF(AND(F14=1,ABS(E14-$J$7)<0.000000001),1,0) -> 0 | I14: Continuous best: cost | J14: =Continuous!H5 -> 10.440611
A15: 11 | B15: =Tranche*INT((A15-1)/7) -> 50 | C15: =MOD(A15-1,7) -> 3 | D15: 0.04392 | E15: =Fee*B15+Vq*C15 -> 25.5 | F15: =IF(D15<=Appetite,1,0) -> 1 | G15: =IF(AND(F15=1,ABS(E15-$J$7)<0.000000001),1,0) -> 0
A16: 12 | B16: =Tranche*INT((A16-1)/7) -> 50 | C16: =MOD(A16-1,7) -> 4 | D16: 0.02801 | E16: =Fee*B16+Vq*C16 -> 33.5 | F16: =IF(D16<=Appetite,1,0) -> 1 | G16: =IF(AND(F16=1,ABS(E16-$J$7)<0.000000001),1,0) -> 0 | I16: Rounded down: line | J16: =INT(J12/Tranche)*Tranche -> 150
A17: 13 | B17: =Tranche*INT((A17-1)/7) -> 50 | C17: =MOD(A17-1,7) -> 5 | D17: 0.01772 | E17: =Fee*B17+Vq*C17 -> 41.5 | F17: =IF(D17<=Appetite,1,0) -> 1 | G17: =IF(AND(F17=1,ABS(E17-$J$7)<0.000000001),1,0) -> 0 | I17: Rounded down: delay | J17: =INT(J13) -> 0
A18: 14 | B18: =Tranche*INT((A18-1)/7) -> 50 | C18: =MOD(A18-1,7) -> 6 | D18: 0.01098 | E18: =Fee*B18+Vq*C18 -> 49.5 | F18: =IF(D18<=Appetite,1,0) -> 1 | G18: =IF(AND(F18=1,ABS(E18-$J$7)<0.000000001),1,0) -> 0 | I18: Rounded down: breach odds | J18: =SUMIFS(D5:D67,B5:B67,J16,C5:C67,J17) -> 0.09587
A19: 15 | B19: =Tranche*INT((A19-1)/7) -> 100 | C19: =MOD(A19-1,7) -> 0 | D19: 0.12374 | E19: =Fee*B19+Vq*C19 -> 3 | F19: =IF(D19<=Appetite,1,0) -> 0 | G19: =IF(AND(F19=1,ABS(E19-$J$7)<0.000000001),1,0) -> 0 | I19: Rounded down: cost | J19: =Fee*J16+Vq*J17 -> 4.5
A20: 16 | B20: =Tranche*INT((A20-1)/7) -> 100 | C20: =MOD(A20-1,7) -> 1 | D20: 0.06165 | E20: =Fee*B20+Vq*C20 -> 11 | F20: =IF(D20<=Appetite,1,0) -> 0 | G20: =IF(AND(F20=1,ABS(E20-$J$7)<0.000000001),1,0) -> 0 | I20: Rounded down: meets the appetite? | J20: =IF(J18<=Appetite,"yes","no: it fails") -> no: it fails
A21: 17 | B21: =Tranche*INT((A21-1)/7) -> 100 | C21: =MOD(A21-1,7) -> 2 | D21: 0.03003 | E21: =Fee*B21+Vq*C21 -> 19 | F21: =IF(D21<=Appetite,1,0) -> 1 | G21: =IF(AND(F21=1,ABS(E21-$J$7)<0.000000001),1,0) -> 0
A22: 18 | B22: =Tranche*INT((A22-1)/7) -> 100 | C22: =MOD(A22-1,7) -> 3 | D22: 0.01517 | E22: =Fee*B22+Vq*C22 -> 27 | F22: =IF(D22<=Appetite,1,0) -> 1 | G22: =IF(AND(F22=1,ABS(E22-$J$7)<0.000000001),1,0) -> 0 | I22: Rounded up: line | J22: =-INT(-J12/Tranche)*Tranche -> 200
A23: 19 | B23: =Tranche*INT((A23-1)/7) -> 100 | C23: =MOD(A23-1,7) -> 4 | D23: 0.00778 | E23: =Fee*B23+Vq*C23 -> 35 | F23: =IF(D23<=Appetite,1,0) -> 1 | G23: =IF(AND(F23=1,ABS(E23-$J$7)<0.000000001),1,0) -> 0 | I23: Rounded up: delay | J23: =-INT(-J13) -> 1
A24: 20 | B24: =Tranche*INT((A24-1)/7) -> 100 | C24: =MOD(A24-1,7) -> 5 | D24: 0.00421 | E24: =Fee*B24+Vq*C24 -> 43 | F24: =IF(D24<=Appetite,1,0) -> 1 | G24: =IF(AND(F24=1,ABS(E24-$J$7)<0.000000001),1,0) -> 0 | I24: Rounded up: breach odds | J24: =SUMIFS(D5:D67,B5:B67,J22,C5:C67,J23) -> 0.03386
A25: 21 | B25: =Tranche*INT((A25-1)/7) -> 100 | C25: =MOD(A25-1,7) -> 6 | D25: 0.00233 | E25: =Fee*B25+Vq*C25 -> 51 | F25: =IF(D25<=Appetite,1,0) -> 1 | G25: =IF(AND(F25=1,ABS(E25-$J$7)<0.000000001),1,0) -> 0 | I25: Rounded up: cost | J25: =Fee*J22+Vq*J23 -> 14
A26: 22 | B26: =Tranche*INT((A26-1)/7) -> 150 | C26: =MOD(A26-1,7) -> 0 | D26: 0.09587 | E26: =Fee*B26+Vq*C26 -> 4.5 | F26: =IF(D26<=Appetite,1,0) -> 0 | G26: =IF(AND(F26=1,ABS(E26-$J$7)<0.000000001),1,0) -> 0 | I26: Rounded up: meets the appetite? | J26: =IF(J24<=Appetite,"yes","no: it fails") -> yes
A27: 23 | B27: =Tranche*INT((A27-1)/7) -> 150 | C27: =MOD(A27-1,7) -> 1 | D27: 0.04003 | E27: =Fee*B27+Vq*C27 -> 12.5 | F27: =IF(D27<=Appetite,1,0) -> 1 | G27: =IF(AND(F27=1,ABS(E27-$J$7)<0.000000001),1,0) -> 1
A28: 24 | B28: =Tranche*INT((A28-1)/7) -> 150 | C28: =MOD(A28-1,7) -> 2 | D28: 0.01548 | E28: =Fee*B28+Vq*C28 -> 20.5 | F28: =IF(D28<=Appetite,1,0) -> 1 | G28: =IF(AND(F28=1,ABS(E28-$J$7)<0.000000001),1,0) -> 0 | I28: The lumps cost (cheapest lumpy less the continuous floor) | J28: =J7-J14 -> 2.0593891
A29: 25 | B29: =Tranche*INT((A29-1)/7) -> 150 | C29: =MOD(A29-1,7) -> 3 | D29: 0.00574 | E29: =Fee*B29+Vq*C29 -> 28.5 | F29: =IF(D29<=Appetite,1,0) -> 1 | G29: =IF(AND(F29=1,ABS(E29-$J$7)<0.000000001),1,0) -> 0 | I29: as a share of the continuous cost | J29: =J28/J14 -> 0.19724795
A30: 26 | B30: =Tranche*INT((A30-1)/7) -> 150 | C30: =MOD(A30-1,7) -> 4 | D30: 0.00236 | E30: =Fee*B30+Vq*C30 -> 36.5 | F30: =IF(D30<=Appetite,1,0) -> 1 | G30: =IF(AND(F30=1,ABS(E30-$J$7)<0.000000001),1,0) -> 0
A31: 27 | B31: =Tranche*INT((A31-1)/7) -> 150 | C31: =MOD(A31-1,7) -> 5 | D31: 0.00096 | E31: =Fee*B31+Vq*C31 -> 44.5 | F31: =IF(D31<=Appetite,1,0) -> 1 | G31: =IF(AND(F31=1,ABS(E31-$J$7)<0.000000001),1,0) -> 0 | I31: Convexity: is the midpoint of the best and the rounded-up package a package? | J31: =IF(MOD((J8+J22)/2,Tranche)=0,"yes","no: the lattice is not convex") -> no: the lattice is not convex
A32: 28 | B32: =Tranche*INT((A32-1)/7) -> 150 | C32: =MOD(A32-1,7) -> 6 | D32: 0.00038 | E32: =Fee*B32+Vq*C32 -> 52.5 | F32: =IF(D32<=Appetite,1,0) -> 1 | G32: =IF(AND(F32=1,ABS(E32-$J$7)<0.000000001),1,0) -> 0 | I32: Forty yes-or-no choices: combinations | J32: =2^40 -> 1099511627776
A33: 29 | B33: =Tranche*INT((A33-1)/7) -> 200 | C33: =MOD(A33-1,7) -> 0 | D33: 0.08674 | E33: =Fee*B33+Vq*C33 -> 6 | F33: =IF(D33<=Appetite,1,0) -> 0 | G33: =IF(AND(F33=1,ABS(E33-$J$7)<0.000000001),1,0) -> 0
A34: 30 | B34: =Tranche*INT((A34-1)/7) -> 200 | C34: =MOD(A34-1,7) -> 1 | D34: 0.03386 | E34: =Fee*B34+Vq*C34 -> 14 | F34: =IF(D34<=Appetite,1,0) -> 1 | G34: =IF(AND(F34=1,ABS(E34-$J$7)<0.000000001),1,0) -> 0
A35: 31 | B35: =Tranche*INT((A35-1)/7) -> 200 | C35: =MOD(A35-1,7) -> 2 | D35: 0.01165 | E35: =Fee*B35+Vq*C35 -> 22 | F35: =IF(D35<=Appetite,1,0) -> 1 | G35: =IF(AND(F35=1,ABS(E35-$J$7)<0.000000001),1,0) -> 0
A36: 32 | B36: =Tranche*INT((A36-1)/7) -> 200 | C36: =MOD(A36-1,7) -> 3 | D36: 0.00348 | E36: =Fee*B36+Vq*C36 -> 30 | F36: =IF(D36<=Appetite,1,0) -> 1 | G36: =IF(AND(F36=1,ABS(E36-$J$7)<0.000000001),1,0) -> 0
A37: 33 | B37: =Tranche*INT((A37-1)/7) -> 200 | C37: =MOD(A37-1,7) -> 4 | D37: 0.00105 | E37: =Fee*B37+Vq*C37 -> 38 | F37: =IF(D37<=Appetite,1,0) -> 1 | G37: =IF(AND(F37=1,ABS(E37-$J$7)<0.000000001),1,0) -> 0
A38: 34 | B38: =Tranche*INT((A38-1)/7) -> 200 | C38: =MOD(A38-1,7) -> 5 | D38: 0.00031 | E38: =Fee*B38+Vq*C38 -> 46 | F38: =IF(D38<=Appetite,1,0) -> 1 | G38: =IF(AND(F38=1,ABS(E38-$J$7)<0.000000001),1,0) -> 0
A39: 35 | B39: =Tranche*INT((A39-1)/7) -> 200 | C39: =MOD(A39-1,7) -> 6 | D39: 7e-05 | E39: =Fee*B39+Vq*C39 -> 54 | F39: =IF(D39<=Appetite,1,0) -> 1 | G39: =IF(AND(F39=1,ABS(E39-$J$7)<0.000000001),1,0) -> 0
A40: 36 | B40: =Tranche*INT((A40-1)/7) -> 250 | C40: =MOD(A40-1,7) -> 0 | D40: 0.08461 | E40: =Fee*B40+Vq*C40 -> 7.5 | F40: =IF(D40<=Appetite,1,0) -> 0 | G40: =IF(AND(F40=1,ABS(E40-$J$7)<0.000000001),1,0) -> 0
A41: 37 | B41: =Tranche*INT((A41-1)/7) -> 250 | C41: =MOD(A41-1,7) -> 1 | D41: 0.03241 | E41: =Fee*B41+Vq*C41 -> 15.5 | F41: =IF(D41<=Appetite,1,0) -> 1 | G41: =IF(AND(F41=1,ABS(E41-$J$7)<0.000000001),1,0) -> 0
...

Sheet FinerLines
A1: The least line for each whole number of quarters (Online Appendix 1.B.4) and Table 1.3
A2: Lines in $1 million steps and in $10 million tranches: the engine's least line meeting the appetite (and its odds). $50 million tranches: formulas on LumpyGrid. Costs at the declared prices.
A4: Delay (quarters) | B4: Line, $1m steps (engine) | C4: Odds (engine) | D4: Cost | E4: Line, $10m tranches (engine) | F4: Odds (engine) | G4: Cost | H4: Line, $50m tranches | I4: Odds | J4: Cost
A5: 0 | B5: none | D5: =IF(ISNUMBER(B5),Fee*B5+Vq*A5,"") | E5: none | G5: =IF(ISNUMBER(E5),Fee*E5+Vq*A5,"") | H5: =IF(COUNTIFS(LumpyGrid!$C$5:$C$67,A5,LumpyGrid!$F$5:$F$67,1)=0,"none",_xlfn.MINIFS(LumpyGrid!$B$5:$B$67,LumpyGrid!$C$5:$C$67,A5,LumpyGrid!$F$5:$F$67,1)) -> none | I5: =IF(ISNUMBER(H5),SUMIFS(LumpyGrid!$D$5:$D$67,LumpyGrid!$B$5:$B$67,H5,LumpyGrid!$C$5:$C$67,A5),"") | J5: =IF(ISNUMBER(H5),Fee*H5+Vq*A5,"")
A6: 1 | B6: 121 | C6: 0.04968 | D6: =IF(ISNUMBER(B6),Fee*B6+Vq*A6,"") -> 11.63 | E6: 130 | F6: 0.0463 | G6: =IF(ISNUMBER(E6),Fee*E6+Vq*A6,"") -> 11.9 | H6: =IF(COUNTIFS(LumpyGrid!$C$5:$C$67,A6,LumpyGrid!$F$5:$F$67,1)=0,"none",_xlfn.MINIFS(LumpyGrid!$B$5:$B$67,LumpyGrid!$C$5:$C$67,A6,LumpyGrid!$F$5:$F$67,1)) -> 150 | I6: =IF(ISNUMBER(H6),SUMIFS(LumpyGrid!$D$5:$D$67,LumpyGrid!$B$5:$B$67,H6,LumpyGrid!$C$5:$C$67,A6),"") -> 0.04003 | J6: =IF(ISNUMBER(H6),Fee*H6+Vq*A6,"") -> 12.5
A7: 2 | B7: 70 | C7: 0.04989 | D7: =IF(ISNUMBER(B7),Fee*B7+Vq*A7,"") -> 18.1 | E7: 70 | F7: 0.04989 | G7: =IF(ISNUMBER(E7),Fee*E7+Vq*A7,"") -> 18.1 | H7: =IF(COUNTIFS(LumpyGrid!$C$5:$C$67,A7,LumpyGrid!$F$5:$F$67,1)=0,"none",_xlfn.MINIFS(LumpyGrid!$B$5:$B$67,LumpyGrid!$C$5:$C$67,A7,LumpyGrid!$F$5:$F$67,1)) -> 100 | I7: =IF(ISNUMBER(H7),SUMIFS(LumpyGrid!$D$5:$D$67,LumpyGrid!$B$5:$B$67,H7,LumpyGrid!$C$5:$C$67,A7),"") -> 0.03003 | J7: =IF(ISNUMBER(H7),Fee*H7+Vq*A7,"") -> 19
A8: 3 | B8: 43 | C8: 0.04982 | D8: =IF(ISNUMBER(B8),Fee*B8+Vq*A8,"") -> 25.29 | E8: 50 | F8: 0.04392 | G8: =IF(ISNUMBER(E8),Fee*E8+Vq*A8,"") -> 25.5 | H8: =IF(COUNTIFS(LumpyGrid!$C$5:$C$67,A8,LumpyGrid!$F$5:$F$67,1)=0,"none",_xlfn.MINIFS(LumpyGrid!$B$5:$B$67,LumpyGrid!$C$5:$C$67,A8,LumpyGrid!$F$5:$F$67,1)) -> 50 | I8: =IF(ISNUMBER(H8),SUMIFS(LumpyGrid!$D$5:$D$67,LumpyGrid!$B$5:$B$67,H8,LumpyGrid!$C$5:$C$67,A8),"") -> 0.04392 | J8: =IF(ISNUMBER(H8),Fee*H8+Vq*A8,"") -> 25.5
A9: 4 | B9: 22 | C9: 0.04946 | D9: =IF(ISNUMBER(B9),Fee*B9+Vq*A9,"") -> 32.66 | E9: 30 | F9: 0.04262 | G9: =IF(ISNUMBER(E9),Fee*E9+Vq*A9,"") -> 32.9 | H9: =IF(COUNTIFS(LumpyGrid!$C$5:$C$67,A9,LumpyGrid!$F$5:$F$67,1)=0,"none",_xlfn.MINIFS(LumpyGrid!$B$5:$B$67,LumpyGrid!$C$5:$C$67,A9,LumpyGrid!$F$5:$F$67,1)) -> 50 | I9: =IF(ISNUMBER(H9),SUMIFS(LumpyGrid!$D$5:$D$67,LumpyGrid!$B$5:$B$67,H9,LumpyGrid!$C$5:$C$67,A9),"") -> 0.02801 | J9: =IF(ISNUMBER(H9),Fee*H9+Vq*A9,"") -> 33.5
A10: 5 | B10: 2 | C10: 0.04988 | D10: =IF(ISNUMBER(B10),Fee*B10+Vq*A10,"") -> 40.06 | E10: 10 | F10: 0.04311 | G10: =IF(ISNUMBER(E10),Fee*E10+Vq*A10,"") -> 40.3 | H10: =IF(COUNTIFS(LumpyGrid!$C$5:$C$67,A10,LumpyGrid!$F$5:$F$67,1)=0,"none",_xlfn.MINIFS(LumpyGrid!$B$5:$B$67,LumpyGrid!$C$5:$C$67,A10,LumpyGrid!$F$5:$F$67,1)) -> 50 | I10: =IF(ISNUMBER(H10),SUMIFS(LumpyGrid!$D$5:$D$67,LumpyGrid!$B$5:$B$67,H10,LumpyGrid!$C$5:$C$67,A10),"") -> 0.01772 | J10: =IF(ISNUMBER(H10),Fee*H10+Vq*A10,"") -> 41.5
A11: 6 | B11: 0 | C11: 0.03668 | D11: =IF(ISNUMBER(B11),Fee*B11+Vq*A11,"") -> 48 | E11: 0 | F11: 0.03668 | G11: =IF(ISNUMBER(E11),Fee*E11+Vq*A11,"") -> 48 | H11: =IF(COUNTIFS(LumpyGrid!$C$5:$C$67,A11,LumpyGrid!$F$5:$F$67,1)=0,"none",_xlfn.MINIFS(LumpyGrid!$B$5:$B$67,LumpyGrid!$C$5:$C$67,A11,LumpyGrid!$F$5:$F$67,1)) -> 0 | I11: =IF(ISNUMBER(H11),SUMIFS(LumpyGrid!$D$5:$D$67,LumpyGrid!$B$5:$B$67,H11,LumpyGrid!$C$5:$C$67,A11),"") -> 0.03668 | J11: =IF(ISNUMBER(H11),Fee*H11+Vq*A11,"") -> 48
A13: Table 1.3: package | B13: Line ($ million) | C13: Delay (quarters) | D13: Breach odds | E13: Cost ($ million)
A14: Continuous levers (Volume I) | B14: =Continuous!H6 -> 170 | C14: =Continuous!H7 -> 0.66757636 | D14: =Continuous!H17 -> 0.05 | E14: =Continuous!H5 -> 10.440611
A15: Whole quarters, line to the $1 million | B15: =INDEX(B5:B11,MATCH(MIN(D5:D11),D5:D11,0)) -> 121 | C15: =INDEX(A5:A11,MATCH(MIN(D5:D11),D5:D11,0)) -> 1 | D15: =INDEX(C5:C11,MATCH(MIN(D5:D11),D5:D11,0)) -> 0.04968 | E15: =MIN(D5:D11) -> 11.63
A16: Whole quarters, $10 million tranches | B16: =INDEX(E5:E11,MATCH(MIN(G5:G11),G5:G11,0)) -> 130 | C16: =INDEX(A5:A11,MATCH(MIN(G5:G11),G5:G11,0)) -> 1 | D16: =INDEX(F5:F11,MATCH(MIN(G5:G11),G5:G11,0)) -> 0.0463 | E16: =MIN(G5:G11) -> 11.9
A17: Whole quarters, $50 million tranches | B17: =INDEX(H5:H11,MATCH(MIN(J5:J11),J5:J11,0)) -> 150 | C17: =INDEX(A5:A11,MATCH(MIN(J5:J11),J5:J11,0)) -> 1 | D17: =INDEX(I5:I11,MATCH(MIN(J5:J11),J5:J11,0)) -> 0.04003 | E17: =MIN(J5:J11) -> 12.5
A18: Rounded down (fails the appetite) | B18: =LumpyGrid!J16 -> 150 | C18: =LumpyGrid!J17 -> 0 | D18: =LumpyGrid!J18 -> 0.09587 | E18: =LumpyGrid!J19 -> 4.5
A19: Rounded up | B19: =LumpyGrid!J22 -> 200 | C19: =LumpyGrid!J23 -> 1 | D19: =LumpyGrid!J24 -> 0.03386 | E19: =LumpyGrid!J25 -> 14
A21: The lumps cost: $50m tranches and whole quarters against the continuous floor | E21: =E17-E14 -> 2.0593891
A22: of which whole quarters | E22: =E15-E14 -> 1.1893891
A23: and then $50 million tranches | E23: =E17-E15 -> 0.87
A24: $10 million tranches would save | E24: =E17-E16 -> 0.6

Sheet Reweight
A1: Rescale, then reweight (Theorem 1.4; Worked Example 1.1, Step 5; AXIOM Lab 2.1, step 4)
A2: Rescaling (after tax, or in thousands of dollars) is a strictly increasing transformation: no package changes rank. Reweighting the value of a quarter of delay is a new objective.
M3: a quarter of delay worth: | N3: =Vq -> 8 | O3: 4 | P3: 16
A4: Line | B4: Delay | C4: Cost | D4: After tax | E4: In $ thousands | F4: Rank | G4: Rank after tax | H4: Rank in thousands | J4: Reweighting | K4: Value | L4: Quarters | M4: Line fees of the cheapest lumpy package | N4: Cost at the declared value | O4: Cost at $4m | P4: Cost at $16m | Q4: Fees saved per extra quarter
A5: =LumpyGrid!B5 -> 0 | B5: =LumpyGrid!C5 -> 0 | C5: =LumpyGrid!E5 -> 0 | D5: =(1-Tax)*C5 -> 0 | E5: =1000*C5 -> 0 | F5: =RANK(C5,$C$5:$C$67,1) -> 1 | G5: =RANK(D5,$D$5:$D$67,1) -> 1 | H5: =RANK(E5,$E$5:$E$67,1) -> 1 | J5: Packages whose rank changes after tax or in thousands | K5: =SUMPRODUCT(--(F5:F67<>G5:G67))+SUMPRODUCT(--(F5:F67<>H5:H67)) -> 0
A6: =LumpyGrid!B6 -> 0 | B6: =LumpyGrid!C6 -> 1 | C6: =LumpyGrid!E6 -> 8 | D6: =(1-Tax)*C6 -> 6 | E6: =1000*C6 -> 8000 | F6: =RANK(C6,$C$5:$C$67,1) -> 7 | G6: =RANK(D6,$D$5:$D$67,1) -> 7 | H6: =RANK(E6,$E$5:$E$67,1) -> 7 | L6: 1 | M6: =Fee*FinerLines!H6 -> 4.5 | N6: =M6+N$3*L6 -> 12.5 | O6: =M6+O$3*L6 -> 8.5 | P6: =M6+P$3*L6 -> 20.5
A7: =LumpyGrid!B7 -> 0 | B7: =LumpyGrid!C7 -> 2 | C7: =LumpyGrid!E7 -> 16 | D7: =(1-Tax)*C7 -> 12 | E7: =1000*C7 -> 16000 | F7: =RANK(C7,$C$5:$C$67,1) -> 16 | G7: =RANK(D7,$D$5:$D$67,1) -> 16 | H7: =RANK(E7,$E$5:$E$67,1) -> 16 | J7: Continuous best at $4m a quarter: line | K7: =Continuous!I6 -> 140 | L7: 2 | M7: =Fee*FinerLines!H7 -> 3 | N7: =M7+N$3*L7 -> 19 | O7: =M7+O$3*L7 -> 11 | P7: =M7+P$3*L7 -> 35 | Q7: =($M$6-M7)/(L7-1) -> 1.5
A8: =LumpyGrid!B8 -> 0 | B8: =LumpyGrid!C8 -> 3 | C8: =LumpyGrid!E8 -> 24 | D8: =(1-Tax)*C8 -> 18 | E8: =1000*C8 -> 24000 | F8: =RANK(C8,$C$5:$C$67,1) -> 25 | G8: =RANK(D8,$D$5:$D$67,1) -> 25 | H8: =RANK(E8,$E$5:$E$67,1) -> 25 | J8: delay (quarters) | K8: =Continuous!I7 -> 0.8311562 | L8: 3 | M8: =Fee*FinerLines!H8 -> 1.5 | N8: =M8+N$3*L8 -> 25.5 | O8: =M8+O$3*L8 -> 13.5 | P8: =M8+P$3*L8 -> 49.5 | Q8: =($M$6-M8)/(L8-1) -> 1.5
A9: =LumpyGrid!B9 -> 0 | B9: =LumpyGrid!C9 -> 4 | C9: =LumpyGrid!E9 -> 32 | D9: =(1-Tax)*C9 -> 24 | E9: =1000*C9 -> 32000 | F9: =RANK(C9,$C$5:$C$67,1) -> 34 | G9: =RANK(D9,$D$5:$D$67,1) -> 34 | H9: =RANK(E9,$E$5:$E$67,1) -> 34 | J9: cost | K9: =Continuous!I5 -> 7.5246248 | L9: 4 | M9: =Fee*FinerLines!H9 -> 1.5 | N9: =M9+N$3*L9 -> 33.5 | O9: =M9+O$3*L9 -> 17.5 | P9: =M9+P$3*L9 -> 65.5 | Q9: =($M$6-M9)/(L9-1) -> 1
A10: =LumpyGrid!B10 -> 0 | B10: =LumpyGrid!C10 -> 5 | C10: =LumpyGrid!E10 -> 40 | D10: =(1-Tax)*C10 -> 30 | E10: =1000*C10 -> 40000 | F10: =RANK(C10,$C$5:$C$67,1) -> 43 | G10: =RANK(D10,$D$5:$D$67,1) -> 43 | H10: =RANK(E10,$E$5:$E$67,1) -> 43 | J10: Continuous best at $16m a quarter: line | K10: =Continuous!J6 -> 195 | L10: 5 | M10: =Fee*FinerLines!H10 -> 1.5 | N10: =M10+N$3*L10 -> 41.5 | O10: =M10+O$3*L10 -> 21.5 | P10: =M10+P$3*L10 -> 81.5 | Q10: =($M$6-M10)/(L10-1) -> 0.75
A11: =LumpyGrid!B11 -> 0 | B11: =LumpyGrid!C11 -> 6 | C11: =LumpyGrid!E11 -> 48 | D11: =(1-Tax)*C11 -> 36 | E11: =1000*C11 -> 48000 | F11: =RANK(C11,$C$5:$C$67,1) -> 52 | G11: =RANK(D11,$D$5:$D$67,1) -> 52 | H11: =RANK(E11,$E$5:$E$67,1) -> 52 | J11: delay (quarters) | K11: =Continuous!J7 -> 0.60392968 | L11: 6 | M11: =Fee*FinerLines!H11 -> 0 | N11: =M11+N$3*L11 -> 48 | O11: =M11+O$3*L11 -> 24 | P11: =M11+P$3*L11 -> 96 | Q11: =($M$6-M11)/(L11-1) -> 0.9
A12: =LumpyGrid!B12 -> 50 | B12: =LumpyGrid!C12 -> 0 | C12: =LumpyGrid!E12 -> 1.5 | D12: =(1-Tax)*C12 -> 1.125 | E12: =1000*C12 -> 1500 | F12: =RANK(C12,$C$5:$C$67,1) -> 2 | G12: =RANK(D12,$D$5:$D$67,1) -> 2 | H12: =RANK(E12,$E$5:$E$67,1) -> 2 | J12: cost | K12: =Continuous!J5 -> 15.512875
A13: =LumpyGrid!B13 -> 50 | B13: =LumpyGrid!C13 -> 1 | C13: =LumpyGrid!E13 -> 9.5 | D13: =(1-Tax)*C13 -> 7.125 | E13: =1000*C13 -> 9500 | F13: =RANK(C13,$C$5:$C$67,1) -> 9 | G13: =RANK(D13,$D$5:$D$67,1) -> 9 | H13: =RANK(E13,$E$5:$E$67,1) -> 9 | J13: The board's number moves the line by | K13: =K10-K7 -> 55 | L13: Cheapest | N13: At the declared value | O13: At $4m | P13: At $16m
A14: =LumpyGrid!B14 -> 50 | B14: =LumpyGrid!C14 -> 2 | C14: =LumpyGrid!E14 -> 17.5 | D14: =(1-Tax)*C14 -> 13.125 | E14: =1000*C14 -> 17500 | F14: =RANK(C14,$C$5:$C$67,1) -> 18 | G14: =RANK(D14,$D$5:$D$67,1) -> 18 | H14: =RANK(E14,$E$5:$E$67,1) -> 18 | L14: cost | N14: =MIN(N6:N11) -> 12.5 | O14: =MIN(O6:O11) -> 8.5 | P14: =MIN(P6:P11) -> 20.5
A15: =LumpyGrid!B15 -> 50 | B15: =LumpyGrid!C15 -> 3 | C15: =LumpyGrid!E15 -> 25.5 | D15: =(1-Tax)*C15 -> 19.125 | E15: =1000*C15 -> 25500 | F15: =RANK(C15,$C$5:$C$67,1) -> 27 | G15: =RANK(D15,$D$5:$D$67,1) -> 27 | H15: =RANK(E15,$E$5:$E$67,1) -> 27 | J15: One quarter is the cheapest lumpy delay when v exceeds | K15: =MAX(Q7:Q11) -> 1.5 | L15: quarters | N15: =INDEX($L$6:$L$11,MATCH(N14,N6:N11,0)) -> 1 | O15: =INDEX($L$6:$L$11,MATCH(O14,O6:O11,0)) -> 1 | P15: =INDEX($L$6:$L$11,MATCH(P14,P6:P11,0)) -> 1
A16: =LumpyGrid!B16 -> 50 | B16: =LumpyGrid!C16 -> 4 | C16: =LumpyGrid!E16 -> 33.5 | D16: =(1-Tax)*C16 -> 25.125 | E16: =1000*C16 -> 33500 | F16: =RANK(C16,$C$5:$C$67,1) -> 36 | G16: =RANK(D16,$D$5:$D$67,1) -> 36 | H16: =RANK(E16,$E$5:$E$67,1) -> 36
A17: =LumpyGrid!B17 -> 50 | B17: =LumpyGrid!C17 -> 5 | C17: =LumpyGrid!E17 -> 41.5 | D17: =(1-Tax)*C17 -> 31.125 | E17: =1000*C17 -> 41500 | F17: =RANK(C17,$C$5:$C$67,1) -> 45 | G17: =RANK(D17,$D$5:$D$67,1) -> 45 | H17: =RANK(E17,$E$5:$E$67,1) -> 45 | J17: At $16m: nearest package to the continuous best, line | K17: =ROUND(K10/Tranche,0)*Tranche -> 200
A18: =LumpyGrid!B18 -> 50 | B18: =LumpyGrid!C18 -> 6 | C18: =LumpyGrid!E18 -> 49.5 | D18: =(1-Tax)*C18 -> 37.125 | E18: =1000*C18 -> 49500 | F18: =RANK(C18,$C$5:$C$67,1) -> 54 | G18: =RANK(D18,$D$5:$D$67,1) -> 54 | H18: =RANK(E18,$E$5:$E$67,1) -> 54 | J18: its delay | K18: =ROUND(K11,0) -> 1
A19: =LumpyGrid!B19 -> 100 | B19: =LumpyGrid!C19 -> 0 | C19: =LumpyGrid!E19 -> 3 | D19: =(1-Tax)*C19 -> 2.25 | E19: =1000*C19 -> 3000 | F19: =RANK(C19,$C$5:$C$67,1) -> 3 | G19: =RANK(D19,$D$5:$D$67,1) -> 3 | H19: =RANK(E19,$E$5:$E$67,1) -> 3 | J19: its cost at $16m | K19: =Fee*K17+P3*K18 -> 22
A20: =LumpyGrid!B20 -> 100 | B20: =LumpyGrid!C20 -> 1 | C20: =LumpyGrid!E20 -> 11 | D20: =(1-Tax)*C20 -> 8.25 | E20: =1000*C20 -> 11000 | F20: =RANK(C20,$C$5:$C$67,1) -> 11 | G20: =RANK(D20,$D$5:$D$67,1) -> 11 | H20: =RANK(E20,$E$5:$E$67,1) -> 11 | J20: The signed package at $16m | K20: =Fee*LumpyGrid!J8+P3*LumpyGrid!J9 -> 20.5
A21: =LumpyGrid!B21 -> 100 | B21: =LumpyGrid!C21 -> 2 | C21: =LumpyGrid!E21 -> 19 | D21: =(1-Tax)*C21 -> 14.25 | E21: =1000*C21 -> 19000 | F21: =RANK(C21,$C$5:$C$67,1) -> 20 | G21: =RANK(D21,$D$5:$D$67,1) -> 20 | H21: =RANK(E21,$E$5:$E$67,1) -> 20 | J21: The signed package at $4m | K21: =Fee*LumpyGrid!J8+O3*LumpyGrid!J9 -> 8.5
A22: =LumpyGrid!B22 -> 100 | B22: =LumpyGrid!C22 -> 3 | C22: =LumpyGrid!E22 -> 27 | D22: =(1-Tax)*C22 -> 20.25 | E22: =1000*C22 -> 27000 | F22: =RANK(C22,$C$5:$C$67,1) -> 29 | G22: =RANK(D22,$D$5:$D$67,1) -> 29 | H22: =RANK(E22,$E$5:$E$67,1) -> 29
A23: =LumpyGrid!B23 -> 100 | B23: =LumpyGrid!C23 -> 4 | C23: =LumpyGrid!E23 -> 35 | D23: =(1-Tax)*C23 -> 26.25 | E23: =1000*C23 -> 35000 | F23: =RANK(C23,$C$5:$C$67,1) -> 38 | G23: =RANK(D23,$D$5:$D$67,1) -> 38 | H23: =RANK(E23,$E$5:$E$67,1) -> 38
A24: =LumpyGrid!B24 -> 100 | B24: =LumpyGrid!C24 -> 5 | C24: =LumpyGrid!E24 -> 43 | D24: =(1-Tax)*C24 -> 32.25 | E24: =1000*C24 -> 43000 | F24: =RANK(C24,$C$5:$C$67,1) -> 47 | G24: =RANK(D24,$D$5:$D$67,1) -> 47 | H24: =RANK(E24,$E$5:$E$67,1) -> 47
A25: =LumpyGrid!B25 -> 100 | B25: =LumpyGrid!C25 -> 6 | C25: =LumpyGrid!E25 -> 51 | D25: =(1-Tax)*C25 -> 38.25 | E25: =1000*C25 -> 51000 | F25: =RANK(C25,$C$5:$C$67,1) -> 56 | G25: =RANK(D25,$D$5:$D$67,1) -> 56 | H25: =RANK(E25,$E$5:$E$67,1) -> 56
A26: =LumpyGrid!B26 -> 150 | B26: =LumpyGrid!C26 -> 0 | C26: =LumpyGrid!E26 -> 4.5 | D26: =(1-Tax)*C26 -> 3.375 | E26: =1000*C26 -> 4500 | F26: =RANK(C26,$C$5:$C$67,1) -> 4 | G26: =RANK(D26,$D$5:$D$67,1) -> 4 | H26: =RANK(E26,$E$5:$E$67,1) -> 4
A27: =LumpyGrid!B27 -> 150 | B27: =LumpyGrid!C27 -> 1 | C27: =LumpyGrid!E27 -> 12.5 | D27: =(1-Tax)*C27 -> 9.375 | E27: =1000*C27 -> 12500 | F27: =RANK(C27,$C$5:$C$67,1) -> 13 | G27: =RANK(D27,$D$5:$D$67,1) -> 13 | H27: =RANK(E27,$E$5:$E$67,1) -> 13
A28: =LumpyGrid!B28 -> 150 | B28: =LumpyGrid!C28 -> 2 | C28: =LumpyGrid!E28 -> 20.5 | D28: =(1-Tax)*C28 -> 15.375 | E28: =1000*C28 -> 20500 | F28: =RANK(C28,$C$5:$C$67,1) -> 22 | G28: =RANK(D28,$D$5:$D$67,1) -> 22 | H28: =RANK(E28,$E$5:$E$67,1) -> 22
A29: =LumpyGrid!B29 -> 150 | B29: =LumpyGrid!C29 -> 3 | C29: =LumpyGrid!E29 -> 28.5 | D29: =(1-Tax)*C29 -> 21.375 | E29: =1000*C29 -> 28500 | F29: =RANK(C29,$C$5:$C$67,1) -> 31 | G29: =RANK(D29,$D$5:$D$67,1) -> 31 | H29: =RANK(E29,$E$5:$E$67,1) -> 31
A30: =LumpyGrid!B30 -> 150 | B30: =LumpyGrid!C30 -> 4 | C30: =LumpyGrid!E30 -> 36.5 | D30: =(1-Tax)*C30 -> 27.375 | E30: =1000*C30 -> 36500 | F30: =RANK(C30,$C$5:$C$67,1) -> 40 | G30: =RANK(D30,$D$5:$D$67,1) -> 40 | H30: =RANK(E30,$E$5:$E$67,1) -> 40
A31: =LumpyGrid!B31 -> 150 | B31: =LumpyGrid!C31 -> 5 | C31: =LumpyGrid!E31 -> 44.5 | D31: =(1-Tax)*C31 -> 33.375 | E31: =1000*C31 -> 44500 | F31: =RANK(C31,$C$5:$C$67,1) -> 49 | G31: =RANK(D31,$D$5:$D$67,1) -> 49 | H31: =RANK(E31,$E$5:$E$67,1) -> 49
A32: =LumpyGrid!B32 -> 150 | B32: =LumpyGrid!C32 -> 6 | C32: =LumpyGrid!E32 -> 52.5 | D32: =(1-Tax)*C32 -> 39.375 | E32: =1000*C32 -> 52500 | F32: =RANK(C32,$C$5:$C$67,1) -> 58 | G32: =RANK(D32,$D$5:$D$67,1) -> 58 | H32: =RANK(E32,$E$5:$E$67,1) -> 58
A33: =LumpyGrid!B33 -> 200 | B33: =LumpyGrid!C33 -> 0 | C33: =LumpyGrid!E33 -> 6 | D33: =(1-Tax)*C33 -> 4.5 | E33: =1000*C33 -> 6000 | F33: =RANK(C33,$C$5:$C$67,1) -> 5 | G33: =RANK(D33,$D$5:$D$67,1) -> 5 | H33: =RANK(E33,$E$5:$E$67,1) -> 5
... A67: =LumpyGrid!B67 -> 400 | B67: =LumpyGrid!C67 -> 6 | C67: =LumpyGrid!E67 -> 60 | D67: =(1-Tax)*C67 -> 45 | E67: =1000*C67 -> 60000 | F67: =RANK(C67,$C$5:$C$67,1) -> 63 | G67: =RANK(D67,$D$5:$D$67,1) -> 63 | H67: =RANK(E67,$E$5:$E$67,1) -> 63

Sheet Commitments
A1: Add a commitment: feasibility is conjunction (Proposition 1.2; AXIOM Lab 2.1, step 5)
A2: Each package against each commitment (1 = met). Adding commitments can only shrink the feasible packages; the order in which they are listed changes nothing.
A4: Quarter | B4: Years | C4: Plan, 0 q of delay | D4: Plan, 1 q of delay | E4: Plan, 2 q of delay | F4: Plan, 3 q of delay | G4: Plan, 4 q of delay | H4: Plan, 5 q of delay | I4: Plan, 6 q of delay | K4: Commitments in force | L4: Feasible packages
A5: 0 | B5: =A5/4 -> 0 | C5: =Per_point*(Plan_target-(Plan_target-Index0)*EXP(-Plan_rate*$B5)-(Depth0-Depth_q*0)*($B5/Trough_tau)*EXP(1-$B5/Trough_tau)) -> 620 | D5: =Per_point*(Plan_target-(Plan_target-Index0)*EXP(-Plan_rate*$B5)-(Depth0-Depth_q*1)*($B5/Trough_tau)*EXP(1-$B5/Trough_tau)) -> 620 | E5: =Per_point*(Plan_target-(Plan_target-Index0)*EXP(-Plan_rate*$B5)-(Depth0-Depth_q*2)*($B5/Trough_tau)*EXP(1-$B5/Trough_tau)) -> 620 | F5: =Per_point*(Plan_target-(Plan_target-Index0)*EXP(-Plan_rate*$B5)-(Depth0-Depth_q*3)*($B5/Trough_tau)*EXP(1-$B5/Trough_tau)) -> 620 | G5: =Per_point*(Plan_target-(Plan_target-Index0)*EXP(-Plan_rate*$B5)-(Depth0-Depth_q*4)*($B5/Trough_tau)*EXP(1-$B5/Trough_tau)) -> 620 | H5: =Per_point*(Plan_target-(Plan_target-Index0)*EXP(-Plan_rate*$B5)-(Depth0-Depth_q*5)*($B5/Trough_tau)*EXP(1-$B5/Trough_tau)) -> 620 | I5: =Per_point*(Plan_target-(Plan_target-Index0)*EXP(-Plan_rate*$B5)-(Depth0-Depth_q*6)*($B5/Trough_tau)*EXP(1-$B5/Trough_tau)) -> 620 | K5: The board's appetite | L5: =SUM(C22:C84) -> 46
A6: 1 | B6: =A6/4 -> 0.25 | C6: =Per_point*(Plan_target-(Plan_target-Index0)*EXP(-Plan_rate*$B6)-(Depth0-Depth_q*0)*($B6/Trough_tau)*EXP(1-$B6/Trough_tau)) -> 574.17772 | D6: =Per_point*(Plan_target-(Plan_target-Index0)*EXP(-Plan_rate*$B6)-(Depth0-Depth_q*1)*($B6/Trough_tau)*EXP(1-$B6/Trough_tau)) -> 581.61424 | E6: =Per_point*(Plan_target-(Plan_target-Index0)*EXP(-Plan_rate*$B6)-(Depth0-Depth_q*2)*($B6/Trough_tau)*EXP(1-$B6/Trough_tau)) -> 589.05075 | F6: =Per_point*(Plan_target-(Plan_target-Index0)*EXP(-Plan_rate*$B6)-(Depth0-Depth_q*3)*($B6/Trough_tau)*EXP(1-$B6/Trough_tau)) -> 596.48726 | G6: =Per_point*(Plan_target-(Plan_target-Index0)*EXP(-Plan_rate*$B6)-(Depth0-Depth_q*4)*($B6/Trough_tau)*EXP(1-$B6/Trough_tau)) -> 603.92378 | H6: =Per_point*(Plan_target-(Plan_target-Index0)*EXP(-Plan_rate*$B6)-(Depth0-Depth_q*5)*($B6/Trough_tau)*EXP(1-$B6/Trough_tau)) -> 611.36029 | I6: =Per_point*(Plan_target-(Plan_target-Index0)*EXP(-Plan_rate*$B6)-(Depth0-Depth_q*6)*($B6/Trough_tau)*EXP(1-$B6/Trough_tau)) -> 618.7968 | K6: + the covenant with the line fully drawn | L6: =SUMPRODUCT(C22:C84,D22:D84) -> 46
A7: 2 | B7: =A7/4 -> 0.5 | C7: =Per_point*(Plan_target-(Plan_target-Index0)*EXP(-Plan_rate*$B7)-(Depth0-Depth_q*0)*($B7/Trough_tau)*EXP(1-$B7/Trough_tau)) -> 540.0666 | D7: =Per_point*(Plan_target-(Plan_target-Index0)*EXP(-Plan_rate*$B7)-(Depth0-Depth_q*1)*($B7/Trough_tau)*EXP(1-$B7/Trough_tau)) -> 553.192 | E7: =Per_point*(Plan_target-(Plan_target-Index0)*EXP(-Plan_rate*$B7)-(Depth0-Depth_q*2)*($B7/Trough_tau)*EXP(1-$B7/Trough_tau)) -> 566.3174 | F7: =Per_point*(Plan_target-(Plan_target-Index0)*EXP(-Plan_rate*$B7)-(Depth0-Depth_q*3)*($B7/Trough_tau)*EXP(1-$B7/Trough_tau)) -> 579.4428 | G7: =Per_point*(Plan_target-(Plan_target-Index0)*EXP(-Plan_rate*$B7)-(Depth0-Depth_q*4)*($B7/Trough_tau)*EXP(1-$B7/Trough_tau)) -> 592.5682 | H7: =Per_point*(Plan_target-(Plan_target-Index0)*EXP(-Plan_rate*$B7)-(Depth0-Depth_q*5)*($B7/Trough_tau)*EXP(1-$B7/Trough_tau)) -> 605.6936 | I7: =Per_point*(Plan_target-(Plan_target-Index0)*EXP(-Plan_rate*$B7)-(Depth0-Depth_q*6)*($B7/Trough_tau)*EXP(1-$B7/Trough_tau)) -> 618.819 | K7: + the capability floor of 55 | L7: =SUMPRODUCT(C22:C84,D22:D84,E22:E84) -> 46
A8: 3 | B8: =A8/4 -> 0.75 | C8: =Per_point*(Plan_target-(Plan_target-Index0)*EXP(-Plan_rate*$B8)-(Depth0-Depth_q*0)*($B8/Trough_tau)*EXP(1-$B8/Trough_tau)) -> 515.55419 | D8: =Per_point*(Plan_target-(Plan_target-Index0)*EXP(-Plan_rate*$B8)-(Depth0-Depth_q*1)*($B8/Trough_tau)*EXP(1-$B8/Trough_tau)) -> 532.92887 | E8: =Per_point*(Plan_target-(Plan_target-Index0)*EXP(-Plan_rate*$B8)-(Depth0-Depth_q*2)*($B8/Trough_tau)*EXP(1-$B8/Trough_tau)) -> 550.30356 | F8: =Per_point*(Plan_target-(Plan_target-Index0)*EXP(-Plan_rate*$B8)-(Depth0-Depth_q*3)*($B8/Trough_tau)*EXP(1-$B8/Trough_tau)) -> 567.67825 | G8: =Per_point*(Plan_target-(Plan_target-Index0)*EXP(-Plan_rate*$B8)-(Depth0-Depth_q*4)*($B8/Trough_tau)*EXP(1-$B8/Trough_tau)) -> 585.05294 | H8: =Per_point*(Plan_target-(Plan_target-Index0)*EXP(-Plan_rate*$B8)-(Depth0-Depth_q*5)*($B8/Trough_tau)*EXP(1-$B8/Trough_tau)) -> 602.42762 | I8: =Per_point*(Plan_target-(Plan_target-Index0)*EXP(-Plan_rate*$B8)-(Depth0-Depth_q*6)*($B8/Trough_tau)*EXP(1-$B8/Trough_tau)) -> 619.80231 | K8: + Volume I's joint check | L8: =SUM(G22:G84) -> 46
A9: 4 | B9: =A9/4 -> 1 | C9: =Per_point*(Plan_target-(Plan_target-Index0)*EXP(-Plan_rate*$B9)-(Depth0-Depth_q*0)*($B9/Trough_tau)*EXP(1-$B9/Trough_tau)) -> 498.8622 | D9: =Per_point*(Plan_target-(Plan_target-Index0)*EXP(-Plan_rate*$B9)-(Depth0-Depth_q*1)*($B9/Trough_tau)*EXP(1-$B9/Trough_tau)) -> 519.30634 | E9: =Per_point*(Plan_target-(Plan_target-Index0)*EXP(-Plan_rate*$B9)-(Depth0-Depth_q*2)*($B9/Trough_tau)*EXP(1-$B9/Trough_tau)) -> 539.75049 | F9: =Per_point*(Plan_target-(Plan_target-Index0)*EXP(-Plan_rate*$B9)-(Depth0-Depth_q*3)*($B9/Trough_tau)*EXP(1-$B9/Trough_tau)) -> 560.19463 | G9: =Per_point*(Plan_target-(Plan_target-Index0)*EXP(-Plan_rate*$B9)-(Depth0-Depth_q*4)*($B9/Trough_tau)*EXP(1-$B9/Trough_tau)) -> 580.63877 | H9: =Per_point*(Plan_target-(Plan_target-Index0)*EXP(-Plan_rate*$B9)-(Depth0-Depth_q*5)*($B9/Trough_tau)*EXP(1-$B9/Trough_tau)) -> 601.08292 | I9: =Per_point*(Plan_target-(Plan_target-Index0)*EXP(-Plan_rate*$B9)-(Depth0-Depth_q*6)*($B9/Trough_tau)*EXP(1-$B9/Trough_tau)) -> 621.52706 | K9: The same four, listed in the opposite order | L9: =SUMPRODUCT(F22:F84,E22:E84,D22:D84,C22:C84) -> 46
A10: 5 | B10: =A10/4 -> 1.25 | C10: =Per_point*(Plan_target-(Plan_target-Index0)*EXP(-Plan_rate*$B10)-(Depth0-Depth_q*0)*($B10/Trough_tau)*EXP(1-$B10/Trough_tau)) -> 488.49718 | D10: =Per_point*(Plan_target-(Plan_target-Index0)*EXP(-Plan_rate*$B10)-(Depth0-Depth_q*1)*($B10/Trough_tau)*EXP(1-$B10/Trough_tau)) -> 511.04955 | E10: =Per_point*(Plan_target-(Plan_target-Index0)*EXP(-Plan_rate*$B10)-(Depth0-Depth_q*2)*($B10/Trough_tau)*EXP(1-$B10/Trough_tau)) -> 533.60192 | F10: =Per_point*(Plan_target-(Plan_target-Index0)*EXP(-Plan_rate*$B10)-(Depth0-Depth_q*3)*($B10/Trough_tau)*EXP(1-$B10/Trough_tau)) -> 556.15428 | G10: =Per_point*(Plan_target-(Plan_target-Index0)*EXP(-Plan_rate*$B10)-(Depth0-Depth_q*4)*($B10/Trough_tau)*EXP(1-$B10/Trough_tau)) -> 578.70665 | H10: =Per_point*(Plan_target-(Plan_target-Index0)*EXP(-Plan_rate*$B10)-(Depth0-Depth_q*5)*($B10/Trough_tau)*EXP(1-$B10/Trough_tau)) -> 601.25902 | I10: =Per_point*(Plan_target-(Plan_target-Index0)*EXP(-Plan_rate*$B10)-(Depth0-Depth_q*6)*($B10/Trough_tau)*EXP(1-$B10/Trough_tau)) -> 623.81138
A11: 6 | B11: =A11/4 -> 1.5 | C11: =Per_point*(Plan_target-(Plan_target-Index0)*EXP(-Plan_rate*$B11)-(Depth0-Depth_q*0)*($B11/Trough_tau)*EXP(1-$B11/Trough_tau)) -> 483.20817 | D11: =Per_point*(Plan_target-(Plan_target-Index0)*EXP(-Plan_rate*$B11)-(Depth0-Depth_q*1)*($B11/Trough_tau)*EXP(1-$B11/Trough_tau)) -> 507.09104 | E11: =Per_point*(Plan_target-(Plan_target-Index0)*EXP(-Plan_rate*$B11)-(Depth0-Depth_q*2)*($B11/Trough_tau)*EXP(1-$B11/Trough_tau)) -> 530.97392 | F11: =Per_point*(Plan_target-(Plan_target-Index0)*EXP(-Plan_rate*$B11)-(Depth0-Depth_q*3)*($B11/Trough_tau)*EXP(1-$B11/Trough_tau)) -> 554.85679 | G11: =Per_point*(Plan_target-(Plan_target-Index0)*EXP(-Plan_rate*$B11)-(Depth0-Depth_q*4)*($B11/Trough_tau)*EXP(1-$B11/Trough_tau)) -> 578.73966 | H11: =Per_point*(Plan_target-(Plan_target-Index0)*EXP(-Plan_rate*$B11)-(Depth0-Depth_q*5)*($B11/Trough_tau)*EXP(1-$B11/Trough_tau)) -> 602.62254 | I11: =Per_point*(Plan_target-(Plan_target-Index0)*EXP(-Plan_rate*$B11)-(Depth0-Depth_q*6)*($B11/Trough_tau)*EXP(1-$B11/Trough_tau)) -> 626.50541 | K11: The covenant would bind only above a line of ($ million) | L11: =Covenant*Ebitda-Net_debt -> 545.16
A12: 7 | B12: =A12/4 -> 1.75 | C12: =Per_point*(Plan_target-(Plan_target-Index0)*EXP(-Plan_rate*$B12)-(Depth0-Depth_q*0)*($B12/Trough_tau)*EXP(1-$B12/Trough_tau)) -> 481.95038 | D12: =Per_point*(Plan_target-(Plan_target-Index0)*EXP(-Plan_rate*$B12)-(Depth0-Depth_q*1)*($B12/Trough_tau)*EXP(1-$B12/Trough_tau)) -> 506.5397 | E12: =Per_point*(Plan_target-(Plan_target-Index0)*EXP(-Plan_rate*$B12)-(Depth0-Depth_q*2)*($B12/Trough_tau)*EXP(1-$B12/Trough_tau)) -> 531.12903 | F12: =Per_point*(Plan_target-(Plan_target-Index0)*EXP(-Plan_rate*$B12)-(Depth0-Depth_q*3)*($B12/Trough_tau)*EXP(1-$B12/Trough_tau)) -> 555.71835 | G12: =Per_point*(Plan_target-(Plan_target-Index0)*EXP(-Plan_rate*$B12)-(Depth0-Depth_q*4)*($B12/Trough_tau)*EXP(1-$B12/Trough_tau)) -> 580.30767 | H12: =Per_point*(Plan_target-(Plan_target-Index0)*EXP(-Plan_rate*$B12)-(Depth0-Depth_q*5)*($B12/Trough_tau)*EXP(1-$B12/Trough_tau)) -> 604.89699 | I12: =Per_point*(Plan_target-(Plan_target-Index0)*EXP(-Plan_rate*$B12)-(Depth0-Depth_q*6)*($B12/Trough_tau)*EXP(1-$B12/Trough_tau)) -> 629.48631
A13: 8 | B13: =A13/4 -> 2 | C13: =Per_point*(Plan_target-(Plan_target-Index0)*EXP(-Plan_rate*$B13)-(Depth0-Depth_q*0)*($B13/Trough_tau)*EXP(1-$B13/Trough_tau)) -> 483.85405 | D13: =Per_point*(Plan_target-(Plan_target-Index0)*EXP(-Plan_rate*$B13)-(Depth0-Depth_q*1)*($B13/Trough_tau)*EXP(1-$B13/Trough_tau)) -> 508.65405 | E13: =Per_point*(Plan_target-(Plan_target-Index0)*EXP(-Plan_rate*$B13)-(Depth0-Depth_q*2)*($B13/Trough_tau)*EXP(1-$B13/Trough_tau)) -> 533.45405 | F13: =Per_point*(Plan_target-(Plan_target-Index0)*EXP(-Plan_rate*$B13)-(Depth0-Depth_q*3)*($B13/Trough_tau)*EXP(1-$B13/Trough_tau)) -> 558.25405 | G13: =Per_point*(Plan_target-(Plan_target-Index0)*EXP(-Plan_rate*$B13)-(Depth0-Depth_q*4)*($B13/Trough_tau)*EXP(1-$B13/Trough_tau)) -> 583.05405 | H13: =Per_point*(Plan_target-(Plan_target-Index0)*EXP(-Plan_rate*$B13)-(Depth0-Depth_q*5)*($B13/Trough_tau)*EXP(1-$B13/Trough_tau)) -> 607.85405 | I13: =Per_point*(Plan_target-(Plan_target-Index0)*EXP(-Plan_rate*$B13)-(Depth0-Depth_q*6)*($B13/Trough_tau)*EXP(1-$B13/Trough_tau)) -> 632.65405 | K13: The signed package, commitment by commitment | L13: Value
A14: 9 | B14: =A14/4 -> 2.25 | C14: =Per_point*(Plan_target-(Plan_target-Index0)*EXP(-Plan_rate*$B14)-(Depth0-Depth_q*0)*($B14/Trough_tau)*EXP(1-$B14/Trough_tau)) -> 488.19778 | D14: =Per_point*(Plan_target-(Plan_target-Index0)*EXP(-Plan_rate*$B14)-(Depth0-Depth_q*1)*($B14/Trough_tau)*EXP(1-$B14/Trough_tau)) -> 512.81944 | E14: =Per_point*(Plan_target-(Plan_target-Index0)*EXP(-Plan_rate*$B14)-(Depth0-Depth_q*2)*($B14/Trough_tau)*EXP(1-$B14/Trough_tau)) -> 537.44111 | F14: =Per_point*(Plan_target-(Plan_target-Index0)*EXP(-Plan_rate*$B14)-(Depth0-Depth_q*3)*($B14/Trough_tau)*EXP(1-$B14/Trough_tau)) -> 562.06277 | G14: =Per_point*(Plan_target-(Plan_target-Index0)*EXP(-Plan_rate*$B14)-(Depth0-Depth_q*4)*($B14/Trough_tau)*EXP(1-$B14/Trough_tau)) -> 586.68444 | H14: =Per_point*(Plan_target-(Plan_target-Index0)*EXP(-Plan_rate*$B14)-(Depth0-Depth_q*5)*($B14/Trough_tau)*EXP(1-$B14/Trough_tau)) -> 611.3061 | I14: =Per_point*(Plan_target-(Plan_target-Index0)*EXP(-Plan_rate*$B14)-(Depth0-Depth_q*6)*($B14/Trough_tau)*EXP(1-$B14/Trough_tau)) -> 635.92776 | K14: Line ($ million) | L14: =LumpyGrid!J8 -> 150
A15: 10 | B15: =A15/4 -> 2.5 | C15: =Per_point*(Plan_target-(Plan_target-Index0)*EXP(-Plan_rate*$B15)-(Depth0-Depth_q*0)*($B15/Trough_tau)*EXP(1-$B15/Trough_tau)) -> 494.3857 | D15: =Per_point*(Plan_target-(Plan_target-Index0)*EXP(-Plan_rate*$B15)-(Depth0-Depth_q*1)*($B15/Trough_tau)*EXP(1-$B15/Trough_tau)) -> 518.52852 | E15: =Per_point*(Plan_target-(Plan_target-Index0)*EXP(-Plan_rate*$B15)-(Depth0-Depth_q*2)*($B15/Trough_tau)*EXP(1-$B15/Trough_tau)) -> 542.67134 | F15: =Per_point*(Plan_target-(Plan_target-Index0)*EXP(-Plan_rate*$B15)-(Depth0-Depth_q*3)*($B15/Trough_tau)*EXP(1-$B15/Trough_tau)) -> 566.81417 | G15: =Per_point*(Plan_target-(Plan_target-Index0)*EXP(-Plan_rate*$B15)-(Depth0-Depth_q*4)*($B15/Trough_tau)*EXP(1-$B15/Trough_tau)) -> 590.95699 | H15: =Per_point*(Plan_target-(Plan_target-Index0)*EXP(-Plan_rate*$B15)-(Depth0-Depth_q*5)*($B15/Trough_tau)*EXP(1-$B15/Trough_tau)) -> 615.09982 | I15: =Per_point*(Plan_target-(Plan_target-Index0)*EXP(-Plan_rate*$B15)-(Depth0-Depth_q*6)*($B15/Trough_tau)*EXP(1-$B15/Trough_tau)) -> 639.24264 | K15: Delay (quarters) | L15: =LumpyGrid!J9 -> 1
A16: 11 | B16: =A16/4 -> 2.75 | C16: =Per_point*(Plan_target-(Plan_target-Index0)*EXP(-Plan_rate*$B16)-(Depth0-Depth_q*0)*($B16/Trough_tau)*EXP(1-$B16/Trough_tau)) -> 501.92795 | D16: =Per_point*(Plan_target-(Plan_target-Index0)*EXP(-Plan_rate*$B16)-(Depth0-Depth_q*1)*($B16/Trough_tau)*EXP(1-$B16/Trough_tau)) -> 525.36451 | E16: =Per_point*(Plan_target-(Plan_target-Index0)*EXP(-Plan_rate*$B16)-(Depth0-Depth_q*2)*($B16/Trough_tau)*EXP(1-$B16/Trough_tau)) -> 548.80108 | F16: =Per_point*(Plan_target-(Plan_target-Index0)*EXP(-Plan_rate*$B16)-(Depth0-Depth_q*3)*($B16/Trough_tau)*EXP(1-$B16/Trough_tau)) -> 572.23764 | G16: =Per_point*(Plan_target-(Plan_target-Index0)*EXP(-Plan_rate*$B16)-(Depth0-Depth_q*4)*($B16/Trough_tau)*EXP(1-$B16/Trough_tau)) -> 595.67421 | H16: =Per_point*(Plan_target-(Plan_target-Index0)*EXP(-Plan_rate*$B16)-(Depth0-Depth_q*5)*($B16/Trough_tau)*EXP(1-$B16/Trough_tau)) -> 619.11077 | I16: =Per_point*(Plan_target-(Plan_target-Index0)*EXP(-Plan_rate*$B16)-(Depth0-Depth_q*6)*($B16/Trough_tau)*EXP(1-$B16/Trough_tau)) -> 642.54733 | K16: Breach odds (engine) | L16: =LumpyGrid!J10 -> 0.04003
A17: 12 | B17: =A17/4 -> 3 | C17: =Per_point*(Plan_target-(Plan_target-Index0)*EXP(-Plan_rate*$B17)-(Depth0-Depth_q*0)*($B17/Trough_tau)*EXP(1-$B17/Trough_tau)) -> 510.42405 | D17: =Per_point*(Plan_target-(Plan_target-Index0)*EXP(-Plan_rate*$B17)-(Depth0-Depth_q*1)*($B17/Trough_tau)*EXP(1-$B17/Trough_tau)) -> 532.98699 | E17: =Per_point*(Plan_target-(Plan_target-Index0)*EXP(-Plan_rate*$B17)-(Depth0-Depth_q*2)*($B17/Trough_tau)*EXP(1-$B17/Trough_tau)) -> 555.54993 | F17: =Per_point*(Plan_target-(Plan_target-Index0)*EXP(-Plan_rate*$B17)-(Depth0-Depth_q*3)*($B17/Trough_tau)*EXP(1-$B17/Trough_tau)) -> 578.11287 | G17: =Per_point*(Plan_target-(Plan_target-Index0)*EXP(-Plan_rate*$B17)-(Depth0-Depth_q*4)*($B17/Trough_tau)*EXP(1-$B17/Trough_tau)) -> 600.67581 | H17: =Per_point*(Plan_target-(Plan_target-Index0)*EXP(-Plan_rate*$B17)-(Depth0-Depth_q*5)*($B17/Trough_tau)*EXP(1-$B17/Trough_tau)) -> 623.23875 | I17: =Per_point*(Plan_target-(Plan_target-Index0)*EXP(-Plan_rate*$B17)-(Depth0-Depth_q*6)*($B17/Trough_tau)*EXP(1-$B17/Trough_tau)) -> 645.80169 | K17: Margin to the appetite (points) | L17: =100*(Appetite-L16) -> 0.997
A18: Deepest draw | C18: =Liq0-MIN(C5:C17) -> 138.04962 | D18: =Liq0-MIN(D5:D17) -> 113.4603 | E18: =Liq0-MIN(E5:E17) -> 89.026083 | F18: =Liq0-MIN(F5:F17) -> 65.14321 | G18: =Liq0-MIN(G5:G17) -> 41.293351 | H18: =Liq0-MIN(H5:H17) -> 18.917081 | I18: =Liq0-MIN(I5:I17) -> 1.2031975 | K18: Leverage with the line fully drawn | L18: =(Net_debt+L14)/Ebitda -> 3.7026634
K19: Capability above its floor | L19: =Capability-Cap_floor -> 3
K20: Joint check: deepest draw | L20: =INDEX($C$18:$I$18,1,L15+1) -> 113.4603
A21: Line | B21: Delay | C21: Appetite (the board) | D21: Covenant, line fully drawn | E21: Capability floor | F21: Joint check | G21: All four | K21: Joint check: closure buffer net of the line | L21: =MAX(P90-L14,0) -> 36.866976
