Workbook

Sheet README
B1: DCT Laboratory — Vol I, Ch 11: Enterprise Performance Architecture
B2: Seed 26111 · Companion to DCT_V1_Ch11_Lab.ipynb and AXIOM Lab 1.11 (module AXIOM-11). Readings in index points; money in $ million.
B4: Worked Example 11.1, Who Really Chose Digital?, with the book's declarations, and the five steps of AXIOM Lab 1.11, Auditing Meridian's Scorecard.
B5: Declarations: the CFO's scorecard (Worked Example 1.1) and the Chapter 1 model's parameters (Online Appendix 1.B.4).
B6: Paths: the four readings of each option and the scorecard, month by month for five years (Figure 11.3; Online Appendix 11.B.6).
B7: Dashboard: Table 11.2's ten dimensions, Meridian's six with supports, indicators and bands, Proposition 11.1's twin, and Section 11.8's sustainability line (lab step 1).
B8: Dependencies: Table 11.4's lag floors recomputed from Chapter 9's fourteen arrows (Theorem 11.3(i)).
B9: Weights: dominance, the tie 1.6 points of weight away, the weight sweep, and the shares of weightings (Theorem 11.2(ii); Figure 11.1; Online Appendix 11.B.2; lab step 2).
B10: Yardsticks: best-to-worst and percentage scales, their effective weights, and two other reference groups (Theorem 11.2(iii); Online Appendix 11.B.3; lab step 3).
B11: Ratios: the rate-and-mix bridge for Theorem 11.5's two divisions and Table 11.5's bank, a mix bench, target cascades and roll-ups (lab step 4).
B12: Frontier: the indivisible programs and Figure 11.2's exchange rate (Theorem 11.4; lab step 5).
B13: Window: the annual reviews and the J-curve's evaluation window (Theorem 11.3(iii); Online Appendix 11.B.1; lab step 5).
... B21: Cross-sheet link: green.

Sheet Declarations
A1: Declarations (Worked Example 11.1, the situation; Worked Example 1.1; the Chapter 1 model of Online Appendix 1.B.4). Readings in index points; liquidity indexed to today = 100 ($620 million).
A3: Reading | B3: Today (Chapter 3) | C3: Weight in the CFO's scorecard | D3: Sign (lower risk is better) | E3: Measurement error (Table 5.2) | F3: Tag (Table 5.2)
A4: Liquidity | B4: 100 | C4: 0.25 | D4: 1 | E4: +/-1% | F4: ECA: capital
A5: Technology | B5: 41 | C5: 0.25 | D5: 1 | E5: +/-4 | F5: ECA: capital
A6: Efficiency | B6: 71 | C6: 0.25 | D6: 1 | E6: +/-3 | F6: EPA: performance
A7: Strategic risk | B7: 64 | C7: 0.25 | D7: -1 | E7: +/-6 | F7: ERRA: risk
A8: Today's score, the weights times (L, T, E, -R) | B8: =SUMPRODUCT(B4:B7,C4:C7,D4:D7) -> 37 | C8: Worked Example 1.1: (100 + 41 + 71 - 64)/4 = 37.0
A9: $ million a liquidity index point | B9: 6.2 | C9: Today = 100 = $620 million
A10: The restructuring's sale closes (years) | B10: 1 | C10: The jump J applies from t = 1
A13: Option | B13: Reading | C13: Target | D13: Speed k a year | E13: Trough sigma D | F13: Trough time tau (years) | G13: Jump J at the sale | H13: Start x(0)
A14: Digital | B14: Liquidity | C14: 112 | D14: 0.35 | E14: -28 | F14: 2 | G14: 0 | H14: =$B$4 -> 100
A15: Digital | B15: Technology | C15: 78 | D15: 0.55 | E15: 0 | G15: 0 | H15: =$B$5 -> 41
A16: Digital | B16: Efficiency | C16: 77 | D16: 0.5 | E16: -9 | F16: 1.5 | G16: 0 | H16: =$B$6 -> 71
A17: Digital | B17: Strategic risk | C17: 51 | D17: 0.4 | E17: 14 | F17: 1.2 | G17: 0 | H17: =$B$7 -> 64
A18: Restructuring | B18: Liquidity | C18: 104 | D18: 0.3 | E18: 0 | G18: 18 | H18: =$B$4 -> 100
A19: Restructuring | B19: Technology | C19: 38 | D19: 0.25 | E19: 0 | G19: 0 | H19: =$B$5 -> 41
A20: Restructuring | B20: Efficiency | C20: 74 | D20: 0.45 | E20: 0 | G20: 0 | H20: =$B$6 -> 71
A21: Restructuring | B21: Strategic risk | C21: 56 | D21: 0.35 | E21: 0 | G21: -8 | H21: =$B$7 -> 64
A22: Turnaround | B22: Liquidity | C22: 106 | D22: 0.45 | E22: 0 | G22: 0 | H22: =$B$4 -> 100
A23: Turnaround | B23: Technology | C23: 33 | D23: 0.2 | E23: 0 | G23: 0 | H23: =$B$5 -> 41
A24: Turnaround | B24: Efficiency | C24: 79 | D24: 0.6 | E24: 0 | G24: 0 | H24: =$B$6 -> 71
A25: Turnaround | B25: Strategic risk | C25: 67 | D25: 0.3 | E25: 0 | G25: 0 | H25: =$B$7 -> 64
A27: Online Appendix 1.B.4: x(t) = target + (x(0) - target) e^(-k t) + sigma D (t / tau) e^(1 - t / tau) + J 1{t >= 1}, t in years. A trough of zero needs no trough time; blank cells are zero.

Sheet Paths
A1: The Chapter 1 model month by month: four readings for each option and the CFO's scorecard (Worked Example 11.1, Step 4; Figure 11.3; Online Appendix 11.B.6)
A2: Each reading follows Online Appendix 1.B.4's model with the parameters on Declarations; the score is the weights times (L, T, E, -R). Flags: 1 when the statement is true that month.
X3: Reading the paths | Y3: Value | Z3: Book
A4: Month | B4: t (years) | C4: Digital: liquidity | D4: Digital: technology | E4: Digital: efficiency | F4: Digital: strategic risk | G4: Restructuring: liquidity | H4: Restructuring: technology | I4: Restructuring: efficiency | J4: Restructuring: strategic risk | K4: Turnaround: liquidity | L4: Turnaround: technology | M4: Turnaround: efficiency | N4: Turnaround: strategic risk | O4: Score: digital | P4: Score: restructuring | Q4: Score: turnaround | R4: Digital below today's score | S4: Digital ahead of the turnaround | T4: Digital ahead of restructuring | U4: Digital's rank | V4: |Restructuring - turnaround| | X4: Digital's low | Y4: =MIN($O$5:$O$65) -> 32.106467 | Z4: 32.11 at month 11
A5: 0 | B5: =A5/12 -> 0 | C5: =Declarations!$C$14+(Declarations!$H$14-Declarations!$C$14)*EXP(-Declarations!$D$14*$B5)+IF(Declarations!$E$14=0,0,Declarations!$E$14*($B5/Declarations!$F$14)*EXP(1-$B5/Declarations!$F$14))+Declarations!$G$14*IF($B5>=Sale_t,1,0) -> 100 | D5: =Declarations!$C$15+(Declarations!$H$15-Declarations!$C$15)*EXP(-Declarations!$D$15*$B5)+IF(Declarations!$E$15=0,0,Declarations!$E$15*($B5/Declarations!$F$15)*EXP(1-$B5/Declarations!$F$15))+Declarations!$G$15*IF($B5>=Sale_t,1,0) -> 41 | E5: =Declarations!$C$16+(Declarations!$H$16-Declarations!$C$16)*EXP(-Declarations!$D$16*$B5)+IF(Declarations!$E$16=0,0,Declarations!$E$16*($B5/Declarations!$F$16)*EXP(1-$B5/Declarations!$F$16))+Declarations!$G$16*IF($B5>=Sale_t,1,0) -> 71 | F5: =Declarations!$C$17+(Declarations!$H$17-Declarations!$C$17)*EXP(-Declarations!$D$17*$B5)+IF(Declarations!$E$17=0,0,Declarations!$E$17*($B5/Declarations!$F$17)*EXP(1-$B5/Declarations!$F$17))+Declarations!$G$17*IF($B5>=Sale_t,1,0) -> 64 | G5: =Declarations!$C$18+(Declarations!$H$18-Declarations!$C$18)*EXP(-Declarations!$D$18*$B5)+IF(Declarations!$E$18=0,0,Declarations!$E$18*($B5/Declarations!$F$18)*EXP(1-$B5/Declarations!$F$18))+Declarations!$G$18*IF($B5>=Sale_t,1,0) -> 100 | H5: =Declarations!$C$19+(Declarations!$H$19-Declarations!$C$19)*EXP(-Declarations!$D$19*$B5)+IF(Declarations!$E$19=0,0,Declarations!$E$19*($B5/Declarations!$F$19)*EXP(1-$B5/Declarations!$F$19))+Declarations!$G$19*IF($B5>=Sale_t,1,0) -> 41 | I5: =Declarations!$C$20+(Declarations!$H$20-Declarations!$C$20)*EXP(-Declarations!$D$20*$B5)+IF(Declarations!$E$20=0,0,Declarations!$E$20*($B5/Declarations!$F$20)*EXP(1-$B5/Declarations!$F$20))+Declarations!$G$20*IF($B5>=Sale_t,1,0) -> 71 | J5: =Declarations!$C$21+(Declarations!$H$21-Declarations!$C$21)*EXP(-Declarations!$D$21*$B5)+IF(Declarations!$E$21=0,0,Declarations!$E$21*($B5/Declarations!$F$21)*EXP(1-$B5/Declarations!$F$21))+Declarations!$G$21*IF($B5>=Sale_t,1,0) -> 64 | K5: =Declarations!$C$22+(Declarations!$H$22-Declarations!$C$22)*EXP(-Declarations!$D$22*$B5)+IF(Declarations!$E$22=0,0,Declarations!$E$22*($B5/Declarations!$F$22)*EXP(1-$B5/Declarations!$F$22))+Declarations!$G$22*IF($B5>=Sale_t,1,0) -> 100 | L5: =Declarations!$C$23+(Declarations!$H$23-Declarations!$C$23)*EXP(-Declarations!$D$23*$B5)+IF(Declarations!$E$23=0,0,Declarations!$E$23*($B5/Declarations!$F$23)*EXP(1-$B5/Declarations!$F$23))+Declarations!$G$23*IF($B5>=Sale_t,1,0) -> 41 | M5: =Declarations!$C$24+(Declarations!$H$24-Declarations!$C$24)*EXP(-Declarations!$D$24*$B5)+IF(Declarations!$E$24=0,0,Declarations!$E$24*($B5/Declarations!$F$24)*EXP(1-$B5/Declarations!$F$24))+Declarations!$G$24*IF($B5>=Sale_t,1,0) -> 71 | N5: =Declarations!$C$25+(Declarations!$H$25-Declarations!$C$25)*EXP(-Declarations!$D$25*$B5)+IF(Declarations!$E$25=0,0,Declarations!$E$25*($B5/Declarations!$F$25)*EXP(1-$B5/Declarations!$F$25))+Declarations!$G$25*IF($B5>=Sale_t,1,0) -> 64 | O5: =W_L*S_L*C5+W_T*S_T*D5+W_E*S_E*E5+W_R*S_R*F5 -> 37 | P5: =W_L*S_L*G5+W_T*S_T*H5+W_E*S_E*I5+W_R*S_R*J5 -> 37 | Q5: =W_L*S_L*K5+W_T*S_T*L5+W_E*S_E*M5+W_R*S_R*N5 -> 37 | R5: =IF(O5<Score_today,1,0) -> 0 | S5: =IF(O5>Q5,1,0) -> 0 | T5: =IF(O5>P5,1,0) -> 0 | U5: =1+IF(P5>O5,1,0)+IF(Q5>O5,1,0) -> 1 | V5: =ABS(P5-Q5) -> 0 | X5: Month of digital's low | Y5: =INDEX($A$5:$A$65,MATCH(Y4,$O$5:$O$65,0)) -> 11
A6: 1 | B6: =A6/12 -> 0.083333333 | C6: =Declarations!$C$14+(Declarations!$H$14-Declarations!$C$14)*EXP(-Declarations!$D$14*$B6)+IF(Declarations!$E$14=0,0,Declarations!$E$14*($B6/Declarations!$F$14)*EXP(1-$B6/Declarations!$F$14))+Declarations!$G$14*IF($B6>=Sale_t,1,0) -> 97.30304 | D6: =Declarations!$C$15+(Declarations!$H$15-Declarations!$C$15)*EXP(-Declarations!$D$15*$B6)+IF(Declarations!$E$15=0,0,Declarations!$E$15*($B6/Declarations!$F$15)*EXP(1-$B6/Declarations!$F$15))+Declarations!$G$15*IF($B6>=Sale_t,1,0) -> 42.657557 | E6: =Declarations!$C$16+(Declarations!$H$16-Declarations!$C$16)*EXP(-Declarations!$D$16*$B6)+IF(Declarations!$E$16=0,0,Declarations!$E$16*($B6/Declarations!$F$16)*EXP(1-$B6/Declarations!$F$16))+Declarations!$G$16*IF($B6>=Sale_t,1,0) -> 69.959171 | F6: =Declarations!$C$17+(Declarations!$H$17-Declarations!$C$17)*EXP(-Declarations!$D$17*$B6)+IF(Declarations!$E$17=0,0,Declarations!$E$17*($B6/Declarations!$F$17)*EXP(1-$B6/Declarations!$F$17))+Declarations!$G$17*IF($B6>=Sale_t,1,0) -> 66.039285 | G6: =Declarations!$C$18+(Declarations!$H$18-Declarations!$C$18)*EXP(-Declarations!$D$18*$B6)+IF(Declarations!$E$18=0,0,Declarations!$E$18*($B6/Declarations!$F$18)*EXP(1-$B6/Declarations!$F$18))+Declarations!$G$18*IF($B6>=Sale_t,1,0) -> 100.09876 | H6: =Declarations!$C$19+(Declarations!$H$19-Declarations!$C$19)*EXP(-Declarations!$D$19*$B6)+IF(Declarations!$E$19=0,0,Declarations!$E$19*($B6/Declarations!$F$19)*EXP(1-$B6/Declarations!$F$19))+Declarations!$G$19*IF($B6>=Sale_t,1,0) -> 40.938147 | I6: =Declarations!$C$20+(Declarations!$H$20-Declarations!$C$20)*EXP(-Declarations!$D$20*$B6)+IF(Declarations!$E$20=0,0,Declarations!$E$20*($B6/Declarations!$F$20)*EXP(1-$B6/Declarations!$F$20))+Declarations!$G$20*IF($B6>=Sale_t,1,0) -> 71.110417 | J6: =Declarations!$C$21+(Declarations!$H$21-Declarations!$C$21)*EXP(-Declarations!$D$21*$B6)+IF(Declarations!$E$21=0,0,Declarations!$E$21*($B6/Declarations!$F$21)*EXP(1-$B6/Declarations!$F$21))+Declarations!$G$21*IF($B6>=Sale_t,1,0) -> 63.770037 | K6: =Declarations!$C$22+(Declarations!$H$22-Declarations!$C$22)*EXP(-Declarations!$D$22*$B6)+IF(Declarations!$E$22=0,0,Declarations!$E$22*($B6/Declarations!$F$22)*EXP(1-$B6/Declarations!$F$22))+Declarations!$G$22*IF($B6>=Sale_t,1,0) -> 100.22083 | L6: =Declarations!$C$23+(Declarations!$H$23-Declarations!$C$23)*EXP(-Declarations!$D$23*$B6)+IF(Declarations!$E$23=0,0,Declarations!$E$23*($B6/Declarations!$F$23)*EXP(1-$B6/Declarations!$F$23))+Declarations!$G$23*IF($B6>=Sale_t,1,0) -> 40.867772 | M6: =Declarations!$C$24+(Declarations!$H$24-Declarations!$C$24)*EXP(-Declarations!$D$24*$B6)+IF(Declarations!$E$24=0,0,Declarations!$E$24*($B6/Declarations!$F$24)*EXP(1-$B6/Declarations!$F$24))+Declarations!$G$24*IF($B6>=Sale_t,1,0) -> 71.390165 | N6: =Declarations!$C$25+(Declarations!$H$25-Declarations!$C$25)*EXP(-Declarations!$D$25*$B6)+IF(Declarations!$E$25=0,0,Declarations!$E$25*($B6/Declarations!$F$25)*EXP(1-$B6/Declarations!$F$25))+Declarations!$G$25*IF($B6>=Sale_t,1,0) -> 64.07407 | O6: =W_L*S_L*C6+W_T*S_T*D6+W_E*S_E*E6+W_R*S_R*F6 -> 35.970121 | P6: =W_L*S_L*G6+W_T*S_T*H6+W_E*S_E*I6+W_R*S_R*J6 -> 37.094322 | Q6: =W_L*S_L*K6+W_T*S_T*L6+W_E*S_E*M6+W_R*S_R*N6 -> 37.101175 | R6: =IF(O6<Score_today,1,0) -> 1 | S6: =IF(O6>Q6,1,0) -> 0 | T6: =IF(O6>P6,1,0) -> 0 | U6: =1+IF(P6>O6,1,0)+IF(Q6>O6,1,0) -> 3 | V6: =ABS(P6-Q6) -> 0.0068531058 | X6: Last month digital is below today's score | Y6: =_xlfn.MAXIFS($A$5:$A$65,$R$5:$R$65,1) -> 28 | Z6: month 28
A7: 2 | B7: =A7/12 -> 0.16666667 | C7: =Declarations!$C$14+(Declarations!$H$14-Declarations!$C$14)*EXP(-Declarations!$D$14*$B7)+IF(Declarations!$E$14=0,0,Declarations!$E$14*($B7/Declarations!$F$14)*EXP(1-$B7/Declarations!$F$14))+Declarations!$G$14*IF($B7>=Sale_t,1,0) -> 94.844448 | D7: =Declarations!$C$15+(Declarations!$H$15-Declarations!$C$15)*EXP(-Declarations!$D$15*$B7)+IF(Declarations!$E$15=0,0,Declarations!$E$15*($B7/Declarations!$F$15)*EXP(1-$B7/Declarations!$F$15))+Declarations!$G$15*IF($B7>=Sale_t,1,0) -> 44.240858 | E7: =Declarations!$C$16+(Declarations!$H$16-Declarations!$C$16)*EXP(-Declarations!$D$16*$B7)+IF(Declarations!$E$16=0,0,Declarations!$E$16*($B7/Declarations!$F$16)*EXP(1-$B7/Declarations!$F$16))+Declarations!$G$16*IF($B7>=Sale_t,1,0) -> 69.047308 | F7: =Declarations!$C$17+(Declarations!$H$17-Declarations!$C$17)*EXP(-Declarations!$D$17*$B7)+IF(Declarations!$E$17=0,0,Declarations!$E$17*($B7/Declarations!$F$17)*EXP(1-$B7/Declarations!$F$17))+Declarations!$G$17*IF($B7>=Sale_t,1,0) -> 67.761734 | G7: =Declarations!$C$18+(Declarations!$H$18-Declarations!$C$18)*EXP(-Declarations!$D$18*$B7)+IF(Declarations!$E$18=0,0,Declarations!$E$18*($B7/Declarations!$F$18)*EXP(1-$B7/Declarations!$F$18))+Declarations!$G$18*IF($B7>=Sale_t,1,0) -> 100.19508 | H7: =Declarations!$C$19+(Declarations!$H$19-Declarations!$C$19)*EXP(-Declarations!$D$19*$B7)+IF(Declarations!$E$19=0,0,Declarations!$E$19*($B7/Declarations!$F$19)*EXP(1-$B7/Declarations!$F$19))+Declarations!$G$19*IF($B7>=Sale_t,1,0) -> 40.877568 | I7: =Declarations!$C$20+(Declarations!$H$20-Declarations!$C$20)*EXP(-Declarations!$D$20*$B7)+IF(Declarations!$E$20=0,0,Declarations!$E$20*($B7/Declarations!$F$20)*EXP(1-$B7/Declarations!$F$20))+Declarations!$G$20*IF($B7>=Sale_t,1,0) -> 71.21677 | J7: =Declarations!$C$21+(Declarations!$H$21-Declarations!$C$21)*EXP(-Declarations!$D$21*$B7)+IF(Declarations!$E$21=0,0,Declarations!$E$21*($B7/Declarations!$F$21)*EXP(1-$B7/Declarations!$F$21))+Declarations!$G$21*IF($B7>=Sale_t,1,0) -> 63.546684 | K7: =Declarations!$C$22+(Declarations!$H$22-Declarations!$C$22)*EXP(-Declarations!$D$22*$B7)+IF(Declarations!$E$22=0,0,Declarations!$E$22*($B7/Declarations!$F$22)*EXP(1-$B7/Declarations!$F$22))+Declarations!$G$22*IF($B7>=Sale_t,1,0) -> 100.43354 | L7: =Declarations!$C$23+(Declarations!$H$23-Declarations!$C$23)*EXP(-Declarations!$D$23*$B7)+IF(Declarations!$E$23=0,0,Declarations!$E$23*($B7/Declarations!$F$23)*EXP(1-$B7/Declarations!$F$23))+Declarations!$G$23*IF($B7>=Sale_t,1,0) -> 40.737729 | M7: =Declarations!$C$24+(Declarations!$H$24-Declarations!$C$24)*EXP(-Declarations!$D$24*$B7)+IF(Declarations!$E$24=0,0,Declarations!$E$24*($B7/Declarations!$F$24)*EXP(1-$B7/Declarations!$F$24))+Declarations!$G$24*IF($B7>=Sale_t,1,0) -> 71.761301 | N7: =Declarations!$C$25+(Declarations!$H$25-Declarations!$C$25)*EXP(-Declarations!$D$25*$B7)+IF(Declarations!$E$25=0,0,Declarations!$E$25*($B7/Declarations!$F$25)*EXP(1-$B7/Declarations!$F$25))+Declarations!$G$25*IF($B7>=Sale_t,1,0) -> 64.146312 | O7: =W_L*S_L*C7+W_T*S_T*D7+W_E*S_E*E7+W_R*S_R*F7 -> 35.09272 | P7: =W_L*S_L*G7+W_T*S_T*H7+W_E*S_E*I7+W_R*S_R*J7 -> 37.185684 | Q7: =W_L*S_L*K7+W_T*S_T*L7+W_E*S_E*M7+W_R*S_R*N7 -> 37.196564 | R7: =IF(O7<Score_today,1,0) -> 1 | S7: =IF(O7>Q7,1,0) -> 0 | T7: =IF(O7>P7,1,0) -> 0 | U7: =1+IF(P7>O7,1,0)+IF(Q7>O7,1,0) -> 3 | V7: =ABS(P7-Q7) -> 0.01088005 | X7: Month digital regains today's score | Y7: =Y6+1 -> 29 | Z7: month 29
A8: 3 | B8: =A8/12 -> 0.25 | C8: =Declarations!$C$14+(Declarations!$H$14-Declarations!$C$14)*EXP(-Declarations!$D$14*$B8)+IF(Declarations!$E$14=0,0,Declarations!$E$14*($B8/Declarations!$F$14)*EXP(1-$B8/Declarations!$F$14))+Declarations!$G$14*IF($B8>=Sale_t,1,0) -> 92.60931 | D8: =Declarations!$C$15+(Declarations!$H$15-Declarations!$C$15)*EXP(-Declarations!$D$15*$B8)+IF(Declarations!$E$15=0,0,Declarations!$E$15*($B8/Declarations!$F$15)*EXP(1-$B8/Declarations!$F$15))+Declarations!$G$15*IF($B8>=Sale_t,1,0) -> 45.753229 | E8: =Declarations!$C$16+(Declarations!$H$16-Declarations!$C$16)*EXP(-Declarations!$D$16*$B8)+IF(Declarations!$E$16=0,0,Declarations!$E$16*($B8/Declarations!$F$16)*EXP(1-$B8/Declarations!$F$16))+Declarations!$G$16*IF($B8>=Sale_t,1,0) -> 68.253555 | F8: =Declarations!$C$17+(Declarations!$H$17-Declarations!$C$17)*EXP(-Declarations!$D$17*$B8)+IF(Declarations!$E$17=0,0,Declarations!$E$17*($B8/Declarations!$F$17)*EXP(1-$B8/Declarations!$F$17))+Declarations!$G$17*IF($B8>=Sale_t,1,0) -> 69.200179 | G8: =Declarations!$C$18+(Declarations!$H$18-Declarations!$C$18)*EXP(-Declarations!$D$18*$B8)+IF(Declarations!$E$18=0,0,Declarations!$E$18*($B8/Declarations!$F$18)*EXP(1-$B8/Declarations!$F$18))+Declarations!$G$18*IF($B8>=Sale_t,1,0) -> 100.28903 | H8: =Declarations!$C$19+(Declarations!$H$19-Declarations!$C$19)*EXP(-Declarations!$D$19*$B8)+IF(Declarations!$E$19=0,0,Declarations!$E$19*($B8/Declarations!$F$19)*EXP(1-$B8/Declarations!$F$19))+Declarations!$G$19*IF($B8>=Sale_t,1,0) -> 40.818239 | I8: =Declarations!$C$20+(Declarations!$H$20-Declarations!$C$20)*EXP(-Declarations!$D$20*$B8)+IF(Declarations!$E$20=0,0,Declarations!$E$20*($B8/Declarations!$F$20)*EXP(1-$B8/Declarations!$F$20))+Declarations!$G$20*IF($B8>=Sale_t,1,0) -> 71.319208 | J8: =Declarations!$C$21+(Declarations!$H$21-Declarations!$C$21)*EXP(-Declarations!$D$21*$B8)+IF(Declarations!$E$21=0,0,Declarations!$E$21*($B8/Declarations!$F$21)*EXP(1-$B8/Declarations!$F$21))+Declarations!$G$21*IF($B8>=Sale_t,1,0) -> 63.329751 | K8: =Declarations!$C$22+(Declarations!$H$22-Declarations!$C$22)*EXP(-Declarations!$D$22*$B8)+IF(Declarations!$E$22=0,0,Declarations!$E$22*($B8/Declarations!$F$22)*EXP(1-$B8/Declarations!$F$22))+Declarations!$G$22*IF($B8>=Sale_t,1,0) -> 100.63842 | L8: =Declarations!$C$23+(Declarations!$H$23-Declarations!$C$23)*EXP(-Declarations!$D$23*$B8)+IF(Declarations!$E$23=0,0,Declarations!$E$23*($B8/Declarations!$F$23)*EXP(1-$B8/Declarations!$F$23))+Declarations!$G$23*IF($B8>=Sale_t,1,0) -> 40.609835 | M8: =Declarations!$C$24+(Declarations!$H$24-Declarations!$C$24)*EXP(-Declarations!$D$24*$B8)+IF(Declarations!$E$24=0,0,Declarations!$E$24*($B8/Declarations!$F$24)*EXP(1-$B8/Declarations!$F$24))+Declarations!$G$24*IF($B8>=Sale_t,1,0) -> 72.114336 | N8: =Declarations!$C$25+(Declarations!$H$25-Declarations!$C$25)*EXP(-Declarations!$D$25*$B8)+IF(Declarations!$E$25=0,0,Declarations!$E$25*($B8/Declarations!$F$25)*EXP(1-$B8/Declarations!$F$25))+Declarations!$G$25*IF($B8>=Sale_t,1,0) -> 64.21677 | O8: =W_L*S_L*C8+W_T*S_T*D8+W_E*S_E*E8+W_R*S_R*F8 -> 34.353979 | P8: =W_L*S_L*G8+W_T*S_T*H8+W_E*S_E*I8+W_R*S_R*J8 -> 37.274181 | Q8: =W_L*S_L*K8+W_T*S_T*L8+W_E*S_E*M8+W_R*S_R*N8 -> 37.286454 | R8: =IF(O8<Score_today,1,0) -> 1 | S8: =IF(O8>Q8,1,0) -> 0 | T8: =IF(O8>P8,1,0) -> 0 | U8: =1+IF(P8>O8,1,0)+IF(Q8>O8,1,0) -> 3 | V8: =ABS(P8-Q8) -> 0.012273933 | X8: Digital's score that month | Y8: =INDEX($O$5:$O$65,Y7+1) -> 37.18741 | Z8: 37.19
A9: 4 | B9: =A9/12 -> 0.33333333 | C9: =Declarations!$C$14+(Declarations!$H$14-Declarations!$C$14)*EXP(-Declarations!$D$14*$B9)+IF(Declarations!$E$14=0,0,Declarations!$E$14*($B9/Declarations!$F$14)*EXP(1-$B9/Declarations!$F$14))+Declarations!$G$14*IF($B9>=Sale_t,1,0) -> 90.583531 | D9: =Declarations!$C$15+(Declarations!$H$15-Declarations!$C$15)*EXP(-Declarations!$D$15*$B9)+IF(Declarations!$E$15=0,0,Declarations!$E$15*($B9/Declarations!$F$15)*EXP(1-$B9/Declarations!$F$15))+Declarations!$G$15*IF($B9>=Sale_t,1,0) -> 47.197847 | E9: =Declarations!$C$16+(Declarations!$H$16-Declarations!$C$16)*EXP(-Declarations!$D$16*$B9)+IF(Declarations!$E$16=0,0,Declarations!$E$16*($B9/Declarations!$F$16)*EXP(1-$B9/Declarations!$F$16))+Declarations!$G$16*IF($B9>=Sale_t,1,0) -> 67.56785 | F9: =Declarations!$C$17+(Declarations!$H$17-Declarations!$C$17)*EXP(-Declarations!$D$17*$B9)+IF(Declarations!$E$17=0,0,Declarations!$E$17*($B9/Declarations!$F$17)*EXP(1-$B9/Declarations!$F$17))+Declarations!$G$17*IF($B9>=Sale_t,1,0) -> 70.38449 | G9: =Declarations!$C$18+(Declarations!$H$18-Declarations!$C$18)*EXP(-Declarations!$D$18*$B9)+IF(Declarations!$E$18=0,0,Declarations!$E$18*($B9/Declarations!$F$18)*EXP(1-$B9/Declarations!$F$18))+Declarations!$G$18*IF($B9>=Sale_t,1,0) -> 100.38065 | H9: =Declarations!$C$19+(Declarations!$H$19-Declarations!$C$19)*EXP(-Declarations!$D$19*$B9)+IF(Declarations!$E$19=0,0,Declarations!$E$19*($B9/Declarations!$F$19)*EXP(1-$B9/Declarations!$F$19))+Declarations!$G$19*IF($B9>=Sale_t,1,0) -> 40.760133 | I9: =Declarations!$C$20+(Declarations!$H$20-Declarations!$C$20)*EXP(-Declarations!$D$20*$B9)+IF(Declarations!$E$20=0,0,Declarations!$E$20*($B9/Declarations!$F$20)*EXP(1-$B9/Declarations!$F$20))+Declarations!$G$20*IF($B9>=Sale_t,1,0) -> 71.417876 | J9: =Declarations!$C$21+(Declarations!$H$21-Declarations!$C$21)*EXP(-Declarations!$D$21*$B9)+IF(Declarations!$E$21=0,0,Declarations!$E$21*($B9/Declarations!$F$21)*EXP(1-$B9/Declarations!$F$21))+Declarations!$G$21*IF($B9>=Sale_t,1,0) -> 63.119054 | K9: =Declarations!$C$22+(Declarations!$H$22-Declarations!$C$22)*EXP(-Declarations!$D$22*$B9)+IF(Declarations!$E$22=0,0,Declarations!$E$22*($B9/Declarations!$F$22)*EXP(1-$B9/Declarations!$F$22))+Declarations!$G$22*IF($B9>=Sale_t,1,0) -> 100.83575 | L9: =Declarations!$C$23+(Declarations!$H$23-Declarations!$C$23)*EXP(-Declarations!$D$23*$B9)+IF(Declarations!$E$23=0,0,Declarations!$E$23*($B9/Declarations!$F$23)*EXP(1-$B9/Declarations!$F$23))+Declarations!$G$23*IF($B9>=Sale_t,1,0) -> 40.484056 | M9: =Declarations!$C$24+(Declarations!$H$24-Declarations!$C$24)*EXP(-Declarations!$D$24*$B9)+IF(Declarations!$E$24=0,0,Declarations!$E$24*($B9/Declarations!$F$24)*EXP(1-$B9/Declarations!$F$24))+Declarations!$G$24*IF($B9>=Sale_t,1,0) -> 72.450154 | N9: =Declarations!$C$25+(Declarations!$H$25-Declarations!$C$25)*EXP(-Declarations!$D$25*$B9)+IF(Declarations!$E$25=0,0,Declarations!$E$25*($B9/Declarations!$F$25)*EXP(1-$B9/Declarations!$F$25))+Declarations!$G$25*IF($B9>=Sale_t,1,0) -> 64.285488 | O9: =W_L*S_L*C9+W_T*S_T*D9+W_E*S_E*E9+W_R*S_R*F9 -> 33.741185 | P9: =W_L*S_L*G9+W_T*S_T*H9+W_E*S_E*I9+W_R*S_R*J9 -> 37.359901 | Q9: =W_L*S_L*K9+W_T*S_T*L9+W_E*S_E*M9+W_R*S_R*N9 -> 37.371119 | R9: =IF(O9<Score_today,1,0) -> 1 | S9: =IF(O9>Q9,1,0) -> 0 | T9: =IF(O9>P9,1,0) -> 0 | U9: =1+IF(P9>O9,1,0)+IF(Q9>O9,1,0) -> 3 | V9: =ABS(P9-Q9) -> 0.011217194 | X9: Month digital passes the turnaround | Y9: =INDEX($A$5:$A$65,MATCH(1,$S$5:$S$65,0)) -> 33 | Z9: month 33
A10: 5 | B10: =A10/12 -> 0.41666667 | C10: =Declarations!$C$14+(Declarations!$H$14-Declarations!$C$14)*EXP(-Declarations!$D$14*$B10)+IF(Declarations!$E$14=0,0,Declarations!$E$14*($B10/Declarations!$F$14)*EXP(1-$B10/Declarations!$F$14))+Declarations!$G$14*IF($B10>=Sale_t,1,0) -> 88.753794 | D10: =Declarations!$C$15+(Declarations!$H$15-Declarations!$C$15)*EXP(-Declarations!$D$15*$B10)+IF(Declarations!$E$15=0,0,Declarations!$E$15*($B10/Declarations!$F$15)*EXP(1-$B10/Declarations!$F$15))+Declarations!$G$15*IF($B10>=Sale_t,1,0) -> 48.577748 | E10: =Declarations!$C$16+(Declarations!$H$16-Declarations!$C$16)*EXP(-Declarations!$D$16*$B10)+IF(Declarations!$E$16=0,0,Declarations!$E$16*($B10/Declarations!$F$16)*EXP(1-$B10/Declarations!$F$16))+Declarations!$G$16*IF($B10>=Sale_t,1,0) -> 66.980873 | F10: =Declarations!$C$17+(Declarations!$H$17-Declarations!$C$17)*EXP(-Declarations!$D$17*$B10)+IF(Declarations!$E$17=0,0,Declarations!$E$17*($B10/Declarations!$F$17)*EXP(1-$B10/Declarations!$F$17))+Declarations!$G$17*IF($B10>=Sale_t,1,0) -> 71.341821 | G10: =Declarations!$C$18+(Declarations!$H$18-Declarations!$C$18)*EXP(-Declarations!$D$18*$B10)+IF(Declarations!$E$18=0,0,Declarations!$E$18*($B10/Declarations!$F$18)*EXP(1-$B10/Declarations!$F$18))+Declarations!$G$18*IF($B10>=Sale_t,1,0) -> 100.47001 | H10: =Declarations!$C$19+(Declarations!$H$19-Declarations!$C$19)*EXP(-Declarations!$D$19*$B10)+IF(Declarations!$E$19=0,0,Declarations!$E$19*($B10/Declarations!$F$19)*EXP(1-$B10/Declarations!$F$19))+Declarations!$G$19*IF($B10>=Sale_t,1,0) -> 40.703225 | I10: =Declarations!$C$20+(Declarations!$H$20-Declarations!$C$20)*EXP(-Declarations!$D$20*$B10)+IF(Declarations!$E$20=0,0,Declarations!$E$20*($B10/Declarations!$F$20)*EXP(1-$B10/Declarations!$F$20))+Declarations!$G$20*IF($B10>=Sale_t,1,0) -> 71.512913 | J10: =Declarations!$C$21+(Declarations!$H$21-Declarations!$C$21)*EXP(-Declarations!$D$21*$B10)+IF(Declarations!$E$21=0,0,Declarations!$E$21*($B10/Declarations!$F$21)*EXP(1-$B10/Declarations!$F$21))+Declarations!$G$21*IF($B10>=Sale_t,1,0) -> 62.914414 | K10: =Declarations!$C$22+(Declarations!$H$22-Declarations!$C$22)*EXP(-Declarations!$D$22*$B10)+IF(Declarations!$E$22=0,0,Declarations!$E$22*($B10/Declarations!$F$22)*EXP(1-$B10/Declarations!$F$22))+Declarations!$G$22*IF($B10>=Sale_t,1,0) -> 101.02583 | L10: =Declarations!$C$23+(Declarations!$H$23-Declarations!$C$23)*EXP(-Declarations!$D$23*$B10)+IF(Declarations!$E$23=0,0,Declarations!$E$23*($B10/Declarations!$F$23)*EXP(1-$B10/Declarations!$F$23))+Declarations!$G$23*IF($B10>=Sale_t,1,0) -> 40.360355 | M10: =Declarations!$C$24+(Declarations!$H$24-Declarations!$C$24)*EXP(-Declarations!$D$24*$B10)+IF(Declarations!$E$24=0,0,Declarations!$E$24*($B10/Declarations!$F$24)*EXP(1-$B10/Declarations!$F$24))+Declarations!$G$24*IF($B10>=Sale_t,1,0) -> 72.769594 | N10: =Declarations!$C$25+(Declarations!$H$25-Declarations!$C$25)*EXP(-Declarations!$D$25*$B10)+IF(Declarations!$E$25=0,0,Declarations!$E$25*($B10/Declarations!$F$25)*EXP(1-$B10/Declarations!$F$25))+Declarations!$G$25*IF($B10>=Sale_t,1,0) -> 64.352509 | O10: =W_L*S_L*C10+W_T*S_T*D10+W_E*S_E*E10+W_R*S_R*F10 -> 33.242648 | P10: =W_L*S_L*G10+W_T*S_T*H10+W_E*S_E*I10+W_R*S_R*J10 -> 37.442934 | Q10: =W_L*S_L*K10+W_T*S_T*L10+W_E*S_E*M10+W_R*S_R*N10 -> 37.450816 | R10: =IF(O10<Score_today,1,0) -> 1 | S10: =IF(O10>Q10,1,0) -> 0 | T10: =IF(O10>P10,1,0) -> 0 | U10: =1+IF(P10>O10,1,0)+IF(Q10>O10,1,0) -> 3 | V10: =ABS(P10-Q10) -> 0.0078821577 | X10: Digital's score that month | Y10: =INDEX($O$5:$O$65,Y9+1) -> 38.742683 | Z10: 38.74
A11: 6 | B11: =A11/12 -> 0.5 | C11: =Declarations!$C$14+(Declarations!$H$14-Declarations!$C$14)*EXP(-Declarations!$D$14*$B11)+IF(Declarations!$E$14=0,0,Declarations!$E$14*($B11/Declarations!$F$14)*EXP(1-$B11/Declarations!$F$14))+Declarations!$G$14*IF($B11>=Sale_t,1,0) -> 87.107516 | D11: =Declarations!$C$15+(Declarations!$H$15-Declarations!$C$15)*EXP(-Declarations!$D$15*$B11)+IF(Declarations!$E$15=0,0,Declarations!$E$15*($B11/Declarations!$F$15)*EXP(1-$B11/Declarations!$F$15))+Declarations!$G$15*IF($B11>=Sale_t,1,0) -> 49.895831 | E11: =Declarations!$C$16+(Declarations!$H$16-Declarations!$C$16)*EXP(-Declarations!$D$16*$B11)+IF(Declarations!$E$16=0,0,Declarations!$E$16*($B11/Declarations!$F$16)*EXP(1-$B11/Declarations!$F$16))+Declarations!$G$16*IF($B11>=Sale_t,1,0) -> 66.483993 | F11: =Declarations!$C$17+(Declarations!$H$17-Declarations!$C$17)*EXP(-Declarations!$D$17*$B11)+IF(Declarations!$E$17=0,0,Declarations!$E$17*($B11/Declarations!$F$17)*EXP(1-$B11/Declarations!$F$17))+Declarations!$G$17*IF($B11>=Sale_t,1,0) -> 72.096844 | G11: =Declarations!$C$18+(Declarations!$H$18-Declarations!$C$18)*EXP(-Declarations!$D$18*$B11)+IF(Declarations!$E$18=0,0,Declarations!$E$18*($B11/Declarations!$F$18)*EXP(1-$B11/Declarations!$F$18))+Declarations!$G$18*IF($B11>=Sale_t,1,0) -> 100.55717 | H11: =Declarations!$C$19+(Declarations!$H$19-Declarations!$C$19)*EXP(-Declarations!$D$19*$B11)+IF(Declarations!$E$19=0,0,Declarations!$E$19*($B11/Declarations!$F$19)*EXP(1-$B11/Declarations!$F$19))+Declarations!$G$19*IF($B11>=Sale_t,1,0) -> 40.647491 | I11: =Declarations!$C$20+(Declarations!$H$20-Declarations!$C$20)*EXP(-Declarations!$D$20*$B11)+IF(Declarations!$E$20=0,0,Declarations!$E$20*($B11/Declarations!$F$20)*EXP(1-$B11/Declarations!$F$20))+Declarations!$G$20*IF($B11>=Sale_t,1,0) -> 71.604451 | J11: =Declarations!$C$21+(Declarations!$H$21-Declarations!$C$21)*EXP(-Declarations!$D$21*$B11)+IF(Declarations!$E$21=0,0,Declarations!$E$21*($B11/Declarations!$F$21)*EXP(1-$B11/Declarations!$F$21))+Declarations!$G$21*IF($B11>=Sale_t,1,0) -> 62.715656 | K11: =Declarations!$C$22+(Declarations!$H$22-Declarations!$C$22)*EXP(-Declarations!$D$22*$B11)+IF(Declarations!$E$22=0,0,Declarations!$E$22*($B11/Declarations!$F$22)*EXP(1-$B11/Declarations!$F$22))+Declarations!$G$22*IF($B11>=Sale_t,1,0) -> 101.2089 | L11: =Declarations!$C$23+(Declarations!$H$23-Declarations!$C$23)*EXP(-Declarations!$D$23*$B11)+IF(Declarations!$E$23=0,0,Declarations!$E$23*($B11/Declarations!$F$23)*EXP(1-$B11/Declarations!$F$23))+Declarations!$G$23*IF($B11>=Sale_t,1,0) -> 40.238699 | M11: =Declarations!$C$24+(Declarations!$H$24-Declarations!$C$24)*EXP(-Declarations!$D$24*$B11)+IF(Declarations!$E$24=0,0,Declarations!$E$24*($B11/Declarations!$F$24)*EXP(1-$B11/Declarations!$F$24))+Declarations!$G$24*IF($B11>=Sale_t,1,0) -> 73.073454 | N11: =Declarations!$C$25+(Declarations!$H$25-Declarations!$C$25)*EXP(-Declarations!$D$25*$B11)+IF(Declarations!$E$25=0,0,Declarations!$E$25*($B11/Declarations!$F$25)*EXP(1-$B11/Declarations!$F$25))+Declarations!$G$25*IF($B11>=Sale_t,1,0) -> 64.417876 | O11: =W_L*S_L*C11+W_T*S_T*D11+W_E*S_E*E11+W_R*S_R*F11 -> 32.847624 | P11: =W_L*S_L*G11+W_T*S_T*H11+W_E*S_E*I11+W_R*S_R*J11 -> 37.523363 | Q11: =W_L*S_L*K11+W_T*S_T*L11+W_E*S_E*M11+W_R*S_R*N11 -> 37.525795 | R11: =IF(O11<Score_today,1,0) -> 1 | S11: =IF(O11>Q11,1,0) -> 0 | T11: =IF(O11>P11,1,0) -> 0 | U11: =1+IF(P11>O11,1,0)+IF(Q11>O11,1,0) -> 3 | V11: =ABS(P11-Q11) -> 0.002431554 | X11: The turnaround's score that month | Y11: =INDEX($Q$5:$Q$65,Y9+1) -> 38.413313 | Z11: 38.41
A12: 7 | B12: =A12/12 -> 0.58333333 | C12: =Declarations!$C$14+(Declarations!$H$14-Declarations!$C$14)*EXP(-Declarations!$D$14*$B12)+IF(Declarations!$E$14=0,0,Declarations!$E$14*($B12/Declarations!$F$14)*EXP(1-$B12/Declarations!$F$14))+Declarations!$G$14*IF($B12>=Sale_t,1,0) -> 85.632816 | D12: =Declarations!$C$15+(Declarations!$H$15-Declarations!$C$15)*EXP(-Declarations!$D$15*$B12)+IF(Declarations!$E$15=0,0,Declarations!$E$15*($B12/Declarations!$F$15)*EXP(1-$B12/Declarations!$F$15))+Declarations!$G$15*IF($B12>=Sale_t,1,0) -> 51.154866 | E12: =Declarations!$C$16+(Declarations!$H$16-Declarations!$C$16)*EXP(-Declarations!$D$16*$B12)+IF(Declarations!$E$16=0,0,Declarations!$E$16*($B12/Declarations!$F$16)*EXP(1-$B12/Declarations!$F$16))+Declarations!$G$16*IF($B12>=Sale_t,1,0) -> 66.069224 | F12: =Declarations!$C$17+(Declarations!$H$17-Declarations!$C$17)*EXP(-Declarations!$D$17*$B12)+IF(Declarations!$E$17=0,0,Declarations!$E$17*($B12/Declarations!$F$17)*EXP(1-$B12/Declarations!$F$17))+Declarations!$G$17*IF($B12>=Sale_t,1,0) -> 72.671956 | G12: =Declarations!$C$18+(Declarations!$H$18-Declarations!$C$18)*EXP(-Declarations!$D$18*$B12)+IF(Declarations!$E$18=0,0,Declarations!$E$18*($B12/Declarations!$F$18)*EXP(1-$B12/Declarations!$F$18))+Declarations!$G$18*IF($B12>=Sale_t,1,0) -> 100.64217 | H12: =Declarations!$C$19+(Declarations!$H$19-Declarations!$C$19)*EXP(-Declarations!$D$19*$B12)+IF(Declarations!$E$19=0,0,Declarations!$E$19*($B12/Declarations!$F$19)*EXP(1-$B12/Declarations!$F$19))+Declarations!$G$19*IF($B12>=Sale_t,1,0) -> 40.592905 | I12: =Declarations!$C$20+(Declarations!$H$20-Declarations!$C$20)*EXP(-Declarations!$D$20*$B12)+IF(Declarations!$E$20=0,0,Declarations!$E$20*($B12/Declarations!$F$20)*EXP(1-$B12/Declarations!$F$20))+Declarations!$G$20*IF($B12>=Sale_t,1,0) -> 71.692621 | J12: =Declarations!$C$21+(Declarations!$H$21-Declarations!$C$21)*EXP(-Declarations!$D$21*$B12)+IF(Declarations!$E$21=0,0,Declarations!$E$21*($B12/Declarations!$F$21)*EXP(1-$B12/Declarations!$F$21))+Declarations!$G$21*IF($B12>=Sale_t,1,0) -> 62.522612 | K12: =Declarations!$C$22+(Declarations!$H$22-Declarations!$C$22)*EXP(-Declarations!$D$22*$B12)+IF(Declarations!$E$22=0,0,Declarations!$E$22*($B12/Declarations!$F$22)*EXP(1-$B12/Declarations!$F$22))+Declarations!$G$22*IF($B12>=Sale_t,1,0) -> 101.38524 | L12: =Declarations!$C$23+(Declarations!$H$23-Declarations!$C$23)*EXP(-Declarations!$D$23*$B12)+IF(Declarations!$E$23=0,0,Declarations!$E$23*($B12/Declarations!$F$23)*EXP(1-$B12/Declarations!$F$23))+Declarations!$G$23*IF($B12>=Sale_t,1,0) -> 40.119054 | M12: =Declarations!$C$24+(Declarations!$H$24-Declarations!$C$24)*EXP(-Declarations!$D$24*$B12)+IF(Declarations!$E$24=0,0,Declarations!$E$24*($B12/Declarations!$F$24)*EXP(1-$B12/Declarations!$F$24))+Declarations!$G$24*IF($B12>=Sale_t,1,0) -> 73.362495 | N12: =Declarations!$C$25+(Declarations!$H$25-Declarations!$C$25)*EXP(-Declarations!$D$25*$B12)+IF(Declarations!$E$25=0,0,Declarations!$E$25*($B12/Declarations!$F$25)*EXP(1-$B12/Declarations!$F$25))+Declarations!$G$25*IF($B12>=Sale_t,1,0) -> 64.481629 | O12: =W_L*S_L*C12+W_T*S_T*D12+W_E*S_E*E12+W_R*S_R*F12 -> 32.546237 | P12: =W_L*S_L*G12+W_T*S_T*H12+W_E*S_E*I12+W_R*S_R*J12 -> 37.601272 | Q12: =W_L*S_L*K12+W_T*S_T*L12+W_E*S_E*M12+W_R*S_R*N12 -> 37.596291 | R12: =IF(O12<Score_today,1,0) -> 1 | S12: =IF(O12>Q12,1,0) -> 0 | T12: =IF(O12>P12,1,0) -> 0 | U12: =1+IF(P12>O12,1,0)+IF(Q12>O12,1,0) -> 3 | V12: =ABS(P12-Q12) -> 0.0049809863 | X12: Month digital passes restructuring | Y12: =INDEX($A$5:$A$65,MATCH(1,$T$5:$T$65,0)) -> 56 | Z12: month 56
A13: 8 | B13: =A13/12 -> 0.66666667 | C13: =Declarations!$C$14+(Declarations!$H$14-Declarations!$C$14)*EXP(-Declarations!$D$14*$B13)+IF(Declarations!$E$14=0,0,Declarations!$E$14*($B13/Declarations!$F$14)*EXP(1-$B13/Declarations!$F$14))+Declarations!$G$14*IF($B13>=Sale_t,1,0) -> 84.318474 | D13: =Declarations!$C$15+(Declarations!$H$15-Declarations!$C$15)*EXP(-Declarations!$D$15*$B13)+IF(Declarations!$E$15=0,0,Declarations!$E$15*($B13/Declarations!$F$15)*EXP(1-$B13/Declarations!$F$15))+Declarations!$G$15*IF($B13>=Sale_t,1,0) -> 52.357497 | E13: =Declarations!$C$16+(Declarations!$H$16-Declarations!$C$16)*EXP(-Declarations!$D$16*$B13)+IF(Declarations!$E$16=0,0,Declarations!$E$16*($B13/Declarations!$F$16)*EXP(1-$B13/Declarations!$F$16))+Declarations!$G$16*IF($B13>=Sale_t,1,0) -> 65.729176 | F13: =Declarations!$C$17+(Declarations!$H$17-Declarations!$C$17)*EXP(-Declarations!$D$17*$B13)+IF(Declarations!$E$17=0,0,Declarations!$E$17*($B13/Declarations!$F$17)*EXP(1-$B13/Declarations!$F$17))+Declarations!$G$17*IF($B13>=Sale_t,1,0) -> 73.087473 | G13: =Declarations!$C$18+(Declarations!$H$18-Declarations!$C$18)*EXP(-Declarations!$D$18*$B13)+IF(Declarations!$E$18=0,0,Declarations!$E$18*($B13/Declarations!$F$18)*EXP(1-$B13/Declarations!$F$18))+Declarations!$G$18*IF($B13>=Sale_t,1,0) -> 100.72508 | H13: =Declarations!$C$19+(Declarations!$H$19-Declarations!$C$19)*EXP(-Declarations!$D$19*$B13)+IF(Declarations!$E$19=0,0,Declarations!$E$19*($B13/Declarations!$F$19)*EXP(1-$B13/Declarations!$F$19))+Declarations!$G$19*IF($B13>=Sale_t,1,0) -> 40.539445 | I13: =Declarations!$C$20+(Declarations!$H$20-Declarations!$C$20)*EXP(-Declarations!$D$20*$B13)+IF(Declarations!$E$20=0,0,Declarations!$E$20*($B13/Declarations!$F$20)*EXP(1-$B13/Declarations!$F$20))+Declarations!$G$20*IF($B13>=Sale_t,1,0) -> 71.777545 | J13: =Declarations!$C$21+(Declarations!$H$21-Declarations!$C$21)*EXP(-Declarations!$D$21*$B13)+IF(Declarations!$E$21=0,0,Declarations!$E$21*($B13/Declarations!$F$21)*EXP(1-$B13/Declarations!$F$21))+Declarations!$G$21*IF($B13>=Sale_t,1,0) -> 62.335117 | K13: =Declarations!$C$22+(Declarations!$H$22-Declarations!$C$22)*EXP(-Declarations!$D$22*$B13)+IF(Declarations!$E$22=0,0,Declarations!$E$22*($B13/Declarations!$F$22)*EXP(1-$B13/Declarations!$F$22))+Declarations!$G$22*IF($B13>=Sale_t,1,0) -> 101.55509 | L13: =Declarations!$C$23+(Declarations!$H$23-Declarations!$C$23)*EXP(-Declarations!$D$23*$B13)+IF(Declarations!$E$23=0,0,Declarations!$E$23*($B13/Declarations!$F$23)*EXP(1-$B13/Declarations!$F$23))+Declarations!$G$23*IF($B13>=Sale_t,1,0) -> 40.001387 | M13: =Declarations!$C$24+(Declarations!$H$24-Declarations!$C$24)*EXP(-Declarations!$D$24*$B13)+IF(Declarations!$E$24=0,0,Declarations!$E$24*($B13/Declarations!$F$24)*EXP(1-$B13/Declarations!$F$24))+Declarations!$G$24*IF($B13>=Sale_t,1,0) -> 73.63744 | N13: =Declarations!$C$25+(Declarations!$H$25-Declarations!$C$25)*EXP(-Declarations!$D$25*$B13)+IF(Declarations!$E$25=0,0,Declarations!$E$25*($B13/Declarations!$F$25)*EXP(1-$B13/Declarations!$F$25))+Declarations!$G$25*IF($B13>=Sale_t,1,0) -> 64.543808 | O13: =W_L*S_L*C13+W_T*S_T*D13+W_E*S_E*E13+W_R*S_R*F13 -> 32.329418 | P13: =W_L*S_L*G13+W_T*S_T*H13+W_E*S_E*I13+W_R*S_R*J13 -> 37.676738 | Q13: =W_L*S_L*K13+W_T*S_T*L13+W_E*S_E*M13+W_R*S_R*N13 -> 37.662527 | R13: =IF(O13<Score_today,1,0) -> 1 | S13: =IF(O13>Q13,1,0) -> 0 | T13: =IF(O13>P13,1,0) -> 0 | U13: =1+IF(P13>O13,1,0)+IF(Q13>O13,1,0) -> 3 | V13: =ABS(P13-Q13) -> 0.014210463 | X13: Digital's score that month | Y13: =INDEX($O$5:$O$65,Y12+1) -> 46.145379 | Z13: 46.15
A14: 9 | B14: =A14/12 -> 0.75 | C14: =Declarations!$C$14+(Declarations!$H$14-Declarations!$C$14)*EXP(-Declarations!$D$14*$B14)+IF(Declarations!$E$14=0,0,Declarations!$E$14*($B14/Declarations!$F$14)*EXP(1-$B14/Declarations!$F$14))+Declarations!$G$14*IF($B14>=Sale_t,1,0) -> 83.153901 | D14: =Declarations!$C$15+(Declarations!$H$15-Declarations!$C$15)*EXP(-Declarations!$D$15*$B14)+IF(Declarations!$E$15=0,0,Declarations!$E$15*($B14/Declarations!$F$15)*EXP(1-$B14/Declarations!$F$15))+Declarations!$G$15*IF($B14>=Sale_t,1,0) -> 53.506252 | E14: =Declarations!$C$16+(Declarations!$H$16-Declarations!$C$16)*EXP(-Declarations!$D$16*$B14)+IF(Declarations!$E$16=0,0,Declarations!$E$16*($B14/Declarations!$F$16)*EXP(1-$B14/Declarations!$F$16))+Declarations!$G$16*IF($B14>=Sale_t,1,0) -> 65.457019 | F14: =Declarations!$C$17+(Declarations!$H$17-Declarations!$C$17)*EXP(-Declarations!$D$17*$B14)+IF(Declarations!$E$17=0,0,Declarations!$E$17*($B14/Declarations!$F$17)*EXP(1-$B14/Declarations!$F$17))+Declarations!$G$17*IF($B14>=Sale_t,1,0) -> 73.361812 | G14: =Declarations!$C$18+(Declarations!$H$18-Declarations!$C$18)*EXP(-Declarations!$D$18*$B14)+IF(Declarations!$E$18=0,0,Declarations!$E$18*($B14/Declarations!$F$18)*EXP(1-$B14/Declarations!$F$18))+Declarations!$G$18*IF($B14>=Sale_t,1,0) -> 100.80594 | H14: =Declarations!$C$19+(Declarations!$H$19-Declarations!$C$19)*EXP(-Declarations!$D$19*$B14)+IF(Declarations!$E$19=0,0,Declarations!$E$19*($B14/Declarations!$F$19)*EXP(1-$B14/Declarations!$F$19))+Declarations!$G$19*IF($B14>=Sale_t,1,0) -> 40.487087 | I14: =Declarations!$C$20+(Declarations!$H$20-Declarations!$C$20)*EXP(-Declarations!$D$20*$B14)+IF(Declarations!$E$20=0,0,Declarations!$E$20*($B14/Declarations!$F$20)*EXP(1-$B14/Declarations!$F$20))+Declarations!$G$20*IF($B14>=Sale_t,1,0) -> 71.859344 | J14: =Declarations!$C$21+(Declarations!$H$21-Declarations!$C$21)*EXP(-Declarations!$D$21*$B14)+IF(Declarations!$E$21=0,0,Declarations!$E$21*($B14/Declarations!$F$21)*EXP(1-$B14/Declarations!$F$21))+Declarations!$G$21*IF($B14>=Sale_t,1,0) -> 62.153011 | K14: =Declarations!$C$22+(Declarations!$H$22-Declarations!$C$22)*EXP(-Declarations!$D$22*$B14)+IF(Declarations!$E$22=0,0,Declarations!$E$22*($B14/Declarations!$F$22)*EXP(1-$B14/Declarations!$F$22))+Declarations!$G$22*IF($B14>=Sale_t,1,0) -> 101.71869 | L14: =Declarations!$C$23+(Declarations!$H$23-Declarations!$C$23)*EXP(-Declarations!$D$23*$B14)+IF(Declarations!$E$23=0,0,Declarations!$E$23*($B14/Declarations!$F$23)*EXP(1-$B14/Declarations!$F$23))+Declarations!$G$23*IF($B14>=Sale_t,1,0) -> 39.885664 | M14: =Declarations!$C$24+(Declarations!$H$24-Declarations!$C$24)*EXP(-Declarations!$D$24*$B14)+IF(Declarations!$E$24=0,0,Declarations!$E$24*($B14/Declarations!$F$24)*EXP(1-$B14/Declarations!$F$24))+Declarations!$G$24*IF($B14>=Sale_t,1,0) -> 73.898975 | N14: =Declarations!$C$25+(Declarations!$H$25-Declarations!$C$25)*EXP(-Declarations!$D$25*$B14)+IF(Declarations!$E$25=0,0,Declarations!$E$25*($B14/Declarations!$F$25)*EXP(1-$B14/Declarations!$F$25))+Declarations!$G$25*IF($B14>=Sale_t,1,0) -> 64.604451 | O14: =W_L*S_L*C14+W_T*S_T*D14+W_E*S_E*E14+W_R*S_R*F14 -> 32.18884 | P14: =W_L*S_L*G14+W_T*S_T*H14+W_E*S_E*I14+W_R*S_R*J14 -> 37.749839 | Q14: =W_L*S_L*K14+W_T*S_T*L14+W_E*S_E*M14+W_R*S_R*N14 -> 37.724719 | R14: =IF(O14<Score_today,1,0) -> 1 | S14: =IF(O14>Q14,1,0) -> 0 | T14: =IF(O14>P14,1,0) -> 0 | U14: =1+IF(P14>O14,1,0)+IF(Q14>O14,1,0) -> 3 | V14: =ABS(P14-Q14) -> 0.025120058 | X14: Restructuring's score that month | Y14: =INDEX($P$5:$P$65,Y12+1) -> 46.004558
A15: 10 | B15: =A15/12 -> 0.83333333 | C15: =Declarations!$C$14+(Declarations!$H$14-Declarations!$C$14)*EXP(-Declarations!$D$14*$B15)+IF(Declarations!$E$14=0,0,Declarations!$E$14*($B15/Declarations!$F$14)*EXP(1-$B15/Declarations!$F$14))+Declarations!$G$14*IF($B15>=Sale_t,1,0) -> 82.129102 | D15: =Declarations!$C$15+(Declarations!$H$15-Declarations!$C$15)*EXP(-Declarations!$D$15*$B15)+IF(Declarations!$E$15=0,0,Declarations!$E$15*($B15/Declarations!$F$15)*EXP(1-$B15/Declarations!$F$15))+Declarations!$G$15*IF($B15>=Sale_t,1,0) -> 54.603543 | E15: =Declarations!$C$16+(Declarations!$H$16-Declarations!$C$16)*EXP(-Declarations!$D$16*$B15)+IF(Declarations!$E$16=0,0,Declarations!$E$16*($B15/Declarations!$F$16)*EXP(1-$B15/Declarations!$F$16))+Declarations!$G$16*IF($B15>=Sale_t,1,0) -> 65.246439 | F15: =Declarations!$C$17+(Declarations!$H$17-Declarations!$C$17)*EXP(-Declarations!$D$17*$B15)+IF(Declarations!$E$17=0,0,Declarations!$E$17*($B15/Declarations!$F$17)*EXP(1-$B15/Declarations!$F$17))+Declarations!$G$17*IF($B15>=Sale_t,1,0) -> 73.511646 | G15: =Declarations!$C$18+(Declarations!$H$18-Declarations!$C$18)*EXP(-Declarations!$D$18*$B15)+IF(Declarations!$E$18=0,0,Declarations!$E$18*($B15/Declarations!$F$18)*EXP(1-$B15/Declarations!$F$18))+Declarations!$G$18*IF($B15>=Sale_t,1,0) -> 100.8848 | H15: =Declarations!$C$19+(Declarations!$H$19-Declarations!$C$19)*EXP(-Declarations!$D$19*$B15)+IF(Declarations!$E$19=0,0,Declarations!$E$19*($B15/Declarations!$F$19)*EXP(1-$B15/Declarations!$F$19))+Declarations!$G$19*IF($B15>=Sale_t,1,0) -> 40.435809 | I15: =Declarations!$C$20+(Declarations!$H$20-Declarations!$C$20)*EXP(-Declarations!$D$20*$B15)+IF(Declarations!$E$20=0,0,Declarations!$E$20*($B15/Declarations!$F$20)*EXP(1-$B15/Declarations!$F$20))+Declarations!$G$20*IF($B15>=Sale_t,1,0) -> 71.938132 | J15: =Declarations!$C$21+(Declarations!$H$21-Declarations!$C$21)*EXP(-Declarations!$D$21*$B15)+IF(Declarations!$E$21=0,0,Declarations!$E$21*($B15/Declarations!$F$21)*EXP(1-$B15/Declarations!$F$21))+Declarations!$G$21*IF($B15>=Sale_t,1,0) -> 61.97614 | K15: =Declarations!$C$22+(Declarations!$H$22-Declarations!$C$22)*EXP(-Declarations!$D$22*$B15)+IF(Declarations!$E$22=0,0,Declarations!$E$22*($B15/Declarations!$F$22)*EXP(1-$B15/Declarations!$F$22))+Declarations!$G$22*IF($B15>=Sale_t,1,0) -> 101.87626 | L15: =Declarations!$C$23+(Declarations!$H$23-Declarations!$C$23)*EXP(-Declarations!$D$23*$B15)+IF(Declarations!$E$23=0,0,Declarations!$E$23*($B15/Declarations!$F$23)*EXP(1-$B15/Declarations!$F$23))+Declarations!$G$23*IF($B15>=Sale_t,1,0) -> 39.771854 | M15: =Declarations!$C$24+(Declarations!$H$24-Declarations!$C$24)*EXP(-Declarations!$D$24*$B15)+IF(Declarations!$E$24=0,0,Declarations!$E$24*($B15/Declarations!$F$24)*EXP(1-$B15/Declarations!$F$24))+Declarations!$G$24*IF($B15>=Sale_t,1,0) -> 74.147755 | N15: =Declarations!$C$25+(Declarations!$H$25-Declarations!$C$25)*EXP(-Declarations!$D$25*$B15)+IF(Declarations!$E$25=0,0,Declarations!$E$25*($B15/Declarations!$F$25)*EXP(1-$B15/Declarations!$F$25))+Declarations!$G$25*IF($B15>=Sale_t,1,0) -> 64.663598 | O15: =W_L*S_L*C15+W_T*S_T*D15+W_E*S_E*E15+W_R*S_R*F15 -> 32.116859 | P15: =W_L*S_L*G15+W_T*S_T*H15+W_E*S_E*I15+W_R*S_R*J15 -> 37.82065 | Q15: =W_L*S_L*K15+W_T*S_T*L15+W_E*S_E*M15+W_R*S_R*N15 -> 37.783069 | R15: =IF(O15<Score_today,1,0) -> 1 | S15: =IF(O15>Q15,1,0) -> 0 | T15: =IF(O15>P15,1,0) -> 0 | U15: =1+IF(P15>O15,1,0)+IF(Q15>O15,1,0) -> 3 | V15: =ABS(P15-Q15) -> 0.037580717 | X15: Restructuring's jump when the sale closes (month 12 less month 11) | Y15: =P17-P16 -> 6.5664434 | Z15: +6.57
A16: 11 | B16: =A16/12 -> 0.91666667 | C16: =Declarations!$C$14+(Declarations!$H$14-Declarations!$C$14)*EXP(-Declarations!$D$14*$B16)+IF(Declarations!$E$14=0,0,Declarations!$E$14*($B16/Declarations!$F$14)*EXP(1-$B16/Declarations!$F$14))+Declarations!$G$14*IF($B16>=Sale_t,1,0) -> 81.234648 | D16: =Declarations!$C$15+(Declarations!$H$15-Declarations!$C$15)*EXP(-Declarations!$D$15*$B16)+IF(Declarations!$E$15=0,0,Declarations!$E$15*($B16/Declarations!$F$15)*EXP(1-$B16/Declarations!$F$15))+Declarations!$G$15*IF($B16>=Sale_t,1,0) -> 55.651678 | E16: =Declarations!$C$16+(Declarations!$H$16-Declarations!$C$16)*EXP(-Declarations!$D$16*$B16)+IF(Declarations!$E$16=0,0,Declarations!$E$16*($B16/Declarations!$F$16)*EXP(1-$B16/Declarations!$F$16))+Declarations!$G$16*IF($B16>=Sale_t,1,0) -> 65.091607 | F16: =Declarations!$C$17+(Declarations!$H$17-Declarations!$C$17)*EXP(-Declarations!$D$17*$B16)+IF(Declarations!$E$17=0,0,Declarations!$E$17*($B16/Declarations!$F$17)*EXP(1-$B16/Declarations!$F$17))+Declarations!$G$17*IF($B16>=Sale_t,1,0) -> 73.552064 | G16: =Declarations!$C$18+(Declarations!$H$18-Declarations!$C$18)*EXP(-Declarations!$D$18*$B16)+IF(Declarations!$E$18=0,0,Declarations!$E$18*($B16/Declarations!$F$18)*EXP(1-$B16/Declarations!$F$18))+Declarations!$G$18*IF($B16>=Sale_t,1,0) -> 100.96171 | H16: =Declarations!$C$19+(Declarations!$H$19-Declarations!$C$19)*EXP(-Declarations!$D$19*$B16)+IF(Declarations!$E$19=0,0,Declarations!$E$19*($B16/Declarations!$F$19)*EXP(1-$B16/Declarations!$F$19))+Declarations!$G$19*IF($B16>=Sale_t,1,0) -> 40.385588 | I16: =Declarations!$C$20+(Declarations!$H$20-Declarations!$C$20)*EXP(-Declarations!$D$20*$B16)+IF(Declarations!$E$20=0,0,Declarations!$E$20*($B16/Declarations!$F$20)*EXP(1-$B16/Declarations!$F$20))+Declarations!$G$20*IF($B16>=Sale_t,1,0) -> 72.01402 | J16: =Declarations!$C$21+(Declarations!$H$21-Declarations!$C$21)*EXP(-Declarations!$D$21*$B16)+IF(Declarations!$E$21=0,0,Declarations!$E$21*($B16/Declarations!$F$21)*EXP(1-$B16/Declarations!$F$21))+Declarations!$G$21*IF($B16>=Sale_t,1,0) -> 61.804353 | K16: =Declarations!$C$22+(Declarations!$H$22-Declarations!$C$22)*EXP(-Declarations!$D$22*$B16)+IF(Declarations!$E$22=0,0,Declarations!$E$22*($B16/Declarations!$F$22)*EXP(1-$B16/Declarations!$F$22))+Declarations!$G$22*IF($B16>=Sale_t,1,0) -> 102.02804 | L16: =Declarations!$C$23+(Declarations!$H$23-Declarations!$C$23)*EXP(-Declarations!$D$23*$B16)+IF(Declarations!$E$23=0,0,Declarations!$E$23*($B16/Declarations!$F$23)*EXP(1-$B16/Declarations!$F$23))+Declarations!$G$23*IF($B16>=Sale_t,1,0) -> 39.659925 | M16: =Declarations!$C$24+(Declarations!$H$24-Declarations!$C$24)*EXP(-Declarations!$D$24*$B16)+IF(Declarations!$E$24=0,0,Declarations!$E$24*($B16/Declarations!$F$24)*EXP(1-$B16/Declarations!$F$24))+Declarations!$G$24*IF($B16>=Sale_t,1,0) -> 74.384402 | N16: =Declarations!$C$25+(Declarations!$H$25-Declarations!$C$25)*EXP(-Declarations!$D$25*$B16)+IF(Declarations!$E$25=0,0,Declarations!$E$25*($B16/Declarations!$F$25)*EXP(1-$B16/Declarations!$F$25))+Declarations!$G$25*IF($B16>=Sale_t,1,0) -> 64.721284 | O16: =W_L*S_L*C16+W_T*S_T*D16+W_E*S_E*E16+W_R*S_R*F16 -> 32.106467 | P16: =W_L*S_L*G16+W_T*S_T*H16+W_E*S_E*I16+W_R*S_R*J16 -> 37.889242 | Q16: =W_L*S_L*K16+W_T*S_T*L16+W_E*S_E*M16+W_R*S_R*N16 -> 37.837771 | R16: =IF(O16<Score_today,1,0) -> 1 | S16: =IF(O16>Q16,1,0) -> 0 | T16: =IF(O16>P16,1,0) -> 0 | U16: =1+IF(P16>O16,1,0)+IF(Q16>O16,1,0) -> 3 | V16: =ABS(P16-Q16) -> 0.05147074 | X16: Largest gap, restructuring and turnaround, before the sale | Y16: =MAX(V5:V16) -> 0.05147074 | Z16: less than 0.1 point
A17: 12 | B17: =A17/12 -> 1 | C17: =Declarations!$C$14+(Declarations!$H$14-Declarations!$C$14)*EXP(-Declarations!$D$14*$B17)+IF(Declarations!$E$14=0,0,Declarations!$E$14*($B17/Declarations!$F$14)*EXP(1-$B17/Declarations!$F$14))+Declarations!$G$14*IF($B17>=Sale_t,1,0) -> 80.461645 | D17: =Declarations!$C$15+(Declarations!$H$15-Declarations!$C$15)*EXP(-Declarations!$D$15*$B17)+IF(Declarations!$E$15=0,0,Declarations!$E$15*($B17/Declarations!$F$15)*EXP(1-$B17/Declarations!$F$15))+Declarations!$G$15*IF($B17>=Sale_t,1,0) -> 56.652857 | E17: =Declarations!$C$16+(Declarations!$H$16-Declarations!$C$16)*EXP(-Declarations!$D$16*$B17)+IF(Declarations!$E$16=0,0,Declarations!$E$16*($B17/Declarations!$F$16)*EXP(1-$B17/Declarations!$F$16))+Declarations!$G$16*IF($B17>=Sale_t,1,0) -> 64.987141 | F17: =Declarations!$C$17+(Declarations!$H$17-Declarations!$C$17)*EXP(-Declarations!$D$17*$B17)+IF(Declarations!$E$17=0,0,Declarations!$E$17*($B17/Declarations!$F$17)*EXP(1-$B17/Declarations!$F$17))+Declarations!$G$17*IF($B17>=Sale_t,1,0) -> 73.496699 | G17: =Declarations!$C$18+(Declarations!$H$18-Declarations!$C$18)*EXP(-Declarations!$D$18*$B17)+IF(Declarations!$E$18=0,0,Declarations!$E$18*($B17/Declarations!$F$18)*EXP(1-$B17/Declarations!$F$18))+Declarations!$G$18*IF($B17>=Sale_t,1,0) -> 119.03673 | H17: =Declarations!$C$19+(Declarations!$H$19-Declarations!$C$19)*EXP(-Declarations!$D$19*$B17)+IF(Declarations!$E$19=0,0,Declarations!$E$19*($B17/Declarations!$F$19)*EXP(1-$B17/Declarations!$F$19))+Declarations!$G$19*IF($B17>=Sale_t,1,0) -> 40.336402 | I17: =Declarations!$C$20+(Declarations!$H$20-Declarations!$C$20)*EXP(-Declarations!$D$20*$B17)+IF(Declarations!$E$20=0,0,Declarations!$E$20*($B17/Declarations!$F$20)*EXP(1-$B17/Declarations!$F$20))+Declarations!$G$20*IF($B17>=Sale_t,1,0) -> 72.087116 | J17: =Declarations!$C$21+(Declarations!$H$21-Declarations!$C$21)*EXP(-Declarations!$D$21*$B17)+IF(Declarations!$E$21=0,0,Declarations!$E$21*($B17/Declarations!$F$21)*EXP(1-$B17/Declarations!$F$21))+Declarations!$G$21*IF($B17>=Sale_t,1,0) -> 53.637505 | K17: =Declarations!$C$22+(Declarations!$H$22-Declarations!$C$22)*EXP(-Declarations!$D$22*$B17)+IF(Declarations!$E$22=0,0,Declarations!$E$22*($B17/Declarations!$F$22)*EXP(1-$B17/Declarations!$F$22))+Declarations!$G$22*IF($B17>=Sale_t,1,0) -> 102.17423 | L17: =Declarations!$C$23+(Declarations!$H$23-Declarations!$C$23)*EXP(-Declarations!$D$23*$B17)+IF(Declarations!$E$23=0,0,Declarations!$E$23*($B17/Declarations!$F$23)*EXP(1-$B17/Declarations!$F$23))+Declarations!$G$23*IF($B17>=Sale_t,1,0) -> 39.549846 | M17: =Declarations!$C$24+(Declarations!$H$24-Declarations!$C$24)*EXP(-Declarations!$D$24*$B17)+IF(Declarations!$E$24=0,0,Declarations!$E$24*($B17/Declarations!$F$24)*EXP(1-$B17/Declarations!$F$24))+Declarations!$G$24*IF($B17>=Sale_t,1,0) -> 74.609507 | N17: =Declarations!$C$25+(Declarations!$H$25-Declarations!$C$25)*EXP(-Declarations!$D$25*$B17)+IF(Declarations!$E$25=0,0,Declarations!$E$25*($B17/Declarations!$F$25)*EXP(1-$B17/Declarations!$F$25))+Declarations!$G$25*IF($B17>=Sale_t,1,0) -> 64.777545 | O17: =W_L*S_L*C17+W_T*S_T*D17+W_E*S_E*E17+W_R*S_R*F17 -> 32.151236 | P17: =W_L*S_L*G17+W_T*S_T*H17+W_E*S_E*I17+W_R*S_R*J17 -> 44.455685 | Q17: =W_L*S_L*K17+W_T*S_T*L17+W_E*S_E*M17+W_R*S_R*N17 -> 37.88901 | R17: =IF(O17<Score_today,1,0) -> 1 | S17: =IF(O17>Q17,1,0) -> 0 | T17: =IF(O17>P17,1,0) -> 0 | U17: =1+IF(P17>O17,1,0)+IF(Q17>O17,1,0) -> 3 | V17: =ABS(P17-Q17) -> 6.5666754
A18: 13 | B18: =A18/12 -> 1.0833333 | C18: =Declarations!$C$14+(Declarations!$H$14-Declarations!$C$14)*EXP(-Declarations!$D$14*$B18)+IF(Declarations!$E$14=0,0,Declarations!$E$14*($B18/Declarations!$F$14)*EXP(1-$B18/Declarations!$F$14))+Declarations!$G$14*IF($B18>=Sale_t,1,0) -> 79.801708 | D18: =Declarations!$C$15+(Declarations!$H$15-Declarations!$C$15)*EXP(-Declarations!$D$15*$B18)+IF(Declarations!$E$15=0,0,Declarations!$E$15*($B18/Declarations!$F$15)*EXP(1-$B18/Declarations!$F$15))+Declarations!$G$15*IF($B18>=Sale_t,1,0) -> 57.609184 | E18: =Declarations!$C$16+(Declarations!$H$16-Declarations!$C$16)*EXP(-Declarations!$D$16*$B18)+IF(Declarations!$E$16=0,0,Declarations!$E$16*($B18/Declarations!$F$16)*EXP(1-$B18/Declarations!$F$16))+Declarations!$G$16*IF($B18>=Sale_t,1,0) -> 64.92808 | F18: =Declarations!$C$17+(Declarations!$H$17-Declarations!$C$17)*EXP(-Declarations!$D$17*$B18)+IF(Declarations!$E$17=0,0,Declarations!$E$17*($B18/Declarations!$F$17)*EXP(1-$B18/Declarations!$F$17))+Declarations!$G$17*IF($B18>=Sale_t,1,0) -> 73.357862 | G18: =Declarations!$C$18+(Declarations!$H$18-Declarations!$C$18)*EXP(-Declarations!$D$18*$B18)+IF(Declarations!$E$18=0,0,Declarations!$E$18*($B18/Declarations!$F$18)*EXP(1-$B18/Declarations!$F$18))+Declarations!$G$18*IF($B18>=Sale_t,1,0) -> 119.10989 | H18: =Declarations!$C$19+(Declarations!$H$19-Declarations!$C$19)*EXP(-Declarations!$D$19*$B18)+IF(Declarations!$E$19=0,0,Declarations!$E$19*($B18/Declarations!$F$19)*EXP(1-$B18/Declarations!$F$19))+Declarations!$G$19*IF($B18>=Sale_t,1,0) -> 40.288231 | I18: =Declarations!$C$20+(Declarations!$H$20-Declarations!$C$20)*EXP(-Declarations!$D$20*$B18)+IF(Declarations!$E$20=0,0,Declarations!$E$20*($B18/Declarations!$F$20)*EXP(1-$B18/Declarations!$F$20))+Declarations!$G$20*IF($B18>=Sale_t,1,0) -> 72.15752 | J18: =Declarations!$C$21+(Declarations!$H$21-Declarations!$C$21)*EXP(-Declarations!$D$21*$B18)+IF(Declarations!$E$21=0,0,Declarations!$E$21*($B18/Declarations!$F$21)*EXP(1-$B18/Declarations!$F$21))+Declarations!$G$21*IF($B18>=Sale_t,1,0) -> 53.475452 | K18: =Declarations!$C$22+(Declarations!$H$22-Declarations!$C$22)*EXP(-Declarations!$D$22*$B18)+IF(Declarations!$E$22=0,0,Declarations!$E$22*($B18/Declarations!$F$22)*EXP(1-$B18/Declarations!$F$22))+Declarations!$G$22*IF($B18>=Sale_t,1,0) -> 102.31504 | L18: =Declarations!$C$23+(Declarations!$H$23-Declarations!$C$23)*EXP(-Declarations!$D$23*$B18)+IF(Declarations!$E$23=0,0,Declarations!$E$23*($B18/Declarations!$F$23)*EXP(1-$B18/Declarations!$F$23))+Declarations!$G$23*IF($B18>=Sale_t,1,0) -> 39.441587 | M18: =Declarations!$C$24+(Declarations!$H$24-Declarations!$C$24)*EXP(-Declarations!$D$24*$B18)+IF(Declarations!$E$24=0,0,Declarations!$E$24*($B18/Declarations!$F$24)*EXP(1-$B18/Declarations!$F$24))+Declarations!$G$24*IF($B18>=Sale_t,1,0) -> 74.823634 | N18: =Declarations!$C$25+(Declarations!$H$25-Declarations!$C$25)*EXP(-Declarations!$D$25*$B18)+IF(Declarations!$E$25=0,0,Declarations!$E$25*($B18/Declarations!$F$25)*EXP(1-$B18/Declarations!$F$25))+Declarations!$G$25*IF($B18>=Sale_t,1,0) -> 64.832418 | O18: =W_L*S_L*C18+W_T*S_T*D18+W_E*S_E*E18+W_R*S_R*F18 -> 32.245278 | P18: =W_L*S_L*G18+W_T*S_T*H18+W_E*S_E*I18+W_R*S_R*J18 -> 44.520047 | Q18: =W_L*S_L*K18+W_T*S_T*L18+W_E*S_E*M18+W_R*S_R*N18 -> 37.936961 | R18: =IF(O18<Score_today,1,0) -> 1 | S18: =IF(O18>Q18,1,0) -> 0 | T18: =IF(O18>P18,1,0) -> 0 | U18: =1+IF(P18>O18,1,0)+IF(Q18>O18,1,0) -> 3 | V18: =ABS(P18-Q18) -> 6.5830866
A19: 14 | B19: =A19/12 -> 1.1666667 | C19: =Declarations!$C$14+(Declarations!$H$14-Declarations!$C$14)*EXP(-Declarations!$D$14*$B19)+IF(Declarations!$E$14=0,0,Declarations!$E$14*($B19/Declarations!$F$14)*EXP(1-$B19/Declarations!$F$14))+Declarations!$G$14*IF($B19>=Sale_t,1,0) -> 79.246932 | D19: =Declarations!$C$15+(Declarations!$H$15-Declarations!$C$15)*EXP(-Declarations!$D$15*$B19)+IF(Declarations!$E$15=0,0,Declarations!$E$15*($B19/Declarations!$F$15)*EXP(1-$B19/Declarations!$F$15))+Declarations!$G$15*IF($B19>=Sale_t,1,0) -> 58.52267 | E19: =Declarations!$C$16+(Declarations!$H$16-Declarations!$C$16)*EXP(-Declarations!$D$16*$B19)+IF(Declarations!$E$16=0,0,Declarations!$E$16*($B19/Declarations!$F$16)*EXP(1-$B19/Declarations!$F$16))+Declarations!$G$16*IF($B19>=Sale_t,1,0) -> 64.909847 | F19: =Declarations!$C$17+(Declarations!$H$17-Declarations!$C$17)*EXP(-Declarations!$D$17*$B19)+IF(Declarations!$E$17=0,0,Declarations!$E$17*($B19/Declarations!$F$17)*EXP(1-$B19/Declarations!$F$17))+Declarations!$G$17*IF($B19>=Sale_t,1,0) -> 73.146656 | G19: =Declarations!$C$18+(Declarations!$H$18-Declarations!$C$18)*EXP(-Declarations!$D$18*$B19)+IF(Declarations!$E$18=0,0,Declarations!$E$18*($B19/Declarations!$F$18)*EXP(1-$B19/Declarations!$F$18))+Declarations!$G$18*IF($B19>=Sale_t,1,0) -> 119.18125 | H19: =Declarations!$C$19+(Declarations!$H$19-Declarations!$C$19)*EXP(-Declarations!$D$19*$B19)+IF(Declarations!$E$19=0,0,Declarations!$E$19*($B19/Declarations!$F$19)*EXP(1-$B19/Declarations!$F$19))+Declarations!$G$19*IF($B19>=Sale_t,1,0) -> 40.241053 | I19: =Declarations!$C$20+(Declarations!$H$20-Declarations!$C$20)*EXP(-Declarations!$D$20*$B19)+IF(Declarations!$E$20=0,0,Declarations!$E$20*($B19/Declarations!$F$20)*EXP(1-$B19/Declarations!$F$20))+Declarations!$G$20*IF($B19>=Sale_t,1,0) -> 72.225334 | J19: =Declarations!$C$21+(Declarations!$H$21-Declarations!$C$21)*EXP(-Declarations!$D$21*$B19)+IF(Declarations!$E$21=0,0,Declarations!$E$21*($B19/Declarations!$F$21)*EXP(1-$B19/Declarations!$F$21))+Declarations!$G$21*IF($B19>=Sale_t,1,0) -> 53.318058 | K19: =Declarations!$C$22+(Declarations!$H$22-Declarations!$C$22)*EXP(-Declarations!$D$22*$B19)+IF(Declarations!$E$22=0,0,Declarations!$E$22*($B19/Declarations!$F$22)*EXP(1-$B19/Declarations!$F$22))+Declarations!$G$22*IF($B19>=Sale_t,1,0) -> 102.45067 | L19: =Declarations!$C$23+(Declarations!$H$23-Declarations!$C$23)*EXP(-Declarations!$D$23*$B19)+IF(Declarations!$E$23=0,0,Declarations!$E$23*($B19/Declarations!$F$23)*EXP(1-$B19/Declarations!$F$23))+Declarations!$G$23*IF($B19>=Sale_t,1,0) -> 39.335117 | M19: =Declarations!$C$24+(Declarations!$H$24-Declarations!$C$24)*EXP(-Declarations!$D$24*$B19)+IF(Declarations!$E$24=0,0,Declarations!$E$24*($B19/Declarations!$F$24)*EXP(1-$B19/Declarations!$F$24))+Declarations!$G$24*IF($B19>=Sale_t,1,0) -> 75.027318 | N19: =Declarations!$C$25+(Declarations!$H$25-Declarations!$C$25)*EXP(-Declarations!$D$25*$B19)+IF(Declarations!$E$25=0,0,Declarations!$E$25*($B19/Declarations!$F$25)*EXP(1-$B19/Declarations!$F$25))+Declarations!$G$25*IF($B19>=Sale_t,1,0) -> 64.885936 | O19: =W_L*S_L*C19+W_T*S_T*D19+W_E*S_E*E19+W_R*S_R*F19 -> 32.383198 | P19: =W_L*S_L*G19+W_T*S_T*H19+W_E*S_E*I19+W_R*S_R*J19 -> 44.582394 | Q19: =W_L*S_L*K19+W_T*S_T*L19+W_E*S_E*M19+W_R*S_R*N19 -> 37.981792 | R19: =IF(O19<Score_today,1,0) -> 1 | S19: =IF(O19>Q19,1,0) -> 0 | T19: =IF(O19>P19,1,0) -> 0 | U19: =1+IF(P19>O19,1,0)+IF(Q19>O19,1,0) -> 3 | V19: =ABS(P19-Q19) -> 6.6006025
