Workbook

Sheet README
B1: DCT Laboratory — Vol I, Ch 4: Enterprise Modeling Principles
B2: Seed 26104 · Companion to DCT_V1_Ch04_Lab.ipynb and AXIOM Lab 1.4 (module AXIOM-04). Headcounts in engineers.
B4: Worked Example 4.1, When the Roll-Up Breaks, with the book's declarations, and the five steps of AXIOM Lab 1.4, Can We Trust the Model?
B5: Declarations: the two units of Industrial Systems and the annual rates of Worked Example 4.1; the matrix A of Appendix 4.A.
B6: Chain: Table 4.1's four model types, and Table 4.4's verification items run on the Worked Example's model (lab step 1).
B7: Projection: the detailed model year by year, Step 1 and Table 4.5's first rows (lab step 2).
B8: RollUpTest: Step 2 and Theorem 4.2's linear test for the total and for any one-row summary you enter (lab step 2).
B9: TotalOnly: the planning model calibrated on Unit A's first year, Table 4.5's errors and Online Appendix 4.B's bound (Step 3).
B10: Repair: what the total hides, the summary carried with the software share, and Proposition 4.3 (Steps 4-5).
B11: FitExtrapolate: the lab's bench, a straight line and polynomials up to degree 8 fitted by LINEST (lab step 3).
B12: LeaveRecord: two models that fit one record equally well and part beyond it (Theorem 4.3; lab step 4).
B13: Triggers: five years of use replayed, with error and mix triggers whose tolerances you set (lab step 5).
... B21: Cross-sheet link: green.

Sheet Declarations
A1: Declarations (Worked Example 4.1, the situation). Headcounts in engineers; rates are shares of a pool a year.
A3: Quantity | B3: Value | C3: Source
A4: Legacy engineers who leave the company, a year | B4: 0.05 | C4: Worked Example 4.1: 5 percent
A5: Legacy engineers retrained into software skills, a year | B5: 0.03 | C5: 3 percent
A6: Software engineers who leave, a year | B6: 0.04 | C6: 4 percent
A7: Legacy pool kept, a = 1 - 0.05 - 0.03 | B7: =1-B4-B5 -> 0.92 | C7: 0.92 (Appendix 4.A)
A8: Software pool kept, d = 1 - 0.04 | B8: =1-B6 -> 0.96 | C8: 0.96 (Appendix 4.A)
A9: Legacy engineers who leave the legacy pool, a year | B9: =B4+B5 -> 0.08 | C9: 8 percent: 5 leave the company, 3 are retrained
A11: Unit of Industrial Systems | B11: Legacy engineers today | C11: Software engineers today | D11: Total today | E11: Software share today
A12: Unit A | B12: 400 | C12: 100 | D12: =B12+C12 -> 500 | E12: =C12/D12 -> 0.2
A13: Unit B | B13: 100 | C13: 400 | D13: =B13+C13 -> 500 | E13: =C13/D13 -> 0.8
A15: The detailed model x' = A x (Appendix 4.A) | B15: Legacy column | C15: Software column
A16: Row of A for next year's legacy engineers | B16: =Keep_L -> 0.92 | C16: 0
A17: Row of A for next year's software engineers | B17: =Retrain -> 0.03 | C17: =Keep_S -> 0.96
A19: The HR dashboard's summary is the total H = legacy + software: the roll-up P = [1 1]. The planning model projects each unit's total with one attrition rate, calibrated on Unit A's first year (TotalOnly).

Sheet Chain
A1: Walk the chain: Table 4.1 and Table 4.4's verification items (Definitions 4.1 and 4.5; AXIOM Lab 1.4, step 1)
A3: Type (Table 4.1) | B3: Medium | C3: Question it settles | D3: Typical failure | E3: Worked Example 4.1's question at this link
A4: Conceptual | B4: diagrams, prose | C4: what matters and how it connects | D4: omitted mechanism; wrong boundary | E4: two pools of engineers in each unit; engineers leave, and legacy engineers are retrained into software
A5: Logical | B5: structured schema | C5: which readings, links, constraints | D5: hidden variable; category error | E5: a unit's state is (legacy, software); links legacy to software and both pools to exit; no pool is negative
A6: Mathematical | B6: spaces, mappings | C6: exact form of dynamics and constraints | D6: unearned assumption (linearity, independence) | E6: x' = A x with A = [[0.92, 0], [0.03, 0.96]] (Appendix 4.A)
A7: Computational | B7: code, data | C7: numbers, paths, optima | D7: implementation bug; discretization artifact | E7: the Projection sheet: the recursion, year by year
A8: Model types in the chain | B8: =COUNTA(A4:A7) -> 4 | C8: The completed chain is Definition 4.1's quadruple M = (X, mu, f-hat, g-hat): headcount pairs; engineers counted by skill pool; f-hat(x) = A x, the modeler's claim; g-hat(x) = the total, the dashboard's reading.
A10: Verification item (Table 4.4) | B10: What it tests | C10: Result | D10: Reading
A11: Mathematics renders the logic | B11: 1 - each column sum of A equals the declared exits | C11: =ABS((1-(Keep_L+Retrain))-Exit_L)+ABS((1-Keep_S)-Exit_S) -> 0 | D11: 0: 5 and 4 percent leave, as declared
A12: Code implements the mathematics | B12: the recursion (Projection) against the closed form, years 0-5 | C12: =MAX(F17:I22) -> 0 | D12: a test on a known solution
A13: Constraints preserved (Definition 4.5) | B13: negative pools over 100 years, both units | C13: =COUNTIF(Projection!B13:C113,"<0")+COUNTIF(Projection!F13:G113,"<0") -> 0 | D13: 0: the model never leaves its own admissible region
A14: Constraints preserved (Definition 4.5) | B14: years in which a unit's total rises (no hiring is declared) | C14: =SUMPRODUCT((Projection!D14:D113>Projection!D13:D112)*1)+SUMPRODUCT((Projection!H14:H113>Projection!H13:H112)*1) -> 0 | D14: 0
A16: Year | B16: Closed form: Unit A legacy | C16: Unit A software | D16: Unit B legacy | E16: Unit B software | F16: |gap| A legacy | G16: |gap| A software | H16: |gap| B legacy | I16: |gap| B software
A17: 0 | B17: =Keep_L^$A17*A_leg0 -> 400 | C17: =Keep_S^$A17*A_soft0+Retrain*A_leg0*(Keep_S^$A17-Keep_L^$A17)/(Keep_S-Keep_L) -> 100 | D17: =Keep_L^$A17*B_leg0 -> 100 | E17: =Keep_S^$A17*B_soft0+Retrain*B_leg0*(Keep_S^$A17-Keep_L^$A17)/(Keep_S-Keep_L) -> 400 | F17: =ABS(B17-Projection!$B$13) -> 0 | G17: =ABS(C17-Projection!$C$13) -> 0 | H17: =ABS(D17-Projection!$F$13) -> 0 | I17: =ABS(E17-Projection!$G$13) -> 0
A18: 1 | B18: =Keep_L^$A18*A_leg0 -> 368 | C18: =Keep_S^$A18*A_soft0+Retrain*A_leg0*(Keep_S^$A18-Keep_L^$A18)/(Keep_S-Keep_L) -> 108 | D18: =Keep_L^$A18*B_leg0 -> 92 | E18: =Keep_S^$A18*B_soft0+Retrain*B_leg0*(Keep_S^$A18-Keep_L^$A18)/(Keep_S-Keep_L) -> 387 | F18: =ABS(B18-Projection!$B$14) -> 0 | G18: =ABS(C18-Projection!$C$14) -> 0 | H18: =ABS(D18-Projection!$F$14) -> 0 | I18: =ABS(E18-Projection!$G$14) -> 0
A19: 2 | B19: =Keep_L^$A19*A_leg0 -> 338.56 | C19: =Keep_S^$A19*A_soft0+Retrain*A_leg0*(Keep_S^$A19-Keep_L^$A19)/(Keep_S-Keep_L) -> 114.72 | D19: =Keep_L^$A19*B_leg0 -> 84.64 | E19: =Keep_S^$A19*B_soft0+Retrain*B_leg0*(Keep_S^$A19-Keep_L^$A19)/(Keep_S-Keep_L) -> 374.28 | F19: =ABS(B19-Projection!$B$15) -> 0 | G19: =ABS(C19-Projection!$C$15) -> 0 | H19: =ABS(D19-Projection!$F$15) -> 0 | I19: =ABS(E19-Projection!$G$15) -> 0
A20: 3 | B20: =Keep_L^$A20*A_leg0 -> 311.4752 | C20: =Keep_S^$A20*A_soft0+Retrain*A_leg0*(Keep_S^$A20-Keep_L^$A20)/(Keep_S-Keep_L) -> 120.288 | D20: =Keep_L^$A20*B_leg0 -> 77.8688 | E20: =Keep_S^$A20*B_soft0+Retrain*B_leg0*(Keep_S^$A20-Keep_L^$A20)/(Keep_S-Keep_L) -> 361.848 | F20: =ABS(B20-Projection!$B$16) -> 0 | G20: =ABS(C20-Projection!$C$16) -> 0 | H20: =ABS(D20-Projection!$F$16) -> 0 | I20: =ABS(E20-Projection!$G$16) -> 0
A21: 4 | B21: =Keep_L^$A21*A_leg0 -> 286.55718 | C21: =Keep_S^$A21*A_soft0+Retrain*A_leg0*(Keep_S^$A21-Keep_L^$A21)/(Keep_S-Keep_L) -> 124.82074 | D21: =Keep_L^$A21*B_leg0 -> 71.639296 | E21: =Keep_S^$A21*B_soft0+Retrain*B_leg0*(Keep_S^$A21-Keep_L^$A21)/(Keep_S-Keep_L) -> 349.71014 | F21: =ABS(B21-Projection!$B$17) -> 0 | G21: =ABS(C21-Projection!$C$17) -> 0 | H21: =ABS(D21-Projection!$F$17) -> 0 | I21: =ABS(E21-Projection!$G$17) -> 0
A22: 5 | B22: =Keep_L^$A22*A_leg0 -> 263.63261 | C22: =Keep_S^$A22*A_soft0+Retrain*A_leg0*(Keep_S^$A22-Keep_L^$A22)/(Keep_S-Keep_L) -> 128.42462 | D22: =Keep_L^$A22*B_leg0 -> 65.908152 | E22: =Keep_S^$A22*B_soft0+Retrain*B_leg0*(Keep_S^$A22-Keep_L^$A22)/(Keep_S-Keep_L) -> 337.87092 | F22: =ABS(B22-Projection!$B$18) -> 0 | G22: =ABS(C22-Projection!$C$18) -> 0 | H22: =ABS(D22-Projection!$F$18) -> 0 | I22: =ABS(E22-Projection!$G$18) -> 0
A24: Closed form: legacy(k) = 0.92^k legacy(0); software(k) = 0.96^k software(0) + 0.03 legacy(0) (0.96^k - 0.92^k) / (0.96 - 0.92). Verification is internal: it can pass for a model that tracks nothing (Figure 4.1); validation, on LeaveRecord, compares the end of the chain with a record.

Sheet Projection
A1: Project the detailed model: Step 1 and Table 4.5's first rows (Worked Example 4.1; AXIOM Lab 1.4, step 2)
A3: Step 1: next year | B3: Unit A | C3: Unit B
A4: Legacy engineers | B4: =Projection!$B$14 -> 368 | C4: =Projection!$F$14 -> 92
A5: Software engineers | B5: =Projection!$C$14 -> 108 | C5: =Projection!$G$14 -> 387
A6: Total | B6: =Projection!$D$14 -> 476 | C6: =Projection!$H$14 -> 479
A8: Table 4.5, detailed model | B8: Year 0 | C8: Year 1 | D8: Year 2 | E8: Year 3 | F8: Year 4 | G8: Year 5
A9: Unit A, detailed model | B9: =Projection!$D$13 -> 500 | C9: =Projection!$D$14 -> 476 | D9: =Projection!$D$15 -> 453.28 | E9: =Projection!$D$16 -> 431.7632 | F9: =Projection!$D$17 -> 411.37792 | G9: =Projection!$D$18 -> 392.05723
A10: Unit B, detailed model | B10: =Projection!$H$13 -> 500 | C10: =Projection!$H$14 -> 479 | D10: =Projection!$H$15 -> 458.92 | E10: =Projection!$H$16 -> 439.7168 | F10: =Projection!$H$17 -> 421.34944 | G10: =Projection!$H$18 -> 403.77907
A12: Year | B12: Unit A: legacy | C12: Unit A: software | D12: Unit A: total | E12: Unit A: software share | F12: Unit B: legacy | G12: Unit B: software | H12: Unit B: total | I12: Unit B: software share
A13: 0 | B13: =A_leg0 -> 400 | C13: =A_soft0 -> 100 | D13: =B13+C13 -> 500 | E13: =C13/D13 -> 0.2 | F13: =B_leg0 -> 100 | G13: =B_soft0 -> 400 | H13: =F13+G13 -> 500 | I13: =G13/H13 -> 0.8
A14: 1 | B14: =Keep_L*B13 -> 368 | C14: =Keep_S*C13+Retrain*B13 -> 108 | D14: =B14+C14 -> 476 | E14: =C14/D14 -> 0.22689076 | F14: =Keep_L*F13 -> 92 | G14: =Keep_S*G13+Retrain*F13 -> 387 | H14: =F14+G14 -> 479 | I14: =G14/H14 -> 0.80793319
A15: 2 | B15: =Keep_L*B14 -> 338.56 | C15: =Keep_S*C14+Retrain*B14 -> 114.72 | D15: =B15+C15 -> 453.28 | E15: =C15/D15 -> 0.2530886 | F15: =Keep_L*F14 -> 84.64 | G15: =Keep_S*G14+Retrain*F14 -> 374.28 | H15: =F15+G15 -> 458.92 | I15: =G15/H15 -> 0.81556698
A16: 3 | B16: =Keep_L*B15 -> 311.4752 | C16: =Keep_S*C15+Retrain*B15 -> 120.288 | D16: =B16+C16 -> 431.7632 | E16: =C16/D16 -> 0.27859716 | F16: =Keep_L*F15 -> 77.8688 | G16: =Keep_S*G15+Retrain*F15 -> 361.848 | H16: =F16+G16 -> 439.7168 | I16: =G16/H16 -> 0.82291147
A17: 4 | B17: =Keep_L*B16 -> 286.55718 | C17: =Keep_S*C16+Retrain*B16 -> 124.82074 | D17: =B17+C17 -> 411.37792 | E17: =C17/D17 -> 0.30342109 | F17: =Keep_L*F16 -> 71.639296 | G17: =Keep_S*G16+Retrain*F16 -> 349.71014 | H17: =F17+G17 -> 421.34944 | I17: =G17/H17 -> 0.82997652
A18: 5 | B18: =Keep_L*B17 -> 263.63261 | C18: =Keep_S*C17+Retrain*B17 -> 128.42462 | D18: =B18+C18 -> 392.05723 | E18: =C18/D18 -> 0.32756601 | F18: =Keep_L*F17 -> 65.908152 | G18: =Keep_S*G17+Retrain*F17 -> 337.87092 | H18: =F18+G18 -> 403.77907 | I18: =G18/H18 -> 0.83677175
A19: 6 | B19: =Keep_L*B18 -> 242.542 | C19: =Keep_S*C18+Retrain*B18 -> 131.19662 | D19: =B19+C19 -> 373.73862 | E19: =C19/D19 -> 0.35103843 | F19: =Keep_L*F18 -> 60.6355 | G19: =Keep_S*G18+Retrain*F18 -> 326.33333 | H19: =F19+G19 -> 386.96883 | I19: =G19/H19 -> 0.8433065
A20: 7 | B20: =Keep_L*B19 -> 223.13864 | C20: =Keep_S*C19+Retrain*B19 -> 133.22501 | D20: =B20+C20 -> 356.36365 | E20: =C20/D20 -> 0.37384568 | F20: =Keep_L*F19 -> 55.78466 | G20: =Keep_S*G19+Retrain*F19 -> 315.09906 | H20: =F20+G20 -> 370.88372 | I20: =G20/H20 -> 0.84958989
A21: 8 | B21: =Keep_L*B20 -> 205.28755 | C21: =Keep_S*C20+Retrain*B20 -> 134.59017 | D21: =B21+C21 -> 339.87772 | E21: =C21/D21 -> 0.39599586 | F21: =Keep_L*F20 -> 51.321887 | G21: =Keep_S*G20+Retrain*F20 -> 304.16863 | H21: =F21+G21 -> 355.49052 | I21: =G21/H21 -> 0.85563079
A22: 9 | B22: =Keep_L*B21 -> 188.86455 | C22: =Keep_S*C21+Retrain*B21 -> 135.36519 | D22: =B22+C22 -> 324.22973 | E22: =C22/D22 -> 0.41749776 | F22: =Keep_L*F21 -> 47.216136 | G22: =Keep_S*G21+Retrain*F21 -> 293.54155 | H22: =F22+G22 -> 340.75768 | I22: =G22/H22 -> 0.86143779
A23: 10 | B23: =Keep_L*B22 -> 173.75538 | C23: =Keep_S*C22+Retrain*B22 -> 135.61652 | D23: =B23+C23 -> 309.3719 | E23: =C23/D23 -> 0.43836081 | F23: =Keep_L*F22 -> 43.438845 | G23: =Keep_S*G22+Retrain*F22 -> 283.21637 | H23: =F23+G23 -> 326.65521 | I23: =G23/H23 -> 0.86701928
A24: 11 | B24: =Keep_L*B23 -> 159.85495 | C24: =Keep_S*C23+Retrain*B23 -> 135.40452 | D24: =B24+C24 -> 295.25947 | E24: =C24/D24 -> 0.45859501 | F24: =Keep_L*F23 -> 39.963738 | G24: =Keep_S*G23+Retrain*F23 -> 273.19088 | H24: =F24+G24 -> 313.15462 | I24: =G24/H24 -> 0.87238337
A25: 12 | B25: =Keep_L*B24 -> 147.06656 | C25: =Keep_S*C24+Retrain*B24 -> 134.78399 | D25: =B25+C25 -> 281.85054 | E25: =C25/D25 -> 0.47821085 | F25: =Keep_L*F24 -> 36.766639 | G25: =Keep_S*G24+Retrain*F24 -> 263.46216 | H25: =F25+G25 -> 300.22879 | I25: =G25/H25 -> 0.87753793
... A113: 100 | B113: =Keep_L*B112 -> 0.09568475 | C113: =Keep_S*C112+Retrain*B112 -> 6.6763642 | D113: =B113+C113 -> 6.7720489 | E113: =C113/D113 -> 0.98587064 | F113: =Keep_L*F112 -> 0.023921187 | G113: =Keep_S*G112+Retrain*F112 -> 7.9954608 | H113: =F113+G113 -> 8.019382 | I113: =G113/H113 -> 0.99701708

Sheet RollUpTest
A1: Apply the roll-up test (Worked Example 4.1, Step 2; Theorem 4.2; Appendix 4.A; Figure 4.2; AXIOM Lab 1.4, step 2)
A3: Step 2 | B3: Unit A | C3: Unit B | D3: B - A
A4: Total today | B4: =Projection!$D$13 -> 500 | C4: =Projection!$H$13 -> 500 | D4: =C4-B4 -> 0
A5: Total next year | B5: =Projection!$D$14 -> 476 | C5: =Projection!$H$14 -> 479 | D5: =C5-B5 -> 3
A6: The same summary today, a different summary next year: the dynamics split the fiber of 500 (Figure 4.2). The total alone is not a state.
A8: One-row roll-up p (Appendix 4.A, linear case) | B8: p: legacy weight | C8: p: software weight | D8: ker p spanned by v: legacy | E8: v: software | F8: A v: legacy | G8: A v: software | H8: p . A v (0 passes) | I8: Verdict (Theorem 4.2) | J8: Rate if it passes
A9: total (the dashboard) | B9: 1 | C9: 1 | D9: =C9 -> 1 | E9: =-B9 -> -1 | F9: =Keep_L*D9 -> 0.92 | G9: =Retrain*D9+Keep_S*E9 -> -0.93 | H9: =B9*F9+C9*G9 -> -0.01 | I9: =IF(ABS(H9)<0.000000000001,"passes: a state","fails: the dynamics split it") -> fails: the dynamics split it | J9: =IF(ABS(H9)<0.000000000001,IF(ABS(C9)>ABS(B9),Keep_S,(B9*Keep_L+C9*Retrain)/B9),"")
A10: software engineers | B10: 0 | C10: 1 | D10: =C10 -> 1 | E10: =-B10 -> 0 | F10: =Keep_L*D10 -> 0.92 | G10: =Retrain*D10+Keep_S*E10 -> 0.03 | H10: =B10*F10+C10*G10 -> 0.03 | I10: =IF(ABS(H10)<0.000000000001,"passes: a state","fails: the dynamics split it") -> fails: the dynamics split it | J10: =IF(ABS(H10)<0.000000000001,IF(ABS(C10)>ABS(B10),Keep_S,(B10*Keep_L+C10*Retrain)/B10),"")
A11: legacy engineers | B11: 1 | C11: 0 | D11: =C11 -> 0 | E11: =-B11 -> -1 | F11: =Keep_L*D11 -> 0 | G11: =Retrain*D11+Keep_S*E11 -> -0.96 | H11: =B11*F11+C11*G11 -> 0 | I11: =IF(ABS(H11)<0.000000000001,"passes: a state","fails: the dynamics split it") -> passes: a state | J11: =IF(ABS(H11)<0.000000000001,IF(ABS(C11)>ABS(B11),Keep_S,(B11*Keep_L+C11*Retrain)/B11),"") -> 0.92
A12: 3 legacy + 4 software | B12: 3 | C12: 4 | D12: =C12 -> 4 | E12: =-B12 -> -3 | F12: =Keep_L*D12 -> 3.68 | G12: =Retrain*D12+Keep_S*E12 -> -2.76 | H12: =B12*F12+C12*G12 -> 0 | I12: =IF(ABS(H12)<0.000000000001,"passes: a state","fails: the dynamics split it") -> passes: a state | J12: =IF(ABS(H12)<0.000000000001,IF(ABS(C12)>ABS(B12),Keep_S,(B12*Keep_L+C12*Retrain)/B12),"") -> 0.96
A13: your own summary | B13: 2 | C13: 1 | D13: =C13 -> 1 | E13: =-B13 -> -2 | F13: =Keep_L*D13 -> 0.92 | G13: =Retrain*D13+Keep_S*E13 -> -1.89 | H13: =B13*F13+C13*G13 -> -0.05 | I13: =IF(ABS(H13)<0.000000000001,"passes: a state","fails: the dynamics split it") -> fails: the dynamics split it | J13: =IF(ABS(H13)<0.000000000001,IF(ABS(C13)>ABS(B13),Keep_S,(B13*Keep_L+C13*Retrain)/B13),"")
A14: For the total, v = (1, -1) and A v = (0.92, -0.93), outside ker P (Appendix 4.A). A one-row roll-up passes exactly when p is a left eigenvector of A: the legacy count (rate 0.92) or 3 legacy + 4 software (0.96).
A16: Move Unit A along each summary's fiber by t (engineers) | B16: -300
A17: A pair with the same summary today | B17: Second unit: legacy | C17: Second unit: software | D17: Summary today: Unit A | E17: Summary today: second unit | F17: Summary next year: Unit A | G17: Summary next year: second unit | H17: Gap next year
A18: total (the dashboard) | B18: =A_leg0+$B$16*D9/MAX(ABS(D9),ABS(E9)) -> 100 | C18: =A_soft0+$B$16*E9/MAX(ABS(D9),ABS(E9)) -> 400 | D18: =B9*A_leg0+C9*A_soft0 -> 500 | E18: =B9*B18+C9*C18 -> 500 | F18: =B9*Keep_L*A_leg0+C9*(Retrain*A_leg0+Keep_S*A_soft0) -> 476 | G18: =B9*Keep_L*B18+C9*(Retrain*B18+Keep_S*C18) -> 479 | H18: =ABS(F18-G18) -> 3
A19: software engineers | B19: =A_leg0+$B$16*D10/MAX(ABS(D10),ABS(E10)) -> 100 | C19: =A_soft0+$B$16*E10/MAX(ABS(D10),ABS(E10)) -> 100 | D19: =B10*A_leg0+C10*A_soft0 -> 100 | E19: =B10*B19+C10*C19 -> 100 | F19: =B10*Keep_L*A_leg0+C10*(Retrain*A_leg0+Keep_S*A_soft0) -> 108 | G19: =B10*Keep_L*B19+C10*(Retrain*B19+Keep_S*C19) -> 99 | H19: =ABS(F19-G19) -> 9
A20: legacy engineers | B20: =A_leg0+$B$16*D11/MAX(ABS(D11),ABS(E11)) -> 400 | C20: =A_soft0+$B$16*E11/MAX(ABS(D11),ABS(E11)) -> 400 | D20: =B11*A_leg0+C11*A_soft0 -> 400 | E20: =B11*B20+C11*C20 -> 400 | F20: =B11*Keep_L*A_leg0+C11*(Retrain*A_leg0+Keep_S*A_soft0) -> 368 | G20: =B11*Keep_L*B20+C11*(Retrain*B20+Keep_S*C20) -> 368 | H20: =ABS(F20-G20) -> 0
A21: 3 legacy + 4 software | B21: =A_leg0+$B$16*D12/MAX(ABS(D12),ABS(E12)) -> 100 | C21: =A_soft0+$B$16*E12/MAX(ABS(D12),ABS(E12)) -> 325 | D21: =B12*A_leg0+C12*A_soft0 -> 1600 | E21: =B12*B21+C12*C21 -> 1600 | F21: =B12*Keep_L*A_leg0+C12*(Retrain*A_leg0+Keep_S*A_soft0) -> 1536 | G21: =B12*Keep_L*B21+C12*(Retrain*B21+Keep_S*C21) -> 1536 | H21: =ABS(F21-G21) -> 0
A22: your own summary | B22: =A_leg0+$B$16*D13/MAX(ABS(D13),ABS(E13)) -> 250 | C22: =A_soft0+$B$16*E13/MAX(ABS(D13),ABS(E13)) -> 400 | D22: =B13*A_leg0+C13*A_soft0 -> 900 | E22: =B13*B22+C13*C22 -> 900 | F22: =B13*Keep_L*A_leg0+C13*(Retrain*A_leg0+Keep_S*A_soft0) -> 844 | G22: =B13*Keep_L*B22+C13*(Retrain*B22+Keep_S*C22) -> 851.5 | H22: =ABS(F22-G22) -> 7.5
A24: With t = -300 the total's pair is Units A and B: 500 and 500 today, 476 and 479 next year. A summary that passes gives the same next-year summary for every pair; one that fails splits them. Change p in row 13 to test your own summary.

Sheet TotalOnly
A1: Watch the error grow: the total-only model (Worked Example 4.1, Step 3; Table 4.5; Online Appendix 4.B)
A3: Rate calibrated on Unit A's first year: total next year / total today | B3: =Projection!$D$14/Projection!$D$13 -> 0.952
A5: Year | B5: Unit A, detailed model | C5: Unit B, detailed model | D5: Total-only model (x 0.952 a year) | E5: Error for Unit B | F5: Error for Unit A | G5: One-step miss for Unit B | H5: Online Appendix 4.B bound
A6: 0 | B6: =Projection!$D$13 -> 500 | C6: =Projection!$H$13 -> 500 | D6: =Projection!$D$13*Rate_r^A6 -> 500 | E6: =D6-C6 -> 0 | F6: =D6-B6 -> 0 | H6: =$B$13*($B$14^A6-1)/($B$14-1) -> 0
A7: 1 | B7: =Projection!$D$14 -> 476 | C7: =Projection!$H$14 -> 479 | D7: =Projection!$D$13*Rate_r^A7 -> 476 | E7: =D7-C7 -> -3 | F7: =D7-B7 -> 0 | G7: =ABS(Rate_r*C6-C7) -> 3 | H7: =$B$13*($B$14^A7-1)/($B$14-1) -> 3
A8: 2 | B8: =Projection!$D$15 -> 453.28 | C8: =Projection!$H$15 -> 458.92 | D8: =Projection!$D$13*Rate_r^A8 -> 453.152 | E8: =D8-C8 -> -5.768 | F8: =D8-B8 -> -0.128 | G8: =ABS(Rate_r*C7-C8) -> 2.912 | H8: =$B$13*($B$14^A8-1)/($B$14-1) -> 5.856
A9: 3 | B9: =Projection!$D$16 -> 431.7632 | C9: =Projection!$H$16 -> 439.7168 | D9: =Projection!$D$13*Rate_r^A9 -> 431.4007 | E9: =D9-C9 -> -8.316096 | F9: =D9-B9 -> -0.362496 | G9: =ABS(Rate_r*C8-C9) -> 2.82496 | H9: =$B$13*($B$14^A9-1)/($B$14-1) -> 8.574912
A10: 4 | B10: =Projection!$D$17 -> 411.37792 | C10: =Projection!$H$17 -> 421.34944 | D10: =Projection!$D$13*Rate_r^A10 -> 410.69347 | E10: =D10-C10 -> -10.65597 | F10: =D10-B10 -> -0.68444979 | G10: =ABS(Rate_r*C9-C10) -> 2.7390464 | H10: =$B$13*($B$14^A10-1)/($B$14-1) -> 11.163316
A11: 5 | B11: =Projection!$D$18 -> 392.05723 | C11: =Projection!$H$18 -> 403.77907 | D11: =Projection!$D$13*Rate_r^A11 -> 390.98018 | E11: =D11-C11 -> -12.798886 | F11: =D11-B11 -> -1.0770477 | G11: =ABS(Rate_r*C10-C11) -> 2.6544026 | H11: =$B$13*($B$14^A11-1)/($B$14-1) -> 13.627477
A13: delta: the largest one-step miss along Unit B's path | B13: =MAX(G7:G11) -> 3
A14: L: the summary model's Lipschitz constant, its rate | B14: =Rate_r -> 0.952
A15: Years in which the bound fails | B15: =SUMPRODUCT((ABS(E6:E11)>H6:H11+0.000000001)*1) -> 0
A16: With L = 1 the bound would be k delta: by year five | B16: =5*B13 -> 15
A18: Online Appendix 4.B: a summary model that misses by at most delta in one step and is Lipschitz with constant L is off by at most delta (L^k - 1)/(L - 1) after k periods. Unit B's error grows from 3 engineers in year one to about 13 by year five; the error for Unit A is not printed in the book.

Sheet Repair
A1: See what the total hides, and repair the summary (Worked Example 4.1, Steps 4-5; Theorems 4.1-4.2; Proposition 4.3)
A3: Step 4, year five | B3: Unit A | C3: Unit B
A4: Software engineers | B4: =Projection!$C$18 -> 128.42462 | C4: =Projection!$G$18 -> 337.87092 | D4: Theorem 4.1: today both units are the dashboard state 500 and differ by 300 software engineers; a question about software capacity cannot be answered from the dashboard.
A5: All engineers | B5: =Projection!$D$18 -> 392.05723 | C5: =Projection!$H$18 -> 403.77907
A6: Software share | B6: =Projection!$E$18 -> 0.32756601 | C6: =Projection!$I$18 -> 0.83677175
A8: Step 5: carry the software share s with the total H | B8: Value | C8: Reading
A9: Base rate: 1 - legacy exits | B9: =1-Exit_L -> 0.95 | C9: 0.95
A10: Mix coefficient: legacy exits - software exits | B10: =Exit_L-Exit_S -> 0.01 | C10: 0.01
A11: Unit A next year: H (0.95 + 0.01 s) | B11: =Declarations!D12*(B9+B10*Declarations!E12) -> 476 | C11: 500 x (0.95 + 0.01 x 0.2) = 476
A12: Unit B next year: H (0.95 + 0.01 s) | B12: =Declarations!D13*(B9+B10*Declarations!E13) -> 479 | C12: 500 x (0.95 + 0.01 x 0.8) = 479
A14: Year | B14: Unit A: H | C14: Unit A: s | D14: Unit B: H | E14: Unit B: s | F14: Table 4.5: Unit A | G14: Table 4.5: Unit B | H14: |gap| Unit A | I14: |gap| Unit B
A15: 0 | B15: =Declarations!D12 -> 500 | C15: =Declarations!E12 -> 0.2 | D15: =Declarations!D13 -> 500 | E15: =Declarations!E13 -> 0.8 | F15: =Projection!$D$13 -> 500 | G15: =Projection!$H$13 -> 500 | H15: =ABS(B15-F15) -> 0 | I15: =ABS(D15-G15) -> 0
A16: 1 | B16: =B15*($B$9+$B$10*C15) -> 476 | C16: =B15*(Retrain+(1-Exit_S-Retrain)*C15)/B16 -> 0.22689076 | D16: =D15*($B$9+$B$10*E15) -> 479 | E16: =D15*(Retrain+(1-Exit_S-Retrain)*E15)/D16 -> 0.80793319 | F16: =Projection!$D$14 -> 476 | G16: =Projection!$H$14 -> 479 | H16: =ABS(B16-F16) -> 0 | I16: =ABS(D16-G16) -> 0
A17: 2 | B17: =B16*($B$9+$B$10*C16) -> 453.28 | C17: =B16*(Retrain+(1-Exit_S-Retrain)*C16)/B17 -> 0.2530886 | D17: =D16*($B$9+$B$10*E16) -> 458.92 | E17: =D16*(Retrain+(1-Exit_S-Retrain)*E16)/D17 -> 0.81556698 | F17: =Projection!$D$15 -> 453.28 | G17: =Projection!$H$15 -> 458.92 | H17: =ABS(B17-F17) -> 0 | I17: =ABS(D17-G17) -> 0
A18: 3 | B18: =B17*($B$9+$B$10*C17) -> 431.7632 | C18: =B17*(Retrain+(1-Exit_S-Retrain)*C17)/B18 -> 0.27859716 | D18: =D17*($B$9+$B$10*E17) -> 439.7168 | E18: =D17*(Retrain+(1-Exit_S-Retrain)*E17)/D18 -> 0.82291147 | F18: =Projection!$D$16 -> 431.7632 | G18: =Projection!$H$16 -> 439.7168 | H18: =ABS(B18-F18) -> 0 | I18: =ABS(D18-G18) -> 0
A19: 4 | B19: =B18*($B$9+$B$10*C18) -> 411.37792 | C19: =B18*(Retrain+(1-Exit_S-Retrain)*C18)/B19 -> 0.30342109 | D19: =D18*($B$9+$B$10*E18) -> 421.34944 | E19: =D18*(Retrain+(1-Exit_S-Retrain)*E18)/D19 -> 0.82997652 | F19: =Projection!$D$17 -> 411.37792 | G19: =Projection!$H$17 -> 421.34944 | H19: =ABS(B19-F19) -> 0 | I19: =ABS(D19-G19) -> 0
A20: 5 | B20: =B19*($B$9+$B$10*C19) -> 392.05723 | C20: =B19*(Retrain+(1-Exit_S-Retrain)*C19)/B20 -> 0.32756601 | D20: =D19*($B$9+$B$10*E19) -> 403.77907 | E20: =D19*(Retrain+(1-Exit_S-Retrain)*E19)/D20 -> 0.83677175 | F20: =Projection!$D$18 -> 392.05723 | G20: =Projection!$H$18 -> 403.77907 | H20: =ABS(B20-F20) -> 0 | I20: =ABS(D20-G20) -> 0
A22: Largest gap, the (H, s) model against Table 4.5 | B22: =MAX(H15:I20) -> 0
A23: The share follows its own rule, s' = (0.03 + 0.93 s) / (0.95 + 0.01 s): the enlarged summary is a state (Theorem 4.2) and agrees with the detailed model at every horizon.
A25: Proposition 4.3: roll the two units up once more | B25: Value
A26: Engineers in the two units together | B26: =Declarations!D12+Declarations!D13 -> 1000
A27: Their software share | B27: =(Declarations!C12+Declarations!C13)/B26 -> 0.5
A28: Next year by the (H, s) model | B28: =B26*(B9+B10*B27) -> 955
A29: Next year, Unit A + Unit B (Step 1) | B29: =Projection!$D$14+Projection!$H$14 -> 955
A30: Next year by the total-only model | B30: =Rate_r*B26 -> 952

Sheet FitExtrapolate
A1: Fit and extrapolate: the model bench (Section 4.5; AXIOM Lab 1.4, step 3)
A2: Bench settings, not Meridian facts. The measurement errors (column D) are the engine's draws with the lab's seed 26104; everything else is a formula. Least squares by LINEST on quarters 1-16; judged on 17-24.
A3: Ceiling of the S-curve (percent of target users) | B3: 60
A4: Speed (a quarter) | B4: 0.35
A5: Midpoint (quarter) | B5: 12
A6: Measurement error, standard deviation (points) | B6: 1.5
A7: History: quarters 1 to | B7: 16
A8: Later quarters | B8: 8
A10: Quarter | B10: z = (quarter - 8.5) / 7.5 | C10: S-curve | D10: Measurement error (engine, seed 26104) | E10: Observed adoption | F10: z^1 | G10: z^2 | H10: z^3 | I10: z^4 | J10: z^5 | K10: z^6 | L10: z^7 | M10: z^8 | N10: Fit, degree 1 | O10: Fit, degree 2 | P10: Fit, degree 3 | Q10: Fit, degree 4 | R10: Fit, degree 5 | S10: Fit, degree 6 | T10: Fit, degree 7 | U10: Fit, degree 8
A11: 1 | B11: =(A11-8.5)/7.5 -> -1 | C11: =$B$3/(1+EXP(-$B$4*(A11-$B$5))) -> 1.2501807 | D11: 1.9463698 | E11: =C11+D11 -> 3.1965504 | F11: =$B11^1 -> -1 | G11: =$B11^2 -> 1 | H11: =$B11^3 -> -1 | I11: =$B11^4 -> 1 | J11: =$B11^5 -> -1 | K11: =$B11^6 -> 1 | L11: =$B11^7 -> -1 | M11: =$B11^8 -> 1 | N11: =$B$38+SUMPRODUCT($C$38:$J$38,$F11:$M11) -> -5.30573 | O11: =$B$39+SUMPRODUCT($C$39:$J$39,$F11:$M11) -> 2.0191005 | P11: =$B$40+SUMPRODUCT($C$40:$J$40,$F11:$M11) -> 3.0718801 | Q11: =$B$41+SUMPRODUCT($C$41:$J$41,$F11:$M11) -> 2.2010371 | R11: =$B$42+SUMPRODUCT($C$42:$J$42,$F11:$M11) -> 3.2442163 | S11: =$B$43+SUMPRODUCT($C$43:$J$43,$F11:$M11) -> 2.9424836 | T11: =$B$44+SUMPRODUCT($C$44:$J$44,$F11:$M11) -> 2.9803448 | U11: =$B$45+SUMPRODUCT($C$45:$J$45,$F11:$M11) -> 3.0125484
A12: 2 | B12: =(A12-8.5)/7.5 -> -0.86666667 | C12: =$B$3/(1+EXP(-$B$4*(A12-$B$5))) -> 1.7587338 | D12: -0.57296548 | E12: =C12+D12 -> 1.1857684 | F12: =$B12^1 -> -0.86666667 | G12: =$B12^2 -> 0.75111111 | H12: =$B12^3 -> -0.65096296 | I12: =$B12^4 -> 0.5641679 | J12: =$B12^5 -> -0.48894551 | K12: =$B12^6 -> 0.42375278 | L12: =$B12^7 -> -0.36725241 | M12: =$B12^8 -> 0.31828542 | N12: =$B$38+SUMPRODUCT($C$38:$J$38,$F12:$M12) -> -2.0802041 | O12: =$B$39+SUMPRODUCT($C$39:$J$39,$F12:$M12) -> 2.3146942 | P12: =$B$40+SUMPRODUCT($C$40:$J$40,$F12:$M12) -> 2.5252501 | Q12: =$B$41+SUMPRODUCT($C$41:$J$41,$F12:$M12) -> 2.8155311 | R12: =$B$42+SUMPRODUCT($C$42:$J$42,$F12:$M12) -> 1.7723519 | S12: =$B$43+SUMPRODUCT($C$43:$J$43,$F12:$M12) -> 2.3154708 | T12: =$B$44+SUMPRODUCT($C$44:$J$44,$F12:$M12) -> 2.2119836 | U12: =$B$45+SUMPRODUCT($C$45:$J$45,$F12:$M12) -> 2.0896096
A13: 3 | B13: =(A13-8.5)/7.5 -> -0.73333333 | C13: =$B$3/(1+EXP(-$B$4*(A13-$B$5))) -> 2.4654767 | D13: 1.4481149 | E13: =C13+D13 -> 3.9135916 | F13: =$B13^1 -> -0.73333333 | G13: =$B13^2 -> 0.53777778 | H13: =$B13^3 -> -0.39437037 | I13: =$B13^4 -> 0.28920494 | J13: =$B13^5 -> -0.21208362 | K13: =$B13^6 -> 0.15552799 | L13: =$B13^7 -> -0.11405386 | M13: =$B13^8 -> 0.083639496 | N13: =$B$38+SUMPRODUCT($C$38:$J$38,$F13:$M13) -> 1.1453218 | O13: =$B$39+SUMPRODUCT($C$39:$J$39,$F13:$M13) -> 3.0288497 | P13: =$B$40+SUMPRODUCT($C$40:$J$40,$F13:$M13) -> 2.6979761 | Q13: =$B$41+SUMPRODUCT($C$41:$J$41,$F13:$M13) -> 3.4029443 | R13: =$B$42+SUMPRODUCT($C$42:$J$42,$F13:$M13) -> 2.359765 | S13: =$B$43+SUMPRODUCT($C$43:$J$43,$F13:$M13) -> 2.5408047 | T13: =$B$44+SUMPRODUCT($C$44:$J$44,$F13:$M13) -> 2.5685695 | U13: =$B$45+SUMPRODUCT($C$45:$J$45,$F13:$M13) -> 2.678062
A14: 4 | B14: =(A14-8.5)/7.5 -> -0.6 | C14: =$B$3/(1+EXP(-$B$4*(A14-$B$5))) -> 3.4394506 | D14: 1.0519027 | E14: =C14+D14 -> 4.4913532 | F14: =$B14^1 -> -0.6 | G14: =$B14^2 -> 0.36 | H14: =$B14^3 -> -0.216 | I14: =$B14^4 -> 0.1296 | J14: =$B14^5 -> -0.07776 | K14: =$B14^6 -> 0.046656 | L14: =$B14^7 -> -0.0279936 | M14: =$B14^8 -> 0.01679616 | N14: =$B$38+SUMPRODUCT($C$38:$J$38,$F14:$M14) -> 4.3708477 | O14: =$B$39+SUMPRODUCT($C$39:$J$39,$F14:$M14) -> 4.1615669 | P14: =$B$40+SUMPRODUCT($C$40:$J$40,$F14:$M14) -> 3.543782 | Q14: =$B$41+SUMPRODUCT($C$41:$J$41,$F14:$M14) -> 4.1849521 | R14: =$B$42+SUMPRODUCT($C$42:$J$42,$F14:$M14) -> 3.9442184 | S14: =$B$43+SUMPRODUCT($C$43:$J$43,$F14:$M14) -> 3.6703379 | T14: =$B$44+SUMPRODUCT($C$44:$J$44,$F14:$M14) -> 3.7524676 | U14: =$B$45+SUMPRODUCT($C$45:$J$45,$F14:$M14) -> 3.8262883
A15: 5 | B15: =(A15-8.5)/7.5 -> -0.46666667 | C15: =$B$3/(1+EXP(-$B$4*(A15-$B$5))) -> 4.766313 | D15: -1.8654794 | E15: =C15+D15 -> 2.9008336 | F15: =$B15^1 -> -0.46666667 | G15: =$B15^2 -> 0.21777778 | H15: =$B15^3 -> -0.10162963 | I15: =$B15^4 -> 0.04742716 | J15: =$B15^5 -> -0.022132675 | K15: =$B15^6 -> 0.010328582 | L15: =$B15^7 -> -0.0048200048 | M15: =$B15^8 -> 0.0022493356 | N15: =$B$38+SUMPRODUCT($C$38:$J$38,$F15:$M15) -> 7.5963737 | O15: =$B$39+SUMPRODUCT($C$39:$J$39,$F15:$M15) -> 5.7128458 | P15: =$B$40+SUMPRODUCT($C$40:$J$40,$F15:$M15) -> 5.0163917 | Q15: =$B$41+SUMPRODUCT($C$41:$J$41,$F15:$M15) -> 5.3385717 | R15: =$B$42+SUMPRODUCT($C$42:$J$42,$F15:$M15) -> 5.9002836 | S15: =$B$43+SUMPRODUCT($C$43:$J$43,$F15:$M15) -> 5.4964259 | T15: =$B$44+SUMPRODUCT($C$44:$J$44,$F15:$M15) -> 5.526909 | U15: =$B$45+SUMPRODUCT($C$45:$J$45,$F15:$M15) -> 5.4610154
A16: 6 | B16: =(A16-8.5)/7.5 -> -0.33333333 | C16: =$B$3/(1+EXP(-$B$4*(A16-$B$5))) -> 6.5458093 | D16: 1.2844069 | E16: =C16+D16 -> 7.8302161 | F16: =$B16^1 -> -0.33333333 | G16: =$B16^2 -> 0.11111111 | H16: =$B16^3 -> -0.037037037 | I16: =$B16^4 -> 0.012345679 | J16: =$B16^5 -> -0.0041152263 | K16: =$B16^6 -> 0.0013717421 | L16: =$B16^7 -> -0.00045724737 | M16: =$B16^8 -> 0.00015241579 | N16: =$B$38+SUMPRODUCT($C$38:$J$38,$F16:$M16) -> 10.8219 | O16: =$B$39+SUMPRODUCT($C$39:$J$39,$F16:$M16) -> 7.6826865 | P16: =$B$40+SUMPRODUCT($C$40:$J$40,$F16:$M16) -> 7.0695292 | Q16: =$B$41+SUMPRODUCT($C$41:$J$41,$F16:$M16) -> 6.9961614 | R16: =$B$42+SUMPRODUCT($C$42:$J$42,$F16:$M16) -> 7.9518012 | S16: =$B$43+SUMPRODUCT($C$43:$J$43,$F16:$M16) -> 7.7429093 | T16: =$B$44+SUMPRODUCT($C$44:$J$44,$F16:$M16) -> 7.6972817 | U16: =$B$45+SUMPRODUCT($C$45:$J$45,$F16:$M16) -> 7.5957163
A17: 7 | B17: =(A17-8.5)/7.5 -> -0.2 | C17: =$B$3/(1+EXP(-$B$4*(A17-$B$5))) -> 8.8828319 | D17: 3.7831509 | E17: =C17+D17 -> 12.665983 | F17: =$B17^1 -> -0.2 | G17: =$B17^2 -> 0.04 | H17: =$B17^3 -> -0.008 | I17: =$B17^4 -> 0.0016 | J17: =$B17^5 -> -0.00032 | K17: =$B17^6 -> 6.4e-05 | L17: =$B17^7 -> -1.28e-05 | M17: =$B17^8 -> 2.56e-06 | N17: =$B$38+SUMPRODUCT($C$38:$J$38,$F17:$M17) -> 14.047425 | O17: =$B$39+SUMPRODUCT($C$39:$J$39,$F17:$M17) -> 10.071089 | P17: =$B$40+SUMPRODUCT($C$40:$J$40,$F17:$M17) -> 9.6569185 | Q17: =$B$41+SUMPRODUCT($C$41:$J$41,$F17:$M17) -> 9.2454212 | R17: =$B$42+SUMPRODUCT($C$42:$J$42,$F17:$M17) -> 10.084342 | S17: =$B$43+SUMPRODUCT($C$43:$J$43,$F17:$M17) -> 10.200393 | T17: =$B$44+SUMPRODUCT($C$44:$J$44,$F17:$M17) -> 10.127583 | U17: =$B$45+SUMPRODUCT($C$45:$J$45,$F17:$M17) -> 10.115197
A18: 8 | B18: =(A18-8.5)/7.5 -> -0.066666667 | C18: =$B$3/(1+EXP(-$B$4*(A18-$B$5))) -> 11.868967 | D18: 0.75870127 | E18: =C18+D18 -> 12.627668 | F18: =$B18^1 -> -0.066666667 | G18: =$B18^2 -> 0.0044444444 | H18: =$B18^3 -> -0.0002962963 | I18: =$B18^4 -> 1.9753086e-05 | J18: =$B18^5 -> -1.3168724e-06 | K18: =$B18^6 -> 8.7791495e-08 | L18: =$B18^7 -> -5.8527663e-09 | M18: =$B18^8 -> 3.9018442e-10 | N18: =$B$38+SUMPRODUCT($C$38:$J$38,$F18:$M18) -> 17.272951 | O18: =$B$39+SUMPRODUCT($C$39:$J$39,$F18:$M18) -> 12.878053 | P18: =$B$40+SUMPRODUCT($C$40:$J$40,$F18:$M18) -> 12.732284 | Q18: =$B$41+SUMPRODUCT($C$41:$J$41,$F18:$M18) -> 12.129392 | R18: =$B$42+SUMPRODUCT($C$42:$J$42,$F18:$M18) -> 12.457665 | S18: =$B$43+SUMPRODUCT($C$43:$J$43,$F18:$M18) -> 12.805819 | T18: =$B$44+SUMPRODUCT($C$44:$J$44,$F18:$M18) -> 12.771841 | U18: =$B$45+SUMPRODUCT($C$45:$J$45,$F18:$M18) -> 12.858543
A19: 9 | B19: =(A19-8.5)/7.5 -> 0.066666667 | C19: =$B$3/(1+EXP(-$B$4*(A19-$B$5))) -> 15.553506 | D19: -1.9976679 | E19: =C19+D19 -> 13.555838 | F19: =$B19^1 -> 0.066666667 | G19: =$B19^2 -> 0.0044444444 | H19: =$B19^3 -> 0.0002962963 | I19: =$B19^4 -> 1.9753086e-05 | J19: =$B19^5 -> 1.3168724e-06 | K19: =$B19^6 -> 8.7791495e-08 | L19: =$B19^7 -> 5.8527663e-09 | M19: =$B19^8 -> 3.9018442e-10 | N19: =$B$38+SUMPRODUCT($C$38:$J$38,$F19:$M19) -> 20.498477 | O19: =$B$39+SUMPRODUCT($C$39:$J$39,$F19:$M19) -> 16.103579 | P19: =$B$40+SUMPRODUCT($C$40:$J$40,$F19:$M19) -> 16.249348 | Q19: =$B$41+SUMPRODUCT($C$41:$J$41,$F19:$M19) -> 15.646457 | R19: =$B$42+SUMPRODUCT($C$42:$J$42,$F19:$M19) -> 15.318184 | S19: =$B$43+SUMPRODUCT($C$43:$J$43,$F19:$M19) -> 15.666337 | T19: =$B$44+SUMPRODUCT($C$44:$J$44,$F19:$M19) -> 15.700315 | U19: =$B$45+SUMPRODUCT($C$45:$J$45,$F19:$M19) -> 15.787017
A20: 10 | B20: =(A20-8.5)/7.5 -> 0.2 | C20: =$B$3/(1+EXP(-$B$4*(A20-$B$5))) -> 19.908734 | D20: -0.82860357 | E20: =C20+D20 -> 19.08013 | F20: =$B20^1 -> 0.2 | G20: =$B20^2 -> 0.04 | H20: =$B20^3 -> 0.008 | I20: =$B20^4 -> 0.0016 | J20: =$B20^5 -> 0.00032 | K20: =$B20^6 -> 6.4e-05 | L20: =$B20^7 -> 1.28e-05 | M20: =$B20^8 -> 2.56e-06 | N20: =$B$38+SUMPRODUCT($C$38:$J$38,$F20:$M20) -> 23.724003 | O20: =$B$39+SUMPRODUCT($C$39:$J$39,$F20:$M20) -> 19.747667 | P20: =$B$40+SUMPRODUCT($C$40:$J$40,$F20:$M20) -> 20.161837 | Q20: =$B$41+SUMPRODUCT($C$41:$J$41,$F20:$M20) -> 19.75034 | R20: =$B$42+SUMPRODUCT($C$42:$J$42,$F20:$M20) -> 18.911419 | S20: =$B$43+SUMPRODUCT($C$43:$J$43,$F20:$M20) -> 19.02747 | T20: =$B$44+SUMPRODUCT($C$44:$J$44,$F20:$M20) -> 19.10028 | U20: =$B$45+SUMPRODUCT($C$45:$J$45,$F20:$M20) -> 19.087894
A21: 11 | B21: =(A21-8.5)/7.5 -> 0.33333333 | C21: =$B$3/(1+EXP(-$B$4*(A21-$B$5))) -> 24.802945 | D21: 0.54217866 | E21: =C21+D21 -> 25.345124 | F21: =$B21^1 -> 0.33333333 | G21: =$B21^2 -> 0.11111111 | H21: =$B21^3 -> 0.037037037 | I21: =$B21^4 -> 0.012345679 | J21: =$B21^5 -> 0.0041152263 | K21: =$B21^6 -> 0.0013717421 | L21: =$B21^7 -> 0.00045724737 | M21: =$B21^8 -> 0.00015241579 | N21: =$B$38+SUMPRODUCT($C$38:$J$38,$F21:$M21) -> 26.949529 | O21: =$B$39+SUMPRODUCT($C$39:$J$39,$F21:$M21) -> 23.810316 | P21: =$B$40+SUMPRODUCT($C$40:$J$40,$F21:$M21) -> 24.423473 | Q21: =$B$41+SUMPRODUCT($C$41:$J$41,$F21:$M21) -> 24.350106 | R21: =$B$42+SUMPRODUCT($C$42:$J$42,$F21:$M21) -> 23.394466 | S21: =$B$43+SUMPRODUCT($C$43:$J$43,$F21:$M21) -> 23.185574 | T21: =$B$44+SUMPRODUCT($C$44:$J$44,$F21:$M21) -> 23.231202 | U21: =$B$45+SUMPRODUCT($C$45:$J$45,$F21:$M21) -> 23.129636
A22: 12 | B22: =(A22-8.5)/7.5 -> 0.46666667 | C22: =$B$3/(1+EXP(-$B$4*(A22-$B$5))) -> 30 | D22: -3.2727117 | E22: =C22+D22 -> 26.727288 | F22: =$B22^1 -> 0.46666667 | G22: =$B22^2 -> 0.21777778 | H22: =$B22^3 -> 0.10162963 | I22: =$B22^4 -> 0.04742716 | J22: =$B22^5 -> 0.022132675 | K22: =$B22^6 -> 0.010328582 | L22: =$B22^7 -> 0.0048200048 | M22: =$B22^8 -> 0.0022493356 | N22: =$B$38+SUMPRODUCT($C$38:$J$38,$F22:$M22) -> 30.175055 | O22: =$B$39+SUMPRODUCT($C$39:$J$39,$F22:$M22) -> 28.291527 | P22: =$B$40+SUMPRODUCT($C$40:$J$40,$F22:$M22) -> 28.987981 | Q22: =$B$41+SUMPRODUCT($C$41:$J$41,$F22:$M22) -> 29.310161 | R22: =$B$42+SUMPRODUCT($C$42:$J$42,$F22:$M22) -> 28.748449 | S22: =$B$43+SUMPRODUCT($C$43:$J$43,$F22:$M22) -> 28.344592 | T22: =$B$44+SUMPRODUCT($C$44:$J$44,$F22:$M22) -> 28.314109 | U22: =$B$45+SUMPRODUCT($C$45:$J$45,$F22:$M22) -> 28.248215
... A34: 24 | B34: =(A34-8.5)/7.5 -> 2.0666667 | C34: =$B$3/(1+EXP(-$B$4*(A34-$B$5))) -> 59.113558 | D34: 2.0658355 | E34: =C34+D34 -> 61.179394 | F34: =$B34^1 -> 2.0666667 | G34: =$B34^2 -> 4.2711111 | H34: =$B34^3 -> 8.826963 | I34: =$B34^4 -> 18.24239 | J34: =$B34^5 -> 37.70094 | K34: =$B34^6 -> 77.915275 | L34: =$B34^7 -> 161.0249 | M34: =$B34^8 -> 332.7848 | N34: =$B$38+SUMPRODUCT($C$38:$J$38,$F34:$M34) -> 68.881366 | O34: =$B$39+SUMPRODUCT($C$39:$J$39,$F34:$M34) -> 114.71388 | P34: =$B$40+SUMPRODUCT($C$40:$J$40,$F34:$M34) -> 90.541597 | Q34: =$B$41+SUMPRODUCT($C$41:$J$41,$F34:$M34) -> 6.6184879 | R34: =$B$42+SUMPRODUCT($C$42:$J$42,$F34:$M34) -> -468.50953 | S34: =$B$43+SUMPRODUCT($C$43:$J$43,$F34:$M34) -> -1198.6702 | T34: =$B$44+SUMPRODUCT($C$44:$J$44,$F34:$M34) -> -1748.6164 | U34: =$B$45+SUMPRODUCT($C$45:$J$45,$F34:$M34) -> 1453.975
A37: Degree | B37: Coefficient of z^0 | C37: z^1 | D37: z^2 | E37: z^3 | F37: z^4 | G37: z^5 | H37: z^6 | I37: z^7 | J37: z^8
A38: 1 | B38: =INDEX(LINEST($E$11:$E$26,$F$11:$F$26),1,2) -> 18.885714 | C38: =INDEX(LINEST($E$11:$E$26,$F$11:$F$26),1,1) -> 24.191444 | D38: 0 | E38: 0 | F38: 0 | G38: 0 | H38: 0 | I38: 0 | J38: 0
A39: 2 | B39: =INDEX(LINEST($E$11:$E$26,$F$11:$G$26),1,3) -> 14.438496 | C39: =INDEX(LINEST($E$11:$E$26,$F$11:$G$26),1,2) -> 24.191444 | D39: =INDEX(LINEST($E$11:$E$26,$F$11:$G$26),1,1) -> 11.772049 | E39: 0 | F39: 0 | G39: 0 | H39: 0 | I39: 0 | J39: 0
A40: 3 | B40: =INDEX(LINEST($E$11:$E$26,$F$11:$H$26),1,4) -> 14.438496 | C40: =INDEX(LINEST($E$11:$E$26,$F$11:$H$26),1,3) -> 26.392448 | D40: =INDEX(LINEST($E$11:$E$26,$F$11:$H$26),1,2) -> 11.772049 | E40: =INDEX(LINEST($E$11:$E$26,$F$11:$H$26),1,1) -> -3.2537829 | F40: 0 | G40: 0 | H40: 0 | I40: 0 | J40: 0
A41: 4 | B41: =INDEX(LINEST($E$11:$E$26,$F$11:$I$26),1,5) -> 13.810634 | C41: =INDEX(LINEST($E$11:$E$26,$F$11:$I$26),1,4) -> 26.392448 | D41: =INDEX(LINEST($E$11:$E$26,$F$11:$I$26),1,3) -> 17.416679 | E41: =INDEX(LINEST($E$11:$E$26,$F$11:$I$26),1,2) -> -3.2537829 | F41: =INDEX(LINEST($E$11:$E$26,$F$11:$I$26),1,1) -> -5.8876105 | G41: 0 | H41: 0 | I41: 0 | J41: 0
A42: 5 | B42: =INDEX(LINEST($E$11:$E$26,$F$11:$J$26),1,6) -> 13.810634 | C42: =INDEX(LINEST($E$11:$E$26,$F$11:$J$26),1,5) -> 21.374085 | D42: =INDEX(LINEST($E$11:$E$26,$F$11:$J$26),1,4) -> 17.416679 | E42: =INDEX(LINEST($E$11:$E$26,$F$11:$J$26),1,3) -> 18.032682 | F42: =INDEX(LINEST($E$11:$E$26,$F$11:$J$26),1,2) -> -5.8876105 | G42: =INDEX(LINEST($E$11:$E$26,$F$11:$J$26),1,1) -> -17.311281 | H42: 0 | I42: 0 | J42: 0
A43: 6 | B43: =INDEX(LINEST($E$11:$E$26,$F$11:$K$26),1,7) -> 14.191335 | C43: =INDEX(LINEST($E$11:$E$26,$F$11:$K$26),1,6) -> 21.374085 | D43: =INDEX(LINEST($E$11:$E$26,$F$11:$K$26),1,5) -> 10.002377 | E43: =INDEX(LINEST($E$11:$E$26,$F$11:$K$26),1,4) -> 18.032682 | F43: =INDEX(LINEST($E$11:$E$26,$F$11:$K$26),1,3) -> 14.613985 | G43: =INDEX(LINEST($E$11:$E$26,$F$11:$K$26),1,2) -> -17.311281 | H43: =INDEX(LINEST($E$11:$E$26,$F$11:$K$26),1,1) -> -13.769729 | I43: 0 | J43: 0
A44: 7 | B44: =INDEX(LINEST($E$11:$E$26,$F$11:$L$26),1,8) -> 14.191335 | C44: =INDEX(LINEST($E$11:$E$26,$F$11:$L$26),1,7) -> 21.903565 | D44: =INDEX(LINEST($E$11:$E$26,$F$11:$L$26),1,6) -> 10.002377 | E44: =INDEX(LINEST($E$11:$E$26,$F$11:$L$26),1,5) -> 13.534333 | F44: =INDEX(LINEST($E$11:$E$26,$F$11:$L$26),1,4) -> 14.613985 | G44: =INDEX(LINEST($E$11:$E$26,$F$11:$L$26),1,3) -> -8.0322754 | H44: =INDEX(LINEST($E$11:$E$26,$F$11:$L$26),1,2) -> -13.769729 | I44: =INDEX(LINEST($E$11:$E$26,$F$11:$L$26),1,1) -> -5.3479985 | J44: 0
A45: 8 | B45: =INDEX(LINEST($E$11:$E$26,$F$11:$M$26),1,9) -> 14.29355 | C45: =INDEX(LINEST($E$11:$E$26,$F$11:$M$26),1,8) -> 21.903565 | D45: =INDEX(LINEST($E$11:$E$26,$F$11:$M$26),1,7) -> 6.4284092 | E45: =INDEX(LINEST($E$11:$E$26,$F$11:$M$26),1,6) -> 13.534333 | F45: =INDEX(LINEST($E$11:$E$26,$F$11:$M$26),1,5) -> 33.569842 | G45: =INDEX(LINEST($E$11:$E$26,$F$11:$M$26),1,4) -> -8.0322754 | H45: =INDEX(LINEST($E$11:$E$26,$F$11:$M$26),1,3) -> -45.213705 | I45: =INDEX(LINEST($E$11:$E$26,$F$11:$M$26),1,2) -> -5.3479985 | J45: =INDEX(LINEST($E$11:$E$26,$F$11:$M$26),1,1) -> 15.992076
A48: Degree (the complexity slider) | B48: Parameters | C48: RMS error on the history | D48: RMS error on later quarters | E48: Forecast for quarter 24 | F48: Better on history, worse later
A49: 1 | B49: 2 | C49: =SQRT(SUMXMY2(N11:N26,$E$11:$E$26)/$B$7) -> 4.3467413 | D49: =SQRT(SUMXMY2(N27:N34,$E$27:$E$34)/$B$8) -> 4.6562643 | E49: =N34 -> 68.881366
A50: 2 | B50: 3 | C50: =SQRT(SUMXMY2(O11:O26,$E$11:$E$26)/$B$7) -> 1.8050212 | D50: =SQRT(SUMXMY2(O27:O34,$E$27:$E$34)/$B$8) -> 31.778027 | E50: =O34 -> 114.71388 | F50: =IF(AND(C50<$C$49,D50>$D$49),1,0) -> 1
A51: 3 | B51: 4 | C51: =SQRT(SUMXMY2(P11:P26,$E$11:$E$26)/$B$7) -> 1.7090641 | D51: =SQRT(SUMXMY2(P27:P34,$E$27:$E$34)/$B$8) -> 18.442831 | E51: =P34 -> 90.541597 | F51: =IF(AND(C51<$C$49,D51>$D$49),1,0) -> 1
A52: 4 | B52: 5 | C52: =SQRT(SUMXMY2(Q11:Q26,$E$11:$E$26)/$B$7) -> 1.6192012 | D52: =SQRT(SUMXMY2(Q27:Q34,$E$27:$E$34)/$B$8) -> 24.772656 | E52: =Q34 -> 6.6184879 | F52: =IF(AND(C52<$C$49,D52>$D$49),1,0) -> 1
A53: 5 | B53: 6 | C53: =SQRT(SUMXMY2(R11:R26,$E$11:$E$26)/$B$7) -> 1.3969413 | D53: =SQRT(SUMXMY2(R27:R34,$E$27:$E$34)/$B$8) -> 248.60801 | E53: =R34 -> -468.50953 | F53: =IF(AND(C53<$C$49,D53>$D$49),1,0) -> 1
A54: 6 | B54: 7 | C54: =SQRT(SUMXMY2(S11:S26,$E$11:$E$26)/$B$7) -> 1.3590594 | D54: =SQRT(SUMXMY2(S27:S34,$E$27:$E$34)/$B$8) -> 575.07783 | E54: =S34 -> -1198.6702 | F54: =IF(AND(C54<$C$49,D54>$D$49),1,0) -> 1
A55: 7 | B55: 8 | C55: =SQRT(SUMXMY2(T11:T26,$E$11:$E$26)/$B$7) -> 1.3577193 | D55: =SQRT(SUMXMY2(T27:T34,$E$27:$E$34)/$B$8) -> 810.75858 | E55: =T34 -> -1748.6164 | F55: =IF(AND(C55<$C$49,D55>$D$49),1,0) -> 1
A56: 8 | B56: 9 | C56: =SQRT(SUMXMY2(U11:U26,$E$11:$E$26)/$B$7) -> 1.3551492 | D56: =SQRT(SUMXMY2(U27:U34,$E$27:$E$34)/$B$8) -> 539.6614 | E56: =U34 -> 1453.975 | F56: =IF(AND(C56<$C$49,D56>$D$49),1,0) -> 1
...

Sheet LeaveRecord
A1: Leave the record: two models, one record (Definition 4.6; Theorem 4.3; Figure 4.3; Table 4.4; AXIOM Lab 1.4, step 4)
A3: The record: Unit A's first year | B3: Value
A4: Total today, H | B4: =Declarations!D12 -> 500
A5: Software share today, s | B5: =Declarations!E12 -> 0.2
A6: Total next year, as recorded | B6: =Projection!$D$14 -> 476
A8: Model fitted to the record | B8: Prediction | C8: Discrepancy | D8: Squared error
A9: Total-only model: rate x H | B9: =Rate_r*B4 -> 476 | C9: =ABS(B9-$B$6) -> 0 | D9: =(B9-$B$6)^2 -> 0
A10: Detailed model: H (0.95 + 0.01 s) | B10: =B4*(1-Exit_L+(Exit_L-Exit_S)*B5) -> 476 | C10: =ABS(B10-$B$6) -> 0 | D10: =(B10-$B$6)^2 -> 0
A12: A unit of any size on the record's mix | B12: Total-only model | C12: Detailed model | D12: Gap
A13: 100 | B13: =Rate_r*A13 -> 95.2 | C13: =A13*(1-Exit_L+(Exit_L-Exit_S)*$B$5) -> 95.2 | D13: =ABS(B13-C13) -> 0
A14: 250 | B14: =Rate_r*A14 -> 238 | C14: =A14*(1-Exit_L+(Exit_L-Exit_S)*$B$5) -> 238 | D14: =ABS(B14-C14) -> 0
A15: 1000 | B15: =Rate_r*A15 -> 952 | C15: =A15*(1-Exit_L+(Exit_L-Exit_S)*$B$5) -> 952 | D15: =ABS(B15-C15) -> 0
A16: 5000 | B16: =Rate_r*A16 -> 4760 | C16: =A16*(1-Exit_L+(Exit_L-Exit_S)*$B$5) -> 4760 | D16: =ABS(B16-C16) -> 0
A18: Beyond the record: software share of a unit of 500 | B18: Total-only model | C18: Detailed model | D18: Gap
A19: 0 | B19: =Rate_r*500 -> 476 | C19: =500*(1-Exit_L+(Exit_L-Exit_S)*A19) -> 475 | D19: =C19-B19 -> -1
A20: 0.1 | B20: =Rate_r*500 -> 476 | C20: =500*(1-Exit_L+(Exit_L-Exit_S)*A20) -> 475.5 | D20: =C20-B20 -> -0.5
A21: 0.2 | B21: =Rate_r*500 -> 476 | C21: =500*(1-Exit_L+(Exit_L-Exit_S)*A21) -> 476 | D21: =C21-B21 -> 0
A22: 0.3 | B22: =Rate_r*500 -> 476 | C22: =500*(1-Exit_L+(Exit_L-Exit_S)*A22) -> 476.5 | D22: =C22-B22 -> 0.5
A23: 0.4 | B23: =Rate_r*500 -> 476 | C23: =500*(1-Exit_L+(Exit_L-Exit_S)*A23) -> 477 | D23: =C23-B23 -> 1
A24: 0.5 | B24: =Rate_r*500 -> 476 | C24: =500*(1-Exit_L+(Exit_L-Exit_S)*A24) -> 477.5 | D24: =C24-B24 -> 1.5
A25: 0.6 | B25: =Rate_r*500 -> 476 | C25: =500*(1-Exit_L+(Exit_L-Exit_S)*A25) -> 478 | D25: =C25-B25 -> 2
A26: 0.7 | B26: =Rate_r*500 -> 476 | C26: =500*(1-Exit_L+(Exit_L-Exit_S)*A26) -> 478.5 | D26: =C26-B26 -> 2.5
A27: 0.8 | B27: =Rate_r*500 -> 476 | C27: =500*(1-Exit_L+(Exit_L-Exit_S)*A27) -> 479 | D27: =C27-B27 -> 3
A28: 0.9 | B28: =Rate_r*500 -> 476 | C28: =500*(1-Exit_L+(Exit_L-Exit_S)*A28) -> 479.5 | D28: =C28-B28 -> 3.5
A29: 1 | B29: =Rate_r*500 -> 476 | C29: =500*(1-Exit_L+(Exit_L-Exit_S)*A29) -> 480 | D29: =C29-B29 -> 4
A31: Gap at Unit B's mix, 80 percent software | B31: =INDEX(D19:D29,MATCH(0.8,A19:A29,0)) -> 3
A32: Unit A's five-year record: the total-only model's largest miss | B32: =MAX(MAX(TotalOnly!F6:F11),-MIN(TotalOnly!F6:F11)) -> 1.0770477
A33: Unit B, year five: the total-only model's miss | B33: =ABS(TotalOnly!E11) -> 12.798886
A34: Both models fit the record exactly and agree for every unit on its mix: no statistic computed from the record can tell them apart (Theorem 4.3). Off the record they separate in proportion to the distance from it.
A36: Section 4.5: the digital-program model, validated on seven years of history | B36: In the record? | C36: The evidence
A37: the program's leverage and liquidity | B37: within the ranges history visited | C37: validation evidence applies
A38: capability spending above 40 percent of capital spending | B38: no year in the record | C38: carried by assumptions
A39: two platforms run side by side | B39: no period in the record | C39: carried by assumptions
A40: a talent market like the one the hiring plan assumes | B40: none in the record | C40: carried by assumptions
A41: The assumptions that carry it: an attrition mechanism credentialed elsewhere, an adoption mechanism declared as an assumption rather than fitted. The model's report should say so beside each such number.

Sheet Triggers
A1: Set triggers: replay five years of use (Section 4.6; Figure 4.4; Table 4.4; AXIOM Lab 1.4, step 5)
A3: Calibration mix: Unit A's software share today | B3: =Declarations!E12 -> 0.2
A4: Error tolerance (engineers): a setting, the book declares none | B4: 1
A5: Mix tolerance (points of software share): a setting | B5: 5
A7: Year | B7: Unit A: plan error | C7: Unit A: share, points from the calibration mix | D7: Unit B: plan error | E7: Unit B: share, points from the calibration mix | F7: A: error fires | G7: A: mix fires | H7: B: error fires | I7: B: mix fires
A8: 0 | B8: =ABS(ROUND(TotalOnly!F6,9)) -> 0 | C8: =100*ABS(Projection!$E$13-$B$3) -> 0 | D8: =ABS(ROUND(TotalOnly!E6,9)) -> 0 | E8: =100*ABS(Projection!$I$13-$B$3) -> 60 | F8: =IF(B8>$B$4+0.000000000001,1,0) -> 0 | G8: =IF(C8>$B$5+0.000000000001,1,0) -> 0 | H8: =IF(D8>$B$4+0.000000000001,1,0) -> 0 | I8: =IF(E8>$B$5+0.000000000001,1,0) -> 1
A9: 1 | B9: =ABS(ROUND(TotalOnly!F7,9)) -> 0 | C9: =100*ABS(Projection!$E$14-$B$3) -> 2.6890756 | D9: =ABS(ROUND(TotalOnly!E7,9)) -> 3 | E9: =100*ABS(Projection!$I$14-$B$3) -> 60.793319 | F9: =IF(B9>$B$4+0.000000000001,1,0) -> 0 | G9: =IF(C9>$B$5+0.000000000001,1,0) -> 0 | H9: =IF(D9>$B$4+0.000000000001,1,0) -> 1 | I9: =IF(E9>$B$5+0.000000000001,1,0) -> 1
A10: 2 | B10: =ABS(ROUND(TotalOnly!F8,9)) -> 0.128 | C10: =100*ABS(Projection!$E$15-$B$3) -> 5.3088599 | D10: =ABS(ROUND(TotalOnly!E8,9)) -> 5.768 | E10: =100*ABS(Projection!$I$15-$B$3) -> 61.556698 | F10: =IF(B10>$B$4+0.000000000001,1,0) -> 0 | G10: =IF(C10>$B$5+0.000000000001,1,0) -> 1 | H10: =IF(D10>$B$4+0.000000000001,1,0) -> 1 | I10: =IF(E10>$B$5+0.000000000001,1,0) -> 1
A11: 3 | B11: =ABS(ROUND(TotalOnly!F9,9)) -> 0.362496 | C11: =100*ABS(Projection!$E$16-$B$3) -> 7.8597157 | D11: =ABS(ROUND(TotalOnly!E9,9)) -> 8.316096 | E11: =100*ABS(Projection!$I$16-$B$3) -> 62.291147 | F11: =IF(B11>$B$4+0.000000000001,1,0) -> 0 | G11: =IF(C11>$B$5+0.000000000001,1,0) -> 1 | H11: =IF(D11>$B$4+0.000000000001,1,0) -> 1 | I11: =IF(E11>$B$5+0.000000000001,1,0) -> 1
A12: 4 | B12: =ABS(ROUND(TotalOnly!F10,9)) -> 0.68444979 | C12: =100*ABS(Projection!$E$17-$B$3) -> 10.342109 | D12: =ABS(ROUND(TotalOnly!E10,9)) -> 10.65597 | E12: =100*ABS(Projection!$I$17-$B$3) -> 62.997652 | F12: =IF(B12>$B$4+0.000000000001,1,0) -> 0 | G12: =IF(C12>$B$5+0.000000000001,1,0) -> 1 | H12: =IF(D12>$B$4+0.000000000001,1,0) -> 1 | I12: =IF(E12>$B$5+0.000000000001,1,0) -> 1
A13: 5 | B13: =ABS(ROUND(TotalOnly!F11,9)) -> 1.0770477 | C13: =100*ABS(Projection!$E$18-$B$3) -> 12.756601 | D13: =ABS(ROUND(TotalOnly!E11,9)) -> 12.798886 | E13: =100*ABS(Projection!$I$18-$B$3) -> 63.677175 | F13: =IF(B13>$B$4+0.000000000001,1,0) -> 1 | G13: =IF(C13>$B$5+0.000000000001,1,0) -> 1 | H13: =IF(D13>$B$4+0.000000000001,1,0) -> 1 | I13: =IF(E13>$B$5+0.000000000001,1,0) -> 1
A15: First year the trigger fires (-1: not within five years) | B15: Unit A | C15: Unit B
A16: Plan error above the error tolerance | B16: =IF(SUM(F8:F13)=0,-1,MATCH(1,F8:F13,0)-1) -> 5 | C16: =IF(SUM(H8:H13)=0,-1,MATCH(1,H8:H13,0)-1) -> 1
A17: Software share beyond the mix tolerance | B17: =IF(SUM(G8:G13)=0,-1,MATCH(1,G8:G13,0)-1) -> 2 | C17: =IF(SUM(I8:I13)=0,-1,MATCH(1,I8:I13,0)-1) -> 0
A19: Trigger settings side by side | B19: Indicator | C19: Tolerance | D19: Unit A: first year | E19: Unit B: first year | F19: A fires, year 0 | G19: A fires, year 1 | H19: A fires, year 2 | I19: A fires, year 3 | J19: A fires, year 4 | K19: A fires, year 5 | L19: B fires, year 0 | M19: B fires, year 1 | N19: B fires, year 2 | O19: B fires, year 3 | P19: B fires, year 4 | Q19: B fires, year 5
A20: plan error above (engineers) | B20: error | C20: 1 | D20: =IF(SUM(F20:K20)=0,-1,MATCH(1,F20:K20,0)-1) -> 5 | E20: =IF(SUM(L20:Q20)=0,-1,MATCH(1,L20:Q20,0)-1) -> 1 | F20: =IF(IF($B20="error",B8,C8)>$C20+0.000000000001,1,0) -> 0 | G20: =IF(IF($B20="error",B9,C9)>$C20+0.000000000001,1,0) -> 0 | H20: =IF(IF($B20="error",B10,C10)>$C20+0.000000000001,1,0) -> 0 | I20: =IF(IF($B20="error",B11,C11)>$C20+0.000000000001,1,0) -> 0 | J20: =IF(IF($B20="error",B12,C12)>$C20+0.000000000001,1,0) -> 0 | K20: =IF(IF($B20="error",B13,C13)>$C20+0.000000000001,1,0) -> 1 | L20: =IF(IF($B20="error",D8,E8)>$C20+0.000000000001,1,0) -> 0 | M20: =IF(IF($B20="error",D9,E9)>$C20+0.000000000001,1,0) -> 1 | N20: =IF(IF($B20="error",D10,E10)>$C20+0.000000000001,1,0) -> 1 | O20: =IF(IF($B20="error",D11,E11)>$C20+0.000000000001,1,0) -> 1 | P20: =IF(IF($B20="error",D12,E12)>$C20+0.000000000001,1,0) -> 1 | Q20: =IF(IF($B20="error",D13,E13)>$C20+0.000000000001,1,0) -> 1
A21: plan error above (engineers) | B21: error | C21: 2.5 | D21: =IF(SUM(F21:K21)=0,-1,MATCH(1,F21:K21,0)-1) -> -1 | E21: =IF(SUM(L21:Q21)=0,-1,MATCH(1,L21:Q21,0)-1) -> 1 | F21: =IF(IF($B21="error",B8,C8)>$C21+0.000000000001,1,0) -> 0 | G21: =IF(IF($B21="error",B9,C9)>$C21+0.000000000001,1,0) -> 0 | H21: =IF(IF($B21="error",B10,C10)>$C21+0.000000000001,1,0) -> 0 | I21: =IF(IF($B21="error",B11,C11)>$C21+0.000000000001,1,0) -> 0 | J21: =IF(IF($B21="error",B12,C12)>$C21+0.000000000001,1,0) -> 0 | K21: =IF(IF($B21="error",B13,C13)>$C21+0.000000000001,1,0) -> 0 | L21: =IF(IF($B21="error",D8,E8)>$C21+0.000000000001,1,0) -> 0 | M21: =IF(IF($B21="error",D9,E9)>$C21+0.000000000001,1,0) -> 1 | N21: =IF(IF($B21="error",D10,E10)>$C21+0.000000000001,1,0) -> 1 | O21: =IF(IF($B21="error",D11,E11)>$C21+0.000000000001,1,0) -> 1 | P21: =IF(IF($B21="error",D12,E12)>$C21+0.000000000001,1,0) -> 1 | Q21: =IF(IF($B21="error",D13,E13)>$C21+0.000000000001,1,0) -> 1
A22: plan error above (engineers) | B22: error | C22: 5 | D22: =IF(SUM(F22:K22)=0,-1,MATCH(1,F22:K22,0)-1) -> -1 | E22: =IF(SUM(L22:Q22)=0,-1,MATCH(1,L22:Q22,0)-1) -> 2 | F22: =IF(IF($B22="error",B8,C8)>$C22+0.000000000001,1,0) -> 0 | G22: =IF(IF($B22="error",B9,C9)>$C22+0.000000000001,1,0) -> 0 | H22: =IF(IF($B22="error",B10,C10)>$C22+0.000000000001,1,0) -> 0 | I22: =IF(IF($B22="error",B11,C11)>$C22+0.000000000001,1,0) -> 0 | J22: =IF(IF($B22="error",B12,C12)>$C22+0.000000000001,1,0) -> 0 | K22: =IF(IF($B22="error",B13,C13)>$C22+0.000000000001,1,0) -> 0 | L22: =IF(IF($B22="error",D8,E8)>$C22+0.000000000001,1,0) -> 0 | M22: =IF(IF($B22="error",D9,E9)>$C22+0.000000000001,1,0) -> 0 | N22: =IF(IF($B22="error",D10,E10)>$C22+0.000000000001,1,0) -> 1 | O22: =IF(IF($B22="error",D11,E11)>$C22+0.000000000001,1,0) -> 1 | P22: =IF(IF($B22="error",D12,E12)>$C22+0.000000000001,1,0) -> 1 | Q22: =IF(IF($B22="error",D13,E13)>$C22+0.000000000001,1,0) -> 1
A23: plan error above (engineers) | B23: error | C23: 10 | D23: =IF(SUM(F23:K23)=0,-1,MATCH(1,F23:K23,0)-1) -> -1 | E23: =IF(SUM(L23:Q23)=0,-1,MATCH(1,L23:Q23,0)-1) -> 4 | F23: =IF(IF($B23="error",B8,C8)>$C23+0.000000000001,1,0) -> 0 | G23: =IF(IF($B23="error",B9,C9)>$C23+0.000000000001,1,0) -> 0 | H23: =IF(IF($B23="error",B10,C10)>$C23+0.000000000001,1,0) -> 0 | I23: =IF(IF($B23="error",B11,C11)>$C23+0.000000000001,1,0) -> 0 | J23: =IF(IF($B23="error",B12,C12)>$C23+0.000000000001,1,0) -> 0 | K23: =IF(IF($B23="error",B13,C13)>$C23+0.000000000001,1,0) -> 0 | L23: =IF(IF($B23="error",D8,E8)>$C23+0.000000000001,1,0) -> 0 | M23: =IF(IF($B23="error",D9,E9)>$C23+0.000000000001,1,0) -> 0 | N23: =IF(IF($B23="error",D10,E10)>$C23+0.000000000001,1,0) -> 0 | O23: =IF(IF($B23="error",D11,E11)>$C23+0.000000000001,1,0) -> 0 | P23: =IF(IF($B23="error",D12,E12)>$C23+0.000000000001,1,0) -> 1 | Q23: =IF(IF($B23="error",D13,E13)>$C23+0.000000000001,1,0) -> 1
A24: software share beyond (points) | B24: mix | C24: 2.5 | D24: =IF(SUM(F24:K24)=0,-1,MATCH(1,F24:K24,0)-1) -> 1 | E24: =IF(SUM(L24:Q24)=0,-1,MATCH(1,L24:Q24,0)-1) -> 0 | F24: =IF(IF($B24="error",B8,C8)>$C24+0.000000000001,1,0) -> 0 | G24: =IF(IF($B24="error",B9,C9)>$C24+0.000000000001,1,0) -> 1 | H24: =IF(IF($B24="error",B10,C10)>$C24+0.000000000001,1,0) -> 1 | I24: =IF(IF($B24="error",B11,C11)>$C24+0.000000000001,1,0) -> 1 | J24: =IF(IF($B24="error",B12,C12)>$C24+0.000000000001,1,0) -> 1 | K24: =IF(IF($B24="error",B13,C13)>$C24+0.000000000001,1,0) -> 1 | L24: =IF(IF($B24="error",D8,E8)>$C24+0.000000000001,1,0) -> 1 | M24: =IF(IF($B24="error",D9,E9)>$C24+0.000000000001,1,0) -> 1 | N24: =IF(IF($B24="error",D10,E10)>$C24+0.000000000001,1,0) -> 1 | O24: =IF(IF($B24="error",D11,E11)>$C24+0.000000000001,1,0) -> 1 | P24: =IF(IF($B24="error",D12,E12)>$C24+0.000000000001,1,0) -> 1 | Q24: =IF(IF($B24="error",D13,E13)>$C24+0.000000000001,1,0) -> 1
A25: software share beyond (points) | B25: mix | C25: 5 | D25: =IF(SUM(F25:K25)=0,-1,MATCH(1,F25:K25,0)-1) -> 2 | E25: =IF(SUM(L25:Q25)=0,-1,MATCH(1,L25:Q25,0)-1) -> 0 | F25: =IF(IF($B25="error",B8,C8)>$C25+0.000000000001,1,0) -> 0 | G25: =IF(IF($B25="error",B9,C9)>$C25+0.000000000001,1,0) -> 0 | H25: =IF(IF($B25="error",B10,C10)>$C25+0.000000000001,1,0) -> 1 | I25: =IF(IF($B25="error",B11,C11)>$C25+0.000000000001,1,0) -> 1 | J25: =IF(IF($B25="error",B12,C12)>$C25+0.000000000001,1,0) -> 1 | K25: =IF(IF($B25="error",B13,C13)>$C25+0.000000000001,1,0) -> 1 | L25: =IF(IF($B25="error",D8,E8)>$C25+0.000000000001,1,0) -> 1 | M25: =IF(IF($B25="error",D9,E9)>$C25+0.000000000001,1,0) -> 1 | N25: =IF(IF($B25="error",D10,E10)>$C25+0.000000000001,1,0) -> 1 | O25: =IF(IF($B25="error",D11,E11)>$C25+0.000000000001,1,0) -> 1 | P25: =IF(IF($B25="error",D12,E12)>$C25+0.000000000001,1,0) -> 1 | Q25: =IF(IF($B25="error",D13,E13)>$C25+0.000000000001,1,0) -> 1
A26: software share beyond (points) | B26: mix | C26: 10 | D26: =IF(SUM(F26:K26)=0,-1,MATCH(1,F26:K26,0)-1) -> 4 | E26: =IF(SUM(L26:Q26)=0,-1,MATCH(1,L26:Q26,0)-1) -> 0 | F26: =IF(IF($B26="error",B8,C8)>$C26+0.000000000001,1,0) -> 0 | G26: =IF(IF($B26="error",B9,C9)>$C26+0.000000000001,1,0) -> 0 | H26: =IF(IF($B26="error",B10,C10)>$C26+0.000000000001,1,0) -> 0 | I26: =IF(IF($B26="error",B11,C11)>$C26+0.000000000001,1,0) -> 0 | J26: =IF(IF($B26="error",B12,C12)>$C26+0.000000000001,1,0) -> 1 | K26: =IF(IF($B26="error",B13,C13)>$C26+0.000000000001,1,0) -> 1 | L26: =IF(IF($B26="error",D8,E8)>$C26+0.000000000001,1,0) -> 1 | M26: =IF(IF($B26="error",D9,E9)>$C26+0.000000000001,1,0) -> 1 | N26: =IF(IF($B26="error",D10,E10)>$C26+0.000000000001,1,0) -> 1 | O26: =IF(IF($B26="error",D11,E11)>$C26+0.000000000001,1,0) -> 1 | P26: =IF(IF($B26="error",D12,E12)>$C26+0.000000000001,1,0) -> 1 | Q26: =IF(IF($B26="error",D13,E13)>$C26+0.000000000001,1,0) -> 1
A28: Year 0: the trigger fires before the first forecast; Unit B lies outside the record from the start. A third trigger is an event, not a measurement: revalidation follows transformation (Section 4.6).

Sheet Contract
A1: The modeling contract for the digital-program model, the lab's deliverable (Section 4.1; Tables 3.1 and 4.2-4.4; Figure 4.4)
A3: (i) Readings, with units (Table 3.1) | B3: Unit
A4: liquidity | B4: US$ billion
A5: net leverage | B5: net debt / EBITDA
A6: workforce capability | B6: index, 0-100
A7: technology platform | B7: index, 0-100
A8: operational efficiency | B8: index, 0-100
A9: return on invested capital | B9: ratio
A10: strategic risk (lower is better) | B10: index, 0-100
A11: market share | B11: ratio
A12: Readings at level L3 | B12: =COUNTA(A4:A11) -> 8
A13: Measurement (Section 4.5): liquidity, leverage and market share are observed directly and precisely; capability, efficiency and strategic risk are index proxies with material error; organizational cohesion is latent.
A15: (ii) Assumption class (Table 4.3) | B15: Content | C15: Meridian instance
A16: Structural | B16: which mechanisms exist; coupling; functional forms | C16: modernization affects efficiency with a one-period lag
A17: Parametric | B17: values and ranges of named parameters | C17: talent attrition between 6 and 11 percent a year
A18: Domain | B18: the region where the model is asserted | C18: leverage at most 4.5x; no acquisitions
A19: Measurement | B19: proxies, error sizes, and delays for each reading | C19: capability index: survey proxy, +/-5 points, twice a year
A20: Horizon | B20: periods over which conclusions are claimed | C20: 12 quarters
A21: Assumption classes | B21: =COUNTA(A16:A20) -> 5
A23: (iii) Validated domain and tolerance | B23: Declaration
A24: record | B24: seven years of history
A25: inside it | B25: the program's leverage and liquidity
A26: beyond it | B26: capability spending above 40 percent of capital spending; two platforms side by side; the hiring plan's talent market
A27: tolerance | B27: declared with the record (Definition 4.6)
A29: (iv) Lifecycle plan (Figure 4.4) | B29: Stage
A30: 1 | B30: Specify
A31: 2 | B31: Build
A32: 3 | B32: Verify
A33: 4 | B33: Validate
A34: 5 | B34: Deploy
A35: 6 | B35: Monitor
A36: 7 | B36: Revise or retire
A37: Stages of the lifecycle | B37: =COUNTA(B30:B36) -> 7
A38: Triggers: drift indicators beyond their declared tolerances (Triggers sheet); the program's start and completion, because revalidation follows transformation. Retirement at the edge of the domain is a success mode.
A40: Parts of the contract (Section 4.1) | B40: Declared on this sheet
A41: (i) the readings represented, with units and measurement conventions | B41: yes
A42: (ii) the assumptions, by the classes of Table 4.3 | B42: yes
A43: (iii) the validated domain and tolerance | B43: yes
A44: (iv) the lifecycle plan | B44: yes
A45: Parts of the modeling contract | B45: =COUNTA(A41:A44) -> 4
...

Sheet Reference_Values
A1: Checkpoint | B1: Engine value | C1: Meaning (where in the book)
A2: Unit A legacy engineers next year | B2: 368 | C2: Worked Example 4.1, Step 1: 368
A3: Unit A total next year | B3: 476 | C3: Step 1: 476
A4: Unit B software engineers next year | B4: 387 | C4: Step 1: 387
A5: Unit B total next year | B5: 479 | C5: Step 1: 479
A6: Unit A total, year 5 | B6: 392.05723 | C6: Table 4.5: 392.1
A7: Unit B total, year 5 | B7: 403.77907 | C7: Table 4.5: 403.8
A8: Total-only model's rate | B8: 0.952 | C8: Step 3: 0.952
A9: Total-only model, year 5 | B9: 390.98018 | C9: Table 4.5: 391.0
A10: Error for Unit B, year 1 | B10: -3 | C10: Table 4.5: -3.0
