Workbook

Sheet README
B1: DCT Laboratory — Vol I, Ch 16: Synthesis, Future Directions, and Transition to Volume II
B2: Seed 26116 · Companion to DCT_V1_Ch16_Lab.ipynb and AXIOM Lab 1.16 (module AXIOM-16). Money in $ million.
B4: Worked Example 16.1, Is Meridian Ready to Optimize?, with the book's declarations, and the five steps of AXIOM Lab 1.16, Certifying Meridian for Volume II.
B5: Declarations: the digital program, its uncertainty, the levers' prices, the commitments, the readings' errors and the register.
B6: Framework: Table 16.1's evidence for the five limitations, and Theorem 16.2's instance (lab step 1).
B7: Scorecard: Chapter 1's model at year 5 and the CFO's scorecard on two scales, the gap (R1) leaves to the board.
B8: Quantiles: the one simulation output, from the book's 100,000 paths (seed 8): each line's critical depth at four appetites; the least delay and cost of every package, the 5 percent package and its price.
B9: R1_Inventory, R2_Consistency, R3_Panel, R4_Horizon: the four gates (Steps 1-4; lab step 2).
B10: DigitalTwin: the gain audit flags a drift (the scenario is this workbook's declaration, seed 26116) and Online Appendix 16.B.2's models within the ceilings (lab step 3).
B11: Certificate: Table 16.4, the grades, the work orders, and Appendix 16.A's runway (Step 5).
B12: Dependencies and Citations: Volume I's citation graph, Figure 16.2, the longest chains and what Theorem 16.4 rests on (lab step 4). Export: the certified instance in Volume II's canonical form (lab step 5).
B13: Reference_Values and Checks: the notebook engine's numbers and a PASS/FAIL comparison with this workbook's formulas.
... B19: Cross-sheet link: green.

Sheet Declarations
A1: Declarations (Worked Example 16.1; Worked Examples 8.1 and 15.1; Tables 5.2, 5.4 and 15.2). Money in $ million.
A3: Quantity | B3: Value | C3: Source | D3: Name
A4: Liquidity today | B4: 620 | C4: Table 5.4; Worked Example 8.1 | D4: Liq0
A5: The board's liquidity floor | B5: 350 | C5: Table 5.4 | D5: Floor_m
A6: Cash above the floor | B6: =B4-B5 -> 270 | C6: Chapter 13's joint check: 270 | D6: Pool
A7: Liquidity per index point | B7: 6.2 | C7: Chapter 1: index 100 = $620 million | D7: Usd_pt
A8: Chapter 1's liquidity target (index) | B8: 112 | C8: Online Appendix 1.B.4 | D8: Liq_target
A9: Relaxation toward the target, a year | B9: 0.35 | C9: Online Appendix 1.B.4 | D9: Relax
A10: Depth of the program's draw, as planned (index points) | B10: 28 | C10: Chapter 1's digital program | D10: Depth0
A11: Years to the deepest draw | B11: 2 | C11: Chapter 1's digital program | D11: Tau
A12: Depth cut by a quarter of delay (index points) | B12: 4 | C12: Chapter 8's phased build: depth 20 for two quarters of delay | D12: Depth_per_q
A13: Standby-line fees a year (share of the line) | B13: 0.01 | C13: Worked Example 15.1 | D13: Fee_year
A14: Program length (years) | B14: 3 | C14: Twelve quarters | D14: Years
A15: Fees over the program (share of the line) | B15: =B13*B14 -> 0.03 | C15: $3 million per $100 million | D15: Fee
A16: Value of a quarter of delay | B16: 8 | C16: The transformation office | D16: Vq
A17: The board's appetite: chance of a breach in some quarter | B17: 0.05 | C17: Chapter 8 | D17: Appetite
A18: Revenue | B18: 4200 | C18: Chapter 1 | D18: Revenue
A19: EBITDA margin | B19: 0.118 | C19: Chapter 1 | D19: Margin
A20: EBITDA | B20: =B18*B19 -> 495.6 | C20: $495.6 million | D20: Ebitda
A21: Net leverage today (net debt / EBITDA) | B21: 3.4 | C21: Table 5.4 | D21: Lev0
A22: Net debt | B22: =B21*B20 -> 1685.04 | C22: $1,685 million | D22: Net_debt
A23: Covenant: net leverage at most | B23: 4.5 | C23: Table 5.4; the CFO | D23: Covenant
A24: Workforce capability today | B24: 58 | C24: Table 5.2 | D24: Capability
A25: Capability floor for the digital build | B25: 55 | C25: HR and the CTO (Table 15.2) | D25: Cap_floor
A26: Strategic-risk ceiling | B26: 75 | C26: Table 5.4; the CRO and the board | D26: Risk_ceil
A27: Error of the leverage reading (share of the reading) | B27: 0.02 | C27: Table 5.2: audited accounts | D27: Band_lev
A28: Error of the capability reading (points) | B28: 5 | C28: Table 5.2: skills survey | D28: Band_cap
A29: Error of the strategic-risk reading (points) | B29: 6 | C29: Table 5.2: risk committee | D29: Band_risk
A30: Persistence of the execution and market deviation | B30: 0.6 | C30: Worked Example 8.1 | D30: A_e
A31: Surprise a quarter: standard deviation | B31: 50 | C31: Worked Example 8.1 | D31: Sd_w
A32: Funding-window closures a year | B32: 0.1 | C32: Worked Example 8.1 | D32: Lam
A33: Closure size: mean | B33: 120 | C33: Worked Example 8.1 | D33: J_mean
A34: Closure size: standard deviation | B34: 50 | C34: Worked Example 8.1 | D34: J_sd
A35: Gamma shape of a closure | B35: =(B33/B34)^2 -> 5.76 | C35: 5.76 | D35: G_shape
A36: Gamma scale of a closure | B36: =B34^2/B33 -> 20.833333 | C36: 20.83 | D36: G_scale
A37: Paths | B37: 100000 | C37: Worked Example 8.1 | D37: N_paths
A38: Random seed of the book's paths | B38: 8 | C38: Volume II, Online Appendix 1.B.4 | D38: Book_seed
A39: Chapter 8's package: line | B39: 100 | C39: Worked Example 8.1 | D39: Line8
A40: Chapter 8's package: delay (quarters) | B40: 2 | C40: the phased build | D40: Delay8
A41: Coupling register: ceiling of each core link | B41: 0.4 | C41: Chapter 14; the risk office | D41: Ceil_gain
...

Sheet Framework
A1: Walk the framework: Table 16.1's evidence, and Theorem 16.2's instance (AXIOM Lab 1.16, step 1; Sections 16.1-16.2)
A3: Limitation removed (Table 16.1) | B3: Meridian's evidence | C3: Reading
A4: L1 Fragmentation: the program's deepest draw | B4: =R2_Consistency!B19 -> 138.04962 | C4: $138 million
A5: L1 Fragmentation: the treasury's buffer | B5: =R2_Consistency!B20 -> 186.86698 | C5: $187 million, both on the $270 million
A6: L2 Snapshots: the average path's lowest point | B6: =R2_Consistency!B24 -> 459.85405 | C6: never breaches the floor
A7: L2 Snapshots: paths that breach the floor (engine, seed 8) | B7: 0.24622 | C7: 24.6 percent
A8: L3 One-number summaries: weight points that tie the leaders | B8: =Scorecard!B43 -> 1.5924031 | C8: 1.6 weight points; the scale flips the ranking
A9: L4 No state: a shock in the core halves in (quarters) | B9: =R3_Panel!B9 -> 3.1062837 | C9: 3.1 quarters
A10: L4 No state: one more link, spectral radius | B10: =R3_Panel!B26 -> 1.0246211 | C10: above 1: a shock would grow
A11: L5 No well-posed problem: the 5% appetite met for | B11: =Quantiles!B95 -> 10.440611 | C11: $10.4 million
A12: L5 No well-posed problem: a breach priced at | B12: =Quantiles!B102 -> 180.70148 | C12: about $180 million
A15: Theorem 16.2's instance (Worked Example 4.1) | B15: Legacy | C15: Software | D15: Total | E15: A year: legacy keeps 0.92 (5% leave, 3% retrain); software keeps 0.96 and gains 0.03 of legacy.
A16: Legacy kept a year | B16: 0.92
A17: Retrained into software a year | B17: 0.03
A18: Software kept a year | B18: 0.96
A20: Year | B20: Unit A legacy | C20: Unit A software | D20: Unit A total | E20: Unit B legacy | F20: Unit B software | G20: Unit B total | H20: Totals model
A21: 0 | B21: 400 | C21: 100 | D21: =B21+C21 -> 500 | E21: 100 | F21: 400 | G21: =E21+F21 -> 500 | H21: =D21 -> 500
A22: 1 | B22: =$B$16*B21 -> 368 | C22: =$B$18*C21+$B$17*B21 -> 108 | D22: =B22+C22 -> 476 | E22: =$B$16*E21 -> 92 | F22: =$B$18*F21+$B$17*E21 -> 387 | G22: =E22+F22 -> 479 | H22: =H21*$D$22/$D$21 -> 476
A23: 2 | B23: =$B$16*B22 -> 338.56 | C23: =$B$18*C22+$B$17*B22 -> 114.72 | D23: =B23+C23 -> 453.28 | E23: =$B$16*E22 -> 84.64 | F23: =$B$18*F22+$B$17*E22 -> 374.28 | G23: =E23+F23 -> 458.92 | H23: =H22*$D$22/$D$21 -> 453.152
A24: 3 | B24: =$B$16*B23 -> 311.4752 | C24: =$B$18*C23+$B$17*B23 -> 120.288 | D24: =B24+C24 -> 431.7632 | E24: =$B$16*E23 -> 77.8688 | F24: =$B$18*F23+$B$17*E23 -> 361.848 | G24: =E24+F24 -> 439.7168 | H24: =H23*$D$22/$D$21 -> 431.4007
A25: 4 | B25: =$B$16*B24 -> 286.55718 | C25: =$B$18*C24+$B$17*B24 -> 124.82074 | D25: =B25+C25 -> 411.37792 | E25: =$B$16*E24 -> 71.639296 | F25: =$B$18*F24+$B$17*E24 -> 349.71014 | G25: =E25+F25 -> 421.34944 | H25: =H24*$D$22/$D$21 -> 410.69347
A26: 5 | B26: =$B$16*B25 -> 263.63261 | C26: =$B$18*C25+$B$17*B25 -> 128.42462 | D26: =B26+C26 -> 392.05723 | E26: =$B$16*E25 -> 65.908152 | F26: =$B$18*F25+$B$17*E25 -> 337.87092 | G26: =E26+F26 -> 403.77907 | H26: =H25*$D$22/$D$21 -> 390.98018
A28: Unit A in year 5 | B28: =D26 -> 392.05723 | C28: 392
A29: Unit B in year 5 | B29: =G26 -> 403.77907 | C29: 404
A30: Engineers apart | B30: =B29-B28 -> 11.721838 | C30: Section 16.2: 12
A31: The totals model (calibrated on unit A's first year), both units | B31: =H26 -> 390.98018 | C31: 391
A32: Any answer from the declared total errs for one unit by at least | B32: =B30/2 -> 5.860919 | C32: Theorem 16.2(ii)

Sheet Scorecard
A1: The CFO's scorecard on two scales: the gap (R1) left for the board (Worked Example 16.1, Step 1; Chapter 11; Table 16.1, L3)
A2: Chapter 1's model (Online Appendix 1.B.4): value(t) = target + (today - target) e^(-rate t) + hump (t/peak) e^(1 - t/peak) + the jump at the sale (year 1). Readings: liquidity index L, technology T, efficiency E, strategic risk R (lower is better).
A4: Option | B4: Reading | C4: Today | D4: Target | E4: Rate a year | F4: Hump (signed) | G4: Hump peak (years) | H4: Jump at year 1 | I4: Value at the year | K4: Reading year | L4: 5
A5: Digital | B5: L | C5: 100 | D5: 112 | E5: 0.35 | F5: -28 | G5: 2 | H5: 0 | I5: =D5+(C5-D5)*EXP(-E5*$L$4)+IF(G5="",0,F5*($L$4/G5)*EXP(1-$L$4/G5))+H5*($L$4>=1) -> 94.295601
A6: Digital | B6: T | C6: 41 | D6: 78 | E6: 0.55 | F6: 0 | H6: 0 | I6: =D6+(C6-D6)*EXP(-E6*$L$4)+IF(G6="",0,F6*($L$4/G6)*EXP(1-$L$4/G6))+H6*($L$4>=1) -> 75.634669
A7: Digital | B7: E | C7: 71 | D7: 77 | E7: 0.5 | F7: -9 | G7: 1.5 | H7: 0 | I7: =D7+(C7-D7)*EXP(-E7*$L$4)+IF(G7="",0,F7*($L$4/G7)*EXP(1-$L$4/G7))+H7*($L$4>=1) -> 73.598331
A8: Digital | B8: R | C8: 64 | D8: 51 | E8: 0.4 | F8: 14 | G8: 1.2 | H8: 0 | I8: =D8+(C8-D8)*EXP(-E8*$L$4)+IF(G8="",0,F8*($L$4/G8)*EXP(1-$L$4/G8))+H8*($L$4>=1) -> 55.21775
A9: Restructuring | B9: L | C9: 100 | D9: 104 | E9: 0.3 | F9: 0 | H9: 18 | I9: =D9+(C9-D9)*EXP(-E9*$L$4)+IF(G9="",0,F9*($L$4/G9)*EXP(1-$L$4/G9))+H9*($L$4>=1) -> 121.10748
A10: Restructuring | B10: T | C10: 41 | D10: 38 | E10: 0.25 | F10: 0 | H10: 0 | I10: =D10+(C10-D10)*EXP(-E10*$L$4)+IF(G10="",0,F10*($L$4/G10)*EXP(1-$L$4/G10))+H10*($L$4>=1) -> 38.859514
A11: Restructuring | B11: E | C11: 71 | D11: 74 | E11: 0.45 | F11: 0 | H11: 0 | I11: =D11+(C11-D11)*EXP(-E11*$L$4)+IF(G11="",0,F11*($L$4/G11)*EXP(1-$L$4/G11))+H11*($L$4>=1) -> 73.683802
A12: Restructuring | B12: R | C12: 64 | D12: 56 | E12: 0.35 | F12: 0 | H12: -8 | I12: =D12+(C12-D12)*EXP(-E12*$L$4)+IF(G12="",0,F12*($L$4/G12)*EXP(1-$L$4/G12))+H12*($L$4>=1) -> 49.390192
A13: Turnaround | B13: L | C13: 100 | D13: 106 | E13: 0.45 | F13: 0 | H13: 0 | I13: =D13+(C13-D13)*EXP(-E13*$L$4)+IF(G13="",0,F13*($L$4/G13)*EXP(1-$L$4/G13))+H13*($L$4>=1) -> 105.3676
A14: Turnaround | B14: T | C14: 41 | D14: 33 | E14: 0.2 | F14: 0 | H14: 0 | I14: =D14+(C14-D14)*EXP(-E14*$L$4)+IF(G14="",0,F14*($L$4/G14)*EXP(1-$L$4/G14))+H14*($L$4>=1) -> 35.943036
A15: Turnaround | B15: E | C15: 71 | D15: 79 | E15: 0.6 | F15: 0 | H15: 0 | I15: =D15+(C15-D15)*EXP(-E15*$L$4)+IF(G15="",0,F15*($L$4/G15)*EXP(1-$L$4/G15))+H15*($L$4>=1) -> 78.601703
A16: Turnaround | B16: R | C16: 64 | D16: 67 | E16: 0.3 | F16: 0 | H16: 0 | I16: =D16+(C16-D16)*EXP(-E16*$L$4)+IF(G16="",0,F16*($L$4/G16)*EXP(1-$L$4/G16))+H16*($L$4>=1) -> 66.33061
A19: Year-5 readings | B19: L | C19: T | D19: E | E19: R | F19: CFO score (L + T + E - R)/4
A20: Sign (risk: lower is better) | B20: 1 | C20: 1 | D20: 1 | E20: -1
A21: Today | B21: =C5 -> 100 | C21: =C6 -> 41 | D21: =C7 -> 71 | E21: =C8 -> 64
A22: Digital | B22: =I5 -> 94.295601 | C22: =I6 -> 75.634669 | D22: =I7 -> 73.598331 | E22: =I8 -> 55.21775 | F22: =SUMPRODUCT(B22:E22,$B$20:$E$20)/4 -> 47.077713
A23: Restructuring | B23: =I9 -> 121.10748 | C23: =I10 -> 38.859514 | D23: =I11 -> 73.683802 | E23: =I12 -> 49.390192 | F23: =SUMPRODUCT(B23:E23,$B$20:$E$20)/4 -> 46.065151
A24: Turnaround | B24: =I13 -> 105.3676 | C24: =I14 -> 35.943036 | D24: =I15 -> 78.601703 | E24: =I16 -> 66.33061 | F24: =SUMPRODUCT(B24:E24,$B$20:$E$20)/4 -> 38.395434
A26: Best-to-worst scale (best 100, worst 0) | B26: L | C26: T | D26: E | E26: R | F26: Equal weights | G26: Rank
A27: Digital | B27: =100*(B22*B$20-MIN(B22*B$20,B23*B$20,B24*B$20))/(MAX(B22*B$20,B23*B$20,B24*B$20)-MIN(B22*B$20,B23*B$20,B24*B$20)) -> 0 | C27: =100*(C22*C$20-MIN(C22*C$20,C23*C$20,C24*C$20))/(MAX(C22*C$20,C23*C$20,C24*C$20)-MIN(C22*C$20,C23*C$20,C24*C$20)) -> 100 | D27: =100*(D22*D$20-MIN(D22*D$20,D23*D$20,D24*D$20))/(MAX(D22*D$20,D23*D$20,D24*D$20)-MIN(D22*D$20,D23*D$20,D24*D$20)) -> 0 | E27: =100*(E22*E$20-MIN(E22*E$20,E23*E$20,E24*E$20))/(MAX(E22*E$20,E23*E$20,E24*E$20)-MIN(E22*E$20,E23*E$20,E24*E$20)) -> 65.59968 | F27: =AVERAGE(B27:E27) -> 41.39992 | G27: =RANK(F27,$F$27:$F$29) -> 2
A28: Restructuring | B28: =100*(B23*B$20-MIN(B22*B$20,B23*B$20,B24*B$20))/(MAX(B22*B$20,B23*B$20,B24*B$20)-MIN(B22*B$20,B23*B$20,B24*B$20)) -> 100 | C28: =100*(C23*C$20-MIN(C22*C$20,C23*C$20,C24*C$20))/(MAX(C22*C$20,C23*C$20,C24*C$20)-MIN(C22*C$20,C23*C$20,C24*C$20)) -> 7.3478428 | D28: =100*(D23*D$20-MIN(D22*D$20,D23*D$20,D24*D$20))/(MAX(D22*D$20,D23*D$20,D24*D$20)-MIN(D22*D$20,D23*D$20,D24*D$20)) -> 1.7082749 | E28: =100*(E23*E$20-MIN(E22*E$20,E23*E$20,E24*E$20))/(MAX(E22*E$20,E23*E$20,E24*E$20)-MIN(E22*E$20,E23*E$20,E24*E$20)) -> 100 | F28: =AVERAGE(B28:E28) -> 52.264029 | G28: =RANK(F28,$F$27:$F$29) -> 1
A29: Turnaround | B29: =100*(B24*B$20-MIN(B22*B$20,B23*B$20,B24*B$20))/(MAX(B22*B$20,B23*B$20,B24*B$20)-MIN(B22*B$20,B23*B$20,B24*B$20)) -> 41.295143 | C29: =100*(C24*C$20-MIN(C22*C$20,C23*C$20,C24*C$20))/(MAX(C22*C$20,C23*C$20,C24*C$20)-MIN(C22*C$20,C23*C$20,C24*C$20)) -> 0 | D29: =100*(D24*D$20-MIN(D22*D$20,D23*D$20,D24*D$20))/(MAX(D22*D$20,D23*D$20,D24*D$20)-MIN(D22*D$20,D23*D$20,D24*D$20)) -> 100 | E29: =100*(E24*E$20-MIN(E22*E$20,E23*E$20,E24*E$20))/(MAX(E22*E$20,E23*E$20,E24*E$20)-MIN(E22*E$20,E23*E$20,E24*E$20)) -> 0 | F29: =AVERAGE(B29:E29) -> 35.323786 | G29: =RANK(F29,$F$27:$F$29) -> 3
A31: Percentage improvement on today | B31: L | C31: T | D31: E | E31: R | F31: Equal weights | G31: Rank
A32: Digital | B32: =100*(B22-B$21)/B$21*B$20 -> -5.7043985 | C32: =100*(C22-C$21)/C$21*C$20 -> 84.474803 | D32: =100*(D22-D$21)/D$21*D$20 -> 3.6596211 | E32: =100*(E22-E$21)/E$21*E$20 -> 13.722266 | F32: =AVERAGE(B32:E32) -> 24.038073 | G32: =RANK(F32,$F$32:$F$34) -> 1
A33: Restructuring | B33: =100*(B23-B$21)/B$21*B$20 -> 21.107479 | C33: =100*(C23-C$21)/C$21*C$20 -> -5.2206966 | D33: =100*(D23-D$21)/D$21*D$20 -> 3.7800033 | E33: =100*(E23-E$21)/E$21*E$20 -> 22.827826 | F33: =AVERAGE(B33:E33) -> 10.623653 | G33: =RANK(F33,$F$32:$F$34) -> 2
A34: Turnaround | B34: =100*(B24-B$21)/B$21*B$20 -> 5.3676047 | C34: =100*(C24-C$21)/C$21*C$20 -> -12.33406 | D34: =100*(D24-D$21)/D$21*D$20 -> 10.706625 | E34: =100*(E24-E$21)/E$21*E$20 -> -3.6415774 | F34: =AVERAGE(B34:E34) -> 0.024648044 | G34: =RANK(F34,$F$32:$F$34) -> 3
A36: First on the best-to-worst scale | B36: =INDEX($A$27:$A$29,MATCH(1,$G$27:$G$29,0)) -> Restructuring | C36: restructuring leads digital 52.3 to 41.4
A37: First on percentage improvement | B37: =INDEX($A$32:$A$34,MATCH(1,$G$32:$G$34,0)) -> Digital | C37: digital leads 24.0 to 10.6: the scale decides the ranking
A39: Digital less restructuring, signed: L | B39: =(B22-B23)*B20 -> -26.811878
A40: Digital less restructuring, signed: T | B40: =(C22-C23)*C20 -> 36.775155
A41: Digital less restructuring, signed: E | B41: =(D22-D23)*D20 -> -0.085471354
A42: Digital less restructuring, signed: R | B42: =(E22-E23)*E20 -> -5.827558
A43: Weight points moved from technology to liquidity that tie the two leaders | B43: =100*AVERAGE(B39:B42)/(B40-B39) -> 1.5924031 | C43: Table 16.1, L3: 1.6 weight points

Sheet R1_Inventory
A1: Declaration completeness, gate (R1): the inventory and its two gaps (Worked Example 16.1, Step 1; AXIOM Lab 1.16, steps 1-2)
A3: Reading (Table 5.2) | B3: Measured by | C3: Error
A4: liquidity | B4: treasury systems | C4: +/-1%
A5: net leverage | B5: audited accounts | C5: +/-2%
A6: workforce capability | B6: skills survey | C6: +/-5 points
A7: technology platform | B7: architecture audit | C7: +/-4 points
A8: operational efficiency | B8: cost benchmarking | C8: +/-3 points
A9: ROIC | B9: audited accounts | C9: +/-0.4 pp
A10: strategic risk | B10: risk committee | C10: +/-6 points
A11: market share | B11: industry data | C11: +/-0.8 pp
A13: Arrow from (Chapter 9) | B13: To | C13: Type | D13: Two-way?
A14: MKT | B14: IND | C14: demand | D14: =IF(COUNTIFS($A$14:$A$27,B14,$B$14:$B$27,A14)>0,1,0) -> 0
A15: MKT | B15: DIG | C15: demand | D15: =IF(COUNTIFS($A$14:$A$27,B15,$B$14:$B$27,A15)>0,1,0) -> 0
A16: MKT | B16: MAT | C16: demand | D16: =IF(COUNTIFS($A$14:$A$27,B16,$B$14:$B$27,A16)>0,1,0) -> 0
A17: IND | B17: TRS | C17: cash | D17: =IF(COUNTIFS($A$14:$A$27,B17,$B$14:$B$27,A17)>0,1,0) -> 1
A18: DIG | B18: TRS | C18: cash | D18: =IF(COUNTIFS($A$14:$A$27,B18,$B$14:$B$27,A18)>0,1,0) -> 1
A19: MAT | B19: TRS | C19: cash | D19: =IF(COUNTIFS($A$14:$A$27,B19,$B$14:$B$27,A19)>0,1,0) -> 0
A20: TRS | B20: IND | C20: funding | D20: =IF(COUNTIFS($A$14:$A$27,B20,$B$14:$B$27,A20)>0,1,0) -> 1
A21: TRS | B21: DIG | C21: funding | D21: =IF(COUNTIFS($A$14:$A$27,B21,$B$14:$B$27,A21)>0,1,0) -> 1
A22: ENG | B22: IND | C22: capability | D22: =IF(COUNTIFS($A$14:$A$27,B22,$B$14:$B$27,A22)>0,1,0) -> 1
A23: IND | B23: ENG | C23: capability | D23: =IF(COUNTIFS($A$14:$A$27,B23,$B$14:$B$27,A23)>0,1,0) -> 1
A24: ENG | B24: DIG | C24: capability | D24: =IF(COUNTIFS($A$14:$A$27,B24,$B$14:$B$27,A24)>0,1,0) -> 1
A25: DIG | B25: ENG | C25: capability | D25: =IF(COUNTIFS($A$14:$A$27,B25,$B$14:$B$27,A25)>0,1,0) -> 1
... A27: GOV | B27: DIG | C27: policy | D27: =IF(COUNTIFS($A$14:$A$27,B27,$B$14:$B$27,A27)>0,1,0) -> 0
A29: Standing commitment (Tables 5.4 and 15.2) | B29: Owner
A30: covenant: net leverage at most 4.5x | B30: CFO
A31: liquidity floor: $350 million | B31: board
A32: strategic-risk ceiling: 75 | B32: CRO, board
A33: plant capacity in Industrial Systems | B33: COO
A34: capability at least 55 for the digital build | B34: HR, CTO
A36: Element of the GEOP (Worked Example 15.1) | B36: Declared as
A37: horizon | B37: the program's 12 quarters
A38: decisions | B38: the standby line (CFO); the delay in quarters (transformation office)
A39: policy class | B39: a package committed today (open loop)
A40: environment | B40: Chapter 8's laws: 100,000 paths, seed 8
A41: objective | B41: the levers' cost: fees priced by the CFO, delay by the transformation office
A42: commitments | B42: the appetite (board); the covenant (CFO); the capability floor (HR, CTO)
A45: State readings declared, each with its office and error | B45: =COUNTA(A4:A11) -> 8 | C45: eight
A46: Components | B46: =SUMPRODUCT(1/COUNTIF(A14:B27,A14:B27)) -> 7 | C46: seven
A47: Typed arrows | B47: =COUNTA(A14:A27) -> 14 | C47: fourteen
...

Sheet Quantiles
A1: The decision table from the book's 100,000 paths (seed 8): the least delay and cost of every package (Worked Example 15.1; Worked Example 16.1, Steps 1, 2 and 4)
A2: Engine values (green): for a line l, a path stays above the floor exactly when the draw's depth is at most its critical depth; sorted over the paths, the value at the appetite's quantile is the deepest draw that meets it. Delay = (28 - that depth)/4, cost = Fee x line + Vq x delay: formulas. Blank: no delay can meet it.
A3: Quantile index (paths allowed to breach) | B3: 3003 | E3: The first appetite is the odds of Chapter 8's package on the book's paths (engine). | H3: 5000 | K3: 5500
A4: Appetite | B4: 0.03003 | E4: 0.045 | H4: 0.05 | K4: 0.055
A5: Line ($ million) | B5: Critical depth | C5: Delay | D5: Cost | E5: Critical depth | F5: Delay | G5: Cost | H5: Critical depth | I5: Delay | J5: Cost | K5: Critical depth | L5: Delay | M5: Cost
A6: 0 | B6: 1.5474426 | C6: =IF(B6<0,"",(Depth0-MIN(Depth0,B6))/Depth_per_q) -> 6.6131394 | D6: =IF(C6="","",Fee*$A6+Vq*C6) -> 52.905115 | E6: 6.3852114 | F6: =IF(E6<0,"",(Depth0-MIN(Depth0,E6))/Depth_per_q) -> 5.4036971 | G6: =IF(F6="","",Fee*$A6+Vq*F6) -> 43.229577 | H6: 7.6213073 | I6: =IF(H6<0,"",(Depth0-MIN(Depth0,H6))/Depth_per_q) -> 5.0946732 | J6: =IF(I6="","",Fee*$A6+Vq*I6) -> 40.757385 | K6: 8.8090794 | L6: =IF(K6<0,"",(Depth0-MIN(Depth0,K6))/Depth_per_q) -> 4.7977301 | M6: =IF(L6="","",Fee*$A6+Vq*L6) -> 38.381841
A7: 5 | B7: 2.6936105 | C7: =IF(B7<0,"",(Depth0-MIN(Depth0,B7))/Depth_per_q) -> 6.3265974 | D7: =IF(C7="","",Fee*$A7+Vq*C7) -> 50.762779 | E7: 7.426928 | F7: =IF(E7<0,"",(Depth0-MIN(Depth0,E7))/Depth_per_q) -> 5.143268 | G7: =IF(F7="","",Fee*$A7+Vq*F7) -> 41.296144 | H7: 8.677322 | I7: =IF(H7<0,"",(Depth0-MIN(Depth0,H7))/Depth_per_q) -> 4.8306695 | J7: =IF(I7="","",Fee*$A7+Vq*I7) -> 38.795356 | K7: 9.8233242 | L7: =IF(K7<0,"",(Depth0-MIN(Depth0,K7))/Depth_per_q) -> 4.5441689 | M7: =IF(L7="","",Fee*$A7+Vq*L7) -> 36.503352
A8: 10 | B8: 3.8281618 | C8: =IF(B8<0,"",(Depth0-MIN(Depth0,B8))/Depth_per_q) -> 6.0429595 | D8: =IF(C8="","",Fee*$A8+Vq*C8) -> 48.643676 | E8: 8.4910737 | F8: =IF(E8<0,"",(Depth0-MIN(Depth0,E8))/Depth_per_q) -> 4.8772316 | G8: =IF(F8="","",Fee*$A8+Vq*F8) -> 39.317853 | H8: 9.6807638 | I8: =IF(H8<0,"",(Depth0-MIN(Depth0,H8))/Depth_per_q) -> 4.579809 | J8: =IF(I8="","",Fee*$A8+Vq*I8) -> 36.938472 | K8: 10.813042 | L8: =IF(K8<0,"",(Depth0-MIN(Depth0,K8))/Depth_per_q) -> 4.2967395 | M8: =IF(L8="","",Fee*$A8+Vq*L8) -> 34.673916
A9: 15 | B9: 5.0043178 | C9: =IF(B9<0,"",(Depth0-MIN(Depth0,B9))/Depth_per_q) -> 5.7489205 | D9: =IF(C9="","",Fee*$A9+Vq*C9) -> 46.441364 | E9: 9.5089735 | F9: =IF(E9<0,"",(Depth0-MIN(Depth0,E9))/Depth_per_q) -> 4.6227566 | G9: =IF(F9="","",Fee*$A9+Vq*F9) -> 37.432053 | H9: 10.685397 | I9: =IF(H9<0,"",(Depth0-MIN(Depth0,H9))/Depth_per_q) -> 4.3286508 | J9: =IF(I9="","",Fee*$A9+Vq*I9) -> 35.079207 | K9: 11.76437 | L9: =IF(K9<0,"",(Depth0-MIN(Depth0,K9))/Depth_per_q) -> 4.0589074 | M9: =IF(L9="","",Fee*$A9+Vq*L9) -> 32.92126
A10: 20 | B10: 6.1116362 | C10: =IF(B10<0,"",(Depth0-MIN(Depth0,B10))/Depth_per_q) -> 5.472091 | D10: =IF(C10="","",Fee*$A10+Vq*C10) -> 44.376728 | E10: 10.541698 | F10: =IF(E10<0,"",(Depth0-MIN(Depth0,E10))/Depth_per_q) -> 4.3645754 | G10: =IF(F10="","",Fee*$A10+Vq*F10) -> 35.516603 | H10: 11.725286 | I10: =IF(H10<0,"",(Depth0-MIN(Depth0,H10))/Depth_per_q) -> 4.0686784 | J10: =IF(I10="","",Fee*$A10+Vq*I10) -> 33.149427 | K10: 12.752734 | L10: =IF(K10<0,"",(Depth0-MIN(Depth0,K10))/Depth_per_q) -> 3.8118166 | M10: =IF(L10="","",Fee*$A10+Vq*L10) -> 31.094533
A11: 25 | B11: 7.2806758 | C11: =IF(B11<0,"",(Depth0-MIN(Depth0,B11))/Depth_per_q) -> 5.179831 | D11: =IF(C11="","",Fee*$A11+Vq*C11) -> 42.188648 | E11: 11.546097 | F11: =IF(E11<0,"",(Depth0-MIN(Depth0,E11))/Depth_per_q) -> 4.1134758 | G11: =IF(F11="","",Fee*$A11+Vq*F11) -> 33.657807 | H11: 12.73204 | I11: =IF(H11<0,"",(Depth0-MIN(Depth0,H11))/Depth_per_q) -> 3.8169899 | J11: =IF(I11="","",Fee*$A11+Vq*I11) -> 31.28592 | K11: 13.714837 | L11: =IF(K11<0,"",(Depth0-MIN(Depth0,K11))/Depth_per_q) -> 3.5712909 | M11: =IF(L11="","",Fee*$A11+Vq*L11) -> 29.320327
A12: 30 | B12: 8.3768794 | C12: =IF(B12<0,"",(Depth0-MIN(Depth0,B12))/Depth_per_q) -> 4.9057801 | D12: =IF(C12="","",Fee*$A12+Vq*C12) -> 40.146241 | E12: 12.538499 | F12: =IF(E12<0,"",(Depth0-MIN(Depth0,E12))/Depth_per_q) -> 3.8653752 | G12: =IF(F12="","",Fee*$A12+Vq*F12) -> 31.823002 | H12: 13.684965 | I12: =IF(H12<0,"",(Depth0-MIN(Depth0,H12))/Depth_per_q) -> 3.5787587 | J12: =IF(I12="","",Fee*$A12+Vq*I12) -> 29.530069 | K12: 14.682351 | L12: =IF(K12<0,"",(Depth0-MIN(Depth0,K12))/Depth_per_q) -> 3.3294124 | M12: =IF(L12="","",Fee*$A12+Vq*L12) -> 27.535299
A13: 35 | B13: 9.5542854 | C13: =IF(B13<0,"",(Depth0-MIN(Depth0,B13))/Depth_per_q) -> 4.6114286 | D13: =IF(C13="","",Fee*$A13+Vq*C13) -> 37.941429 | E13: 13.534125 | F13: =IF(E13<0,"",(Depth0-MIN(Depth0,E13))/Depth_per_q) -> 3.6164689 | G13: =IF(F13="","",Fee*$A13+Vq*F13) -> 29.981751 | H13: 14.61185 | I13: =IF(H13<0,"",(Depth0-MIN(Depth0,H13))/Depth_per_q) -> 3.3470376 | J13: =IF(I13="","",Fee*$A13+Vq*I13) -> 27.826301 | K13: 15.598537 | L13: =IF(K13<0,"",(Depth0-MIN(Depth0,K13))/Depth_per_q) -> 3.1003658 | M13: =IF(L13="","",Fee*$A13+Vq*L13) -> 25.852927
A14: 40 | B14: 10.620755 | C14: =IF(B14<0,"",(Depth0-MIN(Depth0,B14))/Depth_per_q) -> 4.3448112 | D14: =IF(C14="","",Fee*$A14+Vq*C14) -> 35.958489 | E14: 14.459524 | F14: =IF(E14<0,"",(Depth0-MIN(Depth0,E14))/Depth_per_q) -> 3.385119 | G14: =IF(F14="","",Fee*$A14+Vq*F14) -> 28.280952 | H14: 15.573581 | I14: =IF(H14<0,"",(Depth0-MIN(Depth0,H14))/Depth_per_q) -> 3.1066048 | J14: =IF(I14="","",Fee*$A14+Vq*I14) -> 26.052838 | K14: 16.429356 | L14: =IF(K14<0,"",(Depth0-MIN(Depth0,K14))/Depth_per_q) -> 2.8926609 | M14: =IF(L14="","",Fee*$A14+Vq*L14) -> 24.341287
A15: 45 | B15: 11.625358 | C15: =IF(B15<0,"",(Depth0-MIN(Depth0,B15))/Depth_per_q) -> 4.0936604 | D15: =IF(C15="","",Fee*$A15+Vq*C15) -> 34.099283 | E15: 15.335646 | F15: =IF(E15<0,"",(Depth0-MIN(Depth0,E15))/Depth_per_q) -> 3.1660885 | G15: =IF(F15="","",Fee*$A15+Vq*F15) -> 26.678708 | H15: 16.389965 | I15: =IF(H15<0,"",(Depth0-MIN(Depth0,H15))/Depth_per_q) -> 2.9025087 | J15: =IF(I15="","",Fee*$A15+Vq*I15) -> 24.57007 | K15: 17.253341 | L15: =IF(K15<0,"",(Depth0-MIN(Depth0,K15))/Depth_per_q) -> 2.6866647 | M15: =IF(L15="","",Fee*$A15+Vq*L15) -> 22.843318
A16: 50 | B16: 12.665393 | C16: =IF(B16<0,"",(Depth0-MIN(Depth0,B16))/Depth_per_q) -> 3.8336516 | D16: =IF(C16="","",Fee*$A16+Vq*C16) -> 32.169213 | E16: 16.222545 | F16: =IF(E16<0,"",(Depth0-MIN(Depth0,E16))/Depth_per_q) -> 2.9443637 | G16: =IF(F16="","",Fee*$A16+Vq*F16) -> 25.05491 | H16: 17.196095 | I16: =IF(H16<0,"",(Depth0-MIN(Depth0,H16))/Depth_per_q) -> 2.7009762 | J16: =IF(I16="","",Fee*$A16+Vq*I16) -> 23.107809 | K16: 18.001074 | L16: =IF(K16<0,"",(Depth0-MIN(Depth0,K16))/Depth_per_q) -> 2.4997315 | M16: =IF(L16="","",Fee*$A16+Vq*L16) -> 21.497852
A17: 55 | B17: 13.649299 | C17: =IF(B17<0,"",(Depth0-MIN(Depth0,B17))/Depth_per_q) -> 3.5876753 | D17: =IF(C17="","",Fee*$A17+Vq*C17) -> 30.351402 | E17: 17.056024 | F17: =IF(E17<0,"",(Depth0-MIN(Depth0,E17))/Depth_per_q) -> 2.7359939 | G17: =IF(F17="","",Fee*$A17+Vq*F17) -> 23.537951 | H17: 17.951515 | I17: =IF(H17<0,"",(Depth0-MIN(Depth0,H17))/Depth_per_q) -> 2.5121212 | J17: =IF(I17="","",Fee*$A17+Vq*I17) -> 21.74697 | K17: 18.705128 | L17: =IF(K17<0,"",(Depth0-MIN(Depth0,K17))/Depth_per_q) -> 2.323718 | M17: =IF(L17="","",Fee*$A17+Vq*L17) -> 20.239744
... A86: 400 | B86: 23.732449 | C86: =IF(B86<0,"",(Depth0-MIN(Depth0,B86))/Depth_per_q) -> 1.0668877 | D86: =IF(C86="","",Fee*$A86+Vq*C86) -> 20.535101 | E86: 25.351449 | F86: =IF(E86<0,"",(Depth0-MIN(Depth0,E86))/Depth_per_q) -> 0.66213765 | G86: =IF(F86="","",Fee*$A86+Vq*F86) -> 17.297101 | H86: 25.781569 | I86: =IF(H86<0,"",(Depth0-MIN(Depth0,H86))/Depth_per_q) -> 0.55460771 | J86: =IF(I86="","",Fee*$A86+Vq*I86) -> 16.436862 | K86: 26.163908 | L86: =IF(K86<0,"",(Depth0-MIN(Depth0,K86))/Depth_per_q) -> 0.459023 | M86: =IF(L86="","",Fee*$A86+Vq*L86) -> 15.672184
A88: Least cost at each appetite
A89: Least cost | D89: =MIN(D6:D86) -> 14.668098 | G89: =MIN(G6:G86) -> 11.388504 | J89: =MIN(J6:J86) -> 10.440611 | M89: =MIN(M6:M86) -> 9.5814895
A90: Its line | D90: =INDEX($A$6:$A$86,MATCH(D89,D6:D86,0)) -> 180 | G90: =INDEX($A$6:$A$86,MATCH(G89,G6:G86,0)) -> 165 | J90: =INDEX($A$6:$A$86,MATCH(J89,J6:J86,0)) -> 170 | M90: =INDEX($A$6:$A$86,MATCH(M89,M6:M86,0)) -> 165
A91: Its delay (quarters) | D91: =INDEX(C6:C86,MATCH(D89,D6:D86,0)) -> 1.1585123 | G91: =INDEX(F6:F86,MATCH(G89,G6:G86,0)) -> 0.80481304 | J91: =INDEX(I6:I86,MATCH(J89,J6:J86,0)) -> 0.66757636 | M91: =INDEX(L6:L86,MATCH(M89,M6:M86,0)) -> 0.57893619
A93: The 5% package: line | B93: =J90 -> 170 | C93: Worked Example 15.1: about $170 million
A94: The 5% package: delay (quarters) | B94: =J91 -> 0.66757636 | C94: 0.668: two months
A95: The 5% package: least cost | B95: =J89 -> 10.440611 | C95: Table 16.1, L5: $10.4 million
A96: Chapter 8's package at the declared prices | B96: =Fee*Line8+Vq*Delay8 -> 19 | C96: Step 1: $19.0 million
A97: The cheapest package at the same odds | B97: =D89 -> 14.668098 | C97: Step 1: $14.7 million (Online Appendix 16.B.3: 14.67)
A98: Choosing on safety alone cost | B98: =B96-B97 -> 4.3319019 | C98: Online Appendix 16.B.3: 4.33
A99: Least cost at 4.5% | B99: =G89 -> 11.388504
A100: Least cost at 5.5% | B100: =M89 -> 9.5814895
A101: The appetite's multiplier ($ million a point) | B101: =B99-B100 -> 1.8070148 | C101: Table 16.4: $1.8 million a point
A102: Implied cost of a breach, 100 x the multiplier | B102: =100*B101 -> 180.70148 | C102: Table 16.1, L5: about $180 million

Sheet R2_Consistency
A1: Unified consistency, gate (R2): the joint check, its minimal set and the repair (Worked Example 16.1, Step 2; Table 16.1, L1 and L2)
A2: Liquidity = $6.2 million x (Chapter 1's index less the draw D x s(t)), s(t) = (t/2) e^(1 - t/2). The average path is the plan less the closures' expected drain.
A4: Quarter | B4: Years t | C4: Index without the draw | D4: Draw shape s(t) | E4: Plan as drawn (D = 28) | F4: With the package's delay | G4: Expected closures so far | H4: The average path
A5: 0 | B5: =A5/4 -> 0 | C5: =Liq_target+(100-Liq_target)*EXP(-Relax*B5) -> 100 | D5: =(B5/Tau)*EXP(1-B5/Tau) -> 0 | E5: =Usd_pt*(C5-Depth0*D5) -> 620 | F5: =Usd_pt*(C5-$B$31*D5) -> 620 | G5: =Lam/4*A5*J_mean -> 0 | H5: =E5-G5 -> 620
A6: 1 | B6: =A6/4 -> 0.25 | C6: =Liq_target+(100-Liq_target)*EXP(-Relax*B6) -> 101.00537 | D6: =(B6/Tau)*EXP(1-B6/Tau) -> 0.29985941 | E6: =Usd_pt*(C6-Depth0*D6) -> 574.17772 | F6: =Usd_pt*(C6-$B$31*D6) -> 579.14216 | G6: =Lam/4*A6*J_mean -> 3 | H6: =E6-G6 -> 571.17772
A7: 2 | B7: =A7/4 -> 0.5 | C7: =Liq_target+(100-Liq_target)*EXP(-Relax*B7) -> 101.92652 | D7: =(B7/Tau)*EXP(1-B7/Tau) -> 0.52925 | E7: =Usd_pt*(C7-Depth0*D7) -> 540.0666 | F7: =Usd_pt*(C7-$B$31*D7) -> 548.8288 | G7: =Lam/4*A7*J_mean -> 6 | H7: =E7-G7 -> 534.0666
A8: 3 | B8: =A8/4 -> 0.75 | C8: =Liq_target+(100-Liq_target)*EXP(-Relax*B8) -> 102.77048 | D8: =(B8/Tau)*EXP(1-B8/Tau) -> 0.70059223 | E8: =Usd_pt*(C8-Depth0*D8) -> 515.55419 | F8: =Usd_pt*(C8-$B$31*D8) -> 527.15312 | G8: =Lam/4*A8*J_mean -> 9 | H8: =E8-G8 -> 506.55419
A9: 4 | B9: =A9/4 -> 1 | C9: =Liq_target+(100-Liq_target)*EXP(-Relax*B9) -> 103.54374 | D9: =(B9/Tau)*EXP(1-B9/Tau) -> 0.82436064 | E9: =Usd_pt*(C9-Depth0*D9) -> 498.8622 | F9: =Usd_pt*(C9-$B$31*D9) -> 512.51023 | G9: =Lam/4*A9*J_mean -> 12 | H9: =E9-G9 -> 486.8622
A10: 5 | B10: =A10/4 -> 1.25 | C10: =Liq_target+(100-Liq_target)*EXP(-Relax*B10) -> 104.25222 | D10: =(B10/Tau)*EXP(1-B10/Tau) -> 0.90936963 | E10: =Usd_pt*(C10-Depth0*D10) -> 488.49718 | F10: =Usd_pt*(C10-$B$31*D10) -> 503.55261 | G10: =Lam/4*A10*J_mean -> 15 | H10: =E10-G10 -> 473.49718
A11: 6 | B11: =A11/4 -> 1.5 | C11: =Liq_target+(100-Liq_target)*EXP(-Relax*B11) -> 104.90134 | D11: =(B11/Tau)*EXP(1-B11/Tau) -> 0.96301906 | E11: =Usd_pt*(C11-Depth0*D11) -> 483.20817 | F11: =Usd_pt*(C11-$B$31*D11) -> 499.15181 | G11: =Lam/4*A11*J_mean -> 18 | H11: =E11-G11 -> 465.20817
A12: 7 | B12: =A12/4 -> 1.75 | C12: =Liq_target+(100-Liq_target)*EXP(-Relax*B12) -> 105.49607 | D12: =(B12/Tau)*EXP(1-B12/Tau) -> 0.9915049 | E12: =Usd_pt*(C12-Depth0*D12) -> 481.95038 | F12: =Usd_pt*(C12-$B$31*D12) -> 498.36563 | G12: =Lam/4*A12*J_mean -> 21 | H12: =E12-G12 -> 460.95038
A13: 8 | B13: =A13/4 -> 2 | C13: =Liq_target+(100-Liq_target)*EXP(-Relax*B13) -> 106.04098 | D13: =(B13/Tau)*EXP(1-B13/Tau) -> 1 | E13: =Usd_pt*(C13-Depth0*D13) -> 483.85405 | F13: =Usd_pt*(C13-$B$31*D13) -> 500.40995 | G13: =Lam/4*A13*J_mean -> 24 | H13: =E13-G13 -> 459.85405
A14: 9 | B14: =A14/4 -> 2.25 | C14: =Liq_target+(100-Liq_target)*EXP(-Relax*B14) -> 106.54023 | D14: =(B14/Tau)*EXP(1-B14/Tau) -> 0.99280902 | E14: =Usd_pt*(C14-Depth0*D14) -> 488.19778 | F14: =Usd_pt*(C14-$B$31*D14) -> 504.63462 | G14: =Lam/4*A14*J_mean -> 27 | H14: =E14-G14 -> 461.19778
A15: 10 | B15: =A15/4 -> 2.5 | C15: =Liq_target+(100-Liq_target)*EXP(-Relax*B15) -> 106.99766 | D15: =(B15/Tau)*EXP(1-B15/Tau) -> 0.97350098 | E15: =Usd_pt*(C15-Depth0*D15) -> 494.3857 | F15: =Usd_pt*(C15-$B$31*D15) -> 510.50287 | G15: =Lam/4*A15*J_mean -> 30 | H15: =E15-G15 -> 464.3857
A16: 11 | B16: =A16/4 -> 2.75 | C16: =Liq_target+(100-Liq_target)*EXP(-Relax*B16) -> 107.41676 | D16: =(B16/Tau)*EXP(1-B16/Tau) -> 0.94502276 | E16: =Usd_pt*(C16-Depth0*D16) -> 501.92795 | F16: =Usd_pt*(C16-$B$31*D16) -> 517.57364 | G16: =Lam/4*A16*J_mean -> 33 | H16: =E16-G16 -> 468.92795
A17: 12 | B17: =A17/4 -> 3 | C17: =Liq_target+(100-Liq_target)*EXP(-Relax*B17) -> 107.80075 | D17: =(B17/Tau)*EXP(1-B17/Tau) -> 0.90979599 | E17: =Usd_pt*(C17-Depth0*D17) -> 510.42405 | F17: =Usd_pt*(C17-$B$31*D17) -> 525.48653 | G17: =Lam/4*A17*J_mean -> 36 | H17: =E17-G17 -> 474.42405
A19: The program's deepest draw (transformation office) | B19: =Liq0-MIN(E5:E17) -> 138.04962 | C19: Table 16.1, L1: $138 million
A20: Buffer for a 90th-percentile closure (treasury) | B20: =GAMMAINV(0.9,G_shape,G_scale) -> 186.86698 | C20: Table 16.1, L1: $187 million
A21: Each alone fits in the cash above the floor? | B21: =IF(AND(B19<=Pool,B20<=Pool),"yes: both sign-offs pass","no") -> yes: both sign-offs pass | C21: the bilateral checks
A22: Together: draw + buffer | B22: =B19+B20 -> 324.91659 | C22: Step 2: $325 million on $270 million
A23: Short by | B23: =B22-Pool -> 54.916594 | C23: Online Appendix 16.B.3: 54.9
A24: The average path's lowest point | B24: =MIN(H5:H17) -> 459.85405 | C24: Table 16.1, L2: $460 million, above the floor
A26: Without the draw: liquidity left after the buffer, against the floor | B26: =Liq0-B20 -> 433.13302
A27: Without the buffer: liquidity left after the draw, against the floor | B27: =Liq0-B19 -> 481.95038
A28: Without the floor: liquidity left after both claims, against zero | B28: =Liq0-B19-B20 -> 295.08341
A29: The minimal set {draw, buffer, floor}: every pair holds, all three fail? | B29: =IF(AND(B26>=Floor_m,B27>=Floor_m,B28>=0,B28<Floor_m),"yes: a minimal set","no") -> yes: a minimal set | C29: owners: transformation office, treasury, board
A31: Depth with the package's delay, 28 - 4 x delay | B31: =Depth0-Depth_per_q*Quantiles!B94 -> 25.329695 | C31: 25.33
A32: Deepest draw with the delay | B32: =Liq0-MIN(F5:F17) -> 121.63437 | C32: Step 2: $122 million
A33: Buffer the line leaves | B33: =MAX(B20-Quantiles!B93,0) -> 16.866976 | C33: Step 2: all but $17 million
A34: Draw + buffer now | B34: =B32+B33 -> 138.50134 | C34: Step 2: $139 million
A35: Unclaimed | B35: =Pool-B34 -> 131.49866 | C35: Step 2: $131 million
A36: The consistency certificate issues? | B36: =IF(B34<=Pool,"yes","no") -> yes | C36: (R2) passes

Sheet R3_Panel
A1: The analytical panel, gate (R3): the register, its certificate, the phase-two link and its repairs (Worked Example 16.1, Step 3; Theorem 16.5(ii); Section 16.5)
A2: Symmetric core: engineering links e, treasury links t, the phase-two Digital-Industrial Systems link h; every link two-way. Spectral radius (h + sqrt(h^2 + 8(e^2 + t^2)))/2 (Chapter 14).
A4: Engineering links e | B4: =Ceil_gain -> 0.4 | C4: 0.40
A5: Treasury links t | B5: =Ceil_gain -> 0.4 | C5: 0.40
A6: Phase-two link h (not in the register) | B6: 0 | C6: its ceiling is zero
A7: Spectral radius of the register | B7: =((B6)+SQRT((B6)^2+8*((B4)^2+(B5)^2)))/2 -> 0.8 | C7: Step 3: 0.80
A8: The board's rule | B8: =Rule_rho -> 0.84089642 | C8: 0.841
A9: Half-life (quarters) | B9: =LN(2)/LN(1/B7) -> 3.1062837 | C9: 3.1 quarters, inside the four-quarter rule
A10: Multiplier 1/(1 - spectral radius) | B10: =1/(1-B7) -> 5 | C10: 5
A11: The register passes the board's rule? | B11: =IF(B7<=B8,"yes","no") -> yes | C11: (R3) passes
A13: Passes on (column) to (row) | B13: IND | C13: DIG | D13: ENG | E13: TRS | H13: Quarter | I13: IND | J13: DIG | K13: ENG | L13: TRS | M13: Total echo
A14: IND | B14: 0 | C14: =$B$6 -> 0 | D14: =$B$4 -> 0.4 | E14: =$B$5 -> 0.4 | H14: 0 | I14: 0 | J14: 10 | K14: 0 | L14: 0 | M14: =SUM(I14:L14) -> 10
A15: DIG | B15: =$B$6 -> 0 | C15: 0 | D15: =$B$4 -> 0.4 | E15: =$B$5 -> 0.4 | H15: 1 | I15: =SUMPRODUCT($B$14:$E$14,I14:L14) -> 0 | J15: =SUMPRODUCT($B$15:$E$15,I14:L14) -> 0 | K15: =SUMPRODUCT($B$16:$E$16,I14:L14) -> 4 | L15: =SUMPRODUCT($B$17:$E$17,I14:L14) -> 4 | M15: =SUM(I15:L15) -> 8
A16: ENG | B16: =$B$4 -> 0.4 | C16: =$B$4 -> 0.4 | D16: 0 | E16: 0 | H16: 2 | I16: =SUMPRODUCT($B$14:$E$14,I15:L15) -> 3.2 | J16: =SUMPRODUCT($B$15:$E$15,I15:L15) -> 3.2 | K16: =SUMPRODUCT($B$16:$E$16,I15:L15) -> 0 | L16: =SUMPRODUCT($B$17:$E$17,I15:L15) -> 0 | M16: =SUM(I16:L16) -> 6.4
A17: TRS | B17: =$B$5 -> 0.4 | C17: =$B$5 -> 0.4 | D17: 0 | E17: 0 | H17: 3 | I17: =SUMPRODUCT($B$14:$E$14,I16:L16) -> 0 | J17: =SUMPRODUCT($B$15:$E$15,I16:L16) -> 0 | K17: =SUMPRODUCT($B$16:$E$16,I16:L16) -> 2.56 | L17: =SUMPRODUCT($B$17:$E$17,I16:L16) -> 2.56 | M17: =SUM(I17:L17) -> 5.12
H18: 4 | I18: =SUMPRODUCT($B$14:$E$14,I17:L17) -> 2.048 | J18: =SUMPRODUCT($B$15:$E$15,I17:L17) -> 2.048 | K18: =SUMPRODUCT($B$16:$E$16,I17:L17) -> 0 | L18: =SUMPRODUCT($B$17:$E$17,I17:L17) -> 0 | M18: =SUM(I18:L18) -> 4.096
A19: Echo of a $10 million shock at Digital: next quarter | B19: =M15 -> 8 | C19: $8 million | H19: 5 | I19: =SUMPRODUCT($B$14:$E$14,I18:L18) -> 0 | J19: =SUMPRODUCT($B$15:$E$15,I18:L18) -> 0 | K19: =SUMPRODUCT($B$16:$E$16,I18:L18) -> 1.6384 | L19: =SUMPRODUCT($B$17:$E$17,I18:L18) -> 1.6384 | M19: =SUM(I19:L19) -> 3.2768
A20: The quarter after | B20: =M16 -> 6.4 | C20: $6.4 million | H20: 6 | I20: =SUMPRODUCT($B$14:$E$14,I19:L19) -> 1.31072 | J20: =SUMPRODUCT($B$15:$E$15,I19:L19) -> 1.31072 | K20: =SUMPRODUCT($B$16:$E$16,I19:L19) -> 0 | L20: =SUMPRODUCT($B$17:$E$17,I19:L19) -> 0 | M20: =SUM(I20:L20) -> 2.62144
A21: The quarter after that | B21: =M17 -> 5.12 | C21: Online Appendix 16.B.2: 5.12 | H21: 7 | I21: =SUMPRODUCT($B$14:$E$14,I20:L20) -> 0 | J21: =SUMPRODUCT($B$15:$E$15,I20:L20) -> 0 | K21: =SUMPRODUCT($B$16:$E$16,I20:L20) -> 1.048576 | L21: =SUMPRODUCT($B$17:$E$17,I20:L20) -> 1.048576 | M21: =SUM(I21:L21) -> 2.097152
A22: In all, shock included (81 quarters) | B22: =SUM(M14:M94) -> 49.999999 | C22: $50 million | H22: 8 | I22: =SUMPRODUCT($B$14:$E$14,I21:L21) -> 0.8388608 | J22: =SUMPRODUCT($B$15:$E$15,I21:L21) -> 0.8388608 | K22: =SUMPRODUCT($B$16:$E$16,I21:L21) -> 0 | L22: =SUMPRODUCT($B$17:$E$17,I21:L21) -> 0 | M22: =SUM(I22:L22) -> 1.6777216
H23: 9 | I23: =SUMPRODUCT($B$14:$E$14,I22:L22) -> 0 | J23: =SUMPRODUCT($B$15:$E$15,I22:L22) -> 0 | K23: =SUMPRODUCT($B$16:$E$16,I22:L22) -> 0.67108864 | L23: =SUMPRODUCT($B$17:$E$17,I22:L22) -> 0.67108864 | M23: =SUM(I23:L23) -> 1.3421773
H24: 10 | I24: =SUMPRODUCT($B$14:$E$14,I23:L23) -> 0.53687091 | J24: =SUMPRODUCT($B$15:$E$15,I23:L23) -> 0.53687091 | K24: =SUMPRODUCT($B$16:$E$16,I23:L23) -> 0 | L24: =SUMPRODUCT($B$17:$E$17,I23:L23) -> 0 | M24: =SUM(I24:L24) -> 1.0737418
A25: Phase two: the new link declared at the ceiling | B25: =Ceil_gain -> 0.4 | H25: 11 | I25: =SUMPRODUCT($B$14:$E$14,I24:L24) -> 0 | J25: =SUMPRODUCT($B$15:$E$15,I24:L24) -> 0 | K25: =SUMPRODUCT($B$16:$E$16,I24:L24) -> 0.42949673 | L25: =SUMPRODUCT($B$17:$E$17,I24:L24) -> 0.42949673 | M25: =SUM(I25:L25) -> 0.85899346
A26: Spectral radius with the new link | B26: =((B25)+SQRT((B25)^2+8*((B4)^2+(B5)^2)))/2 -> 1.0246211 | C26: Step 3: 1.02 (Online Appendix 16.B.3: 1.025) | H26: 12 | I26: =SUMPRODUCT($B$14:$E$14,I25:L25) -> 0.34359738 | J26: =SUMPRODUCT($B$15:$E$15,I25:L25) -> 0.34359738 | K26: =SUMPRODUCT($B$16:$E$16,I25:L25) -> 0 | L26: =SUMPRODUCT($B$17:$E$17,I25:L25) -> 0 | M26: =SUM(I26:L26) -> 0.68719477
A27: Fails the board's rule and stability? | B27: =IF(AND(B26>Rule_rho,B26>=1),"yes: no certificate holds","no") -> yes: no certificate holds | H27: 13 | I27: =SUMPRODUCT($B$14:$E$14,I26:L26) -> 0 | J27: =SUMPRODUCT($B$15:$E$15,I26:L26) -> 0 | K27: =SUMPRODUCT($B$16:$E$16,I26:L26) -> 0.27487791 | L27: =SUMPRODUCT($B$17:$E$17,I26:L26) -> 0.27487791 | M27: =SUM(I27:L27) -> 0.54975581
H28: 14 | I28: =SUMPRODUCT($B$14:$E$14,I27:L27) -> 0.21990233 | J28: =SUMPRODUCT($B$15:$E$15,I27:L27) -> 0.21990233 | K28: =SUMPRODUCT($B$16:$E$16,I27:L27) -> 0 | L28: =SUMPRODUCT($B$17:$E$17,I27:L27) -> 0 | M28: =SUM(I28:L28) -> 0.43980465
A29: Repair: the new link at most | B29: =(Rule_rho^2-2*(B4^2+B5^2))/Rule_rho -> 0.079803862 | C29: Step 3: 0.08 | H29: 15 | I29: =SUMPRODUCT($B$14:$E$14,I28:L28) -> 0 | J29: =SUMPRODUCT($B$15:$E$15,I28:L28) -> 0 | K29: =SUMPRODUCT($B$16:$E$16,I28:L28) -> 0.17592186 | L29: =SUMPRODUCT($B$17:$E$17,I28:L28) -> 0.17592186 | M29: =SUM(I29:L29) -> 0.35184372
A30: its spectral radius | B30: =((B29)+SQRT((B29)^2+8*((B4)^2+(B5)^2)))/2 -> 0.84089642 | C30: equals the board's rule | H30: 16 | I30: =SUMPRODUCT($B$14:$E$14,I29:L29) -> 0.14073749 | J30: =SUMPRODUCT($B$15:$E$15,I29:L29) -> 0.14073749 | K30: =SUMPRODUCT($B$16:$E$16,I29:L29) -> 0 | L30: =SUMPRODUCT($B$17:$E$17,I29:L29) -> 0 | M30: =SUM(I30:L30) -> 0.28147498
A31: Repair: ring-fence the treasury links at | B31: =SQRT((Rule_rho^2-B25*Rule_rho)/2-B4^2) -> 0.15929252 | C31: Step 3: 0.16 | H31: 17 | I31: =SUMPRODUCT($B$14:$E$14,I30:L30) -> 0 | J31: =SUMPRODUCT($B$15:$E$15,I30:L30) -> 0 | K31: =SUMPRODUCT($B$16:$E$16,I30:L30) -> 0.11258999 | L31: =SUMPRODUCT($B$17:$E$17,I30:L30) -> 0.11258999 | M31: =SUM(I31:L31) -> 0.22517998
A32: its spectral radius | B32: =((B25)+SQRT((B25)^2+8*((B4)^2+(B31)^2)))/2 -> 0.84089642 | C32: equals the board's rule | H32: 18 | I32: =SUMPRODUCT($B$14:$E$14,I31:L31) -> 0.090071993 | J32: =SUMPRODUCT($B$15:$E$15,I31:L31) -> 0.090071993 | K32: =SUMPRODUCT($B$16:$E$16,I31:L31) -> 0 | L32: =SUMPRODUCT($B$17:$E$17,I31:L31) -> 0 | M32: =SUM(I32:L32) -> 0.18014399
A33: Repair: trim all four existing links to | B33: =SQRT((Rule_rho^2-B25*Rule_rho)/4) -> 0.30444549 | C33: Step 3: 0.30 | H33: 19 | I33: =SUMPRODUCT($B$14:$E$14,I32:L32) -> 0 | J33: =SUMPRODUCT($B$15:$E$15,I32:L32) -> 0 | K33: =SUMPRODUCT($B$16:$E$16,I32:L32) -> 0.072057594 | L33: =SUMPRODUCT($B$17:$E$17,I32:L32) -> 0.072057594 | M33: =SUM(I33:L33) -> 0.14411519
A34: its spectral radius | B34: =((B25)+SQRT((B25)^2+8*((B33)^2+(B33)^2)))/2 -> 0.84089642 | C34: equals the board's rule | H34: 20 | I34: =SUMPRODUCT($B$14:$E$14,I33:L33) -> 0.057646075 | J34: =SUMPRODUCT($B$15:$E$15,I33:L33) -> 0.057646075 | K34: =SUMPRODUCT($B$16:$E$16,I33:L33) -> 0 | L34: =SUMPRODUCT($B$17:$E$17,I33:L33) -> 0 | M34: =SUM(I34:L34) -> 0.11529215
H35: 21 | I35: =SUMPRODUCT($B$14:$E$14,I34:L34) -> 0 | J35: =SUMPRODUCT($B$15:$E$15,I34:L34) -> 0 | K35: =SUMPRODUCT($B$16:$E$16,I34:L34) -> 0.04611686 | L35: =SUMPRODUCT($B$17:$E$17,I34:L34) -> 0.04611686 | M35: =SUM(I35:L35) -> 0.09223372
A36: Phase two at the ceiling: the register | H36: 22 | I36: =SUMPRODUCT($B$14:$E$14,I35:L35) -> 0.036893488 | J36: =SUMPRODUCT($B$15:$E$15,I35:L35) -> 0.036893488 | K36: =SUMPRODUCT($B$16:$E$16,I35:L35) -> 0 | L36: =SUMPRODUCT($B$17:$E$17,I35:L35) -> 0 | M36: =SUM(I36:L36) -> 0.073786976
A37: Passes on (column) to (row) | B37: IND | C37: DIG | D37: ENG | E37: TRS | H37: 23 | I37: =SUMPRODUCT($B$14:$E$14,I36:L36) -> 0 | J37: =SUMPRODUCT($B$15:$E$15,I36:L36) -> 0 | K37: =SUMPRODUCT($B$16:$E$16,I36:L36) -> 0.029514791 | L37: =SUMPRODUCT($B$17:$E$17,I36:L36) -> 0.029514791 | M37: =SUM(I37:L37) -> 0.059029581
A38: IND | B38: 0 | C38: =$B$25 -> 0.4 | D38: =$B$4 -> 0.4 | E38: =$B$5 -> 0.4 | H38: 24 | I38: =SUMPRODUCT($B$14:$E$14,I37:L37) -> 0.023611832 | J38: =SUMPRODUCT($B$15:$E$15,I37:L37) -> 0.023611832 | K38: =SUMPRODUCT($B$16:$E$16,I37:L37) -> 0 | L38: =SUMPRODUCT($B$17:$E$17,I37:L37) -> 0 | M38: =SUM(I38:L38) -> 0.047223665
A39: DIG | B39: =$B$25 -> 0.4 | C39: 0 | D39: =$B$4 -> 0.4 | E39: =$B$5 -> 0.4 | H39: 25 | I39: =SUMPRODUCT($B$14:$E$14,I38:L38) -> 0 | J39: =SUMPRODUCT($B$15:$E$15,I38:L38) -> 0 | K39: =SUMPRODUCT($B$16:$E$16,I38:L38) -> 0.018889466 | L39: =SUMPRODUCT($B$17:$E$17,I38:L38) -> 0.018889466 | M39: =SUM(I39:L39) -> 0.037778932
A40: ENG | B40: =$B$4 -> 0.4 | C40: =$B$4 -> 0.4 | D40: 0 | E40: 0 | H40: 26 | I40: =SUMPRODUCT($B$14:$E$14,I39:L39) -> 0.015111573 | J40: =SUMPRODUCT($B$15:$E$15,I39:L39) -> 0.015111573 | K40: =SUMPRODUCT($B$16:$E$16,I39:L39) -> 0 | L40: =SUMPRODUCT($B$17:$E$17,I39:L39) -> 0 | M40: =SUM(I40:L40) -> 0.030223145
A41: TRS | B41: =$B$5 -> 0.4 | C41: =$B$5 -> 0.4 | D41: 0 | E41: 0 | H41: 27 | I41: =SUMPRODUCT($B$14:$E$14,I40:L40) -> 0 | J41: =SUMPRODUCT($B$15:$E$15,I40:L40) -> 0 | K41: =SUMPRODUCT($B$16:$E$16,I40:L40) -> 0.012089258 | L41: =SUMPRODUCT($B$17:$E$17,I40:L40) -> 0.012089258 | M41: =SUM(I41:L41) -> 0.024178516
H42: 28 | I42: =SUMPRODUCT($B$14:$E$14,I41:L41) -> 0.0096714066 | J42: =SUMPRODUCT($B$15:$E$15,I41:L41) -> 0.0096714066 | K42: =SUMPRODUCT($B$16:$E$16,I41:L41) -> 0 | L42: =SUMPRODUCT($B$17:$E$17,I41:L41) -> 0 | M42: =SUM(I42:L42) -> 0.019342813
...

Sheet DigitalTwin
A1: The digital twin: the gain audit flags a drift; the register's certificates are void until re-certified (AXIOM Lab 1.16, step 3; Theorem 16.5(ii); Online Appendix 16.B.2)
A2: The book prints no numbers for the drift: the scenario is this workbook's declaration, not the book's. Readings are the notebook's draws (seed 26116, engine values): the true gain plus an error of +/-0.02 (two standard deviations). Thin pass: within the error of the ceiling; flag: above it by more than the error.
A4: Ceiling of each core link | B4: =Ceil_gain -> 0.4 | C4: the register
A5: Error of a gain reading (two standard deviations) | B5: 0.02 | C5: this workbook's declaration
A6: True gains at the start | B6: 0.36 | C6: this workbook's declaration
A7: The Digital-engineering link drifts up, a quarter | B7: 0.02 | C7: from quarter 4
C8: IND-ENG | D8: DIG-ENG | E8: IND-TRS | F8: DIG-TRS
A9: Quarter | B9: True DIG-ENG | C9: Reading IND-ENG | D9: Reading DIG-ENG | E9: Reading IND-TRS | F9: Reading DIG-TRS | G9: Verdict IND-ENG | H9: Verdict DIG-ENG | I9: Verdict IND-TRS | J9: Verdict DIG-TRS | K9: Any thin pass | L9: Any flag
A10: 0 | B10: =$B$6+$B$7*MAX(A10-3,0) -> 0.36 | C10: 0.36782347 | D10: 0.34584903 | E10: 0.37455668 | F10: 0.35877822 | G10: =IF(C10>$B$4+$B$5,"flag",IF(C10>$B$4-$B$5,"thin pass","passes")) -> passes | H10: =IF(D10>$B$4+$B$5,"flag",IF(D10>$B$4-$B$5,"thin pass","passes")) -> passes | I10: =IF(E10>$B$4+$B$5,"flag",IF(E10>$B$4-$B$5,"thin pass","passes")) -> passes | J10: =IF(F10>$B$4+$B$5,"flag",IF(F10>$B$4-$B$5,"thin pass","passes")) -> passes | K10: =IF(COUNTIF(G10:J10,"thin pass")+COUNTIF(G10:J10,"flag")>0,1,0) -> 0 | L10: =IF(COUNTIF(G10:J10,"flag")>0,1,0) -> 0
A11: 1 | B11: =$B$6+$B$7*MAX(A11-3,0) -> 0.36 | C11: 0.34625735 | D11: 0.37510457 | E11: 0.36700913 | F11: 0.36460843 | G11: =IF(C11>$B$4+$B$5,"flag",IF(C11>$B$4-$B$5,"thin pass","passes")) -> passes | H11: =IF(D11>$B$4+$B$5,"flag",IF(D11>$B$4-$B$5,"thin pass","passes")) -> passes | I11: =IF(E11>$B$4+$B$5,"flag",IF(E11>$B$4-$B$5,"thin pass","passes")) -> passes | J11: =IF(F11>$B$4+$B$5,"flag",IF(F11>$B$4-$B$5,"thin pass","passes")) -> passes | K11: =IF(COUNTIF(G11:J11,"thin pass")+COUNTIF(G11:J11,"flag")>0,1,0) -> 0 | L11: =IF(COUNTIF(G11:J11,"flag")>0,1,0) -> 0
A12: 2 | B12: =$B$6+$B$7*MAX(A12-3,0) -> 0.36 | C12: 0.36819159 | D12: 0.35779282 | E12: 0.3534175 | F12: 0.36501289 | G12: =IF(C12>$B$4+$B$5,"flag",IF(C12>$B$4-$B$5,"thin pass","passes")) -> passes | H12: =IF(D12>$B$4+$B$5,"flag",IF(D12>$B$4-$B$5,"thin pass","passes")) -> passes | I12: =IF(E12>$B$4+$B$5,"flag",IF(E12>$B$4-$B$5,"thin pass","passes")) -> passes | J12: =IF(F12>$B$4+$B$5,"flag",IF(F12>$B$4-$B$5,"thin pass","passes")) -> passes | K12: =IF(COUNTIF(G12:J12,"thin pass")+COUNTIF(G12:J12,"flag")>0,1,0) -> 0 | L12: =IF(COUNTIF(G12:J12,"flag")>0,1,0) -> 0
A13: 3 | B13: =$B$6+$B$7*MAX(A13-3,0) -> 0.36 | C13: 0.3596179 | D13: 0.36496064 | E13: 0.34966654 | F13: 0.37236685 | G13: =IF(C13>$B$4+$B$5,"flag",IF(C13>$B$4-$B$5,"thin pass","passes")) -> passes | H13: =IF(D13>$B$4+$B$5,"flag",IF(D13>$B$4-$B$5,"thin pass","passes")) -> passes | I13: =IF(E13>$B$4+$B$5,"flag",IF(E13>$B$4-$B$5,"thin pass","passes")) -> passes | J13: =IF(F13>$B$4+$B$5,"flag",IF(F13>$B$4-$B$5,"thin pass","passes")) -> passes | K13: =IF(COUNTIF(G13:J13,"thin pass")+COUNTIF(G13:J13,"flag")>0,1,0) -> 0 | L13: =IF(COUNTIF(G13:J13,"flag")>0,1,0) -> 0
A14: 4 | B14: =$B$6+$B$7*MAX(A14-3,0) -> 0.38 | C14: 0.37167697 | D14: 0.39671516 | E14: 0.35953103 | F14: 0.3572778 | G14: =IF(C14>$B$4+$B$5,"flag",IF(C14>$B$4-$B$5,"thin pass","passes")) -> passes | H14: =IF(D14>$B$4+$B$5,"flag",IF(D14>$B$4-$B$5,"thin pass","passes")) -> thin pass | I14: =IF(E14>$B$4+$B$5,"flag",IF(E14>$B$4-$B$5,"thin pass","passes")) -> passes | J14: =IF(F14>$B$4+$B$5,"flag",IF(F14>$B$4-$B$5,"thin pass","passes")) -> passes | K14: =IF(COUNTIF(G14:J14,"thin pass")+COUNTIF(G14:J14,"flag")>0,1,0) -> 1 | L14: =IF(COUNTIF(G14:J14,"flag")>0,1,0) -> 0
A15: 5 | B15: =$B$6+$B$7*MAX(A15-3,0) -> 0.4 | C15: 0.34200378 | D15: 0.39315064 | E15: 0.36227875 | F15: 0.3475844 | G15: =IF(C15>$B$4+$B$5,"flag",IF(C15>$B$4-$B$5,"thin pass","passes")) -> passes | H15: =IF(D15>$B$4+$B$5,"flag",IF(D15>$B$4-$B$5,"thin pass","passes")) -> thin pass | I15: =IF(E15>$B$4+$B$5,"flag",IF(E15>$B$4-$B$5,"thin pass","passes")) -> passes | J15: =IF(F15>$B$4+$B$5,"flag",IF(F15>$B$4-$B$5,"thin pass","passes")) -> passes | K15: =IF(COUNTIF(G15:J15,"thin pass")+COUNTIF(G15:J15,"flag")>0,1,0) -> 1 | L15: =IF(COUNTIF(G15:J15,"flag")>0,1,0) -> 0
A16: 6 | B16: =$B$6+$B$7*MAX(A16-3,0) -> 0.42 | C16: 0.38529759 | D16: 0.42670797 | E16: 0.37306062 | F16: 0.34401212 | G16: =IF(C16>$B$4+$B$5,"flag",IF(C16>$B$4-$B$5,"thin pass","passes")) -> thin pass | H16: =IF(D16>$B$4+$B$5,"flag",IF(D16>$B$4-$B$5,"thin pass","passes")) -> flag | I16: =IF(E16>$B$4+$B$5,"flag",IF(E16>$B$4-$B$5,"thin pass","passes")) -> passes | J16: =IF(F16>$B$4+$B$5,"flag",IF(F16>$B$4-$B$5,"thin pass","passes")) -> passes | K16: =IF(COUNTIF(G16:J16,"thin pass")+COUNTIF(G16:J16,"flag")>0,1,0) -> 1 | L16: =IF(COUNTIF(G16:J16,"flag")>0,1,0) -> 1
A17: 7 | B17: =$B$6+$B$7*MAX(A17-3,0) -> 0.44 | C17: 0.38236254 | D17: 0.43065241 | E17: 0.3825762 | F17: 0.36059186 | G17: =IF(C17>$B$4+$B$5,"flag",IF(C17>$B$4-$B$5,"thin pass","passes")) -> thin pass | H17: =IF(D17>$B$4+$B$5,"flag",IF(D17>$B$4-$B$5,"thin pass","passes")) -> flag | I17: =IF(E17>$B$4+$B$5,"flag",IF(E17>$B$4-$B$5,"thin pass","passes")) -> thin pass | J17: =IF(F17>$B$4+$B$5,"flag",IF(F17>$B$4-$B$5,"thin pass","passes")) -> passes | K17: =IF(COUNTIF(G17:J17,"thin pass")+COUNTIF(G17:J17,"flag")>0,1,0) -> 1 | L17: =IF(COUNTIF(G17:J17,"flag")>0,1,0) -> 1
A18: 8 | B18: =$B$6+$B$7*MAX(A18-3,0) -> 0.46 | C18: 0.36195419 | D18: 0.48124736 | E18: 0.36388778 | F18: 0.34779855 | G18: =IF(C18>$B$4+$B$5,"flag",IF(C18>$B$4-$B$5,"thin pass","passes")) -> passes | H18: =IF(D18>$B$4+$B$5,"flag",IF(D18>$B$4-$B$5,"thin pass","passes")) -> flag | I18: =IF(E18>$B$4+$B$5,"flag",IF(E18>$B$4-$B$5,"thin pass","passes")) -> passes | J18: =IF(F18>$B$4+$B$5,"flag",IF(F18>$B$4-$B$5,"thin pass","passes")) -> passes | K18: =IF(COUNTIF(G18:J18,"thin pass")+COUNTIF(G18:J18,"flag")>0,1,0) -> 1 | L18: =IF(COUNTIF(G18:J18,"flag")>0,1,0) -> 1
A19: 9 | B19: =$B$6+$B$7*MAX(A19-3,0) -> 0.48 | C19: 0.36102931 | D19: 0.49079489 | E19: 0.34426158 | F19: 0.36840115 | G19: =IF(C19>$B$4+$B$5,"flag",IF(C19>$B$4-$B$5,"thin pass","passes")) -> passes | H19: =IF(D19>$B$4+$B$5,"flag",IF(D19>$B$4-$B$5,"thin pass","passes")) -> flag | I19: =IF(E19>$B$4+$B$5,"flag",IF(E19>$B$4-$B$5,"thin pass","passes")) -> passes | J19: =IF(F19>$B$4+$B$5,"flag",IF(F19>$B$4-$B$5,"thin pass","passes")) -> passes | K19: =IF(COUNTIF(G19:J19,"thin pass")+COUNTIF(G19:J19,"flag")>0,1,0) -> 1 | L19: =IF(COUNTIF(G19:J19,"flag")>0,1,0) -> 1
A20: 10 | B20: =$B$6+$B$7*MAX(A20-3,0) -> 0.5 | C20: 0.36149446 | D20: 0.48423394 | E20: 0.37494588 | F20: 0.36305955 | G20: =IF(C20>$B$4+$B$5,"flag",IF(C20>$B$4-$B$5,"thin pass","passes")) -> passes | H20: =IF(D20>$B$4+$B$5,"flag",IF(D20>$B$4-$B$5,"thin pass","passes")) -> flag | I20: =IF(E20>$B$4+$B$5,"flag",IF(E20>$B$4-$B$5,"thin pass","passes")) -> passes | J20: =IF(F20>$B$4+$B$5,"flag",IF(F20>$B$4-$B$5,"thin pass","passes")) -> passes | K20: =IF(COUNTIF(G20:J20,"thin pass")+COUNTIF(G20:J20,"flag")>0,1,0) -> 1 | L20: =IF(COUNTIF(G20:J20,"flag")>0,1,0) -> 1
A21: 11 | B21: =$B$6+$B$7*MAX(A21-3,0) -> 0.52 | C21: 0.34285338 | D21: 0.51272715 | E21: 0.36065908 | F21: 0.36463784 | G21: =IF(C21>$B$4+$B$5,"flag",IF(C21>$B$4-$B$5,"thin pass","passes")) -> passes | H21: =IF(D21>$B$4+$B$5,"flag",IF(D21>$B$4-$B$5,"thin pass","passes")) -> flag | I21: =IF(E21>$B$4+$B$5,"flag",IF(E21>$B$4-$B$5,"thin pass","passes")) -> passes | J21: =IF(F21>$B$4+$B$5,"flag",IF(F21>$B$4-$B$5,"thin pass","passes")) -> passes | K21: =IF(COUNTIF(G21:J21,"thin pass")+COUNTIF(G21:J21,"flag")>0,1,0) -> 1 | L21: =IF(COUNTIF(G21:J21,"flag")>0,1,0) -> 1
A22: 12 | B22: =$B$6+$B$7*MAX(A22-3,0) -> 0.54 | C22: 0.36165972 | D22: 0.53570422 | E22: 0.35067436 | F22: 0.36026329 | G22: =IF(C22>$B$4+$B$5,"flag",IF(C22>$B$4-$B$5,"thin pass","passes")) -> passes | H22: =IF(D22>$B$4+$B$5,"flag",IF(D22>$B$4-$B$5,"thin pass","passes")) -> flag | I22: =IF(E22>$B$4+$B$5,"flag",IF(E22>$B$4-$B$5,"thin pass","passes")) -> passes | J22: =IF(F22>$B$4+$B$5,"flag",IF(F22>$B$4-$B$5,"thin pass","passes")) -> passes | K22: =IF(COUNTIF(G22:J22,"thin pass")+COUNTIF(G22:J22,"flag")>0,1,0) -> 1 | L22: =IF(COUNTIF(G22:J22,"flag")>0,1,0) -> 1
A25: First quarter with a thin pass | B25: =MATCH(1,K10:K22,0)-1 -> 4
A26: First quarter with a flag | B26: =MATCH(1,L10:L22,0)-1 -> 6 | C26: the gain audit fires
A27: The flagged link | B27: =INDEX($C$8:$F$8,MATCH("flag",INDEX($G$10:$J$22,B26+1,0),0)) -> DIG-ENG | C27: attribution: Digital Solutions and shared engineering
A28: Its reading | B28: =INDEX($C$10:$F$22,B26+1,MATCH(B27,$C$8:$F$8,0)) -> 0.42670797
A30: Re-certified register: e = t = the ceiling, DIG-ENG = the reading. B B^T: (1,1) | B30: =$B$4^2+$B$4^2 -> 0.32 | C30: the core is bipartite: the spectral radius is B's largest singular value
A31: (1,2) | B31: =$B$4*B28+$B$4^2 -> 0.33068319
A32: (2,2) | B32: =B28^2+$B$4^2 -> 0.34207969
A33: Spectral radius | B33: =SQRT((B30+B32+SQRT((B30-B32)^2+4*B31^2))/2) -> 0.81357684
A34: Half-life (quarters) | B34: =LN(2)/LN(1/B33) -> 3.3596563
A35: Multiplier | B35: =1/(1-B33) -> 5.3641402
A36: Within the board's rule? | B36: =IF(B33<=Rule_rho,"yes, with the ceiling re-declared","no") -> yes, with the ceiling re-declared
A38: Largest DIG-ENG gain the rule tolerates, others at the ceiling: a = t^2 - r*^2 | B38: =$B$4^2-Rule_rho^2 -> -0.54710678 | C38: (t^2 - L) g^2 - 2 e t^2 g + (e^2 + t^2 - L)(t^2 - L) - t^4 = 0, L = r*^2
A39: b = -2 e t^2 | B39: =-2*$B$4*$B$4^2 -> -0.128
A40: c | B40: =($B$4^2+$B$4^2-Rule_rho^2)*($B$4^2-Rule_rho^2)-$B$4^4 -> 0.18618875
A41: the gain | B41: =(-B39-SQRT(B39^2-4*B38*B40))/(2*B38) -> 0.47799938
A42: Quarter the true drift passes it | B42: =_xlfn.MINIFS($A$10:$A$22,$B$10:$B$22,">"&B41) -> 9 | C42: re-declaring is no longer enough: buy the link down
A44: Certificates the flag voids, all of which Theorem 16.5(ii) grants only within the ceilings: the spectral radius at most 0.80; the half-life at most 3.1 quarters; the multiplier at most 5; the echo of a $10 million shock at most $8m, $6.4m, ..., $50m; the sensitivity certificates of Chapter 14; gate (R3).
A46: Online Appendix 16.B.2: 10,000 models with |A| <= M | B46: Largest spectral radius | C46: Models above the register's radius | D46: Echoes above its bound
A47: seed 16, as in the book's engine | B47: 0.63481061 | C47: 0 | D47: 0
...

Sheet R4_Horizon
A1: Feasibility with horizon honesty, gate (R4): each margin against the error of its reading (Worked Example 16.1, Step 4; Table 16.4)
A3: As first declared: no levers among the decisions | B3: Value | C3: Reading
A4: Breach odds, no levers (engine, seed 8) | B4: 0.24622 | C4: 24.6 percent
A5: Within the appetite? | B5: =IF(B4<=Appetite,"yes","no: (R4) fails") -> no: (R4) fails
A7: Quarter K | B7: Odds of a breach by quarter K (engine) | C7: Within the appetite?
A8: 1 | B8: 0.00215 | C8: =IF(B8<=Appetite,"yes","no") -> yes
A9: 2 | B9: 0.01028 | C9: =IF(B9<=Appetite,"yes","no") -> yes
A10: 3 | B10: 0.02676 | C10: =IF(B10<=Appetite,"yes","no") -> yes
A11: 4 | B11: 0.05112 | C11: =IF(B11<=Appetite,"yes","no") -> no
A12: 5 | B12: 0.08092 | C12: =IF(B12<=Appetite,"yes","no") -> no
A13: 6 | B13: 0.11297 | C13: =IF(B13<=Appetite,"yes","no") -> no
A14: 7 | B14: 0.1429 | C14: =IF(B14<=Appetite,"yes","no") -> no
A15: 8 | B15: 0.16928 | C15: =IF(B15<=Appetite,"yes","no") -> no
A16: 9 | B16: 0.19364 | C16: =IF(B16<=Appetite,"yes","no") -> no
A17: 10 | B17: 0.21387 | C17: =IF(B17<=Appetite,"yes","no") -> no
A18: 11 | B18: 0.2317 | C18: =IF(B18<=Appetite,"yes","no") -> no
A19: 12 | B19: 0.24622 | C19: =IF(B19<=Appetite,"yes","no") -> no
A20: The artifact: quarters for which the declaration honors the appetite | B20: =COUNTIF(B8:B19,"<="&Appetite) -> 3
A22: With the package | B22: Value | C22: Reading
A23: Breach odds with the package (engine, seed 8) | B23: 0.05 | C23: 5.0 percent: binds
A24: Simulation error, points | B24: =100*SQRT(B23*(1-B23)/N_paths) -> 0.068920244 | C24: 0.07 points
A25: Price of the appetite ($ million a point) | B25: =Quantiles!B101 -> 1.8070148 | C25: $1.8 million a point
A26: Net leverage with the line fully drawn | B26: =(Net_debt+Quantiles!B93)/Ebitda -> 3.7430186 | C26: 3.74x
A27: Covenant margin | B27: =Covenant-B26 -> 0.75698144 | C27: 0.76 below the limit
A28: Error of the leverage reading | B28: =Band_lev*B26 -> 0.074860371 | C28: Online Appendix 16.B.3: 0.075
A29: Margin in errors of the reading | B29: =B27/B28 -> 10.111911 | C29: ten times its band
A30: Capability margin | B30: =Capability-Cap_floor -> 3 | C30: 3 points against +/-5
A31: Strategic risk: peak on the plan | B31: =MAX(B46:B646) -> 73.552546 | C31: 73.6
A32: month of the peak | B32: =12*INDEX(A46:A646,MATCH(B31,B46:B646,0)) -> 10.9 | C32: month 11
A33: margin under the ceiling | B33: =Risk_ceil-B31 -> 1.4474538 | C33: 1.4 points against +/-6
A35: Fresh paths (certificate seed 26209): the same package's odds (engine) | B35: 0.04907 | C35: fitted to the book's paths, its odds move by about a standard error on new ones
A36: Fresh paths: the cheapest package's cost (engine) | B36: 10.276112 | C36: a statistical certificate carries its paths, its seed and its error
A38: Table 16.4, bottom: commitment | B38: Margin | C38: Error of the reading | D38: Grade
A39: leverage <= 4.5x | B39: =B27 -> 0.75698144 | C39: =B28 -> 0.074860371 | D39: =IF(ABS(B39)<0.000000001,"statistical: binds",IF(B39>=C39,"strong","weaker than the reading")) -> strong
A40: breach odds <= 5% | B40: =100*(Appetite-B23) -> 0 | C40: =B24 -> 0.068920244 | D40: =IF(ABS(B40)<0.000000001,"statistical: binds",IF(B40>=C40,"strong","weaker than the reading")) -> statistical: binds
A41: capability >= 55 | B41: =B30 -> 3 | C41: =Band_cap -> 5 | D41: =IF(ABS(B41)<0.000000001,"statistical: binds",IF(B41>=C41,"strong","weaker than the reading")) -> weaker than the reading
A42: strategic risk <= 75 | B42: =B33 -> 1.4474538 | C42: =Band_risk -> 6 | D42: =IF(ABS(B42)<0.000000001,"statistical: binds",IF(B42>=C42,"strong","weaker than the reading")) -> weaker than the reading
A45: Years t (a tenth of a month) | B45: Strategic risk on the digital plan
A46: =0/120 -> 0 | B46: =Risk_target+(Risk0-Risk_target)*EXP(-Risk_rate*A46)+Risk_hump*(A46/Risk_peak_t)*EXP(1-A46/Risk_peak_t) -> 64
A47: =1/120 -> 0.0083333333 | B47: =Risk_target+(Risk0-Risk_target)*EXP(-Risk_rate*A47)+Risk_hump*(A47/Risk_peak_t)*EXP(1-A47/Risk_peak_t) -> 64.219187
...

Sheet Certificate
A1: Issue the certificate: Table 16.4, the grades and the work orders; no gate implies the next (Worked Example 16.1, Step 5; Theorem 16.4; Appendix 16.A)
A3: Gate | B3: After Chapter 8 | C3: Now | D3: Verdict now | E3: Owners
