Workbook

Sheet README
B1: DCT Laboratory — Vol II, Ch 12: Multi-Objective Enterprise Optimization
B2: Seed 26212 · Companion to DCT_V2_Ch12_Lab.ipynb and AXIOM Lab 2.12 (module AXIOM-12). Money in $ million.
B4: Worked Example 12.1, Whose Objective Runs the Automation Program?, with the book's declarations: Chapter 5's automation program and the three owners' objectives (the CFO's present value of the payouts, the COO's run-rate savings in year 6, the treasury's reserve on every cash commitment). Deterministic: no random draw enters the book's numbers.
B5: Declarations: the program, the board's commitments and rate, and the reserve, price and goals to explore.
B6: Schedules: all 64 schedules with Chapter 5's war chest raised by the reserve, their best payouts, dominance, the board value, and the war chest recomputed at any reserve with the reserve's price (Steps 1-2).
B7: Frontier: the best schedule with each number of rounds, the five efficient plans, the prices between them, the board's weighted sum and a price to explore; the ideal point; bounds on all objectives but one (Step 3).
B8: Reserve: the reserve's price, the largest reserve each schedule keeps, and the three-round trade-off surface with its two jumps (Step 4).
B9: Grid and Plans: the best payouts for every number of rounds and reserve on the $1 million grid, the 992 plans and the 740 efficient ones; the engine's support test for each, with its certificate checked by formulas.
B10: Choose: the ideal and nadir points, the Chebyshev choices, any efficient plan reached by its own weights, the owners' own bests, and goal programming with and without a second stage (Step 5). Table12_3: Table 12.3.
B11: Computing: Section 12.4's counts and hypervolume, and the lab's own weight sweep and evolutionary search (seed 26212). Uncertainty: Chapter 9's cost-chance frontier as the book prints it and the price of the appetite (Section 12.5).
B12: Engine values (green) are what needs a linear program per plan, or the notebook's searches; everything else is a formula.
B13: Reference_Values and Checks: the engine's numbers and a PASS/FAIL comparison with this workbook's formulas.
... B19: Cross-sheet link: green.

Sheet Declarations
A1: Declarations (Worked Example 12.1, Step 1; Online Appendix Remark 12.B.1). Money in $ million.
A3: Quantity | B3: Value | C3: Source
A4: Today's cash, q_0 | B4: 620 | C4: Chapter 5's program (Volume I, Worked Example 6.1)
A5: Today's efficiency, e_0 (points) | B5: 71
A6: Efficiency ceiling (points) | B6: 85 | C6: A round halves the remaining gap to 85
A7: Share of the gap a round closes | B7: 0.5
A8: Savings per point above 71, a year | B8: 10 | C8: S_k = 10 (e_k - 71)
A9: Cost of a round | B9: 120
A10: Floor on cash at every year end | B10: 350 | C10: The board's commitments
A11: Cash a round needs before it starts | B11: 470
A12: End condition: cash at the end of year 6 | B12: 470
A13: Hurdle rate r (a year) | B13: 0.1 | C13: Payouts discounted at 10 percent; cash earns nothing
A14: Discount factor, beta = 1/(1 + r) | B14: =1/(1+Hurdle_r) -> 0.90909091 | C14: Also the reserve's price: $0.909 of payouts per dollar (Step 4)
A15: Chapter 5's price of savings, beta^6 / r | B15: =Beta_y^6/Hurdle_r -> 5.6447393 | C15: $5.645 of payouts today per dollar a year of year-6 savings (Section 12.2)
A17: Reserve to explore, b (above 0) | B17: 50 | C17: Schedules: the war chest recomputed at this reserve (Section 12.1's example: a $50 million reserve)
A18: Price of savings to explore, w | B18: 10 | C18: Frontier: the plan a weighted sum picks at this price; try 3, 5.645, 10, 20, 40
A20: Goal: payouts of at least | B20: 300 | C20: Worked Example 12.1, Step 5
A21: Goal: savings of at least, a year | B21: 122.5
A22: Goal: a reserve of | B22: 25
A23: Augmentation of the Chebyshev program, rho | B23: 0.0001 | C23: Online Appendix Example 12.B.2
A25: Dynamics: e_k = e_(k-1) + z_k (85 - e_(k-1))/2; S_k = 10 (e_k - 71); q_k = q_(k-1) - 120 z_k + S_k - p_k, p_k >= 0. Commitments, each kept with the reserve b to spare: q_k >= 350 + b every year; q_(k-1) >= 470 + b before a round in year k; q_6 >= 470 + b.
A26: The three owners' objectives (new declarations): the CFO's present value of the payouts at 10 percent; the COO's run-rate savings in year 6, S_6 = 140 - 140/2^n for n rounds; the treasury's reserve b.
A27: Chapter 5's board value is the weighted sum: payouts + (beta^6 / r) x savings. No plan keeps a reserve above $150 million: before the first round, or at the end without one, the cash is at most $620 million against $470 million plus the reserve.

Sheet Schedules
A1: All 64 schedules of rounds, each with its best payouts: Chapter 5's war chest raised by the reserve (Worked Example 12.1, Steps 1-2; Online Appendix Remark 12.B.1; AXIOM Lab 2.12, step 1)
A2: Each row is a schedule (z_k = 1: a round in year k; # is z_1...z_6 read as a binary number). Its best payouts pay out, every year end, everything above the war chest R_k: R_6 = 470 + b; R_(k-1) = max(R_k + 120 z_k - S_k, (470 + b) z_k, 350 + b), with no floor term for R_0.
A3: The schedule keeps every commitment while 620 >= R_0, so the largest reserve it keeps is 620 - R_0 at b = 0. Then p_1 = 620 - 120 z_1 + S_1 - R_1 and p_k = R_(k-1) - 120 z_k + S_k - R_k: the reserve raises every R_k by b, so only p_1 falls, by b. The notebook checks the war chest against the linear program for all 9,664 pairs.
A4: Right-hand block: the war chest recomputed from scratch at the reserve on Declarations (Res_b), and the reserve's price, (PV at 0 - PV at b) / b, for every schedule that keeps it.
AD6: Discount factor | AE6: =Beta_y^1 -> 0.90909091 | AF6: =Beta_y^2 -> 0.82644628 | AG6: =Beta_y^3 -> 0.7513148 | AH6: =Beta_y^4 -> 0.68301346 | AI6: =Beta_y^5 -> 0.62092132 | AJ6: =Beta_y^6 -> 0.56447393 | AY6: =Beta_y^1 -> 0.90909091 | AZ6: =Beta_y^2 -> 0.82644628 | BA6: =Beta_y^3 -> 0.7513148 | BB6: =Beta_y^4 -> 0.68301346 | BC6: =Beta_y^5 -> 0.62092132 | BD6: =Beta_y^6 -> 0.56447393
A7: # | B7: Rounds (years) | C7: z1 | D7: z2 | E7: z3 | F7: z4 | G7: z5 | H7: z6 | I7: Rounds n | J7: e1 | K7: e2 | L7: e3 | M7: e4 | N7: e5 | O7: e6 | P7: S1 | Q7: S2 | R7: S3 | S7: S4 | T7: S5 | U7: S6 | V7: R0 | W7: R1 | X7: R2 | Y7: R3 | Z7: R4 | AA7: R5 | AB7: R6 | AC7: Largest reserve it keeps | AD7: Keeps every commitment, no reserve | AE7: p1 | AF7: p2 | AG7: p3 | AH7: p4 | AI7: p5 | AJ7: p6 | AK7: Payouts, PV (CFO) | AL7: Savings, year 6 (COO) | AM7: Dominated (payouts, savings) | AN7: Efficient | AO7: Board value (Chapter 5) | AP7: Weighted sum at the price to explore | AQ7: R0 at Res_b | AR7: R1 at Res_b | AS7: R2 at Res_b | AT7: R3 at Res_b | AU7: R4 at Res_b | AV7: R5 at Res_b | AW7: R6 at Res_b | AX7: Keeps every commitment at Res_b | AY7: p1 at Res_b | AZ7: p2 at Res_b | BA7: p3 at Res_b | BB7: p4 at Res_b | BC7: p5 at Res_b | BD7: p6 at Res_b | BE7: Payouts, PV, at Res_b | BF7: Reserve's price: (PV at 0 - PV at Res_b) / Res_b | BG7: Payouts, PV, at the goal reserve | BH7: Meets every goal
A8: 0 | B8: none | C8: =MOD(INT($A8/32),2) -> 0 | D8: =MOD(INT($A8/16),2) -> 0 | E8: =MOD(INT($A8/8),2) -> 0 | F8: =MOD(INT($A8/4),2) -> 0 | G8: =MOD(INT($A8/2),2) -> 0 | H8: =MOD(INT($A8/1),2) -> 0 | I8: =SUM(C8:H8) -> 0 | J8: =E_zero+C8*Half_gap*(Ceiling_e-E_zero) -> 71 | K8: =J8+D8*Half_gap*(Ceiling_e-J8) -> 71 | L8: =K8+E8*Half_gap*(Ceiling_e-K8) -> 71 | M8: =L8+F8*Half_gap*(Ceiling_e-L8) -> 71 | N8: =M8+G8*Half_gap*(Ceiling_e-M8) -> 71 | O8: =N8+H8*Half_gap*(Ceiling_e-N8) -> 71 | P8: =Val_pt*(J8-E_zero) -> 0 | Q8: =Val_pt*(K8-E_zero) -> 0 | R8: =Val_pt*(L8-E_zero) -> 0 | S8: =Val_pt*(M8-E_zero) -> 0 | T8: =Val_pt*(N8-E_zero) -> 0 | U8: =Val_pt*(O8-E_zero) -> 0 | V8: =MAX(W8+Cost_round*C8-P8,IF(C8=1,Pre_q,0)) -> 470 | W8: =MAX(X8+Cost_round*D8-Q8,IF(D8=1,Pre_q,0),Floor_q) -> 470 | X8: =MAX(Y8+Cost_round*E8-R8,IF(E8=1,Pre_q,0),Floor_q) -> 470 | Y8: =MAX(Z8+Cost_round*F8-S8,IF(F8=1,Pre_q,0),Floor_q) -> 470 | Z8: =MAX(AA8+Cost_round*G8-T8,IF(G8=1,Pre_q,0),Floor_q) -> 470 | AA8: =MAX(AB8+Cost_round*H8-U8,IF(H8=1,Pre_q,0),Floor_q) -> 470 | AB8: =End_q -> 470 | AC8: =Q_zero-V8 -> 150 | AD8: =IF(AC8>=-0.000000001,1,0) -> 1 | AE8: =IF($AD8=1,Q_zero-Cost_round*C8+P8-W8,"") -> 150 | AF8: =IF($AD8=1,W8-Cost_round*D8+Q8-X8,"") -> 0 | AG8: =IF($AD8=1,X8-Cost_round*E8+R8-Y8,"") -> 0 | AH8: =IF($AD8=1,Y8-Cost_round*F8+S8-Z8,"") -> 0 | AI8: =IF($AD8=1,Z8-Cost_round*G8+T8-AA8,"") -> 0 | AJ8: =IF($AD8=1,AA8-Cost_round*H8+U8-AB8,"") -> 0 | AK8: =IF($AD8=1,SUMPRODUCT(AE8:AJ8,$AE$6:$AJ$6),"") -> 136.36364 | AL8: =U8 -> 0 | AM8: =IF(SUMPRODUCT(($AK$8:$AK$71>=AK8-0.000000001)*($AL$8:$AL$71>=AL8-0.000000001)*((($AK$8:$AK$71>AK8+0.000000001)+($AL$8:$AL$71>AL8+0.000000001))>0))>0,1,0) -> 1 | AN8: =1-AM8 -> 0 | AO8: =AK8+W_board*AL8 -> 136.36364 | AP8: =AK8+W_try*AL8 -> 136.36364 | AQ8: =MAX(AR8+Cost_round*C8-P8,IF(C8=1,Pre_q+Res_b,0)) -> 520 | AR8: =MAX(AS8+Cost_round*D8-Q8,IF(D8=1,Pre_q+Res_b,0),Floor_q+Res_b) -> 520 | AS8: =MAX(AT8+Cost_round*E8-R8,IF(E8=1,Pre_q+Res_b,0),Floor_q+Res_b) -> 520 | AT8: =MAX(AU8+Cost_round*F8-S8,IF(F8=1,Pre_q+Res_b,0),Floor_q+Res_b) -> 520 | AU8: =MAX(AV8+Cost_round*G8-T8,IF(G8=1,Pre_q+Res_b,0),Floor_q+Res_b) -> 520 | AV8: =MAX(AW8+Cost_round*H8-U8,IF(H8=1,Pre_q+Res_b,0),Floor_q+Res_b) -> 520 | AW8: =End_q+Res_b -> 520 | AX8: =IF(Q_zero>=AQ8-0.000000001,1,0) -> 1 | AY8: =IF($AX8=1,Q_zero-Cost_round*C8+P8-AR8,"") -> 100 | AZ8: =IF($AX8=1,AR8-Cost_round*D8+Q8-AS8,"") -> 0 | BA8: =IF($AX8=1,AS8-Cost_round*E8+R8-AT8,"") -> 0 | BB8: =IF($AX8=1,AT8-Cost_round*F8+S8-AU8,"") -> 0 | BC8: =IF($AX8=1,AU8-Cost_round*G8+T8-AV8,"") -> 0 | BD8: =IF($AX8=1,AV8-Cost_round*H8+U8-AW8,"") -> 0 | BE8: =IF($AX8=1,SUMPRODUCT(AY8:BD8,$AY$6:$BD$6),"") -> 90.909091 | BF8: =IF(AND($AX8=1,Res_b>0),(AK8-BE8)/Res_b,"") -> 0.90909091 | BG8: =IF(AC8>=Goal_b-0.000000001,AK8-Beta_y*Goal_b,"") -> 113.63636 | BH8: =IF(AC8>=Goal_b-0.000000001,IF(AND(AL8>=Goal_S-0.000000001,BG8>=Goal_P-0.000000001),1,0),0) -> 0
A9: 1 | B9: 6 | C9: =MOD(INT($A9/32),2) -> 0 | D9: =MOD(INT($A9/16),2) -> 0 | E9: =MOD(INT($A9/8),2) -> 0 | F9: =MOD(INT($A9/4),2) -> 0 | G9: =MOD(INT($A9/2),2) -> 0 | H9: =MOD(INT($A9/1),2) -> 1 | I9: =SUM(C9:H9) -> 1 | J9: =E_zero+C9*Half_gap*(Ceiling_e-E_zero) -> 71 | K9: =J9+D9*Half_gap*(Ceiling_e-J9) -> 71 | L9: =K9+E9*Half_gap*(Ceiling_e-K9) -> 71 | M9: =L9+F9*Half_gap*(Ceiling_e-L9) -> 71 | N9: =M9+G9*Half_gap*(Ceiling_e-M9) -> 71 | O9: =N9+H9*Half_gap*(Ceiling_e-N9) -> 78 | P9: =Val_pt*(J9-E_zero) -> 0 | Q9: =Val_pt*(K9-E_zero) -> 0 | R9: =Val_pt*(L9-E_zero) -> 0 | S9: =Val_pt*(M9-E_zero) -> 0 | T9: =Val_pt*(N9-E_zero) -> 0 | U9: =Val_pt*(O9-E_zero) -> 70 | V9: =MAX(W9+Cost_round*C9-P9,IF(C9=1,Pre_q,0)) -> 520 | W9: =MAX(X9+Cost_round*D9-Q9,IF(D9=1,Pre_q,0),Floor_q) -> 520 | X9: =MAX(Y9+Cost_round*E9-R9,IF(E9=1,Pre_q,0),Floor_q) -> 520 | Y9: =MAX(Z9+Cost_round*F9-S9,IF(F9=1,Pre_q,0),Floor_q) -> 520 | Z9: =MAX(AA9+Cost_round*G9-T9,IF(G9=1,Pre_q,0),Floor_q) -> 520 | AA9: =MAX(AB9+Cost_round*H9-U9,IF(H9=1,Pre_q,0),Floor_q) -> 520 | AB9: =End_q -> 470 | AC9: =Q_zero-V9 -> 100 | AD9: =IF(AC9>=-0.000000001,1,0) -> 1 | AE9: =IF($AD9=1,Q_zero-Cost_round*C9+P9-W9,"") -> 100 | AF9: =IF($AD9=1,W9-Cost_round*D9+Q9-X9,"") -> 0 | AG9: =IF($AD9=1,X9-Cost_round*E9+R9-Y9,"") -> 0 | AH9: =IF($AD9=1,Y9-Cost_round*F9+S9-Z9,"") -> 0 | AI9: =IF($AD9=1,Z9-Cost_round*G9+T9-AA9,"") -> 0 | AJ9: =IF($AD9=1,AA9-Cost_round*H9+U9-AB9,"") -> 0 | AK9: =IF($AD9=1,SUMPRODUCT(AE9:AJ9,$AE$6:$AJ$6),"") -> 90.909091 | AL9: =U9 -> 70 | AM9: =IF(SUMPRODUCT(($AK$8:$AK$71>=AK9-0.000000001)*($AL$8:$AL$71>=AL9-0.000000001)*((($AK$8:$AK$71>AK9+0.000000001)+($AL$8:$AL$71>AL9+0.000000001))>0))>0,1,0) -> 1 | AN9: =1-AM9 -> 0 | AO9: =AK9+W_board*AL9 -> 486.04084 | AP9: =AK9+W_try*AL9 -> 790.90909 | AQ9: =MAX(AR9+Cost_round*C9-P9,IF(C9=1,Pre_q+Res_b,0)) -> 570 | AR9: =MAX(AS9+Cost_round*D9-Q9,IF(D9=1,Pre_q+Res_b,0),Floor_q+Res_b) -> 570 | AS9: =MAX(AT9+Cost_round*E9-R9,IF(E9=1,Pre_q+Res_b,0),Floor_q+Res_b) -> 570 | AT9: =MAX(AU9+Cost_round*F9-S9,IF(F9=1,Pre_q+Res_b,0),Floor_q+Res_b) -> 570 | AU9: =MAX(AV9+Cost_round*G9-T9,IF(G9=1,Pre_q+Res_b,0),Floor_q+Res_b) -> 570 | AV9: =MAX(AW9+Cost_round*H9-U9,IF(H9=1,Pre_q+Res_b,0),Floor_q+Res_b) -> 570 | AW9: =End_q+Res_b -> 520 | AX9: =IF(Q_zero>=AQ9-0.000000001,1,0) -> 1 | AY9: =IF($AX9=1,Q_zero-Cost_round*C9+P9-AR9,"") -> 50 | AZ9: =IF($AX9=1,AR9-Cost_round*D9+Q9-AS9,"") -> 0 | BA9: =IF($AX9=1,AS9-Cost_round*E9+R9-AT9,"") -> 0 | BB9: =IF($AX9=1,AT9-Cost_round*F9+S9-AU9,"") -> 0 | BC9: =IF($AX9=1,AU9-Cost_round*G9+T9-AV9,"") -> 0 | BD9: =IF($AX9=1,AV9-Cost_round*H9+U9-AW9,"") -> 0 | BE9: =IF($AX9=1,SUMPRODUCT(AY9:BD9,$AY$6:$BD$6),"") -> 45.454545 | BF9: =IF(AND($AX9=1,Res_b>0),(AK9-BE9)/Res_b,"") -> 0.90909091 | BG9: =IF(AC9>=Goal_b-0.000000001,AK9-Beta_y*Goal_b,"") -> 68.181818 | BH9: =IF(AC9>=Goal_b-0.000000001,IF(AND(AL9>=Goal_S-0.000000001,BG9>=Goal_P-0.000000001),1,0),0) -> 0
A10: 2 | B10: 5 | C10: =MOD(INT($A10/32),2) -> 0 | D10: =MOD(INT($A10/16),2) -> 0 | E10: =MOD(INT($A10/8),2) -> 0 | F10: =MOD(INT($A10/4),2) -> 0 | G10: =MOD(INT($A10/2),2) -> 1 | H10: =MOD(INT($A10/1),2) -> 0 | I10: =SUM(C10:H10) -> 1 | J10: =E_zero+C10*Half_gap*(Ceiling_e-E_zero) -> 71 | K10: =J10+D10*Half_gap*(Ceiling_e-J10) -> 71 | L10: =K10+E10*Half_gap*(Ceiling_e-K10) -> 71 | M10: =L10+F10*Half_gap*(Ceiling_e-L10) -> 71 | N10: =M10+G10*Half_gap*(Ceiling_e-M10) -> 78 | O10: =N10+H10*Half_gap*(Ceiling_e-N10) -> 78 | P10: =Val_pt*(J10-E_zero) -> 0 | Q10: =Val_pt*(K10-E_zero) -> 0 | R10: =Val_pt*(L10-E_zero) -> 0 | S10: =Val_pt*(M10-E_zero) -> 0 | T10: =Val_pt*(N10-E_zero) -> 70 | U10: =Val_pt*(O10-E_zero) -> 70 | V10: =MAX(W10+Cost_round*C10-P10,IF(C10=1,Pre_q,0)) -> 470 | W10: =MAX(X10+Cost_round*D10-Q10,IF(D10=1,Pre_q,0),Floor_q) -> 470 | X10: =MAX(Y10+Cost_round*E10-R10,IF(E10=1,Pre_q,0),Floor_q) -> 470 | Y10: =MAX(Z10+Cost_round*F10-S10,IF(F10=1,Pre_q,0),Floor_q) -> 470 | Z10: =MAX(AA10+Cost_round*G10-T10,IF(G10=1,Pre_q,0),Floor_q) -> 470 | AA10: =MAX(AB10+Cost_round*H10-U10,IF(H10=1,Pre_q,0),Floor_q) -> 400 | AB10: =End_q -> 470 | AC10: =Q_zero-V10 -> 150 | AD10: =IF(AC10>=-0.000000001,1,0) -> 1 | AE10: =IF($AD10=1,Q_zero-Cost_round*C10+P10-W10,"") -> 150 | AF10: =IF($AD10=1,W10-Cost_round*D10+Q10-X10,"") -> 0 | AG10: =IF($AD10=1,X10-Cost_round*E10+R10-Y10,"") -> 0 | AH10: =IF($AD10=1,Y10-Cost_round*F10+S10-Z10,"") -> 0 | AI10: =IF($AD10=1,Z10-Cost_round*G10+T10-AA10,"") -> 20 | AJ10: =IF($AD10=1,AA10-Cost_round*H10+U10-AB10,"") -> 0 | AK10: =IF($AD10=1,SUMPRODUCT(AE10:AJ10,$AE$6:$AJ$6),"") -> 148.78206 | AL10: =U10 -> 70 | AM10: =IF(SUMPRODUCT(($AK$8:$AK$71>=AK10-0.000000001)*($AL$8:$AL$71>=AL10-0.000000001)*((($AK$8:$AK$71>AK10+0.000000001)+($AL$8:$AL$71>AL10+0.000000001))>0))>0,1,0) -> 1 | AN10: =1-AM10 -> 0 | AO10: =AK10+W_board*AL10 -> 543.91381 | AP10: =AK10+W_try*AL10 -> 848.78206 | AQ10: =MAX(AR10+Cost_round*C10-P10,IF(C10=1,Pre_q+Res_b,0)) -> 520 | AR10: =MAX(AS10+Cost_round*D10-Q10,IF(D10=1,Pre_q+Res_b,0),Floor_q+Res_b) -> 520 | AS10: =MAX(AT10+Cost_round*E10-R10,IF(E10=1,Pre_q+Res_b,0),Floor_q+Res_b) -> 520 | AT10: =MAX(AU10+Cost_round*F10-S10,IF(F10=1,Pre_q+Res_b,0),Floor_q+Res_b) -> 520 | AU10: =MAX(AV10+Cost_round*G10-T10,IF(G10=1,Pre_q+Res_b,0),Floor_q+Res_b) -> 520 | AV10: =MAX(AW10+Cost_round*H10-U10,IF(H10=1,Pre_q+Res_b,0),Floor_q+Res_b) -> 450 | AW10: =End_q+Res_b -> 520 | AX10: =IF(Q_zero>=AQ10-0.000000001,1,0) -> 1 | AY10: =IF($AX10=1,Q_zero-Cost_round*C10+P10-AR10,"") -> 100 | AZ10: =IF($AX10=1,AR10-Cost_round*D10+Q10-AS10,"") -> 0 | BA10: =IF($AX10=1,AS10-Cost_round*E10+R10-AT10,"") -> 0 | BB10: =IF($AX10=1,AT10-Cost_round*F10+S10-AU10,"") -> 0 | BC10: =IF($AX10=1,AU10-Cost_round*G10+T10-AV10,"") -> 20 | BD10: =IF($AX10=1,AV10-Cost_round*H10+U10-AW10,"") -> 0 | BE10: =IF($AX10=1,SUMPRODUCT(AY10:BD10,$AY$6:$BD$6),"") -> 103.32752 | BF10: =IF(AND($AX10=1,Res_b>0),(AK10-BE10)/Res_b,"") -> 0.90909091 | BG10: =IF(AC10>=Goal_b-0.000000001,AK10-Beta_y*Goal_b,"") -> 126.05479 | BH10: =IF(AC10>=Goal_b-0.000000001,IF(AND(AL10>=Goal_S-0.000000001,BG10>=Goal_P-0.000000001),1,0),0) -> 0
A11: 3 | B11: 5, 6 | C11: =MOD(INT($A11/32),2) -> 0 | D11: =MOD(INT($A11/16),2) -> 0 | E11: =MOD(INT($A11/8),2) -> 0 | F11: =MOD(INT($A11/4),2) -> 0 | G11: =MOD(INT($A11/2),2) -> 1 | H11: =MOD(INT($A11/1),2) -> 1 | I11: =SUM(C11:H11) -> 2 | J11: =E_zero+C11*Half_gap*(Ceiling_e-E_zero) -> 71 | K11: =J11+D11*Half_gap*(Ceiling_e-J11) -> 71 | L11: =K11+E11*Half_gap*(Ceiling_e-K11) -> 71 | M11: =L11+F11*Half_gap*(Ceiling_e-L11) -> 71 | N11: =M11+G11*Half_gap*(Ceiling_e-M11) -> 78 | O11: =N11+H11*Half_gap*(Ceiling_e-N11) -> 81.5 | P11: =Val_pt*(J11-E_zero) -> 0 | Q11: =Val_pt*(K11-E_zero) -> 0 | R11: =Val_pt*(L11-E_zero) -> 0 | S11: =Val_pt*(M11-E_zero) -> 0 | T11: =Val_pt*(N11-E_zero) -> 70 | U11: =Val_pt*(O11-E_zero) -> 105 | V11: =MAX(W11+Cost_round*C11-P11,IF(C11=1,Pre_q,0)) -> 535 | W11: =MAX(X11+Cost_round*D11-Q11,IF(D11=1,Pre_q,0),Floor_q) -> 535 | X11: =MAX(Y11+Cost_round*E11-R11,IF(E11=1,Pre_q,0),Floor_q) -> 535 | Y11: =MAX(Z11+Cost_round*F11-S11,IF(F11=1,Pre_q,0),Floor_q) -> 535 | Z11: =MAX(AA11+Cost_round*G11-T11,IF(G11=1,Pre_q,0),Floor_q) -> 535 | AA11: =MAX(AB11+Cost_round*H11-U11,IF(H11=1,Pre_q,0),Floor_q) -> 485 | AB11: =End_q -> 470 | AC11: =Q_zero-V11 -> 85 | AD11: =IF(AC11>=-0.000000001,1,0) -> 1 | AE11: =IF($AD11=1,Q_zero-Cost_round*C11+P11-W11,"") -> 85 | AF11: =IF($AD11=1,W11-Cost_round*D11+Q11-X11,"") -> 0 | AG11: =IF($AD11=1,X11-Cost_round*E11+R11-Y11,"") -> 0 | AH11: =IF($AD11=1,Y11-Cost_round*F11+S11-Z11,"") -> 0 | AI11: =IF($AD11=1,Z11-Cost_round*G11+T11-AA11,"") -> 0 | AJ11: =IF($AD11=1,AA11-Cost_round*H11+U11-AB11,"") -> 0 | AK11: =IF($AD11=1,SUMPRODUCT(AE11:AJ11,$AE$6:$AJ$6),"") -> 77.272727 | AL11: =U11 -> 105 | AM11: =IF(SUMPRODUCT(($AK$8:$AK$71>=AK11-0.000000001)*($AL$8:$AL$71>=AL11-0.000000001)*((($AK$8:$AK$71>AK11+0.000000001)+($AL$8:$AL$71>AL11+0.000000001))>0))>0,1,0) -> 1 | AN11: =1-AM11 -> 0 | AO11: =AK11+W_board*AL11 -> 669.97035 | AP11: =AK11+W_try*AL11 -> 1127.2727 | AQ11: =MAX(AR11+Cost_round*C11-P11,IF(C11=1,Pre_q+Res_b,0)) -> 585 | AR11: =MAX(AS11+Cost_round*D11-Q11,IF(D11=1,Pre_q+Res_b,0),Floor_q+Res_b) -> 585 | AS11: =MAX(AT11+Cost_round*E11-R11,IF(E11=1,Pre_q+Res_b,0),Floor_q+Res_b) -> 585 | AT11: =MAX(AU11+Cost_round*F11-S11,IF(F11=1,Pre_q+Res_b,0),Floor_q+Res_b) -> 585 | AU11: =MAX(AV11+Cost_round*G11-T11,IF(G11=1,Pre_q+Res_b,0),Floor_q+Res_b) -> 585 | AV11: =MAX(AW11+Cost_round*H11-U11,IF(H11=1,Pre_q+Res_b,0),Floor_q+Res_b) -> 535 | AW11: =End_q+Res_b -> 520 | AX11: =IF(Q_zero>=AQ11-0.000000001,1,0) -> 1 | AY11: =IF($AX11=1,Q_zero-Cost_round*C11+P11-AR11,"") -> 35 | AZ11: =IF($AX11=1,AR11-Cost_round*D11+Q11-AS11,"") -> 0 | BA11: =IF($AX11=1,AS11-Cost_round*E11+R11-AT11,"") -> 0 | BB11: =IF($AX11=1,AT11-Cost_round*F11+S11-AU11,"") -> 0 | BC11: =IF($AX11=1,AU11-Cost_round*G11+T11-AV11,"") -> 0 | BD11: =IF($AX11=1,AV11-Cost_round*H11+U11-AW11,"") -> 0 | BE11: =IF($AX11=1,SUMPRODUCT(AY11:BD11,$AY$6:$BD$6),"") -> 31.818182 | BF11: =IF(AND($AX11=1,Res_b>0),(AK11-BE11)/Res_b,"") -> 0.90909091 | BG11: =IF(AC11>=Goal_b-0.000000001,AK11-Beta_y*Goal_b,"") -> 54.545455 | BH11: =IF(AC11>=Goal_b-0.000000001,IF(AND(AL11>=Goal_S-0.000000001,BG11>=Goal_P-0.000000001),1,0),0) -> 0
A12: 4 | B12: 4 | C12: =MOD(INT($A12/32),2) -> 0 | D12: =MOD(INT($A12/16),2) -> 0 | E12: =MOD(INT($A12/8),2) -> 0 | F12: =MOD(INT($A12/4),2) -> 1 | G12: =MOD(INT($A12/2),2) -> 0 | H12: =MOD(INT($A12/1),2) -> 0 | I12: =SUM(C12:H12) -> 1 | J12: =E_zero+C12*Half_gap*(Ceiling_e-E_zero) -> 71 | K12: =J12+D12*Half_gap*(Ceiling_e-J12) -> 71 | L12: =K12+E12*Half_gap*(Ceiling_e-K12) -> 71 | M12: =L12+F12*Half_gap*(Ceiling_e-L12) -> 78 | N12: =M12+G12*Half_gap*(Ceiling_e-M12) -> 78 | O12: =N12+H12*Half_gap*(Ceiling_e-N12) -> 78 | P12: =Val_pt*(J12-E_zero) -> 0 | Q12: =Val_pt*(K12-E_zero) -> 0 | R12: =Val_pt*(L12-E_zero) -> 0 | S12: =Val_pt*(M12-E_zero) -> 70 | T12: =Val_pt*(N12-E_zero) -> 70 | U12: =Val_pt*(O12-E_zero) -> 70 | V12: =MAX(W12+Cost_round*C12-P12,IF(C12=1,Pre_q,0)) -> 470 | W12: =MAX(X12+Cost_round*D12-Q12,IF(D12=1,Pre_q,0),Floor_q) -> 470 | X12: =MAX(Y12+Cost_round*E12-R12,IF(E12=1,Pre_q,0),Floor_q) -> 470 | Y12: =MAX(Z12+Cost_round*F12-S12,IF(F12=1,Pre_q,0),Floor_q) -> 470 | Z12: =MAX(AA12+Cost_round*G12-T12,IF(G12=1,Pre_q,0),Floor_q) -> 350 | AA12: =MAX(AB12+Cost_round*H12-U12,IF(H12=1,Pre_q,0),Floor_q) -> 400 | AB12: =End_q -> 470 | AC12: =Q_zero-V12 -> 150 | AD12: =IF(AC12>=-0.000000001,1,0) -> 1 | AE12: =IF($AD12=1,Q_zero-Cost_round*C12+P12-W12,"") -> 150 | AF12: =IF($AD12=1,W12-Cost_round*D12+Q12-X12,"") -> 0 | AG12: =IF($AD12=1,X12-Cost_round*E12+R12-Y12,"") -> 0 | AH12: =IF($AD12=1,Y12-Cost_round*F12+S12-Z12,"") -> 70 | AI12: =IF($AD12=1,Z12-Cost_round*G12+T12-AA12,"") -> 20 | AJ12: =IF($AD12=1,AA12-Cost_round*H12+U12-AB12,"") -> 0 | AK12: =IF($AD12=1,SUMPRODUCT(AE12:AJ12,$AE$6:$AJ$6),"") -> 196.593 | AL12: =U12 -> 70 | AM12: =IF(SUMPRODUCT(($AK$8:$AK$71>=AK12-0.000000001)*($AL$8:$AL$71>=AL12-0.000000001)*((($AK$8:$AK$71>AK12+0.000000001)+($AL$8:$AL$71>AL12+0.000000001))>0))>0,1,0) -> 1 | AN12: =1-AM12 -> 0 | AO12: =AK12+W_board*AL12 -> 591.72476 | AP12: =AK12+W_try*AL12 -> 896.593 | AQ12: =MAX(AR12+Cost_round*C12-P12,IF(C12=1,Pre_q+Res_b,0)) -> 520 | AR12: =MAX(AS12+Cost_round*D12-Q12,IF(D12=1,Pre_q+Res_b,0),Floor_q+Res_b) -> 520 | AS12: =MAX(AT12+Cost_round*E12-R12,IF(E12=1,Pre_q+Res_b,0),Floor_q+Res_b) -> 520 | AT12: =MAX(AU12+Cost_round*F12-S12,IF(F12=1,Pre_q+Res_b,0),Floor_q+Res_b) -> 520 | AU12: =MAX(AV12+Cost_round*G12-T12,IF(G12=1,Pre_q+Res_b,0),Floor_q+Res_b) -> 400 | AV12: =MAX(AW12+Cost_round*H12-U12,IF(H12=1,Pre_q+Res_b,0),Floor_q+Res_b) -> 450 | AW12: =End_q+Res_b -> 520 | AX12: =IF(Q_zero>=AQ12-0.000000001,1,0) -> 1 | AY12: =IF($AX12=1,Q_zero-Cost_round*C12+P12-AR12,"") -> 100 | AZ12: =IF($AX12=1,AR12-Cost_round*D12+Q12-AS12,"") -> 0 | BA12: =IF($AX12=1,AS12-Cost_round*E12+R12-AT12,"") -> 0 | BB12: =IF($AX12=1,AT12-Cost_round*F12+S12-AU12,"") -> 70 | BC12: =IF($AX12=1,AU12-Cost_round*G12+T12-AV12,"") -> 20 | BD12: =IF($AX12=1,AV12-Cost_round*H12+U12-AW12,"") -> 0 | BE12: =IF($AX12=1,SUMPRODUCT(AY12:BD12,$AY$6:$BD$6),"") -> 151.13846 | BF12: =IF(AND($AX12=1,Res_b>0),(AK12-BE12)/Res_b,"") -> 0.90909091 | BG12: =IF(AC12>=Goal_b-0.000000001,AK12-Beta_y*Goal_b,"") -> 173.86573 | BH12: =IF(AC12>=Goal_b-0.000000001,IF(AND(AL12>=Goal_S-0.000000001,BG12>=Goal_P-0.000000001),1,0),0) -> 0
A13: 5 | B13: 4, 6 | C13: =MOD(INT($A13/32),2) -> 0 | D13: =MOD(INT($A13/16),2) -> 0 | E13: =MOD(INT($A13/8),2) -> 0 | F13: =MOD(INT($A13/4),2) -> 1 | G13: =MOD(INT($A13/2),2) -> 0 | H13: =MOD(INT($A13/1),2) -> 1 | I13: =SUM(C13:H13) -> 2 | J13: =E_zero+C13*Half_gap*(Ceiling_e-E_zero) -> 71 | K13: =J13+D13*Half_gap*(Ceiling_e-J13) -> 71 | L13: =K13+E13*Half_gap*(Ceiling_e-K13) -> 71 | M13: =L13+F13*Half_gap*(Ceiling_e-L13) -> 78 | N13: =M13+G13*Half_gap*(Ceiling_e-M13) -> 78 | O13: =N13+H13*Half_gap*(Ceiling_e-N13) -> 81.5 | P13: =Val_pt*(J13-E_zero) -> 0 | Q13: =Val_pt*(K13-E_zero) -> 0 | R13: =Val_pt*(L13-E_zero) -> 0 | S13: =Val_pt*(M13-E_zero) -> 70 | T13: =Val_pt*(N13-E_zero) -> 70 | U13: =Val_pt*(O13-E_zero) -> 105 | V13: =MAX(W13+Cost_round*C13-P13,IF(C13=1,Pre_q,0)) -> 470 | W13: =MAX(X13+Cost_round*D13-Q13,IF(D13=1,Pre_q,0),Floor_q) -> 470 | X13: =MAX(Y13+Cost_round*E13-R13,IF(E13=1,Pre_q,0),Floor_q) -> 470 | Y13: =MAX(Z13+Cost_round*F13-S13,IF(F13=1,Pre_q,0),Floor_q) -> 470 | Z13: =MAX(AA13+Cost_round*G13-T13,IF(G13=1,Pre_q,0),Floor_q) -> 415 | AA13: =MAX(AB13+Cost_round*H13-U13,IF(H13=1,Pre_q,0),Floor_q) -> 485 | AB13: =End_q -> 470 | AC13: =Q_zero-V13 -> 150 | AD13: =IF(AC13>=-0.000000001,1,0) -> 1 | AE13: =IF($AD13=1,Q_zero-Cost_round*C13+P13-W13,"") -> 150 | AF13: =IF($AD13=1,W13-Cost_round*D13+Q13-X13,"") -> 0 | AG13: =IF($AD13=1,X13-Cost_round*E13+R13-Y13,"") -> 0 | AH13: =IF($AD13=1,Y13-Cost_round*F13+S13-Z13,"") -> 5 | AI13: =IF($AD13=1,Z13-Cost_round*G13+T13-AA13,"") -> 0 | AJ13: =IF($AD13=1,AA13-Cost_round*H13+U13-AB13,"") -> 0 | AK13: =IF($AD13=1,SUMPRODUCT(AE13:AJ13,$AE$6:$AJ$6),"") -> 139.7787 | AL13: =U13 -> 105 | AM13: =IF(SUMPRODUCT(($AK$8:$AK$71>=AK13-0.000000001)*($AL$8:$AL$71>=AL13-0.000000001)*((($AK$8:$AK$71>AK13+0.000000001)+($AL$8:$AL$71>AL13+0.000000001))>0))>0,1,0) -> 1 | AN13: =1-AM13 -> 0 | AO13: =AK13+W_board*AL13 -> 732.47633 | AP13: =AK13+W_try*AL13 -> 1189.7787 | AQ13: =MAX(AR13+Cost_round*C13-P13,IF(C13=1,Pre_q+Res_b,0)) -> 520 | AR13: =MAX(AS13+Cost_round*D13-Q13,IF(D13=1,Pre_q+Res_b,0),Floor_q+Res_b) -> 520 | AS13: =MAX(AT13+Cost_round*E13-R13,IF(E13=1,Pre_q+Res_b,0),Floor_q+Res_b) -> 520 | AT13: =MAX(AU13+Cost_round*F13-S13,IF(F13=1,Pre_q+Res_b,0),Floor_q+Res_b) -> 520 | AU13: =MAX(AV13+Cost_round*G13-T13,IF(G13=1,Pre_q+Res_b,0),Floor_q+Res_b) -> 465 | AV13: =MAX(AW13+Cost_round*H13-U13,IF(H13=1,Pre_q+Res_b,0),Floor_q+Res_b) -> 535 | AW13: =End_q+Res_b -> 520 | AX13: =IF(Q_zero>=AQ13-0.000000001,1,0) -> 1 | AY13: =IF($AX13=1,Q_zero-Cost_round*C13+P13-AR13,"") -> 100 | AZ13: =IF($AX13=1,AR13-Cost_round*D13+Q13-AS13,"") -> 0 | BA13: =IF($AX13=1,AS13-Cost_round*E13+R13-AT13,"") -> 0 | BB13: =IF($AX13=1,AT13-Cost_round*F13+S13-AU13,"") -> 5 | BC13: =IF($AX13=1,AU13-Cost_round*G13+T13-AV13,"") -> 0 | BD13: =IF($AX13=1,AV13-Cost_round*H13+U13-AW13,"") -> 0 | BE13: =IF($AX13=1,SUMPRODUCT(AY13:BD13,$AY$6:$BD$6),"") -> 94.324158 | BF13: =IF(AND($AX13=1,Res_b>0),(AK13-BE13)/Res_b,"") -> 0.90909091 | BG13: =IF(AC13>=Goal_b-0.000000001,AK13-Beta_y*Goal_b,"") -> 117.05143 | BH13: =IF(AC13>=Goal_b-0.000000001,IF(AND(AL13>=Goal_S-0.000000001,BG13>=Goal_P-0.000000001),1,0),0) -> 0
A14: 6 | B14: 4, 5 | C14: =MOD(INT($A14/32),2) -> 0 | D14: =MOD(INT($A14/16),2) -> 0 | E14: =MOD(INT($A14/8),2) -> 0 | F14: =MOD(INT($A14/4),2) -> 1 | G14: =MOD(INT($A14/2),2) -> 1 | H14: =MOD(INT($A14/1),2) -> 0 | I14: =SUM(C14:H14) -> 2 | J14: =E_zero+C14*Half_gap*(Ceiling_e-E_zero) -> 71 | K14: =J14+D14*Half_gap*(Ceiling_e-J14) -> 71 | L14: =K14+E14*Half_gap*(Ceiling_e-K14) -> 71 | M14: =L14+F14*Half_gap*(Ceiling_e-L14) -> 78 | N14: =M14+G14*Half_gap*(Ceiling_e-M14) -> 81.5 | O14: =N14+H14*Half_gap*(Ceiling_e-N14) -> 81.5 | P14: =Val_pt*(J14-E_zero) -> 0 | Q14: =Val_pt*(K14-E_zero) -> 0 | R14: =Val_pt*(L14-E_zero) -> 0 | S14: =Val_pt*(M14-E_zero) -> 70 | T14: =Val_pt*(N14-E_zero) -> 105 | U14: =Val_pt*(O14-E_zero) -> 105 | V14: =MAX(W14+Cost_round*C14-P14,IF(C14=1,Pre_q,0)) -> 520 | W14: =MAX(X14+Cost_round*D14-Q14,IF(D14=1,Pre_q,0),Floor_q) -> 520 | X14: =MAX(Y14+Cost_round*E14-R14,IF(E14=1,Pre_q,0),Floor_q) -> 520 | Y14: =MAX(Z14+Cost_round*F14-S14,IF(F14=1,Pre_q,0),Floor_q) -> 520 | Z14: =MAX(AA14+Cost_round*G14-T14,IF(G14=1,Pre_q,0),Floor_q) -> 470 | AA14: =MAX(AB14+Cost_round*H14-U14,IF(H14=1,Pre_q,0),Floor_q) -> 365 | AB14: =End_q -> 470 | AC14: =Q_zero-V14 -> 100 | AD14: =IF(AC14>=-0.000000001,1,0) -> 1 | AE14: =IF($AD14=1,Q_zero-Cost_round*C14+P14-W14,"") -> 100 | AF14: =IF($AD14=1,W14-Cost_round*D14+Q14-X14,"") -> 0 | AG14: =IF($AD14=1,X14-Cost_round*E14+R14-Y14,"") -> 0 | AH14: =IF($AD14=1,Y14-Cost_round*F14+S14-Z14,"") -> 0 | AI14: =IF($AD14=1,Z14-Cost_round*G14+T14-AA14,"") -> 90 | AJ14: =IF($AD14=1,AA14-Cost_round*H14+U14-AB14,"") -> 0 | AK14: =IF($AD14=1,SUMPRODUCT(AE14:AJ14,$AE$6:$AJ$6),"") -> 146.79201 | AL14: =U14 -> 105 | AM14: =IF(SUMPRODUCT(($AK$8:$AK$71>=AK14-0.000000001)*($AL$8:$AL$71>=AL14-0.000000001)*((($AK$8:$AK$71>AK14+0.000000001)+($AL$8:$AL$71>AL14+0.000000001))>0))>0,1,0) -> 1 | AN14: =1-AM14 -> 0 | AO14: =AK14+W_board*AL14 -> 739.48964 | AP14: =AK14+W_try*AL14 -> 1196.792 | AQ14: =MAX(AR14+Cost_round*C14-P14,IF(C14=1,Pre_q+Res_b,0)) -> 570 | AR14: =MAX(AS14+Cost_round*D14-Q14,IF(D14=1,Pre_q+Res_b,0),Floor_q+Res_b) -> 570 | AS14: =MAX(AT14+Cost_round*E14-R14,IF(E14=1,Pre_q+Res_b,0),Floor_q+Res_b) -> 570 | AT14: =MAX(AU14+Cost_round*F14-S14,IF(F14=1,Pre_q+Res_b,0),Floor_q+Res_b) -> 570 | AU14: =MAX(AV14+Cost_round*G14-T14,IF(G14=1,Pre_q+Res_b,0),Floor_q+Res_b) -> 520 | AV14: =MAX(AW14+Cost_round*H14-U14,IF(H14=1,Pre_q+Res_b,0),Floor_q+Res_b) -> 415 | AW14: =End_q+Res_b -> 520 | AX14: =IF(Q_zero>=AQ14-0.000000001,1,0) -> 1 | AY14: =IF($AX14=1,Q_zero-Cost_round*C14+P14-AR14,"") -> 50 | AZ14: =IF($AX14=1,AR14-Cost_round*D14+Q14-AS14,"") -> 0 | BA14: =IF($AX14=1,AS14-Cost_round*E14+R14-AT14,"") -> 0 | BB14: =IF($AX14=1,AT14-Cost_round*F14+S14-AU14,"") -> 0 | BC14: =IF($AX14=1,AU14-Cost_round*G14+T14-AV14,"") -> 90 | BD14: =IF($AX14=1,AV14-Cost_round*H14+U14-AW14,"") -> 0 | BE14: =IF($AX14=1,SUMPRODUCT(AY14:BD14,$AY$6:$BD$6),"") -> 101.33746 | BF14: =IF(AND($AX14=1,Res_b>0),(AK14-BE14)/Res_b,"") -> 0.90909091 | BG14: =IF(AC14>=Goal_b-0.000000001,AK14-Beta_y*Goal_b,"") -> 124.06474 | BH14: =IF(AC14>=Goal_b-0.000000001,IF(AND(AL14>=Goal_S-0.000000001,BG14>=Goal_P-0.000000001),1,0),0) -> 0
A15: 7 | B15: 4–6 | C15: =MOD(INT($A15/32),2) -> 0 | D15: =MOD(INT($A15/16),2) -> 0 | E15: =MOD(INT($A15/8),2) -> 0 | F15: =MOD(INT($A15/4),2) -> 1 | G15: =MOD(INT($A15/2),2) -> 1 | H15: =MOD(INT($A15/1),2) -> 1 | I15: =SUM(C15:H15) -> 3 | J15: =E_zero+C15*Half_gap*(Ceiling_e-E_zero) -> 71 | K15: =J15+D15*Half_gap*(Ceiling_e-J15) -> 71 | L15: =K15+E15*Half_gap*(Ceiling_e-K15) -> 71 | M15: =L15+F15*Half_gap*(Ceiling_e-L15) -> 78 | N15: =M15+G15*Half_gap*(Ceiling_e-M15) -> 81.5 | O15: =N15+H15*Half_gap*(Ceiling_e-N15) -> 83.25 | P15: =Val_pt*(J15-E_zero) -> 0 | Q15: =Val_pt*(K15-E_zero) -> 0 | R15: =Val_pt*(L15-E_zero) -> 0 | S15: =Val_pt*(M15-E_zero) -> 70 | T15: =Val_pt*(N15-E_zero) -> 105 | U15: =Val_pt*(O15-E_zero) -> 122.5 | V15: =MAX(W15+Cost_round*C15-P15,IF(C15=1,Pre_q,0)) -> 535 | W15: =MAX(X15+Cost_round*D15-Q15,IF(D15=1,Pre_q,0),Floor_q) -> 535 | X15: =MAX(Y15+Cost_round*E15-R15,IF(E15=1,Pre_q,0),Floor_q) -> 535 | Y15: =MAX(Z15+Cost_round*F15-S15,IF(F15=1,Pre_q,0),Floor_q) -> 535 | Z15: =MAX(AA15+Cost_round*G15-T15,IF(G15=1,Pre_q,0),Floor_q) -> 485 | AA15: =MAX(AB15+Cost_round*H15-U15,IF(H15=1,Pre_q,0),Floor_q) -> 470 | AB15: =End_q -> 470 | AC15: =Q_zero-V15 -> 85 | AD15: =IF(AC15>=-0.000000001,1,0) -> 1 | AE15: =IF($AD15=1,Q_zero-Cost_round*C15+P15-W15,"") -> 85 | AF15: =IF($AD15=1,W15-Cost_round*D15+Q15-X15,"") -> 0 | AG15: =IF($AD15=1,X15-Cost_round*E15+R15-Y15,"") -> 0 | AH15: =IF($AD15=1,Y15-Cost_round*F15+S15-Z15,"") -> 0 | AI15: =IF($AD15=1,Z15-Cost_round*G15+T15-AA15,"") -> 0 | AJ15: =IF($AD15=1,AA15-Cost_round*H15+U15-AB15,"") -> 2.5 | AK15: =IF($AD15=1,SUMPRODUCT(AE15:AJ15,$AE$6:$AJ$6),"") -> 78.683912 | AL15: =U15 -> 122.5 | AM15: =IF(SUMPRODUCT(($AK$8:$AK$71>=AK15-0.000000001)*($AL$8:$AL$71>=AL15-0.000000001)*((($AK$8:$AK$71>AK15+0.000000001)+($AL$8:$AL$71>AL15+0.000000001))>0))>0,1,0) -> 1 | AN15: =1-AM15 -> 0 | AO15: =AK15+W_board*AL15 -> 770.16448 | AP15: =AK15+W_try*AL15 -> 1303.6839 | AQ15: =MAX(AR15+Cost_round*C15-P15,IF(C15=1,Pre_q+Res_b,0)) -> 585 | AR15: =MAX(AS15+Cost_round*D15-Q15,IF(D15=1,Pre_q+Res_b,0),Floor_q+Res_b) -> 585 | AS15: =MAX(AT15+Cost_round*E15-R15,IF(E15=1,Pre_q+Res_b,0),Floor_q+Res_b) -> 585 | AT15: =MAX(AU15+Cost_round*F15-S15,IF(F15=1,Pre_q+Res_b,0),Floor_q+Res_b) -> 585 | AU15: =MAX(AV15+Cost_round*G15-T15,IF(G15=1,Pre_q+Res_b,0),Floor_q+Res_b) -> 535 | AV15: =MAX(AW15+Cost_round*H15-U15,IF(H15=1,Pre_q+Res_b,0),Floor_q+Res_b) -> 520 | AW15: =End_q+Res_b -> 520 | AX15: =IF(Q_zero>=AQ15-0.000000001,1,0) -> 1 | AY15: =IF($AX15=1,Q_zero-Cost_round*C15+P15-AR15,"") -> 35 | AZ15: =IF($AX15=1,AR15-Cost_round*D15+Q15-AS15,"") -> 0 | BA15: =IF($AX15=1,AS15-Cost_round*E15+R15-AT15,"") -> 0 | BB15: =IF($AX15=1,AT15-Cost_round*F15+S15-AU15,"") -> 0 | BC15: =IF($AX15=1,AU15-Cost_round*G15+T15-AV15,"") -> 0 | BD15: =IF($AX15=1,AV15-Cost_round*H15+U15-AW15,"") -> 2.5 | BE15: =IF($AX15=1,SUMPRODUCT(AY15:BD15,$AY$6:$BD$6),"") -> 33.229367 | BF15: =IF(AND($AX15=1,Res_b>0),(AK15-BE15)/Res_b,"") -> 0.90909091 | BG15: =IF(AC15>=Goal_b-0.000000001,AK15-Beta_y*Goal_b,"") -> 55.956639 | BH15: =IF(AC15>=Goal_b-0.000000001,IF(AND(AL15>=Goal_S-0.000000001,BG15>=Goal_P-0.000000001),1,0),0) -> 0
A16: 8 | B16: 3 | C16: =MOD(INT($A16/32),2) -> 0 | D16: =MOD(INT($A16/16),2) -> 0 | E16: =MOD(INT($A16/8),2) -> 1 | F16: =MOD(INT($A16/4),2) -> 0 | G16: =MOD(INT($A16/2),2) -> 0 | H16: =MOD(INT($A16/1),2) -> 0 | I16: =SUM(C16:H16) -> 1 | J16: =E_zero+C16*Half_gap*(Ceiling_e-E_zero) -> 71 | K16: =J16+D16*Half_gap*(Ceiling_e-J16) -> 71 | L16: =K16+E16*Half_gap*(Ceiling_e-K16) -> 78 | M16: =L16+F16*Half_gap*(Ceiling_e-L16) -> 78 | N16: =M16+G16*Half_gap*(Ceiling_e-M16) -> 78 | O16: =N16+H16*Half_gap*(Ceiling_e-N16) -> 78 | P16: =Val_pt*(J16-E_zero) -> 0 | Q16: =Val_pt*(K16-E_zero) -> 0 | R16: =Val_pt*(L16-E_zero) -> 70 | S16: =Val_pt*(M16-E_zero) -> 70 | T16: =Val_pt*(N16-E_zero) -> 70 | U16: =Val_pt*(O16-E_zero) -> 70 | V16: =MAX(W16+Cost_round*C16-P16,IF(C16=1,Pre_q,0)) -> 470 | W16: =MAX(X16+Cost_round*D16-Q16,IF(D16=1,Pre_q,0),Floor_q) -> 470 | X16: =MAX(Y16+Cost_round*E16-R16,IF(E16=1,Pre_q,0),Floor_q) -> 470 | Y16: =MAX(Z16+Cost_round*F16-S16,IF(F16=1,Pre_q,0),Floor_q) -> 350 | Z16: =MAX(AA16+Cost_round*G16-T16,IF(G16=1,Pre_q,0),Floor_q) -> 350 | AA16: =MAX(AB16+Cost_round*H16-U16,IF(H16=1,Pre_q,0),Floor_q) -> 400 | AB16: =End_q -> 470 | AC16: =Q_zero-V16 -> 150 | AD16: =IF(AC16>=-0.000000001,1,0) -> 1 | AE16: =IF($AD16=1,Q_zero-Cost_round*C16+P16-W16,"") -> 150 | AF16: =IF($AD16=1,W16-Cost_round*D16+Q16-X16,"") -> 0 | AG16: =IF($AD16=1,X16-Cost_round*E16+R16-Y16,"") -> 70 | AH16: =IF($AD16=1,Y16-Cost_round*F16+S16-Z16,"") -> 70 | AI16: =IF($AD16=1,Z16-Cost_round*G16+T16-AA16,"") -> 20 | AJ16: =IF($AD16=1,AA16-Cost_round*H16+U16-AB16,"") -> 0 | AK16: =IF($AD16=1,SUMPRODUCT(AE16:AJ16,$AE$6:$AJ$6),"") -> 249.18504 | AL16: =U16 -> 70 | AM16: =IF(SUMPRODUCT(($AK$8:$AK$71>=AK16-0.000000001)*($AL$8:$AL$71>=AL16-0.000000001)*((($AK$8:$AK$71>AK16+0.000000001)+($AL$8:$AL$71>AL16+0.000000001))>0))>0,1,0) -> 1 | AN16: =1-AM16 -> 0 | AO16: =AK16+W_board*AL16 -> 644.31679 | AP16: =AK16+W_try*AL16 -> 949.18504 | AQ16: =MAX(AR16+Cost_round*C16-P16,IF(C16=1,Pre_q+Res_b,0)) -> 520 | AR16: =MAX(AS16+Cost_round*D16-Q16,IF(D16=1,Pre_q+Res_b,0),Floor_q+Res_b) -> 520 | AS16: =MAX(AT16+Cost_round*E16-R16,IF(E16=1,Pre_q+Res_b,0),Floor_q+Res_b) -> 520 | AT16: =MAX(AU16+Cost_round*F16-S16,IF(F16=1,Pre_q+Res_b,0),Floor_q+Res_b) -> 400 | AU16: =MAX(AV16+Cost_round*G16-T16,IF(G16=1,Pre_q+Res_b,0),Floor_q+Res_b) -> 400 | AV16: =MAX(AW16+Cost_round*H16-U16,IF(H16=1,Pre_q+Res_b,0),Floor_q+Res_b) -> 450 | AW16: =End_q+Res_b -> 520 | AX16: =IF(Q_zero>=AQ16-0.000000001,1,0) -> 1 | AY16: =IF($AX16=1,Q_zero-Cost_round*C16+P16-AR16,"") -> 100 | AZ16: =IF($AX16=1,AR16-Cost_round*D16+Q16-AS16,"") -> 0 | BA16: =IF($AX16=1,AS16-Cost_round*E16+R16-AT16,"") -> 70 | BB16: =IF($AX16=1,AT16-Cost_round*F16+S16-AU16,"") -> 70 | BC16: =IF($AX16=1,AU16-Cost_round*G16+T16-AV16,"") -> 20 | BD16: =IF($AX16=1,AV16-Cost_round*H16+U16-AW16,"") -> 0 | BE16: =IF($AX16=1,SUMPRODUCT(AY16:BD16,$AY$6:$BD$6),"") -> 203.7305 | BF16: =IF(AND($AX16=1,Res_b>0),(AK16-BE16)/Res_b,"") -> 0.90909091 | BG16: =IF(AC16>=Goal_b-0.000000001,AK16-Beta_y*Goal_b,"") -> 226.45777 | BH16: =IF(AC16>=Goal_b-0.000000001,IF(AND(AL16>=Goal_S-0.000000001,BG16>=Goal_P-0.000000001),1,0),0) -> 0
A17: 9 | B17: 3, 6 | C17: =MOD(INT($A17/32),2) -> 0 | D17: =MOD(INT($A17/16),2) -> 0 | E17: =MOD(INT($A17/8),2) -> 1 | F17: =MOD(INT($A17/4),2) -> 0 | G17: =MOD(INT($A17/2),2) -> 0 | H17: =MOD(INT($A17/1),2) -> 1 | I17: =SUM(C17:H17) -> 2 | J17: =E_zero+C17*Half_gap*(Ceiling_e-E_zero) -> 71 | K17: =J17+D17*Half_gap*(Ceiling_e-J17) -> 71 | L17: =K17+E17*Half_gap*(Ceiling_e-K17) -> 78 | M17: =L17+F17*Half_gap*(Ceiling_e-L17) -> 78 | N17: =M17+G17*Half_gap*(Ceiling_e-M17) -> 78 | O17: =N17+H17*Half_gap*(Ceiling_e-N17) -> 81.5 | P17: =Val_pt*(J17-E_zero) -> 0 | Q17: =Val_pt*(K17-E_zero) -> 0 | R17: =Val_pt*(L17-E_zero) -> 70 | S17: =Val_pt*(M17-E_zero) -> 70 | T17: =Val_pt*(N17-E_zero) -> 70 | U17: =Val_pt*(O17-E_zero) -> 105 | V17: =MAX(W17+Cost_round*C17-P17,IF(C17=1,Pre_q,0)) -> 470 | W17: =MAX(X17+Cost_round*D17-Q17,IF(D17=1,Pre_q,0),Floor_q) -> 470 | X17: =MAX(Y17+Cost_round*E17-R17,IF(E17=1,Pre_q,0),Floor_q) -> 470 | Y17: =MAX(Z17+Cost_round*F17-S17,IF(F17=1,Pre_q,0),Floor_q) -> 350 | Z17: =MAX(AA17+Cost_round*G17-T17,IF(G17=1,Pre_q,0),Floor_q) -> 415 | AA17: =MAX(AB17+Cost_round*H17-U17,IF(H17=1,Pre_q,0),Floor_q) -> 485 | AB17: =End_q -> 470 | AC17: =Q_zero-V17 -> 150 | AD17: =IF(AC17>=-0.000000001,1,0) -> 1 | AE17: =IF($AD17=1,Q_zero-Cost_round*C17+P17-W17,"") -> 150 | AF17: =IF($AD17=1,W17-Cost_round*D17+Q17-X17,"") -> 0 | AG17: =IF($AD17=1,X17-Cost_round*E17+R17-Y17,"") -> 70 | AH17: =IF($AD17=1,Y17-Cost_round*F17+S17-Z17,"") -> 5 | AI17: =IF($AD17=1,Z17-Cost_round*G17+T17-AA17,"") -> 0 | AJ17: =IF($AD17=1,AA17-Cost_round*H17+U17-AB17,"") -> 0 | AK17: =IF($AD17=1,SUMPRODUCT(AE17:AJ17,$AE$6:$AJ$6),"") -> 192.37074 | AL17: =U17 -> 105 | AM17: =IF(SUMPRODUCT(($AK$8:$AK$71>=AK17-0.000000001)*($AL$8:$AL$71>=AL17-0.000000001)*((($AK$8:$AK$71>AK17+0.000000001)+($AL$8:$AL$71>AL17+0.000000001))>0))>0,1,0) -> 1 | AN17: =1-AM17 -> 0 | AO17: =AK17+W_board*AL17 -> 785.06837 | AP17: =AK17+W_try*AL17 -> 1242.3707 | AQ17: =MAX(AR17+Cost_round*C17-P17,IF(C17=1,Pre_q+Res_b,0)) -> 520 | AR17: =MAX(AS17+Cost_round*D17-Q17,IF(D17=1,Pre_q+Res_b,0),Floor_q+Res_b) -> 520 | AS17: =MAX(AT17+Cost_round*E17-R17,IF(E17=1,Pre_q+Res_b,0),Floor_q+Res_b) -> 520 | AT17: =MAX(AU17+Cost_round*F17-S17,IF(F17=1,Pre_q+Res_b,0),Floor_q+Res_b) -> 400 | AU17: =MAX(AV17+Cost_round*G17-T17,IF(G17=1,Pre_q+Res_b,0),Floor_q+Res_b) -> 465 | AV17: =MAX(AW17+Cost_round*H17-U17,IF(H17=1,Pre_q+Res_b,0),Floor_q+Res_b) -> 535 | AW17: =End_q+Res_b -> 520 | AX17: =IF(Q_zero>=AQ17-0.000000001,1,0) -> 1 | AY17: =IF($AX17=1,Q_zero-Cost_round*C17+P17-AR17,"") -> 100 | AZ17: =IF($AX17=1,AR17-Cost_round*D17+Q17-AS17,"") -> 0 | BA17: =IF($AX17=1,AS17-Cost_round*E17+R17-AT17,"") -> 70 | BB17: =IF($AX17=1,AT17-Cost_round*F17+S17-AU17,"") -> 5 | BC17: =IF($AX17=1,AU17-Cost_round*G17+T17-AV17,"") -> 0 | BD17: =IF($AX17=1,AV17-Cost_round*H17+U17-AW17,"") -> 0 | BE17: =IF($AX17=1,SUMPRODUCT(AY17:BD17,$AY$6:$BD$6),"") -> 146.91619 | BF17: =IF(AND($AX17=1,Res_b>0),(AK17-BE17)/Res_b,"") -> 0.90909091 | BG17: =IF(AC17>=Goal_b-0.000000001,AK17-Beta_y*Goal_b,"") -> 169.64347 | BH17: =IF(AC17>=Goal_b-0.000000001,IF(AND(AL17>=Goal_S-0.000000001,BG17>=Goal_P-0.000000001),1,0),0) -> 0
A18: 10 | B18: 3, 5 | C18: =MOD(INT($A18/32),2) -> 0 | D18: =MOD(INT($A18/16),2) -> 0 | E18: =MOD(INT($A18/8),2) -> 1 | F18: =MOD(INT($A18/4),2) -> 0 | G18: =MOD(INT($A18/2),2) -> 1 | H18: =MOD(INT($A18/1),2) -> 0 | I18: =SUM(C18:H18) -> 2 | J18: =E_zero+C18*Half_gap*(Ceiling_e-E_zero) -> 71 | K18: =J18+D18*Half_gap*(Ceiling_e-J18) -> 71 | L18: =K18+E18*Half_gap*(Ceiling_e-K18) -> 78 | M18: =L18+F18*Half_gap*(Ceiling_e-L18) -> 78 | N18: =M18+G18*Half_gap*(Ceiling_e-M18) -> 81.5 | O18: =N18+H18*Half_gap*(Ceiling_e-N18) -> 81.5 | P18: =Val_pt*(J18-E_zero) -> 0 | Q18: =Val_pt*(K18-E_zero) -> 0 | R18: =Val_pt*(L18-E_zero) -> 70 | S18: =Val_pt*(M18-E_zero) -> 70 | T18: =Val_pt*(N18-E_zero) -> 105 | U18: =Val_pt*(O18-E_zero) -> 105 | V18: =MAX(W18+Cost_round*C18-P18,IF(C18=1,Pre_q,0)) -> 470 | W18: =MAX(X18+Cost_round*D18-Q18,IF(D18=1,Pre_q,0),Floor_q) -> 470 | X18: =MAX(Y18+Cost_round*E18-R18,IF(E18=1,Pre_q,0),Floor_q) -> 470 | Y18: =MAX(Z18+Cost_round*F18-S18,IF(F18=1,Pre_q,0),Floor_q) -> 400 | Z18: =MAX(AA18+Cost_round*G18-T18,IF(G18=1,Pre_q,0),Floor_q) -> 470 | AA18: =MAX(AB18+Cost_round*H18-U18,IF(H18=1,Pre_q,0),Floor_q) -> 365 | AB18: =End_q -> 470 | AC18: =Q_zero-V18 -> 150 | AD18: =IF(AC18>=-0.000000001,1,0) -> 1 | AE18: =IF($AD18=1,Q_zero-Cost_round*C18+P18-W18,"") -> 150 | AF18: =IF($AD18=1,W18-Cost_round*D18+Q18-X18,"") -> 0 | AG18: =IF($AD18=1,X18-Cost_round*E18+R18-Y18,"") -> 20 | AH18: =IF($AD18=1,Y18-Cost_round*F18+S18-Z18,"") -> 0 | AI18: =IF($AD18=1,Z18-Cost_round*G18+T18-AA18,"") -> 90 | AJ18: =IF($AD18=1,AA18-Cost_round*H18+U18-AB18,"") -> 0 | AK18: =IF($AD18=1,SUMPRODUCT(AE18:AJ18,$AE$6:$AJ$6),"") -> 207.27285 | AL18: =U18 -> 105 | AM18: =IF(SUMPRODUCT(($AK$8:$AK$71>=AK18-0.000000001)*($AL$8:$AL$71>=AL18-0.000000001)*((($AK$8:$AK$71>AK18+0.000000001)+($AL$8:$AL$71>AL18+0.000000001))>0))>0,1,0) -> 1 | AN18: =1-AM18 -> 0 | AO18: =AK18+W_board*AL18 -> 799.97048 | AP18: =AK18+W_try*AL18 -> 1257.2729 | AQ18: =MAX(AR18+Cost_round*C18-P18,IF(C18=1,Pre_q+Res_b,0)) -> 520 | AR18: =MAX(AS18+Cost_round*D18-Q18,IF(D18=1,Pre_q+Res_b,0),Floor_q+Res_b) -> 520 | AS18: =MAX(AT18+Cost_round*E18-R18,IF(E18=1,Pre_q+Res_b,0),Floor_q+Res_b) -> 520 | AT18: =MAX(AU18+Cost_round*F18-S18,IF(F18=1,Pre_q+Res_b,0),Floor_q+Res_b) -> 450 | AU18: =MAX(AV18+Cost_round*G18-T18,IF(G18=1,Pre_q+Res_b,0),Floor_q+Res_b) -> 520 | AV18: =MAX(AW18+Cost_round*H18-U18,IF(H18=1,Pre_q+Res_b,0),Floor_q+Res_b) -> 415 | AW18: =End_q+Res_b -> 520 | AX18: =IF(Q_zero>=AQ18-0.000000001,1,0) -> 1 | AY18: =IF($AX18=1,Q_zero-Cost_round*C18+P18-AR18,"") -> 100 | AZ18: =IF($AX18=1,AR18-Cost_round*D18+Q18-AS18,"") -> 0 | BA18: =IF($AX18=1,AS18-Cost_round*E18+R18-AT18,"") -> 20 | BB18: =IF($AX18=1,AT18-Cost_round*F18+S18-AU18,"") -> 0 | BC18: =IF($AX18=1,AU18-Cost_round*G18+T18-AV18,"") -> 90 | BD18: =IF($AX18=1,AV18-Cost_round*H18+U18-AW18,"") -> 0 | BE18: =IF($AX18=1,SUMPRODUCT(AY18:BD18,$AY$6:$BD$6),"") -> 161.81831 | BF18: =IF(AND($AX18=1,Res_b>0),(AK18-BE18)/Res_b,"") -> 0.90909091 | BG18: =IF(AC18>=Goal_b-0.000000001,AK18-Beta_y*Goal_b,"") -> 184.54558 | BH18: =IF(AC18>=Goal_b-0.000000001,IF(AND(AL18>=Goal_S-0.000000001,BG18>=Goal_P-0.000000001),1,0),0) -> 0
A19: 11 | B19: 3, 5, 6 | C19: =MOD(INT($A19/32),2) -> 0 | D19: =MOD(INT($A19/16),2) -> 0 | E19: =MOD(INT($A19/8),2) -> 1 | F19: =MOD(INT($A19/4),2) -> 0 | G19: =MOD(INT($A19/2),2) -> 1 | H19: =MOD(INT($A19/1),2) -> 1 | I19: =SUM(C19:H19) -> 3 | J19: =E_zero+C19*Half_gap*(Ceiling_e-E_zero) -> 71 | K19: =J19+D19*Half_gap*(Ceiling_e-J19) -> 71 | L19: =K19+E19*Half_gap*(Ceiling_e-K19) -> 78 | M19: =L19+F19*Half_gap*(Ceiling_e-L19) -> 78 | N19: =M19+G19*Half_gap*(Ceiling_e-M19) -> 81.5 | O19: =N19+H19*Half_gap*(Ceiling_e-N19) -> 83.25 | P19: =Val_pt*(J19-E_zero) -> 0 | Q19: =Val_pt*(K19-E_zero) -> 0 | R19: =Val_pt*(L19-E_zero) -> 70 | S19: =Val_pt*(M19-E_zero) -> 70 | T19: =Val_pt*(N19-E_zero) -> 105 | U19: =Val_pt*(O19-E_zero) -> 122.5 | V19: =MAX(W19+Cost_round*C19-P19,IF(C19=1,Pre_q,0)) -> 470 | W19: =MAX(X19+Cost_round*D19-Q19,IF(D19=1,Pre_q,0),Floor_q) -> 470 | X19: =MAX(Y19+Cost_round*E19-R19,IF(E19=1,Pre_q,0),Floor_q) -> 470 | Y19: =MAX(Z19+Cost_round*F19-S19,IF(F19=1,Pre_q,0),Floor_q) -> 415 | Z19: =MAX(AA19+Cost_round*G19-T19,IF(G19=1,Pre_q,0),Floor_q) -> 485 | AA19: =MAX(AB19+Cost_round*H19-U19,IF(H19=1,Pre_q,0),Floor_q) -> 470 | AB19: =End_q -> 470 | AC19: =Q_zero-V19 -> 150 | AD19: =IF(AC19>=-0.000000001,1,0) -> 1 | AE19: =IF($AD19=1,Q_zero-Cost_round*C19+P19-W19,"") -> 150 | AF19: =IF($AD19=1,W19-Cost_round*D19+Q19-X19,"") -> 0 | AG19: =IF($AD19=1,X19-Cost_round*E19+R19-Y19,"") -> 5 | AH19: =IF($AD19=1,Y19-Cost_round*F19+S19-Z19,"") -> 0 | AI19: =IF($AD19=1,Z19-Cost_round*G19+T19-AA19,"") -> 0 | AJ19: =IF($AD19=1,AA19-Cost_round*H19+U19-AB19,"") -> 2.5 | AK19: =IF($AD19=1,SUMPRODUCT(AE19:AJ19,$AE$6:$AJ$6),"") -> 141.5314 | AL19: =U19 -> 122.5 | AM19: =IF(SUMPRODUCT(($AK$8:$AK$71>=AK19-0.000000001)*($AL$8:$AL$71>=AL19-0.000000001)*((($AK$8:$AK$71>AK19+0.000000001)+($AL$8:$AL$71>AL19+0.000000001))>0))>0,1,0) -> 1 | AN19: =1-AM19 -> 0 | AO19: =AK19+W_board*AL19 -> 833.01196 | AP19: =AK19+W_try*AL19 -> 1366.5314 | AQ19: =MAX(AR19+Cost_round*C19-P19,IF(C19=1,Pre_q+Res_b,0)) -> 520 | AR19: =MAX(AS19+Cost_round*D19-Q19,IF(D19=1,Pre_q+Res_b,0),Floor_q+Res_b) -> 520 | AS19: =MAX(AT19+Cost_round*E19-R19,IF(E19=1,Pre_q+Res_b,0),Floor_q+Res_b) -> 520 | AT19: =MAX(AU19+Cost_round*F19-S19,IF(F19=1,Pre_q+Res_b,0),Floor_q+Res_b) -> 465 | AU19: =MAX(AV19+Cost_round*G19-T19,IF(G19=1,Pre_q+Res_b,0),Floor_q+Res_b) -> 535 | AV19: =MAX(AW19+Cost_round*H19-U19,IF(H19=1,Pre_q+Res_b,0),Floor_q+Res_b) -> 520 | AW19: =End_q+Res_b -> 520 | AX19: =IF(Q_zero>=AQ19-0.000000001,1,0) -> 1 | AY19: =IF($AX19=1,Q_zero-Cost_round*C19+P19-AR19,"") -> 100 | AZ19: =IF($AX19=1,AR19-Cost_round*D19+Q19-AS19,"") -> 0 | BA19: =IF($AX19=1,AS19-Cost_round*E19+R19-AT19,"") -> 5 | BB19: =IF($AX19=1,AT19-Cost_round*F19+S19-AU19,"") -> 0 | BC19: =IF($AX19=1,AU19-Cost_round*G19+T19-AV19,"") -> 0 | BD19: =IF($AX19=1,AV19-Cost_round*H19+U19-AW19,"") -> 2.5 | BE19: =IF($AX19=1,SUMPRODUCT(AY19:BD19,$AY$6:$BD$6),"") -> 96.07685 | BF19: =IF(AND($AX19=1,Res_b>0),(AK19-BE19)/Res_b,"") -> 0.90909091 | BG19: =IF(AC19>=Goal_b-0.000000001,AK19-Beta_y*Goal_b,"") -> 118.80412 | BH19: =IF(AC19>=Goal_b-0.000000001,IF(AND(AL19>=Goal_S-0.000000001,BG19>=Goal_P-0.000000001),1,0),0) -> 0
... A71: 63 | B71: 1–6 | C71: =MOD(INT($A71/32),2) -> 1 | D71: =MOD(INT($A71/16),2) -> 1 | E71: =MOD(INT($A71/8),2) -> 1 | F71: =MOD(INT($A71/4),2) -> 1 | G71: =MOD(INT($A71/2),2) -> 1 | H71: =MOD(INT($A71/1),2) -> 1 | I71: =SUM(C71:H71) -> 6 | J71: =E_zero+C71*Half_gap*(Ceiling_e-E_zero) -> 78 | K71: =J71+D71*Half_gap*(Ceiling_e-J71) -> 81.5 | L71: =K71+E71*Half_gap*(Ceiling_e-K71) -> 83.25 | M71: =L71+F71*Half_gap*(Ceiling_e-L71) -> 84.125 | N71: =M71+G71*Half_gap*(Ceiling_e-M71) -> 84.5625 | O71: =N71+H71*Half_gap*(Ceiling_e-N71) -> 84.78125 | P71: =Val_pt*(J71-E_zero) -> 70 | Q71: =Val_pt*(K71-E_zero) -> 105 | R71: =Val_pt*(L71-E_zero) -> 122.5 | S71: =Val_pt*(M71-E_zero) -> 131.25 | T71: =Val_pt*(N71-E_zero) -> 135.625 | U71: =Val_pt*(O71-E_zero) -> 137.8125 | V71: =MAX(W71+Cost_round*C71-P71,IF(C71=1,Pre_q,0)) -> 535 | W71: =MAX(X71+Cost_round*D71-Q71,IF(D71=1,Pre_q,0),Floor_q) -> 485 | X71: =MAX(Y71+Cost_round*E71-R71,IF(E71=1,Pre_q,0),Floor_q) -> 470 | Y71: =MAX(Z71+Cost_round*F71-S71,IF(F71=1,Pre_q,0),Floor_q) -> 470 | Z71: =MAX(AA71+Cost_round*G71-T71,IF(G71=1,Pre_q,0),Floor_q) -> 470 | AA71: =MAX(AB71+Cost_round*H71-U71,IF(H71=1,Pre_q,0),Floor_q) -> 470 | AB71: =End_q -> 470 | AC71: =Q_zero-V71 -> 85 | AD71: =IF(AC71>=-0.000000001,1,0) -> 1 | AE71: =IF($AD71=1,Q_zero-Cost_round*C71+P71-W71,"") -> 85 | AF71: =IF($AD71=1,W71-Cost_round*D71+Q71-X71,"") -> 0 | AG71: =IF($AD71=1,X71-Cost_round*E71+R71-Y71,"") -> 2.5 | AH71: =IF($AD71=1,Y71-Cost_round*F71+S71-Z71,"") -> 11.25 | AI71: =IF($AD71=1,Z71-Cost_round*G71+T71-AA71,"") -> 15.625 | AJ71: =IF($AD71=1,AA71-Cost_round*H71+U71-AB71,"") -> 17.8125 | AK71: =IF($AD71=1,SUMPRODUCT(AE71:AJ71,$AE$6:$AJ$6),"") -> 106.5915 | AL71: =U71 -> 137.8125 | AM71: =IF(SUMPRODUCT(($AK$8:$AK$71>=AK71-0.000000001)*($AL$8:$AL$71>=AL71-0.000000001)*((($AK$8:$AK$71>AK71+0.000000001)+($AL$8:$AL$71>AL71+0.000000001))>0))>0,1,0) -> 0 | AN71: =1-AM71 -> 1 | AO71: =AK71+W_board*AL71 -> 884.50714 | AP71: =AK71+W_try*AL71 -> 1484.7165 | AQ71: =MAX(AR71+Cost_round*C71-P71,IF(C71=1,Pre_q+Res_b,0)) -> 585 | AR71: =MAX(AS71+Cost_round*D71-Q71,IF(D71=1,Pre_q+Res_b,0),Floor_q+Res_b) -> 535 | AS71: =MAX(AT71+Cost_round*E71-R71,IF(E71=1,Pre_q+Res_b,0),Floor_q+Res_b) -> 520 | AT71: =MAX(AU71+Cost_round*F71-S71,IF(F71=1,Pre_q+Res_b,0),Floor_q+Res_b) -> 520 | AU71: =MAX(AV71+Cost_round*G71-T71,IF(G71=1,Pre_q+Res_b,0),Floor_q+Res_b) -> 520 | AV71: =MAX(AW71+Cost_round*H71-U71,IF(H71=1,Pre_q+Res_b,0),Floor_q+Res_b) -> 520 | AW71: =End_q+Res_b -> 520 | AX71: =IF(Q_zero>=AQ71-0.000000001,1,0) -> 1 | AY71: =IF($AX71=1,Q_zero-Cost_round*C71+P71-AR71,"") -> 35 | AZ71: =IF($AX71=1,AR71-Cost_round*D71+Q71-AS71,"") -> 0 | BA71: =IF($AX71=1,AS71-Cost_round*E71+R71-AT71,"") -> 2.5 | BB71: =IF($AX71=1,AT71-Cost_round*F71+S71-AU71,"") -> 11.25 | BC71: =IF($AX71=1,AU71-Cost_round*G71+T71-AV71,"") -> 15.625 | BD71: =IF($AX71=1,AV71-Cost_round*H71+U71-AW71,"") -> 17.8125 | BE71: =IF($AX71=1,SUMPRODUCT(AY71:BD71,$AY$6:$BD$6),"") -> 61.136958 | BF71: =IF(AND($AX71=1,Res_b>0),(AK71-BE71)/Res_b,"") -> 0.90909091 | BG71: =IF(AC71>=Goal_b-0.000000001,AK71-Beta_y*Goal_b,"") -> 83.86423 | BH71: =IF(AC71>=Goal_b-0.000000001,IF(AND(AL71>=Goal_S-0.000000001,BG71>=Goal_P-0.000000001),1,0),0) -> 0

Sheet Frontier
A1: The frontier first: dominated and efficient schedules, their prices, and the board's weighted sum (Theorems 12.1 and 12.2; Worked Example 12.1, Steps 2-3; Figure 12.1; AXIOM Lab 2.12, steps 1-2)
A2: No reserve. A schedule is dominated when another pays at least as much and saves at least as much, and more of one. Savings depend only on the number of rounds, so only the best schedule with each number can be efficient.
A4: Schedules that keep every commitment, no reserve | B4: =SUM(Sch_feas) -> 64 | C4: All 64 (Step 2)
A5: Dominated | B5: =SUM(Sch_dom) -> 59 | C5: 59
A6: Efficient | B6: =COUNTIFS(Sch_dom,0,Sch_feas,1) -> 5 | C6: Five: the best with two to six rounds
A8: Rounds n | B8: Best payouts (PV) | C8: Its schedule # | D8: Rounds (years) | E8: Savings, year 6 | F8: Efficient? | G8: Board value | H8: p1 | I8: p2 | J8: p3 | K8: p4 | L8: p5 | M8: p6
A9: 0 | B9: =_xlfn.MAXIFS(Sch_P0,Sch_n,A9) -> 136.36364 | C9: =_xlfn.MINIFS(Sch_idx,Sch_n,A9,Sch_P0,">="&(B9-0.000000001)) -> 0 | D9: =INDEX(Sch_label,C9+1) -> none | E9: =INDEX(Sch_S6,C9+1) -> 0 | F9: =IF(INDEX(Sch_dom,C9+1)=1,"dominated","efficient") -> dominated | G9: =B9+W_board*E9 -> 136.36364 | H9: =INDEX(Sch_p1,$C9+1) -> 150 | I9: =INDEX(Sch_p2,$C9+1) -> 0 | J9: =INDEX(Sch_p3,$C9+1) -> 0 | K9: =INDEX(Sch_p4,$C9+1) -> 0 | L9: =INDEX(Sch_p5,$C9+1) -> 0 | M9: =INDEX(Sch_p6,$C9+1) -> 0
A10: 1 | B10: =_xlfn.MAXIFS(Sch_P0,Sch_n,A10) -> 370.67264 | C10: =_xlfn.MINIFS(Sch_idx,Sch_n,A10,Sch_P0,">="&(B10-0.000000001)) -> 32 | D10: =INDEX(Sch_label,C10+1) -> 1 | E10: =INDEX(Sch_S6,C10+1) -> 70 | F10: =IF(INDEX(Sch_dom,C10+1)=1,"dominated","efficient") -> dominated | G10: =B10+W_board*E10 -> 765.8044 | H10: =INDEX(Sch_p1,$C10+1) -> 220 | I10: =INDEX(Sch_p2,$C10+1) -> 70 | J10: =INDEX(Sch_p3,$C10+1) -> 70 | K10: =INDEX(Sch_p4,$C10+1) -> 70 | L10: =INDEX(Sch_p5,$C10+1) -> 20 | M10: =INDEX(Sch_p6,$C10+1) -> 0
A11: 2 | B11: =_xlfn.MAXIFS(Sch_P0,Sch_n,A11) -> 384.17334 | C11: =_xlfn.MINIFS(Sch_idx,Sch_n,A11,Sch_P0,">="&(B11-0.000000001)) -> 48 | D11: =INDEX(Sch_label,C11+1) -> 1, 2 | E11: =INDEX(Sch_S6,C11+1) -> 105 | F11: =IF(INDEX(Sch_dom,C11+1)=1,"dominated","efficient") -> efficient | G11: =B11+W_board*E11 -> 976.87096 | H11: =INDEX(Sch_p1,$C11+1) -> 100 | I11: =INDEX(Sch_p2,$C11+1) -> 105 | J11: =INDEX(Sch_p3,$C11+1) -> 105 | K11: =INDEX(Sch_p4,$C11+1) -> 105 | L11: =INDEX(Sch_p5,$C11+1) -> 90 | M11: =INDEX(Sch_p6,$C11+1) -> 0
A12: 3 | B12: =_xlfn.MAXIFS(Sch_P0,Sch_n,A12) -> 330.45199 | C12: =_xlfn.MINIFS(Sch_idx,Sch_n,A12,Sch_P0,">="&(B12-0.000000001)) -> 56 | D12: =INDEX(Sch_label,C12+1) -> 1–3 | E12: =INDEX(Sch_S6,C12+1) -> 122.5 | F12: =IF(INDEX(Sch_dom,C12+1)=1,"dominated","efficient") -> efficient | G12: =B12+W_board*E12 -> 1021.9325 | H12: =INDEX(Sch_p1,$C12+1) -> 85 | I12: =INDEX(Sch_p2,$C12+1) -> 0 | J12: =INDEX(Sch_p3,$C12+1) -> 122.5 | K12: =INDEX(Sch_p4,$C12+1) -> 122.5 | L12: =INDEX(Sch_p5,$C12+1) -> 122.5 | M12: =INDEX(Sch_p6,$C12+1) -> 2.5
A13: 4 | B13: =_xlfn.MAXIFS(Sch_P0,Sch_n,A13) -> 260.88057 | C13: =_xlfn.MINIFS(Sch_idx,Sch_n,A13,Sch_P0,">="&(B13-0.000000001)) -> 57 | D13: =INDEX(Sch_label,C13+1) -> 1–3, 6 | E13: =INDEX(Sch_S6,C13+1) -> 131.25 | F13: =IF(INDEX(Sch_dom,C13+1)=1,"dominated","efficient") -> efficient | G13: =B13+W_board*E13 -> 1001.7526 | H13: =INDEX(Sch_p1,$C13+1) -> 85 | I13: =INDEX(Sch_p2,$C13+1) -> 0 | J13: =INDEX(Sch_p3,$C13+1) -> 122.5 | K13: =INDEX(Sch_p4,$C13+1) -> 122.5 | L13: =INDEX(Sch_p5,$C13+1) -> 2.5 | M13: =INDEX(Sch_p6,$C13+1) -> 11.25
A14: 5 | B14: =_xlfn.MAXIFS(Sch_P0,Sch_n,A14) -> 186.82159 | C14: =_xlfn.MINIFS(Sch_idx,Sch_n,A14,Sch_P0,">="&(B14-0.000000001)) -> 59 | D14: =INDEX(Sch_label,C14+1) -> 1–3, 5, 6 | E14: =INDEX(Sch_S6,C14+1) -> 135.625 | F14: =IF(INDEX(Sch_dom,C14+1)=1,"dominated","efficient") -> efficient | G14: =B14+W_board*E14 -> 952.38936 | H14: =INDEX(Sch_p1,$C14+1) -> 85 | I14: =INDEX(Sch_p2,$C14+1) -> 0 | J14: =INDEX(Sch_p3,$C14+1) -> 122.5 | K14: =INDEX(Sch_p4,$C14+1) -> 2.5 | L14: =INDEX(Sch_p5,$C14+1) -> 11.25 | M14: =INDEX(Sch_p6,$C14+1) -> 15.625
A15: 6 | B15: =_xlfn.MAXIFS(Sch_P0,Sch_n,A15) -> 106.5915 | C15: =_xlfn.MINIFS(Sch_idx,Sch_n,A15,Sch_P0,">="&(B15-0.000000001)) -> 63 | D15: =INDEX(Sch_label,C15+1) -> 1–6 | E15: =INDEX(Sch_S6,C15+1) -> 137.8125 | F15: =IF(INDEX(Sch_dom,C15+1)=1,"dominated","efficient") -> efficient | G15: =B15+W_board*E15 -> 884.50714 | H15: =INDEX(Sch_p1,$C15+1) -> 85 | I15: =INDEX(Sch_p2,$C15+1) -> 0 | J15: =INDEX(Sch_p3,$C15+1) -> 2.5 | K15: =INDEX(Sch_p4,$C15+1) -> 11.25 | L15: =INDEX(Sch_p5,$C15+1) -> 15.625 | M15: =INDEX(Sch_p6,$C15+1) -> 17.8125
A17: Three rounds: year-end cash, years 1 to 6 | H17: =Q_zero-Cost_round*INDEX(Sch_z1,$C$12+1)+INDEX(Sch_s1,$C$12+1)-H12 -> 485 | I17: =H17-Cost_round*INDEX(Sch_z2,$C$12+1)+INDEX(Sch_s2,$C$12+1)-I12 -> 470 | J17: =I17-Cost_round*INDEX(Sch_z3,$C$12+1)+INDEX(Sch_s3,$C$12+1)-J12 -> 350 | K17: =J17-Cost_round*INDEX(Sch_z4,$C$12+1)+INDEX(Sch_s4,$C$12+1)-K12 -> 350 | L17: =K17-Cost_round*INDEX(Sch_z5,$C$12+1)+INDEX(Sch_s5,$C$12+1)-L12 -> 350 | M17: =L17-Cost_round*INDEX(Sch_z6,$C$12+1)+INDEX(Sch_S6,$C$12+1)-M12 -> 470
A18: Three rounds: paid out in all | B18: =SUM(H12:M12) -> 455 | C18: $455 million (Worked Example 12.1)
A19: One round is dominated by two (1 = yes) | B19: =IF(AND(B11>=B10,E11>=E10,OR(B11>B10,E11>E10)),1,0) -> 1 | C19: Two rounds pay more and save more
A21: From (rounds) | B21: To (rounds) | C21: Payouts given up | D21: Savings gained, a year | E21: Price: payouts per dollar a year
A22: 2 | B22: 3 | C22: =INDEX($B$9:$B$15,A22+1)-INDEX($B$9:$B$15,B22+1) -> 53.721351 | D22: =INDEX($E$9:$E$15,B22+1)-INDEX($E$9:$E$15,A22+1) -> 17.5 | E22: =C22/D22 -> 3.0697915
A23: 3 | B23: 4 | C23: =INDEX($B$9:$B$15,A23+1)-INDEX($B$9:$B$15,B23+1) -> 69.571412 | D23: =INDEX($E$9:$E$15,B23+1)-INDEX($E$9:$E$15,A23+1) -> 8.75 | E23: =C23/D23 -> 7.9510185
A24: 4 | B24: 5 | C24: =INDEX($B$9:$B$15,A24+1)-INDEX($B$9:$B$15,B24+1) -> 74.05898 | D24: =INDEX($E$9:$E$15,B24+1)-INDEX($E$9:$E$15,A24+1) -> 4.375 | E24: =C24/D24 -> 16.927767
A25: 5 | B25: 6 | C25: =INDEX($B$9:$B$15,A25+1)-INDEX($B$9:$B$15,B25+1) -> 80.230091 | D25: =INDEX($E$9:$E$15,B25+1)-INDEX($E$9:$E$15,A25+1) -> 2.1875 | E25: =C25/D25 -> 36.676613
A26: The prices rise along the frontier (1 = yes) | B26: =IF(AND(E22<E23,E23<E24,E24<E25),1,0) -> 1 | C26: So with no reserve every efficient plan wins some weighted sum
A28: Rounds | B28: Wins a weighted sum for prices from | C28: to
A29: 2 | B29: 0 | C29: =E22 -> 3.0697915
A30: 3 | B30: =E22 -> 3.0697915 | C30: =E23 -> 7.9510185
A31: 4 | B31: =E23 -> 7.9510185 | C31: =E24 -> 16.927767
A32: 5 | B32: =E24 -> 16.927767 | C32: =E25 -> 36.676613
A33: 6 | B33: =E25 -> 36.676613 | C33: and above
A35: Chapter 5's price of savings, w | B35: =W_board -> 5.6447393 | C35: $5.645 (Section 12.2)
A36: The board's value of its best plan | B36: =MAX(Sch_board) -> 1021.9325 | C36: $1,021.93 million (Section 12.1)
A37: Its schedule # | B37: =MATCH(B36,Sch_board,0)-1 -> 56
A38: Rounds (years) | B38: =INDEX(Sch_label,B37+1) -> 1–3 | C38: Three rounds, in years 1-3
A39: Rounds | B39: =INDEX(Sch_n,B37+1) -> 3
A40: Payouts (PV) | B40: =INDEX(Sch_P0,B37+1) -> 330.45199
A41: Savings, year 6 | B41: =INDEX(Sch_S6,B37+1) -> 122.5
A43: A price to explore (Declarations) | B43: =W_try -> 10 | C43: Change it on Declarations
A44: The best weighted sum at that price | B44: =MAX(Sch_try) -> 1573.3806
A45: Rounds (years) | B45: =INDEX(Sch_label,MATCH(B44,Sch_try,0)) -> 1–3, 6 | C45: Below 3.07 two rounds; to 7.95 three; to 16.93 four; to 36.68 five; above, six
A47: Ideal point: payouts | B47: =MAX(Sch_P0) -> 384.17334 | C47: $384.17 million
A48: Ideal point: savings | B48: =MAX(Sch_S6) -> 137.8125 | C48: $137.81 million a year
...

Sheet Reserve
A1: Bound the reserve: its price, the largest reserve each schedule keeps, and where the rounds move (Theorem 12.2(iv); Worked Example 12.1, Step 4; Figure 12.2; AXIOM Lab 2.12, step 3)
A2: The reserve raises every term of the war chest by b, so the war chest rises by b in every year and only the year-1 payout falls, by b: a year-1 payout held back until the end, worth beta = $0.909 per dollar.
A4: The reserve's price, beta | B4: =Beta_y -> 0.90909091 | C4: Step 4: $0.909 of payouts for each dollar
A5: The reserve to explore (Declarations) | B5: =Res_b -> 50
A6: Schedules that keep every commitment at that reserve | B6: =SUM(Sch_feasb) -> 64
A7: Price from the war chest recomputed at that reserve: smallest | B7: =MIN(Sch_price) -> 0.90909091 | C7: Every schedule: (PV at 0 - PV at b) / b
A8: largest | B8: =MAX(Sch_price) -> 0.90909091 | C8: The same price whatever the schedule
A9: largest gap from beta | B9: =MAX(ABS(B7-B4),ABS(B8-B4)) -> 0
A11: Schedules keeping at most $85 million | B11: =COUNTIFS(Sch_bmax,">=84.5",Sch_bmax,"<=85.5") -> 16 | C11: Rounds in years 1-3, for instance
A12: Schedules keeping at most $100 million | B12: =COUNTIFS(Sch_bmax,">=99.5",Sch_bmax,"<=100.5") -> 16 | C12: Rounds in years 1 and 2 but not 3, for instance
A13: Schedules keeping up to $150 million | B13: =COUNTIFS(Sch_bmax,">=149.5",Sch_bmax,"<=150.5") -> 32 | C13: A single round in year 1, or rounds in years 1, 3 and 4, for instance
A14: Cash before a year-2 round, after a year-1 round | B14: =Q_zero-Cost_round+Val_pt*Half_gap*(Ceiling_e-E_zero) -> 570 | C14: 620 - 120 + 70 = 570 (Online Appendix 12.B.2)
A15: rounds in years 1 and 2 need a reserve of at most | B15: =B14-Pre_q -> 100 | C15: $100 million
A16: Cash before a year-3 round, after rounds in years 1 and 2 | B16: =B14-Cost_round+Val_pt*(Ceiling_e-E_zero)*(1-(1-Half_gap)^2) -> 555 | C16: 570 - 120 + 105 = 555
A17: rounds in years 1-3 need a reserve of at most | B17: =B16-Pre_q -> 85 | C17: $85 million
A18: The largest reserve any plan keeps | B18: =MAX(Sch_bmax) -> 150 | C18: $150 million
A19: Payout programs on the $1 million grid: 64 schedules x 151 reserves | B19: =COUNT(Sch_idx)*151 -> 9664 | C19: 9,664 (Section 12.4)
A20: that keep every commitment | B20: =SUMPRODUCT((Sch_bmax>=-0.000000001)*(INT(Sch_bmax+0.000000001)+1)) -> 7824 | C20: 7,824 (Online Appendix Remark 12.B.1)
A22: The trade-off surface: the most payouts with savings of at least the bound on Frontier ($122.5 million a year: three rounds) and a reserve of b
A23: Reserve b | B23: Most payouts | C23: Its schedule # | D23: Rounds (years) | E23: Rounds move (1 = yes) | F23: Fall from b - 1 | G23: Fall beyond the price
A24: 0 | B24: =IF(COUNTIFS(Sch_S6,">="&(Bound_S-0.000000001),Sch_bmax,">="&(A24-0.000000001))=0,"",_xlfn.MAXIFS(Sch_P0,Sch_S6,">="&(Bound_S-0.000000001),Sch_bmax,">="&(A24-0.000000001))-Beta_y*A24) -> 330.45199 | C24: =IF(B24="","",_xlfn.MINIFS(Sch_idx,Sch_S6,">="&(Bound_S-0.000000001),Sch_bmax,">="&(A24-0.000000001),Sch_P0,">="&(B24+Beta_y*A24-0.000000001))) -> 56 | D24: =IF(B24="","",INDEX(Sch_label,C24+1)) -> 1–3 | I24: First reserve where the rounds move | J24: =_xlfn.MINIFS($A$25:$A$174,$E$25:$E$174,1) -> 86 | K24: 86: years 1, 2, 4
A25: 1 | B25: =IF(COUNTIFS(Sch_S6,">="&(Bound_S-0.000000001),Sch_bmax,">="&(A25-0.000000001))=0,"",_xlfn.MAXIFS(Sch_P0,Sch_S6,">="&(Bound_S-0.000000001),Sch_bmax,">="&(A25-0.000000001))-Beta_y*A25) -> 329.54289 | C25: =IF(B25="","",_xlfn.MINIFS(Sch_idx,Sch_S6,">="&(Bound_S-0.000000001),Sch_bmax,">="&(A25-0.000000001),Sch_P0,">="&(B25+Beta_y*A25-0.000000001))) -> 56 | D25: =IF(B25="","",INDEX(Sch_label,C25+1)) -> 1–3 | E25: =IF(OR(B25="",B24=""),0,IF(C25<>C24,1,0)) -> 0 | F25: =IF(OR(B25="",B24=""),0,B24-B25) -> 0.90909091 | G25: =F25-Beta_y -> 2.5868196e-14 | I25: Second | J25: =_xlfn.MINIFS($A$25:$A$174,$E$25:$E$174,1,$A$25:$A$174,">"&J24) -> 101 | K25: 101: years 1, 3, 4
