Workbook

Sheet README
B1: DCT Laboratory — Vol I, Ch 10: Enterprise Capital Architecture
B2: Seed 26110 · Companion to DCT_V1_Ch10_Lab.ipynb and AXIOM Lab 1.10 (module AXIOM-10). Money in $ million.
B4: Worked Example 10.1, Keep the Engineers or Rebuild Them?, with the book's declarations, and the five steps of AXIOM Lab 1.10, Meridian's Capital Ledger.
B5: Declarations: the inputs of Worked Example 10.1, Steps 1-2 (the sale's terms are Worked Example 3.1's).
B6: CapitalVector: the ten forms of Table 10.1, the profiles of Table 10.2, Meridian's capital readings (Table 5.2), and the sale read as a conversion (lab step 1).
B7: Rent: Meridian's capability rent and Figure 10.1's three stocks, year by year (Theorem 10.3(ii); lab step 2).
B8: Rebuild: the rebuild clock quarter by quarter, at the cap and at the old maintenance budget (Theorem 10.3(iii); Figure 10.3; Worked Example 10.1, Steps 3-4).
B9: CutAndShock: a four-quarter cut of the rent and a 30 percent write-off, with their recoveries (Proposition 10.4; Online Appendix 10.B.2; lab steps 2-3).
B10: Cash: Table 10.5, a $30 million ask, and the sensitivities of Online Appendix 10.B.6 (Worked Example 10.1, Step 5).
B11: Allocation: Figure 10.2's three policies and the shadow value (Theorems 10.2(i) and 10.4; Online Appendix 10.B.3-10.B.4; lab step 4).
B12: Ledger: the conversion chain and the plug auditor on two capital records (Theorems 10.1 and 10.5(iii); Online Appendix 10.B.5; lab step 5).
B13: Every result is a formula of the declarations. Reference_Values and Checks: the notebook engine's numbers and a PASS/FAIL comparison with this workbook's formulas.
... B19: Cross-sheet link: green.

Sheet Declarations
A1: Declarations (Worked Example 10.1, Steps 1-2; the sale's terms are Worked Example 3.1's). Money in $ million; capability and technology in index points.
A3: Quantity | B3: Value | C3: Source
A4: Liquidity today ($ million) | B4: 620 | C4: Table 3.1; Worked Example 3.1
A5: Technology platform today (index) | B5: 41 | C5: Table 3.1
A6: Workforce capability with the engineering team (index) | B6: 58 | C6: Table 3.1
A7: Capability points lost if the team goes with the unit | B7: 5 | C7: Worked Example 3.1
A8: Workforce capability without the team (index) | B8: =B6-B7 -> 53 | C8: 58 - 5 = 53
A9: Floor for the digital build and the automation program | B9: 55 | C9: Worked Example 3.1; Figure 6.3
A10: Net proceeds if the team goes with the unit ($ million) | B10: 112 | C10: Worked Example 10.1
A11: Discount to keep the team ($ million) | B11: 20 | C11: Worked Example 3.1: $20 million in lower proceeds
A12: Net proceeds if Meridian keeps the team ($ million) | B12: =B10-B11 -> 92 | C12: $92 million
A13: Share of the technology position the unit takes | B13: 0.1 | C13: Worked Example 3.1
A14: Capability lost a quarter to attrition and the aging of skills, delta | B14: 0.025 | C14: Worked Example 10.1, Step 2
A15: Most hiring and training a quarter (points) | B15: 2.5 | C15: Worked Example 10.1, Step 2: the absorption cap
A16: Price of a capability point ($ million) | B16: =B11/B7 -> 4 | C16: The buyer's discount: $20 million for 5 points, also the cost of hiring and training
A17: Depreciation a year, 1 - (1 - delta)^4 | B17: =1-(1-B14)^4 -> 0.096312109 | C17: 9.6 percent, inside the 6-11 percent attrition range of Table 4.3
A18: Ceiling under the cap, cap / delta | B18: =B15/B14 -> 100 | C18: Theorem 10.3(iii): 100
A19: Rent on 58 (points a quarter), delta x 58 | B19: =B14*B6 -> 1.45 | C19: Theorem 10.3(ii): 1.45 points a quarter
A21: Capability as a capital stock, quarterly: C' = (1 - delta) C + I with 0 <= I <= cap (Equation 10.3).

Sheet CapitalVector
A1: Build the capital vector: the ten forms of Table 10.1 and Meridian's readings (AXIOM Lab 1.10, step 1)
A3: Form (Table 10.1) | B3: Symbol | C3: Content | D3: Typical carrier
A4: Financial | B4: C_F | C4: money and funding capacity | D4: treasury
A5: Human | B5: C_H | C5: skills embodied in the workforce | D5: people, functions
A6: Intellectual | B6: C_I | C6: codified knowledge and IP | D6: IP estate; data
A7: Technological | B7: C_T | C7: installed systems and platforms | D7: operations; IT
A8: Organizational | B8: C_O | C8: routines and coordination capacity | D8: the wiring itself
A9: Relational | B9: C_R | C9: external trust and commitments | D9: boundary components
A10: Strategic | B10: C_S | C10: positional advantage and options | D10: corporate center
A11: Governance | B11: C_G | C11: decision quality and legitimacy | D11: board; governance
A12: Innovation | B12: C_N | C12: pipeline of unrealized options | D12: R&D; ventures
A13: Informational | B13: C_Info | C13: decision-relevant data and models | D13: platforms; functions
A14: Forms in the capital vector (Equation 10.1) | B14: =COUNTA(A4:A13) -> 10
A16: Form (Table 10.2) | B16: Depreciation a year (typical) | C16: Build time | D16: Tradable | E16: Separable
A17: Financial | B17: about 0 | C17: immediate | D17: fully | E17: fully
A18: Human | B18: 0.10-0.25 | C18: years | D18: at the margin | E18: no
A19: Intellectual | B19: 0.05-0.20 | C19: years | D19: partly | E19: yes
A20: Technological | B20: 0.15-0.30 | C20: quarters to years | D20: in parts | E20: partly
A21: Organizational | B21: 0.03-0.10 | C21: years | D21: no | E21: no
A22: Relational | B22: 0.05-0.15, plus breach | C22: years | D22: no | E22: no
A23: Strategic | B23: tied to the regime | C23: years | D23: rarely | E23: partly
A24: Table 10.2 profiles the forms of Definitions 10.3-10.9; the other three of the ten, governance, innovation and informational capital, are treated with the same machinery, and no result depends on the length of the list (Section 10.4).
A26: Meridian's capital reading (Table 5.2) | B26: Form | C26: Today | D26: Unit | E26: Measured by | F26: Error | G26: Carrier (Tables 9.1, 10.1)
A27: x1 liquidity | B27: financial | C27: =Liq_today -> 620 | D27: $ million | E27: treasury systems | F27: +/-1% | G27: treasury (TRS)
A28: x2 net leverage (covenant 4.5x, Table 5.4) | B28: financial | C28: 3.4 | D28: net debt / EBITDA | E28: audited accounts | F28: +/-2% | G28: treasury (TRS)
A29: x3 workforce capability | B29: human | C29: =C_keep -> 58 | D29: index 0-100 | E29: skills survey | F29: +/-5 points | G29: engineering (ENG)
A30: x4 technology platform | B30: technological | C30: =Tech_today -> 41 | D30: index 0-100 | E30: architecture audit | F30: +/-4 points | G30: operations; IT
A31: none declared | B31: organizational | C31: latent | E31: no declared proxy (Section 4.5) | F31: widest | G31: the wiring itself
A33: The sale as a conversion (Theorem 10.1; Worked Example 10.1, Step 1) | B33: Today | C33: Keep the team | D33: Let it go
A34: Liquidity ($ million) | B34: =Liq_today -> 620 | C34: =Liq_today+Proc_keep -> 712 | D34: =Liq_today+Proc_leave -> 732
A35: Workforce capability | B35: =C_keep -> 58 | C35: =C_keep -> 58 | D35: =C_leave -> 53
A36: Technology platform | B36: =Tech_today -> 41 | C36: =Tech_today*(1-Tech_share) -> 36.9 | D36: =Tech_today*(1-Tech_share) -> 36.9
A37: Price of a capability point ($ million) | B37: =(D34-C34)/(C35-D35) -> 4
A38: The sale converts part of Industrial Systems' technological, human and relational capital into financial capital; the discount is a market quote for a stock that never appears on the balance sheet.

Sheet Rent
A1: Price the rent: capital is a rental (Theorem 10.3(ii); Figure 10.1; Worked Example 10.1, Step 2; AXIOM Lab 1.10, step 2)
A3: Meridian's capability | B3: Value | C3: Reading
A4: Rent on 58, points a quarter | B4: =Rent_58 -> 1.45 | C4: Holding C* needs I = delta C* every period
A5: Rent on 58, points a year | B5: =4*B4 -> 5.8
A6: Rent on 58, $ million a quarter | B6: =B4*Price_pt -> 5.8
A7: Rent on 58, $ million a year | B7: =4*B6 -> 23.2 | C7: About $23 million a year, already in the operating budget
A8: Depreciation a year | B8: =Dep_year -> 0.096312109
A10: Figure 10.1: stock | B10: Depreciation a year | C10: Target | D10: Rent a year | E10: Years to 90% at the rent | F10: Years to 90% at twice the rent | G10: Approximation (1/delta) ln 10 | H10: First whole year at 90%, at the rent | I10: First whole year at 90%, twice the rent
A11: organizational | B11: 0.05 | C11: 100 | D11: =B11*C11 -> 5 | E11: =LN((D11/B11)/((D11/B11)-0.9*C11))/LN(1/(1-B11)) -> 44.890567 | F11: =LN((2*D11/B11)/((2*D11/B11)-0.9*C11))/LN(1/(1-B11)) -> 11.655266 | G11: =LN(10)/B11 -> 46.051702 | H11: =COUNTIF(B16:B76,"<"&(0.9*C11)) -> 45 | I11: =COUNTIF(C16:C76,"<"&(0.9*C11)) -> 12
A12: human | B12: 0.1 | C12: 100 | D12: =B12*C12 -> 10 | E12: =LN((D12/B12)/((D12/B12)-0.9*C12))/LN(1/(1-B12)) -> 21.854345 | F12: =LN((2*D12/B12)/((2*D12/B12)-0.9*C12))/LN(1/(1-B12)) -> 5.6742034 | G12: =LN(10)/B12 -> 23.025851 | H12: =COUNTIF(D16:D76,"<"&(0.9*C12)) -> 22 | I12: =COUNTIF(E16:E76,"<"&(0.9*C12)) -> 6
A13: technological | B13: 0.25 | C13: 100 | D13: =B13*C13 -> 25 | E13: =LN((D13/B13)/((D13/B13)-0.9*C13))/LN(1/(1-B13)) -> 8.0039228 | F13: =LN((2*D13/B13)/((2*D13/B13)-0.9*C13))/LN(1/(1-B13)) -> 2.078117 | G13: =LN(10)/B13 -> 9.2103404 | H13: =COUNTIF(F16:F76,"<"&(0.9*C13)) -> 9 | I13: =COUNTIF(G16:G76,"<"&(0.9*C13)) -> 3
A14: Twice the rent until the target is reached, then the rent. Slow stocks are cheap to hold and slow to build; spending compresses build time only up to the absorption cap.
A15: Year | B15: Organizational at the rent | C15: Organizational, twice the rent | D15: Human at the rent | E15: Human, twice the rent | F15: Technological at the rent | G15: Technological, twice the rent
A16: 0 | B16: 0 | C16: 0 | D16: 0 | E16: 0 | F16: 0 | G16: 0
A17: 1 | B17: =(1-$B$11)*B16+$D$11 -> 5 | C17: =(1-$B$11)*C16+MIN(2*$D$11,MAX($C$11-(1-$B$11)*C16,0)) -> 10 | D17: =(1-$B$12)*D16+$D$12 -> 10 | E17: =(1-$B$12)*E16+MIN(2*$D$12,MAX($C$12-(1-$B$12)*E16,0)) -> 20 | F17: =(1-$B$13)*F16+$D$13 -> 25 | G17: =(1-$B$13)*G16+MIN(2*$D$13,MAX($C$13-(1-$B$13)*G16,0)) -> 50
A18: 2 | B18: =(1-$B$11)*B17+$D$11 -> 9.75 | C18: =(1-$B$11)*C17+MIN(2*$D$11,MAX($C$11-(1-$B$11)*C17,0)) -> 19.5 | D18: =(1-$B$12)*D17+$D$12 -> 19 | E18: =(1-$B$12)*E17+MIN(2*$D$12,MAX($C$12-(1-$B$12)*E17,0)) -> 38 | F18: =(1-$B$13)*F17+$D$13 -> 43.75 | G18: =(1-$B$13)*G17+MIN(2*$D$13,MAX($C$13-(1-$B$13)*G17,0)) -> 87.5
A19: 3 | B19: =(1-$B$11)*B18+$D$11 -> 14.2625 | C19: =(1-$B$11)*C18+MIN(2*$D$11,MAX($C$11-(1-$B$11)*C18,0)) -> 28.525 | D19: =(1-$B$12)*D18+$D$12 -> 27.1 | E19: =(1-$B$12)*E18+MIN(2*$D$12,MAX($C$12-(1-$B$12)*E18,0)) -> 54.2 | F19: =(1-$B$13)*F18+$D$13 -> 57.8125 | G19: =(1-$B$13)*G18+MIN(2*$D$13,MAX($C$13-(1-$B$13)*G18,0)) -> 100
A20: 4 | B20: =(1-$B$11)*B19+$D$11 -> 18.549375 | C20: =(1-$B$11)*C19+MIN(2*$D$11,MAX($C$11-(1-$B$11)*C19,0)) -> 37.09875 | D20: =(1-$B$12)*D19+$D$12 -> 34.39 | E20: =(1-$B$12)*E19+MIN(2*$D$12,MAX($C$12-(1-$B$12)*E19,0)) -> 68.78 | F20: =(1-$B$13)*F19+$D$13 -> 68.359375 | G20: =(1-$B$13)*G19+MIN(2*$D$13,MAX($C$13-(1-$B$13)*G19,0)) -> 100
A21: 5 | B21: =(1-$B$11)*B20+$D$11 -> 22.621906 | C21: =(1-$B$11)*C20+MIN(2*$D$11,MAX($C$11-(1-$B$11)*C20,0)) -> 45.243812 | D21: =(1-$B$12)*D20+$D$12 -> 40.951 | E21: =(1-$B$12)*E20+MIN(2*$D$12,MAX($C$12-(1-$B$12)*E20,0)) -> 81.902 | F21: =(1-$B$13)*F20+$D$13 -> 76.269531 | G21: =(1-$B$13)*G20+MIN(2*$D$13,MAX($C$13-(1-$B$13)*G20,0)) -> 100
A22: 6 | B22: =(1-$B$11)*B21+$D$11 -> 26.490811 | C22: =(1-$B$11)*C21+MIN(2*$D$11,MAX($C$11-(1-$B$11)*C21,0)) -> 52.981622 | D22: =(1-$B$12)*D21+$D$12 -> 46.8559 | E22: =(1-$B$12)*E21+MIN(2*$D$12,MAX($C$12-(1-$B$12)*E21,0)) -> 93.7118 | F22: =(1-$B$13)*F21+$D$13 -> 82.202148 | G22: =(1-$B$13)*G21+MIN(2*$D$13,MAX($C$13-(1-$B$13)*G21,0)) -> 100
A23: 7 | B23: =(1-$B$11)*B22+$D$11 -> 30.16627 | C23: =(1-$B$11)*C22+MIN(2*$D$11,MAX($C$11-(1-$B$11)*C22,0)) -> 60.332541 | D23: =(1-$B$12)*D22+$D$12 -> 52.17031 | E23: =(1-$B$12)*E22+MIN(2*$D$12,MAX($C$12-(1-$B$12)*E22,0)) -> 100 | F23: =(1-$B$13)*F22+$D$13 -> 86.651611 | G23: =(1-$B$13)*G22+MIN(2*$D$13,MAX($C$13-(1-$B$13)*G22,0)) -> 100
A24: 8 | B24: =(1-$B$11)*B23+$D$11 -> 33.657957 | C24: =(1-$B$11)*C23+MIN(2*$D$11,MAX($C$11-(1-$B$11)*C23,0)) -> 67.315914 | D24: =(1-$B$12)*D23+$D$12 -> 56.953279 | E24: =(1-$B$12)*E23+MIN(2*$D$12,MAX($C$12-(1-$B$12)*E23,0)) -> 100 | F24: =(1-$B$13)*F23+$D$13 -> 89.988708 | G24: =(1-$B$13)*G23+MIN(2*$D$13,MAX($C$13-(1-$B$13)*G23,0)) -> 100
A25: 9 | B25: =(1-$B$11)*B24+$D$11 -> 36.975059 | C25: =(1-$B$11)*C24+MIN(2*$D$11,MAX($C$11-(1-$B$11)*C24,0)) -> 73.950118 | D25: =(1-$B$12)*D24+$D$12 -> 61.257951 | E25: =(1-$B$12)*E24+MIN(2*$D$12,MAX($C$12-(1-$B$12)*E24,0)) -> 100 | F25: =(1-$B$13)*F24+$D$13 -> 92.491531 | G25: =(1-$B$13)*G24+MIN(2*$D$13,MAX($C$13-(1-$B$13)*G24,0)) -> 100
A26: 10 | B26: =(1-$B$11)*B25+$D$11 -> 40.126306 | C26: =(1-$B$11)*C25+MIN(2*$D$11,MAX($C$11-(1-$B$11)*C25,0)) -> 80.252612 | D26: =(1-$B$12)*D25+$D$12 -> 65.132156 | E26: =(1-$B$12)*E25+MIN(2*$D$12,MAX($C$12-(1-$B$12)*E25,0)) -> 100 | F26: =(1-$B$13)*F25+$D$13 -> 94.368649 | G26: =(1-$B$13)*G25+MIN(2*$D$13,MAX($C$13-(1-$B$13)*G25,0)) -> 100
A27: 11 | B27: =(1-$B$11)*B26+$D$11 -> 43.119991 | C27: =(1-$B$11)*C26+MIN(2*$D$11,MAX($C$11-(1-$B$11)*C26,0)) -> 86.239982 | D27: =(1-$B$12)*D26+$D$12 -> 68.61894 | E27: =(1-$B$12)*E26+MIN(2*$D$12,MAX($C$12-(1-$B$12)*E26,0)) -> 100 | F27: =(1-$B$13)*F26+$D$13 -> 95.776486 | G27: =(1-$B$13)*G26+MIN(2*$D$13,MAX($C$13-(1-$B$13)*G26,0)) -> 100
A28: 12 | B28: =(1-$B$11)*B27+$D$11 -> 45.963991 | C28: =(1-$B$11)*C27+MIN(2*$D$11,MAX($C$11-(1-$B$11)*C27,0)) -> 91.927982 | D28: =(1-$B$12)*D27+$D$12 -> 71.757046 | E28: =(1-$B$12)*E27+MIN(2*$D$12,MAX($C$12-(1-$B$12)*E27,0)) -> 100 | F28: =(1-$B$13)*F27+$D$13 -> 96.832365 | G28: =(1-$B$13)*G27+MIN(2*$D$13,MAX($C$13-(1-$B$13)*G27,0)) -> 100
... A76: 60 | B76: =(1-$B$11)*B75+$D$11 -> 95.39302 | C76: =(1-$B$11)*C75+MIN(2*$D$11,MAX($C$11-(1-$B$11)*C75,0)) -> 100 | D76: =(1-$B$12)*D75+$D$12 -> 99.820299 | E76: =(1-$B$12)*E75+MIN(2*$D$12,MAX($C$12-(1-$B$12)*E75,0)) -> 100 | F76: =(1-$B$13)*F75+$D$13 -> 99.999997 | G76: =(1-$B$13)*G75+MIN(2*$D$13,MAX($C$13-(1-$B$13)*G75,0)) -> 100

Sheet Rebuild
A1: Run the rebuild clock: capability after the sale, quarter by quarter (Theorem 10.3(iii); Figure 10.3; Worked Example 10.1, Steps 3-4)
A3: Quantity | B3: Value | C3: Reading
A4: Ceiling under the cap, cap / delta | B4: =Cbar -> 100 | C4: 2.5 / 0.025 = 100
A5: Fewest quarters from 53 to clear 55 | B5: =LN((Cbar-C_leave)/(Cbar-Floor_c))/LN(1/(1-Delta_q)) -> 1.7175702 | C5: ln(47/45) / ln(1/0.975) = 1.7: two quarters in practice
A6: Fewest quarters from 53 to regain 58 | B6: =LN((Cbar-C_leave)/(Cbar-C_keep))/LN(1/(1-Delta_q)) -> 4.442643 | C6: ln(47/42) / ln(1/0.975) = 4.4: five quarters
A7: Quarters below 55, rebuilding at the cap | B7: =COUNTIF($E$17:$E$97,"<"&Floor_c) -> 2 | C7: Table 10.5: 2
A8: Quarters below 58, rebuilding at the cap | B8: =COUNTIF($E$17:$E$97,"<"&(C_keep-0.000000001)) -> 5 | C8: Table 10.5: 5
A9: Capability after one quarter at the cap | B9: =E18 -> 54.175 | C9: Online Appendix 10.B.6: 54.18
A10: Capability after four quarters at the cap | B10: =E21 -> 57.526669 | C10: 57.53
A11: Old budget: quarters below 55 | B11: =COUNTIF($G$17:$G$97,"<"&Floor_c) -> 21 | C11: 21 quarters, more than five years
A12: Old budget: capability after six years | B12: =G41 -> 55.276792 | C12: 55.3
A13: Old budget: quarters to reach 57 | B13: =COUNTIF($G$17:$G$97,"<57") -> 64 | C13: 64 quarters
A14: Step 4: while capability is below 55 the digital build and the automation program are off the menu (Propositions 10.3 and 10.4). The sale removes them on the day it closes.
A16: Quarter after closing | B16: Keep: investment | C16: Keep: capability | D16: Rebuild at the cap: investment | E16: Rebuild: capability | F16: Old budget: investment | G16: Old budget: capability | H16: Closed form 58 - 5 x 0.975^k
A17: 0 | C17: =C_keep -> 58 | E17: =C_leave -> 53 | G17: =C_leave -> 53 | H17: =C_keep-Pts_lost*(1-Delta_q)^A17 -> 53
A18: 1 | B18: =Rent_58 -> 1.45 | C18: =(1-Delta_q)*C17+B18 -> 58 | D18: =MIN(Cap_q,MAX(C_keep-(1-Delta_q)*E17,0)) -> 2.5 | E18: =(1-Delta_q)*E17+D18 -> 54.175 | F18: =Rent_58 -> 1.45 | G18: =(1-Delta_q)*G17+F18 -> 53.125 | H18: =C_keep-Pts_lost*(1-Delta_q)^A18 -> 53.125
A19: 2 | B19: =Rent_58 -> 1.45 | C19: =(1-Delta_q)*C18+B19 -> 58 | D19: =MIN(Cap_q,MAX(C_keep-(1-Delta_q)*E18,0)) -> 2.5 | E19: =(1-Delta_q)*E18+D19 -> 55.320625 | F19: =Rent_58 -> 1.45 | G19: =(1-Delta_q)*G18+F19 -> 53.246875 | H19: =C_keep-Pts_lost*(1-Delta_q)^A19 -> 53.246875
A20: 3 | B20: =Rent_58 -> 1.45 | C20: =(1-Delta_q)*C19+B20 -> 58 | D20: =MIN(Cap_q,MAX(C_keep-(1-Delta_q)*E19,0)) -> 2.5 | E20: =(1-Delta_q)*E19+D20 -> 56.437609 | F20: =Rent_58 -> 1.45 | G20: =(1-Delta_q)*G19+F20 -> 53.365703 | H20: =C_keep-Pts_lost*(1-Delta_q)^A20 -> 53.365703
A21: 4 | B21: =Rent_58 -> 1.45 | C21: =(1-Delta_q)*C20+B21 -> 58 | D21: =MIN(Cap_q,MAX(C_keep-(1-Delta_q)*E20,0)) -> 2.5 | E21: =(1-Delta_q)*E20+D21 -> 57.526669 | F21: =Rent_58 -> 1.45 | G21: =(1-Delta_q)*G20+F21 -> 53.481561 | H21: =C_keep-Pts_lost*(1-Delta_q)^A21 -> 53.481561
A22: 5 | B22: =Rent_58 -> 1.45 | C22: =(1-Delta_q)*C21+B22 -> 58 | D22: =MIN(Cap_q,MAX(C_keep-(1-Delta_q)*E21,0)) -> 1.9114976 | E22: =(1-Delta_q)*E21+D22 -> 58 | F22: =Rent_58 -> 1.45 | G22: =(1-Delta_q)*G21+F22 -> 53.594522 | H22: =C_keep-Pts_lost*(1-Delta_q)^A22 -> 53.594522
A23: 6 | B23: =Rent_58 -> 1.45 | C23: =(1-Delta_q)*C22+B23 -> 58 | D23: =MIN(Cap_q,MAX(C_keep-(1-Delta_q)*E22,0)) -> 1.45 | E23: =(1-Delta_q)*E22+D23 -> 58 | F23: =Rent_58 -> 1.45 | G23: =(1-Delta_q)*G22+F23 -> 53.704658 | H23: =C_keep-Pts_lost*(1-Delta_q)^A23 -> 53.704658
A24: 7 | B24: =Rent_58 -> 1.45 | C24: =(1-Delta_q)*C23+B24 -> 58 | D24: =MIN(Cap_q,MAX(C_keep-(1-Delta_q)*E23,0)) -> 1.45 | E24: =(1-Delta_q)*E23+D24 -> 58 | F24: =Rent_58 -> 1.45 | G24: =(1-Delta_q)*G23+F24 -> 53.812042 | H24: =C_keep-Pts_lost*(1-Delta_q)^A24 -> 53.812042
A25: 8 | B25: =Rent_58 -> 1.45 | C25: =(1-Delta_q)*C24+B25 -> 58 | D25: =MIN(Cap_q,MAX(C_keep-(1-Delta_q)*E24,0)) -> 1.45 | E25: =(1-Delta_q)*E24+D25 -> 58 | F25: =Rent_58 -> 1.45 | G25: =(1-Delta_q)*G24+F25 -> 53.916741 | H25: =C_keep-Pts_lost*(1-Delta_q)^A25 -> 53.916741
A26: 9 | B26: =Rent_58 -> 1.45 | C26: =(1-Delta_q)*C25+B26 -> 58 | D26: =MIN(Cap_q,MAX(C_keep-(1-Delta_q)*E25,0)) -> 1.45 | E26: =(1-Delta_q)*E25+D26 -> 58 | F26: =Rent_58 -> 1.45 | G26: =(1-Delta_q)*G25+F26 -> 54.018822 | H26: =C_keep-Pts_lost*(1-Delta_q)^A26 -> 54.018822
A27: 10 | B27: =Rent_58 -> 1.45 | C27: =(1-Delta_q)*C26+B27 -> 58 | D27: =MIN(Cap_q,MAX(C_keep-(1-Delta_q)*E26,0)) -> 1.45 | E27: =(1-Delta_q)*E26+D27 -> 58 | F27: =Rent_58 -> 1.45 | G27: =(1-Delta_q)*G26+F27 -> 54.118352 | H27: =C_keep-Pts_lost*(1-Delta_q)^A27 -> 54.118352
A28: 11 | B28: =Rent_58 -> 1.45 | C28: =(1-Delta_q)*C27+B28 -> 58 | D28: =MIN(Cap_q,MAX(C_keep-(1-Delta_q)*E27,0)) -> 1.45 | E28: =(1-Delta_q)*E27+D28 -> 58 | F28: =Rent_58 -> 1.45 | G28: =(1-Delta_q)*G27+F28 -> 54.215393 | H28: =C_keep-Pts_lost*(1-Delta_q)^A28 -> 54.215393
A29: 12 | B29: =Rent_58 -> 1.45 | C29: =(1-Delta_q)*C28+B29 -> 58 | D29: =MIN(Cap_q,MAX(C_keep-(1-Delta_q)*E28,0)) -> 1.45 | E29: =(1-Delta_q)*E28+D29 -> 58 | F29: =Rent_58 -> 1.45 | G29: =(1-Delta_q)*G28+F29 -> 54.310008 | H29: =C_keep-Pts_lost*(1-Delta_q)^A29 -> 54.310008
... A97: 80 | B97: =Rent_58 -> 1.45 | C97: =(1-Delta_q)*C96+B97 -> 58 | D97: =MIN(Cap_q,MAX(C_keep-(1-Delta_q)*E96,0)) -> 1.45 | E97: =(1-Delta_q)*E96+D97 -> 58 | F97: =Rent_58 -> 1.45 | G97: =(1-Delta_q)*G96+F97 -> 57.340311 | H97: =C_keep-Pts_lost*(1-Delta_q)^A97 -> 57.340311

Sheet CutAndShock
A1: Cut the rent for four quarters; destroy 30 percent in one (Proposition 10.4; Section 11.8; Online Appendix 10.B.2; AXIOM Lab 1.10, steps 2-3)
A3: Quantity | B3: Value | C3: Reading
A4: Quarters of the cut (no hiring or training) | B4: 4 | C4: AXIOM Lab 1.10, step 2
A5: Share of capability destroyed in one quarter | B5: 0.3 | C5: AXIOM Lab 1.10, step 3
A6: Quarter in which capability first falls below 55 | B6: =SUMPRODUCT(($A$28:$A$128<=B4)*($C$28:$C$128>=Floor_c)) -> 3 | C6: Section 11.8: below the floor within three quarters
A7: Capability at the end of the cut | B7: =INDEX($C$28:$C$128,B4+1) -> 52.413898
A8: The cut's saving ($ million) | B8: =B4*Rent_58*Price_pt -> 23.2 | C8: the year's rent, about $23 million
A9: Old budget after the cut: quarters to clear 55 | B9: =1+SUMPRODUCT(($A$28:$A$128>B4)*($E$28:$E$128<Floor_c)) -> 25 | C9: and it never regains 58
A10: At the cap after the cut: quarters to clear 55 | B10: =1+SUMPRODUCT(($A$28:$A$128>B4)*($C$28:$C$128<Floor_c)) -> 3
A11: At the cap after the cut: quarters to regain 58 | B11: =1+SUMPRODUCT(($A$28:$A$128>B4)*($C$28:$C$128<(C_keep-0.000000001))) -> 5
A12: Investment at the cap over those quarters (points) | B12: =SUMPRODUCT(($A$28:$A$128>B4)*($A$28:$A$128<=B4+B11)*$B$28:$B$128) -> 12.42791
A13: The rent over the same quarters (points) | B13: =Rent_58*B11 -> 7.25
A14: Extra cost of rebuilding at the cap ($ million) | B14: =(B12-B13)*Price_pt -> 20.711639 | C14: the repurchase liability of the cut
A16: Capability after the write-off | B16: =C_keep*(1-B5) -> 40.6 | C16: 58 x 0.7 = 40.6
A17: At the cap: quarters to clear 55 | B17: =COUNTIF($G$28:$G$128,"<"&Floor_c) -> 11
A18: At the cap: quarters to regain 58 | B18: =COUNTIF($G$28:$G$128,"<"&(C_keep-0.000000001)) -> 14 | C18: one quarter to destroy, fourteen to rebuild
A19: Theorem 10.3(iii): fewest quarters back to 58 | B19: =LN((Cbar-B16)/(Cbar-C_keep))/LN(1/(1-Delta_q)) -> 13.690941
A20: Old budget: quarters to clear 55 | B20: =COUNTIF($I$28:$I$128,"<"&Floor_c) -> 70 | C20: and it never regains 58
A22: Repurchase: write-off below the floor, w (points) | B22: 2 | C22: Online Appendix 10.B.2
A23: Repurchase: the floor, c | B23: =Floor_c -> 55
A24: Repurchase period, exact: ln((Cbar - c + w)/(Cbar - c)) / ln(1/(1 - delta)) | B24: =LN((Cbar-B23+B22)/(Cbar-B23))/LN(1/(1-Delta_q)) -> 1.7175702 | C24: 1.72 quarters
A25: Repurchase period, approximation: w / (delta (Cbar - c)) | B25: =B22/(Delta_q*(Cbar-B23)) -> 1.7777778 | C25: 1.78 quarters
A27: Quarter | B27: Cut, then the cap: investment | C27: Capability | D27: Cut, then the old budget: investment | E27: Capability | F27: Write-off, then the cap: investment | G27: Capability | H27: Write-off, then the old budget: investment | I27: Capability
A28: 0 | C28: =C_keep -> 58 | E28: =C_keep -> 58 | G28: =$B$16 -> 40.6 | I28: =$B$16 -> 40.6
A29: 1 | B29: =IF(A29<=$B$4,0,MIN(Cap_q,MAX(C_keep-(1-Delta_q)*C28,0))) -> 0 | C29: =(1-Delta_q)*C28+B29 -> 56.55 | D29: =IF(A29<=$B$4,0,Rent_58) -> 0 | E29: =(1-Delta_q)*E28+D29 -> 56.55 | F29: =MIN(Cap_q,MAX(C_keep-(1-Delta_q)*G28,0)) -> 2.5 | G29: =(1-Delta_q)*G28+F29 -> 42.085 | H29: =Rent_58 -> 1.45 | I29: =(1-Delta_q)*I28+H29 -> 41.035
A30: 2 | B30: =IF(A30<=$B$4,0,MIN(Cap_q,MAX(C_keep-(1-Delta_q)*C29,0))) -> 0 | C30: =(1-Delta_q)*C29+B30 -> 55.13625 | D30: =IF(A30<=$B$4,0,Rent_58) -> 0 | E30: =(1-Delta_q)*E29+D30 -> 55.13625 | F30: =MIN(Cap_q,MAX(C_keep-(1-Delta_q)*G29,0)) -> 2.5 | G30: =(1-Delta_q)*G29+F30 -> 43.532875 | H30: =Rent_58 -> 1.45 | I30: =(1-Delta_q)*I29+H30 -> 41.459125
A31: 3 | B31: =IF(A31<=$B$4,0,MIN(Cap_q,MAX(C_keep-(1-Delta_q)*C30,0))) -> 0 | C31: =(1-Delta_q)*C30+B31 -> 53.757844 | D31: =IF(A31<=$B$4,0,Rent_58) -> 0 | E31: =(1-Delta_q)*E30+D31 -> 53.757844 | F31: =MIN(Cap_q,MAX(C_keep-(1-Delta_q)*G30,0)) -> 2.5 | G31: =(1-Delta_q)*G30+F31 -> 44.944553 | H31: =Rent_58 -> 1.45 | I31: =(1-Delta_q)*I30+H31 -> 41.872647
A32: 4 | B32: =IF(A32<=$B$4,0,MIN(Cap_q,MAX(C_keep-(1-Delta_q)*C31,0))) -> 0 | C32: =(1-Delta_q)*C31+B32 -> 52.413898 | D32: =IF(A32<=$B$4,0,Rent_58) -> 0 | E32: =(1-Delta_q)*E31+D32 -> 52.413898 | F32: =MIN(Cap_q,MAX(C_keep-(1-Delta_q)*G31,0)) -> 2.5 | G32: =(1-Delta_q)*G31+F32 -> 46.320939 | H32: =Rent_58 -> 1.45 | I32: =(1-Delta_q)*I31+H32 -> 42.275831
A33: 5 | B33: =IF(A33<=$B$4,0,MIN(Cap_q,MAX(C_keep-(1-Delta_q)*C32,0))) -> 2.5 | C33: =(1-Delta_q)*C32+B33 -> 53.60355 | D33: =IF(A33<=$B$4,0,Rent_58) -> 1.45 | E33: =(1-Delta_q)*E32+D33 -> 52.55355 | F33: =MIN(Cap_q,MAX(C_keep-(1-Delta_q)*G32,0)) -> 2.5 | G33: =(1-Delta_q)*G32+F33 -> 47.662916 | H33: =Rent_58 -> 1.45 | I33: =(1-Delta_q)*I32+H33 -> 42.668935
A34: 6 | B34: =IF(A34<=$B$4,0,MIN(Cap_q,MAX(C_keep-(1-Delta_q)*C33,0))) -> 2.5 | C34: =(1-Delta_q)*C33+B34 -> 54.763461 | D34: =IF(A34<=$B$4,0,Rent_58) -> 1.45 | E34: =(1-Delta_q)*E33+D34 -> 52.689711 | F34: =MIN(Cap_q,MAX(C_keep-(1-Delta_q)*G33,0)) -> 2.5 | G34: =(1-Delta_q)*G33+F34 -> 48.971343 | H34: =Rent_58 -> 1.45 | I34: =(1-Delta_q)*I33+H34 -> 43.052212
A35: 7 | B35: =IF(A35<=$B$4,0,MIN(Cap_q,MAX(C_keep-(1-Delta_q)*C34,0))) -> 2.5 | C35: =(1-Delta_q)*C34+B35 -> 55.894375 | D35: =IF(A35<=$B$4,0,Rent_58) -> 1.45 | E35: =(1-Delta_q)*E34+D35 -> 52.822469 | F35: =MIN(Cap_q,MAX(C_keep-(1-Delta_q)*G34,0)) -> 2.5 | G35: =(1-Delta_q)*G34+F35 -> 50.247059 | H35: =Rent_58 -> 1.45 | I35: =(1-Delta_q)*I34+H35 -> 43.425906
A36: 8 | B36: =IF(A36<=$B$4,0,MIN(Cap_q,MAX(C_keep-(1-Delta_q)*C35,0))) -> 2.5 | C36: =(1-Delta_q)*C35+B36 -> 56.997016 | D36: =IF(A36<=$B$4,0,Rent_58) -> 1.45 | E36: =(1-Delta_q)*E35+D36 -> 52.951907 | F36: =MIN(Cap_q,MAX(C_keep-(1-Delta_q)*G35,0)) -> 2.5 | G36: =(1-Delta_q)*G35+F36 -> 51.490883 | H36: =Rent_58 -> 1.45 | I36: =(1-Delta_q)*I35+H36 -> 43.790259
A37: 9 | B37: =IF(A37<=$B$4,0,MIN(Cap_q,MAX(C_keep-(1-Delta_q)*C36,0))) -> 2.4279098 | C37: =(1-Delta_q)*C36+B37 -> 58 | D37: =IF(A37<=$B$4,0,Rent_58) -> 1.45 | E37: =(1-Delta_q)*E36+D37 -> 53.078109 | F37: =MIN(Cap_q,MAX(C_keep-(1-Delta_q)*G36,0)) -> 2.5 | G37: =(1-Delta_q)*G36+F37 -> 52.703611 | H37: =Rent_58 -> 1.45 | I37: =(1-Delta_q)*I36+H37 -> 44.145502
A38: 10 | B38: =IF(A38<=$B$4,0,MIN(Cap_q,MAX(C_keep-(1-Delta_q)*C37,0))) -> 1.45 | C38: =(1-Delta_q)*C37+B38 -> 58 | D38: =IF(A38<=$B$4,0,Rent_58) -> 1.45 | E38: =(1-Delta_q)*E37+D38 -> 53.201157 | F38: =MIN(Cap_q,MAX(C_keep-(1-Delta_q)*G37,0)) -> 2.5 | G38: =(1-Delta_q)*G37+F38 -> 53.886021 | H38: =Rent_58 -> 1.45 | I38: =(1-Delta_q)*I37+H38 -> 44.491865
A39: 11 | B39: =IF(A39<=$B$4,0,MIN(Cap_q,MAX(C_keep-(1-Delta_q)*C38,0))) -> 1.45 | C39: =(1-Delta_q)*C38+B39 -> 58 | D39: =IF(A39<=$B$4,0,Rent_58) -> 1.45 | E39: =(1-Delta_q)*E38+D39 -> 53.321128 | F39: =MIN(Cap_q,MAX(C_keep-(1-Delta_q)*G38,0)) -> 2.5 | G39: =(1-Delta_q)*G38+F39 -> 55.03887 | H39: =Rent_58 -> 1.45 | I39: =(1-Delta_q)*I38+H39 -> 44.829568
A40: 12 | B40: =IF(A40<=$B$4,0,MIN(Cap_q,MAX(C_keep-(1-Delta_q)*C39,0))) -> 1.45 | C40: =(1-Delta_q)*C39+B40 -> 58 | D40: =IF(A40<=$B$4,0,Rent_58) -> 1.45 | E40: =(1-Delta_q)*E39+D40 -> 53.438099 | F40: =MIN(Cap_q,MAX(C_keep-(1-Delta_q)*G39,0)) -> 2.5 | G40: =(1-Delta_q)*G39+F40 -> 56.162898 | H40: =Rent_58 -> 1.45 | I40: =(1-Delta_q)*I39+H40 -> 45.158829
... A128: 100 | B128: =IF(A128<=$B$4,0,MIN(Cap_q,MAX(C_keep-(1-Delta_q)*C127,0))) -> 1.45 | C128: =(1-Delta_q)*C127+B128 -> 58 | D128: =IF(A128<=$B$4,0,Rent_58) -> 1.45 | E128: =(1-Delta_q)*E127+D128 -> 57.508468 | F128: =MIN(Cap_q,MAX(C_keep-(1-Delta_q)*G127,0)) -> 1.45 | G128: =(1-Delta_q)*G127+F128 -> 58 | H128: =Rent_58 -> 1.45 | I128: =(1-Delta_q)*I127+H128 -> 56.616399

Sheet Cash
A1: Compare the cash: Table 10.5 and the sensitivities of Online Appendix 10.B.6 (Worked Example 10.1, Step 5)
A3: Table 10.5 | B3: Keep the team | C3: Let it go, rebuild
A4: Proceeds at closing ($ million) | B4: =Proc_keep -> 92 | C4: =Proc_leave -> 112
A5: Capability at closing | B5: =C_keep -> 58 | C5: =C_leave -> 53
A6: Quarters below the floor of 55 | B6: =COUNTIF(Rebuild!$C$17:$C$97,"<"&Floor_c) -> 0 | C6: =Rebuild!B7 -> 2
A7: Quarters below 58 | B7: =COUNTIF(Rebuild!$C$17:$C$97,"<"&(C_keep-0.000000001)) -> 0 | C7: =Rebuild!B8 -> 5
A8: Capability investment over the rebuild window (points) | B8: =Rent_58*$C$7 -> 7.25 | C8: =SUMPRODUCT((Rebuild!$A$17:$A$97>=1)*(Rebuild!$A$17:$A$97<=$C$7)*Rebuild!$D$17:$D$97) -> 11.911498
A9: Capability investment over the rebuild window ($ million) | B9: =B8*Price_pt -> 29 | C9: =C8*Price_pt -> 47.64599
A10: Proceeds net of that investment ($ million) | B10: =B4-B9 -> 63 | C10: =C4-C9 -> 64.35401
A12: Extra investment to rebuild (points) | B12: =C8-B8 -> 4.6614976 | C12: 4.66 points
A13: Extra investment to rebuild ($ million) | B13: =C9-B9 -> 18.64599 | C13: $18.6 million
A14: Rebuilding comes out ahead by ($ million) | B14: =C10-B10 -> 1.3540096 | C14: $1.4 million: in cash, a wash
A16: An ask to leave the team in place ($ million) | B16: 30 | C16: Worked Example 10.1, For discussion
A17: Net proceeds if Meridian pays it and keeps the team | B17: =Proc_leave-B16-B9 -> 53
A18: Keeping then costs more in cash than rebuilding by | B18: =C10-B17 -> 11.35401 | C18: about $11 million: the price of two quarters of digital-program time
A20: Online Appendix 10.B.6 | B20: As declared | C20: Cap 2.0 a quarter | D20: Attrition 6% a year | E20: Attrition 11% a year
A21: Hiring and training cap (points a quarter) | B21: =Cap_q -> 2.5 | C21: 2 | D21: =Cap_q -> 2.5 | E21: =Cap_q -> 2.5
A22: Attrition a year | B22: =Dep_year -> 0.096312109 | C22: =Dep_year -> 0.096312109 | D22: 0.06 | E22: 0.11
A23: Attrition a quarter, (1 - a year)^(1/4) compounded | B23: =Delta_q -> 0.025 | C23: =Delta_q -> 0.025 | D23: =1-(1-D22)^(1/4) -> 0.015349823 | E23: =1-(1-E22)^(1/4) -> 0.028713166
A24: Quarter capability clears 55 | B24: =COUNTIF($C$32:$C$72,"<"&Floor_c) -> 2 | C24: =COUNTIF($E$32:$E$72,"<"&Floor_c) -> 4 | D24: =COUNTIF($G$32:$G$72,"<"&Floor_c) -> 2 | E24: =COUNTIF($I$32:$I$72,"<"&Floor_c) -> 3
A25: Quarter capability regains 58 | B25: =COUNTIF($C$32:$C$72,"<"&(C_keep-0.000000001)) -> 5 | C25: =COUNTIF($E$32:$E$72,"<"&(C_keep-0.000000001)) -> 9 | D25: =COUNTIF($G$32:$G$72,"<"&(C_keep-0.000000001)) -> 4 | E25: =COUNTIF($I$32:$I$72,"<"&(C_keep-0.000000001)) -> 6
A26: Rebuild investment over the window (points) | B26: =SUMPRODUCT(($A$32:$A$72>=1)*($A$32:$A$72<=B25)*$B$32:$B$72) -> 11.911498 | C26: =SUMPRODUCT(($A$32:$A$72>=1)*($A$32:$A$72<=C25)*$D$32:$D$72) -> 17.498359 | D26: =SUMPRODUCT(($A$32:$A$72>=1)*($A$32:$A$72<=D25)*$F$32:$F$72) -> 8.4079002 | E26: =SUMPRODUCT(($A$32:$A$72>=1)*($A$32:$A$72<=E25)*$H$32:$H$72) -> 14.53631
A27: Holding 58 over the window (points) | B27: =B23*C_keep*B25 -> 7.25 | C27: =C23*C_keep*C25 -> 13.05 | D27: =D23*C_keep*D25 -> 3.5611589 | E27: =E23*C_keep*E25 -> 9.9921819
A28: Extra cost of rebuilding ($ million) | B28: =(B26-B27)*Price_pt -> 18.64599 | C28: =(C26-C27)*Price_pt -> 17.793435 | D28: =(D26-D27)*Price_pt -> 19.386965 | E28: =(E26-E27)*Price_pt -> 18.176512
A29: Online Appendix 10.B.6: in every case the extra proceeds of $20 million roughly pay for the rebuild; what differs is the time.
A31: Quarter after closing | B31: As declared: investment | C31: Capability | D31: Cap 2.0: investment | E31: Capability | F31: Attrition 6%: investment | G31: Capability | H31: Attrition 11%: investment | I31: Capability
A32: 0 | C32: =C_leave -> 53 | E32: =C_leave -> 53 | G32: =C_leave -> 53 | I32: =C_leave -> 53
A33: 1 | B33: =MIN($B$21,MAX(C_keep-(1-$B$23)*C32,0)) -> 2.5 | C33: =(1-$B$23)*C32+B33 -> 54.175 | D33: =MIN($C$21,MAX(C_keep-(1-$C$23)*E32,0)) -> 2 | E33: =(1-$C$23)*E32+D33 -> 53.675 | F33: =MIN($D$21,MAX(C_keep-(1-$D$23)*G32,0)) -> 2.5 | G33: =(1-$D$23)*G32+F33 -> 54.686459 | H33: =MIN($E$21,MAX(C_keep-(1-$E$23)*I32,0)) -> 2.5 | I33: =(1-$E$23)*I32+H33 -> 53.978202
A34: 2 | B34: =MIN($B$21,MAX(C_keep-(1-$B$23)*C33,0)) -> 2.5 | C34: =(1-$B$23)*C33+B34 -> 55.320625 | D34: =MIN($C$21,MAX(C_keep-(1-$C$23)*E33,0)) -> 2 | E34: =(1-$C$23)*E33+D34 -> 54.333125 | F34: =MIN($D$21,MAX(C_keep-(1-$D$23)*G33,0)) -> 2.5 | G34: =(1-$D$23)*G33+F34 -> 56.347032 | H34: =MIN($E$21,MAX(C_keep-(1-$E$23)*I33,0)) -> 2.5 | I34: =(1-$E$23)*I33+H34 -> 54.928317
A35: 3 | B35: =MIN($B$21,MAX(C_keep-(1-$B$23)*C34,0)) -> 2.5 | C35: =(1-$B$23)*C34+B35 -> 56.437609 | D35: =MIN($C$21,MAX(C_keep-(1-$C$23)*E34,0)) -> 2 | E35: =(1-$C$23)*E34+D35 -> 54.974797 | F35: =MIN($D$21,MAX(C_keep-(1-$D$23)*G34,0)) -> 2.5 | G35: =(1-$D$23)*G34+F35 -> 57.982115 | H35: =MIN($E$21,MAX(C_keep-(1-$E$23)*I34,0)) -> 2.5 | I35: =(1-$E$23)*I34+H35 -> 55.851151
A36: 4 | B36: =MIN($B$21,MAX(C_keep-(1-$B$23)*C35,0)) -> 2.5 | C36: =(1-$B$23)*C35+B36 -> 57.526669 | D36: =MIN($C$21,MAX(C_keep-(1-$C$23)*E35,0)) -> 2 | E36: =(1-$C$23)*E35+D36 -> 55.600427 | F36: =MIN($D$21,MAX(C_keep-(1-$D$23)*G35,0)) -> 0.90790021 | G36: =(1-$D$23)*G35+F36 -> 58 | H36: =MIN($E$21,MAX(C_keep-(1-$E$23)*I35,0)) -> 2.5 | I36: =(1-$E$23)*I35+H36 -> 56.747488
A37: 5 | B37: =MIN($B$21,MAX(C_keep-(1-$B$23)*C36,0)) -> 1.9114976 | C37: =(1-$B$23)*C36+B37 -> 58 | D37: =MIN($C$21,MAX(C_keep-(1-$C$23)*E36,0)) -> 2 | E37: =(1-$C$23)*E36+D37 -> 56.210416 | F37: =MIN($D$21,MAX(C_keep-(1-$D$23)*G36,0)) -> 0.89028972 | G37: =(1-$D$23)*G36+F37 -> 58 | H37: =MIN($E$21,MAX(C_keep-(1-$E$23)*I36,0)) -> 2.5 | I37: =(1-$E$23)*I36+H37 -> 57.618088
A38: 6 | B38: =MIN($B$21,MAX(C_keep-(1-$B$23)*C37,0)) -> 1.45 | C38: =(1-$B$23)*C37+B38 -> 58 | D38: =MIN($C$21,MAX(C_keep-(1-$C$23)*E37,0)) -> 2 | E38: =(1-$C$23)*E37+D38 -> 56.805156 | F38: =MIN($D$21,MAX(C_keep-(1-$D$23)*G37,0)) -> 0.89028972 | G38: =(1-$D$23)*G37+F38 -> 58 | H38: =MIN($E$21,MAX(C_keep-(1-$E$23)*I37,0)) -> 2.03631 | I38: =(1-$E$23)*I37+H38 -> 58
A39: 7 | B39: =MIN($B$21,MAX(C_keep-(1-$B$23)*C38,0)) -> 1.45 | C39: =(1-$B$23)*C38+B39 -> 58 | D39: =MIN($C$21,MAX(C_keep-(1-$C$23)*E38,0)) -> 2 | E39: =(1-$C$23)*E38+D39 -> 57.385027 | F39: =MIN($D$21,MAX(C_keep-(1-$D$23)*G38,0)) -> 0.89028972 | G39: =(1-$D$23)*G38+F39 -> 58 | H39: =MIN($E$21,MAX(C_keep-(1-$E$23)*I38,0)) -> 1.6653636 | I39: =(1-$E$23)*I38+H39 -> 58
A40: 8 | B40: =MIN($B$21,MAX(C_keep-(1-$B$23)*C39,0)) -> 1.45 | C40: =(1-$B$23)*C39+B40 -> 58 | D40: =MIN($C$21,MAX(C_keep-(1-$C$23)*E39,0)) -> 2 | E40: =(1-$C$23)*E39+D40 -> 57.950401 | F40: =MIN($D$21,MAX(C_keep-(1-$D$23)*G39,0)) -> 0.89028972 | G40: =(1-$D$23)*G39+F40 -> 58 | H40: =MIN($E$21,MAX(C_keep-(1-$E$23)*I39,0)) -> 1.6653636 | I40: =(1-$E$23)*I39+H40 -> 58
A41: 9 | B41: =MIN($B$21,MAX(C_keep-(1-$B$23)*C40,0)) -> 1.45 | C41: =(1-$B$23)*C40+B41 -> 58 | D41: =MIN($C$21,MAX(C_keep-(1-$C$23)*E40,0)) -> 1.4983587 | E41: =(1-$C$23)*E40+D41 -> 58 | F41: =MIN($D$21,MAX(C_keep-(1-$D$23)*G40,0)) -> 0.89028972 | G41: =(1-$D$23)*G40+F41 -> 58 | H41: =MIN($E$21,MAX(C_keep-(1-$E$23)*I40,0)) -> 1.6653636 | I41: =(1-$E$23)*I40+H41 -> 58
A42: 10 | B42: =MIN($B$21,MAX(C_keep-(1-$B$23)*C41,0)) -> 1.45 | C42: =(1-$B$23)*C41+B42 -> 58 | D42: =MIN($C$21,MAX(C_keep-(1-$C$23)*E41,0)) -> 1.45 | E42: =(1-$C$23)*E41+D42 -> 58 | F42: =MIN($D$21,MAX(C_keep-(1-$D$23)*G41,0)) -> 0.89028972 | G42: =(1-$D$23)*G41+F42 -> 58 | H42: =MIN($E$21,MAX(C_keep-(1-$E$23)*I41,0)) -> 1.6653636 | I42: =(1-$E$23)*I41+H42 -> 58
A43: 11 | B43: =MIN($B$21,MAX(C_keep-(1-$B$23)*C42,0)) -> 1.45 | C43: =(1-$B$23)*C42+B43 -> 58 | D43: =MIN($C$21,MAX(C_keep-(1-$C$23)*E42,0)) -> 1.45 | E43: =(1-$C$23)*E42+D43 -> 58 | F43: =MIN($D$21,MAX(C_keep-(1-$D$23)*G42,0)) -> 0.89028972 | G43: =(1-$D$23)*G42+F43 -> 58 | H43: =MIN($E$21,MAX(C_keep-(1-$E$23)*I42,0)) -> 1.6653636 | I43: =(1-$E$23)*I42+H43 -> 58
A44: 12 | B44: =MIN($B$21,MAX(C_keep-(1-$B$23)*C43,0)) -> 1.45 | C44: =(1-$B$23)*C43+B44 -> 58 | D44: =MIN($C$21,MAX(C_keep-(1-$C$23)*E43,0)) -> 1.45 | E44: =(1-$C$23)*E43+D44 -> 58 | F44: =MIN($D$21,MAX(C_keep-(1-$D$23)*G43,0)) -> 0.89028972 | G44: =(1-$D$23)*G43+F44 -> 58 | H44: =MIN($E$21,MAX(C_keep-(1-$E$23)*I43,0)) -> 1.6653636 | I44: =(1-$E$23)*I43+H44 -> 58
... A72: 40 | B72: =MIN($B$21,MAX(C_keep-(1-$B$23)*C71,0)) -> 1.45 | C72: =(1-$B$23)*C71+B72 -> 58 | D72: =MIN($C$21,MAX(C_keep-(1-$C$23)*E71,0)) -> 1.45 | E72: =(1-$C$23)*E71+D72 -> 58 | F72: =MIN($D$21,MAX(C_keep-(1-$D$23)*G71,0)) -> 0.89028972 | G72: =(1-$D$23)*G71+F72 -> 58 | H72: =MIN($E$21,MAX(C_keep-(1-$E$23)*I71,0)) -> 1.6653636 | I72: =(1-$E$23)*I71+H72 -> 58

Sheet Allocation
A1: Allocate a budget: fund the bottleneck (Theorems 10.2(i) and 10.4; Figure 10.2; AXIOM Lab 1.10, step 4)
A2: Section 10.7's technology company: delivery capacity F = min(C_T / 1.0, C_H / 0.5, C_O / 0.75). Capacity reads no financial capital: money left in cash adds nothing until it is converted.
A3: Form | B3: Stock C | C3: Requirement r | D3: Ratio C / r | H3: Online Appendix 10.B.3 | I3: Form 1 | J3: Form 2
A4: technology | B4: 80 | C4: 1 | D4: =B4/C4 -> 80 | H4: Stock C | I4: 10 | J4: 30
A5: human | B5: 45 | C5: 0.5 | D5: =B5/C5 -> 90 | H5: Requirement r | I5: 1 | J5: 2
A6: organizational | B6: 60 | C6: 0.75 | D6: =B6/C6 -> 80 | H6: Ratio C / r | I6: =I4/I5 -> 10 | J6: =J4/J5 -> 15
A7: Capacity, the smallest ratio | B7: =MIN(D4:D6) -> 80 | H7: Budget | I7: 20
A8: Human capital's slack over the bottleneck | B8: =D5/B7-1 -> 0.125 | H8: Kink: budget that lifts form 1 to form 2's ratio | I8: =MAX(I5*MAX(I6,J6)-I4,0)+MAX(J5*MAX(I6,J6)-J4,0) -> 5
H9: Capacity reached | I9: =IF(I7<=I8,MIN(I6,J6)+I7/IF(I6<J6,I5,J5),MAX(I6,J6)+(I7-I8)/(I5+J5)) -> 20
A10: Kink (Theorem 10.4(ii)) | B10: Level l: the k-th smallest ratio | C10: Budget b(l) = sum max(r l - C, 0) | D10: Requirements of the funded forms | E10: Shadow value lambda | H10: Optimal allocation | I10: =MAX(I5*I9-I4,0) -> 10 | J10: =MAX(J5*I9-J4,0) -> 10
A11: 1 | B11: =SMALL($D$4:$D$6,A11) -> 80 | C11: =SUMPRODUCT(($C$4:$C$6*B11-$B$4:$B$6>0)*($C$4:$C$6*B11-$B$4:$B$6)) -> 0 | D11: =SUMPRODUCT(($D$4:$D$6<=B11+0.000000001)*$C$4:$C$6) -> 1.75 | E11: =1/D11 -> 0.57142857
A12: 2 | B12: =SMALL($D$4:$D$6,A12) -> 80 | C12: =SUMPRODUCT(($C$4:$C$6*B12-$B$4:$B$6>0)*($C$4:$C$6*B12-$B$4:$B$6)) -> 0 | D12: =SUMPRODUCT(($D$4:$D$6<=B12+0.000000001)*$C$4:$C$6) -> 1.75 | E12: =1/D12 -> 0.57142857 | H12: Online Appendix 10.B.4: complements C1^a C2^b | I12: Case 1 | J12: Case 2
A13: 3 | B13: =SMALL($D$4:$D$6,A13) -> 90 | C13: =SUMPRODUCT(($C$4:$C$6*B13-$B$4:$B$6>0)*($C$4:$C$6*B13-$B$4:$B$6)) -> 17.5 | D13: =SUMPRODUCT(($D$4:$D$6<=B13+0.000000001)*$C$4:$C$6) -> 2.25 | E13: =1/D13 -> 0.44444444 | H13: a | I13: 0.3 | J13: 0.4
A14: Budget at which all three tie and the bottleneck rotates | B14: =C13 -> 17.5 | H14: b | I14: 0.3 | J14: 0.2
H15: Stock C1 | I15: 40 | J15: 40
A16: Results | B16: Fund the bottleneck | C16: Equal split | D16: All to human capital | H16: Stock C2 | I16: 20 | J16: 20
A17: Capacity after 17.5 points | B17: =INDEX($B$25:$B$85,MATCH(17.5,$A$25:$A$85,0)) -> 90 | C17: =INDEX($C$25:$C$85,MATCH(17.5,$A$25:$A$85,0)) -> 85.833333 | D17: =INDEX($D$25:$D$85,MATCH(17.5,$A$25:$A$85,0)) -> 80 | H17: Budget | I17: 20 | J17: 20
A18: Capacity after 30 points | B18: =INDEX($B$25:$B$85,MATCH(30,$A$25:$A$85,0)) -> 95.555556 | C18: =INDEX($C$25:$C$85,MATCH(30,$A$25:$A$85,0)) -> 90 | D18: =INDEX($D$25:$D$85,MATCH(30,$A$25:$A$85,0)) -> 80 | H18: Final stock of form 1, a / (a + b) x (C1 + C2 + B) | I18: =I13/(I13+I14)*(I15+I16+I17) -> 40 | J18: =J13/(J13+J14)*(J15+J16+J17) -> 53.333333
A19: Capacity bought a point over the 30 | B19: =(B18-$B$7)/30 -> 0.51851852 | C19: =(C18-$B$7)/30 -> 0.33333333 | D19: =(D18-$B$7)/30 -> 0 | H19: Final stock of form 2 | I19: =I14/(I13+I14)*(I15+I16+I17) -> 40 | J19: =J14/(J13+J14)*(J15+J16+J17) -> 26.666667
A20: Bottleneck allocation of 30 points: technology, human, organizational | B20: =MAX($C$4*$B$18-$B$4,0) -> 15.555556 | C20: =MAX($C$5*$B$18-$B$5,0) -> 2.7777778 | D20: =MAX($C$6*$B$18-$B$6,0) -> 11.666667 | H20: Funding of form 1 | I20: =I18-I15 -> 0 | J20: =J18-J15 -> 13.333333
A21: Theorem 10.4(i): every funded form earns the same marginal capacity, the shadow value lambda; an unfunded form's falls short of it. Here lambda = 1/1.75 = 0.571 until the tie, then 1/2.25 = 0.444. | H21: Funding of form 2 | I21: =I19-I16 -> 20 | J21: =J19-J16 -> 6.6666667
A24: Budget spent B | B24: Fund the bottleneck: capacity | C24: Equal split: capacity | D24: All to human capital: capacity | E24: Kink in force
A25: 0 | B25: =INDEX($B$11:$B$13,E25)+(A25-INDEX($C$11:$C$13,E25))/INDEX($D$11:$D$13,E25) -> 80 | C25: =MIN(($B$4+A25/3)/$C$4,($B$5+A25/3)/$C$5,($B$6+A25/3)/$C$6) -> 80 | D25: =MIN($B$4/$C$4,($B$5+A25)/$C$5,$B$6/$C$6) -> 80 | E25: =MATCH(A25,$C$11:$C$13,1) -> 2
A26: 0.5 | B26: =INDEX($B$11:$B$13,E26)+(A26-INDEX($C$11:$C$13,E26))/INDEX($D$11:$D$13,E26) -> 80.285714 | C26: =MIN(($B$4+A26/3)/$C$4,($B$5+A26/3)/$C$5,($B$6+A26/3)/$C$6) -> 80.166667 | D26: =MIN($B$4/$C$4,($B$5+A26)/$C$5,$B$6/$C$6) -> 80 | E26: =MATCH(A26,$C$11:$C$13,1) -> 2
A27: 1 | B27: =INDEX($B$11:$B$13,E27)+(A27-INDEX($C$11:$C$13,E27))/INDEX($D$11:$D$13,E27) -> 80.571429 | C27: =MIN(($B$4+A27/3)/$C$4,($B$5+A27/3)/$C$5,($B$6+A27/3)/$C$6) -> 80.333333 | D27: =MIN($B$4/$C$4,($B$5+A27)/$C$5,$B$6/$C$6) -> 80 | E27: =MATCH(A27,$C$11:$C$13,1) -> 2
A28: 1.5 | B28: =INDEX($B$11:$B$13,E28)+(A28-INDEX($C$11:$C$13,E28))/INDEX($D$11:$D$13,E28) -> 80.857143 | C28: =MIN(($B$4+A28/3)/$C$4,($B$5+A28/3)/$C$5,($B$6+A28/3)/$C$6) -> 80.5 | D28: =MIN($B$4/$C$4,($B$5+A28)/$C$5,$B$6/$C$6) -> 80 | E28: =MATCH(A28,$C$11:$C$13,1) -> 2
A29: 2 | B29: =INDEX($B$11:$B$13,E29)+(A29-INDEX($C$11:$C$13,E29))/INDEX($D$11:$D$13,E29) -> 81.142857 | C29: =MIN(($B$4+A29/3)/$C$4,($B$5+A29/3)/$C$5,($B$6+A29/3)/$C$6) -> 80.666667 | D29: =MIN($B$4/$C$4,($B$5+A29)/$C$5,$B$6/$C$6) -> 80 | E29: =MATCH(A29,$C$11:$C$13,1) -> 2
A30: 2.5 | B30: =INDEX($B$11:$B$13,E30)+(A30-INDEX($C$11:$C$13,E30))/INDEX($D$11:$D$13,E30) -> 81.428571 | C30: =MIN(($B$4+A30/3)/$C$4,($B$5+A30/3)/$C$5,($B$6+A30/3)/$C$6) -> 80.833333 | D30: =MIN($B$4/$C$4,($B$5+A30)/$C$5,$B$6/$C$6) -> 80 | E30: =MATCH(A30,$C$11:$C$13,1) -> 2
A31: 3 | B31: =INDEX($B$11:$B$13,E31)+(A31-INDEX($C$11:$C$13,E31))/INDEX($D$11:$D$13,E31) -> 81.714286 | C31: =MIN(($B$4+A31/3)/$C$4,($B$5+A31/3)/$C$5,($B$6+A31/3)/$C$6) -> 81 | D31: =MIN($B$4/$C$4,($B$5+A31)/$C$5,$B$6/$C$6) -> 80 | E31: =MATCH(A31,$C$11:$C$13,1) -> 2
A32: 3.5 | B32: =INDEX($B$11:$B$13,E32)+(A32-INDEX($C$11:$C$13,E32))/INDEX($D$11:$D$13,E32) -> 82 | C32: =MIN(($B$4+A32/3)/$C$4,($B$5+A32/3)/$C$5,($B$6+A32/3)/$C$6) -> 81.166667 | D32: =MIN($B$4/$C$4,($B$5+A32)/$C$5,$B$6/$C$6) -> 80 | E32: =MATCH(A32,$C$11:$C$13,1) -> 2
A33: 4 | B33: =INDEX($B$11:$B$13,E33)+(A33-INDEX($C$11:$C$13,E33))/INDEX($D$11:$D$13,E33) -> 82.285714 | C33: =MIN(($B$4+A33/3)/$C$4,($B$5+A33/3)/$C$5,($B$6+A33/3)/$C$6) -> 81.333333 | D33: =MIN($B$4/$C$4,($B$5+A33)/$C$5,$B$6/$C$6) -> 80 | E33: =MATCH(A33,$C$11:$C$13,1) -> 2
A34: 4.5 | B34: =INDEX($B$11:$B$13,E34)+(A34-INDEX($C$11:$C$13,E34))/INDEX($D$11:$D$13,E34) -> 82.571429 | C34: =MIN(($B$4+A34/3)/$C$4,($B$5+A34/3)/$C$5,($B$6+A34/3)/$C$6) -> 81.5 | D34: =MIN($B$4/$C$4,($B$5+A34)/$C$5,$B$6/$C$6) -> 80 | E34: =MATCH(A34,$C$11:$C$13,1) -> 2
A35: 5 | B35: =INDEX($B$11:$B$13,E35)+(A35-INDEX($C$11:$C$13,E35))/INDEX($D$11:$D$13,E35) -> 82.857143 | C35: =MIN(($B$4+A35/3)/$C$4,($B$5+A35/3)/$C$5,($B$6+A35/3)/$C$6) -> 81.666667 | D35: =MIN($B$4/$C$4,($B$5+A35)/$C$5,$B$6/$C$6) -> 80 | E35: =MATCH(A35,$C$11:$C$13,1) -> 2
A36: 5.5 | B36: =INDEX($B$11:$B$13,E36)+(A36-INDEX($C$11:$C$13,E36))/INDEX($D$11:$D$13,E36) -> 83.142857 | C36: =MIN(($B$4+A36/3)/$C$4,($B$5+A36/3)/$C$5,($B$6+A36/3)/$C$6) -> 81.833333 | D36: =MIN($B$4/$C$4,($B$5+A36)/$C$5,$B$6/$C$6) -> 80 | E36: =MATCH(A36,$C$11:$C$13,1) -> 2
... A85: 30 | B85: =INDEX($B$11:$B$13,E85)+(A85-INDEX($C$11:$C$13,E85))/INDEX($D$11:$D$13,E85) -> 95.555556 | C85: =MIN(($B$4+A85/3)/$C$4,($B$5+A85/3)/$C$5,($B$6+A85/3)/$C$6) -> 90 | D85: =MIN($B$4/$C$4,($B$5+A85)/$C$5,$B$6/$C$6) -> 80 | E85: =MATCH(A85,$C$11:$C$13,1) -> 3

Sheet Ledger
A1: Audit the ledger: the plug as a detector (Theorems 10.1 and 10.5(iii); Online Appendix 10.B.1, 10.B.5; AXIOM Lab 1.10, step 5)
A3: Conversion chain (Online Appendix 10.B.1) | B3: Value
A4: Cash into a platform: efficiency | B4: 0.8
A5: Platform into usable capability: efficiency | B5: 0.7
A6: Share of the budget delivered as capability | B6: =B4*B5 -> 0.56
A7: Conversion loss (Theorem 10.1(ii)) | B7: =1-B6 -> 0.44
A9: Record A: the sale, booked without the engineering team. Columns B-E are what happened; the auditor sees the stocks (B, E) and the declared channels (F, G) only. The treasury books the unit at $92 million, the price without the team. Quarter 0 ends with the closing.
A10: Quarter | B10: Start | C10: Investment made | D10: Team leaves with the unit (undeclared) | E10: End | F10: Declared investment | G10: Decay, delta x start | H10: Plug | I10: Cash received | J10: Cash declared | K10: Cash plug
A11: -1 | B11: =C_keep -> 58 | C11: =Rent_58 -> 1.45 | D11: 0 | E11: =(1-Delta_q)*B11+C11-D11 -> 58 | F11: =C11 -> 1.45 | G11: =Delta_q*B11 -> 1.45 | H11: =E11-B11-(F11-G11) -> 0 | I11: 0 | J11: 0 | K11: =I11-J11 -> 0
A12: 0 | B12: =E11 -> 58 | C12: =Rent_58 -> 1.45 | D12: =Pts_lost -> 5 | E12: =(1-Delta_q)*B12+C12-D12 -> 53 | F12: =C12 -> 1.45 | G12: =Delta_q*B12 -> 1.45 | H12: =E12-B12-(F12-G12) -> -5 | I12: =Proc_leave -> 112 | J12: =Proc_keep -> 92 | K12: =I12-J12 -> 20
A13: 1 | B13: =E12 -> 53 | C13: =MIN(Cap_q,MAX(C_keep-(1-Delta_q)*B13,0)) -> 2.5 | D13: 0 | E13: =(1-Delta_q)*B13+C13-D13 -> 54.175 | F13: =C13 -> 2.5 | G13: =Delta_q*B13 -> 1.325 | H13: =E13-B13-(F13-G13) -> 0 | I13: 0 | J13: 0 | K13: =I13-J13 -> 0
A14: 2 | B14: =E13 -> 54.175 | C14: =MIN(Cap_q,MAX(C_keep-(1-Delta_q)*B14,0)) -> 2.5 | D14: 0 | E14: =(1-Delta_q)*B14+C14-D14 -> 55.320625 | F14: =C14 -> 2.5 | G14: =Delta_q*B14 -> 1.354375 | H14: =E14-B14-(F14-G14) -> -4.4408921e-15 | I14: 0 | J14: 0 | K14: =I14-J14 -> 0
A15: 3 | B15: =E14 -> 55.320625 | C15: =MIN(Cap_q,MAX(C_keep-(1-Delta_q)*B15,0)) -> 2.5 | D15: 0 | E15: =(1-Delta_q)*B15+C15-D15 -> 56.437609 | F15: =C15 -> 2.5 | G15: =Delta_q*B15 -> 1.3830156 | H15: =E15-B15-(F15-G15) -> 0 | I15: 0 | J15: 0 | K15: =I15-J15 -> 0
A16: 4 | B16: =E15 -> 56.437609 | C16: =MIN(Cap_q,MAX(C_keep-(1-Delta_q)*B16,0)) -> 2.5 | D16: 0 | E16: =(1-Delta_q)*B16+C16-D16 -> 57.526669 | F16: =C16 -> 2.5 | G16: =Delta_q*B16 -> 1.4109402 | H16: =E16-B16-(F16-G16) -> 0 | I16: 0 | J16: 0 | K16: =I16-J16 -> 0
A17: 5 | B17: =E16 -> 57.526669 | C17: =MIN(Cap_q,MAX(C_keep-(1-Delta_q)*B17,0)) -> 1.9114976 | D17: 0 | E17: =(1-Delta_q)*B17+C17-D17 -> 58 | F17: =C17 -> 1.9114976 | G17: =Delta_q*B17 -> 1.4381667 | H17: =E17-B17-(F17-G17) -> 0 | I17: 0 | J17: 0 | K17: =I17-J17 -> 0
A19: Plug in the closing quarter (points) | B19: =H12 -> -5 | C19: One outflow on capability and one inflow of cash, in the closing quarter, at $4 million a point: the team sold with the unit.
A20: Plugs in the other quarters, in absolute value | B20: =SUMPRODUCT(ABS(H11:H17))-ABS(H12) -> 0
A21: Cash plug in the closing quarter ($ million) | B21: =K12 -> 20
A22: Price of the undeclared conversion ($ million a point) | B22: =-B21/B19 -> 4
A24: Record B: training is cut for the quarters of CutAndShock!B4, but the ledger still books the rent as invested and the training budget as spent.
A25: Quarter | B25: Start | C25: Investment made | D25: End | E25: Declared investment | F25: Decay, delta x start | G25: Plug | H25: Training spend declared ($ million) | I25: Training spend made | J25: Cash plug
A26: 1 | B26: =C_keep -> 58 | C26: =IF(A26<=CutAndShock!$B$4,0,Rent_58) -> 0 | D26: =(1-Delta_q)*B26+C26 -> 56.55 | E26: =Rent_58 -> 1.45 | F26: =Delta_q*B26 -> 1.45 | G26: =D26-B26-(E26-F26) -> -1.45 | H26: =E26*Price_pt -> 5.8 | I26: =C26*Price_pt -> 0 | J26: =H26-I26 -> 5.8
A27: 2 | B27: =D26 -> 56.55 | C27: =IF(A27<=CutAndShock!$B$4,0,Rent_58) -> 0 | D27: =(1-Delta_q)*B27+C27 -> 55.13625 | E27: =Rent_58 -> 1.45 | F27: =Delta_q*B27 -> 1.41375 | G27: =D27-B27-(E27-F27) -> -1.45 | H27: =E27*Price_pt -> 5.8 | I27: =C27*Price_pt -> 0 | J27: =H27-I27 -> 5.8
A28: 3 | B28: =D27 -> 55.13625 | C28: =IF(A28<=CutAndShock!$B$4,0,Rent_58) -> 0 | D28: =(1-Delta_q)*B28+C28 -> 53.757844 | E28: =Rent_58 -> 1.45 | F28: =Delta_q*B28 -> 1.3784063 | G28: =D28-B28-(E28-F28) -> -1.45 | H28: =E28*Price_pt -> 5.8 | I28: =C28*Price_pt -> 0 | J28: =H28-I28 -> 5.8
A29: 4 | B29: =D28 -> 53.757844 | C29: =IF(A29<=CutAndShock!$B$4,0,Rent_58) -> 0 | D29: =(1-Delta_q)*B29+C29 -> 52.413898 | E29: =Rent_58 -> 1.45 | F29: =Delta_q*B29 -> 1.3439461 | G29: =D29-B29-(E29-F29) -> -1.45 | H29: =E29*Price_pt -> 5.8 | I29: =C29*Price_pt -> 0 | J29: =H29-I29 -> 5.8
A30: 5 | B30: =D29 -> 52.413898 | C30: =IF(A30<=CutAndShock!$B$4,0,Rent_58) -> 1.45 | D30: =(1-Delta_q)*B30+C30 -> 52.55355 | E30: =Rent_58 -> 1.45 | F30: =Delta_q*B30 -> 1.3103474 | G30: =D30-B30-(E30-F30) -> 2.4424907e-15 | H30: =E30*Price_pt -> 5.8 | I30: =C30*Price_pt -> 5.8 | J30: =H30-I30 -> 0
A31: 6 | B31: =D30 -> 52.55355 | C31: =IF(A31<=CutAndShock!$B$4,0,Rent_58) -> 1.45 | D31: =(1-Delta_q)*B31+C31 -> 52.689711 | E31: =Rent_58 -> 1.45 | F31: =Delta_q*B31 -> 1.3138388 | G31: =D31-B31-(E31-F31) -> 2.4424907e-15 | H31: =E31*Price_pt -> 5.8 | I31: =C31*Price_pt -> 5.8 | J31: =H31-I31 -> 0
A32: 7 | B32: =D31 -> 52.689711 | C32: =IF(A32<=CutAndShock!$B$4,0,Rent_58) -> 1.45 | D32: =(1-Delta_q)*B32+C32 -> 52.822469 | E32: =Rent_58 -> 1.45 | F32: =Delta_q*B32 -> 1.3172428 | G32: =D32-B32-(E32-F32) -> 3.7747583e-15 | H32: =E32*Price_pt -> 5.8 | I32: =C32*Price_pt -> 5.8 | J32: =H32-I32 -> 0
A33: 8 | B33: =D32 -> 52.822469 | C33: =IF(A33<=CutAndShock!$B$4,0,Rent_58) -> 1.45 | D33: =(1-Delta_q)*B33+C33 -> 52.951907 | E33: =Rent_58 -> 1.45 | F33: =Delta_q*B33 -> 1.3205617 | G33: =D33-B33-(E33-F33) -> 0 | H33: =E33*Price_pt -> 5.8 | I33: =C33*Price_pt -> 5.8 | J33: =H33-I33 -> 0
A35: Quarters with a nonzero plug | B35: =COUNTIF(G26:G33,"<-1E-9")+COUNTIF(G26:G33,">1E-9") -> 4
A36: Plug a quarter during the cut (points) | B36: =MIN(G26:G33) -> -1.45 | C36: A persistent negative plug of the rent's size for exactly the quarters of the cut, mirrored in cash: the rent turned back into reported earnings (Section 11.8).
A37: Cash plug in all ($ million) | B37: =SUM(J26:J33) -> 23.2

Sheet Reference_Values
A1: Checkpoint | B1: Engine value | C1: Meaning (where in the book)
A2: Forms in the capital vector | B2: 10 | C2: Table 10.1 and Equation 10.1: ten forms
A3: Price of a capability point | B3: 4 | C3: Worked Example 10.1, Step 1: $4 million a point
A4: Liquidity after the sale, team goes | B4: 732 | C4: Step 1: $732 million
A5: Liquidity after the sale, team kept | B5: 712 | C5: Step 1: $712 million
A6: Technology after the sale | B6: 36.9 | C6: Step 1: 41 to 36.9 either way
A7: Depreciation a year (percent) | B7: 9.6312109 | C7: Online Appendix 10.B.6: 9.6 percent
A8: Rent on 58, points a quarter | B8: 1.45 | C8: Step 2: 1.45 points a quarter
A9: Rent on 58, $ million a year | B9: 23.2 | C9: Step 2: about $23 million a year
A10: Years to 90%, delta 5%, at the rent | B10: 44.890567 | C10: Figure 10.1: 44.9
A11: Years to 90%, delta 10%, at the rent | B11: 21.854345 | C11: Figure 10.1: 21.9
A12: Years to 90%, delta 25%, at the rent | B12: 8.0039228 | C12: Figure 10.1: 8.0
A13: Years to 90%, delta 5%, twice the rent | B13: 11.655266 | C13: Figure 10.1: 11.7
... A60: Record B: cash plug in all | B60: 23.2 | C60: The year's rent, about $23 million (Section 11.8)

Sheet Checks
A1: Checkpoint | B1: Workbook formula value | C1: Engine value | D1: |diff| | E1: Tolerance | F1: Status
A2: Forms in the capital vector | B2: =CapitalVector!B14 -> 10 | C2: =Reference_Values!B2 -> 10 | D2: =ABS(B2-C2) -> 0 | E2: 0 | F2: =IF(D2<=E2,"PASS","FAIL") -> PASS
A3: Price of a capability point | B3: =CapitalVector!B37 -> 4 | C3: =Reference_Values!B3 -> 4 | D3: =ABS(B3-C3) -> 0 | E3: 1e-09 | F3: =IF(D3<=E3,"PASS","FAIL") -> PASS
A4: Liquidity after the sale, team goes | B4: =CapitalVector!D34 -> 732 | C4: =Reference_Values!B4 -> 732 | D4: =ABS(B4-C4) -> 0 | E4: 1e-09 | F4: =IF(D4<=E4,"PASS","FAIL") -> PASS
A5: Liquidity after the sale, team kept | B5: =CapitalVector!C34 -> 712 | C5: =Reference_Values!B5 -> 712 | D5: =ABS(B5-C5) -> 0 | E5: 1e-09 | F5: =IF(D5<=E5,"PASS","FAIL") -> PASS
A6: Technology after the sale | B6: =CapitalVector!C36 -> 36.9 | C6: =Reference_Values!B6 -> 36.9 | D6: =ABS(B6-C6) -> 0 | E6: 1e-09 | F6: =IF(D6<=E6,"PASS","FAIL") -> PASS
A7: Depreciation a year (percent) | B7: =100*Rent!B8 -> 9.6312109 | C7: =Reference_Values!B7 -> 9.6312109 | D7: =ABS(B7-C7) -> 0 | E7: 1e-09 | F7: =IF(D7<=E7,"PASS","FAIL") -> PASS
A8: Rent on 58, points a quarter | B8: =Rent!B4 -> 1.45 | C8: =Reference_Values!B8 -> 1.45 | D8: =ABS(B8-C8) -> 0 | E8: 1e-09 | F8: =IF(D8<=E8,"PASS","FAIL") -> PASS
A9: Rent on 58, $ million a year | B9: =Rent!B7 -> 23.2 | C9: =Reference_Values!B9 -> 23.2 | D9: =ABS(B9-C9) -> 0 | E9: 1e-09 | F9: =IF(D9<=E9,"PASS","FAIL") -> PASS
A10: Years to 90%, delta 5%, at the rent | B10: =Rent!E11 -> 44.890567 | C10: =Reference_Values!B10 -> 44.890567 | D10: =ABS(B10-C10) -> 0 | E10: 1e-09 | F10: =IF(D10<=E10,"PASS","FAIL") -> PASS
A11: Years to 90%, delta 10%, at the rent | B11: =Rent!E12 -> 21.854345 | C11: =Reference_Values!B11 -> 21.854345 | D11: =ABS(B11-C11) -> 0 | E11: 1e-09 | F11: =IF(D11<=E11,"PASS","FAIL") -> PASS
A12: Years to 90%, delta 25%, at the rent | B12: =Rent!E13 -> 8.0039228 | C12: =Reference_Values!B12 -> 8.0039228 | D12: =ABS(B12-C12) -> 0 | E12: 1e-09 | F12: =IF(D12<=E12,"PASS","FAIL") -> PASS
A13: Years to 90%, delta 5%, twice the rent | B13: =Rent!F11 -> 11.655266 | C13: =Reference_Values!B13 -> 11.655266 | D13: =ABS(B13-C13) -> 0 | E13: 1e-09 | F13: =IF(D13<=E13,"PASS","FAIL") -> PASS
A14: Years to 90%, delta 10%, twice the rent | B14: =Rent!F12 -> 5.6742034 | C14: =Reference_Values!B14 -> 5.6742034 | D14: =ABS(B14-C14) -> 0 | E14: 1e-09 | F14: =IF(D14<=E14,"PASS","FAIL") -> PASS
A15: Years to 90%, delta 25%, twice the rent | B15: =Rent!F13 -> 2.078117 | C15: =Reference_Values!B15 -> 2.078117 | D15: =ABS(B15-C15) -> 0 | E15: 1e-09 | F15: =IF(D15<=E15,"PASS","FAIL") -> PASS
A16: Ceiling under the cap | B16: =Rebuild!B4 -> 100 | C16: =Reference_Values!B16 -> 100 | D16: =ABS(B16-C16) -> 0 | E16: 1e-09 | F16: =IF(D16<=E16,"PASS","FAIL") -> PASS
A17: Fewest quarters from 53 to clear 55 | B17: =Rebuild!B5 -> 1.7175702 | C17: =Reference_Values!B17 -> 1.7175702 | D17: =ABS(B17-C17) -> 0 | E17: 1e-09 | F17: =IF(D17<=E17,"PASS","FAIL") -> PASS
A18: Fewest quarters from 53 to regain 58 | B18: =Rebuild!B6 -> 4.442643 | C18: =Reference_Values!B18 -> 4.442643 | D18: =ABS(B18-C18) -> 0 | E18: 1e-09 | F18: =IF(D18<=E18,"PASS","FAIL") -> PASS
A19: Capability after one quarter at the cap | B19: =Rebuild!B9 -> 54.175 | C19: =Reference_Values!B19 -> 54.175 | D19: =ABS(B19-C19) -> 0 | E19: 1e-09 | F19: =IF(D19<=E19,"PASS","FAIL") -> PASS
A20: Capability after four quarters at the cap | B20: =Rebuild!B10 -> 57.526669 | C20: =Reference_Values!B20 -> 57.526669 | D20: =ABS(B20-C20) -> 0 | E20: 1e-09 | F20: =IF(D20<=E20,"PASS","FAIL") -> PASS
A21: Quarters below 55, rebuild at the cap | B21: =Rebuild!B7 -> 2 | C21: =Reference_Values!B21 -> 2 | D21: =ABS(B21-C21) -> 0 | E21: 0 | F21: =IF(D21<=E21,"PASS","FAIL") -> PASS
A22: Quarters below 58, rebuild at the cap | B22: =Rebuild!B8 -> 5 | C22: =Reference_Values!B22 -> 5 | D22: =ABS(B22-C22) -> 0 | E22: 0 | F22: =IF(D22<=E22,"PASS","FAIL") -> PASS
A23: Old budget: quarters below 55 | B23: =Rebuild!B11 -> 21 | C23: =Reference_Values!B23 -> 21 | D23: =ABS(B23-C23) -> 0 | E23: 0 | F23: =IF(D23<=E23,"PASS","FAIL") -> PASS
A24: Old budget: capability after six years | B24: =Rebuild!B12 -> 55.276792 | C24: =Reference_Values!B24 -> 55.276792 | D24: =ABS(B24-C24) -> 0 | E24: 1e-09 | F24: =IF(D24<=E24,"PASS","FAIL") -> PASS
A25: Old budget: quarters to reach 57 | B25: =Rebuild!B13 -> 64 | C25: =Reference_Values!B25 -> 64 | D25: =ABS(B25-C25) -> 0 | E25: 0 | F25: =IF(D25<=E25,"PASS","FAIL") -> PASS
A26: Rebuild investment over the window, points | B26: =Cash!C8 -> 11.911498 | C26: =Reference_Values!B26 -> 11.911498 | D26: =ABS(B26-C26) -> 0 | E26: 1e-09 | F26: =IF(D26<=E26,"PASS","FAIL") -> PASS
A27: Rebuild investment, $ million | B27: =Cash!C9 -> 47.64599 | C27: =Reference_Values!B27 -> 47.64599 | D27: =ABS(B27-C27) -> 0 | E27: 1e-09 | F27: =IF(D27<=E27,"PASS","FAIL") -> PASS
A28: Keep investment, $ million | B28: =Cash!B9 -> 29 | C28: =Reference_Values!B28 -> 29 | D28: =ABS(B28-C28) -> 0 | E28: 1e-09 | F28: =IF(D28<=E28,"PASS","FAIL") -> PASS
A29: Extra cost of rebuilding, $ million | B29: =Cash!B13 -> 18.64599 | C29: =Reference_Values!B29 -> 18.64599 | D29: =ABS(B29-C29) -> 0 | E29: 1e-09 | F29: =IF(D29<=E29,"PASS","FAIL") -> PASS
A30: Net proceeds, keep the team | B30: =Cash!B10 -> 63 | C30: =Reference_Values!B30 -> 63 | D30: =ABS(B30-C30) -> 0 | E30: 1e-09 | F30: =IF(D30<=E30,"PASS","FAIL") -> PASS
A31: Net proceeds, let it go and rebuild | B31: =Cash!C10 -> 64.35401 | C31: =Reference_Values!B31 -> 64.35401 | D31: =ABS(B31-C31) -> 0 | E31: 1e-09 | F31: =IF(D31<=E31,"PASS","FAIL") -> PASS
A32: Cap 2.0: quarter capability clears 55 | B32: =Cash!C24 -> 4 | C32: =Reference_Values!B32 -> 4 | D32: =ABS(B32-C32) -> 0 | E32: 0 | F32: =IF(D32<=E32,"PASS","FAIL") -> PASS
A33: Cap 2.0: quarter capability regains 58 | B33: =Cash!C25 -> 9 | C33: =Reference_Values!B33 -> 9 | D33: =ABS(B33-C33) -> 0 | E33: 0 | F33: =IF(D33<=E33,"PASS","FAIL") -> PASS
A34: Cap 2.0: extra cost, $ million | B34: =Cash!C28 -> 17.793435 | C34: =Reference_Values!B34 -> 17.793435 | D34: =ABS(B34-C34) -> 0 | E34: 1e-09 | F34: =IF(D34<=E34,"PASS","FAIL") -> PASS
A35: Attrition 6%: quarter capability clears 55 | B35: =Cash!D24 -> 2 | C35: =Reference_Values!B35 -> 2 | D35: =ABS(B35-C35) -> 0 | E35: 0 | F35: =IF(D35<=E35,"PASS","FAIL") -> PASS
A36: Attrition 6%: quarter capability regains 58 | B36: =Cash!D25 -> 4 | C36: =Reference_Values!B36 -> 4 | D36: =ABS(B36-C36) -> 0 | E36: 0 | F36: =IF(D36<=E36,"PASS","FAIL") -> PASS
A37: Attrition 6%: extra cost, $ million | B37: =Cash!D28 -> 19.386965 | C37: =Reference_Values!B37 -> 19.386965 | D37: =ABS(B37-C37) -> 0 | E37: 1e-09 | F37: =IF(D37<=E37,"PASS","FAIL") -> PASS
A38: Attrition 11%: quarter capability clears 55 | B38: =Cash!E24 -> 3 | C38: =Reference_Values!B38 -> 3 | D38: =ABS(B38-C38) -> 0 | E38: 0 | F38: =IF(D38<=E38,"PASS","FAIL") -> PASS
A39: Attrition 11%: quarter capability regains 58 | B39: =Cash!E25 -> 6 | C39: =Reference_Values!B39 -> 6 | D39: =ABS(B39-C39) -> 0 | E39: 0 | F39: =IF(D39<=E39,"PASS","FAIL") -> PASS
A40: Attrition 11%: extra cost, $ million | B40: =Cash!E28 -> 18.176512 | C40: =Reference_Values!B40 -> 18.176512 | D40: =ABS(B40-C40) -> 0 | E40: 1e-09 | F40: =IF(D40<=E40,"PASS","FAIL") -> PASS
...
