Workbook

Sheet README
B1: DCT Laboratory — Vol I, Ch 3: Mathematical Foundations
B2: Seed 26103 · Companion to DCT_V1_Ch03_Lab.ipynb and AXIOM Lab 1.3 (module AXIOM-03). Money in $ million; Table 3.1 declares liquidity in $ billion.
B4: Worked Example 3.1, Does the Order of Initiatives Matter?, with the book's declarations, and the five steps of AXIOM Lab 1.3, Measuring Meridian.
B5: Declarations: Meridian's state (Table 3.1) with the declared scaling W_M, the terms of Worked Example 3.1, and Section 3.4's three-reading company.
B6: Vector: raw distances to two peer companies with liquidity in billions and in millions, and Proposition 3.2's reversals (lab step 1). The book declares no peers; the notebook draws two with the lab's seed 26103.
B7: Scaling: Figure 3.3's scaled state and the scaled distances, unchanged by the unit of liquidity when the weight moves the opposite way (Proposition 3.3; lab step 2).
B8: Norms: the effort, Euclidean and bottleneck views of the Year-5 moves (Section 5.8) and of the peers, and the constants that link them (Remark 3.B.1; lab step 3).
B9: Sequencing: Worked Example 3.1, Steps 1-5, Table 3.4, the deal terms against the order, and Online Appendix 3.B's commutator split (lab step 4).
B10: Recommend: Step 6, Theorem 3.2(ii), the break-even for the discussion question, and Chapter 6's floor.
B11: RunDown: the three-reading company with no investment and with a held 8, its eigenvalues and the sensitivity factors of the views (Section 3.4; Sections 7.4-7.6; lab step 5).
B12: Every result is a formula of the declarations. Reference_Values and Checks: the notebook engine's numbers and a PASS/FAIL comparison with this workbook's formulas.
B14: LEGEND
... B18: Cross-sheet link: green.

Sheet Declarations
A1: Declarations (Table 3.1; Worked Example 3.1, The situation; Section 3.4). Money in $ million; Table 3.1 declares liquidity in $ billion.
A3: Reading (Table 3.1) | B3: Unit | C3: Today | D3: Family of unit | E3: Declared scale | F3: Weight in W_M | G3: The declared rule
A4: x1 liquidity | B4: US$ billion | C4: 0.62 | D4: currency | E4: =C4 -> 0.62 | F4: =1/E4 -> 1.6129032 | G4: unbounded: divided by today's value
A5: x2 net leverage | B5: net debt / EBITDA | C5: 3.4 | D5: ratio | E5: =C5 -> 3.4 | F5: =1/E5 -> 0.29411765 | G5: unbounded: divided by today's value
A6: x3 workforce capability | B6: index, 0-100 | C6: 58 | D6: index | E6: 100 | F6: =1/E6 -> 0.01 | G6: bounded index: divided by its range
A7: x4 technology platform | B7: index, 0-100 | C7: 41 | D7: index | E7: 100 | F7: =1/E7 -> 0.01 | G7: bounded index: divided by its range
A8: x5 operational efficiency | B8: index, 0-100 | C8: 71 | D8: index | E8: 100 | F8: =1/E8 -> 0.01 | G8: bounded index: divided by its range
A9: x6 return on invested capital | B9: ratio | C9: 0.083 | D9: ratio | E9: =C9 -> 0.083 | F9: =1/E9 -> 12.048193 | G9: unbounded: divided by today's value
A10: x7 strategic risk (lower is better) | B10: index, 0-100 | C10: 64 | D10: index | E10: 100 | F10: =1/E10 -> 0.01 | G10: bounded index: divided by its range
A11: x8 market share | B11: ratio | C11: 0.19 | D11: ratio | E11: =C11 -> 0.19 | F11: =1/E11 -> 5.2631579 | G11: unbounded: divided by today's value
A12: Readings in Meridian's state | C12: =COUNT(C4:C11) -> 8
A13: W_M = diag(1/0.62, 1/3.4, 1/100, 1/100, 1/100, 1/0.083, 1/100, 1/0.19): every scaled reading is unit-free and of order one (Section 3.3; Figure 3.3).
A15: Worked Example 3.1 | B15: Value | C15: Source
A16: Liquidity today ($ million) | B16: =1000*C4 -> 620 | C16: Table 3.1: $0.62 billion
A17: Technology platform today (index) | B17: =C7 -> 41 | C17: Table 3.1
A18: Workforce capability today (index) | B18: =C6 -> 58 | C18: Table 3.1
A19: Net proceeds of the sale of part of Industrial Systems ($ million) | B19: 112 | C19: The situation
A20: Share of the technology position the divested unit takes | B20: 0.1 | C20: The situation
A21: Workforce points lost unless the contract keeps the engineering team | B21: 5 | C21: The situation
A22: Cost of keeping the shared engineering team ($ million of proceeds) | B22: 20 | C22: Step 4
A23: The digital program's liquidity change by Year 5 ($ million): Worked Example 1.1's build, the Chapter 1 model (Eq. 1.B.1, Table 1.B.1) | B23: =6.2*((112+(100-112)*EXP(-0.35*5)+(-28)*(5/2)*EXP(1-5/2))-100) -> -35.367271 | C23: The situation; Table 1.9
A24: The digital program's technology change by Year 5 (points), the same model | B24: =78+(41-78)*EXP(-0.55*5)-41 -> 34.634669 | C24: The situation; Table 1.9
A25: The digital program's domain: workforce capability of at least | B25: 55 | C25: The situation; Section 3.2
A26: Three-reading company (Equation 3.2) | B26: Capability | C26: Technology | D26: Efficiency | E26: Investment B
A27: Row of A: capability | B27: 0.9 | C27: 0.05 | D27: 0 | E27: 0.6
A28: Row of A: technology | B28: 0.1 | C28: 0.85 | D28: 0 | E28: 0.3
A29: Row of A: efficiency | B29: 0.05 | C29: 0.1 | D29: 0.8 | E29: 0
A30: Starting state x0 | B30: 50 | C30: 40 | D30: 60
A31: Investment in the first year, u0 (Section 3.4) | B31: 10
A32: Investment held every year (Chapter 7) | B32: 8
A33: The digital program's low point below its starting liquidity ($ million; Chapter 1 model, bounded minimisation; engine value) | B33: 138.08206 | C33: The situation: $138 million, around month 21
A34: The board's liquidity floor ($ million; Table 5.4, declared in Chapter 5) | B34: 350
A35: Capability, technology and efficiency are indices; entry a_ij is the response of reading i to reading j, and u is annual capability investment: x_(k+1) = A x_k + B u_k.

Sheet Vector
A1: Read the vector: Table 3.1, raw distances to two peers, and Proposition 3.2 (AXIOM Lab 1.3, step 1)
A2: The book declares no peer companies: the notebook draws two with the lab's seed 26103 (green: engine values). A raw distance is the straight-line distance between the readings as recorded.
A4: Reading | B4: Unit | C4: Family | D4: Meridian | E4: Peer A (seed 26103) | F4: Peer B (seed 26103) | G4: Multiplier: liquidity in $ million | H4: Your multipliers (preset: leverage in percent) | I4: (A - M)^2 as recorded | J4: (B - M)^2 as recorded | K4: (A - M)^2, $ million | L4: (B - M)^2, $ million | M4: (A - M)^2, your units | N4: (B - M)^2, your units
A5: =Declarations!A4 -> x1 liquidity | B5: =Declarations!B4 -> US$ billion | C5: =Declarations!D4 -> currency | D5: =Declarations!C4 -> 0.62 | E5: 0.65 | F5: 0.47 | G5: 1000 | H5: 1 | I5: =(E5-D5)^2 -> 0.0009 | J5: =(F5-D5)^2 -> 0.0225 | K5: =((E5-D5)*G5)^2 -> 900 | L5: =((F5-D5)*G5)^2 -> 22500 | M5: =((E5-D5)*H5)^2 -> 0.0009 | N5: =((F5-D5)*H5)^2 -> 0.0225
A6: =Declarations!A5 -> x2 net leverage | B6: =Declarations!B5 -> net debt / EBITDA | C6: =Declarations!D5 -> ratio | D6: =Declarations!C5 -> 3.4 | E6: 3.9 | F6: 3.3 | G6: 1 | H6: 100 | I6: =(E6-D6)^2 -> 0.25 | J6: =(F6-D6)^2 -> 0.01 | K6: =((E6-D6)*G6)^2 -> 0.25 | L6: =((F6-D6)*G6)^2 -> 0.01 | M6: =((E6-D6)*H6)^2 -> 2500 | N6: =((F6-D6)*H6)^2 -> 100
A7: =Declarations!A6 -> x3 workforce capability | B7: =Declarations!B6 -> index, 0-100 | C7: =Declarations!D6 -> index | D7: =Declarations!C6 -> 58 | E7: 59 | F7: 54 | G7: 1 | H7: 1 | I7: =(E7-D7)^2 -> 1 | J7: =(F7-D7)^2 -> 16 | K7: =((E7-D7)*G7)^2 -> 1 | L7: =((F7-D7)*G7)^2 -> 16 | M7: =((E7-D7)*H7)^2 -> 1 | N7: =((F7-D7)*H7)^2 -> 16
A8: =Declarations!A7 -> x4 technology platform | B8: =Declarations!B7 -> index, 0-100 | C8: =Declarations!D7 -> index | D8: =Declarations!C7 -> 41 | E8: 37 | F8: 47 | G8: 1 | H8: 1 | I8: =(E8-D8)^2 -> 16 | J8: =(F8-D8)^2 -> 36 | K8: =((E8-D8)*G8)^2 -> 16 | L8: =((F8-D8)*G8)^2 -> 36 | M8: =((E8-D8)*H8)^2 -> 16 | N8: =((F8-D8)*H8)^2 -> 36
A9: =Declarations!A8 -> x5 operational efficiency | B9: =Declarations!B8 -> index, 0-100 | C9: =Declarations!D8 -> index | D9: =Declarations!C8 -> 71 | E9: 74 | F9: 58 | G9: 1 | H9: 1 | I9: =(E9-D9)^2 -> 9 | J9: =(F9-D9)^2 -> 169 | K9: =((E9-D9)*G9)^2 -> 9 | L9: =((F9-D9)*G9)^2 -> 169 | M9: =((E9-D9)*H9)^2 -> 9 | N9: =((F9-D9)*H9)^2 -> 169
A10: =Declarations!A9 -> x6 return on invested capital | B10: =Declarations!B9 -> ratio | C10: =Declarations!D9 -> ratio | D10: =Declarations!C9 -> 0.083 | E10: 0.072 | F10: 0.085 | G10: 1 | H10: 1 | I10: =(E10-D10)^2 -> 0.000121 | J10: =(F10-D10)^2 -> 4e-06 | K10: =((E10-D10)*G10)^2 -> 0.000121 | L10: =((F10-D10)*G10)^2 -> 4e-06 | M10: =((E10-D10)*H10)^2 -> 0.000121 | N10: =((F10-D10)*H10)^2 -> 4e-06
A11: =Declarations!A10 -> x7 strategic risk (lower is better) | B11: =Declarations!B10 -> index, 0-100 | C11: =Declarations!D10 -> index | D11: =Declarations!C10 -> 64 | E11: 68 | F11: 79 | G11: 1 | H11: 1 | I11: =(E11-D11)^2 -> 16 | J11: =(F11-D11)^2 -> 225 | K11: =((E11-D11)*G11)^2 -> 16 | L11: =((F11-D11)*G11)^2 -> 225 | M11: =((E11-D11)*H11)^2 -> 16 | N11: =((F11-D11)*H11)^2 -> 225
A12: =Declarations!A11 -> x8 market share | B12: =Declarations!B11 -> ratio | C12: =Declarations!D11 -> ratio | D12: =Declarations!C11 -> 0.19 | E12: 0.2 | F12: 0.17 | G12: 1 | H12: 1 | I12: =(E12-D12)^2 -> 0.0001 | J12: =(F12-D12)^2 -> 0.0004 | K12: =((E12-D12)*G12)^2 -> 0.0001 | L12: =((F12-D12)*G12)^2 -> 0.0004 | M12: =((E12-D12)*H12)^2 -> 0.0001 | N12: =((F12-D12)*H12)^2 -> 0.0004
A14: Raw distance to Peer A, liquidity in $ billion | D14: =SQRT(SUM(I5:I12)) -> 6.5000862
A15: Raw distance to Peer B, liquidity in $ billion | D15: =SQRT(SUM(J5:J12)) -> 21.119491
A16: Closer peer, liquidity in $ billion (1 = Peer A, 2 = Peer B) | D16: =IF(D14<D15,1,2) -> 1
A17: Raw distance to Peer A, liquidity in $ million | D17: =SQRT(SUM(K5:K12)) -> 30.696095
A18: Raw distance to Peer B, liquidity in $ million | D18: =SQRT(SUM(L5:L12)) -> 151.47941
A19: Closer peer, liquidity in $ million (1 = Peer A, 2 = Peer B) | D19: =IF(D17<D18,1,2) -> 1
A20: Does the closer peer change? (1 = yes) | D20: =IF(D16=D19,0,1) -> 0
A21: Peer A: share of its squared distance from the indices, $ billion | D21: =SUMIF(C5:C12,"index",I5:I12)/SUM(I5:I12) -> 0.99405647
A22: Peer A: share of its squared distance from liquidity, $ million | D22: =K5/SUM(K5:K12) -> 0.9551603
A23: Raw distance to Peer A, your units | D23: =SQRT(SUM(M5:M12)) -> 50.418262
A24: Raw distance to Peer B, your units | D24: =SQRT(SUM(N5:N12)) -> 23.367133
A25: Closer peer, your units (1 = Peer A, 2 = Peer B) | D25: =IF(D23<D24,1,2) -> 2
A27: Strategic risk exceeds net leverage, as recorded? (1 = yes) | D27: =IF(D11>D6,1,0) -> 1
A28: Net leverage in percent | D28: =100*D6 -> 340
A29: Strategic risk exceeds net leverage in percent? (1 = yes) | D29: =IF(D11>D28,1,0) -> 0
A30: An undeclared total of the raw readings, as recorded | D30: =SUM(D5:D12) -> 238.293
A31: The same total with liquidity in $ million | D31: =SUMPRODUCT(D5:D12,G5:G12) -> 857.673
A33: Peer pairs drawn the same way (notebook, seed 26103) | D33: 10000
A34: share whose closer peer changes when liquidity switches to millions | D34: 0.4327
A36: Proposition 3.2: changing units loses no information, but a raw comparison across readings, or a total without declared weights, can be reversed by a legitimate change of units. Change column H to try others.

Sheet Scaling
A1: Declare the scaling: W_M, Figure 3.3, and Proposition 3.3 (AXIOM Lab 1.3, step 2)
A2: W_M divides unbounded readings by today's value and bounded indices by their range. Applied in whatever unit a reading is recorded, the rule moves the weight the opposite way to the unit.
A4: Reading | B4: Today | C4: Declared scale | D4: Scaled today (Figure 3.3) | E4: Peer A scaled | F4: Peer B scaled | G4: (A - M)^2 scaled | H4: (B - M)^2 scaled | I4: Liquidity in $ million: today | J4: Declared scale in that unit | K4: Peer A in that unit | L4: Peer B in that unit | M4: (A - M)^2 scaled, that unit | N4: (B - M)^2 scaled, that unit | O4: Peer A's share | P4: Peer B's share
A5: =Declarations!A4 -> x1 liquidity | B5: =Declarations!C4 -> 0.62 | C5: =Declarations!E4 -> 0.62 | D5: =B5/C5 -> 1 | E5: =Vector!E5/C5 -> 1.0483871 | F5: =Vector!F5/C5 -> 0.75806452 | G5: =(E5-D5)^2 -> 0.0023413111 | H5: =(F5-D5)^2 -> 0.058532778 | I5: =B5*Vector!G5 -> 620 | J5: =IF(Declarations!D4="index",Declarations!E4,I5) -> 620 | K5: =Vector!E5*Vector!G5 -> 650 | L5: =Vector!F5*Vector!G5 -> 470 | M5: =((K5-I5)/J5)^2 -> 0.0023413111 | N5: =((L5-I5)/J5)^2 -> 0.058532778 | O5: =G5/SUM(G$5:G$12) -> 0.048272541 | P5: =H5/SUM(H$5:H$12) -> 0.5060815
A6: =Declarations!A5 -> x2 net leverage | B6: =Declarations!C5 -> 3.4 | C6: =Declarations!E5 -> 3.4 | D6: =B6/C6 -> 1 | E6: =Vector!E6/C6 -> 1.1470588 | F6: =Vector!F6/C6 -> 0.97058824 | G6: =(E6-D6)^2 -> 0.021626298 | H6: =(F6-D6)^2 -> 0.0008650519 | I6: =B6*Vector!G6 -> 3.4 | J6: =IF(Declarations!D5="index",Declarations!E5,I6) -> 3.4 | K6: =Vector!E6*Vector!G6 -> 3.9 | L6: =Vector!F6*Vector!G6 -> 3.3 | M6: =((K6-I6)/J6)^2 -> 0.021626298 | N6: =((L6-I6)/J6)^2 -> 0.0008650519 | O6: =G6/SUM(G$5:G$12) -> 0.44588535 | P6: =H6/SUM(H$5:H$12) -> 0.0074793437
A7: =Declarations!A6 -> x3 workforce capability | B7: =Declarations!C6 -> 58 | C7: =Declarations!E6 -> 100 | D7: =B7/C7 -> 0.58 | E7: =Vector!E7/C7 -> 0.59 | F7: =Vector!F7/C7 -> 0.54 | G7: =(E7-D7)^2 -> 0.0001 | H7: =(F7-D7)^2 -> 0.0016 | I7: =B7*Vector!G7 -> 58 | J7: =IF(Declarations!D6="index",Declarations!E6,I7) -> 100 | K7: =Vector!E7*Vector!G7 -> 59 | L7: =Vector!F7*Vector!G7 -> 54 | M7: =((K7-I7)/J7)^2 -> 0.0001 | N7: =((L7-I7)/J7)^2 -> 0.0016 | O7: =G7/SUM(G$5:G$12) -> 0.0020617739 | P7: =H7/SUM(H$5:H$12) -> 0.013833794
A8: =Declarations!A7 -> x4 technology platform | B8: =Declarations!C7 -> 41 | C8: =Declarations!E7 -> 100 | D8: =B8/C8 -> 0.41 | E8: =Vector!E8/C8 -> 0.37 | F8: =Vector!F8/C8 -> 0.47 | G8: =(E8-D8)^2 -> 0.0016 | H8: =(F8-D8)^2 -> 0.0036 | I8: =B8*Vector!G8 -> 41 | J8: =IF(Declarations!D7="index",Declarations!E7,I8) -> 100 | K8: =Vector!E8*Vector!G8 -> 37 | L8: =Vector!F8*Vector!G8 -> 47 | M8: =((K8-I8)/J8)^2 -> 0.0016 | N8: =((L8-I8)/J8)^2 -> 0.0036 | O8: =G8/SUM(G$5:G$12) -> 0.032988382 | P8: =H8/SUM(H$5:H$12) -> 0.031126037
A9: =Declarations!A8 -> x5 operational efficiency | B9: =Declarations!C8 -> 71 | C9: =Declarations!E8 -> 100 | D9: =B9/C9 -> 0.71 | E9: =Vector!E9/C9 -> 0.74 | F9: =Vector!F9/C9 -> 0.58 | G9: =(E9-D9)^2 -> 0.0009 | H9: =(F9-D9)^2 -> 0.0169 | I9: =B9*Vector!G9 -> 71 | J9: =IF(Declarations!D8="index",Declarations!E8,I9) -> 100 | K9: =Vector!E9*Vector!G9 -> 74 | L9: =Vector!F9*Vector!G9 -> 58 | M9: =((K9-I9)/J9)^2 -> 0.0009 | N9: =((L9-I9)/J9)^2 -> 0.0169 | O9: =G9/SUM(G$5:G$12) -> 0.018555965 | P9: =H9/SUM(H$5:H$12) -> 0.14611945
A10: =Declarations!A9 -> x6 return on invested capital | B10: =Declarations!C9 -> 0.083 | C10: =Declarations!E9 -> 0.083 | D10: =B10/C10 -> 1 | E10: =Vector!E10/C10 -> 0.86746988 | F10: =Vector!F10/C10 -> 1.0240964 | G10: =(E10-D10)^2 -> 0.017564233 | H10: =(F10-D10)^2 -> 0.0005806358 | I10: =B10*Vector!G10 -> 0.083 | J10: =IF(Declarations!D9="index",Declarations!E9,I10) -> 0.083 | K10: =Vector!E10*Vector!G10 -> 0.072 | L10: =Vector!F10*Vector!G10 -> 0.085 | M10: =((K10-I10)/J10)^2 -> 0.017564233 | N10: =((L10-I10)/J10)^2 -> 0.0005806358 | O10: =G10/SUM(G$5:G$12) -> 0.36213476 | P10: =H10/SUM(H$5:H$12) -> 0.0050202475
A11: =Declarations!A10 -> x7 strategic risk (lower is better) | B11: =Declarations!C10 -> 64 | C11: =Declarations!E10 -> 100 | D11: =B11/C11 -> 0.64 | E11: =Vector!E11/C11 -> 0.68 | F11: =Vector!F11/C11 -> 0.79 | G11: =(E11-D11)^2 -> 0.0016 | H11: =(F11-D11)^2 -> 0.0225 | I11: =B11*Vector!G11 -> 64 | J11: =IF(Declarations!D10="index",Declarations!E10,I11) -> 100 | K11: =Vector!E11*Vector!G11 -> 68 | L11: =Vector!F11*Vector!G11 -> 79 | M11: =((K11-I11)/J11)^2 -> 0.0016 | N11: =((L11-I11)/J11)^2 -> 0.0225 | O11: =G11/SUM(G$5:G$12) -> 0.032988382 | P11: =H11/SUM(H$5:H$12) -> 0.19453773
A12: =Declarations!A11 -> x8 market share | B12: =Declarations!C11 -> 0.19 | C12: =Declarations!E11 -> 0.19 | D12: =B12/C12 -> 1 | E12: =Vector!E12/C12 -> 1.0526316 | F12: =Vector!F12/C12 -> 0.89473684 | G12: =(E12-D12)^2 -> 0.0027700831 | H12: =(F12-D12)^2 -> 0.011080332 | I12: =B12*Vector!G12 -> 0.19 | J12: =IF(Declarations!D11="index",Declarations!E11,I12) -> 0.19 | K12: =Vector!E12*Vector!G12 -> 0.2 | L12: =Vector!F12*Vector!G12 -> 0.17 | M12: =((K12-I12)/J12)^2 -> 0.0027700831 | N12: =((L12-I12)/J12)^2 -> 0.011080332 | O12: =G12/SUM(G$5:G$12) -> 0.057112849 | P12: =H12/SUM(H$5:H$12) -> 0.095801898
A14: Readings at 1.00 after scaling | D14: =SUMPRODUCT(--(ABS(D5:D12-1)<0.000000000001)) -> 4
A15: Scaled distance to Peer A, liquidity in $ billion | D15: =SQRT(SUM(G5:G12)) -> 0.22023153
A16: Scaled distance to Peer B, liquidity in $ billion | D16: =SQRT(SUM(H5:H12)) -> 0.34008646
A17: Scaled distance to Peer A, liquidity in $ million | D17: =SQRT(SUM(M5:M12)) -> 0.22023153
A18: Scaled distance to Peer B, liquidity in $ million | D18: =SQRT(SUM(N5:N12)) -> 0.34008646
A19: Largest gap between the two units (Proposition 3.3) | D19: =MAX(ABS(D15-D17),ABS(D16-D18)) -> 0
A20: Closer peer, declared scaling (1 = Peer A, 2 = Peer B) | D20: =IF(D15<D16,1,2) -> 1
A21: Weight left at 1/0.62 in millions: distance to Peer A | D21: =SQRT(G5*Vector!G5^2+SUM(G6:G12)) -> 48.387574
A22: Largest share of a squared distance from one reading | D22: =MAX(O5:P12) -> 0.5060815
A24: Proposition 3.3: a weighted distance gives the same answer after a change of units only if its weights change in the opposite direction. Leaving liquidity's weight at 1/0.62 while recording millions makes liquidity a thousand times too heavy.

Sheet Norms
A1: Compare distance measures: the effort, Euclidean and bottleneck views (Definition 3.5; Theorem 3.1; Remark 3.B.1; Section 5.8; AXIOM Lab 1.3, step 3)
A3: Reading (Chapter 1 model; Table 1.9) | B3: Declared scale | C3: Today | D3: Turnaround | E3: Restructuring | F3: Digital | H3: The peers: scaled move |peer - Meridian| | I3: Peer A | J3: Peer B
A4: Liquidity (index, today = 100 = $0.62 billion) | B4: 100 | C4: 100 | D4: 105.4 | E4: 121.1 | F4: 94.3 | H4: =Declarations!A4 -> x1 liquidity | I4: =SQRT(Scaling!G5) -> 0.048387097 | J4: =SQRT(Scaling!H5) -> 0.24193548
A5: Technology platform | B5: 100 | C5: 41 | D5: 35.9 | E5: 38.9 | F5: 75.6 | H5: =Declarations!A5 -> x2 net leverage | I5: =SQRT(Scaling!G6) -> 0.14705882 | J5: =SQRT(Scaling!H6) -> 0.029411765
A6: Operational efficiency | B6: 100 | C6: 71 | D6: 78.6 | E6: 73.7 | F6: 73.6 | H6: =Declarations!A6 -> x3 workforce capability | I6: =SQRT(Scaling!G7) -> 0.01 | J6: =SQRT(Scaling!H7) -> 0.04
A7: Strategic risk | B7: 100 | C7: 64 | D7: 66.3 | E7: 49.4 | F7: 55.2 | H7: =Declarations!A7 -> x4 technology platform | I7: =SQRT(Scaling!G8) -> 0.04 | J7: =SQRT(Scaling!H8) -> 0.06
A8: W_M divides liquidity by today's value: 100 in index units. The other four readings do not move in the Chapter 1 model. | H8: =Declarations!A8 -> x5 operational efficiency | I8: =SQRT(Scaling!G9) -> 0.03 | J8: =SQRT(Scaling!H9) -> 0.13
A9: Scaled move: |Year 5 - today| / scale | D9: Turnaround | E9: Restructuring | F9: Digital | H9: =Declarations!A9 -> x6 return on invested capital | I9: =SQRT(Scaling!G10) -> 0.13253012 | J9: =SQRT(Scaling!H10) -> 0.024096386
A10: Liquidity (index, today = 100 = $0.62 billion) | D10: =ABS(D4-$C4)/$B4 -> 0.054 | E10: =ABS(E4-$C4)/$B4 -> 0.211 | F10: =ABS(F4-$C4)/$B4 -> 0.057 | H10: =Declarations!A10 -> x7 strategic risk (lower is better) | I10: =SQRT(Scaling!G11) -> 0.04 | J10: =SQRT(Scaling!H11) -> 0.15
A11: Technology platform | D11: =ABS(D5-$C5)/$B5 -> 0.051 | E11: =ABS(E5-$C5)/$B5 -> 0.021 | F11: =ABS(F5-$C5)/$B5 -> 0.346 | H11: =Declarations!A11 -> x8 market share | I11: =SQRT(Scaling!G12) -> 0.052631579 | J11: =SQRT(Scaling!H12) -> 0.10526316
A12: Operational efficiency | D12: =ABS(D6-$C6)/$B6 -> 0.076 | E12: =ABS(E6-$C6)/$B6 -> 0.027 | F12: =ABS(F6-$C6)/$B6 -> 0.026
A13: Strategic risk | D13: =ABS(D7-$C7)/$B7 -> 0.023 | E13: =ABS(E7-$C7)/$B7 -> 0.146 | F13: =ABS(F7-$C7)/$B7 -> 0.088 | H13: Effort view | I13: =SUM(I4:I11) -> 0.50060762 | J13: =SUM(J4:J11) -> 0.78070679
H14: Euclidean view | I14: =SQRT(SUMSQ(I4:I11)) -> 0.22023153 | J14: =SQRT(SUMSQ(J4:J11)) -> 0.34008646
A15: Effort view: the sum of the moves | D15: =SUM(D10:D13) -> 0.204 | E15: =SUM(E10:E13) -> 0.405 | F15: =SUM(F10:F13) -> 0.517 | H15: Bottleneck view | I15: =MAX(I4:I11) -> 0.14705882 | J15: =MAX(J4:J11) -> 0.24193548
A16: Euclidean view (Section 5.8: 0.11, 0.26, 0.36) | D16: =SQRT(SUMSQ(D10:D13)) -> 0.10872902 | E16: =SQRT(SUMSQ(E10:E13)) -> 0.2588571 | F16: =SQRT(SUMSQ(F10:F13)) -> 0.36247069 | H16: Effort / bottleneck | I16: =I13/I15 -> 3.4041318 | J16: =J13/J15 -> 3.2269214
A17: Bottleneck view: the largest move | D17: =MAX(D10:D13) -> 0.076 | E17: =MAX(E10:E13) -> 0.211 | F17: =MAX(F10:F13) -> 0.346
A18: Effort / bottleneck | D18: =D15/D17 -> 2.6842105 | E18: =E15/E17 -> 1.9194313 | F18: =F15/F17 -> 1.4942197 | H18: Closer peer, effort view (1 = Peer A) | I18: =IF(I13<J13,1,2) -> 1
A19: Euclidean / bottleneck | D19: =D16/D17 -> 1.430645 | E19: =E16/E17 -> 1.2268109 | F19: =F16/F17 -> 1.0476031 | H19: Closer peer, Euclidean view | I19: =IF(I14<J14,1,2) -> 1
A20: Effort / Euclidean | D20: =D15/D16 -> 1.876224 | E20: =E15/E16 -> 1.5645698 | F20: =F15/F16 -> 1.4263222 | H20: Closer peer, bottleneck view | I20: =IF(I15<J15,1,2) -> 1
A23: The constants (Remark 3.B.1) | B23: Every reading moves by 1 | C23: Only the first moves by 1
A24: =Declarations!A4 -> x1 liquidity | B24: 1 | C24: 1
A25: =Declarations!A5 -> x2 net leverage | B25: 1 | C25: 0
A26: =Declarations!A6 -> x3 workforce capability | B26: 1 | C26: 0
A27: =Declarations!A7 -> x4 technology platform | B27: 1 | C27: 0
A28: =Declarations!A8 -> x5 operational efficiency | B28: 1 | C28: 0
A29: =Declarations!A9 -> x6 return on invested capital | B29: 1 | C29: 0
A30: =Declarations!A10 -> x7 strategic risk (lower is better) | B30: 1 | C30: 0
A31: =Declarations!A11 -> x8 market share | B31: 1 | C31: 0
A33: Effort view | B33: =SUM(B24:B31) -> 8 | C33: =SUM(C24:C31) -> 1
A34: Euclidean view | B34: =SQRT(SUMSQ(B24:B31)) -> 2.8284271 | C34: =SQRT(SUMSQ(C24:C31)) -> 1
A35: Bottleneck view | B35: =MAX(B24:B31) -> 1 | C35: =MAX(C24:C31) -> 1
A36: Effort / bottleneck: n at most, attained by equal moves | B36: =B33/B35 -> 8 | C36: =C33/C35 -> 1
A37: Effort / Euclidean: the square root of n at most | B37: =B33/B34 -> 2.8284271 | C37: =C33/C34 -> 1
A39: Readings, n | B39: =N_read -> 8
A40: Square root of n | B40: =SQRT(B39) -> 2.8284271
A41: Every Year-5 move and both peers inside [1, n] for effort / bottleneck (1 = yes) | B41: =IF(AND(MIN(D18:F18,I16:J16)>=1,MAX(D18:F18,I16:J16)<=B39),1,0) -> 1
A43: Over the notebook's 10,000 peer pairs (seed 26103): smallest effort / bottleneck | B43: 1.34875
A44: largest effort / bottleneck | B44: 6.7377
A45: share of pairs on which the effort and bottleneck views name different closer peers | B45: 0.2481
A47: Theorem 3.1: all norms agree on which sequences converge, which sets are open, which mappings are continuous and which states are stable; they disagree only on the numbers, and a ranking is a number.

Sheet Sequencing
A1: Sequence the initiatives: Worked Example 3.1, Steps 1-5, and Table 3.4 (Proposition 3.1; Theorem 3.2(iii); Online Appendix 3.B; AXIOM Lab 1.3, step 4)
A2: A state is (liquidity $ million, technology platform index, workforce capability index). The digital program runs only from workforce capability of at least 55, its domain; Feasible is 1 when a step can start. The digital program is Worked Example 1.1's build: its Year-5 changes add to the state it starts from, and its cash bottoms $138 million below its start around month 21.
A4: State | B4: Liquidity | C4: Technology | D4: Workforce | E4: Low point on the way ($ million) | F4: Feasible (1 = yes)
A5: Today | B5: =Liq_today -> 620 | C5: =Tech_today -> 41 | D5: =Work_today -> 58
A6: Step 1: the sale alone (the engineers go with the unit) | B6: =B5+Sale_net -> 732 | C6: =(1-Tech_share)*C5 -> 36.9 | D6: =D5-W_loss -> 53 | F6: 1
A7: its change | B7: =B6-B5 -> 112 | C7: =C6-C5 -> -4.1 | D7: =D6-D5 -> -5
A8: Step 1: the digital program alone | B8: =B5+Build_liq -> 584.63273 | C8: =C5+Build_tech -> 75.634669 | D8: =D5 -> 58 | E8: =IF(F8=1,B5-Build_dip,"") -> 481.91794 | F8: =IF(D5>=W_min,1,0) -> 1
A9: its change | B9: =B8-B5 -> -35.367271 | C9: =C8-C5 -> 34.634669 | D9: =D8-D5 -> 0
A10: Bag of initiatives: today plus both changes | B10: =B5+B7+B9 -> 696.63273 | C10: =C5+C7+C9 -> 71.534669 | D10: =D5+D7+D9 -> 53
A12: Step 2: restructure, then digital (as designed): after the sale | B12: =B5+Sale_net -> 732 | C12: =(1-Tech_share)*C5 -> 36.9 | D12: =D5-W_loss -> 53 | F12: 1
A13: then the digital program | B13: =IF(F13=1,B12+Build_liq,"infeasible") -> infeasible | C13: =IF(F13=1,C12+Build_tech,"infeasible") -> infeasible | D13: =IF(F13=1,D12,"infeasible") -> infeasible | E13: =IF(F13=1,B12-Build_dip,"") | F13: =IF(D12>=W_min,1,0) -> 0
A15: Step 3: digital, then restructure: after the build | B15: =B5+Build_liq -> 584.63273 | C15: =C5+Build_tech -> 75.634669 | D15: =D5 -> 58 | E15: =IF(F15=1,B5-Build_dip,"") -> 481.91794 | F15: =IF(D5>=W_min,1,0) -> 1
A16: then the sale | B16: =B15+Sale_net -> 696.63273 | C16: =(1-Tech_share)*C15 -> 68.071202 | D16: =D15-W_loss -> 53 | F16: 1
A18: Step 4: restructure (engineers kept), then digital: after the sale | B18: =B5+Sale_net-Keep_cost -> 712 | C18: =(1-Tech_share)*C5 -> 36.9 | D18: =D5 -> 58 | F18: 1
A19: then the digital program | B19: =B18+Build_liq -> 676.63273 | C19: =C18+Build_tech -> 71.534669 | D19: =D18 -> 58 | E19: =IF(F19=1,B18-Build_dip,"") -> 573.91794 | F19: =IF(D18>=W_min,1,0) -> 1
A21: Digital, then the sale with the engineers kept (the same terms in both orders; not in Table 3.4) | B21: =B15+Sale_net-Keep_cost -> 676.63273 | C21: =(1-Tech_share)*C15 -> 68.071202 | D21: =D15 -> 58 | F21: 1
A23: Table 3.4 | B23: Liquidity | C23: Technology | D23: Workforce
A24: Today | B24: =B5 -> 620 | C24: =C5 -> 41 | D24: =D5 -> 58
A25: Bag of initiatives (each appraised alone, then added) | B25: =B10 -> 696.63273 | C25: =C10 -> 71.534669 | D25: =D10 -> 53
A26: Restructure, then digital (as designed) | B26: =B13 -> infeasible | C26: =C13 -> infeasible | D26: =D13 -> infeasible
A27: Digital, then restructure | B27: =B16 -> 696.63273 | C27: =C16 -> 68.071202 | D27: =D16 -> 53
A28: Restructure (engineers kept), then digital | B28: =B19 -> 676.63273 | C28: =C19 -> 71.534669 | D28: =D19 -> 58
A31: Step 5: digital-first minus restructure-first | B31: Liquidity | C31: Technology | D31: Workforce
A32: The gap between Table 3.4's two feasible orders | B32: =B16-B19 -> 20 | C32: =C16-C19 -> -3.4634669 | D32: =D16-D19 -> -5
A33: deal terms: digital first, engineers gone minus kept | B33: =B16-B21 -> 20 | C33: =C16-C21 -> 0 | D33: =D16-D21 -> -5
A34: order: the same terms (engineers kept), digital first minus the sale first | B34: =B21-B19 -> 0 | C34: =C21-C19 -> -3.4634669 | D34: =D21-D19 -> 0
A35: deal terms + order - gap | B35: =B33+B34-B32 -> 0 | C35: =C33+C34-C32 -> 0 | D35: =D33+D34-D32 -> 0
A37: Online Appendix 3.B: R = the sale (engineers kept), A_R and b_R | B37: Column 1 | C37: Column 2 | D37: Column 3 | E37: b_R
A38: Row 1 | B38: =1 -> 1 | C38: =0 -> 0 | D38: =0 -> 0 | E38: =Sale_net-Keep_cost -> 92
A39: Row 2 | B39: =0 -> 0 | C39: =1-Tech_share -> 0.9 | D39: =0 -> 0 | E39: 0
A40: Row 3 | B40: =0 -> 0 | C40: =0 -> 0 | D40: =1 -> 1 | E40: 0
A41: D = the digital program, A_D and b_D (a pure shift) | B41: Column 1 | C41: Column 2 | D41: Column 3 | E41: b_D
A42: Row 1 | B42: =1 -> 1 | C42: =0 -> 0 | D42: =0 -> 0 | E42: =Build_liq -> -35.367271
A43: Row 2 | B43: =0 -> 0 | C43: =1 -> 1 | D43: =0 -> 0 | E43: =Build_tech -> 34.634669
A44: Row 3 | B44: =0 -> 0 | C44: =0 -> 0 | D44: =1 -> 1 | E44: 0
A45: A_D A_R | B45: Column 1 | C45: Column 2 | D45: Column 3
A46: Row 1 | B46: =$B$42*$B$38+$C$42*$B$39+$D$42*$B$40 -> 1 | C46: =$B$42*$C$38+$C$42*$C$39+$D$42*$C$40 -> 0 | D46: =$B$42*$D$38+$C$42*$D$39+$D$42*$D$40 -> 0
A47: Row 2 | B47: =$B$43*$B$38+$C$43*$B$39+$D$43*$B$40 -> 0 | C47: =$B$43*$C$38+$C$43*$C$39+$D$43*$C$40 -> 0.9 | D47: =$B$43*$D$38+$C$43*$D$39+$D$43*$D$40 -> 0
A48: Row 3 | B48: =$B$44*$B$38+$C$44*$B$39+$D$44*$B$40 -> 0 | C48: =$B$44*$C$38+$C$44*$C$39+$D$44*$C$40 -> 0 | D48: =$B$44*$D$38+$C$44*$D$39+$D$44*$D$40 -> 1
A49: A_R A_D | B49: Column 1 | C49: Column 2 | D49: Column 3
...

Sheet Recommend
A1: Recommend: Worked Example 3.1, Step 6; Theorem 3.2(ii); the discussion question; Chapter 6's floor
A3: Theorem 3.2(ii): sensitivities multiply along a program | B3: Value
A4: Sensitivity factor of a mild step | B4: 1.2
A5: Sensitivity factor of a consolidating step | B5: 0.7
A6: Five mild steps: the program's factor is at most | B6: =B4^5 -> 2.48832
A7: Three mild and two consolidating steps: at most | B7: =B4^3*B5^2 -> 0.84672
A9: For discussion: cash against platform strength | B9: Value
A10: Extra cash at the end, digital-first ($ million) | B10: =Sequencing!B32 -> 20
A11: Extra platform points, restructure-first with the engineers kept | B11: =-Sequencing!C32 -> 3.4634669
A12: Extra workforce points, restructure-first with the engineers kept | B12: =-Sequencing!D32 -> 5
A13: Value of a workforce point ($ million): what the retention clause charges | B13: =Keep_cost/W_loss -> 4
A14: Break-even value of a platform point ($ million) | B14: =(B10-B13*B12)/B11 -> 0
A15: Above the break-even, restructure-first with the engineers kept is worth more; below it, digital-first. At the clause's price the break-even is $0: digital-first's extra cash is the clause itself. The book leaves these values to the board; replace B13 to try another price of capability.
A17: Chapter 6: the board's floor (Table 5.4) | B17: Value
A18: Liquidity floor ($ million) | B18: =Liq_floor -> 350
A19: Digital, then restructure: lowest liquidity on the way | B19: =MIN(Sequencing!B5,Sequencing!E15,Sequencing!B16) -> 481.91794
A20: against the floor | B20: =B19-B18 -> 131.91794
A21: Restructure (engineers kept), then digital: lowest liquidity on the way | B21: =MIN(Sequencing!B5,Sequencing!B18,Sequencing!E19) -> 573.91794
A22: against the floor | B22: =B21-B18 -> 223.91794
A23: Sections 6.5-6.6: on the floor both orders run; the build needs liquidity of at least $488 million when it starts, so that its low point respects the floor.

Sheet RunDown
A1: Watch a company run down: Section 3.4's three-reading company (Equation 3.2; Table 3.2; Sections 7.4-7.6; AXIOM Lab 1.3, step 5)
A3: Quantity | B3: Capability | C3: Technology | D3: Efficiency
A4: One year from x0 = (50, 40, 60) with u0 = 10 (Section 3.4) | B4: =Declarations!$B$27*Declarations!$B$30+Declarations!$C$27*Declarations!$C$30+Declarations!$D$27*Declarations!$D$30+Declarations!$E$27*U_first -> 53 | C4: =Declarations!$B$28*Declarations!$B$30+Declarations!$C$28*Declarations!$C$30+Declarations!$D$28*Declarations!$D$30+Declarations!$E$28*U_first -> 42 | D4: =Declarations!$B$29*Declarations!$B$30+Declarations!$C$29*Declarations!$C$30+Declarations!$D$29*Declarations!$D$30+Declarations!$E$29*U_first -> 54.5
A6: Eigenvalues and sensitivity factors | B6: Value
A7: Trace of the capability-technology block | B7: =Declarations!$B$27+Declarations!$C$28 -> 1.75
A8: Determinant of that block | B8: =Declarations!$B$27*Declarations!$C$28-Declarations!$C$27*Declarations!$B$28 -> 0.76
A9: Largest eigenvalue | B9: =(B7+SQRT(B7^2-4*B8))/2 -> 0.95
A10: Second eigenvalue | B10: =(B7-SQRT(B7^2-4*B8))/2 -> 0.8
A11: Third eigenvalue, a33 | B11: =Declarations!$D$29 -> 0.8
A12: Check: a13 = a23 = 0, so A is block lower-triangular (1 = yes) | B12: =IF(AND(Declarations!$D$27=0,Declarations!$D$28=0),1,0) -> 1
A13: Spectral radius (Table 3.2) | B13: =MAX(ABS(B9),ABS(B10),ABS(B11)) -> 0.95
A14: Half-life of the slowest mode, years (Section 7.6) | B14: =LN(0.5)/LN(B13) -> 13.513407
A15: One-year sensitivity factor, bottleneck view: the largest row sum | B15: =MAX(ABS(Declarations!$B$27)+ABS(Declarations!$C$27)+ABS(Declarations!$D$27),ABS(Declarations!$B$28)+ABS(Declarations!$C$28)+ABS(Declarations!$D$28),ABS(Declarations!$B$29)+ABS(Declarations!$C$29)+ABS(Declarations!$D$29)) -> 0.95
A16: One-year sensitivity factor, effort view: the largest column sum | B16: =MAX(ABS(Declarations!$B$27)+ABS(Declarations!$B$28)+ABS(Declarations!$B$29),ABS(Declarations!$C$27)+ABS(Declarations!$C$28)+ABS(Declarations!$C$29),ABS(Declarations!$D$27)+ABS(Declarations!$D$28)+ABS(Declarations!$D$29)) -> 1.05
A18: Steady state under a held investment (Section 7.5) | B18: Capability | C18: Technology | D18: Efficiency
A19: Added by each unit of investment held forever | B19: =(Declarations!$E$27*(1-Declarations!$C$28)+Declarations!$C$27*Declarations!$E$28)/((1-Declarations!$B$27)*(1-Declarations!$C$28)-Declarations!$C$27*Declarations!$B$28) -> 10.5 | C19: =((1-Declarations!$B$27)*Declarations!$E$28+Declarations!$B$28*Declarations!$E$27)/((1-Declarations!$B$27)*(1-Declarations!$C$28)-Declarations!$C$27*Declarations!$B$28) -> 9 | D19: =(Declarations!$B$29*B19+Declarations!$C$29*C19+Declarations!$E$29)/(1-Declarations!$D$29) -> 7.125
A20: Under the held investment of Declarations!B32 | B20: =B19*U_held -> 84 | C20: =C19*U_held -> 72 | D20: =D19*U_held -> 57
A22: Technology at year 10: momentum alone (Section 7.4) | B22: =C38 -> 27.225229 | D22: Effort view of A^k: its peak over years 1-30 | G22: =MAX(Q29:Q58) -> 1.1174819
A23: Technology at year 10: with the held investment | B23: =F38 -> 52.185268 | D23: reached in year | G23: =INDEX(A29:A58,MATCH(G22,Q29:Q58,0)) -> 5
A24: Technology at year 10: the program's addition | B24: =B23-B22 -> 24.960038 | D24: below one from year (it is one or more until then) | G24: =1+COUNTIF(Q29:Q58,">=1") -> 11
D25: Bottleneck view of A^k against the spectral radius^k: largest gap | G25: =MAX(S28:S58) -> 0
A27: Year | B27: No investment: capability | C27: technology | D27: efficiency | E27: Held investment: capability | F27: technology | G27: efficiency | H27: From capability 1: capability | I27: technology | J27: efficiency | K27: From technology 1: capability | L27: technology | M27: efficiency | N27: From efficiency 1: capability | O27: technology | P27: efficiency | Q27: Effort view of A^k: largest column sum | R27: Bottleneck view of A^k: largest row sum | S27: |bottleneck - spectral radius^k|
A28: 0 | B28: =Declarations!$B$30 -> 50 | C28: =Declarations!$C$30 -> 40 | D28: =Declarations!$D$30 -> 60 | E28: =Declarations!$B$30 -> 50 | F28: =Declarations!$C$30 -> 40 | G28: =Declarations!$D$30 -> 60 | H28: 1 | I28: 0 | J28: 0 | K28: 0 | L28: 1 | M28: 0 | N28: 0 | O28: 0 | P28: 1 | Q28: =MAX(ABS(H28)+ABS(I28)+ABS(J28),ABS(K28)+ABS(L28)+ABS(M28),ABS(N28)+ABS(O28)+ABS(P28)) -> 1 | R28: =MAX(ABS(H28)+ABS(K28)+ABS(N28),ABS(I28)+ABS(L28)+ABS(O28),ABS(J28)+ABS(M28)+ABS(P28)) -> 1 | S28: =ABS(R28-$B$13^A28) -> 0
A29: 1 | B29: =Declarations!$B$27*B28+Declarations!$C$27*C28+Declarations!$D$27*D28 -> 47 | C29: =Declarations!$B$28*B28+Declarations!$C$28*C28+Declarations!$D$28*D28 -> 39 | D29: =Declarations!$B$29*B28+Declarations!$C$29*C28+Declarations!$D$29*D28 -> 54.5 | E29: =Declarations!$B$27*E28+Declarations!$C$27*F28+Declarations!$D$27*G28+Declarations!$E$27*U_held -> 51.8 | F29: =Declarations!$B$28*E28+Declarations!$C$28*F28+Declarations!$D$28*G28+Declarations!$E$28*U_held -> 41.4 | G29: =Declarations!$B$29*E28+Declarations!$C$29*F28+Declarations!$D$29*G28+Declarations!$E$29*U_held -> 54.5 | H29: =Declarations!$B$27*H28+Declarations!$C$27*I28+Declarations!$D$27*J28 -> 0.9 | I29: =Declarations!$B$28*H28+Declarations!$C$28*I28+Declarations!$D$28*J28 -> 0.1 | J29: =Declarations!$B$29*H28+Declarations!$C$29*I28+Declarations!$D$29*J28 -> 0.05 | K29: =Declarations!$B$27*K28+Declarations!$C$27*L28+Declarations!$D$27*M28 -> 0.05 | L29: =Declarations!$B$28*K28+Declarations!$C$28*L28+Declarations!$D$28*M28 -> 0.85 | M29: =Declarations!$B$29*K28+Declarations!$C$29*L28+Declarations!$D$29*M28 -> 0.1 | N29: =Declarations!$B$27*N28+Declarations!$C$27*O28+Declarations!$D$27*P28 -> 0 | O29: =Declarations!$B$28*N28+Declarations!$C$28*O28+Declarations!$D$28*P28 -> 0 | P29: =Declarations!$B$29*N28+Declarations!$C$29*O28+Declarations!$D$29*P28 -> 0.8 | Q29: =MAX(ABS(H29)+ABS(I29)+ABS(J29),ABS(K29)+ABS(L29)+ABS(M29),ABS(N29)+ABS(O29)+ABS(P29)) -> 1.05 | R29: =MAX(ABS(H29)+ABS(K29)+ABS(N29),ABS(I29)+ABS(L29)+ABS(O29),ABS(J29)+ABS(M29)+ABS(P29)) -> 0.95 | S29: =ABS(R29-$B$13^A29) -> 0
A30: 2 | B30: =Declarations!$B$27*B29+Declarations!$C$27*C29+Declarations!$D$27*D29 -> 44.25 | C30: =Declarations!$B$28*B29+Declarations!$C$28*C29+Declarations!$D$28*D29 -> 37.85 | D30: =Declarations!$B$29*B29+Declarations!$C$29*C29+Declarations!$D$29*D29 -> 49.85 | E30: =Declarations!$B$27*E29+Declarations!$C$27*F29+Declarations!$D$27*G29+Declarations!$E$27*U_held -> 53.49 | F30: =Declarations!$B$28*E29+Declarations!$C$28*F29+Declarations!$D$28*G29+Declarations!$E$28*U_held -> 42.77 | G30: =Declarations!$B$29*E29+Declarations!$C$29*F29+Declarations!$D$29*G29+Declarations!$E$29*U_held -> 50.33 | H30: =Declarations!$B$27*H29+Declarations!$C$27*I29+Declarations!$D$27*J29 -> 0.815 | I30: =Declarations!$B$28*H29+Declarations!$C$28*I29+Declarations!$D$28*J29 -> 0.175 | J30: =Declarations!$B$29*H29+Declarations!$C$29*I29+Declarations!$D$29*J29 -> 0.095 | K30: =Declarations!$B$27*K29+Declarations!$C$27*L29+Declarations!$D$27*M29 -> 0.0875 | L30: =Declarations!$B$28*K29+Declarations!$C$28*L29+Declarations!$D$28*M29 -> 0.7275 | M30: =Declarations!$B$29*K29+Declarations!$C$29*L29+Declarations!$D$29*M29 -> 0.1675 | N30: =Declarations!$B$27*N29+Declarations!$C$27*O29+Declarations!$D$27*P29 -> 0 | O30: =Declarations!$B$28*N29+Declarations!$C$28*O29+Declarations!$D$28*P29 -> 0 | P30: =Declarations!$B$29*N29+Declarations!$C$29*O29+Declarations!$D$29*P29 -> 0.64 | Q30: =MAX(ABS(H30)+ABS(I30)+ABS(J30),ABS(K30)+ABS(L30)+ABS(M30),ABS(N30)+ABS(O30)+ABS(P30)) -> 1.085 | R30: =MAX(ABS(H30)+ABS(K30)+ABS(N30),ABS(I30)+ABS(L30)+ABS(O30),ABS(J30)+ABS(M30)+ABS(P30)) -> 0.9025 | S30: =ABS(R30-$B$13^A30) -> 0
A31: 3 | B31: =Declarations!$B$27*B30+Declarations!$C$27*C30+Declarations!$D$27*D30 -> 41.7175 | C31: =Declarations!$B$28*B30+Declarations!$C$28*C30+Declarations!$D$28*D30 -> 36.5975 | D31: =Declarations!$B$29*B30+Declarations!$C$29*C30+Declarations!$D$29*D30 -> 45.8775 | E31: =Declarations!$B$27*E30+Declarations!$C$27*F30+Declarations!$D$27*G30+Declarations!$E$27*U_held -> 55.0795 | F31: =Declarations!$B$28*E30+Declarations!$C$28*F30+Declarations!$D$28*G30+Declarations!$E$28*U_held -> 44.1035 | G31: =Declarations!$B$29*E30+Declarations!$C$29*F30+Declarations!$D$29*G30+Declarations!$E$29*U_held -> 47.2155 | H31: =Declarations!$B$27*H30+Declarations!$C$27*I30+Declarations!$D$27*J30 -> 0.74225 | I31: =Declarations!$B$28*H30+Declarations!$C$28*I30+Declarations!$D$28*J30 -> 0.23025 | J31: =Declarations!$B$29*H30+Declarations!$C$29*I30+Declarations!$D$29*J30 -> 0.13425 | K31: =Declarations!$B$27*K30+Declarations!$C$27*L30+Declarations!$D$27*M30 -> 0.115125 | L31: =Declarations!$B$28*K30+Declarations!$C$28*L30+Declarations!$D$28*M30 -> 0.627125 | M31: =Declarations!$B$29*K30+Declarations!$C$29*L30+Declarations!$D$29*M30 -> 0.211125 | N31: =Declarations!$B$27*N30+Declarations!$C$27*O30+Declarations!$D$27*P30 -> 0 | O31: =Declarations!$B$28*N30+Declarations!$C$28*O30+Declarations!$D$28*P30 -> 0 | P31: =Declarations!$B$29*N30+Declarations!$C$29*O30+Declarations!$D$29*P30 -> 0.512 | Q31: =MAX(ABS(H31)+ABS(I31)+ABS(J31),ABS(K31)+ABS(L31)+ABS(M31),ABS(N31)+ABS(O31)+ABS(P31)) -> 1.10675 | R31: =MAX(ABS(H31)+ABS(K31)+ABS(N31),ABS(I31)+ABS(L31)+ABS(O31),ABS(J31)+ABS(M31)+ABS(P31)) -> 0.857375 | S31: =ABS(R31-$B$13^A31) -> 0
A32: 4 | B32: =Declarations!$B$27*B31+Declarations!$C$27*C31+Declarations!$D$27*D31 -> 39.375625 | C32: =Declarations!$B$28*B31+Declarations!$C$28*C31+Declarations!$D$28*D31 -> 35.279625 | D32: =Declarations!$B$29*B31+Declarations!$C$29*C31+Declarations!$D$29*D31 -> 42.447625 | E32: =Declarations!$B$27*E31+Declarations!$C$27*F31+Declarations!$D$27*G31+Declarations!$E$27*U_held -> 56.576725 | F32: =Declarations!$B$28*E31+Declarations!$C$28*F31+Declarations!$D$28*G31+Declarations!$E$28*U_held -> 45.395925 | G32: =Declarations!$B$29*E31+Declarations!$C$29*F31+Declarations!$D$29*G31+Declarations!$E$29*U_held -> 44.936725 | H32: =Declarations!$B$27*H31+Declarations!$C$27*I31+Declarations!$D$27*J31 -> 0.6795375 | I32: =Declarations!$B$28*H31+Declarations!$C$28*I31+Declarations!$D$28*J31 -> 0.2699375 | J32: =Declarations!$B$29*H31+Declarations!$C$29*I31+Declarations!$D$29*J31 -> 0.1675375 | K32: =Declarations!$B$27*K31+Declarations!$C$27*L31+Declarations!$D$27*M31 -> 0.13496875 | L32: =Declarations!$B$28*K31+Declarations!$C$28*L31+Declarations!$D$28*M31 -> 0.54456875 | M32: =Declarations!$B$29*K31+Declarations!$C$29*L31+Declarations!$D$29*M31 -> 0.23736875 | N32: =Declarations!$B$27*N31+Declarations!$C$27*O31+Declarations!$D$27*P31 -> 0 | O32: =Declarations!$B$28*N31+Declarations!$C$28*O31+Declarations!$D$28*P31 -> 0 | P32: =Declarations!$B$29*N31+Declarations!$C$29*O31+Declarations!$D$29*P31 -> 0.4096 | Q32: =MAX(ABS(H32)+ABS(I32)+ABS(J32),ABS(K32)+ABS(L32)+ABS(M32),ABS(N32)+ABS(O32)+ABS(P32)) -> 1.1170125 | R32: =MAX(ABS(H32)+ABS(K32)+ABS(N32),ABS(I32)+ABS(L32)+ABS(O32),ABS(J32)+ABS(M32)+ABS(P32)) -> 0.81450625 | S32: =ABS(R32-$B$13^A32) -> 0
A33: 5 | B33: =Declarations!$B$27*B32+Declarations!$C$27*C32+Declarations!$D$27*D32 -> 37.202044 | C33: =Declarations!$B$28*B32+Declarations!$C$28*C32+Declarations!$D$28*D32 -> 33.925244 | D33: =Declarations!$B$29*B32+Declarations!$C$29*C32+Declarations!$D$29*D32 -> 39.454844 | E33: =Declarations!$B$27*E32+Declarations!$C$27*F32+Declarations!$D$27*G32+Declarations!$E$27*U_held -> 57.988849 | F33: =Declarations!$B$28*E32+Declarations!$C$28*F32+Declarations!$D$28*G32+Declarations!$E$28*U_held -> 46.644209 | G33: =Declarations!$B$29*E32+Declarations!$C$29*F32+Declarations!$D$29*G32+Declarations!$E$29*U_held -> 43.317809 | H33: =Declarations!$B$27*H32+Declarations!$C$27*I32+Declarations!$D$27*J32 -> 0.62508062 | I33: =Declarations!$B$28*H32+Declarations!$C$28*I32+Declarations!$D$28*J32 -> 0.29740062 | J33: =Declarations!$B$29*H32+Declarations!$C$29*I32+Declarations!$D$29*J32 -> 0.19500063 | K33: =Declarations!$B$27*K32+Declarations!$C$27*L32+Declarations!$D$27*M32 -> 0.14870031 | L33: =Declarations!$B$28*K32+Declarations!$C$28*L32+Declarations!$D$28*M32 -> 0.47638031 | M33: =Declarations!$B$29*K32+Declarations!$C$29*L32+Declarations!$D$29*M32 -> 0.25110031 | N33: =Declarations!$B$27*N32+Declarations!$C$27*O32+Declarations!$D$27*P32 -> 0 | O33: =Declarations!$B$28*N32+Declarations!$C$28*O32+Declarations!$D$28*P32 -> 0 | P33: =Declarations!$B$29*N32+Declarations!$C$29*O32+Declarations!$D$29*P32 -> 0.32768 | Q33: =MAX(ABS(H33)+ABS(I33)+ABS(J33),ABS(K33)+ABS(L33)+ABS(M33),ABS(N33)+ABS(O33)+ABS(P33)) -> 1.1174819 | R33: =MAX(ABS(H33)+ABS(K33)+ABS(N33),ABS(I33)+ABS(L33)+ABS(O33),ABS(J33)+ABS(M33)+ABS(P33)) -> 0.77378094 | S33: =ABS(R33-$B$13^A33) -> 0
A34: 6 | B34: =Declarations!$B$27*B33+Declarations!$C$27*C33+Declarations!$D$27*D33 -> 35.178102 | C34: =Declarations!$B$28*B33+Declarations!$C$28*C33+Declarations!$D$28*D33 -> 32.556662 | D34: =Declarations!$B$29*B33+Declarations!$C$29*C33+Declarations!$D$29*D33 -> 36.816502 | E34: =Declarations!$B$27*E33+Declarations!$C$27*F33+Declarations!$D$27*G33+Declarations!$E$27*U_held -> 59.322174 | F34: =Declarations!$B$28*E33+Declarations!$C$28*F33+Declarations!$D$28*G33+Declarations!$E$28*U_held -> 47.846462 | G34: =Declarations!$B$29*E33+Declarations!$C$29*F33+Declarations!$D$29*G33+Declarations!$E$29*U_held -> 42.21811 | H34: =Declarations!$B$27*H33+Declarations!$C$27*I33+Declarations!$D$27*J33 -> 0.57744259 | I34: =Declarations!$B$28*H33+Declarations!$C$28*I33+Declarations!$D$28*J33 -> 0.31529859 | J34: =Declarations!$B$29*H33+Declarations!$C$29*I33+Declarations!$D$29*J33 -> 0.21699459 | K34: =Declarations!$B$27*K33+Declarations!$C$27*L33+Declarations!$D$27*M33 -> 0.1576493 | L34: =Declarations!$B$28*K33+Declarations!$C$28*L33+Declarations!$D$28*M33 -> 0.4197933 | M34: =Declarations!$B$29*K33+Declarations!$C$29*L33+Declarations!$D$29*M33 -> 0.2559533 | N34: =Declarations!$B$27*N33+Declarations!$C$27*O33+Declarations!$D$27*P33 -> 0 | O34: =Declarations!$B$28*N33+Declarations!$C$28*O33+Declarations!$D$28*P33 -> 0 | P34: =Declarations!$B$29*N33+Declarations!$C$29*O33+Declarations!$D$29*P33 -> 0.262144 | Q34: =MAX(ABS(H34)+ABS(I34)+ABS(J34),ABS(K34)+ABS(L34)+ABS(M34),ABS(N34)+ABS(O34)+ABS(P34)) -> 1.1097358 | R34: =MAX(ABS(H34)+ABS(K34)+ABS(N34),ABS(I34)+ABS(L34)+ABS(O34),ABS(J34)+ABS(M34)+ABS(P34)) -> 0.73509189 | S34: =ABS(R34-$B$13^A34) -> 0
A35: 7 | B35: =Declarations!$B$27*B34+Declarations!$C$27*C34+Declarations!$D$27*D34 -> 33.288124 | C35: =Declarations!$B$28*B34+Declarations!$C$28*C34+Declarations!$D$28*D34 -> 31.190972 | D35: =Declarations!$B$29*B34+Declarations!$C$29*C34+Declarations!$D$29*D34 -> 34.467772 | E35: =Declarations!$B$27*E34+Declarations!$C$27*F34+Declarations!$D$27*G34+Declarations!$E$27*U_held -> 60.58228 | F35: =Declarations!$B$28*E34+Declarations!$C$28*F34+Declarations!$D$28*G34+Declarations!$E$28*U_held -> 49.00171 | G35: =Declarations!$B$29*E34+Declarations!$C$29*F34+Declarations!$D$29*G34+Declarations!$E$29*U_held -> 41.525243 | H35: =Declarations!$B$27*H34+Declarations!$C$27*I34+Declarations!$D$27*J34 -> 0.53546326 | I35: =Declarations!$B$28*H34+Declarations!$C$28*I34+Declarations!$D$28*J34 -> 0.32574806 | J35: =Declarations!$B$29*H34+Declarations!$C$29*I34+Declarations!$D$29*J34 -> 0.23399766 | K35: =Declarations!$B$27*K34+Declarations!$C$27*L34+Declarations!$D$27*M34 -> 0.16287403 | L35: =Declarations!$B$28*K34+Declarations!$C$28*L34+Declarations!$D$28*M34 -> 0.37258923 | M35: =Declarations!$B$29*K34+Declarations!$C$29*L34+Declarations!$D$29*M34 -> 0.25462443 | N35: =Declarations!$B$27*N34+Declarations!$C$27*O34+Declarations!$D$27*P34 -> 0 | O35: =Declarations!$B$28*N34+Declarations!$C$28*O34+Declarations!$D$28*P34 -> 0 | P35: =Declarations!$B$29*N34+Declarations!$C$29*O34+Declarations!$D$29*P34 -> 0.2097152 | Q35: =MAX(ABS(H35)+ABS(I35)+ABS(J35),ABS(K35)+ABS(L35)+ABS(M35),ABS(N35)+ABS(O35)+ABS(P35)) -> 1.095209 | R35: =MAX(ABS(H35)+ABS(K35)+ABS(N35),ABS(I35)+ABS(L35)+ABS(O35),ABS(J35)+ABS(M35)+ABS(P35)) -> 0.6983373 | S35: =ABS(R35-$B$13^A35) -> 0
A36: 8 | B36: =Declarations!$B$27*B35+Declarations!$C$27*C35+Declarations!$D$27*D35 -> 31.518861 | C36: =Declarations!$B$28*B35+Declarations!$C$28*C35+Declarations!$D$28*D35 -> 29.841139 | D36: =Declarations!$B$29*B35+Declarations!$C$29*C35+Declarations!$D$29*D35 -> 32.357721 | E36: =Declarations!$B$27*E35+Declarations!$C$27*F35+Declarations!$D$27*G35+Declarations!$E$27*U_held -> 61.774138 | F36: =Declarations!$B$28*E35+Declarations!$C$28*F35+Declarations!$D$28*G35+Declarations!$E$28*U_held -> 50.109682 | G36: =Declarations!$B$29*E35+Declarations!$C$29*F35+Declarations!$D$29*G35+Declarations!$E$29*U_held -> 41.14948 | H36: =Declarations!$B$27*H35+Declarations!$C$27*I35+Declarations!$D$27*J35 -> 0.49820434 | I36: =Declarations!$B$28*H35+Declarations!$C$28*I35+Declarations!$D$28*J35 -> 0.33043218 | J36: =Declarations!$B$29*H35+Declarations!$C$29*I35+Declarations!$D$29*J35 -> 0.2465461 | K36: =Declarations!$B$27*K35+Declarations!$C$27*L35+Declarations!$D$27*M35 -> 0.16521609 | L36: =Declarations!$B$28*K35+Declarations!$C$28*L35+Declarations!$D$28*M35 -> 0.33298825 | M36: =Declarations!$B$29*K35+Declarations!$C$29*L35+Declarations!$D$29*M35 -> 0.24910217 | N36: =Declarations!$B$27*N35+Declarations!$C$27*O35+Declarations!$D$27*P35 -> 0 | O36: =Declarations!$B$28*N35+Declarations!$C$28*O35+Declarations!$D$28*P35 -> 0 | P36: =Declarations!$B$29*N35+Declarations!$C$29*O35+Declarations!$D$29*P35 -> 0.16777216 | Q36: =MAX(ABS(H36)+ABS(I36)+ABS(J36),ABS(K36)+ABS(L36)+ABS(M36),ABS(N36)+ABS(O36)+ABS(P36)) -> 1.0751826 | R36: =MAX(ABS(H36)+ABS(K36)+ABS(N36),ABS(I36)+ABS(L36)+ABS(O36),ABS(J36)+ABS(M36)+ABS(P36)) -> 0.66342043 | S36: =ABS(R36-$B$13^A36) -> 0
A37: 9 | B37: =Declarations!$B$27*B36+Declarations!$C$27*C36+Declarations!$D$27*D36 -> 29.859032 | C37: =Declarations!$B$28*B36+Declarations!$C$28*C36+Declarations!$D$28*D36 -> 28.516854 | D37: =Declarations!$B$29*B36+Declarations!$C$29*C36+Declarations!$D$29*D36 -> 30.446234 | E37: =Declarations!$B$27*E36+Declarations!$C$27*F36+Declarations!$D$27*G36+Declarations!$E$27*U_held -> 62.902208 | F37: =Declarations!$B$28*E36+Declarations!$C$28*F36+Declarations!$D$28*G36+Declarations!$E$28*U_held -> 51.170643 | G37: =Declarations!$B$29*E36+Declarations!$C$29*F36+Declarations!$D$29*G36+Declarations!$E$29*U_held -> 41.019259 | H37: =Declarations!$B$27*H36+Declarations!$C$27*I36+Declarations!$D$27*J36 -> 0.46490552 | I37: =Declarations!$B$28*H36+Declarations!$C$28*I36+Declarations!$D$28*J36 -> 0.33068779 | J37: =Declarations!$B$29*H36+Declarations!$C$29*I36+Declarations!$D$29*J36 -> 0.25519032 | K37: =Declarations!$B$27*K36+Declarations!$C$27*L36+Declarations!$D$27*M36 -> 0.16534389 | L37: =Declarations!$B$28*K36+Declarations!$C$28*L36+Declarations!$D$28*M36 -> 0.29956162 | M37: =Declarations!$B$29*K36+Declarations!$C$29*L36+Declarations!$D$29*M36 -> 0.24084137 | N37: =Declarations!$B$27*N36+Declarations!$C$27*O36+Declarations!$D$27*P36 -> 0 | O37: =Declarations!$B$28*N36+Declarations!$C$28*O36+Declarations!$D$28*P36 -> 0 | P37: =Declarations!$B$29*N36+Declarations!$C$29*O36+Declarations!$D$29*P36 -> 0.13421773 | Q37: =MAX(ABS(H37)+ABS(I37)+ABS(J37),ABS(K37)+ABS(L37)+ABS(M37),ABS(N37)+ABS(O37)+ABS(P37)) -> 1.0507836 | R37: =MAX(ABS(H37)+ABS(K37)+ABS(N37),ABS(I37)+ABS(L37)+ABS(O37),ABS(J37)+ABS(M37)+ABS(P37)) -> 0.63024941 | S37: =ABS(R37-$B$13^A37) -> 0
A38: 10 | B38: =Declarations!$B$27*B37+Declarations!$C$27*C37+Declarations!$D$27*D37 -> 28.298971 | C38: =Declarations!$B$28*B37+Declarations!$C$28*C37+Declarations!$D$28*D37 -> 27.225229 | D38: =Declarations!$B$29*B37+Declarations!$C$29*C37+Declarations!$D$29*D37 -> 28.701624 | E38: =Declarations!$B$27*E37+Declarations!$C$27*F37+Declarations!$D$27*G37+Declarations!$E$27*U_held -> 63.970519 | F38: =Declarations!$B$28*E37+Declarations!$C$28*F37+Declarations!$D$28*G37+Declarations!$E$28*U_held -> 52.185268 | G38: =Declarations!$B$29*E37+Declarations!$C$29*F37+Declarations!$D$29*G37+Declarations!$E$29*U_held -> 41.077582 | H38: =Declarations!$B$27*H37+Declarations!$C$27*I37+Declarations!$D$27*J37 -> 0.43494935 | I38: =Declarations!$B$28*H37+Declarations!$C$28*I37+Declarations!$D$28*J37 -> 0.32757517 | J38: =Declarations!$B$29*H37+Declarations!$C$29*I37+Declarations!$D$29*J37 -> 0.26046631 | K38: =Declarations!$B$27*K37+Declarations!$C$27*L37+Declarations!$D$27*M37 -> 0.16378759 | L38: =Declarations!$B$28*K37+Declarations!$C$28*L37+Declarations!$D$28*M37 -> 0.27116177 | M38: =Declarations!$B$29*K37+Declarations!$C$29*L37+Declarations!$D$29*M37 -> 0.23089645 | N38: =Declarations!$B$27*N37+Declarations!$C$27*O37+Declarations!$D$27*P37 -> 0 | O38: =Declarations!$B$28*N37+Declarations!$C$28*O37+Declarations!$D$28*P37 -> 0 | P38: =Declarations!$B$29*N37+Declarations!$C$29*O37+Declarations!$D$29*P37 -> 0.10737418 | Q38: =MAX(ABS(H38)+ABS(I38)+ABS(J38),ABS(K38)+ABS(L38)+ABS(M38),ABS(N38)+ABS(O38)+ABS(P38)) -> 1.0229908 | R38: =MAX(ABS(H38)+ABS(K38)+ABS(N38),ABS(I38)+ABS(L38)+ABS(O38),ABS(J38)+ABS(M38)+ABS(P38)) -> 0.59873694 | S38: =ABS(R38-$B$13^A38) -> 0
A39: 11 | B39: =Declarations!$B$27*B38+Declarations!$C$27*C38+Declarations!$D$27*D38 -> 26.830335 | C39: =Declarations!$B$28*B38+Declarations!$C$28*C38+Declarations!$D$28*D38 -> 25.971342 | D39: =Declarations!$B$29*B38+Declarations!$C$29*C38+Declarations!$D$29*D38 -> 27.098771 | E39: =Declarations!$B$27*E38+Declarations!$C$27*F38+Declarations!$D$27*G38+Declarations!$E$27*U_held -> 64.982731 | F39: =Declarations!$B$28*E38+Declarations!$C$28*F38+Declarations!$D$28*G38+Declarations!$E$28*U_held -> 53.154529 | G39: =Declarations!$B$29*E38+Declarations!$C$29*F38+Declarations!$D$29*G38+Declarations!$E$29*U_held -> 41.279118 | H39: =Declarations!$B$27*H38+Declarations!$C$27*I38+Declarations!$D$27*J38 -> 0.40783318 | I39: =Declarations!$B$28*H38+Declarations!$C$28*I38+Declarations!$D$28*J38 -> 0.32193383 | J39: =Declarations!$B$29*H38+Declarations!$C$29*I38+Declarations!$D$29*J38 -> 0.26287803 | K39: =Declarations!$B$27*K38+Declarations!$C$27*L38+Declarations!$D$27*M38 -> 0.16096692 | L39: =Declarations!$B$28*K38+Declarations!$C$28*L38+Declarations!$D$28*M38 -> 0.24686626 | M39: =Declarations!$B$29*K38+Declarations!$C$29*L38+Declarations!$D$29*M38 -> 0.22002272 | N39: =Declarations!$B$27*N38+Declarations!$C$27*O38+Declarations!$D$27*P38 -> 0 | O39: =Declarations!$B$28*N38+Declarations!$C$28*O38+Declarations!$D$28*P38 -> 0 | P39: =Declarations!$B$29*N38+Declarations!$C$29*O38+Declarations!$D$29*P38 -> 0.085899346 | Q39: =MAX(ABS(H39)+ABS(I39)+ABS(J39),ABS(K39)+ABS(L39)+ABS(M39),ABS(N39)+ABS(O39)+ABS(P39)) -> 0.99264504 | R39: =MAX(ABS(H39)+ABS(K39)+ABS(N39),ABS(I39)+ABS(L39)+ABS(O39),ABS(J39)+ABS(M39)+ABS(P39)) -> 0.56880009 | S39: =ABS(R39-$B$13^A39) -> 0
A40: 12 | B40: =Declarations!$B$27*B39+Declarations!$C$27*C39+Declarations!$D$27*D39 -> 25.445869 | C40: =Declarations!$B$28*B39+Declarations!$C$28*C39+Declarations!$D$28*D39 -> 24.758674 | D40: =Declarations!$B$29*B39+Declarations!$C$29*C39+Declarations!$D$29*D39 -> 25.617668 | E40: =Declarations!$B$27*E39+Declarations!$C$27*F39+Declarations!$D$27*G39+Declarations!$E$27*U_held -> 65.942184 | F40: =Declarations!$B$28*E39+Declarations!$C$28*F39+Declarations!$D$28*G39+Declarations!$E$28*U_held -> 54.079623 | G40: =Declarations!$B$29*E39+Declarations!$C$29*F39+Declarations!$D$29*G39+Declarations!$E$29*U_held -> 41.587884 | H40: =Declarations!$B$27*H39+Declarations!$C$27*I39+Declarations!$D$27*J39 -> 0.38314655 | I40: =Declarations!$B$28*H39+Declarations!$C$28*I39+Declarations!$D$28*J39 -> 0.31442707 | J40: =Declarations!$B$29*H39+Declarations!$C$29*I39+Declarations!$D$29*J39 -> 0.26288747 | K40: =Declarations!$B$27*K39+Declarations!$C$27*L39+Declarations!$D$27*M39 -> 0.15721354 | L40: =Declarations!$B$28*K39+Declarations!$C$28*L39+Declarations!$D$28*M39 -> 0.22593301 | M40: =Declarations!$B$29*K39+Declarations!$C$29*L39+Declarations!$D$29*M39 -> 0.20875314 | N40: =Declarations!$B$27*N39+Declarations!$C$27*O39+Declarations!$D$27*P39 -> 0 | O40: =Declarations!$B$28*N39+Declarations!$C$28*O39+Declarations!$D$28*P39 -> 0 | P40: =Declarations!$B$29*N39+Declarations!$C$29*O39+Declarations!$D$29*P39 -> 0.068719477 | Q40: =MAX(ABS(H40)+ABS(I40)+ABS(J40),ABS(K40)+ABS(L40)+ABS(M40),ABS(N40)+ABS(O40)+ABS(P40)) -> 0.96046109 | R40: =MAX(ABS(H40)+ABS(K40)+ABS(N40),ABS(I40)+ABS(L40)+ABS(O40),ABS(J40)+ABS(M40)+ABS(P40)) -> 0.54036009 | S40: =ABS(R40-$B$13^A40) -> 0
... A58: 30 | B58: =Declarations!$B$27*B57+Declarations!$C$27*C57+Declarations!$D$27*D57 -> 10.020602 | C58: =Declarations!$B$28*B57+Declarations!$C$28*C57+Declarations!$D$28*D57 -> 10.008223 | D58: =Declarations!$B$29*B57+Declarations!$C$29*C57+Declarations!$D$29*D57 -> 10.00977 | E58: =Declarations!$B$27*E57+Declarations!$C$27*F57+Declarations!$D$27*G57+Declarations!$E$27*U_held -> 76.844549 | F58: =Declarations!$B$28*E57+Declarations!$C$28*F57+Declarations!$D$28*G57+Declarations!$E$28*U_held -> 64.847025 | G58: =Declarations!$B$29*E57+Declarations!$C$29*F57+Declarations!$D$29*G57+Declarations!$E$29*U_held -> 49.894995 | H58: =Declarations!$B$27*H57+Declarations!$C$27*I57+Declarations!$D$27*J57 -> 0.14350516 | I58: =Declarations!$B$28*H57+Declarations!$C$28*I57+Declarations!$D$28*J57 -> 0.14226722 | J58: =Declarations!$B$29*H57+Declarations!$C$29*I57+Declarations!$D$29*J57 -> 0.13994608 | K58: =Declarations!$B$27*K57+Declarations!$C$27*L57+Declarations!$D$27*M57 -> 0.071133608 | L58: =Declarations!$B$28*K57+Declarations!$C$28*L57+Declarations!$D$28*M57 -> 0.072371548 | M58: =Declarations!$B$29*K57+Declarations!$C$29*L57+Declarations!$D$29*M57 -> 0.073454746 | N58: =Declarations!$B$27*N57+Declarations!$C$27*O57+Declarations!$D$27*P57 -> 0 | O58: =Declarations!$B$28*N57+Declarations!$C$28*O57+Declarations!$D$28*P57 -> 0 | P58: =Declarations!$B$29*N57+Declarations!$C$29*O57+Declarations!$D$29*P57 -> 0.00123794 | Q58: =MAX(ABS(H58)+ABS(I58)+ABS(J58),ABS(K58)+ABS(L58)+ABS(M58),ABS(N58)+ABS(O58)+ABS(P58)) -> 0.42571845 | R58: =MAX(ABS(H58)+ABS(K58)+ABS(N58),ABS(I58)+ABS(L58)+ABS(O58),ABS(J58)+ABS(M58)+ABS(P58)) -> 0.21463876 | S58: =ABS(R58-$B$13^A58) -> 0

Sheet Reference_Values
A1: Checkpoint | B1: Engine value | C1: Meaning (where in the book)
A2: Readings in Meridian's state | B2: 8 | C2: Table 3.1: eight readings
A3: Scaled workforce capability | B3: 0.58 | C3: Figure 3.3: 0.58
A4: Scaled technology platform | B4: 0.41 | C4: Figure 3.3: 0.41
A5: Scaled operational efficiency | B5: 0.71 | C5: Figure 3.3: 0.71
A6: Scaled strategic risk | B6: 0.64 | C6: Figure 3.3: 0.64
A7: Readings at 1.00 after scaling | B7: 4 | C7: Figure 3.3: liquidity, leverage, ROIC, market share
A8: Raw distance to Peer A, liquidity in $ billion | B8: 6.5000862 | C8: Lab step 1 (peers drawn with seed 26103)
A9: Raw distance to Peer B, liquidity in $ billion | B9: 21.119491 | C9: Lab step 1
A10: Raw distance to Peer A, liquidity in $ million | B10: 30.696095 | C10: Lab step 1
A11: Raw distance to Peer B, liquidity in $ million | B11: 151.47941 | C11: Lab step 1
A12: Peer A's squared raw distance from the indices, $ billion | B12: 0.99405647 | C12: The index readings dominate in billions (Section 3.3)
A13: Peer A's squared raw distance from liquidity, $ million | B13: 0.9551603 | C13: Liquidity dominates in millions
... A94: Bottleneck view of A^k against 0.95^k | B94: 0 | C94: Exact: rows of A sum to 0.95

Sheet Checks
A1: Checkpoint | B1: Workbook formula value | C1: Engine value | D1: |diff| | E1: Tolerance | F1: Status
A2: Readings in Meridian's state | B2: =Declarations!C12 -> 8 | C2: =Reference_Values!B2 -> 8 | D2: =ABS(B2-C2) -> 0 | E2: 0 | F2: =IF(D2<=E2,"PASS","FAIL") -> PASS
A3: Scaled workforce capability | B3: =Scaling!D7 -> 0.58 | C3: =Reference_Values!B3 -> 0.58 | D3: =ABS(B3-C3) -> 0 | E3: 1e-09 | F3: =IF(D3<=E3,"PASS","FAIL") -> PASS
A4: Scaled technology platform | B4: =Scaling!D8 -> 0.41 | C4: =Reference_Values!B4 -> 0.41 | D4: =ABS(B4-C4) -> 0 | E4: 1e-09 | F4: =IF(D4<=E4,"PASS","FAIL") -> PASS
A5: Scaled operational efficiency | B5: =Scaling!D9 -> 0.71 | C5: =Reference_Values!B5 -> 0.71 | D5: =ABS(B5-C5) -> 0 | E5: 1e-09 | F5: =IF(D5<=E5,"PASS","FAIL") -> PASS
A6: Scaled strategic risk | B6: =Scaling!D11 -> 0.64 | C6: =Reference_Values!B6 -> 0.64 | D6: =ABS(B6-C6) -> 0 | E6: 1e-09 | F6: =IF(D6<=E6,"PASS","FAIL") -> PASS
A7: Readings at 1.00 after scaling | B7: =Scaling!D14 -> 4 | C7: =Reference_Values!B7 -> 4 | D7: =ABS(B7-C7) -> 0 | E7: 0 | F7: =IF(D7<=E7,"PASS","FAIL") -> PASS
A8: Raw distance to Peer A, liquidity in $ billion | B8: =Vector!D14 -> 6.5000862 | C8: =Reference_Values!B8 -> 6.5000862 | D8: =ABS(B8-C8) -> 0 | E8: 1e-09 | F8: =IF(D8<=E8,"PASS","FAIL") -> PASS
A9: Raw distance to Peer B, liquidity in $ billion | B9: =Vector!D15 -> 21.119491 | C9: =Reference_Values!B9 -> 21.119491 | D9: =ABS(B9-C9) -> 0 | E9: 1e-09 | F9: =IF(D9<=E9,"PASS","FAIL") -> PASS
A10: Raw distance to Peer A, liquidity in $ million | B10: =Vector!D17 -> 30.696095 | C10: =Reference_Values!B10 -> 30.696095 | D10: =ABS(B10-C10) -> 0 | E10: 1e-09 | F10: =IF(D10<=E10,"PASS","FAIL") -> PASS
A11: Raw distance to Peer B, liquidity in $ million | B11: =Vector!D18 -> 151.47941 | C11: =Reference_Values!B11 -> 151.47941 | D11: =ABS(B11-C11) -> 0 | E11: 1e-09 | F11: =IF(D11<=E11,"PASS","FAIL") -> PASS
A12: Peer A's squared raw distance from the indices, $ billion | B12: =Vector!D21 -> 0.99405647 | C12: =Reference_Values!B12 -> 0.99405647 | D12: =ABS(B12-C12) -> 0 | E12: 1e-09 | F12: =IF(D12<=E12,"PASS","FAIL") -> PASS
A13: Peer A's squared raw distance from liquidity, $ million | B13: =Vector!D22 -> 0.9551603 | C13: =Reference_Values!B13 -> 0.9551603 | D13: =ABS(B13-C13) -> 0 | E13: 1e-09 | F13: =IF(D13<=E13,"PASS","FAIL") -> PASS
