Workbook

Sheet README
B1: DCT Laboratory — Vol II, Ch 10: Neuro-Fuzzy Robust Enterprise Optimization
B2: Seed 26210 · Companion to DCT_V2_Ch10_Lab.ipynb and AXIOM Lab 2.10 (module AXIOM-10). Money in $ million.
B4: Worked Example 10.1, What Can Meridian Guarantee Without Odds?, with the book's declarations: Chapter 9's levers and floor; the engineering office's bound on deviations and the treasury's bound on a closure, crisp and in graded words; the board's graded goal for cost. Chances are judged under Chapter 9's law on the book's 100,000 paths (seed 8) and its 100,000 fresh paths (seed 26209).
B5: Declarations: the law, the levers and their prices, the offices' words, the board's goal, the bank's cap.
B6: Plan: the plan's margin above the floor and the lift of a quarter of delay, quarter by quarter; the binding quarter and the prices of a dollar by line and by delay (Section 10.2).
B7: Robust: packages robust on declared sets in closed form, with the binding quarter and a cap on the line (Proposition 10.1(ii); Steps 1-2 and 5); Proposition 10.3(iii)'s quiet-then-damage future.
B8: Graded: the 101 cuts of the offices' words, the graded price, the board's goal and the max-min choice (Theorem 10.2; Proposition 10.2; Figure 10.1; Step 3).
B9: Frontier: Chapter 9's cheapest package for each appetite and Table 10.3 (Theorem 10.1(iii); Figure 10.3; Step 4).
B10: Rules: the eight neuro-fuzzy rules, their conclusions and slopes, and the Sugeno output at any declaration against the exact robust cost (Theorem 10.3; Equation 10.2; Step 5).
B11: Engine values (green) are what needs Chapter 9's simulated paths (chances, the share of paths inside a set, the frontier's lines and delays) or the neuro-fuzzy training (widths, coefficients, the certification grid). Everything else is a formula.
B12: Reference_Values and Checks: the engine's numbers and a PASS/FAIL comparison with this workbook's formulas.
B14: LEGEND
... B18: Cross-sheet link: green.

Sheet Declarations
A1: Declarations (Worked Example 10.1, Step 1; Chapter 9's law and levers). Money in $ million.
A3: Quantity | B3: Value | C3: Source
A4: Liquidity today | B4: 620 | C4: Meridian's state (Volume I, Chapter 1)
A5: $ million per index point | B5: =B4/100 -> 6.2 | C5: Index 100 = $620 million
A6: Plan without the draw: long-run index | B6: 112 | C6: The Chapter 1 plan relaxes from 100 toward 112
A7: at the rate (a year) | B7: 0.35
A8: The draw's depth (index points) | B8: 28 | C8: The digital program's draw, deepest at two years
A9: The draw is deepest at (years) | B9: 2 | C9: Shape S(t) = (t/2) e^(1 - t/2)
A10: Floor | B10: 350 | C10: The board's floor
A11: Persistence of a deviation a quarter | B11: 0.6 | C11: E' = 0.6 E + w (Volume I, Chapter 8)
A12: Standard deviation of w, a quarter | B12: 50
A13: Funding-window closures a year | B13: 0.1 | C13: About once a decade
A14: Closure size: mean | B14: 120 | C14: Gamma-distributed, never recovered
A15: Closure size: standard deviation | B15: 50
A16: Line fees over the program, per $ of line | B16: 0.03 | C16: The treasury
A17: A quarter of delay | B17: 8 | C17: The transformation office
A18: Depth cut by a quarter of delay (points) | B18: 4
A19: The appetite | B19: 0.05 | C19: At most a 5 percent chance of a breach in some quarter
A20: Paths (the book's, seed 8; fresh, seed 26209) | B20: 100000 | C20: Chapter 9's law
A22: The new declarations: bounds without odds, graded words, the board's goal (Worked Example 10.1, Steps 1-4)
A23: Deviations: usually within | B23: 50 | C23: The engineering office: possibility 1 up to here
A24: Deviations: never beyond | B24: 200 | C24: Possibility 0 beyond; the cut at alpha: 200 - 150 alpha
A25: A closure: most plausibly about | B25: 120 | C25: The treasury: possibility 1 up to here
A26: A closure: never above | B26: 300 | C26: Possibility 0 beyond; the cut at alpha: 300 - 180 alpha
A27: The board's goal: a guarantee should cost about ... or less | B27: 5 | C27: Goal 1 up to here
A28: and surely no more than | B28: 20 | C28: Goal 0 beyond; linear between
A29: A bank's cap on the line | B29: 100 | C29: Worked Example 10.1, Step 4
A30: Volume I's joint check: one closure of at most | B30: 187 | C30: Volume I, Worked Example 13.1: the 90th percentile, at the deepest draw
A31: A closure's 90th percentile under the law | B31: =GAMMAINV(0.9,(B14/B15)^2,B15^2/B14) -> 186.86698 | C31: Gamma with mean 120 and standard deviation 50: $187 million

Sheet Plan
A1: The plan's margin above the floor and the lift of a quarter of delay (Section 10.2; Proposition 10.1(ii); AXIOM Lab 2.10, step 1)
A2: On U(D, S) the floor holds in quarter k exactly when m_k + l_k phi - D - (S - l)^+ >= 0. A line covers a dollar of closure for 3 cents; delay buys a dollar of liquidity in quarter k for 8 / l_k.
A4: Quarter k | B4: t (years) | C4: Plan index without the draw | D4: Without the draw ($m) | E4: The draw's shape S | F4: $m per point of depth | G4: Planned liquidity ($m) | H4: Margin above the floor, m_k | I4: Lift of a quarter of delay, l_k | J4: Delay's price a dollar of liquidity
A5: 1 | B5: =A5/4 -> 0.25 | C5: =Xinf+(100-Xinf)*EXP(-Krel*B5) -> 101.00537 | D5: =PerPt*C5 -> 626.23332 | E5: =(B5/Tpk)*EXP(1-B5/Tpk) -> 0.29985941 | F5: =PerPt*E5 -> 1.8591284 | G5: =D5-Depth0*F5 -> 574.17772 | H5: =G5-FloorL -> 224.17772 | I5: =DPQ*F5 -> 7.4365134 | J5: =VQ/I5 -> 1.075773
A6: 2 | B6: =A6/4 -> 0.5 | C6: =Xinf+(100-Xinf)*EXP(-Krel*B6) -> 101.92652 | D6: =PerPt*C6 -> 631.9444 | E6: =(B6/Tpk)*EXP(1-B6/Tpk) -> 0.52925 | F6: =PerPt*E6 -> 3.28135 | G6: =D6-Depth0*F6 -> 540.0666 | H6: =G6-FloorL -> 190.0666 | I6: =DPQ*F6 -> 13.1254 | J6: =VQ/I6 -> 0.60950523
A7: 3 | B7: =A7/4 -> 0.75 | C7: =Xinf+(100-Xinf)*EXP(-Krel*B7) -> 102.77048 | D7: =PerPt*C7 -> 637.177 | E7: =(B7/Tpk)*EXP(1-B7/Tpk) -> 0.70059223 | F7: =PerPt*E7 -> 4.3436719 | G7: =D7-Depth0*F7 -> 515.55419 | H7: =G7-FloorL -> 165.55419 | I7: =DPQ*F7 -> 17.374687 | J7: =VQ/I7 -> 0.46043994
A8: 4 | B8: =A8/4 -> 1 | C8: =Xinf+(100-Xinf)*EXP(-Krel*B8) -> 103.54374 | D8: =PerPt*C8 -> 641.97121 | E8: =(B8/Tpk)*EXP(1-B8/Tpk) -> 0.82436064 | F8: =PerPt*E8 -> 5.1110359 | G8: =D8-Depth0*F8 -> 498.8622 | H8: =G8-FloorL -> 148.8622 | I8: =DPQ*F8 -> 20.444144 | J8: =VQ/I8 -> 0.3913101
A9: 5 | B9: =A9/4 -> 1.25 | C9: =Xinf+(100-Xinf)*EXP(-Krel*B9) -> 104.25222 | D9: =PerPt*C9 -> 646.36375 | E9: =(B9/Tpk)*EXP(1-B9/Tpk) -> 0.90936963 | F9: =PerPt*E9 -> 5.6380917 | G9: =D9-Depth0*F9 -> 488.49718 | H9: =G9-FloorL -> 138.49718 | I9: =DPQ*F9 -> 22.552367 | J9: =VQ/I9 -> 0.35472995
A10: 6 | B10: =A10/4 -> 1.5 | C10: =Xinf+(100-Xinf)*EXP(-Krel*B10) -> 104.90134 | D10: =PerPt*C10 -> 650.38828 | E10: =(B10/Tpk)*EXP(1-B10/Tpk) -> 0.96301906 | F10: =PerPt*E10 -> 5.9707182 | G10: =D10-Depth0*F10 -> 483.20817 | H10: =G10-FloorL -> 133.20817 | I10: =DPQ*F10 -> 23.882873 | J10: =VQ/I10 -> 0.33496808
A11: 7 | B11: =A11/4 -> 1.75 | C11: =Xinf+(100-Xinf)*EXP(-Krel*B11) -> 105.49607 | D11: =PerPt*C11 -> 654.07563 | E11: =(B11/Tpk)*EXP(1-B11/Tpk) -> 0.9915049 | F11: =PerPt*E11 -> 6.1473304 | G11: =D11-Depth0*F11 -> 481.95038 | H11: =G11-FloorL -> 131.95038 | I11: =DPQ*F11 -> 24.589321 | J11: =VQ/I11 -> 0.32534448
A12: 8 | B12: =A12/4 -> 2 | C12: =Xinf+(100-Xinf)*EXP(-Krel*B12) -> 106.04098 | D12: =PerPt*C12 -> 657.45405 | E12: =(B12/Tpk)*EXP(1-B12/Tpk) -> 1 | F12: =PerPt*E12 -> 6.2 | G12: =D12-Depth0*F12 -> 483.85405 | H12: =G12-FloorL -> 133.85405 | I12: =DPQ*F12 -> 24.8 | J12: =VQ/I12 -> 0.32258065
A13: 9 | B13: =A13/4 -> 2.25 | C13: =Xinf+(100-Xinf)*EXP(-Krel*B13) -> 106.54023 | D13: =PerPt*C13 -> 660.54943 | E13: =(B13/Tpk)*EXP(1-B13/Tpk) -> 0.99280902 | F13: =PerPt*E13 -> 6.1554159 | G13: =D13-Depth0*F13 -> 488.19778 | H13: =G13-FloorL -> 138.19778 | I13: =DPQ*F13 -> 24.621664 | J13: =VQ/I13 -> 0.32491712
A14: 10 | B14: =A14/4 -> 2.5 | C14: =Xinf+(100-Xinf)*EXP(-Krel*B14) -> 106.99766 | D14: =PerPt*C14 -> 663.38547 | E14: =(B14/Tpk)*EXP(1-B14/Tpk) -> 0.97350098 | F14: =PerPt*E14 -> 6.0357061 | G14: =D14-Depth0*F14 -> 494.3857 | H14: =G14-FloorL -> 144.3857 | I14: =DPQ*F14 -> 24.142824 | J14: =VQ/I14 -> 0.3313614
A15: 11 | B15: =A15/4 -> 2.75 | C15: =Xinf+(100-Xinf)*EXP(-Krel*B15) -> 107.41676 | D15: =PerPt*C15 -> 665.9839 | E15: =(B15/Tpk)*EXP(1-B15/Tpk) -> 0.94502276 | F15: =PerPt*E15 -> 5.8591411 | G15: =D15-Depth0*F15 -> 501.92795 | H15: =G15-FloorL -> 151.92795 | I15: =DPQ*F15 -> 23.436564 | J15: =VQ/I15 -> 0.34134696
A16: 12 | B16: =A16/4 -> 3 | C16: =Xinf+(100-Xinf)*EXP(-Krel*B16) -> 107.80075 | D16: =PerPt*C16 -> 668.36463 | E16: =(B16/Tpk)*EXP(1-B16/Tpk) -> 0.90979599 | F16: =PerPt*E16 -> 5.6407351 | G16: =D16-Depth0*F16 -> 510.42405 | H16: =G16-FloorL -> 160.42405 | I16: =DPQ*F16 -> 22.562941 | J16: =VQ/I16 -> 0.35456371
A19: The plan's least margin above the floor | B19: =MIN(H5:H16) -> 131.95038 | C19: $132 million
A20: in quarter | B20: =MATCH(B19,H5:H16,0) -> 7 | C20: 7: the binding quarter of the crisp set
A21: A quarter of delay lifts that quarter by | B21: =INDEX(I5:I16,B20) -> 24.589321 | C21: $24.6 million
A22: The line's price a dollar of closure | B22: =Fee -> 0.03 | C22: 3 cents
A23: Delay's price a dollar of liquidity there | B23: =VQ/B21 -> 0.32534448 | C23: About 33 cents
A24: Planned liquidity at its low point | B24: =MIN(G5:G16) -> 481.95038 | C24: $482 million

Sheet Robust
A1: Robust packages on declared sets (Proposition 10.1(ii); Worked Example 10.1, Steps 1-2 and 5; AXIOM Lab 2.10, step 1)
A2: The least delay the deviations need, phi* = max(0, max_k (D - m_k)/l_k); the margin absorbs u* = min(S, min_k (m_k - D + l_k phi*)) of a closure; the line covers the rest, l = S - u*. With a cap on the line, u = S - cap and the delay carries it. The binding quarter is where (D + u - m_k)/l_k is largest.
A4: Declared set | B4: Cut alpha | C4: D: deviations' bound | D4: S: closure's bound | E4: Cap on the line | F4: Delay the deviations need | G4: Margin absorbs (no cap) | H4: Capped? | I4: Margin absorbs | J4: Line | K4: Delay | L4: Cost | M4: Need, q1 | N4: Need, q2 | O4: Need, q3 | P4: Need, q4 | Q4: Need, q5 | R4: Need, q6 | S4: Need, q7 | T4: Need, q8 | U4: Need, q9 | V4: Need, q10 | W4: Need, q11 | X4: Need, q12 | Y4: Binding quarter | Z4: Paths in the set (engine) | AA4: Breach under the law (engine) | AB4: Fresh paths (engine)
A5: Volume I's joint check | C5: 0 | D5: =SJoint -> 187 | F5: =MAX(0,(C5-Plan!$H$5)/Plan!$I$5,(C5-Plan!$H$6)/Plan!$I$6,(C5-Plan!$H$7)/Plan!$I$7,(C5-Plan!$H$8)/Plan!$I$8,(C5-Plan!$H$9)/Plan!$I$9,(C5-Plan!$H$10)/Plan!$I$10,(C5-Plan!$H$11)/Plan!$I$11,(C5-Plan!$H$12)/Plan!$I$12,(C5-Plan!$H$13)/Plan!$I$13,(C5-Plan!$H$14)/Plan!$I$14,(C5-Plan!$H$15)/Plan!$I$15,(C5-Plan!$H$16)/Plan!$I$16) -> 0 | G5: =MIN(D5,Plan!$H$5-C5+Plan!$I$5*F5,Plan!$H$6-C5+Plan!$I$6*F5,Plan!$H$7-C5+Plan!$I$7*F5,Plan!$H$8-C5+Plan!$I$8*F5,Plan!$H$9-C5+Plan!$I$9*F5,Plan!$H$10-C5+Plan!$I$10*F5,Plan!$H$11-C5+Plan!$I$11*F5,Plan!$H$12-C5+Plan!$I$12*F5,Plan!$H$13-C5+Plan!$I$13*F5,Plan!$H$14-C5+Plan!$I$14*F5,Plan!$H$15-C5+Plan!$I$15*F5,Plan!$H$16-C5+Plan!$I$16*F5) -> 131.95038 | H5: =IF(ISNUMBER(E5),IF(D5-G5>E5,1,0),0) -> 0 | I5: =IF(H5=1,D5-E5,G5) -> 131.95038 | J5: =D5-I5 -> 55.049618 | K5: =IF(H5=1,MAX(0,(C5+I5-Plan!$H$5)/Plan!$I$5,(C5+I5-Plan!$H$6)/Plan!$I$6,(C5+I5-Plan!$H$7)/Plan!$I$7,(C5+I5-Plan!$H$8)/Plan!$I$8,(C5+I5-Plan!$H$9)/Plan!$I$9,(C5+I5-Plan!$H$10)/Plan!$I$10,(C5+I5-Plan!$H$11)/Plan!$I$11,(C5+I5-Plan!$H$12)/Plan!$I$12,(C5+I5-Plan!$H$13)/Plan!$I$13,(C5+I5-Plan!$H$14)/Plan!$I$14,(C5+I5-Plan!$H$15)/Plan!$I$15,(C5+I5-Plan!$H$16)/Plan!$I$16),F5) -> 0 | L5: =Fee*J5+VQ*K5 -> 1.6514885 | M5: =(C5+I5-Plan!$H$5)/Plan!$I$5 -> -12.40196 | N5: =(C5+I5-Plan!$H$6)/Plan!$I$6 -> -4.4277671 | O5: =(C5+I5-Plan!$H$7)/Plan!$I$7 -> -1.9340667 | P5: =(C5+I5-Plan!$H$8)/Plan!$I$8 -> -0.82722063 | Q5: =(C5+I5-Plan!$H$9)/Plan!$I$9 -> -0.2902932 | R5: =(C5+I5-Plan!$H$10)/Plan!$I$10 -> -0.052664907 | S5: =(C5+I5-Plan!$H$11)/Plan!$I$11 -> 0 | T5: =(C5+I5-Plan!$H$12)/Plan!$I$12 -> -0.076760929 | U5: =(C5+I5-Plan!$H$13)/Plan!$I$13 -> -0.25373586 | V5: =(C5+I5-Plan!$H$14)/Plan!$I$14 -> -0.51507286 | W5: =(C5+I5-Plan!$H$15)/Plan!$I$15 -> -0.85241014 | X5: =(C5+I5-Plan!$H$16)/Plan!$I$16 -> -1.2619661 | Y5: =MATCH(MAX(M5:X5),M5:X5,0) -> 7 | Z5: 0.01488 | AA5: 0.17388 | AB5: 0.17124
A6: Crisp set (the 0.5-cut) | B6: 0.5 | C6: =DNever-(DNever-DUsual)*B6 -> 125 | D6: =SNever-(SNever-SPlaus)*B6 -> 210 | F6: =MAX(0,(C6-Plan!$H$5)/Plan!$I$5,(C6-Plan!$H$6)/Plan!$I$6,(C6-Plan!$H$7)/Plan!$I$7,(C6-Plan!$H$8)/Plan!$I$8,(C6-Plan!$H$9)/Plan!$I$9,(C6-Plan!$H$10)/Plan!$I$10,(C6-Plan!$H$11)/Plan!$I$11,(C6-Plan!$H$12)/Plan!$I$12,(C6-Plan!$H$13)/Plan!$I$13,(C6-Plan!$H$14)/Plan!$I$14,(C6-Plan!$H$15)/Plan!$I$15,(C6-Plan!$H$16)/Plan!$I$16) -> 0 | G6: =MIN(D6,Plan!$H$5-C6+Plan!$I$5*F6,Plan!$H$6-C6+Plan!$I$6*F6,Plan!$H$7-C6+Plan!$I$7*F6,Plan!$H$8-C6+Plan!$I$8*F6,Plan!$H$9-C6+Plan!$I$9*F6,Plan!$H$10-C6+Plan!$I$10*F6,Plan!$H$11-C6+Plan!$I$11*F6,Plan!$H$12-C6+Plan!$I$12*F6,Plan!$H$13-C6+Plan!$I$13*F6,Plan!$H$14-C6+Plan!$I$14*F6,Plan!$H$15-C6+Plan!$I$15*F6,Plan!$H$16-C6+Plan!$I$16*F6) -> 6.9503824 | H6: =IF(ISNUMBER(E6),IF(D6-G6>E6,1,0),0) -> 0 | I6: =IF(H6=1,D6-E6,G6) -> 6.9503824 | J6: =D6-I6 -> 203.04962 | K6: =IF(H6=1,MAX(0,(C6+I6-Plan!$H$5)/Plan!$I$5,(C6+I6-Plan!$H$6)/Plan!$I$6,(C6+I6-Plan!$H$7)/Plan!$I$7,(C6+I6-Plan!$H$8)/Plan!$I$8,(C6+I6-Plan!$H$9)/Plan!$I$9,(C6+I6-Plan!$H$10)/Plan!$I$10,(C6+I6-Plan!$H$11)/Plan!$I$11,(C6+I6-Plan!$H$12)/Plan!$I$12,(C6+I6-Plan!$H$13)/Plan!$I$13,(C6+I6-Plan!$H$14)/Plan!$I$14,(C6+I6-Plan!$H$15)/Plan!$I$15,(C6+I6-Plan!$H$16)/Plan!$I$16),F6) -> 0 | L6: =Fee*J6+VQ*K6 -> 6.0914885 | M6: =(C6+I6-Plan!$H$5)/Plan!$I$5 -> -12.40196 | N6: =(C6+I6-Plan!$H$6)/Plan!$I$6 -> -4.4277671 | O6: =(C6+I6-Plan!$H$7)/Plan!$I$7 -> -1.9340667 | P6: =(C6+I6-Plan!$H$8)/Plan!$I$8 -> -0.82722063 | Q6: =(C6+I6-Plan!$H$9)/Plan!$I$9 -> -0.2902932 | R6: =(C6+I6-Plan!$H$10)/Plan!$I$10 -> -0.052664907 | S6: =(C6+I6-Plan!$H$11)/Plan!$I$11 -> 0 | T6: =(C6+I6-Plan!$H$12)/Plan!$I$12 -> -0.076760929 | U6: =(C6+I6-Plan!$H$13)/Plan!$I$13 -> -0.25373586 | V6: =(C6+I6-Plan!$H$14)/Plan!$I$14 -> -0.51507286 | W6: =(C6+I6-Plan!$H$15)/Plan!$I$15 -> -0.85241014 | X6: =(C6+I6-Plan!$H$16)/Plan!$I$16 -> -1.2619661 | Y6: =MATCH(MAX(M6:X6),M6:X6,0) -> 7 | Z6: 0.78907 | AA6: 0.08645 | AB6: 0.08435
A7: Max-min choice | B7: =Graded!$U$7 -> 0.38 | C7: =DNever-(DNever-DUsual)*B7 -> 143 | D7: =SNever-(SNever-SPlaus)*B7 -> 231.6 | F7: =MAX(0,(C7-Plan!$H$5)/Plan!$I$5,(C7-Plan!$H$6)/Plan!$I$6,(C7-Plan!$H$7)/Plan!$I$7,(C7-Plan!$H$8)/Plan!$I$8,(C7-Plan!$H$9)/Plan!$I$9,(C7-Plan!$H$10)/Plan!$I$10,(C7-Plan!$H$11)/Plan!$I$11,(C7-Plan!$H$12)/Plan!$I$12,(C7-Plan!$H$13)/Plan!$I$13,(C7-Plan!$H$14)/Plan!$I$14,(C7-Plan!$H$15)/Plan!$I$15,(C7-Plan!$H$16)/Plan!$I$16) -> 0.44936651 | G7: =MIN(D7,Plan!$H$5-C7+Plan!$I$5*F7,Plan!$H$6-C7+Plan!$I$6*F7,Plan!$H$7-C7+Plan!$I$7*F7,Plan!$H$8-C7+Plan!$I$8*F7,Plan!$H$9-C7+Plan!$I$9*F7,Plan!$H$10-C7+Plan!$I$10*F7,Plan!$H$11-C7+Plan!$I$11*F7,Plan!$H$12-C7+Plan!$I$12*F7,Plan!$H$13-C7+Plan!$I$13*F7,Plan!$H$14-C7+Plan!$I$14*F7,Plan!$H$15-C7+Plan!$I$15*F7,Plan!$H$16-C7+Plan!$I$16*F7) -> 0 | H7: =IF(ISNUMBER(E7),IF(D7-G7>E7,1,0),0) -> 0 | I7: =IF(H7=1,D7-E7,G7) -> 0 | J7: =D7-I7 -> 231.6 | K7: =IF(H7=1,MAX(0,(C7+I7-Plan!$H$5)/Plan!$I$5,(C7+I7-Plan!$H$6)/Plan!$I$6,(C7+I7-Plan!$H$7)/Plan!$I$7,(C7+I7-Plan!$H$8)/Plan!$I$8,(C7+I7-Plan!$H$9)/Plan!$I$9,(C7+I7-Plan!$H$10)/Plan!$I$10,(C7+I7-Plan!$H$11)/Plan!$I$11,(C7+I7-Plan!$H$12)/Plan!$I$12,(C7+I7-Plan!$H$13)/Plan!$I$13,(C7+I7-Plan!$H$14)/Plan!$I$14,(C7+I7-Plan!$H$15)/Plan!$I$15,(C7+I7-Plan!$H$16)/Plan!$I$16),F7) -> 0.44936651 | L7: =Fee*J7+VQ*K7 -> 10.542932 | M7: =(C7+I7-Plan!$H$5)/Plan!$I$5 -> -10.9161 | N7: =(C7+I7-Plan!$H$6)/Plan!$I$6 -> -3.5859171 | O7: =(C7+I7-Plan!$H$7)/Plan!$I$7 -> -1.298106 | P7: =(C7+I7-Plan!$H$8)/Plan!$I$8 -> -0.28674225 | Q7: =(C7+I7-Plan!$H$9)/Plan!$I$9 -> 0.19966059 | R7: =(C7+I7-Plan!$H$10)/Plan!$I$10 -> 0.40999374 | S7: =(C7+I7-Plan!$H$11)/Plan!$I$11 -> 0.44936651 | T7: =(C7+I7-Plan!$H$12)/Plan!$I$12 -> 0.36878817 | U7: =(C7+I7-Plan!$H$13)/Plan!$I$13 -> 0.19504038 | V7: =(C7+I7-Plan!$H$14)/Plan!$I$14 -> -0.057395763 | W7: =(C7+I7-Plan!$H$15)/Plan!$I$15 -> -0.38094097 | X7: =(C7+I7-Plan!$H$16)/Plan!$I$16 -> -0.77224188 | Y7: =MATCH(MAX(M7:X7),M7:X7,0) -> 7 | Z7: 0.87036 | AA7: 0.05637 | AB7: 0.05508
A8: Meeting 5% under the law | B8: =Graded!$U$12 -> 0.35 | C8: =DNever-(DNever-DUsual)*B8 -> 147.5 | D8: =SNever-(SNever-SPlaus)*B8 -> 237 | F8: =MAX(0,(C8-Plan!$H$5)/Plan!$I$5,(C8-Plan!$H$6)/Plan!$I$6,(C8-Plan!$H$7)/Plan!$I$7,(C8-Plan!$H$8)/Plan!$I$8,(C8-Plan!$H$9)/Plan!$I$9,(C8-Plan!$H$10)/Plan!$I$10,(C8-Plan!$H$11)/Plan!$I$11,(C8-Plan!$H$12)/Plan!$I$12,(C8-Plan!$H$13)/Plan!$I$13,(C8-Plan!$H$14)/Plan!$I$14,(C8-Plan!$H$15)/Plan!$I$15,(C8-Plan!$H$16)/Plan!$I$16) -> 0.63237278 | G8: =MIN(D8,Plan!$H$5-C8+Plan!$I$5*F8,Plan!$H$6-C8+Plan!$I$6*F8,Plan!$H$7-C8+Plan!$I$7*F8,Plan!$H$8-C8+Plan!$I$8*F8,Plan!$H$9-C8+Plan!$I$9*F8,Plan!$H$10-C8+Plan!$I$10*F8,Plan!$H$11-C8+Plan!$I$11*F8,Plan!$H$12-C8+Plan!$I$12*F8,Plan!$H$13-C8+Plan!$I$13*F8,Plan!$H$14-C8+Plan!$I$14*F8,Plan!$H$15-C8+Plan!$I$15*F8,Plan!$H$16-C8+Plan!$I$16*F8) -> 0 | H8: =IF(ISNUMBER(E8),IF(D8-G8>E8,1,0),0) -> 0 | I8: =IF(H8=1,D8-E8,G8) -> 0 | J8: =D8-I8 -> 237 | K8: =IF(H8=1,MAX(0,(C8+I8-Plan!$H$5)/Plan!$I$5,(C8+I8-Plan!$H$6)/Plan!$I$6,(C8+I8-Plan!$H$7)/Plan!$I$7,(C8+I8-Plan!$H$8)/Plan!$I$8,(C8+I8-Plan!$H$9)/Plan!$I$9,(C8+I8-Plan!$H$10)/Plan!$I$10,(C8+I8-Plan!$H$11)/Plan!$I$11,(C8+I8-Plan!$H$12)/Plan!$I$12,(C8+I8-Plan!$H$13)/Plan!$I$13,(C8+I8-Plan!$H$14)/Plan!$I$14,(C8+I8-Plan!$H$15)/Plan!$I$15,(C8+I8-Plan!$H$16)/Plan!$I$16),F8) -> 0.63237278 | L8: =Fee*J8+VQ*K8 -> 12.168982 | M8: =(C8+I8-Plan!$H$5)/Plan!$I$5 -> -10.310977 | N8: =(C8+I8-Plan!$H$6)/Plan!$I$6 -> -3.2430704 | O8: =(C8+I8-Plan!$H$7)/Plan!$I$7 -> -1.0391086 | P8: =(C8+I8-Plan!$H$8)/Plan!$I$8 -> -0.066630319 | Q8: =(C8+I8-Plan!$H$9)/Plan!$I$9 -> 0.39919619 | R8: =(C8+I8-Plan!$H$10)/Plan!$I$10 -> 0.59841329 | S8: =(C8+I8-Plan!$H$11)/Plan!$I$11 -> 0.63237278 | T8: =(C8+I8-Plan!$H$12)/Plan!$I$12 -> 0.55023978 | U8: =(C8+I8-Plan!$H$13)/Plan!$I$13 -> 0.37780626 | V8: =(C8+I8-Plan!$H$14)/Plan!$I$14 -> 0.12899502 | W8: =(C8+I8-Plan!$H$15)/Plan!$I$15 -> -0.1889333 | X8: =(C8+I8-Plan!$H$16)/Plan!$I$16 -> -0.57279979 | Y8: =MATCH(MAX(M8:X8),M8:X8,0) -> 7 | Z8: 0.88533 | AA8: 0.04712 | AB8: 0.04617
A9: 95% of paths in the set | B9: =Graded!$U$13 -> 0.08 | C9: =DNever-(DNever-DUsual)*B9 -> 188 | D9: =SNever-(SNever-SPlaus)*B9 -> 285.6 | F9: =MAX(0,(C9-Plan!$H$5)/Plan!$I$5,(C9-Plan!$H$6)/Plan!$I$6,(C9-Plan!$H$7)/Plan!$I$7,(C9-Plan!$H$8)/Plan!$I$8,(C9-Plan!$H$9)/Plan!$I$9,(C9-Plan!$H$10)/Plan!$I$10,(C9-Plan!$H$11)/Plan!$I$11,(C9-Plan!$H$12)/Plan!$I$12,(C9-Plan!$H$13)/Plan!$I$13,(C9-Plan!$H$14)/Plan!$I$14,(C9-Plan!$H$15)/Plan!$I$15,(C9-Plan!$H$16)/Plan!$I$16) -> 2.2941892 | G9: =MIN(D9,Plan!$H$5-C9+Plan!$I$5*F9,Plan!$H$6-C9+Plan!$I$6*F9,Plan!$H$7-C9+Plan!$I$7*F9,Plan!$H$8-C9+Plan!$I$8*F9,Plan!$H$9-C9+Plan!$I$9*F9,Plan!$H$10-C9+Plan!$I$10*F9,Plan!$H$11-C9+Plan!$I$11*F9,Plan!$H$12-C9+Plan!$I$12*F9,Plan!$H$13-C9+Plan!$I$13*F9,Plan!$H$14-C9+Plan!$I$14*F9,Plan!$H$15-C9+Plan!$I$15*F9,Plan!$H$16-C9+Plan!$I$16*F9) -> 0 | H9: =IF(ISNUMBER(E9),IF(D9-G9>E9,1,0),0) -> 0 | I9: =IF(H9=1,D9-E9,G9) -> 0 | J9: =D9-I9 -> 285.6 | K9: =IF(H9=1,MAX(0,(C9+I9-Plan!$H$5)/Plan!$I$5,(C9+I9-Plan!$H$6)/Plan!$I$6,(C9+I9-Plan!$H$7)/Plan!$I$7,(C9+I9-Plan!$H$8)/Plan!$I$8,(C9+I9-Plan!$H$9)/Plan!$I$9,(C9+I9-Plan!$H$10)/Plan!$I$10,(C9+I9-Plan!$H$11)/Plan!$I$11,(C9+I9-Plan!$H$12)/Plan!$I$12,(C9+I9-Plan!$H$13)/Plan!$I$13,(C9+I9-Plan!$H$14)/Plan!$I$14,(C9+I9-Plan!$H$15)/Plan!$I$15,(C9+I9-Plan!$H$16)/Plan!$I$16),F9) -> 2.2941892 | L9: =Fee*J9+VQ*K9 -> 26.921513 | M9: =(C9+I9-Plan!$H$5)/Plan!$I$5 -> -4.8648769 | N9: =(C9+I9-Plan!$H$6)/Plan!$I$6 -> -0.1574502 | O9: =(C9+I9-Plan!$H$7)/Plan!$I$7 -> 1.2918686 | P9: =(C9+I9-Plan!$H$8)/Plan!$I$8 -> 1.9143771 | Q9: =(C9+I9-Plan!$H$9)/Plan!$I$9 -> 2.1950166 | R9: =(C9+I9-Plan!$H$10)/Plan!$I$10 -> 2.2941892 | S9: =(C9+I9-Plan!$H$11)/Plan!$I$11 -> 2.2794292 | T9: =(C9+I9-Plan!$H$12)/Plan!$I$12 -> 2.1833043 | U9: =(C9+I9-Plan!$H$13)/Plan!$I$13 -> 2.0226992 | V9: =(C9+I9-Plan!$H$14)/Plan!$I$14 -> 1.8065121 | W9: =(C9+I9-Plan!$H$15)/Plan!$I$15 -> 1.5391357 | X9: =(C9+I9-Plan!$H$16)/Plan!$I$16 -> 1.222179 | Y9: =MATCH(MAX(M9:X9),M9:X9,0) -> 6 | Z9: 0.95021 | AA9: 0.00757 | AB9: 0.00731
A10: The whole support (the 0-cut) | B10: 0 | C10: =DNever-(DNever-DUsual)*B10 -> 200 | D10: =SNever-(SNever-SPlaus)*B10 -> 300 | F10: =MAX(0,(C10-Plan!$H$5)/Plan!$I$5,(C10-Plan!$H$6)/Plan!$I$6,(C10-Plan!$H$7)/Plan!$I$7,(C10-Plan!$H$8)/Plan!$I$8,(C10-Plan!$H$9)/Plan!$I$9,(C10-Plan!$H$10)/Plan!$I$10,(C10-Plan!$H$11)/Plan!$I$11,(C10-Plan!$H$12)/Plan!$I$12,(C10-Plan!$H$13)/Plan!$I$13,(C10-Plan!$H$14)/Plan!$I$14,(C10-Plan!$H$15)/Plan!$I$15,(C10-Plan!$H$16)/Plan!$I$16) -> 2.7966413 | G10: =MIN(D10,Plan!$H$5-C10+Plan!$I$5*F10,Plan!$H$6-C10+Plan!$I$6*F10,Plan!$H$7-C10+Plan!$I$7*F10,Plan!$H$8-C10+Plan!$I$8*F10,Plan!$H$9-C10+Plan!$I$9*F10,Plan!$H$10-C10+Plan!$I$10*F10,Plan!$H$11-C10+Plan!$I$11*F10,Plan!$H$12-C10+Plan!$I$12*F10,Plan!$H$13-C10+Plan!$I$13*F10,Plan!$H$14-C10+Plan!$I$14*F10,Plan!$H$15-C10+Plan!$I$15*F10,Plan!$H$16-C10+Plan!$I$16*F10) -> 0 | H10: =IF(ISNUMBER(E10),IF(D10-G10>E10,1,0),0) -> 0 | I10: =IF(H10=1,D10-E10,G10) -> 0 | J10: =D10-I10 -> 300 | K10: =IF(H10=1,MAX(0,(C10+I10-Plan!$H$5)/Plan!$I$5,(C10+I10-Plan!$H$6)/Plan!$I$6,(C10+I10-Plan!$H$7)/Plan!$I$7,(C10+I10-Plan!$H$8)/Plan!$I$8,(C10+I10-Plan!$H$9)/Plan!$I$9,(C10+I10-Plan!$H$10)/Plan!$I$10,(C10+I10-Plan!$H$11)/Plan!$I$11,(C10+I10-Plan!$H$12)/Plan!$I$12,(C10+I10-Plan!$H$13)/Plan!$I$13,(C10+I10-Plan!$H$14)/Plan!$I$14,(C10+I10-Plan!$H$15)/Plan!$I$15,(C10+I10-Plan!$H$16)/Plan!$I$16),F10) -> 2.7966413 | L10: =Fee*J10+VQ*K10 -> 31.37313 | M10: =(C10+I10-Plan!$H$5)/Plan!$I$5 -> -3.2512174 | N10: =(C10+I10-Plan!$H$6)/Plan!$I$6 -> 0.75680764 | O10: =(C10+I10-Plan!$H$7)/Plan!$I$7 -> 1.9825285 | P10: =(C10+I10-Plan!$H$8)/Plan!$I$8 -> 2.5013422 | Q10: =(C10+I10-Plan!$H$9)/Plan!$I$9 -> 2.7271115 | R10: =(C10+I10-Plan!$H$10)/Plan!$I$10 -> 2.7966413 | S10: =(C10+I10-Plan!$H$11)/Plan!$I$11 -> 2.7674459 | T10: =(C10+I10-Plan!$H$12)/Plan!$I$12 -> 2.6671753 | U10: =(C10+I10-Plan!$H$13)/Plan!$I$13 -> 2.5100749 | V10: =(C10+I10-Plan!$H$14)/Plan!$I$14 -> 2.3035542 | W10: =(C10+I10-Plan!$H$15)/Plan!$I$15 -> 2.0511561 | X10: =(C10+I10-Plan!$H$16)/Plan!$I$16 -> 1.7540246 | Y10: =MATCH(MAX(M10:X10),M10:X10,0) -> 6 | Z10: 0.95581 | AA10: 0.00393 | AB10: 0.00394
A11: The revision of Step 5 | C11: 140 | D11: 230 | F11: =MAX(0,(C11-Plan!$H$5)/Plan!$I$5,(C11-Plan!$H$6)/Plan!$I$6,(C11-Plan!$H$7)/Plan!$I$7,(C11-Plan!$H$8)/Plan!$I$8,(C11-Plan!$H$9)/Plan!$I$9,(C11-Plan!$H$10)/Plan!$I$10,(C11-Plan!$H$11)/Plan!$I$11,(C11-Plan!$H$12)/Plan!$I$12,(C11-Plan!$H$13)/Plan!$I$13,(C11-Plan!$H$14)/Plan!$I$14,(C11-Plan!$H$15)/Plan!$I$15,(C11-Plan!$H$16)/Plan!$I$16) -> 0.32736233 | G11: =MIN(D11,Plan!$H$5-C11+Plan!$I$5*F11,Plan!$H$6-C11+Plan!$I$6*F11,Plan!$H$7-C11+Plan!$I$7*F11,Plan!$H$8-C11+Plan!$I$8*F11,Plan!$H$9-C11+Plan!$I$9*F11,Plan!$H$10-C11+Plan!$I$10*F11,Plan!$H$11-C11+Plan!$I$11*F11,Plan!$H$12-C11+Plan!$I$12*F11,Plan!$H$13-C11+Plan!$I$13*F11,Plan!$H$14-C11+Plan!$I$14*F11,Plan!$H$15-C11+Plan!$I$15*F11,Plan!$H$16-C11+Plan!$I$16*F11) -> 0 | H11: =IF(ISNUMBER(E11),IF(D11-G11>E11,1,0),0) -> 0 | I11: =IF(H11=1,D11-E11,G11) -> 0 | J11: =D11-I11 -> 230 | K11: =IF(H11=1,MAX(0,(C11+I11-Plan!$H$5)/Plan!$I$5,(C11+I11-Plan!$H$6)/Plan!$I$6,(C11+I11-Plan!$H$7)/Plan!$I$7,(C11+I11-Plan!$H$8)/Plan!$I$8,(C11+I11-Plan!$H$9)/Plan!$I$9,(C11+I11-Plan!$H$10)/Plan!$I$10,(C11+I11-Plan!$H$11)/Plan!$I$11,(C11+I11-Plan!$H$12)/Plan!$I$12,(C11+I11-Plan!$H$13)/Plan!$I$13,(C11+I11-Plan!$H$14)/Plan!$I$14,(C11+I11-Plan!$H$15)/Plan!$I$15,(C11+I11-Plan!$H$16)/Plan!$I$16),F11) -> 0.32736233 | L11: =Fee*J11+VQ*K11 -> 9.5188987 | M11: =(C11+I11-Plan!$H$5)/Plan!$I$5 -> -11.319515 | N11: =(C11+I11-Plan!$H$6)/Plan!$I$6 -> -3.8144816 | O11: =(C11+I11-Plan!$H$7)/Plan!$I$7 -> -1.470771 | P11: =(C11+I11-Plan!$H$8)/Plan!$I$8 -> -0.43348354 | Q11: =(C11+I11-Plan!$H$9)/Plan!$I$9 -> 0.066636857 | R11: =(C11+I11-Plan!$H$10)/Plan!$I$10 -> 0.28438071 | S11: =(C11+I11-Plan!$H$11)/Plan!$I$11 -> 0.32736233 | T11: =(C11+I11-Plan!$H$12)/Plan!$I$12 -> 0.24782043 | U11: =(C11+I11-Plan!$H$13)/Plan!$I$13 -> 0.073196459 | V11: =(C11+I11-Plan!$H$14)/Plan!$I$14 -> -0.18165629 | W11: =(C11+I11-Plan!$H$15)/Plan!$I$15 -> -0.50894608 | X11: =(C11+I11-Plan!$H$16)/Plan!$I$16 -> -0.90520328 | Y11: =MATCH(MAX(M11:X11),M11:X11,0) -> 7 | Z11: 0.85976 | AA11: 0.06332 | AB11: 0.06137
A12: The crisp set, the line capped | B12: 0.5 | C12: =DNever-(DNever-DUsual)*B12 -> 125 | D12: =SNever-(SNever-SPlaus)*B12 -> 210 | E12: =CapL -> 100 | F12: =MAX(0,(C12-Plan!$H$5)/Plan!$I$5,(C12-Plan!$H$6)/Plan!$I$6,(C12-Plan!$H$7)/Plan!$I$7,(C12-Plan!$H$8)/Plan!$I$8,(C12-Plan!$H$9)/Plan!$I$9,(C12-Plan!$H$10)/Plan!$I$10,(C12-Plan!$H$11)/Plan!$I$11,(C12-Plan!$H$12)/Plan!$I$12,(C12-Plan!$H$13)/Plan!$I$13,(C12-Plan!$H$14)/Plan!$I$14,(C12-Plan!$H$15)/Plan!$I$15,(C12-Plan!$H$16)/Plan!$I$16) -> 0 | G12: =MIN(D12,Plan!$H$5-C12+Plan!$I$5*F12,Plan!$H$6-C12+Plan!$I$6*F12,Plan!$H$7-C12+Plan!$I$7*F12,Plan!$H$8-C12+Plan!$I$8*F12,Plan!$H$9-C12+Plan!$I$9*F12,Plan!$H$10-C12+Plan!$I$10*F12,Plan!$H$11-C12+Plan!$I$11*F12,Plan!$H$12-C12+Plan!$I$12*F12,Plan!$H$13-C12+Plan!$I$13*F12,Plan!$H$14-C12+Plan!$I$14*F12,Plan!$H$15-C12+Plan!$I$15*F12,Plan!$H$16-C12+Plan!$I$16*F12) -> 6.9503824 | H12: =IF(ISNUMBER(E12),IF(D12-G12>E12,1,0),0) -> 1 | I12: =IF(H12=1,D12-E12,G12) -> 110 | J12: =D12-I12 -> 100 | K12: =IF(H12=1,MAX(0,(C12+I12-Plan!$H$5)/Plan!$I$5,(C12+I12-Plan!$H$6)/Plan!$I$6,(C12+I12-Plan!$H$7)/Plan!$I$7,(C12+I12-Plan!$H$8)/Plan!$I$8,(C12+I12-Plan!$H$9)/Plan!$I$9,(C12+I12-Plan!$H$10)/Plan!$I$10,(C12+I12-Plan!$H$11)/Plan!$I$11,(C12+I12-Plan!$H$12)/Plan!$I$12,(C12+I12-Plan!$H$13)/Plan!$I$13,(C12+I12-Plan!$H$14)/Plan!$I$14,(C12+I12-Plan!$H$15)/Plan!$I$15,(C12+I12-Plan!$H$16)/Plan!$I$16),F12) -> 4.279055 | L12: =Fee*J12+VQ*K12 -> 37.23244 | M12: =(C12+I12-Plan!$H$5)/Plan!$I$5 -> 1.4552892 | N12: =(C12+I12-Plan!$H$6)/Plan!$I$6 -> 3.423393 | O12: =(C12+I12-Plan!$H$7)/Plan!$I$7 -> 3.9969533 | P12: =(C12+I12-Plan!$H$8)/Plan!$I$8 -> 4.2133239 | Q12: =(C12+I12-Plan!$H$9)/Plan!$I$9 -> 4.279055 | R12: =(C12+I12-Plan!$H$10)/Plan!$I$10 -> 4.2621266 | S12: =(C12+I12-Plan!$H$11)/Plan!$I$11 -> 4.190828 | T12: =(C12+I12-Plan!$H$12)/Plan!$I$12 -> 4.0784656 | U12: =(C12+I12-Plan!$H$13)/Plan!$I$13 -> 3.9315872 | V12: =(C12+I12-Plan!$H$14)/Plan!$I$14 -> 3.7532603 | W12: =(C12+I12-Plan!$H$15)/Plan!$I$15 -> 3.5445491 | X12: =(C12+I12-Plan!$H$16)/Plan!$I$16 -> 3.3052408 | Y12: =MATCH(MAX(M12:X12),M12:X12,0) -> 5 | Z12: 0.78907 | AA12: 0.00643 | AB12: 0.00664
A14: The crisp set: deviations use, of the least margin | B14: =C6 -> 125 | C14: $125 million of $132 million
A15: the closure's first part fits in the rest | B15: =I6 -> 6.9503824 | C15: $7 million
A16: the line covers the remainder | B16: =J6 -> 203.04962 | C16: $203 million, no delay: $6.09 million
A17: the set holds (engine) | B17: =Z6 -> 0.78907 | C17: 79 percent of the book's paths
A18: so Theorem 10.1(iii) promised a chance of at most | B18: =1-B17 -> 0.21093 | C18: 21 percent; under the law 8.6 percent
A19: Proposition 10.3(iii): quarter 7 on a future quiet through quarter 6, then deviations at -D and the closure, crisp package | B19: =FloorL+Plan!$H$11+Plan!$I$11*K6-C6-MAX(D6-J6,0) -> 350 | C19: Exactly the floor: cash read before quarter 7 saw nothing, so a rule that reads cash saves nothing
A20: Volume I's joint check: the margin absorbs | B20: =I5 -> 131.95038 | C20: All of quarter 7's margin
A21: breach under the law (engine) | B21: =AA5 -> 0.17388 | C21: 17.4 percent: its set left out the deviations, which alone breach 8.4 percent
A23: Change D, S or the cap in the blue cells: the package, its cost and the binding quarter recompute. The chances need Chapter 9's paths and stay the engine's.

Sheet Graded
A1: The offices' words cut by cut, the graded price, and the max-min choice (Theorem 10.2; Proposition 10.2; Figure 10.1; Worked Example 10.1, Step 3; AXIOM Lab 2.10, step 2)
A2: Cut at alpha: D = 200 - 150 alpha, S = 300 - 180 alpha (Theorem 10.2(i)); necessity of safety 1 - alpha (Theorem 10.2(ii)); the board's goal (20 - cost)/15, clipped to [0, 1]; the max-min choice maximizes the smaller of the goal and the necessity (Theorem 10.2(iii)), on the book's grid of 0.01.
A5: Cut alpha | B5: D | C5: S | D5: Delay | E5: Margin absorbs | F5: Line | G5: Delay | H5: Cost | I5: Goal for cost | J5: Necessity of safety | K5: Level: min(goal, necessity) | L5: Paths in the set (engine) | M5: Breach under the law (engine) | N5: Fresh paths (engine) | O5: Meets 5%: alpha | P5: Holds 95%: alpha | Q5: 'Very cheap': level | R5: 'Somewhat cheap': level
A6: 0 | B6: =DNever-(DNever-DUsual)*A6 -> 200 | C6: =SNever-(SNever-SPlaus)*A6 -> 300 | D6: =MAX(0,(B6-Plan!$H$5)/Plan!$I$5,(B6-Plan!$H$6)/Plan!$I$6,(B6-Plan!$H$7)/Plan!$I$7,(B6-Plan!$H$8)/Plan!$I$8,(B6-Plan!$H$9)/Plan!$I$9,(B6-Plan!$H$10)/Plan!$I$10,(B6-Plan!$H$11)/Plan!$I$11,(B6-Plan!$H$12)/Plan!$I$12,(B6-Plan!$H$13)/Plan!$I$13,(B6-Plan!$H$14)/Plan!$I$14,(B6-Plan!$H$15)/Plan!$I$15,(B6-Plan!$H$16)/Plan!$I$16) -> 2.7966413 | E6: =MIN(C6,Plan!$H$5-B6+Plan!$I$5*D6,Plan!$H$6-B6+Plan!$I$6*D6,Plan!$H$7-B6+Plan!$I$7*D6,Plan!$H$8-B6+Plan!$I$8*D6,Plan!$H$9-B6+Plan!$I$9*D6,Plan!$H$10-B6+Plan!$I$10*D6,Plan!$H$11-B6+Plan!$I$11*D6,Plan!$H$12-B6+Plan!$I$12*D6,Plan!$H$13-B6+Plan!$I$13*D6,Plan!$H$14-B6+Plan!$I$14*D6,Plan!$H$15-B6+Plan!$I$15*D6,Plan!$H$16-B6+Plan!$I$16*D6) -> 0 | F6: =C6-E6 -> 300 | G6: =D6 -> 2.7966413 | H6: =Fee*F6+VQ*G6 -> 31.37313 | I6: =MAX(0,MIN(1,(GNone-H6)/(GNone-GFull))) -> 0 | J6: =1-A6 -> 1 | K6: =MIN(I6,J6) -> 0 | L6: 0.95581 | M6: 0.00393 | N6: 0.00394 | O6: =IF(M6<=Alpha,A6,-1) -> 0 | P6: =IF(L6>=0.95,A6,-1) -> 0 | Q6: =MIN(I6^2,J6) -> 0 | R6: =MIN(SQRT(I6),J6) -> 0 | T6: Max-min level | U6: =MAX(K6:K106) -> 0.62 | V6: 0.62
A7: 0.01 | B7: =DNever-(DNever-DUsual)*A7 -> 198.5 | C7: =SNever-(SNever-SPlaus)*A7 -> 298.2 | D7: =MAX(0,(B7-Plan!$H$5)/Plan!$I$5,(B7-Plan!$H$6)/Plan!$I$6,(B7-Plan!$H$7)/Plan!$I$7,(B7-Plan!$H$8)/Plan!$I$8,(B7-Plan!$H$9)/Plan!$I$9,(B7-Plan!$H$10)/Plan!$I$10,(B7-Plan!$H$11)/Plan!$I$11,(B7-Plan!$H$12)/Plan!$I$12,(B7-Plan!$H$13)/Plan!$I$13,(B7-Plan!$H$14)/Plan!$I$14,(B7-Plan!$H$15)/Plan!$I$15,(B7-Plan!$H$16)/Plan!$I$16) -> 2.7338348 | E7: =MIN(C7,Plan!$H$5-B7+Plan!$I$5*D7,Plan!$H$6-B7+Plan!$I$6*D7,Plan!$H$7-B7+Plan!$I$7*D7,Plan!$H$8-B7+Plan!$I$8*D7,Plan!$H$9-B7+Plan!$I$9*D7,Plan!$H$10-B7+Plan!$I$10*D7,Plan!$H$11-B7+Plan!$I$11*D7,Plan!$H$12-B7+Plan!$I$12*D7,Plan!$H$13-B7+Plan!$I$13*D7,Plan!$H$14-B7+Plan!$I$14*D7,Plan!$H$15-B7+Plan!$I$15*D7,Plan!$H$16-B7+Plan!$I$16*D7) -> 0 | F7: =C7-E7 -> 298.2 | G7: =D7 -> 2.7338348 | H7: =Fee*F7+VQ*G7 -> 30.816678 | I7: =MAX(0,MIN(1,(GNone-H7)/(GNone-GFull))) -> 0 | J7: =1-A7 -> 0.99 | K7: =MIN(I7,J7) -> 0 | L7: 0.9552 | M7: 0.00423 | N7: 0.00418 | O7: =IF(M7<=Alpha,A7,-1) -> 0.01 | P7: =IF(L7>=0.95,A7,-1) -> 0.01 | Q7: =MIN(I7^2,J7) -> 0 | R7: =MIN(SQRT(I7),J7) -> 0 | T7: at the cut | U7: =INDEX(A6:A106,MATCH(U6,K6:K106,0)) -> 0.38 | V7: 0.38 (ties: the larger cut)
A8: 0.02 | B8: =DNever-(DNever-DUsual)*A8 -> 197 | C8: =SNever-(SNever-SPlaus)*A8 -> 296.4 | D8: =MAX(0,(B8-Plan!$H$5)/Plan!$I$5,(B8-Plan!$H$6)/Plan!$I$6,(B8-Plan!$H$7)/Plan!$I$7,(B8-Plan!$H$8)/Plan!$I$8,(B8-Plan!$H$9)/Plan!$I$9,(B8-Plan!$H$10)/Plan!$I$10,(B8-Plan!$H$11)/Plan!$I$11,(B8-Plan!$H$12)/Plan!$I$12,(B8-Plan!$H$13)/Plan!$I$13,(B8-Plan!$H$14)/Plan!$I$14,(B8-Plan!$H$15)/Plan!$I$15,(B8-Plan!$H$16)/Plan!$I$16) -> 2.6710283 | E8: =MIN(C8,Plan!$H$5-B8+Plan!$I$5*D8,Plan!$H$6-B8+Plan!$I$6*D8,Plan!$H$7-B8+Plan!$I$7*D8,Plan!$H$8-B8+Plan!$I$8*D8,Plan!$H$9-B8+Plan!$I$9*D8,Plan!$H$10-B8+Plan!$I$10*D8,Plan!$H$11-B8+Plan!$I$11*D8,Plan!$H$12-B8+Plan!$I$12*D8,Plan!$H$13-B8+Plan!$I$13*D8,Plan!$H$14-B8+Plan!$I$14*D8,Plan!$H$15-B8+Plan!$I$15*D8,Plan!$H$16-B8+Plan!$I$16*D8) -> 0 | F8: =C8-E8 -> 296.4 | G8: =D8 -> 2.6710283 | H8: =Fee*F8+VQ*G8 -> 30.260226 | I8: =MAX(0,MIN(1,(GNone-H8)/(GNone-GFull))) -> 0 | J8: =1-A8 -> 0.98 | K8: =MIN(I8,J8) -> 0 | L8: 0.9546 | M8: 0.00459 | N8: 0.00461 | O8: =IF(M8<=Alpha,A8,-1) -> 0.02 | P8: =IF(L8>=0.95,A8,-1) -> 0.02 | Q8: =MIN(I8^2,J8) -> 0 | R8: =MIN(SQRT(I8),J8) -> 0 | T8: necessity of safety | U8: =1-U7 -> 0.62 | V8: 0.62
A9: 0.03 | B9: =DNever-(DNever-DUsual)*A9 -> 195.5 | C9: =SNever-(SNever-SPlaus)*A9 -> 294.6 | D9: =MAX(0,(B9-Plan!$H$5)/Plan!$I$5,(B9-Plan!$H$6)/Plan!$I$6,(B9-Plan!$H$7)/Plan!$I$7,(B9-Plan!$H$8)/Plan!$I$8,(B9-Plan!$H$9)/Plan!$I$9,(B9-Plan!$H$10)/Plan!$I$10,(B9-Plan!$H$11)/Plan!$I$11,(B9-Plan!$H$12)/Plan!$I$12,(B9-Plan!$H$13)/Plan!$I$13,(B9-Plan!$H$14)/Plan!$I$14,(B9-Plan!$H$15)/Plan!$I$15,(B9-Plan!$H$16)/Plan!$I$16) -> 2.6082218 | E9: =MIN(C9,Plan!$H$5-B9+Plan!$I$5*D9,Plan!$H$6-B9+Plan!$I$6*D9,Plan!$H$7-B9+Plan!$I$7*D9,Plan!$H$8-B9+Plan!$I$8*D9,Plan!$H$9-B9+Plan!$I$9*D9,Plan!$H$10-B9+Plan!$I$10*D9,Plan!$H$11-B9+Plan!$I$11*D9,Plan!$H$12-B9+Plan!$I$12*D9,Plan!$H$13-B9+Plan!$I$13*D9,Plan!$H$14-B9+Plan!$I$14*D9,Plan!$H$15-B9+Plan!$I$15*D9,Plan!$H$16-B9+Plan!$I$16*D9) -> 0 | F9: =C9-E9 -> 294.6 | G9: =D9 -> 2.6082218 | H9: =Fee*F9+VQ*G9 -> 29.703774 | I9: =MAX(0,MIN(1,(GNone-H9)/(GNone-GFull))) -> 0 | J9: =1-A9 -> 0.97 | K9: =MIN(I9,J9) -> 0 | L9: 0.95389 | M9: 0.00506 | N9: 0.00498 | O9: =IF(M9<=Alpha,A9,-1) -> 0.03 | P9: =IF(L9>=0.95,A9,-1) -> 0.03 | Q9: =MIN(I9^2,J9) -> 0 | R9: =MIN(SQRT(I9),J9) -> 0 | T9: goal for its cost | U9: =INDEX(I6:I106,MATCH(U7,A6:A106,0)) -> 0.63047119 | V9: 0.630
A10: 0.04 | B10: =DNever-(DNever-DUsual)*A10 -> 194 | C10: =SNever-(SNever-SPlaus)*A10 -> 292.8 | D10: =MAX(0,(B10-Plan!$H$5)/Plan!$I$5,(B10-Plan!$H$6)/Plan!$I$6,(B10-Plan!$H$7)/Plan!$I$7,(B10-Plan!$H$8)/Plan!$I$8,(B10-Plan!$H$9)/Plan!$I$9,(B10-Plan!$H$10)/Plan!$I$10,(B10-Plan!$H$11)/Plan!$I$11,(B10-Plan!$H$12)/Plan!$I$12,(B10-Plan!$H$13)/Plan!$I$13,(B10-Plan!$H$14)/Plan!$I$14,(B10-Plan!$H$15)/Plan!$I$15,(B10-Plan!$H$16)/Plan!$I$16) -> 2.5454152 | E10: =MIN(C10,Plan!$H$5-B10+Plan!$I$5*D10,Plan!$H$6-B10+Plan!$I$6*D10,Plan!$H$7-B10+Plan!$I$7*D10,Plan!$H$8-B10+Plan!$I$8*D10,Plan!$H$9-B10+Plan!$I$9*D10,Plan!$H$10-B10+Plan!$I$10*D10,Plan!$H$11-B10+Plan!$I$11*D10,Plan!$H$12-B10+Plan!$I$12*D10,Plan!$H$13-B10+Plan!$I$13*D10,Plan!$H$14-B10+Plan!$I$14*D10,Plan!$H$15-B10+Plan!$I$15*D10,Plan!$H$16-B10+Plan!$I$16*D10) -> 0 | F10: =C10-E10 -> 292.8 | G10: =D10 -> 2.5454152 | H10: =Fee*F10+VQ*G10 -> 29.147322 | I10: =MAX(0,MIN(1,(GNone-H10)/(GNone-GFull))) -> 0 | J10: =1-A10 -> 0.96 | K10: =MIN(I10,J10) -> 0 | L10: 0.95319 | M10: 0.00557 | N10: 0.00539 | O10: =IF(M10<=Alpha,A10,-1) -> 0.04 | P10: =IF(L10>=0.95,A10,-1) -> 0.04 | Q10: =MIN(I10^2,J10) -> 0 | R10: =MIN(SQRT(I10),J10) -> 0 | T10: cost | U10: =INDEX(H6:H106,MATCH(U7,A6:A106,0)) -> 10.542932 | V10: $10.54 million; package on Robust
A11: 0.05 | B11: =DNever-(DNever-DUsual)*A11 -> 192.5 | C11: =SNever-(SNever-SPlaus)*A11 -> 291 | D11: =MAX(0,(B11-Plan!$H$5)/Plan!$I$5,(B11-Plan!$H$6)/Plan!$I$6,(B11-Plan!$H$7)/Plan!$I$7,(B11-Plan!$H$8)/Plan!$I$8,(B11-Plan!$H$9)/Plan!$I$9,(B11-Plan!$H$10)/Plan!$I$10,(B11-Plan!$H$11)/Plan!$I$11,(B11-Plan!$H$12)/Plan!$I$12,(B11-Plan!$H$13)/Plan!$I$13,(B11-Plan!$H$14)/Plan!$I$14,(B11-Plan!$H$15)/Plan!$I$15,(B11-Plan!$H$16)/Plan!$I$16) -> 2.4826087 | E11: =MIN(C11,Plan!$H$5-B11+Plan!$I$5*D11,Plan!$H$6-B11+Plan!$I$6*D11,Plan!$H$7-B11+Plan!$I$7*D11,Plan!$H$8-B11+Plan!$I$8*D11,Plan!$H$9-B11+Plan!$I$9*D11,Plan!$H$10-B11+Plan!$I$10*D11,Plan!$H$11-B11+Plan!$I$11*D11,Plan!$H$12-B11+Plan!$I$12*D11,Plan!$H$13-B11+Plan!$I$13*D11,Plan!$H$14-B11+Plan!$I$14*D11,Plan!$H$15-B11+Plan!$I$15*D11,Plan!$H$16-B11+Plan!$I$16*D11) -> 0 | F11: =C11-E11 -> 291 | G11: =D11 -> 2.4826087 | H11: =Fee*F11+VQ*G11 -> 28.59087 | I11: =MAX(0,MIN(1,(GNone-H11)/(GNone-GFull))) -> 0 | J11: =1-A11 -> 0.95 | K11: =MIN(I11,J11) -> 0 | L11: 0.95273 | M11: 0.0061 | N11: 0.00583 | O11: =IF(M11<=Alpha,A11,-1) -> 0.05 | P11: =IF(L11>=0.95,A11,-1) -> 0.05 | Q11: =MIN(I11^2,J11) -> 0 | R11: =MIN(SQRT(I11),J11) -> 0
A12: 0.06 | B12: =DNever-(DNever-DUsual)*A12 -> 191 | C12: =SNever-(SNever-SPlaus)*A12 -> 289.2 | D12: =MAX(0,(B12-Plan!$H$5)/Plan!$I$5,(B12-Plan!$H$6)/Plan!$I$6,(B12-Plan!$H$7)/Plan!$I$7,(B12-Plan!$H$8)/Plan!$I$8,(B12-Plan!$H$9)/Plan!$I$9,(B12-Plan!$H$10)/Plan!$I$10,(B12-Plan!$H$11)/Plan!$I$11,(B12-Plan!$H$12)/Plan!$I$12,(B12-Plan!$H$13)/Plan!$I$13,(B12-Plan!$H$14)/Plan!$I$14,(B12-Plan!$H$15)/Plan!$I$15,(B12-Plan!$H$16)/Plan!$I$16) -> 2.4198022 | E12: =MIN(C12,Plan!$H$5-B12+Plan!$I$5*D12,Plan!$H$6-B12+Plan!$I$6*D12,Plan!$H$7-B12+Plan!$I$7*D12,Plan!$H$8-B12+Plan!$I$8*D12,Plan!$H$9-B12+Plan!$I$9*D12,Plan!$H$10-B12+Plan!$I$10*D12,Plan!$H$11-B12+Plan!$I$11*D12,Plan!$H$12-B12+Plan!$I$12*D12,Plan!$H$13-B12+Plan!$I$13*D12,Plan!$H$14-B12+Plan!$I$14*D12,Plan!$H$15-B12+Plan!$I$15*D12,Plan!$H$16-B12+Plan!$I$16*D12) -> 0 | F12: =C12-E12 -> 289.2 | G12: =D12 -> 2.4198022 | H12: =Fee*F12+VQ*G12 -> 28.034418 | I12: =MAX(0,MIN(1,(GNone-H12)/(GNone-GFull))) -> 0 | J12: =1-A12 -> 0.94 | K12: =MIN(I12,J12) -> 0 | L12: 0.9519 | M12: 0.00659 | N12: 0.0064 | O12: =IF(M12<=Alpha,A12,-1) -> 0.06 | P12: =IF(L12>=0.95,A12,-1) -> 0.06 | Q12: =MIN(I12^2,J12) -> 0 | R12: =MIN(SQRT(I12),J12) -> 0 | T12: Cheapest cut meeting 5% under the law | U12: =MAX(O6:O106) -> 0.35 | V12: 0.35: $12.17 million
A13: 0.07 | B13: =DNever-(DNever-DUsual)*A13 -> 189.5 | C13: =SNever-(SNever-SPlaus)*A13 -> 287.4 | D13: =MAX(0,(B13-Plan!$H$5)/Plan!$I$5,(B13-Plan!$H$6)/Plan!$I$6,(B13-Plan!$H$7)/Plan!$I$7,(B13-Plan!$H$8)/Plan!$I$8,(B13-Plan!$H$9)/Plan!$I$9,(B13-Plan!$H$10)/Plan!$I$10,(B13-Plan!$H$11)/Plan!$I$11,(B13-Plan!$H$12)/Plan!$I$12,(B13-Plan!$H$13)/Plan!$I$13,(B13-Plan!$H$14)/Plan!$I$14,(B13-Plan!$H$15)/Plan!$I$15,(B13-Plan!$H$16)/Plan!$I$16) -> 2.3569957 | E13: =MIN(C13,Plan!$H$5-B13+Plan!$I$5*D13,Plan!$H$6-B13+Plan!$I$6*D13,Plan!$H$7-B13+Plan!$I$7*D13,Plan!$H$8-B13+Plan!$I$8*D13,Plan!$H$9-B13+Plan!$I$9*D13,Plan!$H$10-B13+Plan!$I$10*D13,Plan!$H$11-B13+Plan!$I$11*D13,Plan!$H$12-B13+Plan!$I$12*D13,Plan!$H$13-B13+Plan!$I$13*D13,Plan!$H$14-B13+Plan!$I$14*D13,Plan!$H$15-B13+Plan!$I$15*D13,Plan!$H$16-B13+Plan!$I$16*D13) -> 0 | F13: =C13-E13 -> 287.4 | G13: =D13 -> 2.3569957 | H13: =Fee*F13+VQ*G13 -> 27.477966 | I13: =MAX(0,MIN(1,(GNone-H13)/(GNone-GFull))) -> 0 | J13: =1-A13 -> 0.93 | K13: =MIN(I13,J13) -> 0 | L13: 0.95109 | M13: 0.007 | N13: 0.00685 | O13: =IF(M13<=Alpha,A13,-1) -> 0.07 | P13: =IF(L13>=0.95,A13,-1) -> 0.07 | Q13: =MIN(I13^2,J13) -> 0 | R13: =MIN(SQRT(I13),J13) -> 0 | T13: First cut holding 95% of the paths | U13: =MAX(P6:P106) -> 0.08 | V13: 0.08: $26.92 million (Theorem 10.1(iii))
A14: 0.08 | B14: =DNever-(DNever-DUsual)*A14 -> 188 | C14: =SNever-(SNever-SPlaus)*A14 -> 285.6 | D14: =MAX(0,(B14-Plan!$H$5)/Plan!$I$5,(B14-Plan!$H$6)/Plan!$I$6,(B14-Plan!$H$7)/Plan!$I$7,(B14-Plan!$H$8)/Plan!$I$8,(B14-Plan!$H$9)/Plan!$I$9,(B14-Plan!$H$10)/Plan!$I$10,(B14-Plan!$H$11)/Plan!$I$11,(B14-Plan!$H$12)/Plan!$I$12,(B14-Plan!$H$13)/Plan!$I$13,(B14-Plan!$H$14)/Plan!$I$14,(B14-Plan!$H$15)/Plan!$I$15,(B14-Plan!$H$16)/Plan!$I$16) -> 2.2941892 | E14: =MIN(C14,Plan!$H$5-B14+Plan!$I$5*D14,Plan!$H$6-B14+Plan!$I$6*D14,Plan!$H$7-B14+Plan!$I$7*D14,Plan!$H$8-B14+Plan!$I$8*D14,Plan!$H$9-B14+Plan!$I$9*D14,Plan!$H$10-B14+Plan!$I$10*D14,Plan!$H$11-B14+Plan!$I$11*D14,Plan!$H$12-B14+Plan!$I$12*D14,Plan!$H$13-B14+Plan!$I$13*D14,Plan!$H$14-B14+Plan!$I$14*D14,Plan!$H$15-B14+Plan!$I$15*D14,Plan!$H$16-B14+Plan!$I$16*D14) -> 0 | F14: =C14-E14 -> 285.6 | G14: =D14 -> 2.2941892 | H14: =Fee*F14+VQ*G14 -> 26.921513 | I14: =MAX(0,MIN(1,(GNone-H14)/(GNone-GFull))) -> 0 | J14: =1-A14 -> 0.92 | K14: =MIN(I14,J14) -> 0 | L14: 0.95021 | M14: 0.00757 | N14: 0.00731 | O14: =IF(M14<=Alpha,A14,-1) -> 0.08 | P14: =IF(L14>=0.95,A14,-1) -> 0.08 | Q14: =MIN(I14^2,J14) -> 0 | R14: =MIN(SQRT(I14),J14) -> 0
A15: 0.09 | B15: =DNever-(DNever-DUsual)*A15 -> 186.5 | C15: =SNever-(SNever-SPlaus)*A15 -> 283.8 | D15: =MAX(0,(B15-Plan!$H$5)/Plan!$I$5,(B15-Plan!$H$6)/Plan!$I$6,(B15-Plan!$H$7)/Plan!$I$7,(B15-Plan!$H$8)/Plan!$I$8,(B15-Plan!$H$9)/Plan!$I$9,(B15-Plan!$H$10)/Plan!$I$10,(B15-Plan!$H$11)/Plan!$I$11,(B15-Plan!$H$12)/Plan!$I$12,(B15-Plan!$H$13)/Plan!$I$13,(B15-Plan!$H$14)/Plan!$I$14,(B15-Plan!$H$15)/Plan!$I$15,(B15-Plan!$H$16)/Plan!$I$16) -> 2.2313827 | E15: =MIN(C15,Plan!$H$5-B15+Plan!$I$5*D15,Plan!$H$6-B15+Plan!$I$6*D15,Plan!$H$7-B15+Plan!$I$7*D15,Plan!$H$8-B15+Plan!$I$8*D15,Plan!$H$9-B15+Plan!$I$9*D15,Plan!$H$10-B15+Plan!$I$10*D15,Plan!$H$11-B15+Plan!$I$11*D15,Plan!$H$12-B15+Plan!$I$12*D15,Plan!$H$13-B15+Plan!$I$13*D15,Plan!$H$14-B15+Plan!$I$14*D15,Plan!$H$15-B15+Plan!$I$15*D15,Plan!$H$16-B15+Plan!$I$16*D15) -> 0 | F15: =C15-E15 -> 283.8 | G15: =D15 -> 2.2313827 | H15: =Fee*F15+VQ*G15 -> 26.365061 | I15: =MAX(0,MIN(1,(GNone-H15)/(GNone-GFull))) -> 0 | J15: =1-A15 -> 0.91 | K15: =MIN(I15,J15) -> 0 | L15: 0.94934 | M15: 0.00809 | N15: 0.00782 | O15: =IF(M15<=Alpha,A15,-1) -> 0.09 | P15: =IF(L15>=0.95,A15,-1) -> -1 | Q15: =MIN(I15^2,J15) -> 0 | R15: =MIN(SQRT(I15),J15) -> 0 | T15: Graded price at possibility 1 | U15: =H106 -> 1.1414885 | V15: $1.14 million
A16: 0.1 | B16: =DNever-(DNever-DUsual)*A16 -> 185 | C16: =SNever-(SNever-SPlaus)*A16 -> 282 | D16: =MAX(0,(B16-Plan!$H$5)/Plan!$I$5,(B16-Plan!$H$6)/Plan!$I$6,(B16-Plan!$H$7)/Plan!$I$7,(B16-Plan!$H$8)/Plan!$I$8,(B16-Plan!$H$9)/Plan!$I$9,(B16-Plan!$H$10)/Plan!$I$10,(B16-Plan!$H$11)/Plan!$I$11,(B16-Plan!$H$12)/Plan!$I$12,(B16-Plan!$H$13)/Plan!$I$13,(B16-Plan!$H$14)/Plan!$I$14,(B16-Plan!$H$15)/Plan!$I$15,(B16-Plan!$H$16)/Plan!$I$16) -> 2.1685762 | E16: =MIN(C16,Plan!$H$5-B16+Plan!$I$5*D16,Plan!$H$6-B16+Plan!$I$6*D16,Plan!$H$7-B16+Plan!$I$7*D16,Plan!$H$8-B16+Plan!$I$8*D16,Plan!$H$9-B16+Plan!$I$9*D16,Plan!$H$10-B16+Plan!$I$10*D16,Plan!$H$11-B16+Plan!$I$11*D16,Plan!$H$12-B16+Plan!$I$12*D16,Plan!$H$13-B16+Plan!$I$13*D16,Plan!$H$14-B16+Plan!$I$14*D16,Plan!$H$15-B16+Plan!$I$15*D16,Plan!$H$16-B16+Plan!$I$16*D16) -> 0 | F16: =C16-E16 -> 282 | G16: =D16 -> 2.1685762 | H16: =Fee*F16+VQ*G16 -> 25.808609 | I16: =MAX(0,MIN(1,(GNone-H16)/(GNone-GFull))) -> 0 | J16: =1-A16 -> 0.9 | K16: =MIN(I16,J16) -> 0 | L16: 0.94837 | M16: 0.00868 | N16: 0.00835 | O16: =IF(M16<=Alpha,A16,-1) -> 0.1 | P16: =IF(L16>=0.95,A16,-1) -> -1 | Q16: =MIN(I16^2,J16) -> 0 | R16: =MIN(SQRT(I16),J16) -> 0 | T16: at possibility 0 | U16: =H6 -> 31.37313 | V16: $31.37 million
A17: 0.11 | B17: =DNever-(DNever-DUsual)*A17 -> 183.5 | C17: =SNever-(SNever-SPlaus)*A17 -> 280.2 | D17: =MAX(0,(B17-Plan!$H$5)/Plan!$I$5,(B17-Plan!$H$6)/Plan!$I$6,(B17-Plan!$H$7)/Plan!$I$7,(B17-Plan!$H$8)/Plan!$I$8,(B17-Plan!$H$9)/Plan!$I$9,(B17-Plan!$H$10)/Plan!$I$10,(B17-Plan!$H$11)/Plan!$I$11,(B17-Plan!$H$12)/Plan!$I$12,(B17-Plan!$H$13)/Plan!$I$13,(B17-Plan!$H$14)/Plan!$I$14,(B17-Plan!$H$15)/Plan!$I$15,(B17-Plan!$H$16)/Plan!$I$16) -> 2.1057696 | E17: =MIN(C17,Plan!$H$5-B17+Plan!$I$5*D17,Plan!$H$6-B17+Plan!$I$6*D17,Plan!$H$7-B17+Plan!$I$7*D17,Plan!$H$8-B17+Plan!$I$8*D17,Plan!$H$9-B17+Plan!$I$9*D17,Plan!$H$10-B17+Plan!$I$10*D17,Plan!$H$11-B17+Plan!$I$11*D17,Plan!$H$12-B17+Plan!$I$12*D17,Plan!$H$13-B17+Plan!$I$13*D17,Plan!$H$14-B17+Plan!$I$14*D17,Plan!$H$15-B17+Plan!$I$15*D17,Plan!$H$16-B17+Plan!$I$16*D17) -> 0 | F17: =C17-E17 -> 280.2 | G17: =D17 -> 2.1057696 | H17: =Fee*F17+VQ*G17 -> 25.252157 | I17: =MAX(0,MIN(1,(GNone-H17)/(GNone-GFull))) -> 0 | J17: =1-A17 -> 0.89 | K17: =MIN(I17,J17) -> 0 | L17: 0.94735 | M17: 0.00944 | N17: 0.00896 | O17: =IF(M17<=Alpha,A17,-1) -> 0.11 | P17: =IF(L17>=0.95,A17,-1) -> -1 | Q17: =MIN(I17^2,J17) -> 0 | R17: =MIN(SQRT(I17),J17) -> 0 | T17: its 0.5-cut (Proposition 10.2(i)) | U17: =H56 -> 6.0914885 | V17: Step 2's crisp answer, $6.09 million
A18: 0.12 | B18: =DNever-(DNever-DUsual)*A18 -> 182 | C18: =SNever-(SNever-SPlaus)*A18 -> 278.4 | D18: =MAX(0,(B18-Plan!$H$5)/Plan!$I$5,(B18-Plan!$H$6)/Plan!$I$6,(B18-Plan!$H$7)/Plan!$I$7,(B18-Plan!$H$8)/Plan!$I$8,(B18-Plan!$H$9)/Plan!$I$9,(B18-Plan!$H$10)/Plan!$I$10,(B18-Plan!$H$11)/Plan!$I$11,(B18-Plan!$H$12)/Plan!$I$12,(B18-Plan!$H$13)/Plan!$I$13,(B18-Plan!$H$14)/Plan!$I$14,(B18-Plan!$H$15)/Plan!$I$15,(B18-Plan!$H$16)/Plan!$I$16) -> 2.0429631 | E18: =MIN(C18,Plan!$H$5-B18+Plan!$I$5*D18,Plan!$H$6-B18+Plan!$I$6*D18,Plan!$H$7-B18+Plan!$I$7*D18,Plan!$H$8-B18+Plan!$I$8*D18,Plan!$H$9-B18+Plan!$I$9*D18,Plan!$H$10-B18+Plan!$I$10*D18,Plan!$H$11-B18+Plan!$I$11*D18,Plan!$H$12-B18+Plan!$I$12*D18,Plan!$H$13-B18+Plan!$I$13*D18,Plan!$H$14-B18+Plan!$I$14*D18,Plan!$H$15-B18+Plan!$I$15*D18,Plan!$H$16-B18+Plan!$I$16*D18) -> 0 | F18: =C18-E18 -> 278.4 | G18: =D18 -> 2.0429631 | H18: =Fee*F18+VQ*G18 -> 24.695705 | I18: =MAX(0,MIN(1,(GNone-H18)/(GNone-GFull))) -> 0 | J18: =1-A18 -> 0.88 | K18: =MIN(I18,J18) -> 0 | L18: 0.94639 | M18: 0.0101 | N18: 0.00974 | O18: =IF(M18<=Alpha,A18,-1) -> 0.12 | P18: =IF(L18>=0.95,A18,-1) -> -1 | Q18: =MIN(I18^2,J18) -> 0 | R18: =MIN(SQRT(I18),J18) -> 0 | T18: the crisp set's package (Robust) | U18: =Robust!L6 -> 6.0914885
A19: 0.13 | B19: =DNever-(DNever-DUsual)*A19 -> 180.5 | C19: =SNever-(SNever-SPlaus)*A19 -> 276.6 | D19: =MAX(0,(B19-Plan!$H$5)/Plan!$I$5,(B19-Plan!$H$6)/Plan!$I$6,(B19-Plan!$H$7)/Plan!$I$7,(B19-Plan!$H$8)/Plan!$I$8,(B19-Plan!$H$9)/Plan!$I$9,(B19-Plan!$H$10)/Plan!$I$10,(B19-Plan!$H$11)/Plan!$I$11,(B19-Plan!$H$12)/Plan!$I$12,(B19-Plan!$H$13)/Plan!$I$13,(B19-Plan!$H$14)/Plan!$I$14,(B19-Plan!$H$15)/Plan!$I$15,(B19-Plan!$H$16)/Plan!$I$16) -> 1.9801566 | E19: =MIN(C19,Plan!$H$5-B19+Plan!$I$5*D19,Plan!$H$6-B19+Plan!$I$6*D19,Plan!$H$7-B19+Plan!$I$7*D19,Plan!$H$8-B19+Plan!$I$8*D19,Plan!$H$9-B19+Plan!$I$9*D19,Plan!$H$10-B19+Plan!$I$10*D19,Plan!$H$11-B19+Plan!$I$11*D19,Plan!$H$12-B19+Plan!$I$12*D19,Plan!$H$13-B19+Plan!$I$13*D19,Plan!$H$14-B19+Plan!$I$14*D19,Plan!$H$15-B19+Plan!$I$15*D19,Plan!$H$16-B19+Plan!$I$16*D19) -> 0 | F19: =C19-E19 -> 276.6 | G19: =D19 -> 1.9801566 | H19: =Fee*F19+VQ*G19 -> 24.139253 | I19: =MAX(0,MIN(1,(GNone-H19)/(GNone-GFull))) -> 0 | J19: =1-A19 -> 0.87 | K19: =MIN(I19,J19) -> 0 | L19: 0.94519 | M19: 0.01074 | N19: 0.01051 | O19: =IF(M19<=Alpha,A19,-1) -> 0.13 | P19: =IF(L19>=0.95,A19,-1) -> -1 | Q19: =MIN(I19^2,J19) -> 0 | R19: =MIN(SQRT(I19),J19) -> 0 | T19: Steps where the price falls as the set grows | U19: =SUMPRODUCT((H7:H106>H6:H105+0.000000001)*1) -> 0 | V19: None (Theorem 10.2(ii))
A20: 0.14 | B20: =DNever-(DNever-DUsual)*A20 -> 179 | C20: =SNever-(SNever-SPlaus)*A20 -> 274.8 | D20: =MAX(0,(B20-Plan!$H$5)/Plan!$I$5,(B20-Plan!$H$6)/Plan!$I$6,(B20-Plan!$H$7)/Plan!$I$7,(B20-Plan!$H$8)/Plan!$I$8,(B20-Plan!$H$9)/Plan!$I$9,(B20-Plan!$H$10)/Plan!$I$10,(B20-Plan!$H$11)/Plan!$I$11,(B20-Plan!$H$12)/Plan!$I$12,(B20-Plan!$H$13)/Plan!$I$13,(B20-Plan!$H$14)/Plan!$I$14,(B20-Plan!$H$15)/Plan!$I$15,(B20-Plan!$H$16)/Plan!$I$16) -> 1.9173501 | E20: =MIN(C20,Plan!$H$5-B20+Plan!$I$5*D20,Plan!$H$6-B20+Plan!$I$6*D20,Plan!$H$7-B20+Plan!$I$7*D20,Plan!$H$8-B20+Plan!$I$8*D20,Plan!$H$9-B20+Plan!$I$9*D20,Plan!$H$10-B20+Plan!$I$10*D20,Plan!$H$11-B20+Plan!$I$11*D20,Plan!$H$12-B20+Plan!$I$12*D20,Plan!$H$13-B20+Plan!$I$13*D20,Plan!$H$14-B20+Plan!$I$14*D20,Plan!$H$15-B20+Plan!$I$15*D20,Plan!$H$16-B20+Plan!$I$16*D20) -> 0 | F20: =C20-E20 -> 274.8 | G20: =D20 -> 1.9173501 | H20: =Fee*F20+VQ*G20 -> 23.582801 | I20: =MAX(0,MIN(1,(GNone-H20)/(GNone-GFull))) -> 0 | J20: =1-A20 -> 0.86 | K20: =MIN(I20,J20) -> 0 | L20: 0.94384 | M20: 0.01168 | N20: 0.01139 | O20: =IF(M20<=Alpha,A20,-1) -> 0.14 | P20: =IF(L20>=0.95,A20,-1) -> -1 | Q20: =MIN(I20^2,J20) -> 0 | R20: =MIN(SQRT(I20),J20) -> 0 | T20: Cuts whose chance exceeds the share of paths outside the set | U20: =SUMPRODUCT((M6:M106>1-L6:L106)*1) -> 0 | V20: None (Theorem 10.1(iii))
A21: 0.15 | B21: =DNever-(DNever-DUsual)*A21 -> 177.5 | C21: =SNever-(SNever-SPlaus)*A21 -> 273 | D21: =MAX(0,(B21-Plan!$H$5)/Plan!$I$5,(B21-Plan!$H$6)/Plan!$I$6,(B21-Plan!$H$7)/Plan!$I$7,(B21-Plan!$H$8)/Plan!$I$8,(B21-Plan!$H$9)/Plan!$I$9,(B21-Plan!$H$10)/Plan!$I$10,(B21-Plan!$H$11)/Plan!$I$11,(B21-Plan!$H$12)/Plan!$I$12,(B21-Plan!$H$13)/Plan!$I$13,(B21-Plan!$H$14)/Plan!$I$14,(B21-Plan!$H$15)/Plan!$I$15,(B21-Plan!$H$16)/Plan!$I$16) -> 1.8545436 | E21: =MIN(C21,Plan!$H$5-B21+Plan!$I$5*D21,Plan!$H$6-B21+Plan!$I$6*D21,Plan!$H$7-B21+Plan!$I$7*D21,Plan!$H$8-B21+Plan!$I$8*D21,Plan!$H$9-B21+Plan!$I$9*D21,Plan!$H$10-B21+Plan!$I$10*D21,Plan!$H$11-B21+Plan!$I$11*D21,Plan!$H$12-B21+Plan!$I$12*D21,Plan!$H$13-B21+Plan!$I$13*D21,Plan!$H$14-B21+Plan!$I$14*D21,Plan!$H$15-B21+Plan!$I$15*D21,Plan!$H$16-B21+Plan!$I$16*D21) -> 0 | F21: =C21-E21 -> 273 | G21: =D21 -> 1.8545436 | H21: =Fee*F21+VQ*G21 -> 23.026349 | I21: =MAX(0,MIN(1,(GNone-H21)/(GNone-GFull))) -> 0 | J21: =1-A21 -> 0.85 | K21: =MIN(I21,J21) -> 0 | L21: 0.94231 | M21: 0.01269 | N21: 0.01248 | O21: =IF(M21<=Alpha,A21,-1) -> 0.15 | P21: =IF(L21>=0.95,A21,-1) -> -1 | Q21: =MIN(I21^2,J21) -> 0 | R21: =MIN(SQRT(I21),J21) -> 0 | T21: Largest standard error of a chance (points) | U21: =100*SQRT(MAX(M6:M106)*(1-MAX(M6:M106))/NPaths) -> 0.12584862 | V21: Below 0.13 points
A22: 0.16 | B22: =DNever-(DNever-DUsual)*A22 -> 176 | C22: =SNever-(SNever-SPlaus)*A22 -> 271.2 | D22: =MAX(0,(B22-Plan!$H$5)/Plan!$I$5,(B22-Plan!$H$6)/Plan!$I$6,(B22-Plan!$H$7)/Plan!$I$7,(B22-Plan!$H$8)/Plan!$I$8,(B22-Plan!$H$9)/Plan!$I$9,(B22-Plan!$H$10)/Plan!$I$10,(B22-Plan!$H$11)/Plan!$I$11,(B22-Plan!$H$12)/Plan!$I$12,(B22-Plan!$H$13)/Plan!$I$13,(B22-Plan!$H$14)/Plan!$I$14,(B22-Plan!$H$15)/Plan!$I$15,(B22-Plan!$H$16)/Plan!$I$16) -> 1.7917371 | E22: =MIN(C22,Plan!$H$5-B22+Plan!$I$5*D22,Plan!$H$6-B22+Plan!$I$6*D22,Plan!$H$7-B22+Plan!$I$7*D22,Plan!$H$8-B22+Plan!$I$8*D22,Plan!$H$9-B22+Plan!$I$9*D22,Plan!$H$10-B22+Plan!$I$10*D22,Plan!$H$11-B22+Plan!$I$11*D22,Plan!$H$12-B22+Plan!$I$12*D22,Plan!$H$13-B22+Plan!$I$13*D22,Plan!$H$14-B22+Plan!$I$14*D22,Plan!$H$15-B22+Plan!$I$15*D22,Plan!$H$16-B22+Plan!$I$16*D22) -> 0 | F22: =C22-E22 -> 271.2 | G22: =D22 -> 1.7917371 | H22: =Fee*F22+VQ*G22 -> 22.469897 | I22: =MAX(0,MIN(1,(GNone-H22)/(GNone-GFull))) -> 0 | J22: =1-A22 -> 0.84 | K22: =MIN(I22,J22) -> 0 | L22: 0.94086 | M22: 0.0136 | N22: 0.01325 | O22: =IF(M22<=Alpha,A22,-1) -> 0.16 | P22: =IF(L22>=0.95,A22,-1) -> -1 | Q22: =MIN(I22^2,J22) -> 0 | R22: =MIN(SQRT(I22),J22) -> 0
A23: 0.17 | B23: =DNever-(DNever-DUsual)*A23 -> 174.5 | C23: =SNever-(SNever-SPlaus)*A23 -> 269.4 | D23: =MAX(0,(B23-Plan!$H$5)/Plan!$I$5,(B23-Plan!$H$6)/Plan!$I$6,(B23-Plan!$H$7)/Plan!$I$7,(B23-Plan!$H$8)/Plan!$I$8,(B23-Plan!$H$9)/Plan!$I$9,(B23-Plan!$H$10)/Plan!$I$10,(B23-Plan!$H$11)/Plan!$I$11,(B23-Plan!$H$12)/Plan!$I$12,(B23-Plan!$H$13)/Plan!$I$13,(B23-Plan!$H$14)/Plan!$I$14,(B23-Plan!$H$15)/Plan!$I$15,(B23-Plan!$H$16)/Plan!$I$16) -> 1.7304104 | E23: =MIN(C23,Plan!$H$5-B23+Plan!$I$5*D23,Plan!$H$6-B23+Plan!$I$6*D23,Plan!$H$7-B23+Plan!$I$7*D23,Plan!$H$8-B23+Plan!$I$8*D23,Plan!$H$9-B23+Plan!$I$9*D23,Plan!$H$10-B23+Plan!$I$10*D23,Plan!$H$11-B23+Plan!$I$11*D23,Plan!$H$12-B23+Plan!$I$12*D23,Plan!$H$13-B23+Plan!$I$13*D23,Plan!$H$14-B23+Plan!$I$14*D23,Plan!$H$15-B23+Plan!$I$15*D23,Plan!$H$16-B23+Plan!$I$16*D23) -> 0 | F23: =C23-E23 -> 269.4 | G23: =D23 -> 1.7304104 | H23: =Fee*F23+VQ*G23 -> 21.925283 | I23: =MAX(0,MIN(1,(GNone-H23)/(GNone-GFull))) -> 0 | J23: =1-A23 -> 0.83 | K23: =MIN(I23,J23) -> 0 | L23: 0.93923 | M23: 0.01446 | N23: 0.01421 | O23: =IF(M23<=Alpha,A23,-1) -> 0.17 | P23: =IF(L23>=0.95,A23,-1) -> -1 | Q23: =MIN(I23^2,J23) -> 0 | R23: =MIN(SQRT(I23),J23) -> 0 | T23: Hedges: the level with a goal 'very cheap' | U23: =MAX(Q6:Q106) -> 0.58 | V23: The goal squared (the lab's illustration)
A24: 0.18 | B24: =DNever-(DNever-DUsual)*A24 -> 173 | C24: =SNever-(SNever-SPlaus)*A24 -> 267.6 | D24: =MAX(0,(B24-Plan!$H$5)/Plan!$I$5,(B24-Plan!$H$6)/Plan!$I$6,(B24-Plan!$H$7)/Plan!$I$7,(B24-Plan!$H$8)/Plan!$I$8,(B24-Plan!$H$9)/Plan!$I$9,(B24-Plan!$H$10)/Plan!$I$10,(B24-Plan!$H$11)/Plan!$I$11,(B24-Plan!$H$12)/Plan!$I$12,(B24-Plan!$H$13)/Plan!$I$13,(B24-Plan!$H$14)/Plan!$I$14,(B24-Plan!$H$15)/Plan!$I$15,(B24-Plan!$H$16)/Plan!$I$16) -> 1.6694083 | E24: =MIN(C24,Plan!$H$5-B24+Plan!$I$5*D24,Plan!$H$6-B24+Plan!$I$6*D24,Plan!$H$7-B24+Plan!$I$7*D24,Plan!$H$8-B24+Plan!$I$8*D24,Plan!$H$9-B24+Plan!$I$9*D24,Plan!$H$10-B24+Plan!$I$10*D24,Plan!$H$11-B24+Plan!$I$11*D24,Plan!$H$12-B24+Plan!$I$12*D24,Plan!$H$13-B24+Plan!$I$13*D24,Plan!$H$14-B24+Plan!$I$14*D24,Plan!$H$15-B24+Plan!$I$15*D24,Plan!$H$16-B24+Plan!$I$16*D24) -> 0 | F24: =C24-E24 -> 267.6 | G24: =D24 -> 1.6694083 | H24: =Fee*F24+VQ*G24 -> 21.383267 | I24: =MAX(0,MIN(1,(GNone-H24)/(GNone-GFull))) -> 0 | J24: =1-A24 -> 0.82 | K24: =MIN(I24,J24) -> 0 | L24: 0.93744 | M24: 0.01554 | N24: 0.01524 | O24: =IF(M24<=Alpha,A24,-1) -> 0.18 | P24: =IF(L24>=0.95,A24,-1) -> -1 | Q24: =MIN(I24^2,J24) -> 0 | R24: =MIN(SQRT(I24),J24) -> 0 | T24: with a goal 'somewhat cheap' | U24: =MAX(R6:R106) -> 0.67 | V24: The goal's square root
A25: 0.19 | B25: =DNever-(DNever-DUsual)*A25 -> 171.5 | C25: =SNever-(SNever-SPlaus)*A25 -> 265.8 | D25: =MAX(0,(B25-Plan!$H$5)/Plan!$I$5,(B25-Plan!$H$6)/Plan!$I$6,(B25-Plan!$H$7)/Plan!$I$7,(B25-Plan!$H$8)/Plan!$I$8,(B25-Plan!$H$9)/Plan!$I$9,(B25-Plan!$H$10)/Plan!$I$10,(B25-Plan!$H$11)/Plan!$I$11,(B25-Plan!$H$12)/Plan!$I$12,(B25-Plan!$H$13)/Plan!$I$13,(B25-Plan!$H$14)/Plan!$I$14,(B25-Plan!$H$15)/Plan!$I$15,(B25-Plan!$H$16)/Plan!$I$16) -> 1.6084062 | E25: =MIN(C25,Plan!$H$5-B25+Plan!$I$5*D25,Plan!$H$6-B25+Plan!$I$6*D25,Plan!$H$7-B25+Plan!$I$7*D25,Plan!$H$8-B25+Plan!$I$8*D25,Plan!$H$9-B25+Plan!$I$9*D25,Plan!$H$10-B25+Plan!$I$10*D25,Plan!$H$11-B25+Plan!$I$11*D25,Plan!$H$12-B25+Plan!$I$12*D25,Plan!$H$13-B25+Plan!$I$13*D25,Plan!$H$14-B25+Plan!$I$14*D25,Plan!$H$15-B25+Plan!$I$15*D25,Plan!$H$16-B25+Plan!$I$16*D25) -> 0 | F25: =C25-E25 -> 265.8 | G25: =D25 -> 1.6084062 | H25: =Fee*F25+VQ*G25 -> 20.84125 | I25: =MAX(0,MIN(1,(GNone-H25)/(GNone-GFull))) -> 0 | J25: =1-A25 -> 0.81 | K25: =MIN(I25,J25) -> 0 | L25: 0.9356 | M25: 0.01671 | N25: 0.01621 | O25: =IF(M25<=Alpha,A25,-1) -> 0.19 | P25: =IF(L25>=0.95,A25,-1) -> -1 | Q25: =MIN(I25^2,J25) -> 0 | R25: =MIN(SQRT(I25),J25) -> 0 | T25: a stronger goal can only lower the level: violations | U25: =IF(AND(U23<=U6,U6<=U24),0,1) -> 0 | V25: Proposition 10.2(iii)
A26: 0.2 | B26: =DNever-(DNever-DUsual)*A26 -> 170 | C26: =SNever-(SNever-SPlaus)*A26 -> 264 | D26: =MAX(0,(B26-Plan!$H$5)/Plan!$I$5,(B26-Plan!$H$6)/Plan!$I$6,(B26-Plan!$H$7)/Plan!$I$7,(B26-Plan!$H$8)/Plan!$I$8,(B26-Plan!$H$9)/Plan!$I$9,(B26-Plan!$H$10)/Plan!$I$10,(B26-Plan!$H$11)/Plan!$I$11,(B26-Plan!$H$12)/Plan!$I$12,(B26-Plan!$H$13)/Plan!$I$13,(B26-Plan!$H$14)/Plan!$I$14,(B26-Plan!$H$15)/Plan!$I$15,(B26-Plan!$H$16)/Plan!$I$16) -> 1.5474041 | E26: =MIN(C26,Plan!$H$5-B26+Plan!$I$5*D26,Plan!$H$6-B26+Plan!$I$6*D26,Plan!$H$7-B26+Plan!$I$7*D26,Plan!$H$8-B26+Plan!$I$8*D26,Plan!$H$9-B26+Plan!$I$9*D26,Plan!$H$10-B26+Plan!$I$10*D26,Plan!$H$11-B26+Plan!$I$11*D26,Plan!$H$12-B26+Plan!$I$12*D26,Plan!$H$13-B26+Plan!$I$13*D26,Plan!$H$14-B26+Plan!$I$14*D26,Plan!$H$15-B26+Plan!$I$15*D26,Plan!$H$16-B26+Plan!$I$16*D26) -> 0 | F26: =C26-E26 -> 264 | G26: =D26 -> 1.5474041 | H26: =Fee*F26+VQ*G26 -> 20.299233 | I26: =MAX(0,MIN(1,(GNone-H26)/(GNone-GFull))) -> 0 | J26: =1-A26 -> 0.8 | K26: =MIN(I26,J26) -> 0 | L26: 0.93368 | M26: 0.01785 | N26: 0.01752 | O26: =IF(M26<=Alpha,A26,-1) -> 0.2 | P26: =IF(L26>=0.95,A26,-1) -> -1 | Q26: =MIN(I26^2,J26) -> 0 | R26: =MIN(SQRT(I26),J26) -> 0
A27: 0.21 | B27: =DNever-(DNever-DUsual)*A27 -> 168.5 | C27: =SNever-(SNever-SPlaus)*A27 -> 262.2 | D27: =MAX(0,(B27-Plan!$H$5)/Plan!$I$5,(B27-Plan!$H$6)/Plan!$I$6,(B27-Plan!$H$7)/Plan!$I$7,(B27-Plan!$H$8)/Plan!$I$8,(B27-Plan!$H$9)/Plan!$I$9,(B27-Plan!$H$10)/Plan!$I$10,(B27-Plan!$H$11)/Plan!$I$11,(B27-Plan!$H$12)/Plan!$I$12,(B27-Plan!$H$13)/Plan!$I$13,(B27-Plan!$H$14)/Plan!$I$14,(B27-Plan!$H$15)/Plan!$I$15,(B27-Plan!$H$16)/Plan!$I$16) -> 1.486402 | E27: =MIN(C27,Plan!$H$5-B27+Plan!$I$5*D27,Plan!$H$6-B27+Plan!$I$6*D27,Plan!$H$7-B27+Plan!$I$7*D27,Plan!$H$8-B27+Plan!$I$8*D27,Plan!$H$9-B27+Plan!$I$9*D27,Plan!$H$10-B27+Plan!$I$10*D27,Plan!$H$11-B27+Plan!$I$11*D27,Plan!$H$12-B27+Plan!$I$12*D27,Plan!$H$13-B27+Plan!$I$13*D27,Plan!$H$14-B27+Plan!$I$14*D27,Plan!$H$15-B27+Plan!$I$15*D27,Plan!$H$16-B27+Plan!$I$16*D27) -> 0 | F27: =C27-E27 -> 262.2 | G27: =D27 -> 1.486402 | H27: =Fee*F27+VQ*G27 -> 19.757216 | I27: =MAX(0,MIN(1,(GNone-H27)/(GNone-GFull))) -> 0.016185576 | J27: =1-A27 -> 0.79 | K27: =MIN(I27,J27) -> 0.016185576 | L27: 0.93158 | M27: 0.01906 | N27: 0.01865 | O27: =IF(M27<=Alpha,A27,-1) -> 0.21 | P27: =IF(L27>=0.95,A27,-1) -> -1 | Q27: =MIN(I27^2,J27) -> 0.00026197288 | R27: =MIN(SQRT(I27),J27) -> 0.12722255
A28: 0.22 | B28: =DNever-(DNever-DUsual)*A28 -> 167 | C28: =SNever-(SNever-SPlaus)*A28 -> 260.4 | D28: =MAX(0,(B28-Plan!$H$5)/Plan!$I$5,(B28-Plan!$H$6)/Plan!$I$6,(B28-Plan!$H$7)/Plan!$I$7,(B28-Plan!$H$8)/Plan!$I$8,(B28-Plan!$H$9)/Plan!$I$9,(B28-Plan!$H$10)/Plan!$I$10,(B28-Plan!$H$11)/Plan!$I$11,(B28-Plan!$H$12)/Plan!$I$12,(B28-Plan!$H$13)/Plan!$I$13,(B28-Plan!$H$14)/Plan!$I$14,(B28-Plan!$H$15)/Plan!$I$15,(B28-Plan!$H$16)/Plan!$I$16) -> 1.4254 | E28: =MIN(C28,Plan!$H$5-B28+Plan!$I$5*D28,Plan!$H$6-B28+Plan!$I$6*D28,Plan!$H$7-B28+Plan!$I$7*D28,Plan!$H$8-B28+Plan!$I$8*D28,Plan!$H$9-B28+Plan!$I$9*D28,Plan!$H$10-B28+Plan!$I$10*D28,Plan!$H$11-B28+Plan!$I$11*D28,Plan!$H$12-B28+Plan!$I$12*D28,Plan!$H$13-B28+Plan!$I$13*D28,Plan!$H$14-B28+Plan!$I$14*D28,Plan!$H$15-B28+Plan!$I$15*D28,Plan!$H$16-B28+Plan!$I$16*D28) -> 0 | F28: =C28-E28 -> 260.4 | G28: =D28 -> 1.4254 | H28: =Fee*F28+VQ*G28 -> 19.2152 | I28: =MAX(0,MIN(1,(GNone-H28)/(GNone-GFull))) -> 0.052320024 | J28: =1-A28 -> 0.78 | K28: =MIN(I28,J28) -> 0.052320024 | L28: 0.92919 | M28: 0.02041 | N28: 0.02023 | O28: =IF(M28<=Alpha,A28,-1) -> 0.22 | P28: =IF(L28>=0.95,A28,-1) -> -1 | Q28: =MIN(I28^2,J28) -> 0.002737385 | R28: =MIN(SQRT(I28),J28) -> 0.22873571
A29: 0.23 | B29: =DNever-(DNever-DUsual)*A29 -> 165.5 | C29: =SNever-(SNever-SPlaus)*A29 -> 258.6 | D29: =MAX(0,(B29-Plan!$H$5)/Plan!$I$5,(B29-Plan!$H$6)/Plan!$I$6,(B29-Plan!$H$7)/Plan!$I$7,(B29-Plan!$H$8)/Plan!$I$8,(B29-Plan!$H$9)/Plan!$I$9,(B29-Plan!$H$10)/Plan!$I$10,(B29-Plan!$H$11)/Plan!$I$11,(B29-Plan!$H$12)/Plan!$I$12,(B29-Plan!$H$13)/Plan!$I$13,(B29-Plan!$H$14)/Plan!$I$14,(B29-Plan!$H$15)/Plan!$I$15,(B29-Plan!$H$16)/Plan!$I$16) -> 1.3643979 | E29: =MIN(C29,Plan!$H$5-B29+Plan!$I$5*D29,Plan!$H$6-B29+Plan!$I$6*D29,Plan!$H$7-B29+Plan!$I$7*D29,Plan!$H$8-B29+Plan!$I$8*D29,Plan!$H$9-B29+Plan!$I$9*D29,Plan!$H$10-B29+Plan!$I$10*D29,Plan!$H$11-B29+Plan!$I$11*D29,Plan!$H$12-B29+Plan!$I$12*D29,Plan!$H$13-B29+Plan!$I$13*D29,Plan!$H$14-B29+Plan!$I$14*D29,Plan!$H$15-B29+Plan!$I$15*D29,Plan!$H$16-B29+Plan!$I$16*D29) -> 0 | F29: =C29-E29 -> 258.6 | G29: =D29 -> 1.3643979 | H29: =Fee*F29+VQ*G29 -> 18.673183 | I29: =MAX(0,MIN(1,(GNone-H29)/(GNone-GFull))) -> 0.088454472 | J29: =1-A29 -> 0.77 | K29: =MIN(I29,J29) -> 0.088454472 | L29: 0.92682 | M29: 0.02181 | N29: 0.02179 | O29: =IF(M29<=Alpha,A29,-1) -> 0.23 | P29: =IF(L29>=0.95,A29,-1) -> -1 | Q29: =MIN(I29^2,J29) -> 0.0078241937 | R29: =MIN(SQRT(I29),J29) -> 0.29741297
