Workbook

Sheet README
B1: DCT Laboratory — Vol II, Ch 7: Dynamic Programming for Enterprise Systems
B2: Seed 26207 · Companion to DCT_V2_Ch07_Lab.ipynb and AXIOM Lab 2.7 (module AXIOM-07). Money in $ million.
B4: Worked Example 7.1, How Much Margin Should Meridian Hold Above the Capability Floor?, with the book's declarations.
B5: Declarations: the inputs of Step 1. CriticalRatio: Theorem 7.2's critical ratio and the target 55.75.
B6: BackwardInduction: a twelve-quarter horizon solved by formulas on a grid of 0.25 points, with its rule table.
B7: LookAhead: the value of each hiring decision one quarter ahead at three capability levels.
B8: Values: the engine's value function V* on a grid of 0.05 points; the formulas apply the Bellman operator to it and certify it by its residual.
B9: Prices: the price of a point and the engineering team's value. UpperBound: Theorem 7.2(iii), a bound on what any rule can achieve.
B10: RulesAndPlans: Table 7.3 and the value of responding, from the engine's exact evaluations.
B11: Value iteration (813 sweeps), policy iteration, the simulation and the finer calendars run in the notebook.
B12: Reference_Values and Checks: the engine's numbers and a PASS/FAIL comparison with this workbook's formulas.
B14: LEGEND
... B18: Cross-sheet link: green.

Sheet Declarations
A1: Declarations (Worked Example 7.1, Step 1). Money in $ million; capability in points.
A3: Quantity | B3: Value | C3: Source
A4: Discount rate a year | B4: 0.1 | C4: The board's 10 percent a year
A5: Discount factor a quarter, beta | B5: =(1+B4)^(-1/4) -> 0.97645409 | C5: beta = 1.1^(-1/4)
A6: Capability kept each quarter, alpha | B6: 0.975 | C6: 2.5 percent attrition a quarter (Volume I, Chapter 10)
A7: Cost of hiring and training a point, k | B7: 4 | C7: $4 million a point
A8: Hiring cap a quarter (points) | B8: 2.5 | C8: At most 2.5 points a quarter
A9: Capability floor | B9: 55 | C9: Below 55 the digital build slows (Chapter 6)
A10: Delay cost of the digital build a year | B10: 32 | C10: $32 million a year (Chapter 6)
A11: Slowdown per point short | B11: 0.2 | C11: A fifth per point short
A12: Cost of a point short for a quarter, p | B12: =B10/4*B11 -> 1.6 | C12: 8/5 = $1.6 million
A13: Effective horizon 1/(1 - beta), quarters | B13: =1/(1-B5) -> 42.47022
A15: Unplanned loss w (points) | B15: Probability | C15: P(loss > w) | D15: P(loss >= w)
A16: 1.5 | B16: 0.05 | C16: =SUMIF($A$16:$A$20,">"&A16,$B$16:$B$20) -> 0 | D16: =SUMIF($A$16:$A$20,">="&A16,$B$16:$B$20) -> 0.05
A17: 0.75 | B17: 0.2 | C17: =SUMIF($A$16:$A$20,">"&A17,$B$16:$B$20) -> 0.05 | D17: =SUMIF($A$16:$A$20,">="&A17,$B$16:$B$20) -> 0.25
A18: 0 | B18: 0.5 | C18: =SUMIF($A$16:$A$20,">"&A18,$B$16:$B$20) -> 0.25 | D18: =SUMIF($A$16:$A$20,">="&A18,$B$16:$B$20) -> 0.75
A19: -0.75 | B19: 0.2 | C19: =SUMIF($A$16:$A$20,">"&A19,$B$16:$B$20) -> 0.75 | D19: =SUMIF($A$16:$A$20,">="&A19,$B$16:$B$20) -> 0.95
A20: -1.5 | B20: 0.05 | C20: =SUMIF($A$16:$A$20,">"&A20,$B$16:$B$20) -> 0.95 | D20: =SUMIF($A$16:$A$20,">="&A20,$B$16:$B$20) -> 1
A21: Total probability | B21: =SUM(B16:B20) -> 1
A22: Mean loss a quarter | B22: =SUMPRODUCT(A16:A20,B16:B20) -> 0
A23: Standard deviation a quarter | B23: =SQRT(SUMPRODUCT(A16:A20,A16:A20,B16:B20)-B22^2) -> 0.67082039
A25: The engineering office's record: capability moves as c' = 0.975c + h - w each quarter.

Sheet CriticalRatio
A1: Look one quarter ahead: the critical ratio and the target (Theorem 7.2; AXIOM Lab 2.7, step 1)
A2: Quantity | B2: Value | C2: Reading
A3: Holding a planned point for a quarter, k(1 - alpha beta) | B3: =Cost_k*(1-Alpha_keep*Beta_q) -> 0.19182905 | C3: 0.767 a year
A4: A point short next quarter, beta p | B4: =Beta_q*Short_p -> 1.5623265
A5: Critical ratio | B5: =B3/B4 -> 0.12278422 | C5: Theorem 7.2(ii)
A6: Margin: smallest loss w with P(loss > w) <= ratio | B6: =_xlfn.MINIFS(Loss_w,Declarations!$C$16:$C$20,"<="&B5) -> 0.75 | C6: P(loss > 0.75) = 0.05 <= ratio <= P(loss >= 0.75) = 0.25
A7: Target for planned capability, floor + margin | B7: =Floor_c+B6 -> 55.75 | C7: Top up to 55.75
A8: Hire nothing above (target / alpha) | B8: =B7/Alpha_keep -> 57.179487
A9: Hire at the cap below ((target - cap) / alpha) | B9: =(B7-Cap_h)/Alpha_keep -> 54.615385
A10: Holding a planned point for a year | B10: =4*B3 -> 0.7673162
A12: Loss w last quarter | B12: Hiring needed to restore the target | C12: Hiring done (cap, no firing) | D12: Planned capability reached
A13: =Declarations!A16 -> 1.5 | B13: =(1-Alpha_keep)*$B$7+Alpha_keep*A13 -> 2.85625 | C13: =MIN(Cap_h,MAX(0,B13)) -> 2.5 | D13: =Alpha_keep*($B$7-A13)+C13 -> 55.39375
A14: =Declarations!A17 -> 0.75 | B14: =(1-Alpha_keep)*$B$7+Alpha_keep*A14 -> 2.125 | C14: =MIN(Cap_h,MAX(0,B14)) -> 2.125 | D14: =Alpha_keep*($B$7-A14)+C14 -> 55.75
A15: =Declarations!A18 -> 0 | B15: =(1-Alpha_keep)*$B$7+Alpha_keep*A15 -> 1.39375 | C15: =MIN(Cap_h,MAX(0,B15)) -> 1.39375 | D15: =Alpha_keep*($B$7-A15)+C15 -> 55.75
A16: =Declarations!A19 -> -0.75 | B16: =(1-Alpha_keep)*$B$7+Alpha_keep*A16 -> 0.6625 | C16: =MIN(Cap_h,MAX(0,B16)) -> 0.6625 | D16: =Alpha_keep*($B$7-A16)+C16 -> 55.75
A17: =Declarations!A20 -> -1.5 | B17: =(1-Alpha_keep)*$B$7+Alpha_keep*A17 -> -0.06875 | C17: =MIN(Cap_h,MAX(0,B17)) -> 0 | D17: =Alpha_keep*($B$7-A17)+C17 -> 55.81875
A19: After the worst loss the cap cannot restore the target; after the best gain capability stays above it with no hiring. The recursion, not the formula, certifies the target (Worked Example 7.1, Step 3).

Sheet BackwardInduction
A1: Solve backward: twelve quarters from V_12 = 0 on a grid of 0.25 points (Theorem 7.1(i); AXIOM Lab 2.7, step 2)
A2: Each quarter: G(y) = -k y + beta E V_next(y - w) at the nodes; V(c) = g(c) + k alpha c + the best G over the reachable planned levels [L, U] (nodes, and the ends by interpolation). Values are linear between nodes. Rule 'none': hiring is not worth its cost at any capability above 50.
C3: capability levels: | D3: 53 | E3: 54 | F3: 55 | G3: 56 | H3: 57 | I3: 58
A4: Quarter k | B4: Target (best planned level) | C4: Rule | D4: Hiring at 53 | E4: Hiring at 54 | F4: Hiring at 55 | G4: Hiring at 56 | H4: Hiring at 57 | I4: Hiring at 58 | J4: Engine target | K4: V_k(58) | L4: V_k(53)
A5: 0 | B5: =_xlfn.MINIFS($A$21:$A$141,$BF$21:$BF$141,">="&(MAX($BF$21:$BF$141)-0.000000001)) -> 55.75 | C5: =IF(B5>=Alpha_keep*50,"top up to "&TEXT(B5,"0.00"),"none: hire nothing") -> top up to 55.75 | D5: =MIN(Cap_h,MAX(0,$B5-Alpha_keep*D$3)) -> 2.5 | E5: =MIN(Cap_h,MAX(0,$B5-Alpha_keep*E$3)) -> 2.5 | F5: =MIN(Cap_h,MAX(0,$B5-Alpha_keep*F$3)) -> 2.125 | G5: =MIN(Cap_h,MAX(0,$B5-Alpha_keep*G$3)) -> 1.15 | H5: =MIN(Cap_h,MAX(0,$B5-Alpha_keep*H$3)) -> 0.175 | I5: =MIN(Cap_h,MAX(0,$B5-Alpha_keep*I$3)) -> 0 | J5: 55.75 | K5: =INDEX($BI$21:$BI$141,MATCH(58,$A$21:$A$141,0)) -> -40.454736 | L5: =INDEX($BI$21:$BI$141,MATCH(53,$A$21:$A$141,0)) -> -64.299579
A6: 1 | B6: =_xlfn.MINIFS($A$21:$A$141,$BB$21:$BB$141,">="&(MAX($BB$21:$BB$141)-0.000000001)) -> 55.75 | C6: =IF(B6>=Alpha_keep*50,"top up to "&TEXT(B6,"0.00"),"none: hire nothing") -> top up to 55.75 | D6: =MIN(Cap_h,MAX(0,$B6-Alpha_keep*D$3)) -> 2.5 | E6: =MIN(Cap_h,MAX(0,$B6-Alpha_keep*E$3)) -> 2.5 | F6: =MIN(Cap_h,MAX(0,$B6-Alpha_keep*F$3)) -> 2.125 | G6: =MIN(Cap_h,MAX(0,$B6-Alpha_keep*G$3)) -> 1.15 | H6: =MIN(Cap_h,MAX(0,$B6-Alpha_keep*H$3)) -> 0.175 | I6: =MIN(Cap_h,MAX(0,$B6-Alpha_keep*I$3)) -> 0 | J6: 55.75 | K6: =INDEX($BE$21:$BE$141,MATCH(58,$A$21:$A$141,0)) -> -35.865734 | L6: =INDEX($BE$21:$BE$141,MATCH(53,$A$21:$A$141,0)) -> -59.710559
A7: 2 | B7: =_xlfn.MINIFS($A$21:$A$141,$AX$21:$AX$141,">="&(MAX($AX$21:$AX$141)-0.000000001)) -> 55.75 | C7: =IF(B7>=Alpha_keep*50,"top up to "&TEXT(B7,"0.00"),"none: hire nothing") -> top up to 55.75 | D7: =MIN(Cap_h,MAX(0,$B7-Alpha_keep*D$3)) -> 2.5 | E7: =MIN(Cap_h,MAX(0,$B7-Alpha_keep*E$3)) -> 2.5 | F7: =MIN(Cap_h,MAX(0,$B7-Alpha_keep*F$3)) -> 2.125 | G7: =MIN(Cap_h,MAX(0,$B7-Alpha_keep*G$3)) -> 1.15 | H7: =MIN(Cap_h,MAX(0,$B7-Alpha_keep*H$3)) -> 0.175 | I7: =MIN(Cap_h,MAX(0,$B7-Alpha_keep*I$3)) -> 0 | J7: 55.75 | K7: =INDEX($BA$21:$BA$141,MATCH(58,$A$21:$A$141,0)) -> -31.166077 | L7: =INDEX($BA$21:$BA$141,MATCH(53,$A$21:$A$141,0)) -> -55.010807
A8: 3 | B8: =_xlfn.MINIFS($A$21:$A$141,$AT$21:$AT$141,">="&(MAX($AT$21:$AT$141)-0.000000001)) -> 55.75 | C8: =IF(B8>=Alpha_keep*50,"top up to "&TEXT(B8,"0.00"),"none: hire nothing") -> top up to 55.75 | D8: =MIN(Cap_h,MAX(0,$B8-Alpha_keep*D$3)) -> 2.5 | E8: =MIN(Cap_h,MAX(0,$B8-Alpha_keep*E$3)) -> 2.5 | F8: =MIN(Cap_h,MAX(0,$B8-Alpha_keep*F$3)) -> 2.125 | G8: =MIN(Cap_h,MAX(0,$B8-Alpha_keep*G$3)) -> 1.15 | H8: =MIN(Cap_h,MAX(0,$B8-Alpha_keep*H$3)) -> 0.175 | I8: =MIN(Cap_h,MAX(0,$B8-Alpha_keep*I$3)) -> 0 | J8: 55.75 | K8: =INDEX($AW$21:$AW$141,MATCH(58,$A$21:$A$141,0)) -> -26.353107 | L8: =INDEX($AW$21:$AW$141,MATCH(53,$A$21:$A$141,0)) -> -50.197335
A9: 4 | B9: =_xlfn.MINIFS($A$21:$A$141,$AP$21:$AP$141,">="&(MAX($AP$21:$AP$141)-0.000000001)) -> 55.75 | C9: =IF(B9>=Alpha_keep*50,"top up to "&TEXT(B9,"0.00"),"none: hire nothing") -> top up to 55.75 | D9: =MIN(Cap_h,MAX(0,$B9-Alpha_keep*D$3)) -> 2.5 | E9: =MIN(Cap_h,MAX(0,$B9-Alpha_keep*E$3)) -> 2.5 | F9: =MIN(Cap_h,MAX(0,$B9-Alpha_keep*F$3)) -> 2.125 | G9: =MIN(Cap_h,MAX(0,$B9-Alpha_keep*G$3)) -> 1.15 | H9: =MIN(Cap_h,MAX(0,$B9-Alpha_keep*H$3)) -> 0.175 | I9: =MIN(Cap_h,MAX(0,$B9-Alpha_keep*I$3)) -> 0 | J9: 55.75 | K9: =INDEX($AS$21:$AS$141,MATCH(58,$A$21:$A$141,0)) -> -21.424217 | L9: =INDEX($AS$21:$AS$141,MATCH(53,$A$21:$A$141,0)) -> -45.265743
A10: 5 | B10: =_xlfn.MINIFS($A$21:$A$141,$AL$21:$AL$141,">="&(MAX($AL$21:$AL$141)-0.000000001)) -> 55.75 | C10: =IF(B10>=Alpha_keep*50,"top up to "&TEXT(B10,"0.00"),"none: hire nothing") -> top up to 55.75 | D10: =MIN(Cap_h,MAX(0,$B10-Alpha_keep*D$3)) -> 2.5 | E10: =MIN(Cap_h,MAX(0,$B10-Alpha_keep*E$3)) -> 2.5 | F10: =MIN(Cap_h,MAX(0,$B10-Alpha_keep*F$3)) -> 2.125 | G10: =MIN(Cap_h,MAX(0,$B10-Alpha_keep*G$3)) -> 1.15 | H10: =MIN(Cap_h,MAX(0,$B10-Alpha_keep*H$3)) -> 0.175 | I10: =MIN(Cap_h,MAX(0,$B10-Alpha_keep*I$3)) -> 0 | J10: 55.75 | K10: =INDEX($AO$21:$AO$141,MATCH(58,$A$21:$A$141,0)) -> -16.378054 | L10: =INDEX($AO$21:$AO$141,MATCH(53,$A$21:$A$141,0)) -> -40.20487
A11: 6 | B11: =_xlfn.MINIFS($A$21:$A$141,$AH$21:$AH$141,">="&(MAX($AH$21:$AH$141)-0.000000001)) -> 55.75 | C11: =IF(B11>=Alpha_keep*50,"top up to "&TEXT(B11,"0.00"),"none: hire nothing") -> top up to 55.75 | D11: =MIN(Cap_h,MAX(0,$B11-Alpha_keep*D$3)) -> 2.5 | E11: =MIN(Cap_h,MAX(0,$B11-Alpha_keep*E$3)) -> 2.5 | F11: =MIN(Cap_h,MAX(0,$B11-Alpha_keep*F$3)) -> 2.125 | G11: =MIN(Cap_h,MAX(0,$B11-Alpha_keep*G$3)) -> 1.15 | H11: =MIN(Cap_h,MAX(0,$B11-Alpha_keep*H$3)) -> 0.175 | I11: =MIN(Cap_h,MAX(0,$B11-Alpha_keep*I$3)) -> 0 | J11: 55.75 | K11: =INDEX($AK$21:$AK$141,MATCH(58,$A$21:$A$141,0)) -> -11.229682 | L11: =INDEX($AK$21:$AK$141,MATCH(53,$A$21:$A$141,0)) -> -34.972059
A12: 7 | B12: =_xlfn.MINIFS($A$21:$A$141,$AD$21:$AD$141,">="&(MAX($AD$21:$AD$141)-0.000000001)) -> 55.75 | C12: =IF(B12>=Alpha_keep*50,"top up to "&TEXT(B12,"0.00"),"none: hire nothing") -> top up to 55.75 | D12: =MIN(Cap_h,MAX(0,$B12-Alpha_keep*D$3)) -> 2.5 | E12: =MIN(Cap_h,MAX(0,$B12-Alpha_keep*E$3)) -> 2.5 | F12: =MIN(Cap_h,MAX(0,$B12-Alpha_keep*F$3)) -> 2.125 | G12: =MIN(Cap_h,MAX(0,$B12-Alpha_keep*G$3)) -> 1.15 | H12: =MIN(Cap_h,MAX(0,$B12-Alpha_keep*H$3)) -> 0.175 | I12: =MIN(Cap_h,MAX(0,$B12-Alpha_keep*I$3)) -> 0 | J12: 55.75 | K12: =INDEX($AG$21:$AG$141,MATCH(58,$A$21:$A$141,0)) -> -6.2002755 | L12: =INDEX($AG$21:$AG$141,MATCH(53,$A$21:$A$141,0)) -> -29.448414
A13: 8 | B13: =_xlfn.MINIFS($A$21:$A$141,$Z$21:$Z$141,">="&(MAX($Z$21:$Z$141)-0.000000001)) -> 54.75 | C13: =IF(B13>=Alpha_keep*50,"top up to "&TEXT(B13,"0.00"),"none: hire nothing") -> top up to 54.75 | D13: =MIN(Cap_h,MAX(0,$B13-Alpha_keep*D$3)) -> 2.5 | E13: =MIN(Cap_h,MAX(0,$B13-Alpha_keep*E$3)) -> 2.1 | F13: =MIN(Cap_h,MAX(0,$B13-Alpha_keep*F$3)) -> 1.125 | G13: =MIN(Cap_h,MAX(0,$B13-Alpha_keep*G$3)) -> 0.15 | H13: =MIN(Cap_h,MAX(0,$B13-Alpha_keep*H$3)) -> 0 | I13: =MIN(Cap_h,MAX(0,$B13-Alpha_keep*I$3)) -> 0 | J13: 54.75 | K13: =INDEX($AC$21:$AC$141,MATCH(58,$A$21:$A$141,0)) -> -2.4348266 | L13: =INDEX($AC$21:$AC$141,MATCH(53,$A$21:$A$141,0)) -> -23.085896
A14: 9 | B14: =_xlfn.MINIFS($A$21:$A$141,$V$21:$V$141,">="&(MAX($V$21:$V$141)-0.000000001)) -> 44.25 | C14: =IF(B14>=Alpha_keep*50,"top up to "&TEXT(B14,"0.00"),"none: hire nothing") -> none: hire nothing | D14: =MIN(Cap_h,MAX(0,$B14-Alpha_keep*D$3)) -> 0 | E14: =MIN(Cap_h,MAX(0,$B14-Alpha_keep*E$3)) -> 0 | F14: =MIN(Cap_h,MAX(0,$B14-Alpha_keep*F$3)) -> 0 | G14: =MIN(Cap_h,MAX(0,$B14-Alpha_keep*G$3)) -> 0 | H14: =MIN(Cap_h,MAX(0,$B14-Alpha_keep*H$3)) -> 0 | I14: =MIN(Cap_h,MAX(0,$B14-Alpha_keep*I$3)) -> 0 | J14: 44.25 | K14: =INDEX($Y$21:$Y$141,MATCH(58,$A$21:$A$141,0)) -> -0.46191925 | L14: =INDEX($Y$21:$Y$141,MATCH(53,$A$21:$A$141,0)) -> -15.437964
A15: 10 | B15: =_xlfn.MINIFS($A$21:$A$141,$R$21:$R$141,">="&(MAX($R$21:$R$141)-0.000000001)) -> 42.5 | C15: =IF(B15>=Alpha_keep*50,"top up to "&TEXT(B15,"0.00"),"none: hire nothing") -> none: hire nothing | D15: =MIN(Cap_h,MAX(0,$B15-Alpha_keep*D$3)) -> 0 | E15: =MIN(Cap_h,MAX(0,$B15-Alpha_keep*E$3)) -> 0 | F15: =MIN(Cap_h,MAX(0,$B15-Alpha_keep*F$3)) -> 0 | G15: =MIN(Cap_h,MAX(0,$B15-Alpha_keep*G$3)) -> 0 | H15: =MIN(Cap_h,MAX(0,$B15-Alpha_keep*H$3)) -> 0 | I15: =MIN(Cap_h,MAX(0,$B15-Alpha_keep*I$3)) -> 0 | J15: 42.5 | K15: =INDEX($U$21:$U$141,MATCH(58,$A$21:$A$141,0)) -> 0 | L15: =INDEX($U$21:$U$141,MATCH(53,$A$21:$A$141,0)) -> -8.3947358
A16: 11 | B16: =_xlfn.MINIFS($A$21:$A$141,$N$21:$N$141,">="&(MAX($N$21:$N$141)-0.000000001)) -> 40 | C16: =IF(B16>=Alpha_keep*50,"top up to "&TEXT(B16,"0.00"),"none: hire nothing") -> none: hire nothing | D16: =MIN(Cap_h,MAX(0,$B16-Alpha_keep*D$3)) -> 0 | E16: =MIN(Cap_h,MAX(0,$B16-Alpha_keep*E$3)) -> 0 | F16: =MIN(Cap_h,MAX(0,$B16-Alpha_keep*F$3)) -> 0 | G16: =MIN(Cap_h,MAX(0,$B16-Alpha_keep*G$3)) -> 0 | H16: =MIN(Cap_h,MAX(0,$B16-Alpha_keep*H$3)) -> 0 | I16: =MIN(Cap_h,MAX(0,$B16-Alpha_keep*I$3)) -> 0 | J16: 40 | K16: =INDEX($Q$21:$Q$141,MATCH(58,$A$21:$A$141,0)) -> 0 | L16: =INDEX($Q$21:$Q$141,MATCH(53,$A$21:$A$141,0)) -> -3.2
A17: Value of the team over twelve quarters, V_0(58) - V_0(53) | F17: =K5-L5 -> 23.844843
A18: Grid: lowest node | B18: 40 | C18: spacing | D18: 0.25 | E18: highest node | F18: =B18+120*D18 -> 70 | G18: Quarters whose target matches the engine | J18: =SUMPRODUCT(--(ABS(B5:B16-J5:J16)<0.000000001)) -> 12
G19: Largest gap to the engine's V_0 | J19: =MAX(BK21:BK141) -> 1.1368684e-13
A20: c | B20: node | C20: g(c) | D20: k alpha c | E20: a (lowest hire) | F20: b (highest hire) | G20: L | H20: U | I20: jL | J20: tL | K20: jU | L20: tU | M20: V_12 | N20: G_11 | O20: G_11(L) | P20: G_11(U) | Q20: V_11 | R20: G_10 | S20: G_10(L) | T20: G_10(U) | U20: V_10 | V20: G_9 | W20: G_9(L) | X20: G_9(U) | Y20: V_9 | Z20: G_8 | AA20: G_8(L) | AB20: G_8(U) | AC20: V_8 | AD20: G_7 | AE20: G_7(L) | AF20: G_7(U) | AG20: V_7 | AH20: G_6 | AI20: G_6(L) | AJ20: G_6(U) | AK20: V_6 | AL20: G_5 | AM20: G_5(L) | AN20: G_5(U) | AO20: V_5 | AP20: G_4 | AQ20: G_4(L) | AR20: G_4(U) | AS20: V_4 | AT20: G_3 | AU20: G_3(L) | AV20: G_3(U) | AW20: V_3 | AX20: G_2 | AY20: G_2(L) | AZ20: G_2(U) | BA20: V_2 | BB20: G_1 | BC20: G_1(L) | BD20: G_1(U) | BE20: V_1 | BF20: G_0 | BG20: G_0(L) | BH20: G_0(U) | BI20: V_0 | BJ20: Engine V_0 | BK20: |V_0 - engine|
A21: =$B$18 -> 40 | B21: 1 | C21: =-Short_p*MAX(Floor_c-A21,0) -> -24 | D21: =Cost_k*Alpha_keep*A21 -> 156 | E21: =MIN(Cap_h,MAX(0,$B$18+MAX(Loss_w)-Alpha_keep*A21)) -> 2.5 | F21: =MAX(MIN(Cap_h,$F$18+MIN(Loss_w)-Alpha_keep*A21),E21) -> 2.5 | G21: =Alpha_keep*A21+E21 -> 41.5 | H21: =Alpha_keep*A21+F21 -> 41.5 | I21: =MIN(INT((G21-$B$18)/$D$18+0.000000001),119) -> 6 | J21: =(G21-$B$18)/$D$18-I21 -> 0 | K21: =MIN(INT((H21-$B$18)/$D$18+0.000000001),119) -> 6 | L21: =(H21-$B$18)/$D$18-K21 -> 0 | M21: 0 | N21: =-Cost_k*$A21+Beta_q*(Declarations!$B$16*INDEX(M$21:M$141,MAX(1,MIN(121,$B21-ROUND(Declarations!$A$16/$D$18,0))))+Declarations!$B$17*INDEX(M$21:M$141,MAX(1,MIN(121,$B21-ROUND(Declarations!$A$17/$D$18,0))))+Declarations!$B$18*INDEX(M$21:M$141,MAX(1,MIN(121,$B21-ROUND(Declarations!$A$18/$D$18,0))))+Declarations!$B$19*INDEX(M$21:M$141,MAX(1,MIN(121,$B21-ROUND(Declarations!$A$19/$D$18,0))))+Declarations!$B$20*INDEX(M$21:M$141,MAX(1,MIN(121,$B21-ROUND(Declarations!$A$20/$D$18,0))))) -> -160 | O21: =INDEX(N$21:N$141,$I21+1)*(1-$J21)+INDEX(N$21:N$141,$I21+2)*$J21 -> -166 | P21: =INDEX(N$21:N$141,$K21+1)*(1-$L21)+INDEX(N$21:N$141,$K21+2)*$L21 -> -166 | Q21: =$C21+$D21+MAX(O21,P21,IF(COUNTIFS($A$21:$A$141,">="&$G21,$A$21:$A$141,"<="&$H21)>0,_xlfn.MAXIFS(N$21:N$141,$A$21:$A$141,">="&$G21,$A$21:$A$141,"<="&$H21),O21)) -> -34 | R21: =-Cost_k*$A21+Beta_q*(Declarations!$B$16*INDEX(Q$21:Q$141,MAX(1,MIN(121,$B21-ROUND(Declarations!$A$16/$D$18,0))))+Declarations!$B$17*INDEX(Q$21:Q$141,MAX(1,MIN(121,$B21-ROUND(Declarations!$A$17/$D$18,0))))+Declarations!$B$18*INDEX(Q$21:Q$141,MAX(1,MIN(121,$B21-ROUND(Declarations!$A$18/$D$18,0))))+Declarations!$B$19*INDEX(Q$21:Q$141,MAX(1,MIN(121,$B21-ROUND(Declarations!$A$19/$D$18,0))))+Declarations!$B$20*INDEX(Q$21:Q$141,MAX(1,MIN(121,$B21-ROUND(Declarations!$A$20/$D$18,0))))) -> -191.99108 | S21: =INDEX(R$21:R$141,$I21+1)*(1-$J21)+INDEX(R$21:R$141,$I21+2)*$J21 -> -191.22669 | T21: =INDEX(R$21:R$141,$K21+1)*(1-$L21)+INDEX(R$21:R$141,$K21+2)*$L21 -> -191.22669 | U21: =$C21+$D21+MAX(S21,T21,IF(COUNTIFS($A$21:$A$141,">="&$G21,$A$21:$A$141,"<="&$H21)>0,_xlfn.MAXIFS(R$21:R$141,$A$21:$A$141,">="&$G21,$A$21:$A$141,"<="&$H21),S21)) -> -59.226691 | V21: =-Cost_k*$A21+Beta_q*(Declarations!$B$16*INDEX(U$21:U$141,MAX(1,MIN(121,$B21-ROUND(Declarations!$A$16/$D$18,0))))+Declarations!$B$17*INDEX(U$21:U$141,MAX(1,MIN(121,$B21-ROUND(Declarations!$A$17/$D$18,0))))+Declarations!$B$18*INDEX(U$21:U$141,MAX(1,MIN(121,$B21-ROUND(Declarations!$A$18/$D$18,0))))+Declarations!$B$19*INDEX(U$21:U$141,MAX(1,MIN(121,$B21-ROUND(Declarations!$A$19/$D$18,0))))+Declarations!$B$20*INDEX(U$21:U$141,MAX(1,MIN(121,$B21-ROUND(Declarations!$A$20/$D$18,0))))) -> -216.4852 | W21: =INDEX(V$21:V$141,$I21+1)*(1-$J21)+INDEX(V$21:V$141,$I21+2)*$J21 -> -215.18827 | X21: =INDEX(V$21:V$141,$K21+1)*(1-$L21)+INDEX(V$21:V$141,$K21+2)*$L21 -> -215.18827 | Y21: =$C21+$D21+MAX(W21,X21,IF(COUNTIFS($A$21:$A$141,">="&$G21,$A$21:$A$141,"<="&$H21)>0,_xlfn.MAXIFS(V$21:V$141,$A$21:$A$141,">="&$G21,$A$21:$A$141,"<="&$H21),W21)) -> -83.188271 | Z21: =-Cost_k*$A21+Beta_q*(Declarations!$B$16*INDEX(Y$21:Y$141,MAX(1,MIN(121,$B21-ROUND(Declarations!$A$16/$D$18,0))))+Declarations!$B$17*INDEX(Y$21:Y$141,MAX(1,MIN(121,$B21-ROUND(Declarations!$A$17/$D$18,0))))+Declarations!$B$18*INDEX(Y$21:Y$141,MAX(1,MIN(121,$B21-ROUND(Declarations!$A$18/$D$18,0))))+Declarations!$B$19*INDEX(Y$21:Y$141,MAX(1,MIN(121,$B21-ROUND(Declarations!$A$19/$D$18,0))))+Declarations!$B$20*INDEX(Y$21:Y$141,MAX(1,MIN(121,$B21-ROUND(Declarations!$A$20/$D$18,0))))) -> -239.72106 | AA21: =INDEX(Z$21:Z$141,$I21+1)*(1-$J21)+INDEX(Z$21:Z$141,$I21+2)*$J21 -> -237.35706 | AB21: =INDEX(Z$21:Z$141,$K21+1)*(1-$L21)+INDEX(Z$21:Z$141,$K21+2)*$L21 -> -237.35706 | AC21: =$C21+$D21+MAX(AA21,AB21,IF(COUNTIFS($A$21:$A$141,">="&$G21,$A$21:$A$141,"<="&$H21)>0,_xlfn.MAXIFS(Z$21:Z$141,$A$21:$A$141,">="&$G21,$A$21:$A$141,"<="&$H21),AA21)) -> -105.35706 | AD21: =-Cost_k*$A21+Beta_q*(Declarations!$B$16*INDEX(AC$21:AC$141,MAX(1,MIN(121,$B21-ROUND(Declarations!$A$16/$D$18,0))))+Declarations!$B$17*INDEX(AC$21:AC$141,MAX(1,MIN(121,$B21-ROUND(Declarations!$A$17/$D$18,0))))+Declarations!$B$18*INDEX(AC$21:AC$141,MAX(1,MIN(121,$B21-ROUND(Declarations!$A$18/$D$18,0))))+Declarations!$B$19*INDEX(AC$21:AC$141,MAX(1,MIN(121,$B21-ROUND(Declarations!$A$19/$D$18,0))))+Declarations!$B$20*INDEX(AC$21:AC$141,MAX(1,MIN(121,$B21-ROUND(Declarations!$A$20/$D$18,0))))) -> -261.22411 | AE21: =INDEX(AD$21:AD$141,$I21+1)*(1-$J21)+INDEX(AD$21:AD$141,$I21+2)*$J21 -> -258.14726 | AF21: =INDEX(AD$21:AD$141,$K21+1)*(1-$L21)+INDEX(AD$21:AD$141,$K21+2)*$L21 -> -258.14726 | AG21: =$C21+$D21+MAX(AE21,AF21,IF(COUNTIFS($A$21:$A$141,">="&$G21,$A$21:$A$141,"<="&$H21)>0,_xlfn.MAXIFS(AD$21:AD$141,$A$21:$A$141,">="&$G21,$A$21:$A$141,"<="&$H21),AE21)) -> -126.14726 | AH21: =-Cost_k*$A21+Beta_q*(Declarations!$B$16*INDEX(AG$21:AG$141,MAX(1,MIN(121,$B21-ROUND(Declarations!$A$16/$D$18,0))))+Declarations!$B$17*INDEX(AG$21:AG$141,MAX(1,MIN(121,$B21-ROUND(Declarations!$A$17/$D$18,0))))+Declarations!$B$18*INDEX(AG$21:AG$141,MAX(1,MIN(121,$B21-ROUND(Declarations!$A$18/$D$18,0))))+Declarations!$B$19*INDEX(AG$21:AG$141,MAX(1,MIN(121,$B21-ROUND(Declarations!$A$19/$D$18,0))))+Declarations!$B$20*INDEX(AG$21:AG$141,MAX(1,MIN(121,$B21-ROUND(Declarations!$A$20/$D$18,0))))) -> -281.37102 | AI21: =INDEX(AH$21:AH$141,$I21+1)*(1-$J21)+INDEX(AH$21:AH$141,$I21+2)*$J21 -> -277.23377 | AJ21: =INDEX(AH$21:AH$141,$K21+1)*(1-$L21)+INDEX(AH$21:AH$141,$K21+2)*$L21 -> -277.23377 | AK21: =$C21+$D21+MAX(AI21,AJ21,IF(COUNTIFS($A$21:$A$141,">="&$G21,$A$21:$A$141,"<="&$H21)>0,_xlfn.MAXIFS(AH$21:AH$141,$A$21:$A$141,">="&$G21,$A$21:$A$141,"<="&$H21),AI21)) -> -145.23377 | AL21: =-Cost_k*$A21+Beta_q*(Declarations!$B$16*INDEX(AK$21:AK$141,MAX(1,MIN(121,$B21-ROUND(Declarations!$A$16/$D$18,0))))+Declarations!$B$17*INDEX(AK$21:AK$141,MAX(1,MIN(121,$B21-ROUND(Declarations!$A$17/$D$18,0))))+Declarations!$B$18*INDEX(AK$21:AK$141,MAX(1,MIN(121,$B21-ROUND(Declarations!$A$18/$D$18,0))))+Declarations!$B$19*INDEX(AK$21:AK$141,MAX(1,MIN(121,$B21-ROUND(Declarations!$A$19/$D$18,0))))+Declarations!$B$20*INDEX(AK$21:AK$141,MAX(1,MIN(121,$B21-ROUND(Declarations!$A$20/$D$18,0))))) -> -299.79743 | AM21: =INDEX(AL$21:AL$141,$I21+1)*(1-$J21)+INDEX(AL$21:AL$141,$I21+2)*$J21 -> -294.49319 | AN21: =INDEX(AL$21:AL$141,$K21+1)*(1-$L21)+INDEX(AL$21:AL$141,$K21+2)*$L21 -> -294.49319 | AO21: =$C21+$D21+MAX(AM21,AN21,IF(COUNTIFS($A$21:$A$141,">="&$G21,$A$21:$A$141,"<="&$H21)>0,_xlfn.MAXIFS(AL$21:AL$141,$A$21:$A$141,">="&$G21,$A$21:$A$141,"<="&$H21),AM21)) -> -162.49319 | AP21: =-Cost_k*$A21+Beta_q*(Declarations!$B$16*INDEX(AO$21:AO$141,MAX(1,MIN(121,$B21-ROUND(Declarations!$A$16/$D$18,0))))+Declarations!$B$17*INDEX(AO$21:AO$141,MAX(1,MIN(121,$B21-ROUND(Declarations!$A$17/$D$18,0))))+Declarations!$B$18*INDEX(AO$21:AO$141,MAX(1,MIN(121,$B21-ROUND(Declarations!$A$18/$D$18,0))))+Declarations!$B$19*INDEX(AO$21:AO$141,MAX(1,MIN(121,$B21-ROUND(Declarations!$A$19/$D$18,0))))+Declarations!$B$20*INDEX(AO$21:AO$141,MAX(1,MIN(121,$B21-ROUND(Declarations!$A$20/$D$18,0))))) -> -316.4619 | AQ21: =INDEX(AP$21:AP$141,$I21+1)*(1-$J21)+INDEX(AP$21:AP$141,$I21+2)*$J21 -> -310.06124 | AR21: =INDEX(AP$21:AP$141,$K21+1)*(1-$L21)+INDEX(AP$21:AP$141,$K21+2)*$L21 -> -310.06124 | AS21: =$C21+$D21+MAX(AQ21,AR21,IF(COUNTIFS($A$21:$A$141,">="&$G21,$A$21:$A$141,"<="&$H21)>0,_xlfn.MAXIFS(AP$21:AP$141,$A$21:$A$141,">="&$G21,$A$21:$A$141,"<="&$H21),AQ21)) -> -178.06124 | AT21: =-Cost_k*$A21+Beta_q*(Declarations!$B$16*INDEX(AS$21:AS$141,MAX(1,MIN(121,$B21-ROUND(Declarations!$A$16/$D$18,0))))+Declarations!$B$17*INDEX(AS$21:AS$141,MAX(1,MIN(121,$B21-ROUND(Declarations!$A$17/$D$18,0))))+Declarations!$B$18*INDEX(AS$21:AS$141,MAX(1,MIN(121,$B21-ROUND(Declarations!$A$18/$D$18,0))))+Declarations!$B$19*INDEX(AS$21:AS$141,MAX(1,MIN(121,$B21-ROUND(Declarations!$A$19/$D$18,0))))+Declarations!$B$20*INDEX(AS$21:AS$141,MAX(1,MIN(121,$B21-ROUND(Declarations!$A$20/$D$18,0))))) -> -331.46133 | AU21: =INDEX(AT$21:AT$141,$I21+1)*(1-$J21)+INDEX(AT$21:AT$141,$I21+2)*$J21 -> -323.8599 | AV21: =INDEX(AT$21:AT$141,$K21+1)*(1-$L21)+INDEX(AT$21:AT$141,$K21+2)*$L21 -> -323.8599 | AW21: =$C21+$D21+MAX(AU21,AV21,IF(COUNTIFS($A$21:$A$141,">="&$G21,$A$21:$A$141,"<="&$H21)>0,_xlfn.MAXIFS(AT$21:AT$141,$A$21:$A$141,">="&$G21,$A$21:$A$141,"<="&$H21),AU21)) -> -191.8599 | AX21: =-Cost_k*$A21+Beta_q*(Declarations!$B$16*INDEX(AW$21:AW$141,MAX(1,MIN(121,$B21-ROUND(Declarations!$A$16/$D$18,0))))+Declarations!$B$17*INDEX(AW$21:AW$141,MAX(1,MIN(121,$B21-ROUND(Declarations!$A$17/$D$18,0))))+Declarations!$B$18*INDEX(AW$21:AW$141,MAX(1,MIN(121,$B21-ROUND(Declarations!$A$18/$D$18,0))))+Declarations!$B$19*INDEX(AW$21:AW$141,MAX(1,MIN(121,$B21-ROUND(Declarations!$A$19/$D$18,0))))+Declarations!$B$20*INDEX(AW$21:AW$141,MAX(1,MIN(121,$B21-ROUND(Declarations!$A$20/$D$18,0))))) -> -344.71587 | AY21: =INDEX(AX$21:AX$141,$I21+1)*(1-$J21)+INDEX(AX$21:AX$141,$I21+2)*$J21 -> -335.84434 | AZ21: =INDEX(AX$21:AX$141,$K21+1)*(1-$L21)+INDEX(AX$21:AX$141,$K21+2)*$L21 -> -335.84434 | BA21: =$C21+$D21+MAX(AY21,AZ21,IF(COUNTIFS($A$21:$A$141,">="&$G21,$A$21:$A$141,"<="&$H21)>0,_xlfn.MAXIFS(AX$21:AX$141,$A$21:$A$141,">="&$G21,$A$21:$A$141,"<="&$H21),AY21)) -> -203.84434 | BB21: =-Cost_k*$A21+Beta_q*(Declarations!$B$16*INDEX(BA$21:BA$141,MAX(1,MIN(121,$B21-ROUND(Declarations!$A$16/$D$18,0))))+Declarations!$B$17*INDEX(BA$21:BA$141,MAX(1,MIN(121,$B21-ROUND(Declarations!$A$17/$D$18,0))))+Declarations!$B$18*INDEX(BA$21:BA$141,MAX(1,MIN(121,$B21-ROUND(Declarations!$A$18/$D$18,0))))+Declarations!$B$19*INDEX(BA$21:BA$141,MAX(1,MIN(121,$B21-ROUND(Declarations!$A$19/$D$18,0))))+Declarations!$B$20*INDEX(BA$21:BA$141,MAX(1,MIN(121,$B21-ROUND(Declarations!$A$20/$D$18,0))))) -> -356.19776 | BC21: =INDEX(BB$21:BB$141,$I21+1)*(1-$J21)+INDEX(BB$21:BB$141,$I21+2)*$J21 -> -346.07244 | BD21: =INDEX(BB$21:BB$141,$K21+1)*(1-$L21)+INDEX(BB$21:BB$141,$K21+2)*$L21 -> -346.07244 | BE21: =$C21+$D21+MAX(BC21,BD21,IF(COUNTIFS($A$21:$A$141,">="&$G21,$A$21:$A$141,"<="&$H21)>0,_xlfn.MAXIFS(BB$21:BB$141,$A$21:$A$141,">="&$G21,$A$21:$A$141,"<="&$H21),BC21)) -> -214.07244 | BF21: =-Cost_k*$A21+Beta_q*(Declarations!$B$16*INDEX(BE$21:BE$141,MAX(1,MIN(121,$B21-ROUND(Declarations!$A$16/$D$18,0))))+Declarations!$B$17*INDEX(BE$21:BE$141,MAX(1,MIN(121,$B21-ROUND(Declarations!$A$17/$D$18,0))))+Declarations!$B$18*INDEX(BE$21:BE$141,MAX(1,MIN(121,$B21-ROUND(Declarations!$A$18/$D$18,0))))+Declarations!$B$19*INDEX(BE$21:BE$141,MAX(1,MIN(121,$B21-ROUND(Declarations!$A$19/$D$18,0))))+Declarations!$B$20*INDEX(BE$21:BE$141,MAX(1,MIN(121,$B21-ROUND(Declarations!$A$20/$D$18,0))))) -> -365.97493 | BG21: =INDEX(BF$21:BF$141,$I21+1)*(1-$J21)+INDEX(BF$21:BF$141,$I21+2)*$J21 -> -354.67259 | BH21: =INDEX(BF$21:BF$141,$K21+1)*(1-$L21)+INDEX(BF$21:BF$141,$K21+2)*$L21 -> -354.67259 | BI21: =$C21+$D21+MAX(BG21,BH21,IF(COUNTIFS($A$21:$A$141,">="&$G21,$A$21:$A$141,"<="&$H21)>0,_xlfn.MAXIFS(BF$21:BF$141,$A$21:$A$141,">="&$G21,$A$21:$A$141,"<="&$H21),BG21)) -> -222.67259 | BJ21: -222.67259 | BK21: =ABS(BI21-BJ21) -> 0
A22: =A21+$D$18 -> 40.25 | B22: 2 | C22: =-Short_p*MAX(Floor_c-A22,0) -> -23.6 | D22: =Cost_k*Alpha_keep*A22 -> 156.975 | E22: =MIN(Cap_h,MAX(0,$B$18+MAX(Loss_w)-Alpha_keep*A22)) -> 2.25625 | F22: =MAX(MIN(Cap_h,$F$18+MIN(Loss_w)-Alpha_keep*A22),E22) -> 2.5 | G22: =Alpha_keep*A22+E22 -> 41.5 | H22: =Alpha_keep*A22+F22 -> 41.74375 | I22: =MIN(INT((G22-$B$18)/$D$18+0.000000001),119) -> 6 | J22: =(G22-$B$18)/$D$18-I22 -> 0 | K22: =MIN(INT((H22-$B$18)/$D$18+0.000000001),119) -> 6 | L22: =(H22-$B$18)/$D$18-K22 -> 0.975 | M22: 0 | N22: =-Cost_k*$A22+Beta_q*(Declarations!$B$16*INDEX(M$21:M$141,MAX(1,MIN(121,$B22-ROUND(Declarations!$A$16/$D$18,0))))+Declarations!$B$17*INDEX(M$21:M$141,MAX(1,MIN(121,$B22-ROUND(Declarations!$A$17/$D$18,0))))+Declarations!$B$18*INDEX(M$21:M$141,MAX(1,MIN(121,$B22-ROUND(Declarations!$A$18/$D$18,0))))+Declarations!$B$19*INDEX(M$21:M$141,MAX(1,MIN(121,$B22-ROUND(Declarations!$A$19/$D$18,0))))+Declarations!$B$20*INDEX(M$21:M$141,MAX(1,MIN(121,$B22-ROUND(Declarations!$A$20/$D$18,0))))) -> -161 | O22: =INDEX(N$21:N$141,$I22+1)*(1-$J22)+INDEX(N$21:N$141,$I22+2)*$J22 -> -166 | P22: =INDEX(N$21:N$141,$K22+1)*(1-$L22)+INDEX(N$21:N$141,$K22+2)*$L22 -> -166.975 | Q22: =$C22+$D22+MAX(O22,P22,IF(COUNTIFS($A$21:$A$141,">="&$G22,$A$21:$A$141,"<="&$H22)>0,_xlfn.MAXIFS(N$21:N$141,$A$21:$A$141,">="&$G22,$A$21:$A$141,"<="&$H22),O22)) -> -32.625 | R22: =-Cost_k*$A22+Beta_q*(Declarations!$B$16*INDEX(Q$21:Q$141,MAX(1,MIN(121,$B22-ROUND(Declarations!$A$16/$D$18,0))))+Declarations!$B$17*INDEX(Q$21:Q$141,MAX(1,MIN(121,$B22-ROUND(Declarations!$A$17/$D$18,0))))+Declarations!$B$18*INDEX(Q$21:Q$141,MAX(1,MIN(121,$B22-ROUND(Declarations!$A$18/$D$18,0))))+Declarations!$B$19*INDEX(Q$21:Q$141,MAX(1,MIN(121,$B22-ROUND(Declarations!$A$19/$D$18,0))))+Declarations!$B$20*INDEX(Q$21:Q$141,MAX(1,MIN(121,$B22-ROUND(Declarations!$A$20/$D$18,0))))) -> -191.98411 | S22: =INDEX(R$21:R$141,$I22+1)*(1-$J22)+INDEX(R$21:R$141,$I22+2)*$J22 -> -191.22669 | T22: =INDEX(R$21:R$141,$K22+1)*(1-$L22)+INDEX(R$21:R$141,$K22+2)*$L22 -> -190.93904 | U22: =$C22+$D22+MAX(S22,T22,IF(COUNTIFS($A$21:$A$141,">="&$G22,$A$21:$A$141,"<="&$H22)>0,_xlfn.MAXIFS(R$21:R$141,$A$21:$A$141,">="&$G22,$A$21:$A$141,"<="&$H22),S22)) -> -57.564045 | V22: =-Cost_k*$A22+Beta_q*(Declarations!$B$16*INDEX(U$21:U$141,MAX(1,MIN(121,$B22-ROUND(Declarations!$A$16/$D$18,0))))+Declarations!$B$17*INDEX(U$21:U$141,MAX(1,MIN(121,$B22-ROUND(Declarations!$A$17/$D$18,0))))+Declarations!$B$18*INDEX(U$21:U$141,MAX(1,MIN(121,$B22-ROUND(Declarations!$A$18/$D$18,0))))+Declarations!$B$19*INDEX(U$21:U$141,MAX(1,MIN(121,$B22-ROUND(Declarations!$A$19/$D$18,0))))+Declarations!$B$20*INDEX(U$21:U$141,MAX(1,MIN(121,$B22-ROUND(Declarations!$A$20/$D$18,0))))) -> -216.31787 | W22: =INDEX(V$21:V$141,$I22+1)*(1-$J22)+INDEX(V$21:V$141,$I22+2)*$J22 -> -215.18827 | X22: =INDEX(V$21:V$141,$K22+1)*(1-$L22)+INDEX(V$21:V$141,$K22+2)*$L22 -> -214.8211 | Y22: =$C22+$D22+MAX(W22,X22,IF(COUNTIFS($A$21:$A$141,">="&$G22,$A$21:$A$141,"<="&$H22)>0,_xlfn.MAXIFS(V$21:V$141,$A$21:$A$141,">="&$G22,$A$21:$A$141,"<="&$H22),W22)) -> -81.446098 | Z22: =-Cost_k*$A22+Beta_q*(Declarations!$B$16*INDEX(Y$21:Y$141,MAX(1,MIN(121,$B22-ROUND(Declarations!$A$16/$D$18,0))))+Declarations!$B$17*INDEX(Y$21:Y$141,MAX(1,MIN(121,$B22-ROUND(Declarations!$A$17/$D$18,0))))+Declarations!$B$18*INDEX(Y$21:Y$141,MAX(1,MIN(121,$B22-ROUND(Declarations!$A$18/$D$18,0))))+Declarations!$B$19*INDEX(Y$21:Y$141,MAX(1,MIN(121,$B22-ROUND(Declarations!$A$19/$D$18,0))))+Declarations!$B$20*INDEX(Y$21:Y$141,MAX(1,MIN(121,$B22-ROUND(Declarations!$A$20/$D$18,0))))) -> -239.45906 | AA22: =INDEX(Z$21:Z$141,$I22+1)*(1-$J22)+INDEX(Z$21:Z$141,$I22+2)*$J22 -> -237.35706 | AB22: =INDEX(Z$21:Z$141,$K22+1)*(1-$L22)+INDEX(Z$21:Z$141,$K22+2)*$L22 -> -236.80811 | AC22: =$C22+$D22+MAX(AA22,AB22,IF(COUNTIFS($A$21:$A$141,">="&$G22,$A$21:$A$141,"<="&$H22)>0,_xlfn.MAXIFS(Z$21:Z$141,$A$21:$A$141,">="&$G22,$A$21:$A$141,"<="&$H22),AA22)) -> -103.43311 | AD22: =-Cost_k*$A22+Beta_q*(Declarations!$B$16*INDEX(AC$21:AC$141,MAX(1,MIN(121,$B22-ROUND(Declarations!$A$16/$D$18,0))))+Declarations!$B$17*INDEX(AC$21:AC$141,MAX(1,MIN(121,$B22-ROUND(Declarations!$A$17/$D$18,0))))+Declarations!$B$18*INDEX(AC$21:AC$141,MAX(1,MIN(121,$B22-ROUND(Declarations!$A$18/$D$18,0))))+Declarations!$B$19*INDEX(AC$21:AC$141,MAX(1,MIN(121,$B22-ROUND(Declarations!$A$19/$D$18,0))))+Declarations!$B$20*INDEX(AC$21:AC$141,MAX(1,MIN(121,$B22-ROUND(Declarations!$A$20/$D$18,0))))) -> -260.84571 | AE22: =INDEX(AD$21:AD$141,$I22+1)*(1-$J22)+INDEX(AD$21:AD$141,$I22+2)*$J22 -> -258.14726 | AF22: =INDEX(AD$21:AD$141,$K22+1)*(1-$L22)+INDEX(AD$21:AD$141,$K22+2)*$L22 -> -257.45025 | AG22: =$C22+$D22+MAX(AE22,AF22,IF(COUNTIFS($A$21:$A$141,">="&$G22,$A$21:$A$141,"<="&$H22)>0,_xlfn.MAXIFS(AD$21:AD$141,$A$21:$A$141,">="&$G22,$A$21:$A$141,"<="&$H22),AE22)) -> -124.07525 | AH22: =-Cost_k*$A22+Beta_q*(Declarations!$B$16*INDEX(AG$21:AG$141,MAX(1,MIN(121,$B22-ROUND(Declarations!$A$16/$D$18,0))))+Declarations!$B$17*INDEX(AG$21:AG$141,MAX(1,MIN(121,$B22-ROUND(Declarations!$A$17/$D$18,0))))+Declarations!$B$18*INDEX(AG$21:AG$141,MAX(1,MIN(121,$B22-ROUND(Declarations!$A$18/$D$18,0))))+Declarations!$B$19*INDEX(AG$21:AG$141,MAX(1,MIN(121,$B22-ROUND(Declarations!$A$19/$D$18,0))))+Declarations!$B$20*INDEX(AG$21:AG$141,MAX(1,MIN(121,$B22-ROUND(Declarations!$A$20/$D$18,0))))) -> -280.86333 | AI22: =INDEX(AH$21:AH$141,$I22+1)*(1-$J22)+INDEX(AH$21:AH$141,$I22+2)*$J22 -> -277.23377 | AJ22: =INDEX(AH$21:AH$141,$K22+1)*(1-$L22)+INDEX(AH$21:AH$141,$K22+2)*$L22 -> -276.29621 | AK22: =$C22+$D22+MAX(AI22,AJ22,IF(COUNTIFS($A$21:$A$141,">="&$G22,$A$21:$A$141,"<="&$H22)>0,_xlfn.MAXIFS(AH$21:AH$141,$A$21:$A$141,">="&$G22,$A$21:$A$141,"<="&$H22),AI22)) -> -142.92121 | AL22: =-Cost_k*$A22+Beta_q*(Declarations!$B$16*INDEX(AK$21:AK$141,MAX(1,MIN(121,$B22-ROUND(Declarations!$A$16/$D$18,0))))+Declarations!$B$17*INDEX(AK$21:AK$141,MAX(1,MIN(121,$B22-ROUND(Declarations!$A$17/$D$18,0))))+Declarations!$B$18*INDEX(AK$21:AK$141,MAX(1,MIN(121,$B22-ROUND(Declarations!$A$18/$D$18,0))))+Declarations!$B$19*INDEX(AK$21:AK$141,MAX(1,MIN(121,$B22-ROUND(Declarations!$A$19/$D$18,0))))+Declarations!$B$20*INDEX(AK$21:AK$141,MAX(1,MIN(121,$B22-ROUND(Declarations!$A$20/$D$18,0))))) -> -299.11454 | AM22: =INDEX(AL$21:AL$141,$I22+1)*(1-$J22)+INDEX(AL$21:AL$141,$I22+2)*$J22 -> -294.49319 | AN22: =INDEX(AL$21:AL$141,$K22+1)*(1-$L22)+INDEX(AL$21:AL$141,$K22+2)*$L22 -> -293.34105 | AO22: =$C22+$D22+MAX(AM22,AN22,IF(COUNTIFS($A$21:$A$141,">="&$G22,$A$21:$A$141,"<="&$H22)>0,_xlfn.MAXIFS(AL$21:AL$141,$A$21:$A$141,">="&$G22,$A$21:$A$141,"<="&$H22),AM22)) -> -159.96605 | AP22: =-Cost_k*$A22+Beta_q*(Declarations!$B$16*INDEX(AO$21:AO$141,MAX(1,MIN(121,$B22-ROUND(Declarations!$A$16/$D$18,0))))+Declarations!$B$17*INDEX(AO$21:AO$141,MAX(1,MIN(121,$B22-ROUND(Declarations!$A$17/$D$18,0))))+Declarations!$B$18*INDEX(AO$21:AO$141,MAX(1,MIN(121,$B22-ROUND(Declarations!$A$18/$D$18,0))))+Declarations!$B$19*INDEX(AO$21:AO$141,MAX(1,MIN(121,$B22-ROUND(Declarations!$A$19/$D$18,0))))+Declarations!$B$20*INDEX(AO$21:AO$141,MAX(1,MIN(121,$B22-ROUND(Declarations!$A$20/$D$18,0))))) -> -315.62139 | AQ22: =INDEX(AP$21:AP$141,$I22+1)*(1-$J22)+INDEX(AP$21:AP$141,$I22+2)*$J22 -> -310.06124 | AR22: =INDEX(AP$21:AP$141,$K22+1)*(1-$L22)+INDEX(AP$21:AP$141,$K22+2)*$L22 -> -308.68812 | AS22: =$C22+$D22+MAX(AQ22,AR22,IF(COUNTIFS($A$21:$A$141,">="&$G22,$A$21:$A$141,"<="&$H22)>0,_xlfn.MAXIFS(AP$21:AP$141,$A$21:$A$141,">="&$G22,$A$21:$A$141,"<="&$H22),AQ22)) -> -175.31312 | AT22: =-Cost_k*$A22+Beta_q*(Declarations!$B$16*INDEX(AS$21:AS$141,MAX(1,MIN(121,$B22-ROUND(Declarations!$A$16/$D$18,0))))+Declarations!$B$17*INDEX(AS$21:AS$141,MAX(1,MIN(121,$B22-ROUND(Declarations!$A$17/$D$18,0))))+Declarations!$B$18*INDEX(AS$21:AS$141,MAX(1,MIN(121,$B22-ROUND(Declarations!$A$18/$D$18,0))))+Declarations!$B$19*INDEX(AS$21:AS$141,MAX(1,MIN(121,$B22-ROUND(Declarations!$A$19/$D$18,0))))+Declarations!$B$20*INDEX(AS$21:AS$141,MAX(1,MIN(121,$B22-ROUND(Declarations!$A$20/$D$18,0))))) -> -330.45356 | AU22: =INDEX(AT$21:AT$141,$I22+1)*(1-$J22)+INDEX(AT$21:AT$141,$I22+2)*$J22 -> -323.8599 | AV22: =INDEX(AT$21:AT$141,$K22+1)*(1-$L22)+INDEX(AT$21:AT$141,$K22+2)*$L22 -> -322.24323 | AW22: =$C22+$D22+MAX(AU22,AV22,IF(COUNTIFS($A$21:$A$141,">="&$G22,$A$21:$A$141,"<="&$H22)>0,_xlfn.MAXIFS(AT$21:AT$141,$A$21:$A$141,">="&$G22,$A$21:$A$141,"<="&$H22),AU22)) -> -188.86823 | AX22: =-Cost_k*$A22+Beta_q*(Declarations!$B$16*INDEX(AW$21:AW$141,MAX(1,MIN(121,$B22-ROUND(Declarations!$A$16/$D$18,0))))+Declarations!$B$17*INDEX(AW$21:AW$141,MAX(1,MIN(121,$B22-ROUND(Declarations!$A$17/$D$18,0))))+Declarations!$B$18*INDEX(AW$21:AW$141,MAX(1,MIN(121,$B22-ROUND(Declarations!$A$18/$D$18,0))))+Declarations!$B$19*INDEX(AW$21:AW$141,MAX(1,MIN(121,$B22-ROUND(Declarations!$A$19/$D$18,0))))+Declarations!$B$20*INDEX(AW$21:AW$141,MAX(1,MIN(121,$B22-ROUND(Declarations!$A$20/$D$18,0))))) -> -343.52648 | AY22: =INDEX(AX$21:AX$141,$I22+1)*(1-$J22)+INDEX(AX$21:AX$141,$I22+2)*$J22 -> -335.84434 | AZ22: =INDEX(AX$21:AX$141,$K22+1)*(1-$L22)+INDEX(AX$21:AX$141,$K22+2)*$L22 -> -333.97881 | BA22: =$C22+$D22+MAX(AY22,AZ22,IF(COUNTIFS($A$21:$A$141,">="&$G22,$A$21:$A$141,"<="&$H22)>0,_xlfn.MAXIFS(AX$21:AX$141,$A$21:$A$141,">="&$G22,$A$21:$A$141,"<="&$H22),AY22)) -> -200.60381 | BB22: =-Cost_k*$A22+Beta_q*(Declarations!$B$16*INDEX(BA$21:BA$141,MAX(1,MIN(121,$B22-ROUND(Declarations!$A$16/$D$18,0))))+Declarations!$B$17*INDEX(BA$21:BA$141,MAX(1,MIN(121,$B22-ROUND(Declarations!$A$17/$D$18,0))))+Declarations!$B$18*INDEX(BA$21:BA$141,MAX(1,MIN(121,$B22-ROUND(Declarations!$A$18/$D$18,0))))+Declarations!$B$19*INDEX(BA$21:BA$141,MAX(1,MIN(121,$B22-ROUND(Declarations!$A$19/$D$18,0))))+Declarations!$B$20*INDEX(BA$21:BA$141,MAX(1,MIN(121,$B22-ROUND(Declarations!$A$20/$D$18,0))))) -> -354.82518 | BC22: =INDEX(BB$21:BB$141,$I22+1)*(1-$J22)+INDEX(BB$21:BB$141,$I22+2)*$J22 -> -346.07244 | BD22: =INDEX(BB$21:BB$141,$K22+1)*(1-$L22)+INDEX(BB$21:BB$141,$K22+2)*$L22 -> -343.96684 | BE22: =$C22+$D22+MAX(BC22,BD22,IF(COUNTIFS($A$21:$A$141,">="&$G22,$A$21:$A$141,"<="&$H22)>0,_xlfn.MAXIFS(BB$21:BB$141,$A$21:$A$141,">="&$G22,$A$21:$A$141,"<="&$H22),BC22)) -> -210.59184 | BF22: =-Cost_k*$A22+Beta_q*(Declarations!$B$16*INDEX(BE$21:BE$141,MAX(1,MIN(121,$B22-ROUND(Declarations!$A$16/$D$18,0))))+Declarations!$B$17*INDEX(BE$21:BE$141,MAX(1,MIN(121,$B22-ROUND(Declarations!$A$17/$D$18,0))))+Declarations!$B$18*INDEX(BE$21:BE$141,MAX(1,MIN(121,$B22-ROUND(Declarations!$A$18/$D$18,0))))+Declarations!$B$19*INDEX(BE$21:BE$141,MAX(1,MIN(121,$B22-ROUND(Declarations!$A$19/$D$18,0))))+Declarations!$B$20*INDEX(BE$21:BE$141,MAX(1,MIN(121,$B22-ROUND(Declarations!$A$20/$D$18,0))))) -> -364.4273 | BG22: =INDEX(BF$21:BF$141,$I22+1)*(1-$J22)+INDEX(BF$21:BF$141,$I22+2)*$J22 -> -354.67259 | BH22: =INDEX(BF$21:BF$141,$K22+1)*(1-$L22)+INDEX(BF$21:BF$141,$K22+2)*$L22 -> -352.34687 | BI22: =$C22+$D22+MAX(BG22,BH22,IF(COUNTIFS($A$21:$A$141,">="&$G22,$A$21:$A$141,"<="&$H22)>0,_xlfn.MAXIFS(BF$21:BF$141,$A$21:$A$141,">="&$G22,$A$21:$A$141,"<="&$H22),BG22)) -> -218.97187 | BJ22: -218.97187 | BK22: =ABS(BI22-BJ22) -> 0
A23: =A22+$D$18 -> 40.5 | B23: 3 | C23: =-Short_p*MAX(Floor_c-A23,0) -> -23.2 | D23: =Cost_k*Alpha_keep*A23 -> 157.95 | E23: =MIN(Cap_h,MAX(0,$B$18+MAX(Loss_w)-Alpha_keep*A23)) -> 2.0125 | F23: =MAX(MIN(Cap_h,$F$18+MIN(Loss_w)-Alpha_keep*A23),E23) -> 2.5 | G23: =Alpha_keep*A23+E23 -> 41.5 | H23: =Alpha_keep*A23+F23 -> 41.9875 | I23: =MIN(INT((G23-$B$18)/$D$18+0.000000001),119) -> 6 | J23: =(G23-$B$18)/$D$18-I23 -> 0 | K23: =MIN(INT((H23-$B$18)/$D$18+0.000000001),119) -> 7 | L23: =(H23-$B$18)/$D$18-K23 -> 0.95 | M23: 0 | N23: =-Cost_k*$A23+Beta_q*(Declarations!$B$16*INDEX(M$21:M$141,MAX(1,MIN(121,$B23-ROUND(Declarations!$A$16/$D$18,0))))+Declarations!$B$17*INDEX(M$21:M$141,MAX(1,MIN(121,$B23-ROUND(Declarations!$A$17/$D$18,0))))+Declarations!$B$18*INDEX(M$21:M$141,MAX(1,MIN(121,$B23-ROUND(Declarations!$A$18/$D$18,0))))+Declarations!$B$19*INDEX(M$21:M$141,MAX(1,MIN(121,$B23-ROUND(Declarations!$A$19/$D$18,0))))+Declarations!$B$20*INDEX(M$21:M$141,MAX(1,MIN(121,$B23-ROUND(Declarations!$A$20/$D$18,0))))) -> -162 | O23: =INDEX(N$21:N$141,$I23+1)*(1-$J23)+INDEX(N$21:N$141,$I23+2)*$J23 -> -166 | P23: =INDEX(N$21:N$141,$K23+1)*(1-$L23)+INDEX(N$21:N$141,$K23+2)*$L23 -> -167.95 | Q23: =$C23+$D23+MAX(O23,P23,IF(COUNTIFS($A$21:$A$141,">="&$G23,$A$21:$A$141,"<="&$H23)>0,_xlfn.MAXIFS(N$21:N$141,$A$21:$A$141,">="&$G23,$A$21:$A$141,"<="&$H23),O23)) -> -31.25 | R23: =-Cost_k*$A23+Beta_q*(Declarations!$B$16*INDEX(Q$21:Q$141,MAX(1,MIN(121,$B23-ROUND(Declarations!$A$16/$D$18,0))))+Declarations!$B$17*INDEX(Q$21:Q$141,MAX(1,MIN(121,$B23-ROUND(Declarations!$A$17/$D$18,0))))+Declarations!$B$18*INDEX(Q$21:Q$141,MAX(1,MIN(121,$B23-ROUND(Declarations!$A$18/$D$18,0))))+Declarations!$B$19*INDEX(Q$21:Q$141,MAX(1,MIN(121,$B23-ROUND(Declarations!$A$19/$D$18,0))))+Declarations!$B$20*INDEX(Q$21:Q$141,MAX(1,MIN(121,$B23-ROUND(Declarations!$A$20/$D$18,0))))) -> -191.97714 | S23: =INDEX(R$21:R$141,$I23+1)*(1-$J23)+INDEX(R$21:R$141,$I23+2)*$J23 -> -191.22669 | T23: =INDEX(R$21:R$141,$K23+1)*(1-$L23)+INDEX(R$21:R$141,$K23+2)*$L23 -> -190.7859 | U23: =$C23+$D23+MAX(S23,T23,IF(COUNTIFS($A$21:$A$141,">="&$G23,$A$21:$A$141,"<="&$H23)>0,_xlfn.MAXIFS(R$21:R$141,$A$21:$A$141,">="&$G23,$A$21:$A$141,"<="&$H23),S23)) -> -56.035905 | V23: =-Cost_k*$A23+Beta_q*(Declarations!$B$16*INDEX(U$21:U$141,MAX(1,MIN(121,$B23-ROUND(Declarations!$A$16/$D$18,0))))+Declarations!$B$17*INDEX(U$21:U$141,MAX(1,MIN(121,$B23-ROUND(Declarations!$A$17/$D$18,0))))+Declarations!$B$18*INDEX(U$21:U$141,MAX(1,MIN(121,$B23-ROUND(Declarations!$A$18/$D$18,0))))+Declarations!$B$19*INDEX(U$21:U$141,MAX(1,MIN(121,$B23-ROUND(Declarations!$A$19/$D$18,0))))+Declarations!$B$20*INDEX(U$21:U$141,MAX(1,MIN(121,$B23-ROUND(Declarations!$A$20/$D$18,0))))) -> -216.23409 | W23: =INDEX(V$21:V$141,$I23+1)*(1-$J23)+INDEX(V$21:V$141,$I23+2)*$J23 -> -215.18827 | X23: =INDEX(V$21:V$141,$K23+1)*(1-$L23)+INDEX(V$21:V$141,$K23+2)*$L23 -> -214.47715 | Y23: =$C23+$D23+MAX(W23,X23,IF(COUNTIFS($A$21:$A$141,">="&$G23,$A$21:$A$141,"<="&$H23)>0,_xlfn.MAXIFS(V$21:V$141,$A$21:$A$141,">="&$G23,$A$21:$A$141,"<="&$H23),W23)) -> -79.727147 | Z23: =-Cost_k*$A23+Beta_q*(Declarations!$B$16*INDEX(Y$21:Y$141,MAX(1,MIN(121,$B23-ROUND(Declarations!$A$16/$D$18,0))))+Declarations!$B$17*INDEX(Y$21:Y$141,MAX(1,MIN(121,$B23-ROUND(Declarations!$A$17/$D$18,0))))+Declarations!$B$18*INDEX(Y$21:Y$141,MAX(1,MIN(121,$B23-ROUND(Declarations!$A$18/$D$18,0))))+Declarations!$B$19*INDEX(Y$21:Y$141,MAX(1,MIN(121,$B23-ROUND(Declarations!$A$19/$D$18,0))))+Declarations!$B$20*INDEX(Y$21:Y$141,MAX(1,MIN(121,$B23-ROUND(Declarations!$A$20/$D$18,0))))) -> -239.2103 | AA23: =INDEX(Z$21:Z$141,$I23+1)*(1-$J23)+INDEX(Z$21:Z$141,$I23+2)*$J23 -> -237.35706 | AB23: =INDEX(Z$21:Z$141,$K23+1)*(1-$L23)+INDEX(Z$21:Z$141,$K23+2)*$L23 -> -236.27526 | AC23: =$C23+$D23+MAX(AA23,AB23,IF(COUNTIFS($A$21:$A$141,">="&$G23,$A$21:$A$141,"<="&$H23)>0,_xlfn.MAXIFS(Z$21:Z$141,$A$21:$A$141,">="&$G23,$A$21:$A$141,"<="&$H23),AA23)) -> -101.52526 | AD23: =-Cost_k*$A23+Beta_q*(Declarations!$B$16*INDEX(AC$21:AC$141,MAX(1,MIN(121,$B23-ROUND(Declarations!$A$16/$D$18,0))))+Declarations!$B$17*INDEX(AC$21:AC$141,MAX(1,MIN(121,$B23-ROUND(Declarations!$A$17/$D$18,0))))+Declarations!$B$18*INDEX(AC$21:AC$141,MAX(1,MIN(121,$B23-ROUND(Declarations!$A$18/$D$18,0))))+Declarations!$B$19*INDEX(AC$21:AC$141,MAX(1,MIN(121,$B23-ROUND(Declarations!$A$19/$D$18,0))))+Declarations!$B$20*INDEX(AC$21:AC$141,MAX(1,MIN(121,$B23-ROUND(Declarations!$A$20/$D$18,0))))) -> -260.48038 | AE23: =INDEX(AD$21:AD$141,$I23+1)*(1-$J23)+INDEX(AD$21:AD$141,$I23+2)*$J23 -> -258.14726 | AF23: =INDEX(AD$21:AD$141,$K23+1)*(1-$L23)+INDEX(AD$21:AD$141,$K23+2)*$L23 -> -256.76467 | AG23: =$C23+$D23+MAX(AE23,AF23,IF(COUNTIFS($A$21:$A$141,">="&$G23,$A$21:$A$141,"<="&$H23)>0,_xlfn.MAXIFS(AD$21:AD$141,$A$21:$A$141,">="&$G23,$A$21:$A$141,"<="&$H23),AE23)) -> -122.01467 | AH23: =-Cost_k*$A23+Beta_q*(Declarations!$B$16*INDEX(AG$21:AG$141,MAX(1,MIN(121,$B23-ROUND(Declarations!$A$16/$D$18,0))))+Declarations!$B$17*INDEX(AG$21:AG$141,MAX(1,MIN(121,$B23-ROUND(Declarations!$A$17/$D$18,0))))+Declarations!$B$18*INDEX(AG$21:AG$141,MAX(1,MIN(121,$B23-ROUND(Declarations!$A$18/$D$18,0))))+Declarations!$B$19*INDEX(AG$21:AG$141,MAX(1,MIN(121,$B23-ROUND(Declarations!$A$19/$D$18,0))))+Declarations!$B$20*INDEX(AG$21:AG$141,MAX(1,MIN(121,$B23-ROUND(Declarations!$A$20/$D$18,0))))) -> -280.36342 | AI23: =INDEX(AH$21:AH$141,$I23+1)*(1-$J23)+INDEX(AH$21:AH$141,$I23+2)*$J23 -> -277.23377 | AJ23: =INDEX(AH$21:AH$141,$K23+1)*(1-$L23)+INDEX(AH$21:AH$141,$K23+2)*$L23 -> -275.36959 | AK23: =$C23+$D23+MAX(AI23,AJ23,IF(COUNTIFS($A$21:$A$141,">="&$G23,$A$21:$A$141,"<="&$H23)>0,_xlfn.MAXIFS(AH$21:AH$141,$A$21:$A$141,">="&$G23,$A$21:$A$141,"<="&$H23),AI23)) -> -140.61959 | AL23: =-Cost_k*$A23+Beta_q*(Declarations!$B$16*INDEX(AK$21:AK$141,MAX(1,MIN(121,$B23-ROUND(Declarations!$A$16/$D$18,0))))+Declarations!$B$17*INDEX(AK$21:AK$141,MAX(1,MIN(121,$B23-ROUND(Declarations!$A$17/$D$18,0))))+Declarations!$B$18*INDEX(AK$21:AK$141,MAX(1,MIN(121,$B23-ROUND(Declarations!$A$18/$D$18,0))))+Declarations!$B$19*INDEX(AK$21:AK$141,MAX(1,MIN(121,$B23-ROUND(Declarations!$A$19/$D$18,0))))+Declarations!$B$20*INDEX(AK$21:AK$141,MAX(1,MIN(121,$B23-ROUND(Declarations!$A$20/$D$18,0))))) -> -298.44029 | AM23: =INDEX(AL$21:AL$141,$I23+1)*(1-$J23)+INDEX(AL$21:AL$141,$I23+2)*$J23 -> -294.49319 | AN23: =INDEX(AL$21:AL$141,$K23+1)*(1-$L23)+INDEX(AL$21:AL$141,$K23+2)*$L23 -> -292.20076 | AO23: =$C23+$D23+MAX(AM23,AN23,IF(COUNTIFS($A$21:$A$141,">="&$G23,$A$21:$A$141,"<="&$H23)>0,_xlfn.MAXIFS(AL$21:AL$141,$A$21:$A$141,">="&$G23,$A$21:$A$141,"<="&$H23),AM23)) -> -157.45076 | AP23: =-Cost_k*$A23+Beta_q*(Declarations!$B$16*INDEX(AO$21:AO$141,MAX(1,MIN(121,$B23-ROUND(Declarations!$A$16/$D$18,0))))+Declarations!$B$17*INDEX(AO$21:AO$141,MAX(1,MIN(121,$B23-ROUND(Declarations!$A$17/$D$18,0))))+Declarations!$B$18*INDEX(AO$21:AO$141,MAX(1,MIN(121,$B23-ROUND(Declarations!$A$18/$D$18,0))))+Declarations!$B$19*INDEX(AO$21:AO$141,MAX(1,MIN(121,$B23-ROUND(Declarations!$A$19/$D$18,0))))+Declarations!$B$20*INDEX(AO$21:AO$141,MAX(1,MIN(121,$B23-ROUND(Declarations!$A$20/$D$18,0))))) -> -314.78897 | AQ23: =INDEX(AP$21:AP$141,$I23+1)*(1-$J23)+INDEX(AP$21:AP$141,$I23+2)*$J23 -> -310.06124 | AR23: =INDEX(AP$21:AP$141,$K23+1)*(1-$L23)+INDEX(AP$21:AP$141,$K23+2)*$L23 -> -307.32158 | AS23: =$C23+$D23+MAX(AQ23,AR23,IF(COUNTIFS($A$21:$A$141,">="&$G23,$A$21:$A$141,"<="&$H23)>0,_xlfn.MAXIFS(AP$21:AP$141,$A$21:$A$141,">="&$G23,$A$21:$A$141,"<="&$H23),AQ23)) -> -172.57158 | AT23: =-Cost_k*$A23+Beta_q*(Declarations!$B$16*INDEX(AS$21:AS$141,MAX(1,MIN(121,$B23-ROUND(Declarations!$A$16/$D$18,0))))+Declarations!$B$17*INDEX(AS$21:AS$141,MAX(1,MIN(121,$B23-ROUND(Declarations!$A$17/$D$18,0))))+Declarations!$B$18*INDEX(AS$21:AS$141,MAX(1,MIN(121,$B23-ROUND(Declarations!$A$18/$D$18,0))))+Declarations!$B$19*INDEX(AS$21:AS$141,MAX(1,MIN(121,$B23-ROUND(Declarations!$A$19/$D$18,0))))+Declarations!$B$20*INDEX(AS$21:AS$141,MAX(1,MIN(121,$B23-ROUND(Declarations!$A$20/$D$18,0))))) -> -329.44993 | AU23: =INDEX(AT$21:AT$141,$I23+1)*(1-$J23)+INDEX(AT$21:AT$141,$I23+2)*$J23 -> -323.8599 | AV23: =INDEX(AT$21:AT$141,$K23+1)*(1-$L23)+INDEX(AT$21:AT$141,$K23+2)*$L23 -> -320.62889 | AW23: =$C23+$D23+MAX(AU23,AV23,IF(COUNTIFS($A$21:$A$141,">="&$G23,$A$21:$A$141,"<="&$H23)>0,_xlfn.MAXIFS(AT$21:AT$141,$A$21:$A$141,">="&$G23,$A$21:$A$141,"<="&$H23),AU23)) -> -185.87889 | AX23: =-Cost_k*$A23+Beta_q*(Declarations!$B$16*INDEX(AW$21:AW$141,MAX(1,MIN(121,$B23-ROUND(Declarations!$A$16/$D$18,0))))+Declarations!$B$17*INDEX(AW$21:AW$141,MAX(1,MIN(121,$B23-ROUND(Declarations!$A$17/$D$18,0))))+Declarations!$B$18*INDEX(AW$21:AW$141,MAX(1,MIN(121,$B23-ROUND(Declarations!$A$18/$D$18,0))))+Declarations!$B$19*INDEX(AW$21:AW$141,MAX(1,MIN(121,$B23-ROUND(Declarations!$A$19/$D$18,0))))+Declarations!$B$20*INDEX(AW$21:AW$141,MAX(1,MIN(121,$B23-ROUND(Declarations!$A$20/$D$18,0))))) -> -342.3385 | AY23: =INDEX(AX$21:AX$141,$I23+1)*(1-$J23)+INDEX(AX$21:AX$141,$I23+2)*$J23 -> -335.84434 | AZ23: =INDEX(AX$21:AX$141,$K23+1)*(1-$L23)+INDEX(AX$21:AX$141,$K23+2)*$L23 -> -332.11406 | BA23: =$C23+$D23+MAX(AY23,AZ23,IF(COUNTIFS($A$21:$A$141,">="&$G23,$A$21:$A$141,"<="&$H23)>0,_xlfn.MAXIFS(AX$21:AX$141,$A$21:$A$141,">="&$G23,$A$21:$A$141,"<="&$H23),AY23)) -> -197.36406 | BB23: =-Cost_k*$A23+Beta_q*(Declarations!$B$16*INDEX(BA$21:BA$141,MAX(1,MIN(121,$B23-ROUND(Declarations!$A$16/$D$18,0))))+Declarations!$B$17*INDEX(BA$21:BA$141,MAX(1,MIN(121,$B23-ROUND(Declarations!$A$17/$D$18,0))))+Declarations!$B$18*INDEX(BA$21:BA$141,MAX(1,MIN(121,$B23-ROUND(Declarations!$A$18/$D$18,0))))+Declarations!$B$19*INDEX(BA$21:BA$141,MAX(1,MIN(121,$B23-ROUND(Declarations!$A$19/$D$18,0))))+Declarations!$B$20*INDEX(BA$21:BA$141,MAX(1,MIN(121,$B23-ROUND(Declarations!$A$20/$D$18,0))))) -> -353.45316 | BC23: =INDEX(BB$21:BB$141,$I23+1)*(1-$J23)+INDEX(BB$21:BB$141,$I23+2)*$J23 -> -346.07244 | BD23: =INDEX(BB$21:BB$141,$K23+1)*(1-$L23)+INDEX(BB$21:BB$141,$K23+2)*$L23 -> -341.86235 | BE23: =$C23+$D23+MAX(BC23,BD23,IF(COUNTIFS($A$21:$A$141,">="&$G23,$A$21:$A$141,"<="&$H23)>0,_xlfn.MAXIFS(BB$21:BB$141,$A$21:$A$141,">="&$G23,$A$21:$A$141,"<="&$H23),BC23)) -> -207.11235 | BF23: =-Cost_k*$A23+Beta_q*(Declarations!$B$16*INDEX(BE$21:BE$141,MAX(1,MIN(121,$B23-ROUND(Declarations!$A$16/$D$18,0))))+Declarations!$B$17*INDEX(BE$21:BE$141,MAX(1,MIN(121,$B23-ROUND(Declarations!$A$17/$D$18,0))))+Declarations!$B$18*INDEX(BE$21:BE$141,MAX(1,MIN(121,$B23-ROUND(Declarations!$A$18/$D$18,0))))+Declarations!$B$19*INDEX(BE$21:BE$141,MAX(1,MIN(121,$B23-ROUND(Declarations!$A$19/$D$18,0))))+Declarations!$B$20*INDEX(BE$21:BE$141,MAX(1,MIN(121,$B23-ROUND(Declarations!$A$20/$D$18,0))))) -> -362.88076 | BG23: =INDEX(BF$21:BF$141,$I23+1)*(1-$J23)+INDEX(BF$21:BF$141,$I23+2)*$J23 -> -354.67259 | BH23: =INDEX(BF$21:BF$141,$K23+1)*(1-$L23)+INDEX(BF$21:BF$141,$K23+2)*$L23 -> -350.02455 | BI23: =$C23+$D23+MAX(BG23,BH23,IF(COUNTIFS($A$21:$A$141,">="&$G23,$A$21:$A$141,"<="&$H23)>0,_xlfn.MAXIFS(BF$21:BF$141,$A$21:$A$141,">="&$G23,$A$21:$A$141,"<="&$H23),BG23)) -> -215.27455 | BJ23: -215.27455 | BK23: =ABS(BI23-BJ23) -> 0
A24: =A23+$D$18 -> 40.75 | B24: 4 | C24: =-Short_p*MAX(Floor_c-A24,0) -> -22.8 | D24: =Cost_k*Alpha_keep*A24 -> 158.925 | E24: =MIN(Cap_h,MAX(0,$B$18+MAX(Loss_w)-Alpha_keep*A24)) -> 1.76875 | F24: =MAX(MIN(Cap_h,$F$18+MIN(Loss_w)-Alpha_keep*A24),E24) -> 2.5 | G24: =Alpha_keep*A24+E24 -> 41.5 | H24: =Alpha_keep*A24+F24 -> 42.23125 | I24: =MIN(INT((G24-$B$18)/$D$18+0.000000001),119) -> 6 | J24: =(G24-$B$18)/$D$18-I24 -> 0 | K24: =MIN(INT((H24-$B$18)/$D$18+0.000000001),119) -> 8 | L24: =(H24-$B$18)/$D$18-K24 -> 0.925 | M24: 0 | N24: =-Cost_k*$A24+Beta_q*(Declarations!$B$16*INDEX(M$21:M$141,MAX(1,MIN(121,$B24-ROUND(Declarations!$A$16/$D$18,0))))+Declarations!$B$17*INDEX(M$21:M$141,MAX(1,MIN(121,$B24-ROUND(Declarations!$A$17/$D$18,0))))+Declarations!$B$18*INDEX(M$21:M$141,MAX(1,MIN(121,$B24-ROUND(Declarations!$A$18/$D$18,0))))+Declarations!$B$19*INDEX(M$21:M$141,MAX(1,MIN(121,$B24-ROUND(Declarations!$A$19/$D$18,0))))+Declarations!$B$20*INDEX(M$21:M$141,MAX(1,MIN(121,$B24-ROUND(Declarations!$A$20/$D$18,0))))) -> -163 | O24: =INDEX(N$21:N$141,$I24+1)*(1-$J24)+INDEX(N$21:N$141,$I24+2)*$J24 -> -166 | P24: =INDEX(N$21:N$141,$K24+1)*(1-$L24)+INDEX(N$21:N$141,$K24+2)*$L24 -> -168.925 | Q24: =$C24+$D24+MAX(O24,P24,IF(COUNTIFS($A$21:$A$141,">="&$G24,$A$21:$A$141,"<="&$H24)>0,_xlfn.MAXIFS(N$21:N$141,$A$21:$A$141,">="&$G24,$A$21:$A$141,"<="&$H24),O24)) -> -29.875 | R24: =-Cost_k*$A24+Beta_q*(Declarations!$B$16*INDEX(Q$21:Q$141,MAX(1,MIN(121,$B24-ROUND(Declarations!$A$16/$D$18,0))))+Declarations!$B$17*INDEX(Q$21:Q$141,MAX(1,MIN(121,$B24-ROUND(Declarations!$A$17/$D$18,0))))+Declarations!$B$18*INDEX(Q$21:Q$141,MAX(1,MIN(121,$B24-ROUND(Declarations!$A$18/$D$18,0))))+Declarations!$B$19*INDEX(Q$21:Q$141,MAX(1,MIN(121,$B24-ROUND(Declarations!$A$19/$D$18,0))))+Declarations!$B$20*INDEX(Q$21:Q$141,MAX(1,MIN(121,$B24-ROUND(Declarations!$A$20/$D$18,0))))) -> -191.97017 | S24: =INDEX(R$21:R$141,$I24+1)*(1-$J24)+INDEX(R$21:R$141,$I24+2)*$J24 -> -191.22669 | T24: =INDEX(R$21:R$141,$K24+1)*(1-$L24)+INDEX(R$21:R$141,$K24+2)*$L24 -> -190.68147 | U24: =$C24+$D24+MAX(S24,T24,IF(COUNTIFS($A$21:$A$141,">="&$G24,$A$21:$A$141,"<="&$H24)>0,_xlfn.MAXIFS(R$21:R$141,$A$21:$A$141,">="&$G24,$A$21:$A$141,"<="&$H24),S24)) -> -54.556465 | V24: =-Cost_k*$A24+Beta_q*(Declarations!$B$16*INDEX(U$21:U$141,MAX(1,MIN(121,$B24-ROUND(Declarations!$A$16/$D$18,0))))+Declarations!$B$17*INDEX(U$21:U$141,MAX(1,MIN(121,$B24-ROUND(Declarations!$A$17/$D$18,0))))+Declarations!$B$18*INDEX(U$21:U$141,MAX(1,MIN(121,$B24-ROUND(Declarations!$A$18/$D$18,0))))+Declarations!$B$19*INDEX(U$21:U$141,MAX(1,MIN(121,$B24-ROUND(Declarations!$A$19/$D$18,0))))+Declarations!$B$20*INDEX(U$21:U$141,MAX(1,MIN(121,$B24-ROUND(Declarations!$A$20/$D$18,0))))) -> -216.17613 | W24: =INDEX(V$21:V$141,$I24+1)*(1-$J24)+INDEX(V$21:V$141,$I24+2)*$J24 -> -215.18827 | X24: =INDEX(V$21:V$141,$K24+1)*(1-$L24)+INDEX(V$21:V$141,$K24+2)*$L24 -> -214.14493 | Y24: =$C24+$D24+MAX(W24,X24,IF(COUNTIFS($A$21:$A$141,">="&$G24,$A$21:$A$141,"<="&$H24)>0,_xlfn.MAXIFS(V$21:V$141,$A$21:$A$141,">="&$G24,$A$21:$A$141,"<="&$H24),W24)) -> -78.019933 | Z24: =-Cost_k*$A24+Beta_q*(Declarations!$B$16*INDEX(Y$21:Y$141,MAX(1,MIN(121,$B24-ROUND(Declarations!$A$16/$D$18,0))))+Declarations!$B$17*INDEX(Y$21:Y$141,MAX(1,MIN(121,$B24-ROUND(Declarations!$A$17/$D$18,0))))+Declarations!$B$18*INDEX(Y$21:Y$141,MAX(1,MIN(121,$B24-ROUND(Declarations!$A$18/$D$18,0))))+Declarations!$B$19*INDEX(Y$21:Y$141,MAX(1,MIN(121,$B24-ROUND(Declarations!$A$19/$D$18,0))))+Declarations!$B$20*INDEX(Y$21:Y$141,MAX(1,MIN(121,$B24-ROUND(Declarations!$A$20/$D$18,0))))) -> -238.97675 | AA24: =INDEX(Z$21:Z$141,$I24+1)*(1-$J24)+INDEX(Z$21:Z$141,$I24+2)*$J24 -> -237.35706 | AB24: =INDEX(Z$21:Z$141,$K24+1)*(1-$L24)+INDEX(Z$21:Z$141,$K24+2)*$L24 -> -235.78685 | AC24: =$C24+$D24+MAX(AA24,AB24,IF(COUNTIFS($A$21:$A$141,">="&$G24,$A$21:$A$141,"<="&$H24)>0,_xlfn.MAXIFS(Z$21:Z$141,$A$21:$A$141,">="&$G24,$A$21:$A$141,"<="&$H24),AA24)) -> -99.661851 | AD24: =-Cost_k*$A24+Beta_q*(Declarations!$B$16*INDEX(AC$21:AC$141,MAX(1,MIN(121,$B24-ROUND(Declarations!$A$16/$D$18,0))))+Declarations!$B$17*INDEX(AC$21:AC$141,MAX(1,MIN(121,$B24-ROUND(Declarations!$A$17/$D$18,0))))+Declarations!$B$18*INDEX(AC$21:AC$141,MAX(1,MIN(121,$B24-ROUND(Declarations!$A$18/$D$18,0))))+Declarations!$B$19*INDEX(AC$21:AC$141,MAX(1,MIN(121,$B24-ROUND(Declarations!$A$19/$D$18,0))))+Declarations!$B$20*INDEX(AC$21:AC$141,MAX(1,MIN(121,$B24-ROUND(Declarations!$A$20/$D$18,0))))) -> -260.14247 | AE24: =INDEX(AD$21:AD$141,$I24+1)*(1-$J24)+INDEX(AD$21:AD$141,$I24+2)*$J24 -> -258.14726 | AF24: =INDEX(AD$21:AD$141,$K24+1)*(1-$L24)+INDEX(AD$21:AD$141,$K24+2)*$L24 -> -256.09133 | AG24: =$C24+$D24+MAX(AE24,AF24,IF(COUNTIFS($A$21:$A$141,">="&$G24,$A$21:$A$141,"<="&$H24)>0,_xlfn.MAXIFS(AD$21:AD$141,$A$21:$A$141,">="&$G24,$A$21:$A$141,"<="&$H24),AE24)) -> -119.96633 | AH24: =-Cost_k*$A24+Beta_q*(Declarations!$B$16*INDEX(AG$21:AG$141,MAX(1,MIN(121,$B24-ROUND(Declarations!$A$16/$D$18,0))))+Declarations!$B$17*INDEX(AG$21:AG$141,MAX(1,MIN(121,$B24-ROUND(Declarations!$A$17/$D$18,0))))+Declarations!$B$18*INDEX(AG$21:AG$141,MAX(1,MIN(121,$B24-ROUND(Declarations!$A$18/$D$18,0))))+Declarations!$B$19*INDEX(AG$21:AG$141,MAX(1,MIN(121,$B24-ROUND(Declarations!$A$19/$D$18,0))))+Declarations!$B$20*INDEX(AG$21:AG$141,MAX(1,MIN(121,$B24-ROUND(Declarations!$A$20/$D$18,0))))) -> -279.87167 | AI24: =INDEX(AH$21:AH$141,$I24+1)*(1-$J24)+INDEX(AH$21:AH$141,$I24+2)*$J24 -> -277.23377 | AJ24: =INDEX(AH$21:AH$141,$K24+1)*(1-$L24)+INDEX(AH$21:AH$141,$K24+2)*$L24 -> -274.45548 | AK24: =$C24+$D24+MAX(AI24,AJ24,IF(COUNTIFS($A$21:$A$141,">="&$G24,$A$21:$A$141,"<="&$H24)>0,_xlfn.MAXIFS(AH$21:AH$141,$A$21:$A$141,">="&$G24,$A$21:$A$141,"<="&$H24),AI24)) -> -138.33048 | AL24: =-Cost_k*$A24+Beta_q*(Declarations!$B$16*INDEX(AK$21:AK$141,MAX(1,MIN(121,$B24-ROUND(Declarations!$A$16/$D$18,0))))+Declarations!$B$17*INDEX(AK$21:AK$141,MAX(1,MIN(121,$B24-ROUND(Declarations!$A$17/$D$18,0))))+Declarations!$B$18*INDEX(AK$21:AK$141,MAX(1,MIN(121,$B24-ROUND(Declarations!$A$18/$D$18,0))))+Declarations!$B$19*INDEX(AK$21:AK$141,MAX(1,MIN(121,$B24-ROUND(Declarations!$A$19/$D$18,0))))+Declarations!$B$20*INDEX(AK$21:AK$141,MAX(1,MIN(121,$B24-ROUND(Declarations!$A$20/$D$18,0))))) -> -297.77599 | AM24: =INDEX(AL$21:AL$141,$I24+1)*(1-$J24)+INDEX(AL$21:AL$141,$I24+2)*$J24 -> -294.49319 | AN24: =INDEX(AL$21:AL$141,$K24+1)*(1-$L24)+INDEX(AL$21:AL$141,$K24+2)*$L24 -> -291.07318 | AO24: =$C24+$D24+MAX(AM24,AN24,IF(COUNTIFS($A$21:$A$141,">="&$G24,$A$21:$A$141,"<="&$H24)>0,_xlfn.MAXIFS(AL$21:AL$141,$A$21:$A$141,">="&$G24,$A$21:$A$141,"<="&$H24),AM24)) -> -154.94818 | AP24: =-Cost_k*$A24+Beta_q*(Declarations!$B$16*INDEX(AO$21:AO$141,MAX(1,MIN(121,$B24-ROUND(Declarations!$A$16/$D$18,0))))+Declarations!$B$17*INDEX(AO$21:AO$141,MAX(1,MIN(121,$B24-ROUND(Declarations!$A$17/$D$18,0))))+Declarations!$B$18*INDEX(AO$21:AO$141,MAX(1,MIN(121,$B24-ROUND(Declarations!$A$18/$D$18,0))))+Declarations!$B$19*INDEX(AO$21:AO$141,MAX(1,MIN(121,$B24-ROUND(Declarations!$A$19/$D$18,0))))+Declarations!$B$20*INDEX(AO$21:AO$141,MAX(1,MIN(121,$B24-ROUND(Declarations!$A$20/$D$18,0))))) -> -313.96493 | AQ24: =INDEX(AP$21:AP$141,$I24+1)*(1-$J24)+INDEX(AP$21:AP$141,$I24+2)*$J24 -> -310.06124 | AR24: =INDEX(AP$21:AP$141,$K24+1)*(1-$L24)+INDEX(AP$21:AP$141,$K24+2)*$L24 -> -305.96087 | AS24: =$C24+$D24+MAX(AQ24,AR24,IF(COUNTIFS($A$21:$A$141,">="&$G24,$A$21:$A$141,"<="&$H24)>0,_xlfn.MAXIFS(AP$21:AP$141,$A$21:$A$141,">="&$G24,$A$21:$A$141,"<="&$H24),AQ24)) -> -169.83587 | AT24: =-Cost_k*$A24+Beta_q*(Declarations!$B$16*INDEX(AS$21:AS$141,MAX(1,MIN(121,$B24-ROUND(Declarations!$A$16/$D$18,0))))+Declarations!$B$17*INDEX(AS$21:AS$141,MAX(1,MIN(121,$B24-ROUND(Declarations!$A$17/$D$18,0))))+Declarations!$B$18*INDEX(AS$21:AS$141,MAX(1,MIN(121,$B24-ROUND(Declarations!$A$18/$D$18,0))))+Declarations!$B$19*INDEX(AS$21:AS$141,MAX(1,MIN(121,$B24-ROUND(Declarations!$A$19/$D$18,0))))+Declarations!$B$20*INDEX(AS$21:AS$141,MAX(1,MIN(121,$B24-ROUND(Declarations!$A$20/$D$18,0))))) -> -328.4499 | AU24: =INDEX(AT$21:AT$141,$I24+1)*(1-$J24)+INDEX(AT$21:AT$141,$I24+2)*$J24 -> -323.8599 | AV24: =INDEX(AT$21:AT$141,$K24+1)*(1-$L24)+INDEX(AT$21:AT$141,$K24+2)*$L24 -> -319.01641 | AW24: =$C24+$D24+MAX(AU24,AV24,IF(COUNTIFS($A$21:$A$141,">="&$G24,$A$21:$A$141,"<="&$H24)>0,_xlfn.MAXIFS(AT$21:AT$141,$A$21:$A$141,">="&$G24,$A$21:$A$141,"<="&$H24),AU24)) -> -182.89141 | AX24: =-Cost_k*$A24+Beta_q*(Declarations!$B$16*INDEX(AW$21:AW$141,MAX(1,MIN(121,$B24-ROUND(Declarations!$A$16/$D$18,0))))+Declarations!$B$17*INDEX(AW$21:AW$141,MAX(1,MIN(121,$B24-ROUND(Declarations!$A$17/$D$18,0))))+Declarations!$B$18*INDEX(AW$21:AW$141,MAX(1,MIN(121,$B24-ROUND(Declarations!$A$18/$D$18,0))))+Declarations!$B$19*INDEX(AW$21:AW$141,MAX(1,MIN(121,$B24-ROUND(Declarations!$A$19/$D$18,0))))+Declarations!$B$20*INDEX(AW$21:AW$141,MAX(1,MIN(121,$B24-ROUND(Declarations!$A$20/$D$18,0))))) -> -341.15163 | AY24: =INDEX(AX$21:AX$141,$I24+1)*(1-$J24)+INDEX(AX$21:AX$141,$I24+2)*$J24 -> -335.84434 | AZ24: =INDEX(AX$21:AX$141,$K24+1)*(1-$L24)+INDEX(AX$21:AX$141,$K24+2)*$L24 -> -330.24994 | BA24: =$C24+$D24+MAX(AY24,AZ24,IF(COUNTIFS($A$21:$A$141,">="&$G24,$A$21:$A$141,"<="&$H24)>0,_xlfn.MAXIFS(AX$21:AX$141,$A$21:$A$141,">="&$G24,$A$21:$A$141,"<="&$H24),AY24)) -> -194.12494 | BB24: =-Cost_k*$A24+Beta_q*(Declarations!$B$16*INDEX(BA$21:BA$141,MAX(1,MIN(121,$B24-ROUND(Declarations!$A$16/$D$18,0))))+Declarations!$B$17*INDEX(BA$21:BA$141,MAX(1,MIN(121,$B24-ROUND(Declarations!$A$17/$D$18,0))))+Declarations!$B$18*INDEX(BA$21:BA$141,MAX(1,MIN(121,$B24-ROUND(Declarations!$A$18/$D$18,0))))+Declarations!$B$19*INDEX(BA$21:BA$141,MAX(1,MIN(121,$B24-ROUND(Declarations!$A$19/$D$18,0))))+Declarations!$B$20*INDEX(BA$21:BA$141,MAX(1,MIN(121,$B24-ROUND(Declarations!$A$20/$D$18,0))))) -> -352.08165 | BC24: =INDEX(BB$21:BB$141,$I24+1)*(1-$J24)+INDEX(BB$21:BB$141,$I24+2)*$J24 -> -346.07244 | BD24: =INDEX(BB$21:BB$141,$K24+1)*(1-$L24)+INDEX(BB$21:BB$141,$K24+2)*$L24 -> -339.7593 | BE24: =$C24+$D24+MAX(BC24,BD24,IF(COUNTIFS($A$21:$A$141,">="&$G24,$A$21:$A$141,"<="&$H24)>0,_xlfn.MAXIFS(BB$21:BB$141,$A$21:$A$141,">="&$G24,$A$21:$A$141,"<="&$H24),BC24)) -> -203.6343 | BF24: =-Cost_k*$A24+Beta_q*(Declarations!$B$16*INDEX(BE$21:BE$141,MAX(1,MIN(121,$B24-ROUND(Declarations!$A$16/$D$18,0))))+Declarations!$B$17*INDEX(BE$21:BE$141,MAX(1,MIN(121,$B24-ROUND(Declarations!$A$17/$D$18,0))))+Declarations!$B$18*INDEX(BE$21:BE$141,MAX(1,MIN(121,$B24-ROUND(Declarations!$A$18/$D$18,0))))+Declarations!$B$19*INDEX(BE$21:BE$141,MAX(1,MIN(121,$B24-ROUND(Declarations!$A$19/$D$18,0))))+Declarations!$B$20*INDEX(BE$21:BE$141,MAX(1,MIN(121,$B24-ROUND(Declarations!$A$20/$D$18,0))))) -> -361.33563 | BG24: =INDEX(BF$21:BF$141,$I24+1)*(1-$J24)+INDEX(BF$21:BF$141,$I24+2)*$J24 -> -354.67259 | BH24: =INDEX(BF$21:BF$141,$K24+1)*(1-$L24)+INDEX(BF$21:BF$141,$K24+2)*$L24 -> -347.70654 | BI24: =$C24+$D24+MAX(BG24,BH24,IF(COUNTIFS($A$21:$A$141,">="&$G24,$A$21:$A$141,"<="&$H24)>0,_xlfn.MAXIFS(BF$21:BF$141,$A$21:$A$141,">="&$G24,$A$21:$A$141,"<="&$H24),BG24)) -> -211.58154 | BJ24: -211.58154 | BK24: =ABS(BI24-BJ24) -> 0
