Workbook

Sheet README
B1: DCT Laboratory — Vol II, Ch 8: Hamilton–Jacobi–Bellman Enterprise Framework
B2: Seed 26208 · Companion to DCT_V2_Ch08_Lab.ipynb and AXIOM Lab 2.8 (module AXIOM-08). Money in $ million.
B4: Worked Example 8.1, How Fast Should Meridian Close Its Engineering Gap?, with the book's declarations, and Chapter 6's capability problem solved with the HJB equation (Sections 8.2, 8.4 and 8.6). Nothing in the chapter is random.
B5: Declarations: the hiring loop of Step 1 and Chapter 6's capability declarations.
B6: Riccati: the quadratic value, its two roots, the rule and the price of an engineer of gap (Step 2; Theorem 8.3), and Theorem 8.2(iii)'s residual audit of other candidates.
B7: Hamiltonian: approvals where the marginal premium equals the value of an approval, at three gaps (Proposition 8.1(ii)).
B8: PolicyIteration: Kleinman's iteration from Volume I's cautious gain (Theorem 8.3(iii)); the costs of proportional rules if approvals landed at once.
B9: Delay: the predicted gap and the best rule with the quarter's delay (Step 3; Proposition 8.3(ii)), and the least cost against the months approvals take to land (Figure 8.3(b)).
B10: Rules: Table 8.3. The costs, surpluses and gaps of rules run with the delay need a simulation and come from the engine; gains, extra costs and the at-once column are formulas.
B11: CriticalGain: the gain above which a rule on today's gap swings ever wider, by bisection.
B12: Sensitivities: Step 5, the gain through q/r, a misdeclared delay, and productivity of 30 percent.
B13: Capability: Chapter 6's value and prices in closed form, the never-start threshold, the corners, the HJB equation at 58, and the costate against the value's slope along the best plans.
... B21: Cross-sheet link: green.

Sheet Declarations
A1: Declarations (Worked Example 8.1, Step 1; Chapter 6's capability problem). Money in $ million; time in years.
A3: Quantity | B3: Value | C3: Source
A4: Share of a gap carried over a quarter | B4: 0.9 | C4: Retraining and internal moves close 10 percent of any gap each quarter (Volume I, Worked Example 7.1)
A5: a: the gap closes on its own, a year | B5: =-4*LN(B4) -> 0.42144206 | C5: a = 4 ln(10/9) = 0.42
A6: b: share of approvals that become engineers | B6: 0.6 | C6: 60 percent of approved external hires become productive engineers
A7: tau: approvals become engineers after (years) | B7: 0.25 | C7: A quarter
A8: Cost of a gap of 100 engineers, a year | B8: 32 | C8: Program office: as much as stopping the build (a quarter of delay is worth $8 million, Volume I, Chapter 15)
A9: q = that cost / 100^2 | B9: =B8/100^2 -> 0.0032 | C9: A gap of d engineers costs q d^2 a year
A10: Premium for approving 400 a year, a year | B10: 20 | C10: Human resources: agency fees and signing bonuses beyond planned salaries
A11: r = that premium / 400^2 | B11: =B10/400^2 -> 0.000125 | C11: Approving v a year costs r v^2 a year
A12: Hurdle rate a year | B12: 0.1 | C12: The board's 10 percent (Chapter 5)
A13: rho = ln(1 + hurdle rate) | B13: =LN(1+B12) -> 0.09531018 | C13: 9.5 percent in continuous time
A14: Gap today: bench minus target (engineers) | B14: -100 | C14: 100 short, nothing in the pipeline
A15: Volume I's cautious gain, a quarter | B15: 0.5 | C15: Approve half the gap each quarter
A16: Volume I's deadbeat gain, a quarter | B16: 1.5 | C16: One and a half times the gap each quarter
A17: Cautious gain as a rate a year | B17: =4*B15 -> 2 | C17: Rules run continuously: v = -k d
A18: Deadbeat gain as a rate a year | B18: =4*B16 -> 6
A19: q / r | B19: =B9/B11 -> 25.6 | C19: The gain depends on the two costs only through their ratio
A20: Premium per hire at 400 a year | B20: =B11*400 -> 0.05 | C20: $50,000 a hire; at 100 a year, $12,500
A22: Chapter 6's capability problem (Worked Example 6.1)
A23: Attrition a quarter | B23: 0.025 | C23: 2.5 percent a quarter (Volume I, Chapter 10)
A24: delta = -4 ln(1 - attrition), a year | B24: =-4*LN(1-B23) -> 0.10127123 | C24: 0.101 a year
A25: Hiring cap a quarter (points) | B25: 2.5
A26: Volume I's ceiling = cap / attrition | B26: =B25/B23 -> 100 | C26: 100
A27: Hiring cap a year, u bar = ceiling x delta | B27: =B26*B24 -> 10.127123 | C27: 10.13 points a year
A28: Cost of hiring and training a point, k | B28: 4 | C28: $4 million a point
A29: Capability floor of the digital build | B29: 55 | C29: The build runs from the first moment capability reaches 55, which it must then keep
A30: Delay while the build waits, a year | B30: 32 | C30: $32 million a year
A32: Hiring loop: d'(t) = -a d(t) + b v(t - tau); cost of a rule = PV of q d^2 + r v^2 at rho over an open horizon. Capability: dc/dt = u - delta c, 0 <= u <= u bar, cost k u plus the delay below the floor.

Sheet Riccati
A1: Assemble the equation: a quadratic value -p d^2 and its two roots (Theorem 8.3; Worked Example 8.1, Step 2; AXIOM Lab 2.8, step 1)
A3: Quantity | B3: Value | C3: Reading
A4: Coefficient b^2 / r | B4: =B_share^2/R_prem -> 2880 | C4: (b^2/r) p^2 + (2a + rho) p - q = 0
A5: Coefficient 2a + rho | B5: =2*A_close+Rho_a -> 0.93819431
A6: Constant -q | B6: =-Q_gap -> -0.0032
A7: Positive root p | B7: =(-(B5)+SQRT((B5)^2+4*(B4)*(Q_gap)))/(2*(B4)) -> 0.00090372174 | C7: The value is -p d^2
A8: Second root p- | B8: =(-B5-SQRT(B5^2+4*B4*Q_gap))/(2*B4) -> -0.0012294837 | C8: Also solves the equation
A9: Gain K = b p / r, a year | B9: =B_share*B7/R_prem -> 4.3378644 | C9: The best rule v = -K d
A10: Gain a quarter | B10: =B9/4 -> 1.0844661 | C10: Between Volume I's cautious (0.5) and deadbeat (1.5) gains
A11: The gap closes at a + bK, a year | B11: =A_close+B_share*B9 -> 3.0241607
A12: Half-life of the gap (years) | B12: =LN(2)/B11 -> 0.22920316
A13: Half-life of the gap (months) | B13: =12*B12 -> 2.7504379 | C13: 2.75 months
A14: Least cost from 100 short, p d0^2 | B14: =B7*D0_gap^2 -> 9.0372174 | C14: $9.04 million
A15: Price of an engineer of gap at 100 short, 2p|d0| | B15: =2*B7*ABS(D0_gap) -> 0.18074435 | C15: $181,000
A16: First approval rate, K|d0| (a year) | B16: =B9*ABS(D0_gap) -> 433.78644
A17: Marginal premium on the last approval, 2 r v | B17: =2*R_prem*B16 -> 0.10844661 | C17: $108,000
A18: Value of an approval, b x price | B18: =B_share*B15 -> 0.10844661 | C18: Equal: Proposition 8.1(ii)
A19: Second root's gain, b p- / r | B19: =B_share*B8/R_prem -> -5.9015215 | C19: Its rule is v = -K- d
A20: It releases at 100 short (a year) | B20: =-B19*ABS(D0_gap) -> 590.15215 | C20: Releases engineers while the bench is short
A21: Its closed loop grows at -a - b K-, a year | B21: =-A_close-B_share*B19 -> 3.1194709 | C21: e^(-rho t) W(d(t)) does not tend to zero: Theorem 8.2(ii) certifies nothing
A22: Effective horizon 1/rho (years) | B22: =1/Rho_a -> 10.492059 | C22: Theorem 8.2(iii)
A23: A residual of $0.1 million a year puts the values within | B23: =0.1/Rho_a -> 1.0492059 | C23: $1.05 million
A25: Theorem 8.2(iii) audit of candidate values -p d^2 on the gaps from 100 short to 100 over
A26: Candidate p | B26: Riccati quadratic at p | C26: Residual at 100 short, eps | D26: Bound eps/rho | E26: Value off by |p - p*| d0^2 | F26: Greedy gain b p / r | G26: Its cost from 100 short | H26: Loss against the best | I26: Bound 2 eps/rho
A27: 0.0005 | B27: =$B$4*A27^2+$B$5*A27+$B$6 -> -0.0020109028 | C27: =D0_gap^2*ABS(B27) -> 20.109028 | D27: =C27/Rho_a -> 210.98511 | E27: =ABS(A27-$B$7)*D0_gap^2 -> 4.0372174 | F27: =B_share*A27/R_prem -> 2.4 | G27: =(Q_gap+R_prem*F27^2)*D0_gap^2/(2*(A_close+B_share*F27)+Rho_a) -> 10.266633 | H27: =G27-$B$14 -> 1.2294157 | I27: =2*C27/Rho_a -> 421.97021
A28: 0.0008 | B28: =$B$4*A28^2+$B$5*A28+$B$6 -> -0.00060624456 | C28: =D0_gap^2*ABS(B28) -> 6.0624456 | D28: =C28/Rho_a -> 63.607535 | E28: =ABS(A28-$B$7)*D0_gap^2 -> 1.0372174 | F28: =B_share*A28/R_prem -> 3.84 | G28: =(Q_gap+R_prem*F28^2)*D0_gap^2/(2*(A_close+B_share*F28)+Rho_a) -> 9.0930821 | H28: =G28-$B$14 -> 0.055864642 | I28: =2*C28/Rho_a -> 127.21507
A29: 0.0009 | B29: =$B$4*A29^2+$B$5*A29+$B$6 -> -2.2825125e-05 | C29: =D0_gap^2*ABS(B29) -> 0.22825125 | D29: =C29/Rho_a -> 2.3948256 | E29: =ABS(A29-$B$7)*D0_gap^2 -> 0.037217429 | F29: =B_share*A29/R_prem -> 4.32 | G29: =(Q_gap+R_prem*F29^2)*D0_gap^2/(2*(A_close+B_share*F29)+Rho_a) -> 9.0372826 | H29: =G29-$B$14 -> 6.5159558e-05 | I29: =2*C29/Rho_a -> 4.7896511
A30: =B7 -> 0.00090372174 | B30: =$B$4*A30^2+$B$5*A30+$B$6 -> 0 | C30: =D0_gap^2*ABS(B30) -> 0 | D30: =C30/Rho_a -> 0 | E30: =ABS(A30-$B$7)*D0_gap^2 -> 0 | F30: =B_share*A30/R_prem -> 4.3378644 | G30: =(Q_gap+R_prem*F30^2)*D0_gap^2/(2*(A_close+B_share*F30)+Rho_a) -> 9.0372174 | H30: =G30-$B$14 -> 0 | I30: =2*C30/Rho_a -> 0
A31: 0.001 | B31: =$B$4*A31^2+$B$5*A31+$B$6 -> 0.00061819431 | C31: =D0_gap^2*ABS(B31) -> 6.1819431 | D31: =C31/Rho_a -> 64.861309 | E31: =ABS(A31-$B$7)*D0_gap^2 -> 0.96278257 | F31: =B_share*A31/R_prem -> 4.8 | G31: =(Q_gap+R_prem*F31^2)*D0_gap^2/(2*(A_close+B_share*F31)+Rho_a) -> 9.0770732 | H31: =G31-$B$14 -> 0.039855768 | I31: =2*C31/Rho_a -> 129.72262
A32: 0.0012 | B32: =$B$4*A32^2+$B$5*A32+$B$6 -> 0.0020730332 | C32: =D0_gap^2*ABS(B32) -> 20.730332 | D32: =C32/Rho_a -> 217.50386 | E32: =ABS(A32-$B$7)*D0_gap^2 -> 2.9627826 | F32: =B_share*A32/R_prem -> 5.76 | G32: =(Q_gap+R_prem*F32^2)*D0_gap^2/(2*(A_close+B_share*F32)+Rho_a) -> 9.3592588 | H32: =G32-$B$14 -> 0.32204135 | I32: =2*C32/Rho_a -> 435.00771
A34: The residual of -p d^2 at the gap d is -d^2 times the Riccati quadratic: it vanishes everywhere at the two roots. The value's error and the greedy rule's loss stay within the bounds.

Sheet Hamiltonian
A1: Read the Hamiltonian: approve until the marginal premium equals the value of an approval (Proposition 8.1(ii); AXIOM Lab 2.8, step 2)
A2: At the gap d, the part of the Hamiltonian the approval rate moves is -r v^2 + b V'(d) v, with V'(d) = -2 p d, the price of an engineer of gap.
A4: Gap d | B4: -100 | C4: -50 | D4: -25
A5: Price of an engineer of gap, V'(d) = -2 p d | B5: =-2*Riccati!$B$7*B4 -> 0.18074435 | C5: =-2*Riccati!$B$7*C4 -> 0.090372174 | D5: =-2*Riccati!$B$7*D4 -> 0.045186087
A6: Best approval rate, b V'(d) / (2r) | B6: =B_share*B5/(2*R_prem) -> 433.78644 | C6: =B_share*C5/(2*R_prem) -> 216.89322 | D6: =B_share*D5/(2*R_prem) -> 108.44661
A7: Marginal premium at it, 2 r v | B7: =2*R_prem*B6 -> 0.10844661 | C7: =2*R_prem*C6 -> 0.054223305 | D7: =2*R_prem*D6 -> 0.027111652
A8: Value of an approval, b V'(d) | B8: =B_share*B5 -> 0.10844661 | C8: =B_share*C5 -> 0.054223305 | D8: =B_share*D5 -> 0.027111652
A10: Approval rate v (a year) | B10: -r v^2 + b V'(d) v at gap 1 | C10: at gap 2 | D10: at gap 3
A11: 0 | B11: =-R_prem*$A11^2+B$8*$A11 -> 0 | C11: =-R_prem*$A11^2+C$8*$A11 -> 0 | D11: =-R_prem*$A11^2+D$8*$A11 -> 0
A12: 10 | B12: =-R_prem*$A12^2+B$8*$A12 -> 1.0719661 | C12: =-R_prem*$A12^2+C$8*$A12 -> 0.52973305 | D12: =-R_prem*$A12^2+D$8*$A12 -> 0.25861652
A13: 20 | B13: =-R_prem*$A13^2+B$8*$A13 -> 2.1189322 | C13: =-R_prem*$A13^2+C$8*$A13 -> 1.0344661 | D13: =-R_prem*$A13^2+D$8*$A13 -> 0.49223305
A14: 30 | B14: =-R_prem*$A14^2+B$8*$A14 -> 3.1408983 | C14: =-R_prem*$A14^2+C$8*$A14 -> 1.5141991 | D14: =-R_prem*$A14^2+D$8*$A14 -> 0.70084957
A15: 40 | B15: =-R_prem*$A15^2+B$8*$A15 -> 4.1378644 | C15: =-R_prem*$A15^2+C$8*$A15 -> 1.9689322 | D15: =-R_prem*$A15^2+D$8*$A15 -> 0.88446609
A16: 50 | B16: =-R_prem*$A16^2+B$8*$A16 -> 5.1098305 | C16: =-R_prem*$A16^2+C$8*$A16 -> 2.3986652 | D16: =-R_prem*$A16^2+D$8*$A16 -> 1.0430826
A17: 60 | B17: =-R_prem*$A17^2+B$8*$A17 -> 6.0567965 | C17: =-R_prem*$A17^2+C$8*$A17 -> 2.8033983 | D17: =-R_prem*$A17^2+D$8*$A17 -> 1.1766991
A18: 70 | B18: =-R_prem*$A18^2+B$8*$A18 -> 6.9787626 | C18: =-R_prem*$A18^2+C$8*$A18 -> 3.1831313 | D18: =-R_prem*$A18^2+D$8*$A18 -> 1.2853157
A19: 80 | B19: =-R_prem*$A19^2+B$8*$A19 -> 7.8757287 | C19: =-R_prem*$A19^2+C$8*$A19 -> 3.5378644 | D19: =-R_prem*$A19^2+D$8*$A19 -> 1.3689322
A20: 90 | B20: =-R_prem*$A20^2+B$8*$A20 -> 8.7476948 | C20: =-R_prem*$A20^2+C$8*$A20 -> 3.8675974 | D20: =-R_prem*$A20^2+D$8*$A20 -> 1.4275487
A21: 100 | B21: =-R_prem*$A21^2+B$8*$A21 -> 9.5946609 | C21: =-R_prem*$A21^2+C$8*$A21 -> 4.1723305 | D21: =-R_prem*$A21^2+D$8*$A21 -> 1.4611652
A22: 110 | B22: =-R_prem*$A22^2+B$8*$A22 -> 10.416627 | C22: =-R_prem*$A22^2+C$8*$A22 -> 4.4520635 | D22: =-R_prem*$A22^2+D$8*$A22 -> 1.4697818
... A61: 500 | B61: =-R_prem*$A61^2+B$8*$A61 -> 22.973305 | C61: =-R_prem*$A61^2+C$8*$A61 -> -4.1383477 | D61: =-R_prem*$A61^2+D$8*$A61 -> -17.694174
A63: Best rate on this grid of 10 | B63: =INDEX($A$11:$A$61,MATCH(MAX(B11:B61),B11:B61,0)) -> 430 | C63: =INDEX($A$11:$A$61,MATCH(MAX(C11:C61),C11:C61,0)) -> 220 | D63: =INDEX($A$11:$A$61,MATCH(MAX(D11:D61),D11:D61,0)) -> 110

Sheet PolicyIteration
A1: Find the gain by policy iteration from Volume I's cautious gain (Theorem 8.3(iii); Section 8.6)
A2: Evaluate the rule v = -k d: its cost is p_k d^2 with p_k = (q + r k^2)/(2(a + b k) + rho). Make it greedy for that cost: k <- b p_k / r. Kleinman: Newton's method on the Riccati equation.
A4: Step | B4: Gain k a year | C4: p_k | D4: Cost from 100 short | E4: Above the best | F4: Discounted gap dies out at (a year)
A5: 0 | B5: =K_caut -> 2 | C5: =(Q_gap+R_prem*B5^2)/(2*(A_close+B_share*B5)+Rho_a) -> 0.0011083837 | D5: =C5*D0_gap^2 -> 11.083837 | E5: =D5-Riccati!$B$14 -> 2.0466191 | F5: =A_close+B_share*B5+Rho_a/2 -> 1.6690972
A6: 1 | B6: =B_share*C5/R_prem -> 5.3202415 | C6: =(Q_gap+R_prem*B6^2)/(2*(A_close+B_share*B6)+Rho_a) -> 0.00092019609 | D6: =C6*D0_gap^2 -> 9.2019609 | E6: =D6-Riccati!$B$14 -> 0.16474343 | F6: =A_close+B_share*B6+Rho_a/2 -> 3.6612421
A7: 2 | B7: =B_share*C6/R_prem -> 4.4169412 | C7: =(Q_gap+R_prem*B7^2)/(2*(A_close+B_share*B7)+Rho_a) -> 0.00090384704 | D7: =C7*D0_gap^2 -> 9.0384704 | E7: =D7-Riccati!$B$14 -> 0.0012529301 | F7: =A_close+B_share*B7+Rho_a/2 -> 3.1192619
A8: 3 | B8: =B_share*C7/R_prem -> 4.3384658 | C8: =(Q_gap+R_prem*B8^2)/(2*(A_close+B_share*B8)+Rho_a) -> 0.00090372175 | D8: =C8*D0_gap^2 -> 9.0372175 | E8: =D8-Riccati!$B$14 -> 7.3581731e-08 | F8: =A_close+B_share*B8+Rho_a/2 -> 3.0721766
A9: 4 | B9: =B_share*C8/R_prem -> 4.3378644 | C9: =(Q_gap+R_prem*B9^2)/(2*(A_close+B_share*B9)+Rho_a) -> 0.00090372174 | D9: =C9*D0_gap^2 -> 9.0372174 | E9: =D9-Riccati!$B$14 -> 0 | F9: =A_close+B_share*B9+Rho_a/2 -> 3.0718158
A10: 5 | B10: =B_share*C9/R_prem -> 4.3378644 | C10: =(Q_gap+R_prem*B10^2)/(2*(A_close+B_share*B10)+Rho_a) -> 0.00090372174 | D10: =C10*D0_gap^2 -> 9.0372174 | E10: =D10-Riccati!$B$14 -> 0 | F10: =A_close+B_share*B10+Rho_a/2 -> 3.0718158
A11: 6 | B11: =B_share*C10/R_prem -> 4.3378644 | C11: =(Q_gap+R_prem*B11^2)/(2*(A_close+B_share*B11)+Rho_a) -> 0.00090372174 | D11: =C11*D0_gap^2 -> 9.0372174 | E11: =D11-Riccati!$B$14 -> 0 | F11: =A_close+B_share*B11+Rho_a/2 -> 3.0718158
A13: Costs from 100 short if approvals landed at once
A14: Rule | B14: Gain k a year | C14: Cost (q + r k^2) d0^2 / (2(a + b k) + rho)
A15: Step 2's gain (the Riccati rule) | B15: =Riccati!B9 -> 4.3378644 | C15: =(Q_gap+R_prem*B15^2)*D0_gap^2/(2*(A_close+B_share*B15)+Rho_a) -> 9.0372174
A16: Best gain on today's gap (engine: a search over simulated costs) | B16: 2.4823475 | C16: =(Q_gap+R_prem*B16^2)*D0_gap^2/(2*(A_close+B_share*B16)+Rho_a) -> 10.135932
A17: Volume I's cautious gain | B17: =K_caut -> 2 | C17: =(Q_gap+R_prem*B17^2)*D0_gap^2/(2*(A_close+B_share*B17)+Rho_a) -> 11.083837
A18: Volume I's deadbeat gain | B18: =K_dead -> 6 | C18: =(Q_gap+R_prem*B18^2)*D0_gap^2/(2*(A_close+B_share*B18)+Rho_a) -> 9.4615583
A19: The cautious gain is the worst of these, above the best by | C19: =C17-C15 -> 2.0466191

Sheet Delay
A1: Allow for the delay: steer by the predicted gap (Proposition 8.3(ii); Worked Example 8.1, Step 3; Figure 8.3(b))
A2: The predicted gap z(t) = d(t + tau) moves as the gap would if approvals landed at once; the first quarter's cost is fixed; the rest is Theorem 8.3's problem in z with q' = q e^(-rho tau).
A3: Quantity | B3: Value | C3: Reading
A4: q' = q e^(-rho tau) | B4: =Q_gap*EXP(-Rho_a*Tau_d) -> 0.0031246531 | C4: The gap's cost, a quarter later
A5: p': positive root with q' | B5: =(-(Riccati!B5)+SQRT((Riccati!B5)^2+4*(Riccati!B4)*(B4)))/(2*(Riccati!B4)) -> 0.00089138618
A6: Gain K' = b p' / r, a year | B6: =B_share*B5/R_prem -> 4.2786537 | C6: Approve 4.28 times the predicted gap
A7: Gain a quarter | B7: =B6/4 -> 1.0696634
A8: Predicted gap today, z0 = e^(-a tau) d0 | B8: =EXP(-A_close*Tau_d)*D0_gap -> -90 | C8: Nothing in flight: 90 short a quarter from now
A9: First quarter's cost (fixed) | B9: =Q_gap*D0_gap^2*(1-EXP(-(2*A_close+Rho_a)*Tau_d))/(2*A_close+Rho_a) -> 7.1310495 | C9: Nothing HR does reaches the bench
A10: The rest, p' z0^2 | B10: =B5*B8^2 -> 7.2202281
A11: Least cost with the delay | B11: =B9+B10 -> 14.351278 | C11: $14.35 million
A12: The quarter's delay costs | B12: =B11-Riccati!B14 -> 5.3140601 | C12: $5.31 million
A13: The predicted gap closes at a + b K' | B13: =A_close+B_share*B6 -> 2.9886343
A14: First approval rate, K' |z0| (a year) | B14: =B6*ABS(B8) -> 385.07883 | C14: 385 a year
A15: Approvals in the first quarter | B15: =B14*(1-EXP(-B13*Tau_d))/B13 -> 67.811203 | C15: 68
A16: Gap after a year | B16: =B8*EXP(-B13*(1-Tau_d)) -> -9.5671368 | C16: 10 short, no overshoot
A17: Marginal premium at the start, 2 r v | B17: =2*R_prem*B14 -> 0.096269707
A18: Value of an approval at the start, b 2p'|z0| | B18: =B_share*2*B5*ABS(B8) -> 0.096269707 | C18: Equal
A19: Price of an engineer already on the bench | B19: =2*Q_gap*ABS(D0_gap)*(1-EXP(-(2*A_close+Rho_a)*Tau_d))/(2*A_close+Rho_a)+2*B5*ABS(B8)*EXP(-A_close*Tau_d) -> 0.28702555 | C19: $287,000, against $181,000 without the delay
A21: The least cost against the time approvals take to land (Figure 8.3(b))
A22: Months to land | B22: tau (years) | C22: q' | D22: p' | E22: z0 | F22: First period's cost | G22: Least cost
A23: 0 | B23: =A23/12 -> 0 | C23: =Q_gap*EXP(-Rho_a*B23) -> 0.0032 | D23: =(-(Riccati!$B$5)+SQRT((Riccati!$B$5)^2+4*(Riccati!$B$4)*(C23)))/(2*(Riccati!$B$4)) -> 0.00090372174 | E23: =EXP(-A_close*B23)*D0_gap -> -100 | F23: =Q_gap*D0_gap^2*(1-EXP(-(2*A_close+Rho_a)*B23))/(2*A_close+Rho_a) -> 0 | G23: =F23+D23*E23^2 -> 9.0372174
A24: 1 | B24: =A24/12 -> 0.083333333 | C24: =Q_gap*EXP(-Rho_a*B24) -> 0.0031746846 | D24: =(-(Riccati!$B$5)+SQRT((Riccati!$B$5)^2+4*(Riccati!$B$4)*(C24)))/(2*(Riccati!$B$4)) -> 0.00089959316 | E24: =EXP(-A_close*B24)*D0_gap -> -96.548938 | F24: =Q_gap*D0_gap^2*(1-EXP(-(2*A_close+Rho_a)*B24))/(2*A_close+Rho_a) -> 2.5650873 | G24: =F24+D24*E24^2 -> 10.950823
A25: 2 | B25: =A25/12 -> 0.16666667 | C25: =Q_gap*EXP(-Rho_a*B25) -> 0.0031495695 | D25: =(-(Riccati!$B$5)+SQRT((Riccati!$B$5)^2+4*(Riccati!$B$4)*(C25)))/(2*(Riccati!$B$4)) -> 0.00089548133 | E25: =EXP(-A_close*B25)*D0_gap -> -93.216975 | F25: =Q_gap*D0_gap^2*(1-EXP(-(2*A_close+Rho_a)*B25))/(2*A_close+Rho_a) -> 4.9372679 | G25: =F25+D25*E25^2 -> 12.718467
A26: 3 | B26: =A26/12 -> 0.25 | C26: =Q_gap*EXP(-Rho_a*B26) -> 0.0031246531 | D26: =(-(Riccati!$B$5)+SQRT((Riccati!$B$5)^2+4*(Riccati!$B$4)*(C26)))/(2*(Riccati!$B$4)) -> 0.00089138618 | E26: =EXP(-A_close*B26)*D0_gap -> -90 | F26: =Q_gap*D0_gap^2*(1-EXP(-(2*A_close+Rho_a)*B26))/(2*A_close+Rho_a) -> 7.1310495 | G26: =F26+D26*E26^2 -> 14.351278
A27: 4 | B27: =A27/12 -> 0.33333333 | C27: =Q_gap*EXP(-Rho_a*B27) -> 0.0030999338 | D27: =(-(Riccati!$B$5)+SQRT((Riccati!$B$5)^2+4*(Riccati!$B$4)*(C27)))/(2*(Riccati!$B$4)) -> 0.00088730765 | E27: =EXP(-A_close*B27)*D0_gap -> -86.894045 | F27: =Q_gap*D0_gap^2*(1-EXP(-(2*A_close+Rho_a)*B27))/(2*A_close+Rho_a) -> 9.1598483 | G27: =F27+D27*E27^2 -> 15.859531
A28: 5 | B28: =A28/12 -> 0.41666667 | C28: =Q_gap*EXP(-Rho_a*B28) -> 0.00307541 | D28: =(-(Riccati!$B$5)+SQRT((Riccati!$B$5)^2+4*(Riccati!$B$4)*(C28)))/(2*(Riccati!$B$4)) -> 0.00088324567 | E28: =EXP(-A_close*B28)*D0_gap -> -83.895278 | F28: =Q_gap*D0_gap^2*(1-EXP(-(2*A_close+Rho_a)*B28))/(2*A_close+Rho_a) -> 11.036072 | G28: =F28+D28*E28^2 -> 17.252724
A29: 6 | B29: =A29/12 -> 0.5 | C29: =Q_gap*EXP(-Rho_a*B29) -> 0.0030510803 | D29: =(-(Riccati!$B$5)+SQRT((Riccati!$B$5)^2+4*(Riccati!$B$4)*(C29)))/(2*(Riccati!$B$4)) -> 0.00087920017 | E29: =EXP(-A_close*B29)*D0_gap -> -81 | F29: =Q_gap*D0_gap^2*(1-EXP(-(2*A_close+Rho_a)*B29))/(2*A_close+Rho_a) -> 12.771195 | G29: =F29+D29*E29^2 -> 18.539627
A31: Cutting the delay from a quarter to a month is worth | G31: =G26-G24 -> 3.4004549

Sheet Rules
A1: Table 8.3: rules for closing a gap of 100 engineers when approvals take a quarter to land (Worked Example 8.1, Step 4; AXIOM Lab 2.8, step 3)
A2: Engine values (green): the delay equation simulated at steps of 1e-4 and 5e-5 years over 12 years, the cost extrapolated (Online Appendix 8.B.1). Gains, extra costs and the at-once column are formulas.
A4: Rule | B4: Steers by | C4: Gain a year | D4: Gain a quarter | E4: Approved, first quarter | F4: Largest surplus | G4: Gap after a year | H4: Cost | I4: Extra | J4: At once
A5: Best rule: steer by the predicted gap | B5: the predicted gap | C5: =Delay!B6 -> 4.2786537 | D5: =C5/4 -> 1.0696634 | E5: 67.814643 | F5: 0 | G5: -9.5659029 | H5: 14.351277 | I5: - | J5: =Riccati!B14 -> 9.0372174
A6: Step 2's gain on today's gap | B6: today's gap | C6: =Riccati!B9 -> 4.3378644 | D6: =C6/4 -> 1.0844661 | E6: 102.93016 | F6: 15.866575 | G6: 12.242305 | H6: 17.470796 | I6: =H6-$H$5 -> 3.1195184 | J6: =(Q_gap+R_prem*C6^2)*D0_gap^2/(2*(A_close+B_share*C6)+Rho_a) -> 9.0372174
A7: Best gain on today's gap | B7: today's gap | C7: 2.4823475 | D7: =C7/4 -> 0.62058686 | E7: 58.901895 | F7: 0.11914512 | G7: -5.8606917 | H7: 14.581192 | I7: =H7-$H$5 -> 0.22991454 | J7: =(Q_gap+R_prem*C7^2)*D0_gap^2/(2*(A_close+B_share*C7)+Rho_a) -> 10.135932
A8: Volume I's cautious gain | B8: today's gap | C8: =K_caut -> 2 | D8: =C8/4 -> 0.5 | E8: 47.456608 | F8: 0 | G8: -14.173388 | H8: 14.844011 | I8: =H8-$H$5 -> 0.49273311 | J8: =(Q_gap+R_prem*C8^2)*D0_gap^2/(2*(A_close+B_share*C8)+Rho_a) -> 11.083837
A9: Volume I's deadbeat gain | B9: today's gap | C9: =K_dead -> 6 | D9: =C9/4 -> 1.5 | E9: 142.36982 | F9: 36.558913 | G9: 10.941216 | H9: 25.069531 | I9: =H9-$H$5 -> 10.718254 | J9: =(Q_gap+R_prem*C9^2)*D0_gap^2/(2*(A_close+B_share*C9)+Rho_a) -> 9.4615583
A11: The best rule in closed form (Delay sheet), and its simulated cost less it | H11: =Delay!B11 -> 14.351278 | I11: =H5-H11 -> -8.2721927e-08
A12: If approvals landed at once, the cautious gain would be above the best by | J12: =J8-J5 -> 2.0466191
A14: Figure 8.3(a): the cost of v = -k d from 100 short, against the gain
A15: Gain k a year | B15: Approvals land at once (formula) | C15: A quarter late (engine)
A16: 1 | B16: =(Q_gap+R_prem*A16^2)*D0_gap^2/(2*(A_close+B_share*A16)+Rho_a) -> 15.550504 | C16: 18.013038
A17: 2 | B17: =(Q_gap+R_prem*A17^2)*D0_gap^2/(2*(A_close+B_share*A17)+Rho_a) -> 11.083837 | C17: 14.844009
A18: 3 | B18: =(Q_gap+R_prem*A18^2)*D0_gap^2/(2*(A_close+B_share*A18)+Rho_a) -> 9.5302222 | C18: 14.83181
A19: 4 | B19: =(Q_gap+R_prem*A19^2)*D0_gap^2/(2*(A_close+B_share*A19)+Rho_a) -> 9.0620842 | C19: 16.547144
A20: 5 | B20: =(Q_gap+R_prem*A20^2)*D0_gap^2/(2*(A_close+B_share*A20)+Rho_a) -> 9.1162048 | C20: 19.825708
A21: 6 | B21: =(Q_gap+R_prem*A21^2)*D0_gap^2/(2*(A_close+B_share*A21)+Rho_a) -> 9.4615583 | C21: 25.069506
A22: 7 | B22: =(Q_gap+R_prem*A22^2)*D0_gap^2/(2*(A_close+B_share*A22)+Rho_a) -> 9.9858706 | C22: 33.382257
A23: 8 | B23: =(Q_gap+R_prem*A23^2)*D0_gap^2/(2*(A_close+B_share*A23)+Rho_a) -> 10.628007 | C23: 47.465922
A25: Steering harder on today's gap pays only if approvals land at once; a quarter late, the best gain on today's gap is 2.48 a year and the cost climbs steeply above it.

Sheet CriticalGain
A1: Why a rule on today's gap must be gentle: its critical gain (Proposition 8.3(i); Online Appendix 8.B.1)
A2: d'(t) = -a d(t) - b k d(t - tau) has a root s = i w when b k cos(w tau) = -a and b k sin(w tau) = w: w solves w + a tan(w tau) = 0 between pi/(2 tau) and pi/tau. Bisection.
A4: Step | B4: Low | C4: High | D4: Middle | E4: w + a tan(w tau) | G4: Result | H4: Value
A5: 1 | B5: =PI()/(2*Tau_d)+0.000000001 -> 6.2831853 | C5: =PI()/Tau_d-0.000000001 -> 12.566371 | D5: =(B5+C5)/2 -> 9.424778 | E5: =D5+A_close*TAN(D5*Tau_d) -> 9.0033359 | G5: w (radians a year) | H5: =D64 -> 6.5405698
A6: 2 | B6: =IF(E5<0,D5,B5) -> 6.2831853 | C6: =IF(E5<0,C5,D5) -> 9.424778 | D6: =(B6+C6)/2 -> 7.8539816 | E6: =D6+A_close*TAN(D6*Tau_d) -> 6.8365305 | G6: Critical gain (a^2 + w^2)^(1/2) / b, a year | H6: =SQRT(A_close^2+H5^2)/B_share -> 10.923556
A7: 3 | B7: =IF(E6<0,D6,B6) -> 6.2831853 | C7: =IF(E6<0,C6,D6) -> 7.8539816 | D7: =(B7+C7)/2 -> 7.0685835 | E7: =D7+A_close*TAN(D7*Tau_d) -> 4.9498511 | G7: a quarter | H7: =H6/4 -> 2.730889
A8: 4 | B8: =IF(E7<0,D7,B7) -> 6.2831853 | C8: =IF(E7<0,C7,D7) -> 7.0685835 | D8: =(B8+C8)/2 -> 6.6758844 | E8: =D8+A_close*TAN(D8*Tau_d) -> 2.3969113 | G8: Period of the swings 2 pi / w (years) | H8: =2*PI()/H5 -> 0.96064801
A9: 5 | B9: =IF(E8<0,D8,B8) -> 6.2831853 | C9: =IF(E8<0,C8,D8) -> 6.6758844 | D9: =(B9+C9)/2 -> 6.4795348 | E9: =D9+A_close*TAN(D9*Tau_d) -> -2.0991154 | G9: Volume I's quarterly review: stable below 1/b, a quarter | H9: =1/B_share -> 1.6666667
A10: 6 | B10: =IF(E9<0,D9,B9) -> 6.4795348 | C10: =IF(E9<0,C9,D9) -> 6.6758844 | D10: =(B10+C10)/2 -> 6.5777096 | E10: =D10+A_close*TAN(D10*Tau_d) -> 0.86435899
A11: 7 | B11: =IF(E10<0,D10,B10) -> 6.4795348 | C11: =IF(E10<0,C10,D10) -> 6.5777096 | D11: =(B11+C11)/2 -> 6.5286222 | E11: =D11+A_close*TAN(D11*Tau_d) -> -0.33119355 | G11: Largest gap of v = -k d (engine) | H11: Years 2-4 | I11: Years 10-12
A12: 8 | B12: =IF(E11<0,D11,B11) -> 6.5286222 | C12: =IF(E11<0,C11,D11) -> 6.5777096 | D12: =(B12+C12)/2 -> 6.5531659 | E12: =D12+A_close*TAN(D12*Tau_d) -> 0.31861627 | G12: Gain 10 a year (2.5 a quarter) | H12: 61.399625 | I12: 8.3704876
A13: 9 | B13: =IF(E12<0,D12,B12) -> 6.5286222 | C13: =IF(E12<0,C12,D12) -> 6.5531659 | D13: =(B13+C13)/2 -> 6.5408941 | E13: =D13+A_close*TAN(D13*Tau_d) -> 0.008578091 | G13: Gain 12 a year (3.0 a quarter) | H13: 280.33302 | I13: 2412.6239
A14: 10 | B14: =IF(E13<0,D13,B13) -> 6.5286222 | C14: =IF(E13<0,C13,D13) -> 6.5408941 | D14: =(B14+C14)/2 -> 6.5347582 | E14: =D14+A_close*TAN(D14*Tau_d) -> -0.15731909
A15: 11 | B15: =IF(E14<0,D14,B14) -> 6.5347582 | C15: =IF(E14<0,C14,D14) -> 6.5408941 | D15: =(B15+C15)/2 -> 6.5378261 | E15: =D15+A_close*TAN(D15*Tau_d) -> -0.073409384 | G15: Engine values: the delay equation simulated at steps of 5e-5 and 2.5e-5 years; a window's largest gap converges at first order in the step, so it is extrapolated, 2 m(dt/2) - m(dt) (Online Appendix 8.B.1).
A16: 12 | B16: =IF(E15<0,D15,B15) -> 6.5378261 | C16: =IF(E15<0,C15,D15) -> 6.5408941 | D16: =(B16+C16)/2 -> 6.5393601 | E16: =D16+A_close*TAN(D16*Tau_d) -> -0.032179684 | G16: Below the critical gain the swings die out; above it they grow. Steering by the predicted gap removes the delay from the loop.
A17: 13 | B17: =IF(E16<0,D16,B16) -> 6.5393601 | C17: =IF(E16<0,C16,D16) -> 6.5408941 | D17: =(B17+C17)/2 -> 6.5401271 | E17: =D17+A_close*TAN(D17*Tau_d) -> -0.011742334
A18: 14 | B18: =IF(E17<0,D17,B17) -> 6.5401271 | C18: =IF(E17<0,C17,D17) -> 6.5408941 | D18: =(B18+C18)/2 -> 6.5405106 | E18: =D18+A_close*TAN(D18*Tau_d) -> -0.0015675712
A19: 15 | B19: =IF(E18<0,D18,B18) -> 6.5405106 | C19: =IF(E18<0,C18,D18) -> 6.5408941 | D19: =(B19+C19)/2 -> 6.5407023 | E19: =D19+A_close*TAN(D19*Tau_d) -> 0.0035088894
A20: 16 | B20: =IF(E19<0,D19,B19) -> 6.5405106 | C20: =IF(E19<0,C19,D19) -> 6.5407023 | D20: =(B20+C20)/2 -> 6.5406065 | E20: =D20+A_close*TAN(D20*Tau_d) -> 0.00097156748
A21: 17 | B21: =IF(E20<0,D20,B20) -> 6.5405106 | C21: =IF(E20<0,C20,D20) -> 6.5406065 | D21: =(B21+C21)/2 -> 6.5405585 | E21: =D21+A_close*TAN(D21*Tau_d) -> -0.00029777462
A22: 18 | B22: =IF(E21<0,D21,B21) -> 6.5405585 | C22: =IF(E21<0,C21,D21) -> 6.5406065 | D22: =(B22+C22)/2 -> 6.5405825 | E22: =D22+A_close*TAN(D22*Tau_d) -> 0.00033695322
A23: 19 | B23: =IF(E22<0,D22,B22) -> 6.5405585 | C23: =IF(E22<0,C22,D22) -> 6.5405825 | D23: =(B23+C23)/2 -> 6.5405705 | E23: =D23+A_close*TAN(D23*Tau_d) -> 1.9603496e-05
A24: 20 | B24: =IF(E23<0,D23,B23) -> 6.5405585 | C24: =IF(E23<0,C23,D23) -> 6.5405705 | D24: =(B24+C24)/2 -> 6.5405645 | E24: =D24+A_close*TAN(D24*Tau_d) -> -0.00013908201
A25: 21 | B25: =IF(E24<0,D24,B24) -> 6.5405645 | C25: =IF(E24<0,C24,D24) -> 6.5405705 | D25: =(B25+C25)/2 -> 6.5405675 | E25: =D25+A_close*TAN(D25*Tau_d) -> -5.9738371e-05
A26: 22 | B26: =IF(E25<0,D25,B25) -> 6.5405675 | C26: =IF(E25<0,C25,D25) -> 6.5405705 | D26: =(B26+C26)/2 -> 6.540569 | E26: =D26+A_close*TAN(D26*Tau_d) -> -2.0067215e-05
A27: 23 | B27: =IF(E26<0,D26,B26) -> 6.540569 | C27: =IF(E26<0,C26,D26) -> 6.5405705 | D27: =(B27+C27)/2 -> 6.5405698 | E27: =D27+A_close*TAN(D27*Tau_d) -> -2.3180403e-07
A28: 24 | B28: =IF(E27<0,D27,B27) -> 6.5405698 | C28: =IF(E27<0,C27,D27) -> 6.5405705 | D28: =(B28+C28)/2 -> 6.5405701 | E28: =D28+A_close*TAN(D28*Tau_d) -> 9.68586e-06
... A64: 60 | B64: =IF(E63<0,D63,B63) -> 6.5405698 | C64: =IF(E63<0,C63,D63) -> 6.5405698 | D64: =(B64+C64)/2 -> 6.5405698 | E64: =D64+A_close*TAN(D64*Tau_d) -> 0

Sheet Sensitivities
A1: Test the declarations (Worked Example 8.1, Step 5; Figure 8.3(b))
A3: Declaration | B3: q multiplier | C3: r multiplier | D3: q | E3: r | F3: p at once | G3: Gain K at once | H3: Least cost at once | I3: q' | J3: p' | K3: Gain K' with the delay | L3: Least cost with the delay
A4: Base | B4: 1 | C4: 1 | D4: =Q_gap*B4 -> 0.0032 | E4: =R_prem*C4 -> 0.000125 | F4: =(-(2*A_close+Rho_a)+SQRT((2*A_close+Rho_a)^2+4*(B_share^2/E4)*(D4)))/(2*(B_share^2/E4)) -> 0.00090372174 | G4: =B_share*F4/E4 -> 4.3378644 | H4: =F4*D0_gap^2 -> 9.0372174 | I4: =D4*EXP(-Rho_a*Tau_d) -> 0.0031246531 | J4: =(-(2*A_close+Rho_a)+SQRT((2*A_close+Rho_a)^2+4*(B_share^2/E4)*(I4)))/(2*(B_share^2/E4)) -> 0.00089138618 | K4: =B_share*J4/E4 -> 4.2786537 | L4: =D4*D0_gap^2*(1-EXP(-(2*A_close+Rho_a)*Tau_d))/(2*A_close+Rho_a)+J4*(EXP(-A_close*Tau_d)*D0_gap)^2 -> 14.351278
A5: Gap cost doubled | B5: 2 | C5: 1 | D5: =Q_gap*B5 -> 0.0064 | E5: =R_prem*C5 -> 0.000125 | F5: =(-(2*A_close+Rho_a)+SQRT((2*A_close+Rho_a)^2+4*(B_share^2/E5)*(D5)))/(2*(B_share^2/E5)) -> 0.0013367031 | G5: =B_share*F5/E5 -> 6.416175 | H5: =F5*D0_gap^2 -> 13.367031 | I5: =D5*EXP(-Rho_a*Tau_d) -> 0.0062493062 | J5: =(-(2*A_close+Rho_a)+SQRT((2*A_close+Rho_a)^2+4*(B_share^2/E5)*(I5)))/(2*(B_share^2/E5)) -> 0.0013191542 | K5: =B_share*J5/E5 -> 6.3319401 | L5: =D5*D0_gap^2*(1-EXP(-(2*A_close+Rho_a)*Tau_d))/(2*A_close+Rho_a)+J5*(EXP(-A_close*Tau_d)*D0_gap)^2 -> 24.947248
A6: Gap cost halved | B6: 0.5 | C6: 1 | D6: =Q_gap*B6 -> 0.0016 | E6: =R_prem*C6 -> 0.000125 | F6: =(-(2*A_close+Rho_a)+SQRT((2*A_close+Rho_a)^2+4*(B_share^2/E6)*(D6)))/(2*(B_share^2/E6)) -> 0.0006000645 | G6: =B_share*F6/E6 -> 2.8803096 | H6: =F6*D0_gap^2 -> 6.000645 | I6: =D6*EXP(-Rho_a*Tau_d) -> 0.0015623265 | J6: =(-(2*A_close+Rho_a)+SQRT((2*A_close+Rho_a)^2+4*(B_share^2/E6)*(I6)))/(2*(B_share^2/E6)) -> 0.00059144305 | K6: =B_share*J6/E6 -> 2.8389266 | L6: =D6*D0_gap^2*(1-EXP(-(2*A_close+Rho_a)*Tau_d))/(2*A_close+Rho_a)+J6*(EXP(-A_close*Tau_d)*D0_gap)^2 -> 8.3562134
A7: Premium doubled | B7: 1 | C7: 2 | D7: =Q_gap*B7 -> 0.0032 | E7: =R_prem*C7 -> 0.00025 | F7: =(-(2*A_close+Rho_a)+SQRT((2*A_close+Rho_a)^2+4*(B_share^2/E7)*(D7)))/(2*(B_share^2/E7)) -> 0.001200129 | G7: =B_share*F7/E7 -> 2.8803096 | H7: =F7*D0_gap^2 -> 12.00129 | I7: =D7*EXP(-Rho_a*Tau_d) -> 0.0031246531 | J7: =(-(2*A_close+Rho_a)+SQRT((2*A_close+Rho_a)^2+4*(B_share^2/E7)*(I7)))/(2*(B_share^2/E7)) -> 0.0011828861 | K7: =B_share*J7/E7 -> 2.8389266 | L7: =D7*D0_gap^2*(1-EXP(-(2*A_close+Rho_a)*Tau_d))/(2*A_close+Rho_a)+J7*(EXP(-A_close*Tau_d)*D0_gap)^2 -> 16.712427
A8: Premium halved | B8: 1 | C8: 0.5 | D8: =Q_gap*B8 -> 0.0032 | E8: =R_prem*C8 -> 6.25e-05 | F8: =(-(2*A_close+Rho_a)+SQRT((2*A_close+Rho_a)^2+4*(B_share^2/E8)*(D8)))/(2*(B_share^2/E8)) -> 0.00066835156 | G8: =B_share*F8/E8 -> 6.416175 | H8: =F8*D0_gap^2 -> 6.6835156 | I8: =D8*EXP(-Rho_a*Tau_d) -> 0.0031246531 | J8: =(-(2*A_close+Rho_a)+SQRT((2*A_close+Rho_a)^2+4*(B_share^2/E8)*(I8)))/(2*(B_share^2/E8)) -> 0.0006595771 | K8: =B_share*J8/E8 -> 6.3319401 | L8: =D8*D0_gap^2*(1-EXP(-(2*A_close+Rho_a)*Tau_d))/(2*A_close+Rho_a)+J8*(EXP(-A_close*Tau_d)*D0_gap)^2 -> 12.473624
A10: Approvals take half a year while HR steers for a quarter (engine: the delay equation simulated over 14 years)
A11: Rule | B11: Cost | C11: Largest surplus
A12: Best rule, built for a quarter | B12: 19.994894 | C12: 16.347645
A13: Step 2's gain on today's gap | B13: 42.850427 | C13: 64.291656
A14: Volume I's cautious gain | B14: 19.529529 | C14: 12.070892
A16: Rule built for half a year: q' | B16: =Q_gap*EXP(-Rho_a*0.5) -> 0.0030510803
A17: p' | B17: =(-(Riccati!B5)+SQRT((Riccati!B5)^2+4*(Riccati!B4)*(B16)))/(2*(Riccati!B4)) -> 0.00087920017
A18: Gain K', a year | B18: =B_share*B17/R_prem -> 4.2201608 | C18: 4.220
A19: Least cost | B19: =Q_gap*D0_gap^2*(1-EXP(-(2*A_close+Rho_a)*0.5))/(2*A_close+Rho_a)+B17*(EXP(-A_close*0.5)*D0_gap)^2 -> 18.539627 | C19: No overshoot
A20: Simulated (engine) | B20: 18.539627 | C20: The closed form, simulated
A22: Only 30 percent of approvals become engineers
A23: Share that becomes engineers | B23: 0.3 | C23: HR's rule still counts 60 percent
A24: Rule built for 60 percent: cost (engine, simulated over 14 years) | B24: 19.610881
A25: Redesigned: p' | B25: =(-(2*A_close+Rho_a)+SQRT((2*A_close+Rho_a)^2+4*(B23^2/R_prem)*(Delay!B4)))/(2*(B23^2/R_prem)) -> 0.0015311991
A26: Redesigned: gain K', a year | B26: =B23*B25/R_prem -> 3.6748778 | C26: 3.675
A27: Redesigned: least cost | B27: =Delay!B9+B25*Delay!B8^2 -> 19.533762
A28: The rule built for 60 percent comes within | B28: =B24-B27 -> 0.077119036 | C28: $0.08 million

Sheet Capability
A1: Chapter 6's capability problem by the HJB equation: values, prices, corners (Propositions 8.1 and 8.2; AXIOM Lab 2.8, step 4)
A3: Capability c | B3: Value V(c) | C3: Price of a point V'(c) | D3: Switching function V' - k | E3: Decision
A4: 45 | B4: =IF(A4<Floor_F,MAX((-(Cost_k*Ubar_c+Delay_D)*(1-EXP(-Rho_a*LN((Top_c-A4)/(Top_c-Floor_F))/Delta_c))/Rho_a+EXP(-Rho_a*LN((Top_c-A4)/(Top_c-Floor_F))/Delta_c)*(-Cost_k*Delta_c*Floor_F/Rho_a)),(-Delay_D/Rho_a)),(EXP(-Rho_a*LN(A4/Floor_F)/Delta_c)*(-Cost_k*Delta_c*Floor_F/Rho_a))) -> -324.45516 | C4: =IF(A4<Floor_F,EXP(-Rho_a*LN((Top_c-A4)/(Top_c-Floor_F))/Delta_c)*(Cost_k*Ubar_c+Delay_D+Rho_a*(-Cost_k*Delta_c*Floor_F/Rho_a))/(Ubar_c-Delta_c*A4),IF(A4=Floor_F,Cost_k,EXP(-Rho_a*LN(A4/Floor_F)/Delta_c)*(-Rho_a*(-Cost_k*Delta_c*Floor_F/Rho_a))/(Delta_c*A4))) -> 7.4659295 | D4: =C4-Cost_k -> 3.4659295 | E4: =IF(ABS(D4)<0.000000001,"hold: pay the rent",IF(D4>0,"hire at the cap","hire nothing")) -> hire at the cap
A5: 53 | B5: =IF(A5<Floor_F,MAX((-(Cost_k*Ubar_c+Delay_D)*(1-EXP(-Rho_a*LN((Top_c-A5)/(Top_c-Floor_F))/Delta_c))/Rho_a+EXP(-Rho_a*LN((Top_c-A5)/(Top_c-Floor_F))/Delta_c)*(-Cost_k*Delta_c*Floor_F/Rho_a)),(-Delay_D/Rho_a)),(EXP(-Rho_a*LN(A5/Floor_F)/Delta_c)*(-Cost_k*Delta_c*Floor_F/Rho_a))) -> -254.89212 | C5: =IF(A5<Floor_F,EXP(-Rho_a*LN((Top_c-A5)/(Top_c-Floor_F))/Delta_c)*(Cost_k*Ubar_c+Delay_D+Rho_a*(-Cost_k*Delta_c*Floor_F/Rho_a))/(Ubar_c-Delta_c*A5),IF(A5=Floor_F,Cost_k,EXP(-Rho_a*LN(A5/Floor_F)/Delta_c)*(-Rho_a*(-Cost_k*Delta_c*Floor_F/Rho_a))/(Delta_c*A5))) -> 10.129671 | D5: =C5-Cost_k -> 6.1296707 | E5: =IF(ABS(D5)<0.000000001,"hold: pay the rent",IF(D5>0,"hire at the cap","hire nothing")) -> hire at the cap
A6: 55 | B6: =IF(A6<Floor_F,MAX((-(Cost_k*Ubar_c+Delay_D)*(1-EXP(-Rho_a*LN((Top_c-A6)/(Top_c-Floor_F))/Delta_c))/Rho_a+EXP(-Rho_a*LN((Top_c-A6)/(Top_c-Floor_F))/Delta_c)*(-Cost_k*Delta_c*Floor_F/Rho_a)),(-Delay_D/Rho_a)),(EXP(-Rho_a*LN(A6/Floor_F)/Delta_c)*(-Cost_k*Delta_c*Floor_F/Rho_a))) -> -233.75962 | C6: =IF(A6<Floor_F,EXP(-Rho_a*LN((Top_c-A6)/(Top_c-Floor_F))/Delta_c)*(Cost_k*Ubar_c+Delay_D+Rho_a*(-Cost_k*Delta_c*Floor_F/Rho_a))/(Ubar_c-Delta_c*A6),IF(A6=Floor_F,Cost_k,EXP(-Rho_a*LN(A6/Floor_F)/Delta_c)*(-Rho_a*(-Cost_k*Delta_c*Floor_F/Rho_a))/(Delta_c*A6))) -> 4 | D6: =C6-Cost_k -> 0 | E6: =IF(ABS(D6)<0.000000001,"hold: pay the rent",IF(D6>0,"hire at the cap","hire nothing")) -> hold: pay the rent
A7: 58 | B7: =IF(A7<Floor_F,MAX((-(Cost_k*Ubar_c+Delay_D)*(1-EXP(-Rho_a*LN((Top_c-A7)/(Top_c-Floor_F))/Delta_c))/Rho_a+EXP(-Rho_a*LN((Top_c-A7)/(Top_c-Floor_F))/Delta_c)*(-Cost_k*Delta_c*Floor_F/Rho_a)),(-Delay_D/Rho_a)),(EXP(-Rho_a*LN(A7/Floor_F)/Delta_c)*(-Cost_k*Delta_c*Floor_F/Rho_a))) -> -222.36266 | C7: =IF(A7<Floor_F,EXP(-Rho_a*LN((Top_c-A7)/(Top_c-Floor_F))/Delta_c)*(Cost_k*Ubar_c+Delay_D+Rho_a*(-Cost_k*Delta_c*Floor_F/Rho_a))/(Ubar_c-Delta_c*A7),IF(A7=Floor_F,Cost_k,EXP(-Rho_a*LN(A7/Floor_F)/Delta_c)*(-Rho_a*(-Cost_k*Delta_c*Floor_F/Rho_a))/(Delta_c*A7))) -> 3.6081706 | D7: =C7-Cost_k -> -0.39182944 | E7: =IF(ABS(D7)<0.000000001,"hold: pay the rent",IF(D7>0,"hire at the cap","hire nothing")) -> hire nothing
A9: Quantity | B9: Value | C9: Reading
A10: Value of the floor forever, V(55) = -k delta 55 / rho | B10: =(-Cost_k*Delta_c*Floor_F/Rho_a) -> -233.75962
A11: Never starting the build: -D / rho | B11: =(-Delay_D/Rho_a) -> -335.74588
A12: x = k u bar / (k u bar + D + rho V(55)) | B12: =Cost_k*Ubar_c/(Cost_k*Ubar_c+Delay_D+Rho_a*(-Cost_k*Delta_c*Floor_F/Rho_a)) -> 0.80647906 | C12: e^(-rho tau) where racing ties never starting
A13: Never-start threshold c_a = 100 - 45 x^(-delta/rho) | B13: =Top_c-(Top_c-Floor_F)*B12^(-Delta_c/Rho_a) -> 43.446247 | C13: Corner: below it the build never starts
A14: Racing from c_a, a check: V_race(c_a) | B14: =(-(Cost_k*Ubar_c+Delay_D)*(1-EXP(-Rho_a*LN((Top_c-B13)/(Top_c-Floor_F))/Delta_c))/Rho_a+EXP(-Rho_a*LN((Top_c-B13)/(Top_c-Floor_F))/Delta_c)*(-Cost_k*Delta_c*Floor_F/Rho_a)) -> -335.74588 | C14: Equals -D / rho
A15: Price just above c_a | B15: =IF(B13<Floor_F,EXP(-Rho_a*LN((Top_c-B13)/(Top_c-Floor_F))/Delta_c)*(Cost_k*Ubar_c+Delay_D+Rho_a*(-Cost_k*Delta_c*Floor_F/Rho_a))/(Ubar_c-Delta_c*B13),IF(B13=Floor_F,Cost_k,EXP(-Rho_a*LN(B13/Floor_F)/Delta_c)*(-Rho_a*(-Cost_k*Delta_c*Floor_F/Rho_a))/(Delta_c*B13))) -> 7.0729169 | C15: Jumps from 0 below
A16: Price just below the floor, k + D / (u bar - delta 55) | B16: =Cost_k+Delay_D/(Ubar_c-Delta_c*Floor_F) -> 11.021847 | C16: Its cost plus the delay it saves; $4 million above
A17: Rent on the floor, k delta 55 (a year) | B17: =Cost_k*Delta_c*Floor_F -> 22.279671
A18: Rent as a share of the position's value | B18: =B17/-B10 -> 0.09531018 | C18: rho: the hurdle return
A19: Holding at c_a: rent on c_a plus the delay (a year) | B19: =Cost_k*Delta_c*B13+Delay_D -> 49.59942 | C19: More than D, what never starting costs at the hurdle rate
A21: HJB at 58: rho V(58) | B21: =Rho_a*B7 -> -21.193425
A22: Drift at 58, delta x 58 (points a year) | B22: =Delta_c*A7 -> 5.8737315
A23: Price of a point at 58 | B23: =C7 -> 3.6081706
A24: Cost of the drift, drift x price (a year) | B24: =B22*B23 -> 21.193425 | C24: Equals -rho V(58)
A25: Hiring's coefficient in the Hamiltonian, V'(58) - k | B25: =B23-Cost_k -> -0.39182944 | C25: Negative: hire nothing
A27: PMP-HJB comparison: Chapter 6's costate m(0) e^((rho + delta) t) against the value's slope at c(t)
A28: Years | B28: Drift from 58: c(t) | C28: Costate | D28: Slope V'(c(t)) | E28: Gap | F28: Race from 53: c(t) | G28: Costate | H28: Slope V'(c(t)) | I28: Gap
A29: 0 | B29: =$A$7*EXP(-Delta_c*A29) -> 58 | C29: =$C$7*EXP((Rho_a+Delta_c)*A29) -> 3.6081706 | D29: =IF(B29<Floor_F,EXP(-Rho_a*LN((Top_c-B29)/(Top_c-Floor_F))/Delta_c)*(Cost_k*Ubar_c+Delay_D+Rho_a*(-Cost_k*Delta_c*Floor_F/Rho_a))/(Ubar_c-Delta_c*B29),IF(B29=Floor_F,Cost_k,EXP(-Rho_a*LN(B29/Floor_F)/Delta_c)*(-Rho_a*(-Cost_k*Delta_c*Floor_F/Rho_a))/(Delta_c*B29))) -> 3.6081706 | E29: =ABS(C29-D29) -> 0 | F29: =Top_c-(Top_c-$A$5)*EXP(-Delta_c*A29) -> 53 | G29: =$C$5*EXP((Rho_a+Delta_c)*A29) -> 10.129671 | H29: =IF(F29<Floor_F,EXP(-Rho_a*LN((Top_c-F29)/(Top_c-Floor_F))/Delta_c)*(Cost_k*Ubar_c+Delay_D+Rho_a*(-Cost_k*Delta_c*Floor_F/Rho_a))/(Ubar_c-Delta_c*F29),IF(F29=Floor_F,Cost_k,EXP(-Rho_a*LN(F29/Floor_F)/Delta_c)*(-Rho_a*(-Cost_k*Delta_c*Floor_F/Rho_a))/(Delta_c*F29))) -> 10.129671 | I29: =ABS(G29-H29) -> 0
A30: 0.04 | B30: =$A$7*EXP(-Delta_c*A30) -> 57.765526 | C30: =$C$7*EXP((Rho_a+Delta_c)*A30) -> 3.6366544 | D30: =IF(B30<Floor_F,EXP(-Rho_a*LN((Top_c-B30)/(Top_c-Floor_F))/Delta_c)*(Cost_k*Ubar_c+Delay_D+Rho_a*(-Cost_k*Delta_c*Floor_F/Rho_a))/(Ubar_c-Delta_c*B30),IF(B30=Floor_F,Cost_k,EXP(-Rho_a*LN(B30/Floor_F)/Delta_c)*(-Rho_a*(-Cost_k*Delta_c*Floor_F/Rho_a))/(Delta_c*B30))) -> 3.6366544 | E30: =ABS(C30-D30) -> 0 | F30: =Top_c-(Top_c-$A$5)*EXP(-Delta_c*A30) -> 53.190005 | G30: =$C$5*EXP((Rho_a+Delta_c)*A30) -> 10.209637 | H30: =IF(F30<Floor_F,EXP(-Rho_a*LN((Top_c-F30)/(Top_c-Floor_F))/Delta_c)*(Cost_k*Ubar_c+Delay_D+Rho_a*(-Cost_k*Delta_c*Floor_F/Rho_a))/(Ubar_c-Delta_c*F30),IF(F30=Floor_F,Cost_k,EXP(-Rho_a*LN(F30/Floor_F)/Delta_c)*(-Rho_a*(-Cost_k*Delta_c*Floor_F/Rho_a))/(Delta_c*F30))) -> 10.209637 | I30: =ABS(G30-H30) -> 0
A31: 0.08 | B31: =$A$7*EXP(-Delta_c*A31) -> 57.532 | C31: =$C$7*EXP((Rho_a+Delta_c)*A31) -> 3.665363 | D31: =IF(B31<Floor_F,EXP(-Rho_a*LN((Top_c-B31)/(Top_c-Floor_F))/Delta_c)*(Cost_k*Ubar_c+Delay_D+Rho_a*(-Cost_k*Delta_c*Floor_F/Rho_a))/(Ubar_c-Delta_c*B31),IF(B31=Floor_F,Cost_k,EXP(-Rho_a*LN(B31/Floor_F)/Delta_c)*(-Rho_a*(-Cost_k*Delta_c*Floor_F/Rho_a))/(Delta_c*B31))) -> 3.665363 | E31: =ABS(C31-D31) -> 0 | F31: =Top_c-(Top_c-$A$5)*EXP(-Delta_c*A31) -> 53.379242 | G31: =$C$5*EXP((Rho_a+Delta_c)*A31) -> 10.290234 | H31: =IF(F31<Floor_F,EXP(-Rho_a*LN((Top_c-F31)/(Top_c-Floor_F))/Delta_c)*(Cost_k*Ubar_c+Delay_D+Rho_a*(-Cost_k*Delta_c*Floor_F/Rho_a))/(Ubar_c-Delta_c*F31),IF(F31=Floor_F,Cost_k,EXP(-Rho_a*LN(F31/Floor_F)/Delta_c)*(-Rho_a*(-Cost_k*Delta_c*Floor_F/Rho_a))/(Delta_c*F31))) -> 10.290234 | I31: =ABS(G31-H31) -> 0
A32: 0.12 | B32: =$A$7*EXP(-Delta_c*A32) -> 57.299418 | C32: =$C$7*EXP((Rho_a+Delta_c)*A32) -> 3.6942983 | D32: =IF(B32<Floor_F,EXP(-Rho_a*LN((Top_c-B32)/(Top_c-Floor_F))/Delta_c)*(Cost_k*Ubar_c+Delay_D+Rho_a*(-Cost_k*Delta_c*Floor_F/Rho_a))/(Ubar_c-Delta_c*B32),IF(B32=Floor_F,Cost_k,EXP(-Rho_a*LN(B32/Floor_F)/Delta_c)*(-Rho_a*(-Cost_k*Delta_c*Floor_F/Rho_a))/(Delta_c*B32))) -> 3.6942983 | E32: =ABS(C32-D32) -> 0 | F32: =Top_c-(Top_c-$A$5)*EXP(-Delta_c*A32) -> 53.567713 | G32: =$C$5*EXP((Rho_a+Delta_c)*A32) -> 10.371468 | H32: =IF(F32<Floor_F,EXP(-Rho_a*LN((Top_c-F32)/(Top_c-Floor_F))/Delta_c)*(Cost_k*Ubar_c+Delay_D+Rho_a*(-Cost_k*Delta_c*Floor_F/Rho_a))/(Ubar_c-Delta_c*F32),IF(F32=Floor_F,Cost_k,EXP(-Rho_a*LN(F32/Floor_F)/Delta_c)*(-Rho_a*(-Cost_k*Delta_c*Floor_F/Rho_a))/(Delta_c*F32))) -> 10.371468 | I32: =ABS(G32-H32) -> 0
A33: 0.16 | B33: =$A$7*EXP(-Delta_c*A33) -> 57.067776 | C33: =$C$7*EXP((Rho_a+Delta_c)*A33) -> 3.7234621 | D33: =IF(B33<Floor_F,EXP(-Rho_a*LN((Top_c-B33)/(Top_c-Floor_F))/Delta_c)*(Cost_k*Ubar_c+Delay_D+Rho_a*(-Cost_k*Delta_c*Floor_F/Rho_a))/(Ubar_c-Delta_c*B33),IF(B33=Floor_F,Cost_k,EXP(-Rho_a*LN(B33/Floor_F)/Delta_c)*(-Rho_a*(-Cost_k*Delta_c*Floor_F/Rho_a))/(Delta_c*B33))) -> 3.7234621 | E33: =ABS(C33-D33) -> 0 | F33: =Top_c-(Top_c-$A$5)*EXP(-Delta_c*A33) -> 53.755423 | G33: =$C$5*EXP((Rho_a+Delta_c)*A33) -> 10.453343 | H33: =IF(F33<Floor_F,EXP(-Rho_a*LN((Top_c-F33)/(Top_c-Floor_F))/Delta_c)*(Cost_k*Ubar_c+Delay_D+Rho_a*(-Cost_k*Delta_c*Floor_F/Rho_a))/(Ubar_c-Delta_c*F33),IF(F33=Floor_F,Cost_k,EXP(-Rho_a*LN(F33/Floor_F)/Delta_c)*(-Rho_a*(-Cost_k*Delta_c*Floor_F/Rho_a))/(Delta_c*F33))) -> 10.453343 | I33: =ABS(G33-H33) -> 0
A34: 0.2 | B34: =$A$7*EXP(-Delta_c*A34) -> 56.837071 | C34: =$C$7*EXP((Rho_a+Delta_c)*A34) -> 3.752856 | D34: =IF(B34<Floor_F,EXP(-Rho_a*LN((Top_c-B34)/(Top_c-Floor_F))/Delta_c)*(Cost_k*Ubar_c+Delay_D+Rho_a*(-Cost_k*Delta_c*Floor_F/Rho_a))/(Ubar_c-Delta_c*B34),IF(B34=Floor_F,Cost_k,EXP(-Rho_a*LN(B34/Floor_F)/Delta_c)*(-Rho_a*(-Cost_k*Delta_c*Floor_F/Rho_a))/(Delta_c*B34))) -> 3.752856 | E34: =ABS(C34-D34) -> 0 | F34: =Top_c-(Top_c-$A$5)*EXP(-Delta_c*A34) -> 53.942374 | G34: =$C$5*EXP((Rho_a+Delta_c)*A34) -> 10.535864 | H34: =IF(F34<Floor_F,EXP(-Rho_a*LN((Top_c-F34)/(Top_c-Floor_F))/Delta_c)*(Cost_k*Ubar_c+Delay_D+Rho_a*(-Cost_k*Delta_c*Floor_F/Rho_a))/(Ubar_c-Delta_c*F34),IF(F34=Floor_F,Cost_k,EXP(-Rho_a*LN(F34/Floor_F)/Delta_c)*(-Rho_a*(-Cost_k*Delta_c*Floor_F/Rho_a))/(Delta_c*F34))) -> 10.535864 | I34: =ABS(G34-H34) -> 0
A35: 0.24 | B35: =$A$7*EXP(-Delta_c*A35) -> 56.607298 | C35: =$C$7*EXP((Rho_a+Delta_c)*A35) -> 3.782482 | D35: =IF(B35<Floor_F,EXP(-Rho_a*LN((Top_c-B35)/(Top_c-Floor_F))/Delta_c)*(Cost_k*Ubar_c+Delay_D+Rho_a*(-Cost_k*Delta_c*Floor_F/Rho_a))/(Ubar_c-Delta_c*B35),IF(B35=Floor_F,Cost_k,EXP(-Rho_a*LN(B35/Floor_F)/Delta_c)*(-Rho_a*(-Cost_k*Delta_c*Floor_F/Rho_a))/(Delta_c*B35))) -> 3.782482 | E35: =ABS(C35-D35) -> 0 | F35: =Top_c-(Top_c-$A$5)*EXP(-Delta_c*A35) -> 54.128569 | G35: =$C$5*EXP((Rho_a+Delta_c)*A35) -> 10.619037 | H35: =IF(F35<Floor_F,EXP(-Rho_a*LN((Top_c-F35)/(Top_c-Floor_F))/Delta_c)*(Cost_k*Ubar_c+Delay_D+Rho_a*(-Cost_k*Delta_c*Floor_F/Rho_a))/(Ubar_c-Delta_c*F35),IF(F35=Floor_F,Cost_k,EXP(-Rho_a*LN(F35/Floor_F)/Delta_c)*(-Rho_a*(-Cost_k*Delta_c*Floor_F/Rho_a))/(Delta_c*F35))) -> 10.619037 | I35: =ABS(G35-H35) -> 0
A36: 0.28 | B36: =$A$7*EXP(-Delta_c*A36) -> 56.378454 | C36: =$C$7*EXP((Rho_a+Delta_c)*A36) -> 3.8123419 | D36: =IF(B36<Floor_F,EXP(-Rho_a*LN((Top_c-B36)/(Top_c-Floor_F))/Delta_c)*(Cost_k*Ubar_c+Delay_D+Rho_a*(-Cost_k*Delta_c*Floor_F/Rho_a))/(Ubar_c-Delta_c*B36),IF(B36=Floor_F,Cost_k,EXP(-Rho_a*LN(B36/Floor_F)/Delta_c)*(-Rho_a*(-Cost_k*Delta_c*Floor_F/Rho_a))/(Delta_c*B36))) -> 3.8123419 | E36: =ABS(C36-D36) -> 0 | F36: =Top_c-(Top_c-$A$5)*EXP(-Delta_c*A36) -> 54.314011 | G36: =$C$5*EXP((Rho_a+Delta_c)*A36) -> 10.702867 | H36: =IF(F36<Floor_F,EXP(-Rho_a*LN((Top_c-F36)/(Top_c-Floor_F))/Delta_c)*(Cost_k*Ubar_c+Delay_D+Rho_a*(-Cost_k*Delta_c*Floor_F/Rho_a))/(Ubar_c-Delta_c*F36),IF(F36=Floor_F,Cost_k,EXP(-Rho_a*LN(F36/Floor_F)/Delta_c)*(-Rho_a*(-Cost_k*Delta_c*Floor_F/Rho_a))/(Delta_c*F36))) -> 10.702867 | I36: =ABS(G36-H36) -> 0
A37: 0.32 | B37: =$A$7*EXP(-Delta_c*A37) -> 56.150535 | C37: =$C$7*EXP((Rho_a+Delta_c)*A37) -> 3.8424375 | D37: =IF(B37<Floor_F,EXP(-Rho_a*LN((Top_c-B37)/(Top_c-Floor_F))/Delta_c)*(Cost_k*Ubar_c+Delay_D+Rho_a*(-Cost_k*Delta_c*Floor_F/Rho_a))/(Ubar_c-Delta_c*B37),IF(B37=Floor_F,Cost_k,EXP(-Rho_a*LN(B37/Floor_F)/Delta_c)*(-Rho_a*(-Cost_k*Delta_c*Floor_F/Rho_a))/(Delta_c*B37))) -> 3.8424375 | E37: =ABS(C37-D37) -> 0 | F37: =Top_c-(Top_c-$A$5)*EXP(-Delta_c*A37) -> 54.498704 | G37: =$C$5*EXP((Rho_a+Delta_c)*A37) -> 10.787358 | H37: =IF(F37<Floor_F,EXP(-Rho_a*LN((Top_c-F37)/(Top_c-Floor_F))/Delta_c)*(Cost_k*Ubar_c+Delay_D+Rho_a*(-Cost_k*Delta_c*Floor_F/Rho_a))/(Ubar_c-Delta_c*F37),IF(F37=Floor_F,Cost_k,EXP(-Rho_a*LN(F37/Floor_F)/Delta_c)*(-Rho_a*(-Cost_k*Delta_c*Floor_F/Rho_a))/(Delta_c*F37))) -> 10.787358 | I37: =ABS(G37-H37) -> 0
A38: 0.36 | B38: =$A$7*EXP(-Delta_c*A38) -> 55.923538 | C38: =$C$7*EXP((Rho_a+Delta_c)*A38) -> 3.8727707 | D38: =IF(B38<Floor_F,EXP(-Rho_a*LN((Top_c-B38)/(Top_c-Floor_F))/Delta_c)*(Cost_k*Ubar_c+Delay_D+Rho_a*(-Cost_k*Delta_c*Floor_F/Rho_a))/(Ubar_c-Delta_c*B38),IF(B38=Floor_F,Cost_k,EXP(-Rho_a*LN(B38/Floor_F)/Delta_c)*(-Rho_a*(-Cost_k*Delta_c*Floor_F/Rho_a))/(Delta_c*B38))) -> 3.8727707 | E38: =ABS(C38-D38) -> 0 | F38: =Top_c-(Top_c-$A$5)*EXP(-Delta_c*A38) -> 54.68265 | G38: =$C$5*EXP((Rho_a+Delta_c)*A38) -> 10.872516 | H38: =IF(F38<Floor_F,EXP(-Rho_a*LN((Top_c-F38)/(Top_c-Floor_F))/Delta_c)*(Cost_k*Ubar_c+Delay_D+Rho_a*(-Cost_k*Delta_c*Floor_F/Rho_a))/(Ubar_c-Delta_c*F38),IF(F38=Floor_F,Cost_k,EXP(-Rho_a*LN(F38/Floor_F)/Delta_c)*(-Rho_a*(-Cost_k*Delta_c*Floor_F/Rho_a))/(Delta_c*F38))) -> 10.872516 | I38: =ABS(G38-H38) -> 0
A39: 0.4 | B39: =$A$7*EXP(-Delta_c*A39) -> 55.697459 | C39: =$C$7*EXP((Rho_a+Delta_c)*A39) -> 3.9033433 | D39: =IF(B39<Floor_F,EXP(-Rho_a*LN((Top_c-B39)/(Top_c-Floor_F))/Delta_c)*(Cost_k*Ubar_c+Delay_D+Rho_a*(-Cost_k*Delta_c*Floor_F/Rho_a))/(Ubar_c-Delta_c*B39),IF(B39=Floor_F,Cost_k,EXP(-Rho_a*LN(B39/Floor_F)/Delta_c)*(-Rho_a*(-Cost_k*Delta_c*Floor_F/Rho_a))/(Delta_c*B39))) -> 3.9033433 | E39: =ABS(C39-D39) -> 0 | F39: =Top_c-(Top_c-$A$5)*EXP(-Delta_c*A39) -> 54.865853 | G39: =$C$5*EXP((Rho_a+Delta_c)*A39) -> 10.958346 | H39: =IF(F39<Floor_F,EXP(-Rho_a*LN((Top_c-F39)/(Top_c-Floor_F))/Delta_c)*(Cost_k*Ubar_c+Delay_D+Rho_a*(-Cost_k*Delta_c*Floor_F/Rho_a))/(Ubar_c-Delta_c*F39),IF(F39=Floor_F,Cost_k,EXP(-Rho_a*LN(F39/Floor_F)/Delta_c)*(-Rho_a*(-Cost_k*Delta_c*Floor_F/Rho_a))/(Delta_c*F39))) -> 10.958346 | I39: =ABS(G39-H39) -> 0
A41: The drift from 58 reaches the floor after 0.524 years, the race from 53 after 0.429: the table stops before either arrives. Along both the costate and the value's slope agree (Theorem 8.1(iii)).

Sheet Scheme
A1: Solve on a grid: the upwind scheme's values on grids of 1 to 1/16 point, against the closed form (Proposition 8.4; Figure 8.1; AXIOM Lab 2.8, step 5)
A2: For the rule policy iteration converges to (race from the never-start edge, hold the floor, drift above it) the upwind equations solve level by level: racing, V_j = (-(k u bar + D) + (f/h) V_j+1)/(rho + f/h), f = u bar - delta c, from the floor down, and no lower than -D/rho; drifting, V_j = (|f|/h) V_j-1/(rho + |f|/h), |f| = delta c, from the floor up. Policy-iteration steps are the engine's.
A4: Grid of 1 point | H4: Grid of 1/2 point | O4: Grid of 1/4 point | V4: Grid of 1/8 point | AC4: Grid of 1/16 point
A5: Spacing h | B5: 1 | H5: Spacing h | I5: 0.5 | O5: Spacing h | P5: 0.25 | V5: Spacing h | W5: 0.125 | AC5: Spacing h | AD5: 0.0625
A6: Levels | B6: =COUNT($A$20:$A$70) -> 51 | H6: Levels | I6: =COUNT($H$20:$H$120) -> 101 | O6: Levels | P6: =COUNT($O$20:$O$220) -> 201 | V6: Levels | W6: =COUNT($V$20:$V$420) -> 401 | AC6: Levels | AD6: =COUNT($AC$20:$AC$820) -> 801
A7: Policy-iteration steps (engine) | B7: 15 | H7: Policy-iteration steps (engine) | I7: 28 | O7: Policy-iteration steps (engine) | P7: 55 | V7: Policy-iteration steps (engine) | W7: 109 | AC7: Policy-iteration steps (engine) | AD7: 216
A8: V(45) | B8: =INDEX($D$20:$D$70,MATCH(45,$A$20:$A$70,0)) -> -322.87269 | H8: V(45) | I8: =INDEX($K$20:$K$120,MATCH(45,$H$20:$H$120,0)) -> -323.65703 | O8: V(45) | P8: =INDEX($R$20:$R$220,MATCH(45,$O$20:$O$220,0)) -> -324.05435 | V8: V(45) | W8: =INDEX($Y$20:$Y$420,MATCH(45,$V$20:$V$420,0)) -> -324.25431 | AC8: V(45) | AD8: =INDEX($AF$20:$AF$820,MATCH(45,$AC$20:$AC$820,0)) -> -324.35462
A9: V(53) | B9: =INDEX($D$20:$D$70,MATCH(53,$A$20:$A$70,0)) -> -254.46393 | H9: V(53) | I9: =INDEX($K$20:$K$120,MATCH(53,$H$20:$H$120,0)) -> -254.67585 | O9: V(53) | P9: =INDEX($R$20:$R$220,MATCH(53,$O$20:$O$220,0)) -> -254.78344 | V9: V(53) | W9: =INDEX($Y$20:$Y$420,MATCH(53,$V$20:$V$420,0)) -> -254.83764 | AC9: V(53) | AD9: =INDEX($AF$20:$AF$820,MATCH(53,$AC$20:$AC$820,0)) -> -254.86484
A10: V(55) | B10: =INDEX($D$20:$D$70,MATCH(55,$A$20:$A$70,0)) -> -233.75962 | H10: V(55) | I10: =INDEX($K$20:$K$120,MATCH(55,$H$20:$H$120,0)) -> -233.75962 | O10: V(55) | P10: =INDEX($R$20:$R$220,MATCH(55,$O$20:$O$220,0)) -> -233.75962 | V10: V(55) | W10: =INDEX($Y$20:$Y$420,MATCH(55,$V$20:$V$420,0)) -> -233.75962 | AC10: V(55) | AD10: =INDEX($AF$20:$AF$820,MATCH(55,$AC$20:$AC$820,0)) -> -233.75962
A11: V(58) | B11: =INDEX($D$20:$D$70,MATCH(58,$A$20:$A$70,0)) -> -222.55056 | H11: V(58) | I11: =INDEX($K$20:$K$120,MATCH(58,$H$20:$H$120,0)) -> -222.45738 | O11: V(58) | P11: =INDEX($R$20:$R$220,MATCH(58,$O$20:$O$220,0)) -> -222.41021 | V11: V(58) | W11: =INDEX($Y$20:$Y$420,MATCH(58,$V$20:$V$420,0)) -> -222.38649 | AC11: V(58) | AD11: =INDEX($AF$20:$AF$820,MATCH(58,$AC$20:$AC$820,0)) -> -222.37458
A12: Largest error at 45, 53, 55, 58 | B12: =MAX(ABS(INDEX($D$20:$D$70,MATCH(45,$A$20:$A$70,0))-INDEX($E$20:$E$70,MATCH(45,$A$20:$A$70,0))),ABS(INDEX($D$20:$D$70,MATCH(53,$A$20:$A$70,0))-INDEX($E$20:$E$70,MATCH(53,$A$20:$A$70,0))),ABS(INDEX($D$20:$D$70,MATCH(55,$A$20:$A$70,0))-INDEX($E$20:$E$70,MATCH(55,$A$20:$A$70,0))),ABS(INDEX($D$20:$D$70,MATCH(58,$A$20:$A$70,0))-INDEX($E$20:$E$70,MATCH(58,$A$20:$A$70,0)))) -> 1.5824661 | H12: Largest error at 45, 53, 55, 58 | I12: =MAX(ABS(INDEX($K$20:$K$120,MATCH(45,$H$20:$H$120,0))-INDEX($L$20:$L$120,MATCH(45,$H$20:$H$120,0))),ABS(INDEX($K$20:$K$120,MATCH(53,$H$20:$H$120,0))-INDEX($L$20:$L$120,MATCH(53,$H$20:$H$120,0))),ABS(INDEX($K$20:$K$120,MATCH(55,$H$20:$H$120,0))-INDEX($L$20:$L$120,MATCH(55,$H$20:$H$120,0))),ABS(INDEX($K$20:$K$120,MATCH(58,$H$20:$H$120,0))-INDEX($L$20:$L$120,MATCH(58,$H$20:$H$120,0)))) -> 0.79812336 | O12: Largest error at 45, 53, 55, 58 | P12: =MAX(ABS(INDEX($R$20:$R$220,MATCH(45,$O$20:$O$220,0))-INDEX($S$20:$S$220,MATCH(45,$O$20:$O$220,0))),ABS(INDEX($R$20:$R$220,MATCH(53,$O$20:$O$220,0))-INDEX($S$20:$S$220,MATCH(53,$O$20:$O$220,0))),ABS(INDEX($R$20:$R$220,MATCH(55,$O$20:$O$220,0))-INDEX($S$20:$S$220,MATCH(55,$O$20:$O$220,0))),ABS(INDEX($R$20:$R$220,MATCH(58,$O$20:$O$220,0))-INDEX($S$20:$S$220,MATCH(58,$O$20:$O$220,0)))) -> 0.40080657 | V12: Largest error at 45, 53, 55, 58 | W12: =MAX(ABS(INDEX($Y$20:$Y$420,MATCH(45,$V$20:$V$420,0))-INDEX($Z$20:$Z$420,MATCH(45,$V$20:$V$420,0))),ABS(INDEX($Y$20:$Y$420,MATCH(53,$V$20:$V$420,0))-INDEX($Z$20:$Z$420,MATCH(53,$V$20:$V$420,0))),ABS(INDEX($Y$20:$Y$420,MATCH(55,$V$20:$V$420,0))-INDEX($Z$20:$Z$420,MATCH(55,$V$20:$V$420,0))),ABS(INDEX($Y$20:$Y$420,MATCH(58,$V$20:$V$420,0))-INDEX($Z$20:$Z$420,MATCH(58,$V$20:$V$420,0)))) -> 0.20084234 | AC12: Largest error at 45, 53, 55, 58 | AD12: =MAX(ABS(INDEX($AF$20:$AF$820,MATCH(45,$AC$20:$AC$820,0))-INDEX($AG$20:$AG$820,MATCH(45,$AC$20:$AC$820,0))),ABS(INDEX($AF$20:$AF$820,MATCH(53,$AC$20:$AC$820,0))-INDEX($AG$20:$AG$820,MATCH(53,$AC$20:$AC$820,0))),ABS(INDEX($AF$20:$AF$820,MATCH(55,$AC$20:$AC$820,0))-INDEX($AG$20:$AG$820,MATCH(55,$AC$20:$AC$820,0))),ABS(INDEX($AF$20:$AF$820,MATCH(58,$AC$20:$AC$820,0))-INDEX($AG$20:$AG$820,MATCH(58,$AC$20:$AC$820,0)))) -> 0.10053129
A13: Largest error over all levels | B13: =MAX($F$20:$F$70) -> 1.6813842 | H13: Largest error over all levels | I13: =MAX($M$20:$M$120) -> 0.87132784 | O13: Largest error over all levels | P13: =MAX($T$20:$T$220) -> 0.43752 | V13: Largest error over all levels | W13: =MAX($AA$20:$AA$420) -> 0.21922696 | AC13: Largest error over all levels | AD13: =MAX($AH$20:$AH$820) -> 0.10973059
A14: at the level | B14: =INDEX($A$20:$A$70,MATCH(MAX($F$20:$F$70),$F$20:$F$70,0)) -> 44 | H14: at the level | I14: =INDEX($H$20:$H$120,MATCH(MAX($M$20:$M$120),$M$20:$M$120,0)) -> 43.5 | O14: at the level | P14: =INDEX($O$20:$O$220,MATCH(MAX($T$20:$T$220),$T$20:$T$220,0)) -> 43.5 | V14: at the level | W14: =INDEX($V$20:$V$420,MATCH(MAX($AA$20:$AA$420),$AA$20:$AA$420,0)) -> 43.5 | AC14: at the level | AD14: =INDEX($AC$20:$AC$820,MATCH(MAX($AH$20:$AH$820),$AH$20:$AH$820,0)) -> 43.5
A15: The race starts from | B15: =_xlfn.MINIFS($A$20:$A$70,$C$20:$C$70,">="&(-Delay_D/Rho_a),$A$20:$A$70,"<"&Floor_F) -> 44 | H15: The race starts from | I15: =_xlfn.MINIFS($H$20:$H$120,$J$20:$J$120,">="&(-Delay_D/Rho_a),$H$20:$H$120,"<"&Floor_F) -> 43.5 | O15: The race starts from | P15: =_xlfn.MINIFS($O$20:$O$220,$Q$20:$Q$220,">="&(-Delay_D/Rho_a),$O$20:$O$220,"<"&Floor_F) -> 43.5 | V15: The race starts from | W15: =_xlfn.MINIFS($V$20:$V$420,$X$20:$X$420,">="&(-Delay_D/Rho_a),$V$20:$V$420,"<"&Floor_F) -> 43.5 | AC15: The race starts from | AD15: =_xlfn.MINIFS($AC$20:$AC$820,$AE$20:$AE$820,">="&(-Delay_D/Rho_a),$AC$20:$AC$820,"<"&Floor_F) -> 43.4375
A16: Price just below the floor | B16: =(D45-D44)/B5 -> 10.566065 | H16: Price just below the floor | I16: =(K70-K69)/I5 -> 10.789145 | O16: Price just below the floor | P16: =(R120-R119)/P5 -> 10.904255 | V16: Price just below the floor | W16: =(Y220-Y219)/W5 -> 10.962736 | AC16: Price just below the floor | AD16: =(AF420-AF419)/AD5 -> 10.992212
A17: Price just above the floor | B17: =(D46-D45)/B5 -> 3.863639 | H17: Price just above the floor | I17: =(K71-K70)/I5 -> 3.9306372 | O17: Price just above the floor | P17: =(R121-R120)/P5 -> 3.9650153 | V17: Price just above the floor | W17: =(Y221-Y220)/W5 -> 3.9824308 | AC17: Price just above the floor | AD17: =(AF421-AF420)/AD5 -> 3.9911961
A19: c | B19: Drift f | C19: V, racing | D19: V, scheme | E19: Closed form | F19: |Error| | H19: c | I19: Drift f | J19: V, racing | K19: V, scheme | L19: Closed form | M19: |Error| | O19: c | P19: Drift f | Q19: V, racing | R19: V, scheme | S19: Closed form | T19: |Error| | V19: c | W19: Drift f | X19: V, racing | Y19: V, scheme | Z19: Closed form | AA19: |Error| | AC19: c | AD19: Drift f | AE19: V, racing | AF19: V, scheme | AG19: Closed form | AH19: |Error|
A20: =30+0*$B$5 -> 30 | B20: =Ubar_c-Delta_c*A20 -> 7.0889862 | C20: =(-(Cost_k*Ubar_c+Delay_D)+B20/$B$5*C21)/(Rho_a+B20/$B$5) -> -410.56255 | D20: =MAX(C20,-Delay_D/Rho_a) -> -335.74588 | E20: =IF(A20<Floor_F,MAX((-(Cost_k*Ubar_c+Delay_D)*(1-EXP(-Rho_a*LN((Top_c-A20)/(Top_c-Floor_F))/Delta_c))/Rho_a+EXP(-Rho_a*LN((Top_c-A20)/(Top_c-Floor_F))/Delta_c)*(-Cost_k*Delta_c*Floor_F/Rho_a)),(-Delay_D/Rho_a)),(EXP(-Rho_a*LN(A20/Floor_F)/Delta_c)*(-Cost_k*Delta_c*Floor_F/Rho_a))) -> -335.74588 | F20: =ABS(D20-E20) -> 0 | H20: =30+0*$I$5 -> 30 | I20: =Ubar_c-Delta_c*H20 -> 7.0889862 | J20: =(-(Cost_k*Ubar_c+Delay_D)+I20/$I$5*J21)/(Rho_a+I20/$I$5) -> -411.79704 | K20: =MAX(J20,-Delay_D/Rho_a) -> -335.74588 | L20: =IF(H20<Floor_F,MAX((-(Cost_k*Ubar_c+Delay_D)*(1-EXP(-Rho_a*LN((Top_c-H20)/(Top_c-Floor_F))/Delta_c))/Rho_a+EXP(-Rho_a*LN((Top_c-H20)/(Top_c-Floor_F))/Delta_c)*(-Cost_k*Delta_c*Floor_F/Rho_a)),(-Delay_D/Rho_a)),(EXP(-Rho_a*LN(H20/Floor_F)/Delta_c)*(-Cost_k*Delta_c*Floor_F/Rho_a))) -> -335.74588 | M20: =ABS(K20-L20) -> 0 | O20: =30+0*$P$5 -> 30 | P20: =Ubar_c-Delta_c*O20 -> 7.0889862 | Q20: =(-(Cost_k*Ubar_c+Delay_D)+P20/$P$5*Q21)/(Rho_a+P20/$P$5) -> -412.42071 | R20: =MAX(Q20,-Delay_D/Rho_a) -> -335.74588 | S20: =IF(O20<Floor_F,MAX((-(Cost_k*Ubar_c+Delay_D)*(1-EXP(-Rho_a*LN((Top_c-O20)/(Top_c-Floor_F))/Delta_c))/Rho_a+EXP(-Rho_a*LN((Top_c-O20)/(Top_c-Floor_F))/Delta_c)*(-Cost_k*Delta_c*Floor_F/Rho_a)),(-Delay_D/Rho_a)),(EXP(-Rho_a*LN(O20/Floor_F)/Delta_c)*(-Cost_k*Delta_c*Floor_F/Rho_a))) -> -335.74588 | T20: =ABS(R20-S20) -> 0 | V20: =30+0*$W$5 -> 30 | W20: =Ubar_c-Delta_c*V20 -> 7.0889862 | X20: =(-(Cost_k*Ubar_c+Delay_D)+W20/$W$5*X21)/(Rho_a+W20/$W$5) -> -412.73416 | Y20: =MAX(X20,-Delay_D/Rho_a) -> -335.74588 | Z20: =IF(V20<Floor_F,MAX((-(Cost_k*Ubar_c+Delay_D)*(1-EXP(-Rho_a*LN((Top_c-V20)/(Top_c-Floor_F))/Delta_c))/Rho_a+EXP(-Rho_a*LN((Top_c-V20)/(Top_c-Floor_F))/Delta_c)*(-Cost_k*Delta_c*Floor_F/Rho_a)),(-Delay_D/Rho_a)),(EXP(-Rho_a*LN(V20/Floor_F)/Delta_c)*(-Cost_k*Delta_c*Floor_F/Rho_a))) -> -335.74588 | AA20: =ABS(Y20-Z20) -> 0 | AC20: =30+0*$AD$5 -> 30 | AD20: =Ubar_c-Delta_c*AC20 -> 7.0889862 | AE20: =(-(Cost_k*Ubar_c+Delay_D)+AD20/$AD$5*AE21)/(Rho_a+AD20/$AD$5) -> -412.8913 | AF20: =MAX(AE20,-Delay_D/Rho_a) -> -335.74588 | AG20: =IF(AC20<Floor_F,MAX((-(Cost_k*Ubar_c+Delay_D)*(1-EXP(-Rho_a*LN((Top_c-AC20)/(Top_c-Floor_F))/Delta_c))/Rho_a+EXP(-Rho_a*LN((Top_c-AC20)/(Top_c-Floor_F))/Delta_c)*(-Cost_k*Delta_c*Floor_F/Rho_a)),(-Delay_D/Rho_a)),(EXP(-Rho_a*LN(AC20/Floor_F)/Delta_c)*(-Cost_k*Delta_c*Floor_F/Rho_a))) -> -335.74588 | AH20: =ABS(AF20-AG20) -> 0
