Workbook

Sheet README
B1: DCT Laboratory — Vol II, Ch 3: Convex Enterprise Optimization
B2: Seed 26203 · Companion to DCT_V2_Ch03_Lab.ipynb and AXIOM Lab 2.3 (module AXIOM-03). Money in $ million, undiscounted.
B4: Worked Example 3.1, How Good Is the Three-Round Plan?, with the book's declarations (Worked Example 2.1's instance, built on Volume I's automation program).
B5: Declarations: the inputs. Recognize: Volume I's form against the exponential form on the chord witnesses, and the CFO's pledge (Step 1).
B6: LumpyPlans: the 64 schedules of rounds by Volume I's recursion and in exponential form, their values at seven credits, and their Lagrangian at Step 3's prices.
B7: Relaxation: the closed form of Online Appendix 3.B.4, the marginal values and prices of Figure 3.3(a), the KKT residuals and the ceiling (Steps 2-3).
B8: Credit: Table 3.5, the bands where the relaxation proves the lumpy plan best, the thresholds, and where rounding fails (Step 5).
B9: CapitalCap: the $360 million cap, its range of prices, and Theorem 3.5(iii)'s bound against re-solves (Step 6).
B10: OA_Cases: the two-channel budget's dual function and a tiered penalty at its kink (Online Appendix 3.B.1-3.B.2; not Meridian).
B11: The barrier method, the random chords and starting plans (seed 26203) and the fine scans of the credit run in the notebook; their results are engine values here.
B12: Reference_Values and Checks: the engine's numbers and a PASS/FAIL comparison with this workbook's formulas.
B14: LEGEND
... B18: Cross-sheet link: green.

Sheet Declarations
A1: Declarations (Worked Example 3.1: Worked Example 2.1's instance, Volume I's automation program). Money in $ million, undiscounted.
A3: Quantity | B3: Value | C3: Source
A4: Cost of a round | B4: 120 | C4: Volume I, Worked Example 6.1
A5: Efficiency ceiling | B5: 85 | C5: A round closes half the gap to it
A6: Operational efficiency today | B6: 71 | C6: Meridian's state
A7: Share of the remaining gap a round closes | B7: 0.5
A8: Savings per efficiency point above today's, a year | B8: 10 | C8: From the year of the round
A9: Liquidity today | B9: 620
A10: The board's floor, after a round and at every year end | B10: 350
A11: End condition: liquidity at the end of year 6, at least | B11: 470 | C11: Another round stays possible
A12: Workforce capability today | B12: 58 | C12: A round raises it by a point
A13: Capability a round needs | B13: 55 | C13: Never binds: capability only rises
A14: Years | B14: 6
A15: Years of year-6 savings credited, M | B15: 10 | C15: Ten years (Worked Example 2.1)
A16: Capital cap (Step 6) | B16: 360 | C16: Three rounds' worth
A17: Efficiency gap today | B17: =Ceil_e-Eff_now -> 14 | C17: 14 points
A18: Savings once efficiency reaches the ceiling, a year | B18: =Val_pt*B17 -> 140 | C18: 140
A19: Slope coefficient, 140 ln 2 | B19: =B18*LN(2) -> 97.040605 | C19: S'(Z) = 97.04 x 2^-Z
A20: Cash paid out with no round, 620 - 470 | B20: =Liq_now-Q_end -> 150
A21: A first round's savings, a year | B21: =Val_pt*Half_g*B17 -> 70 | C21: 70
A23: The relaxation lets rounds be fractions, 0 <= z_k <= 1, and writes the gap after Z rounds to date as 14 x 2^-Z: savings S(Z) = 140 (1 - 2^-Z), identical to Volume I's at every lumpy plan (Step 1).
A24: Liquidity q_k = 620 + sum over j <= k of (S_j - 120 z_j - p_j); the objective is the six-year payout plus M years of the year-6 savings.

Sheet Recognize
A1: Recognize: Volume I's form and the exponential form on the chord witnesses (Worked Example 3.1, Step 1; AXIOM Lab 2.3, step 1)
A2: Volume I's form for fractional rounds multiplies them: year-2 savings 140 (1 - (1 - z1/2)(1 - z2/2)). The exponential form: 140 (1 - 2^-(z1 + z2)).
A4: Plan | B4: z1 | C4: z2 | D4: Year-2 savings, Volume I's form | E4: Year-2 savings, exponential form
A5: a whole round in year 1 | B5: 1 | C5: 0 | D5: =S_max*(1-(1-Half_g*B5)*(1-Half_g*C5)) -> 70 | E5: =S_max*(1-2^(-(B5+C5))) -> 70
A6: a whole round in year 2 | B6: 0 | C6: 1 | D6: =S_max*(1-(1-Half_g*B6)*(1-Half_g*C6)) -> 70 | E6: =S_max*(1-2^(-(B6+C6))) -> 70
A7: two half rounds: their blend | B7: 0.5 | C7: 0.5 | D7: =S_max*(1-(1-Half_g*B7)*(1-Half_g*C7)) -> 61.25 | E7: =S_max*(1-2^(-(B7+C7))) -> 70
A8: no round | B8: 0 | C8: 0 | D8: =S_max*(1-(1-Half_g*B8)*(1-Half_g*C8)) -> 0 | E8: =S_max*(1-2^(-(B8+C8))) -> 0
A9: both rounds | B9: 1 | C9: 1 | D9: =S_max*(1-(1-Half_g*B9)*(1-Half_g*C9)) -> 105 | E9: =S_max*(1-2^(-(B9+C9))) -> 105
A11: The blend of the two whole-round plans is worth (Volume I's form) | B11: =D7 -> 61.25
A12: The blend of their values | B12: =(D5+D6)/2 -> 70
A13: Chord test for concavity, Volume I's form | B13: =IF(B11>=B12-0.000000001,"passes","fails") -> fails
A14: No round and both rounds average | B14: =(D8+D9)/2 -> 52.5
A15: Chord test for convexity, Volume I's form | B15: =IF(B11<=B14+0.000000001,"passes","fails") -> fails
A16: Chord test for concavity, exponential form | B16: =IF(E7>=(E5+E6)/2-0.000000001,"passes","fails") -> passes
A17: Curvature of Volume I's year-2 savings: the cross term | B17: =-S_max*Half_g^2 -> -35
A18: Its eigenvalues: plus and minus the cross term (indefinite) | B18: =ABS(B17) -> 35
A21: The CFO's pledge, p >= S/2 | B21: Rounds to date Z | C21: Payout p | D21: Savings S(Z) | E21: S/2 | F21: Keeps the pledge?
A22: a plan with no round, nothing paid | B22: 0 | C22: 0 | D22: =S_max*(1-2^(-(B22))) -> 0 | E22: =D22/2 -> 0 | F22: =IF(C22>=E22-0.000000001,"yes","no") -> yes
A23: two rounds, half the savings paid | B23: 2 | C23: =E23 -> 52.5 | D23: =S_max*(1-2^(-(B23))) -> 105 | E23: =D23/2 -> 52.5 | F23: =IF(C23>=E23-0.000000001,"yes","no") -> yes
A24: their midpoint | B24: =(B22+B23)/2 -> 1 | C24: =(C22+C23)/2 -> 26.25 | D24: =S_max*(1-2^(-(B24))) -> 70 | E24: =D24/2 -> 35 | F24: =IF(C24>=E24-0.000000001,"yes","no") -> no
A25: Payout the midpoint needs | B25: =E24 -> 35
A26: A concave quantity held below the payout: not convex, and the board dropped the pledge. A cap, p <= S/2, would be convex.
A28: Block of the relaxation | B28: Shape or rule (Table 3.2) | C28: Certificate
A29: rounds 0 <= z_k <= 1 | B29: a box | C29: convex region
A30: gap 14 x 2^-Z_k | B30: an exponential of a sum of decisions | C30: convex
A31: savings S_k = 140 - 10 x gap | B31: a constant less a convex function | C31: concave
A32: liquidity q_k = 620 + sum(S_j - 120 z_j - p_j) | B32: a sum of concave and affine terms | C32: concave
A33: floors q >= 350, after a round and at year end | B33: a concave quantity above a floor | C33: convex commitment
A34: end condition q_6 >= 470 | B34: a concave quantity above a floor | C34: convex commitment
A35: objective: payouts + M S_6 | B35: affine plus concave | C35: concave
A36: CFO's pledge p_k >= S_k / 2 (dropped) | B36: a concave quantity below the payout | C36: not convex

Sheet LumpyPlans
A1: The 64 lumpy plans: Volume I's recursion against the exponential form, their values, and their Lagrangian at Step 3's prices (Steps 1 and 4; AXIOM Lab 2.3, steps 1 and 4)
A2: Each plan pays out everything above $470 million; its value is that payout plus M years of the year-6 savings. Every lumpy plan is a relaxed plan with the same value, so none can exceed the relaxation's ceiling.
A4: Plans that keep the floors, the capability precondition and the end condition | L4: =SUM($AN$17:$AN$80) -> 64
A5: Largest difference between Volume I's savings and the exponential form's | L5: =MAX($Z$17:$Z$80) -> 0
A6: Best value at the declared credit | L6: =MAX($AP$17:$AP$80) -> 1680
A7: Its plan number | L7: =INDEX($A$17:$A$80,MATCH(L6,$AP$17:$AP$80,0)) -> 56
A8: Its rounds | L8: =INDEX($AM$17:$AM$80,MATCH(L6,$AP$17:$AP$80,0)) -> 3
A9: Its payout | L9: =INDEX($AO$17:$AO$80,MATCH(L6,$AP$17:$AP$80,0)) -> 455
A10: Its year-6 savings | L10: =INDEX($S$17:$S$80,MATCH(L6,$AP$17:$AP$80,0)) -> 122.5
A11: Rounded down: three rounds, years 1-3 (plan 56) | L11: =INDEX($AP$17:$AP$80,MATCH(56,$A$17:$A$80,0)) -> 1680
A12: Rounded up: four rounds, years 1-4 (plan 60) | L12: =INDEX($AP$17:$AP$80,MATCH(60,$A$17:$A$80,0)) -> 1673.75
A13: Largest Lagrangian at Step 3's prices: no lumpy plan beats the ceiling | L13: =MAX($AQ$17:$AQ$80) -> 1680
AQ15: credits: | AR15: 0 | AS15: 5 | AT15: 10 | AU15: 20 | AV15: 40 | AW15: 60 | AX15: 54
A16: Plan | B16: z1 | C16: z2 | D16: z3 | E16: z4 | F16: z5 | G16: z6 | H16: Efficiency, year 1 | I16: Efficiency, year 2 | J16: Efficiency, year 3 | K16: Efficiency, year 4 | L16: Efficiency, year 5 | M16: Efficiency, year 6 | N16: Savings, year 1 (Volume I) | O16: Savings, year 2 (Volume I) | P16: Savings, year 3 (Volume I) | Q16: Savings, year 4 (Volume I) | R16: Savings, year 5 (Volume I) | S16: Savings, year 6 (Volume I) | T16: Savings, year 1 (exponential) | U16: Savings, year 2 (exponential) | V16: Savings, year 3 (exponential) | W16: Savings, year 4 (exponential) | X16: Savings, year 5 (exponential) | Y16: Savings, year 6 (exponential) | Z16: Largest difference | AA16: Liquidity after the round, year 1 | AB16: Liquidity after the round, year 2 | AC16: Liquidity after the round, year 3 | AD16: Liquidity after the round, year 4 | AE16: Liquidity after the round, year 5 | AF16: Liquidity after the round, year 6 | AG16: Year-end liquidity, year 1 | AH16: Year-end liquidity, year 2 | AI16: Year-end liquidity, year 3 | AJ16: Year-end liquidity, year 4 | AK16: Year-end liquidity, year 5 | AL16: Year-end liquidity, year 6 | AM16: Rounds | AN16: Keeps every commitment | AO16: Payout (all above 470) | AP16: Value at the declared credit | AQ16: Lagrangian at Step 3's prices | AR16: Value at credit 0 | AS16: Value at credit 5 | AT16: Value at credit 10 | AU16: Value at credit 20 | AV16: Value at credit 40 | AW16: Value at credit 60 | AX16: Value at credit 54
A17: 0 | B17: =MOD(INT($A17/2^5),2) -> 0 | C17: =MOD(INT($A17/2^4),2) -> 0 | D17: =MOD(INT($A17/2^3),2) -> 0 | E17: =MOD(INT($A17/2^2),2) -> 0 | F17: =MOD(INT($A17/2^1),2) -> 0 | G17: =MOD(INT($A17/2^0),2) -> 0 | H17: =Eff_now+B17*Half_g*(Ceil_e-Eff_now) -> 71 | I17: =H17+C17*Half_g*(Ceil_e-H17) -> 71 | J17: =I17+D17*Half_g*(Ceil_e-I17) -> 71 | K17: =J17+E17*Half_g*(Ceil_e-J17) -> 71 | L17: =K17+F17*Half_g*(Ceil_e-K17) -> 71 | M17: =L17+G17*Half_g*(Ceil_e-L17) -> 71 | N17: =Val_pt*(H17-Eff_now) -> 0 | O17: =Val_pt*(I17-Eff_now) -> 0 | P17: =Val_pt*(J17-Eff_now) -> 0 | Q17: =Val_pt*(K17-Eff_now) -> 0 | R17: =Val_pt*(L17-Eff_now) -> 0 | S17: =Val_pt*(M17-Eff_now) -> 0 | T17: =S_max*(1-2^(-(SUM($B17:B17)))) -> 0 | U17: =S_max*(1-2^(-(SUM($B17:C17)))) -> 0 | V17: =S_max*(1-2^(-(SUM($B17:D17)))) -> 0 | W17: =S_max*(1-2^(-(SUM($B17:E17)))) -> 0 | X17: =S_max*(1-2^(-(SUM($B17:F17)))) -> 0 | Y17: =S_max*(1-2^(-(SUM($B17:G17)))) -> 0 | Z17: =MAX(ABS(N17-T17),ABS(O17-U17),ABS(P17-V17),ABS(Q17-W17),ABS(R17-X17),ABS(S17-Y17)) -> 0 | AA17: =Liq_now-Cost_r*B17 -> 620 | AB17: =AG17-Cost_r*C17 -> 620 | AC17: =AH17-Cost_r*D17 -> 620 | AD17: =AI17-Cost_r*E17 -> 620 | AE17: =AJ17-Cost_r*F17 -> 620 | AF17: =AK17-Cost_r*G17 -> 620 | AG17: =AA17+N17 -> 620 | AH17: =AB17+O17 -> 620 | AI17: =AC17+P17 -> 620 | AJ17: =AD17+Q17 -> 620 | AK17: =AE17+R17 -> 620 | AL17: =AF17+S17 -> 620 | AM17: =SUM(B17:G17) -> 0 | AN17: =IF(AND(MIN(AA17:AF17)>=Floor_q,MIN(AG17:AL17)>=Floor_q,AL17>=Q_end,Cap_now>=Cap_min),1,0) -> 1 | AO17: =AL17-Q_end -> 150 | AP17: =IF(AN17=1,AO17+Credit_M*S17,-1000000000) -> 150 | AQ17: =AP17+SUMPRODUCT(Relaxation!$C$23:$H$23,1-B17:G17)+SUMPRODUCT(Relaxation!$C$24:$H$24,B17:G17) -> 283.43083 | AR17: =IF($AN17=1,$AO17+AR$15*$S17,-1000000000) -> 150 | AS17: =IF($AN17=1,$AO17+AS$15*$S17,-1000000000) -> 150 | AT17: =IF($AN17=1,$AO17+AT$15*$S17,-1000000000) -> 150 | AU17: =IF($AN17=1,$AO17+AU$15*$S17,-1000000000) -> 150 | AV17: =IF($AN17=1,$AO17+AV$15*$S17,-1000000000) -> 150 | AW17: =IF($AN17=1,$AO17+AW$15*$S17,-1000000000) -> 150 | AX17: =IF($AN17=1,$AO17+AX$15*$S17,-1000000000) -> 150
A18: 1 | B18: =MOD(INT($A18/2^5),2) -> 0 | C18: =MOD(INT($A18/2^4),2) -> 0 | D18: =MOD(INT($A18/2^3),2) -> 0 | E18: =MOD(INT($A18/2^2),2) -> 0 | F18: =MOD(INT($A18/2^1),2) -> 0 | G18: =MOD(INT($A18/2^0),2) -> 1 | H18: =Eff_now+B18*Half_g*(Ceil_e-Eff_now) -> 71 | I18: =H18+C18*Half_g*(Ceil_e-H18) -> 71 | J18: =I18+D18*Half_g*(Ceil_e-I18) -> 71 | K18: =J18+E18*Half_g*(Ceil_e-J18) -> 71 | L18: =K18+F18*Half_g*(Ceil_e-K18) -> 71 | M18: =L18+G18*Half_g*(Ceil_e-L18) -> 78 | N18: =Val_pt*(H18-Eff_now) -> 0 | O18: =Val_pt*(I18-Eff_now) -> 0 | P18: =Val_pt*(J18-Eff_now) -> 0 | Q18: =Val_pt*(K18-Eff_now) -> 0 | R18: =Val_pt*(L18-Eff_now) -> 0 | S18: =Val_pt*(M18-Eff_now) -> 70 | T18: =S_max*(1-2^(-(SUM($B18:B18)))) -> 0 | U18: =S_max*(1-2^(-(SUM($B18:C18)))) -> 0 | V18: =S_max*(1-2^(-(SUM($B18:D18)))) -> 0 | W18: =S_max*(1-2^(-(SUM($B18:E18)))) -> 0 | X18: =S_max*(1-2^(-(SUM($B18:F18)))) -> 0 | Y18: =S_max*(1-2^(-(SUM($B18:G18)))) -> 70 | Z18: =MAX(ABS(N18-T18),ABS(O18-U18),ABS(P18-V18),ABS(Q18-W18),ABS(R18-X18),ABS(S18-Y18)) -> 0 | AA18: =Liq_now-Cost_r*B18 -> 620 | AB18: =AG18-Cost_r*C18 -> 620 | AC18: =AH18-Cost_r*D18 -> 620 | AD18: =AI18-Cost_r*E18 -> 620 | AE18: =AJ18-Cost_r*F18 -> 620 | AF18: =AK18-Cost_r*G18 -> 500 | AG18: =AA18+N18 -> 620 | AH18: =AB18+O18 -> 620 | AI18: =AC18+P18 -> 620 | AJ18: =AD18+Q18 -> 620 | AK18: =AE18+R18 -> 620 | AL18: =AF18+S18 -> 570 | AM18: =SUM(B18:G18) -> 1 | AN18: =IF(AND(MIN(AA18:AF18)>=Floor_q,MIN(AG18:AL18)>=Floor_q,AL18>=Q_end,Cap_now>=Cap_min),1,0) -> 1 | AO18: =AL18-Q_end -> 100 | AP18: =IF(AN18=1,AO18+Credit_M*S18,-1000000000) -> 800 | AQ18: =AP18+SUMPRODUCT(Relaxation!$C$23:$H$23,1-B18:G18)+SUMPRODUCT(Relaxation!$C$24:$H$24,B18:G18) -> 951.89237 | AR18: =IF($AN18=1,$AO18+AR$15*$S18,-1000000000) -> 100 | AS18: =IF($AN18=1,$AO18+AS$15*$S18,-1000000000) -> 450 | AT18: =IF($AN18=1,$AO18+AT$15*$S18,-1000000000) -> 800 | AU18: =IF($AN18=1,$AO18+AU$15*$S18,-1000000000) -> 1500 | AV18: =IF($AN18=1,$AO18+AV$15*$S18,-1000000000) -> 2900 | AW18: =IF($AN18=1,$AO18+AW$15*$S18,-1000000000) -> 4300 | AX18: =IF($AN18=1,$AO18+AX$15*$S18,-1000000000) -> 3880
A19: 2 | B19: =MOD(INT($A19/2^5),2) -> 0 | C19: =MOD(INT($A19/2^4),2) -> 0 | D19: =MOD(INT($A19/2^3),2) -> 0 | E19: =MOD(INT($A19/2^2),2) -> 0 | F19: =MOD(INT($A19/2^1),2) -> 1 | G19: =MOD(INT($A19/2^0),2) -> 0 | H19: =Eff_now+B19*Half_g*(Ceil_e-Eff_now) -> 71 | I19: =H19+C19*Half_g*(Ceil_e-H19) -> 71 | J19: =I19+D19*Half_g*(Ceil_e-I19) -> 71 | K19: =J19+E19*Half_g*(Ceil_e-J19) -> 71 | L19: =K19+F19*Half_g*(Ceil_e-K19) -> 78 | M19: =L19+G19*Half_g*(Ceil_e-L19) -> 78 | N19: =Val_pt*(H19-Eff_now) -> 0 | O19: =Val_pt*(I19-Eff_now) -> 0 | P19: =Val_pt*(J19-Eff_now) -> 0 | Q19: =Val_pt*(K19-Eff_now) -> 0 | R19: =Val_pt*(L19-Eff_now) -> 70 | S19: =Val_pt*(M19-Eff_now) -> 70 | T19: =S_max*(1-2^(-(SUM($B19:B19)))) -> 0 | U19: =S_max*(1-2^(-(SUM($B19:C19)))) -> 0 | V19: =S_max*(1-2^(-(SUM($B19:D19)))) -> 0 | W19: =S_max*(1-2^(-(SUM($B19:E19)))) -> 0 | X19: =S_max*(1-2^(-(SUM($B19:F19)))) -> 70 | Y19: =S_max*(1-2^(-(SUM($B19:G19)))) -> 70 | Z19: =MAX(ABS(N19-T19),ABS(O19-U19),ABS(P19-V19),ABS(Q19-W19),ABS(R19-X19),ABS(S19-Y19)) -> 0 | AA19: =Liq_now-Cost_r*B19 -> 620 | AB19: =AG19-Cost_r*C19 -> 620 | AC19: =AH19-Cost_r*D19 -> 620 | AD19: =AI19-Cost_r*E19 -> 620 | AE19: =AJ19-Cost_r*F19 -> 500 | AF19: =AK19-Cost_r*G19 -> 570 | AG19: =AA19+N19 -> 620 | AH19: =AB19+O19 -> 620 | AI19: =AC19+P19 -> 620 | AJ19: =AD19+Q19 -> 620 | AK19: =AE19+R19 -> 570 | AL19: =AF19+S19 -> 640 | AM19: =SUM(B19:G19) -> 1 | AN19: =IF(AND(MIN(AA19:AF19)>=Floor_q,MIN(AG19:AL19)>=Floor_q,AL19>=Q_end,Cap_now>=Cap_min),1,0) -> 1 | AO19: =AL19-Q_end -> 170 | AP19: =IF(AN19=1,AO19+Credit_M*S19,-1000000000) -> 870 | AQ19: =AP19+SUMPRODUCT(Relaxation!$C$23:$H$23,1-B19:G19)+SUMPRODUCT(Relaxation!$C$24:$H$24,B19:G19) -> 1012.6616 | AR19: =IF($AN19=1,$AO19+AR$15*$S19,-1000000000) -> 170 | AS19: =IF($AN19=1,$AO19+AS$15*$S19,-1000000000) -> 520 | AT19: =IF($AN19=1,$AO19+AT$15*$S19,-1000000000) -> 870 | AU19: =IF($AN19=1,$AO19+AU$15*$S19,-1000000000) -> 1570 | AV19: =IF($AN19=1,$AO19+AV$15*$S19,-1000000000) -> 2970 | AW19: =IF($AN19=1,$AO19+AW$15*$S19,-1000000000) -> 4370 | AX19: =IF($AN19=1,$AO19+AX$15*$S19,-1000000000) -> 3950
A20: 3 | B20: =MOD(INT($A20/2^5),2) -> 0 | C20: =MOD(INT($A20/2^4),2) -> 0 | D20: =MOD(INT($A20/2^3),2) -> 0 | E20: =MOD(INT($A20/2^2),2) -> 0 | F20: =MOD(INT($A20/2^1),2) -> 1 | G20: =MOD(INT($A20/2^0),2) -> 1 | H20: =Eff_now+B20*Half_g*(Ceil_e-Eff_now) -> 71 | I20: =H20+C20*Half_g*(Ceil_e-H20) -> 71 | J20: =I20+D20*Half_g*(Ceil_e-I20) -> 71 | K20: =J20+E20*Half_g*(Ceil_e-J20) -> 71 | L20: =K20+F20*Half_g*(Ceil_e-K20) -> 78 | M20: =L20+G20*Half_g*(Ceil_e-L20) -> 81.5 | N20: =Val_pt*(H20-Eff_now) -> 0 | O20: =Val_pt*(I20-Eff_now) -> 0 | P20: =Val_pt*(J20-Eff_now) -> 0 | Q20: =Val_pt*(K20-Eff_now) -> 0 | R20: =Val_pt*(L20-Eff_now) -> 70 | S20: =Val_pt*(M20-Eff_now) -> 105 | T20: =S_max*(1-2^(-(SUM($B20:B20)))) -> 0 | U20: =S_max*(1-2^(-(SUM($B20:C20)))) -> 0 | V20: =S_max*(1-2^(-(SUM($B20:D20)))) -> 0 | W20: =S_max*(1-2^(-(SUM($B20:E20)))) -> 0 | X20: =S_max*(1-2^(-(SUM($B20:F20)))) -> 70 | Y20: =S_max*(1-2^(-(SUM($B20:G20)))) -> 105 | Z20: =MAX(ABS(N20-T20),ABS(O20-U20),ABS(P20-V20),ABS(Q20-W20),ABS(R20-X20),ABS(S20-Y20)) -> 0 | AA20: =Liq_now-Cost_r*B20 -> 620 | AB20: =AG20-Cost_r*C20 -> 620 | AC20: =AH20-Cost_r*D20 -> 620 | AD20: =AI20-Cost_r*E20 -> 620 | AE20: =AJ20-Cost_r*F20 -> 500 | AF20: =AK20-Cost_r*G20 -> 450 | AG20: =AA20+N20 -> 620 | AH20: =AB20+O20 -> 620 | AI20: =AC20+P20 -> 620 | AJ20: =AD20+Q20 -> 620 | AK20: =AE20+R20 -> 570 | AL20: =AF20+S20 -> 555 | AM20: =SUM(B20:G20) -> 2 | AN20: =IF(AND(MIN(AA20:AF20)>=Floor_q,MIN(AG20:AL20)>=Floor_q,AL20>=Q_end,Cap_now>=Cap_min),1,0) -> 1 | AO20: =AL20-Q_end -> 85 | AP20: =IF(AN20=1,AO20+Credit_M*S20,-1000000000) -> 1135 | AQ20: =AP20+SUMPRODUCT(Relaxation!$C$23:$H$23,1-B20:G20)+SUMPRODUCT(Relaxation!$C$24:$H$24,B20:G20) -> 1296.1231 | AR20: =IF($AN20=1,$AO20+AR$15*$S20,-1000000000) -> 85 | AS20: =IF($AN20=1,$AO20+AS$15*$S20,-1000000000) -> 610 | AT20: =IF($AN20=1,$AO20+AT$15*$S20,-1000000000) -> 1135 | AU20: =IF($AN20=1,$AO20+AU$15*$S20,-1000000000) -> 2185 | AV20: =IF($AN20=1,$AO20+AV$15*$S20,-1000000000) -> 4285 | AW20: =IF($AN20=1,$AO20+AW$15*$S20,-1000000000) -> 6385 | AX20: =IF($AN20=1,$AO20+AX$15*$S20,-1000000000) -> 5755
A21: 4 | B21: =MOD(INT($A21/2^5),2) -> 0 | C21: =MOD(INT($A21/2^4),2) -> 0 | D21: =MOD(INT($A21/2^3),2) -> 0 | E21: =MOD(INT($A21/2^2),2) -> 1 | F21: =MOD(INT($A21/2^1),2) -> 0 | G21: =MOD(INT($A21/2^0),2) -> 0 | H21: =Eff_now+B21*Half_g*(Ceil_e-Eff_now) -> 71 | I21: =H21+C21*Half_g*(Ceil_e-H21) -> 71 | J21: =I21+D21*Half_g*(Ceil_e-I21) -> 71 | K21: =J21+E21*Half_g*(Ceil_e-J21) -> 78 | L21: =K21+F21*Half_g*(Ceil_e-K21) -> 78 | M21: =L21+G21*Half_g*(Ceil_e-L21) -> 78 | N21: =Val_pt*(H21-Eff_now) -> 0 | O21: =Val_pt*(I21-Eff_now) -> 0 | P21: =Val_pt*(J21-Eff_now) -> 0 | Q21: =Val_pt*(K21-Eff_now) -> 70 | R21: =Val_pt*(L21-Eff_now) -> 70 | S21: =Val_pt*(M21-Eff_now) -> 70 | T21: =S_max*(1-2^(-(SUM($B21:B21)))) -> 0 | U21: =S_max*(1-2^(-(SUM($B21:C21)))) -> 0 | V21: =S_max*(1-2^(-(SUM($B21:D21)))) -> 0 | W21: =S_max*(1-2^(-(SUM($B21:E21)))) -> 70 | X21: =S_max*(1-2^(-(SUM($B21:F21)))) -> 70 | Y21: =S_max*(1-2^(-(SUM($B21:G21)))) -> 70 | Z21: =MAX(ABS(N21-T21),ABS(O21-U21),ABS(P21-V21),ABS(Q21-W21),ABS(R21-X21),ABS(S21-Y21)) -> 0 | AA21: =Liq_now-Cost_r*B21 -> 620 | AB21: =AG21-Cost_r*C21 -> 620 | AC21: =AH21-Cost_r*D21 -> 620 | AD21: =AI21-Cost_r*E21 -> 500 | AE21: =AJ21-Cost_r*F21 -> 570 | AF21: =AK21-Cost_r*G21 -> 640 | AG21: =AA21+N21 -> 620 | AH21: =AB21+O21 -> 620 | AI21: =AC21+P21 -> 620 | AJ21: =AD21+Q21 -> 570 | AK21: =AE21+R21 -> 640 | AL21: =AF21+S21 -> 710 | AM21: =SUM(B21:G21) -> 1 | AN21: =IF(AND(MIN(AA21:AF21)>=Floor_q,MIN(AG21:AL21)>=Floor_q,AL21>=Q_end,Cap_now>=Cap_min),1,0) -> 1 | AO21: =AL21-Q_end -> 240 | AP21: =IF(AN21=1,AO21+Credit_M*S21,-1000000000) -> 940 | AQ21: =AP21+SUMPRODUCT(Relaxation!$C$23:$H$23,1-B21:G21)+SUMPRODUCT(Relaxation!$C$24:$H$24,B21:G21) -> 1073.4308 | AR21: =IF($AN21=1,$AO21+AR$15*$S21,-1000000000) -> 240 | AS21: =IF($AN21=1,$AO21+AS$15*$S21,-1000000000) -> 590 | AT21: =IF($AN21=1,$AO21+AT$15*$S21,-1000000000) -> 940 | AU21: =IF($AN21=1,$AO21+AU$15*$S21,-1000000000) -> 1640 | AV21: =IF($AN21=1,$AO21+AV$15*$S21,-1000000000) -> 3040 | AW21: =IF($AN21=1,$AO21+AW$15*$S21,-1000000000) -> 4440 | AX21: =IF($AN21=1,$AO21+AX$15*$S21,-1000000000) -> 4020
A22: 5 | B22: =MOD(INT($A22/2^5),2) -> 0 | C22: =MOD(INT($A22/2^4),2) -> 0 | D22: =MOD(INT($A22/2^3),2) -> 0 | E22: =MOD(INT($A22/2^2),2) -> 1 | F22: =MOD(INT($A22/2^1),2) -> 0 | G22: =MOD(INT($A22/2^0),2) -> 1 | H22: =Eff_now+B22*Half_g*(Ceil_e-Eff_now) -> 71 | I22: =H22+C22*Half_g*(Ceil_e-H22) -> 71 | J22: =I22+D22*Half_g*(Ceil_e-I22) -> 71 | K22: =J22+E22*Half_g*(Ceil_e-J22) -> 78 | L22: =K22+F22*Half_g*(Ceil_e-K22) -> 78 | M22: =L22+G22*Half_g*(Ceil_e-L22) -> 81.5 | N22: =Val_pt*(H22-Eff_now) -> 0 | O22: =Val_pt*(I22-Eff_now) -> 0 | P22: =Val_pt*(J22-Eff_now) -> 0 | Q22: =Val_pt*(K22-Eff_now) -> 70 | R22: =Val_pt*(L22-Eff_now) -> 70 | S22: =Val_pt*(M22-Eff_now) -> 105 | T22: =S_max*(1-2^(-(SUM($B22:B22)))) -> 0 | U22: =S_max*(1-2^(-(SUM($B22:C22)))) -> 0 | V22: =S_max*(1-2^(-(SUM($B22:D22)))) -> 0 | W22: =S_max*(1-2^(-(SUM($B22:E22)))) -> 70 | X22: =S_max*(1-2^(-(SUM($B22:F22)))) -> 70 | Y22: =S_max*(1-2^(-(SUM($B22:G22)))) -> 105 | Z22: =MAX(ABS(N22-T22),ABS(O22-U22),ABS(P22-V22),ABS(Q22-W22),ABS(R22-X22),ABS(S22-Y22)) -> 0 | AA22: =Liq_now-Cost_r*B22 -> 620 | AB22: =AG22-Cost_r*C22 -> 620 | AC22: =AH22-Cost_r*D22 -> 620 | AD22: =AI22-Cost_r*E22 -> 500 | AE22: =AJ22-Cost_r*F22 -> 570 | AF22: =AK22-Cost_r*G22 -> 520 | AG22: =AA22+N22 -> 620 | AH22: =AB22+O22 -> 620 | AI22: =AC22+P22 -> 620 | AJ22: =AD22+Q22 -> 570 | AK22: =AE22+R22 -> 640 | AL22: =AF22+S22 -> 625 | AM22: =SUM(B22:G22) -> 2 | AN22: =IF(AND(MIN(AA22:AF22)>=Floor_q,MIN(AG22:AL22)>=Floor_q,AL22>=Q_end,Cap_now>=Cap_min),1,0) -> 1 | AO22: =AL22-Q_end -> 155 | AP22: =IF(AN22=1,AO22+Credit_M*S22,-1000000000) -> 1205 | AQ22: =AP22+SUMPRODUCT(Relaxation!$C$23:$H$23,1-B22:G22)+SUMPRODUCT(Relaxation!$C$24:$H$24,B22:G22) -> 1356.8924 | AR22: =IF($AN22=1,$AO22+AR$15*$S22,-1000000000) -> 155 | AS22: =IF($AN22=1,$AO22+AS$15*$S22,-1000000000) -> 680 | AT22: =IF($AN22=1,$AO22+AT$15*$S22,-1000000000) -> 1205 | AU22: =IF($AN22=1,$AO22+AU$15*$S22,-1000000000) -> 2255 | AV22: =IF($AN22=1,$AO22+AV$15*$S22,-1000000000) -> 4355 | AW22: =IF($AN22=1,$AO22+AW$15*$S22,-1000000000) -> 6455 | AX22: =IF($AN22=1,$AO22+AX$15*$S22,-1000000000) -> 5825
A23: 6 | B23: =MOD(INT($A23/2^5),2) -> 0 | C23: =MOD(INT($A23/2^4),2) -> 0 | D23: =MOD(INT($A23/2^3),2) -> 0 | E23: =MOD(INT($A23/2^2),2) -> 1 | F23: =MOD(INT($A23/2^1),2) -> 1 | G23: =MOD(INT($A23/2^0),2) -> 0 | H23: =Eff_now+B23*Half_g*(Ceil_e-Eff_now) -> 71 | I23: =H23+C23*Half_g*(Ceil_e-H23) -> 71 | J23: =I23+D23*Half_g*(Ceil_e-I23) -> 71 | K23: =J23+E23*Half_g*(Ceil_e-J23) -> 78 | L23: =K23+F23*Half_g*(Ceil_e-K23) -> 81.5 | M23: =L23+G23*Half_g*(Ceil_e-L23) -> 81.5 | N23: =Val_pt*(H23-Eff_now) -> 0 | O23: =Val_pt*(I23-Eff_now) -> 0 | P23: =Val_pt*(J23-Eff_now) -> 0 | Q23: =Val_pt*(K23-Eff_now) -> 70 | R23: =Val_pt*(L23-Eff_now) -> 105 | S23: =Val_pt*(M23-Eff_now) -> 105 | T23: =S_max*(1-2^(-(SUM($B23:B23)))) -> 0 | U23: =S_max*(1-2^(-(SUM($B23:C23)))) -> 0 | V23: =S_max*(1-2^(-(SUM($B23:D23)))) -> 0 | W23: =S_max*(1-2^(-(SUM($B23:E23)))) -> 70 | X23: =S_max*(1-2^(-(SUM($B23:F23)))) -> 105 | Y23: =S_max*(1-2^(-(SUM($B23:G23)))) -> 105 | Z23: =MAX(ABS(N23-T23),ABS(O23-U23),ABS(P23-V23),ABS(Q23-W23),ABS(R23-X23),ABS(S23-Y23)) -> 0 | AA23: =Liq_now-Cost_r*B23 -> 620 | AB23: =AG23-Cost_r*C23 -> 620 | AC23: =AH23-Cost_r*D23 -> 620 | AD23: =AI23-Cost_r*E23 -> 500 | AE23: =AJ23-Cost_r*F23 -> 450 | AF23: =AK23-Cost_r*G23 -> 555 | AG23: =AA23+N23 -> 620 | AH23: =AB23+O23 -> 620 | AI23: =AC23+P23 -> 620 | AJ23: =AD23+Q23 -> 570 | AK23: =AE23+R23 -> 555 | AL23: =AF23+S23 -> 660 | AM23: =SUM(B23:G23) -> 2 | AN23: =IF(AND(MIN(AA23:AF23)>=Floor_q,MIN(AG23:AL23)>=Floor_q,AL23>=Q_end,Cap_now>=Cap_min),1,0) -> 1 | AO23: =AL23-Q_end -> 190 | AP23: =IF(AN23=1,AO23+Credit_M*S23,-1000000000) -> 1240 | AQ23: =AP23+SUMPRODUCT(Relaxation!$C$23:$H$23,1-B23:G23)+SUMPRODUCT(Relaxation!$C$24:$H$24,B23:G23) -> 1382.6616 | AR23: =IF($AN23=1,$AO23+AR$15*$S23,-1000000000) -> 190 | AS23: =IF($AN23=1,$AO23+AS$15*$S23,-1000000000) -> 715 | AT23: =IF($AN23=1,$AO23+AT$15*$S23,-1000000000) -> 1240 | AU23: =IF($AN23=1,$AO23+AU$15*$S23,-1000000000) -> 2290 | AV23: =IF($AN23=1,$AO23+AV$15*$S23,-1000000000) -> 4390 | AW23: =IF($AN23=1,$AO23+AW$15*$S23,-1000000000) -> 6490 | AX23: =IF($AN23=1,$AO23+AX$15*$S23,-1000000000) -> 5860
A24: 7 | B24: =MOD(INT($A24/2^5),2) -> 0 | C24: =MOD(INT($A24/2^4),2) -> 0 | D24: =MOD(INT($A24/2^3),2) -> 0 | E24: =MOD(INT($A24/2^2),2) -> 1 | F24: =MOD(INT($A24/2^1),2) -> 1 | G24: =MOD(INT($A24/2^0),2) -> 1 | H24: =Eff_now+B24*Half_g*(Ceil_e-Eff_now) -> 71 | I24: =H24+C24*Half_g*(Ceil_e-H24) -> 71 | J24: =I24+D24*Half_g*(Ceil_e-I24) -> 71 | K24: =J24+E24*Half_g*(Ceil_e-J24) -> 78 | L24: =K24+F24*Half_g*(Ceil_e-K24) -> 81.5 | M24: =L24+G24*Half_g*(Ceil_e-L24) -> 83.25 | N24: =Val_pt*(H24-Eff_now) -> 0 | O24: =Val_pt*(I24-Eff_now) -> 0 | P24: =Val_pt*(J24-Eff_now) -> 0 | Q24: =Val_pt*(K24-Eff_now) -> 70 | R24: =Val_pt*(L24-Eff_now) -> 105 | S24: =Val_pt*(M24-Eff_now) -> 122.5 | T24: =S_max*(1-2^(-(SUM($B24:B24)))) -> 0 | U24: =S_max*(1-2^(-(SUM($B24:C24)))) -> 0 | V24: =S_max*(1-2^(-(SUM($B24:D24)))) -> 0 | W24: =S_max*(1-2^(-(SUM($B24:E24)))) -> 70 | X24: =S_max*(1-2^(-(SUM($B24:F24)))) -> 105 | Y24: =S_max*(1-2^(-(SUM($B24:G24)))) -> 122.5 | Z24: =MAX(ABS(N24-T24),ABS(O24-U24),ABS(P24-V24),ABS(Q24-W24),ABS(R24-X24),ABS(S24-Y24)) -> 0 | AA24: =Liq_now-Cost_r*B24 -> 620 | AB24: =AG24-Cost_r*C24 -> 620 | AC24: =AH24-Cost_r*D24 -> 620 | AD24: =AI24-Cost_r*E24 -> 500 | AE24: =AJ24-Cost_r*F24 -> 450 | AF24: =AK24-Cost_r*G24 -> 435 | AG24: =AA24+N24 -> 620 | AH24: =AB24+O24 -> 620 | AI24: =AC24+P24 -> 620 | AJ24: =AD24+Q24 -> 570 | AK24: =AE24+R24 -> 555 | AL24: =AF24+S24 -> 557.5 | AM24: =SUM(B24:G24) -> 3 | AN24: =IF(AND(MIN(AA24:AF24)>=Floor_q,MIN(AG24:AL24)>=Floor_q,AL24>=Q_end,Cap_now>=Cap_min),1,0) -> 1 | AO24: =AL24-Q_end -> 87.5 | AP24: =IF(AN24=1,AO24+Credit_M*S24,-1000000000) -> 1312.5 | AQ24: =AP24+SUMPRODUCT(Relaxation!$C$23:$H$23,1-B24:G24)+SUMPRODUCT(Relaxation!$C$24:$H$24,B24:G24) -> 1473.6231 | AR24: =IF($AN24=1,$AO24+AR$15*$S24,-1000000000) -> 87.5 | AS24: =IF($AN24=1,$AO24+AS$15*$S24,-1000000000) -> 700 | AT24: =IF($AN24=1,$AO24+AT$15*$S24,-1000000000) -> 1312.5 | AU24: =IF($AN24=1,$AO24+AU$15*$S24,-1000000000) -> 2537.5 | AV24: =IF($AN24=1,$AO24+AV$15*$S24,-1000000000) -> 4987.5 | AW24: =IF($AN24=1,$AO24+AW$15*$S24,-1000000000) -> 7437.5 | AX24: =IF($AN24=1,$AO24+AX$15*$S24,-1000000000) -> 6702.5
A25: 8 | B25: =MOD(INT($A25/2^5),2) -> 0 | C25: =MOD(INT($A25/2^4),2) -> 0 | D25: =MOD(INT($A25/2^3),2) -> 1 | E25: =MOD(INT($A25/2^2),2) -> 0 | F25: =MOD(INT($A25/2^1),2) -> 0 | G25: =MOD(INT($A25/2^0),2) -> 0 | H25: =Eff_now+B25*Half_g*(Ceil_e-Eff_now) -> 71 | I25: =H25+C25*Half_g*(Ceil_e-H25) -> 71 | J25: =I25+D25*Half_g*(Ceil_e-I25) -> 78 | K25: =J25+E25*Half_g*(Ceil_e-J25) -> 78 | L25: =K25+F25*Half_g*(Ceil_e-K25) -> 78 | M25: =L25+G25*Half_g*(Ceil_e-L25) -> 78 | N25: =Val_pt*(H25-Eff_now) -> 0 | O25: =Val_pt*(I25-Eff_now) -> 0 | P25: =Val_pt*(J25-Eff_now) -> 70 | Q25: =Val_pt*(K25-Eff_now) -> 70 | R25: =Val_pt*(L25-Eff_now) -> 70 | S25: =Val_pt*(M25-Eff_now) -> 70 | T25: =S_max*(1-2^(-(SUM($B25:B25)))) -> 0 | U25: =S_max*(1-2^(-(SUM($B25:C25)))) -> 0 | V25: =S_max*(1-2^(-(SUM($B25:D25)))) -> 70 | W25: =S_max*(1-2^(-(SUM($B25:E25)))) -> 70 | X25: =S_max*(1-2^(-(SUM($B25:F25)))) -> 70 | Y25: =S_max*(1-2^(-(SUM($B25:G25)))) -> 70 | Z25: =MAX(ABS(N25-T25),ABS(O25-U25),ABS(P25-V25),ABS(Q25-W25),ABS(R25-X25),ABS(S25-Y25)) -> 0 | AA25: =Liq_now-Cost_r*B25 -> 620 | AB25: =AG25-Cost_r*C25 -> 620 | AC25: =AH25-Cost_r*D25 -> 500 | AD25: =AI25-Cost_r*E25 -> 570 | AE25: =AJ25-Cost_r*F25 -> 640 | AF25: =AK25-Cost_r*G25 -> 710 | AG25: =AA25+N25 -> 620 | AH25: =AB25+O25 -> 620 | AI25: =AC25+P25 -> 570 | AJ25: =AD25+Q25 -> 640 | AK25: =AE25+R25 -> 710 | AL25: =AF25+S25 -> 780 | AM25: =SUM(B25:G25) -> 1 | AN25: =IF(AND(MIN(AA25:AF25)>=Floor_q,MIN(AG25:AL25)>=Floor_q,AL25>=Q_end,Cap_now>=Cap_min),1,0) -> 1 | AO25: =AL25-Q_end -> 310 | AP25: =IF(AN25=1,AO25+Credit_M*S25,-1000000000) -> 1010 | AQ25: =AP25+SUMPRODUCT(Relaxation!$C$23:$H$23,1-B25:G25)+SUMPRODUCT(Relaxation!$C$24:$H$24,B25:G25) -> 1131.3008 | AR25: =IF($AN25=1,$AO25+AR$15*$S25,-1000000000) -> 310 | AS25: =IF($AN25=1,$AO25+AS$15*$S25,-1000000000) -> 660 | AT25: =IF($AN25=1,$AO25+AT$15*$S25,-1000000000) -> 1010 | AU25: =IF($AN25=1,$AO25+AU$15*$S25,-1000000000) -> 1710 | AV25: =IF($AN25=1,$AO25+AV$15*$S25,-1000000000) -> 3110 | AW25: =IF($AN25=1,$AO25+AW$15*$S25,-1000000000) -> 4510 | AX25: =IF($AN25=1,$AO25+AX$15*$S25,-1000000000) -> 4090
A26: 9 | B26: =MOD(INT($A26/2^5),2) -> 0 | C26: =MOD(INT($A26/2^4),2) -> 0 | D26: =MOD(INT($A26/2^3),2) -> 1 | E26: =MOD(INT($A26/2^2),2) -> 0 | F26: =MOD(INT($A26/2^1),2) -> 0 | G26: =MOD(INT($A26/2^0),2) -> 1 | H26: =Eff_now+B26*Half_g*(Ceil_e-Eff_now) -> 71 | I26: =H26+C26*Half_g*(Ceil_e-H26) -> 71 | J26: =I26+D26*Half_g*(Ceil_e-I26) -> 78 | K26: =J26+E26*Half_g*(Ceil_e-J26) -> 78 | L26: =K26+F26*Half_g*(Ceil_e-K26) -> 78 | M26: =L26+G26*Half_g*(Ceil_e-L26) -> 81.5 | N26: =Val_pt*(H26-Eff_now) -> 0 | O26: =Val_pt*(I26-Eff_now) -> 0 | P26: =Val_pt*(J26-Eff_now) -> 70 | Q26: =Val_pt*(K26-Eff_now) -> 70 | R26: =Val_pt*(L26-Eff_now) -> 70 | S26: =Val_pt*(M26-Eff_now) -> 105 | T26: =S_max*(1-2^(-(SUM($B26:B26)))) -> 0 | U26: =S_max*(1-2^(-(SUM($B26:C26)))) -> 0 | V26: =S_max*(1-2^(-(SUM($B26:D26)))) -> 70 | W26: =S_max*(1-2^(-(SUM($B26:E26)))) -> 70 | X26: =S_max*(1-2^(-(SUM($B26:F26)))) -> 70 | Y26: =S_max*(1-2^(-(SUM($B26:G26)))) -> 105 | Z26: =MAX(ABS(N26-T26),ABS(O26-U26),ABS(P26-V26),ABS(Q26-W26),ABS(R26-X26),ABS(S26-Y26)) -> 0 | AA26: =Liq_now-Cost_r*B26 -> 620 | AB26: =AG26-Cost_r*C26 -> 620 | AC26: =AH26-Cost_r*D26 -> 500 | AD26: =AI26-Cost_r*E26 -> 570 | AE26: =AJ26-Cost_r*F26 -> 640 | AF26: =AK26-Cost_r*G26 -> 590 | AG26: =AA26+N26 -> 620 | AH26: =AB26+O26 -> 620 | AI26: =AC26+P26 -> 570 | AJ26: =AD26+Q26 -> 640 | AK26: =AE26+R26 -> 710 | AL26: =AF26+S26 -> 695 | AM26: =SUM(B26:G26) -> 2 | AN26: =IF(AND(MIN(AA26:AF26)>=Floor_q,MIN(AG26:AL26)>=Floor_q,AL26>=Q_end,Cap_now>=Cap_min),1,0) -> 1 | AO26: =AL26-Q_end -> 225 | AP26: =IF(AN26=1,AO26+Credit_M*S26,-1000000000) -> 1275 | AQ26: =AP26+SUMPRODUCT(Relaxation!$C$23:$H$23,1-B26:G26)+SUMPRODUCT(Relaxation!$C$24:$H$24,B26:G26) -> 1414.7623 | AR26: =IF($AN26=1,$AO26+AR$15*$S26,-1000000000) -> 225 | AS26: =IF($AN26=1,$AO26+AS$15*$S26,-1000000000) -> 750 | AT26: =IF($AN26=1,$AO26+AT$15*$S26,-1000000000) -> 1275 | AU26: =IF($AN26=1,$AO26+AU$15*$S26,-1000000000) -> 2325 | AV26: =IF($AN26=1,$AO26+AV$15*$S26,-1000000000) -> 4425 | AW26: =IF($AN26=1,$AO26+AW$15*$S26,-1000000000) -> 6525 | AX26: =IF($AN26=1,$AO26+AX$15*$S26,-1000000000) -> 5895
A27: 10 | B27: =MOD(INT($A27/2^5),2) -> 0 | C27: =MOD(INT($A27/2^4),2) -> 0 | D27: =MOD(INT($A27/2^3),2) -> 1 | E27: =MOD(INT($A27/2^2),2) -> 0 | F27: =MOD(INT($A27/2^1),2) -> 1 | G27: =MOD(INT($A27/2^0),2) -> 0 | H27: =Eff_now+B27*Half_g*(Ceil_e-Eff_now) -> 71 | I27: =H27+C27*Half_g*(Ceil_e-H27) -> 71 | J27: =I27+D27*Half_g*(Ceil_e-I27) -> 78 | K27: =J27+E27*Half_g*(Ceil_e-J27) -> 78 | L27: =K27+F27*Half_g*(Ceil_e-K27) -> 81.5 | M27: =L27+G27*Half_g*(Ceil_e-L27) -> 81.5 | N27: =Val_pt*(H27-Eff_now) -> 0 | O27: =Val_pt*(I27-Eff_now) -> 0 | P27: =Val_pt*(J27-Eff_now) -> 70 | Q27: =Val_pt*(K27-Eff_now) -> 70 | R27: =Val_pt*(L27-Eff_now) -> 105 | S27: =Val_pt*(M27-Eff_now) -> 105 | T27: =S_max*(1-2^(-(SUM($B27:B27)))) -> 0 | U27: =S_max*(1-2^(-(SUM($B27:C27)))) -> 0 | V27: =S_max*(1-2^(-(SUM($B27:D27)))) -> 70 | W27: =S_max*(1-2^(-(SUM($B27:E27)))) -> 70 | X27: =S_max*(1-2^(-(SUM($B27:F27)))) -> 105 | Y27: =S_max*(1-2^(-(SUM($B27:G27)))) -> 105 | Z27: =MAX(ABS(N27-T27),ABS(O27-U27),ABS(P27-V27),ABS(Q27-W27),ABS(R27-X27),ABS(S27-Y27)) -> 0 | AA27: =Liq_now-Cost_r*B27 -> 620 | AB27: =AG27-Cost_r*C27 -> 620 | AC27: =AH27-Cost_r*D27 -> 500 | AD27: =AI27-Cost_r*E27 -> 570 | AE27: =AJ27-Cost_r*F27 -> 520 | AF27: =AK27-Cost_r*G27 -> 625 | AG27: =AA27+N27 -> 620 | AH27: =AB27+O27 -> 620 | AI27: =AC27+P27 -> 570 | AJ27: =AD27+Q27 -> 640 | AK27: =AE27+R27 -> 625 | AL27: =AF27+S27 -> 730 | AM27: =SUM(B27:G27) -> 2 | AN27: =IF(AND(MIN(AA27:AF27)>=Floor_q,MIN(AG27:AL27)>=Floor_q,AL27>=Q_end,Cap_now>=Cap_min),1,0) -> 1 | AO27: =AL27-Q_end -> 260 | AP27: =IF(AN27=1,AO27+Credit_M*S27,-1000000000) -> 1310 | AQ27: =AP27+SUMPRODUCT(Relaxation!$C$23:$H$23,1-B27:G27)+SUMPRODUCT(Relaxation!$C$24:$H$24,B27:G27) -> 1440.5315 | AR27: =IF($AN27=1,$AO27+AR$15*$S27,-1000000000) -> 260 | AS27: =IF($AN27=1,$AO27+AS$15*$S27,-1000000000) -> 785 | AT27: =IF($AN27=1,$AO27+AT$15*$S27,-1000000000) -> 1310 | AU27: =IF($AN27=1,$AO27+AU$15*$S27,-1000000000) -> 2360 | AV27: =IF($AN27=1,$AO27+AV$15*$S27,-1000000000) -> 4460 | AW27: =IF($AN27=1,$AO27+AW$15*$S27,-1000000000) -> 6560 | AX27: =IF($AN27=1,$AO27+AX$15*$S27,-1000000000) -> 5930
A28: 11 | B28: =MOD(INT($A28/2^5),2) -> 0 | C28: =MOD(INT($A28/2^4),2) -> 0 | D28: =MOD(INT($A28/2^3),2) -> 1 | E28: =MOD(INT($A28/2^2),2) -> 0 | F28: =MOD(INT($A28/2^1),2) -> 1 | G28: =MOD(INT($A28/2^0),2) -> 1 | H28: =Eff_now+B28*Half_g*(Ceil_e-Eff_now) -> 71 | I28: =H28+C28*Half_g*(Ceil_e-H28) -> 71 | J28: =I28+D28*Half_g*(Ceil_e-I28) -> 78 | K28: =J28+E28*Half_g*(Ceil_e-J28) -> 78 | L28: =K28+F28*Half_g*(Ceil_e-K28) -> 81.5 | M28: =L28+G28*Half_g*(Ceil_e-L28) -> 83.25 | N28: =Val_pt*(H28-Eff_now) -> 0 | O28: =Val_pt*(I28-Eff_now) -> 0 | P28: =Val_pt*(J28-Eff_now) -> 70 | Q28: =Val_pt*(K28-Eff_now) -> 70 | R28: =Val_pt*(L28-Eff_now) -> 105 | S28: =Val_pt*(M28-Eff_now) -> 122.5 | T28: =S_max*(1-2^(-(SUM($B28:B28)))) -> 0 | U28: =S_max*(1-2^(-(SUM($B28:C28)))) -> 0 | V28: =S_max*(1-2^(-(SUM($B28:D28)))) -> 70 | W28: =S_max*(1-2^(-(SUM($B28:E28)))) -> 70 | X28: =S_max*(1-2^(-(SUM($B28:F28)))) -> 105 | Y28: =S_max*(1-2^(-(SUM($B28:G28)))) -> 122.5 | Z28: =MAX(ABS(N28-T28),ABS(O28-U28),ABS(P28-V28),ABS(Q28-W28),ABS(R28-X28),ABS(S28-Y28)) -> 0 | AA28: =Liq_now-Cost_r*B28 -> 620 | AB28: =AG28-Cost_r*C28 -> 620 | AC28: =AH28-Cost_r*D28 -> 500 | AD28: =AI28-Cost_r*E28 -> 570 | AE28: =AJ28-Cost_r*F28 -> 520 | AF28: =AK28-Cost_r*G28 -> 505 | AG28: =AA28+N28 -> 620 | AH28: =AB28+O28 -> 620 | AI28: =AC28+P28 -> 570 | AJ28: =AD28+Q28 -> 640 | AK28: =AE28+R28 -> 625 | AL28: =AF28+S28 -> 627.5 | AM28: =SUM(B28:G28) -> 3 | AN28: =IF(AND(MIN(AA28:AF28)>=Floor_q,MIN(AG28:AL28)>=Floor_q,AL28>=Q_end,Cap_now>=Cap_min),1,0) -> 1 | AO28: =AL28-Q_end -> 157.5 | AP28: =IF(AN28=1,AO28+Credit_M*S28,-1000000000) -> 1382.5 | AQ28: =AP28+SUMPRODUCT(Relaxation!$C$23:$H$23,1-B28:G28)+SUMPRODUCT(Relaxation!$C$24:$H$24,B28:G28) -> 1531.4931 | AR28: =IF($AN28=1,$AO28+AR$15*$S28,-1000000000) -> 157.5 | AS28: =IF($AN28=1,$AO28+AS$15*$S28,-1000000000) -> 770 | AT28: =IF($AN28=1,$AO28+AT$15*$S28,-1000000000) -> 1382.5 | AU28: =IF($AN28=1,$AO28+AU$15*$S28,-1000000000) -> 2607.5 | AV28: =IF($AN28=1,$AO28+AV$15*$S28,-1000000000) -> 5057.5 | AW28: =IF($AN28=1,$AO28+AW$15*$S28,-1000000000) -> 7507.5 | AX28: =IF($AN28=1,$AO28+AX$15*$S28,-1000000000) -> 6772.5
... A80: 63 | B80: =MOD(INT($A80/2^5),2) -> 1 | C80: =MOD(INT($A80/2^4),2) -> 1 | D80: =MOD(INT($A80/2^3),2) -> 1 | E80: =MOD(INT($A80/2^2),2) -> 1 | F80: =MOD(INT($A80/2^1),2) -> 1 | G80: =MOD(INT($A80/2^0),2) -> 1 | H80: =Eff_now+B80*Half_g*(Ceil_e-Eff_now) -> 78 | I80: =H80+C80*Half_g*(Ceil_e-H80) -> 81.5 | J80: =I80+D80*Half_g*(Ceil_e-I80) -> 83.25 | K80: =J80+E80*Half_g*(Ceil_e-J80) -> 84.125 | L80: =K80+F80*Half_g*(Ceil_e-K80) -> 84.5625 | M80: =L80+G80*Half_g*(Ceil_e-L80) -> 84.78125 | N80: =Val_pt*(H80-Eff_now) -> 70 | O80: =Val_pt*(I80-Eff_now) -> 105 | P80: =Val_pt*(J80-Eff_now) -> 122.5 | Q80: =Val_pt*(K80-Eff_now) -> 131.25 | R80: =Val_pt*(L80-Eff_now) -> 135.625 | S80: =Val_pt*(M80-Eff_now) -> 137.8125 | T80: =S_max*(1-2^(-(SUM($B80:B80)))) -> 70 | U80: =S_max*(1-2^(-(SUM($B80:C80)))) -> 105 | V80: =S_max*(1-2^(-(SUM($B80:D80)))) -> 122.5 | W80: =S_max*(1-2^(-(SUM($B80:E80)))) -> 131.25 | X80: =S_max*(1-2^(-(SUM($B80:F80)))) -> 135.625 | Y80: =S_max*(1-2^(-(SUM($B80:G80)))) -> 137.8125 | Z80: =MAX(ABS(N80-T80),ABS(O80-U80),ABS(P80-V80),ABS(Q80-W80),ABS(R80-X80),ABS(S80-Y80)) -> 0 | AA80: =Liq_now-Cost_r*B80 -> 500 | AB80: =AG80-Cost_r*C80 -> 450 | AC80: =AH80-Cost_r*D80 -> 435 | AD80: =AI80-Cost_r*E80 -> 437.5 | AE80: =AJ80-Cost_r*F80 -> 448.75 | AF80: =AK80-Cost_r*G80 -> 464.375 | AG80: =AA80+N80 -> 570 | AH80: =AB80+O80 -> 555 | AI80: =AC80+P80 -> 557.5 | AJ80: =AD80+Q80 -> 568.75 | AK80: =AE80+R80 -> 584.375 | AL80: =AF80+S80 -> 602.1875 | AM80: =SUM(B80:G80) -> 6 | AN80: =IF(AND(MIN(AA80:AF80)>=Floor_q,MIN(AG80:AL80)>=Floor_q,AL80>=Q_end,Cap_now>=Cap_min),1,0) -> 1 | AO80: =AL80-Q_end -> 132.1875 | AP80: =IF(AN80=1,AO80+Credit_M*S80,-1000000000) -> 1510.3125 | AQ80: =AP80+SUMPRODUCT(Relaxation!$C$23:$H$23,1-B80:G80)+SUMPRODUCT(Relaxation!$C$24:$H$24,B80:G80) -> 1538.0048 | AR80: =IF($AN80=1,$AO80+AR$15*$S80,-1000000000) -> 132.1875 | AS80: =IF($AN80=1,$AO80+AS$15*$S80,-1000000000) -> 821.25 | AT80: =IF($AN80=1,$AO80+AT$15*$S80,-1000000000) -> 1510.3125 | AU80: =IF($AN80=1,$AO80+AU$15*$S80,-1000000000) -> 2888.4375 | AV80: =IF($AN80=1,$AO80+AV$15*$S80,-1000000000) -> 5644.6875 | AW80: =IF($AN80=1,$AO80+AW$15*$S80,-1000000000) -> 8400.9375 | AX80: =IF($AN80=1,$AO80+AX$15*$S80,-1000000000) -> 7574.0625
AQ82: Best value | AR82: =MAX($AR$17:$AR$80) -> 505 | AS82: =MAX($AS$17:$AS$80) -> 1067.5 | AT82: =MAX($AT$17:$AT$80) -> 1680 | AU82: =MAX($AU$17:$AU$80) -> 2986.25 | AV82: =MAX($AV$17:$AV$80) -> 5675 | AW82: =MAX($AW$17:$AW$80) -> 8400.9375 | AX82: =MAX($AX$17:$AX$80) -> 7574.0625
AQ83: Its rounds | AR83: =INDEX($AM$17:$AM$80,MATCH(AR82,$AR$17:$AR$80,0)) -> 2 | AS83: =INDEX($AM$17:$AM$80,MATCH(AS82,$AS$17:$AS$80,0)) -> 3 | AT83: =INDEX($AM$17:$AM$80,MATCH(AT82,$AT$17:$AT$80,0)) -> 3 | AU83: =INDEX($AM$17:$AM$80,MATCH(AU82,$AU$17:$AU$80,0)) -> 4 | AV83: =INDEX($AM$17:$AM$80,MATCH(AV82,$AV$17:$AV$80,0)) -> 5 | AW83: =INDEX($AM$17:$AM$80,MATCH(AW82,$AW$17:$AW$80,0)) -> 6 | AX83: =INDEX($AM$17:$AM$80,MATCH(AX82,$AX$17:$AX$80,0)) -> 6

Sheet Relaxation
A1: Solve and audit: the relaxation's closed form, its marginal values and prices, the KKT residuals and the ceiling (Steps 2-3; Figure 3.3(a); Online Appendix 3.B.4)
A2: Payouts can wait, so the floors never bind and the end condition prices cash at $1: the relaxation runs n whole rounds early, then a fraction where (6 - n + M) S'(Z) = 120. Each n is a candidate; the best wins.
A4: Whole rounds n | B4: Coefficient 6 - n + M | C4: Stationary Z = log2(97.04 c / 120) | D4: Z, kept in [n, n + 1] | E4: Value
A5: 0 | B5: =Years_n-A5+Credit_M -> 16 | C5: =IF(B5>0,LOG(Slope_s*B5/Cost_r,2),A5) -> 3.693626 | D5: =MIN(A5+1,MAX(A5,C5)) -> 1 | E5: =Const_c+S_max*(1-2^(-(MIN(1,D5))))+S_max*(1-2^(-(MIN(2,D5))))+S_max*(1-2^(-(MIN(3,D5))))+S_max*(1-2^(-(MIN(4,D5))))+S_max*(1-2^(-(MIN(5,D5))))+S_max*(1-2^(-(MIN(6,D5))))-Cost_r*D5+Credit_M*S_max*(1-2^(-(D5))) -> 1150
A6: 1 | B6: =Years_n-A6+Credit_M -> 15 | C6: =IF(B6>0,LOG(Slope_s*B6/Cost_r,2),A6) -> 3.6005166 | D6: =MIN(A6+1,MAX(A6,C6)) -> 2 | E6: =Const_c+S_max*(1-2^(-(MIN(1,D6))))+S_max*(1-2^(-(MIN(2,D6))))+S_max*(1-2^(-(MIN(3,D6))))+S_max*(1-2^(-(MIN(4,D6))))+S_max*(1-2^(-(MIN(5,D6))))+S_max*(1-2^(-(MIN(6,D6))))-Cost_r*D6+Credit_M*S_max*(1-2^(-(D6))) -> 1555
A7: 2 | B7: =Years_n-A7+Credit_M -> 14 | C7: =IF(B7>0,LOG(Slope_s*B7/Cost_r,2),A7) -> 3.500981 | D7: =MIN(A7+1,MAX(A7,C7)) -> 3 | E7: =Const_c+S_max*(1-2^(-(MIN(1,D7))))+S_max*(1-2^(-(MIN(2,D7))))+S_max*(1-2^(-(MIN(3,D7))))+S_max*(1-2^(-(MIN(4,D7))))+S_max*(1-2^(-(MIN(5,D7))))+S_max*(1-2^(-(MIN(6,D7))))-Cost_r*D7+Credit_M*S_max*(1-2^(-(D7))) -> 1680
A8: 3 | B8: =Years_n-A8+Credit_M -> 13 | C8: =IF(B8>0,LOG(Slope_s*B8/Cost_r,2),A8) -> 3.3940658 | D8: =MIN(A8+1,MAX(A8,C8)) -> 3.3940658 | E8: =Const_c+S_max*(1-2^(-(MIN(1,D8))))+S_max*(1-2^(-(MIN(2,D8))))+S_max*(1-2^(-(MIN(3,D8))))+S_max*(1-2^(-(MIN(4,D8))))+S_max*(1-2^(-(MIN(5,D8))))+S_max*(1-2^(-(MIN(6,D8))))-Cost_r*D8+Credit_M*S_max*(1-2^(-(D8))) -> 1687.0887
A9: 4 | B9: =Years_n-A9+Credit_M -> 12 | C9: =IF(B9>0,LOG(Slope_s*B9/Cost_r,2),A9) -> 3.2785885 | D9: =MIN(A9+1,MAX(A9,C9)) -> 4 | E9: =Const_c+S_max*(1-2^(-(MIN(1,D9))))+S_max*(1-2^(-(MIN(2,D9))))+S_max*(1-2^(-(MIN(3,D9))))+S_max*(1-2^(-(MIN(4,D9))))+S_max*(1-2^(-(MIN(5,D9))))+S_max*(1-2^(-(MIN(6,D9))))-Cost_r*D9+Credit_M*S_max*(1-2^(-(D9))) -> 1673.75
A10: 5 | B10: =Years_n-A10+Credit_M -> 11 | C10: =IF(B10>0,LOG(Slope_s*B10/Cost_r,2),A10) -> 3.1530577 | D10: =MIN(A10+1,MAX(A10,C10)) -> 5 | E10: =Const_c+S_max*(1-2^(-(MIN(1,D10))))+S_max*(1-2^(-(MIN(2,D10))))+S_max*(1-2^(-(MIN(3,D10))))+S_max*(1-2^(-(MIN(4,D10))))+S_max*(1-2^(-(MIN(5,D10))))+S_max*(1-2^(-(MIN(6,D10))))-Cost_r*D10+Credit_M*S_max*(1-2^(-(D10))) -> 1606.25
A11: 6 | B11: =Years_n-A11+Credit_M -> 10 | C11: =IF(B11>0,LOG(Slope_s*B11/Cost_r,2),A11) -> 3.0155541 | D11: =Years_n -> 6 | E11: =Const_c+S_max*(1-2^(-(MIN(1,D11))))+S_max*(1-2^(-(MIN(2,D11))))+S_max*(1-2^(-(MIN(3,D11))))+S_max*(1-2^(-(MIN(4,D11))))+S_max*(1-2^(-(MIN(5,D11))))+S_max*(1-2^(-(MIN(6,D11))))-Cost_r*D11+Credit_M*S_max*(1-2^(-(D11))) -> 1510.3125
A12: The relaxation's value: the ceiling | B12: =MAX(E5:E11) -> 1687.0887
A13: Its rounds to date by year 6, Z* | B13: =INDEX(D5:D11,MATCH(B12,E5:E11,0)) -> 3.3940658
A14: Check: 97.04 x 13/120, whose log2 is Z* | B14: =Slope_s*(Years_n-3+Credit_M)/Cost_r -> 10.512732
A16: Online Appendix 3.B.4's table | C16: Year 1 | D16: Year 2 | E16: Year 3 | F16: Year 4 | G16: Year 5 | H16: Year 6
A17: Year | C17: 1 | D17: 2 | E17: 3 | F17: 4 | G17: 5 | H17: 6
A18: Round z_k | C18: =MIN(1,MAX(0,$B$13-(C17-1))) -> 1 | D18: =MIN(1,MAX(0,$B$13-(D17-1))) -> 1 | E18: =MIN(1,MAX(0,$B$13-(E17-1))) -> 1 | F18: =MIN(1,MAX(0,$B$13-(F17-1))) -> 0.39406577 | G18: =MIN(1,MAX(0,$B$13-(G17-1))) -> 0 | H18: =MIN(1,MAX(0,$B$13-(H17-1))) -> 0
A19: Rounds to date Z_k | C19: =MIN(C17,$B$13) -> 1 | D19: =MIN(D17,$B$13) -> 2 | E19: =MIN(E17,$B$13) -> 3 | F19: =MIN(F17,$B$13) -> 3.3940658 | G19: =MIN(G17,$B$13) -> 3.3940658 | H19: =MIN(H17,$B$13) -> 3.3940658
A20: Savings S(Z_k) | C20: =S_max*(1-2^(-(C19))) -> 70 | D20: =S_max*(1-2^(-(D19))) -> 105 | E20: =S_max*(1-2^(-(E19))) -> 122.5 | F20: =S_max*(1-2^(-(F19))) -> 126.68282 | G20: =S_max*(1-2^(-(G19))) -> 126.68282 | H20: =S_max*(1-2^(-(H19))) -> 126.68282
A21: Slope S'(Z_k) | C21: =Slope_s*2^(-C19) -> 48.520303 | D21: =Slope_s*2^(-D19) -> 24.260151 | E21: =Slope_s*2^(-E19) -> 12.130076 | F21: =Slope_s*2^(-F19) -> 9.2307692 | G21: =Slope_s*2^(-G19) -> 9.2307692 | H21: =Slope_s*2^(-H19) -> 9.2307692
A22: Marginal value of a round: sum of S' from the year on, plus M x S'(Z_6) | C22: =SUM(C21:$H21)+Credit_M*$H21 -> 204.91053 | D22: =SUM(D21:$H21)+Credit_M*$H21 -> 156.39023 | E22: =SUM(E21:$H21)+Credit_M*$H21 -> 132.13008 | F22: =SUM(F21:$H21)+Credit_M*$H21 -> 120 | G22: =SUM(G21:$H21)+Credit_M*$H21 -> 110.76923 | H22: =SUM(H21:$H21)+Credit_M*$H21 -> 101.53846
A23: Price of the year's limit (margin less cost, where the round is whole) | C23: =IF(C18>=1-0.000000001,C22-Cost_r,0) -> 84.91053 | D23: =IF(D18>=1-0.000000001,D22-Cost_r,0) -> 36.390227 | E23: =IF(E18>=1-0.000000001,E22-Cost_r,0) -> 12.130076 | F23: =IF(F18>=1-0.000000001,F22-Cost_r,0) -> 0 | G23: =IF(G18>=1-0.000000001,G22-Cost_r,0) -> 0 | H23: =IF(H18>=1-0.000000001,H22-Cost_r,0) -> 0
A24: Price of forcing a round (cost less margin, where there is none) | C24: =IF(C18<=0.000000001,Cost_r-C22,0) -> 0 | D24: =IF(D18<=0.000000001,Cost_r-D22,0) -> 0 | E24: =IF(E18<=0.000000001,Cost_r-E22,0) -> 0 | F24: =IF(F18<=0.000000001,Cost_r-F22,0) -> 0 | G24: =IF(G18<=0.000000001,Cost_r-G22,0) -> 9.2307692 | H24: =IF(H18<=0.000000001,Cost_r-H22,0) -> 18.461538
A25: Stationarity: margin - cost - limit price + forcing price | C25: =C22-Cost_r-C23+C24 -> 0 | D25: =D22-Cost_r-D23+D24 -> 0 | E25: =E22-Cost_r-E23+E24 -> 0 | F25: =F22-Cost_r-F23+F24 -> 0 | G25: =G22-Cost_r-G23+G24 -> 0 | H25: =H22-Cost_r-H23+H24 -> 0
A26: Complementarity: limit price x (1 - z) + forcing price x z | C26: =C23*(1-C18)+C24*C18 -> 0 | D26: =D23*(1-D18)+D24*D18 -> 0 | E26: =E23*(1-E18)+E24*E18 -> 0 | F26: =F23*(1-F18)+F24*F18 -> 0 | G26: =G23*(1-G18)+G24*G18 -> 0 | H26: =H23*(1-H18)+H24*H18 -> 0
A27: Liquidity after the round (payouts deferred to year 6) | C27: =Liq_now-Cost_r*C18 -> 500 | D27: =C28-Cost_r*D18 -> 450 | E27: =D28-Cost_r*E18 -> 435 | F27: =E28-Cost_r*F18 -> 510.21211 | G27: =F28-Cost_r*G18 -> 636.89492 | H27: =G28-Cost_r*H18 -> 763.57774
A28: Year-end liquidity before any payout | C28: =C27+C20 -> 570 | D28: =D27+D20 -> 555 | E28: =E27+E20 -> 557.5 | F28: =F27+F20 -> 636.89492 | G28: =G27+G20 -> 763.57774 | H28: =H27+H20 -> 890.26055
A29: Payout: everything above $470 million, at year 6 | C29: 0 | D29: 0 | E29: 0 | F29: 0 | G29: 0 | H29: =H28-Q_end -> 420.26055
A30: Year-end liquidity | C30: =C28-C29 -> 570 | D30: =D28-D29 -> 555 | E30: =E28-E29 -> 557.5 | F30: =F28-F29 -> 636.89492 | G30: =G28-G29 -> 763.57774 | H30: =H28-H29 -> 470
A32: Total payout | C32: =SUM(C29:H29) -> 420.26055
A33: Value: payout + M x year-6 savings (equals the ceiling) | C33: =C32+Credit_M*H20 -> 1687.0887
A34: Commitments: the smallest slack of a floor (positive: the floors carry no price) | C34: =MIN(MIN(C27:H27),MIN(C30:H30))-Floor_q -> 85
A35: Commitments: the end condition's slack (it binds, at a price of 1) | C35: =H30-Q_end -> 0
A36: Signs: the smallest price | C36: =MIN(C23:H24) -> 0
A37: Complementarity: the largest product | C37: =MAX(C26:H26) -> 0
A38: Stationarity: the largest residual | C38: =MAX(MAX(C25:H25),-MIN(C25:H25)) -> 0
A39: Lagrangian at the plan with these prices (stationary and concave, so its maximum: the ceiling) | C39: =C33+SUMPRODUCT(C23:H23,1-C18:H18)+SUMPRODUCT(C24:H24,C18:H18) -> 1687.0887
A41: Pricing only the end condition: rounds to date maximizing 11 S(Z) - 120 Z | C41: =LOG((1+Credit_M)*Slope_s/Cost_r,2) -> 3.1530577
A42: That price list's ceiling: 150 + 5 x 140 + 11 S(Z) - 120 Z (valid, but loose) | C42: =Const_c+(Years_n-1)*S_max+(1+Credit_M)*S_max*(1-2^(-(C41)))-Cost_r*C41 -> 1838.5097
A44: The notebook's barrier method (engine) | C44: Year 1 | D44: Year 2 | E44: Year 3 | F44: Year 4 | G44: Year 5 | H44: Year 6
A45: Rounds | C45: 1 | D45: 1 | E45: 0.99999999 | F45: 0.39406576 | G45: 1.0833333e-08 | H45: 5.4166666e-09
...

Sheet Credit
A1: Move the credit: Table 3.5, where the relaxation proves the lumpy plan best, and where rounding fails (Worked Example 3.1, Step 5; AXIOM Lab 2.3, step 5)
A2: For each credit M, the closed form's seven candidates (Z_n and its value V_n) give the ceiling; the best lumpy value is the best of the 64 plans on LumpyPlans.
A4: Credit M | B4: Z_0 | C4: Z_1 | D4: Z_2 | E4: Z_3 | F4: Z_4 | G4: Z_5 | H4: Z_6 | I4: V_0 | J4: V_1 | K4: V_2 | L4: V_3 | M4: V_4 | N4: V_5 | O4: V_6 | P4: Ceiling | Q4: Relaxation's rounds | R4: Best lumpy value | S4: Its rounds | T4: Gap | U4: Rounded relaxation | V4: Rounding
A5: 0 | B5: =MIN(1,MAX(0,LOG(Slope_s*(Years_n-0+$A5)/Cost_r,2))) -> 1 | C5: =MIN(2,MAX(1,LOG(Slope_s*(Years_n-1+$A5)/Cost_r,2))) -> 2 | D5: =MIN(3,MAX(2,LOG(Slope_s*(Years_n-2+$A5)/Cost_r,2))) -> 2 | E5: =MIN(4,MAX(3,LOG(Slope_s*(Years_n-3+$A5)/Cost_r,2))) -> 3 | F5: =MIN(5,MAX(4,LOG(Slope_s*(Years_n-4+$A5)/Cost_r,2))) -> 4 | G5: =MIN(6,MAX(5,LOG(Slope_s*(Years_n-5+$A5)/Cost_r,2))) -> 5 | H5: =Years_n -> 6 | I5: =Const_c+S_max*(1-2^(-(MIN(1,B5))))+S_max*(1-2^(-(MIN(2,B5))))+S_max*(1-2^(-(MIN(3,B5))))+S_max*(1-2^(-(MIN(4,B5))))+S_max*(1-2^(-(MIN(5,B5))))+S_max*(1-2^(-(MIN(6,B5))))-Cost_r*B5+$A5*S_max*(1-2^(-(B5))) -> 450 | J5: =Const_c+S_max*(1-2^(-(MIN(1,C5))))+S_max*(1-2^(-(MIN(2,C5))))+S_max*(1-2^(-(MIN(3,C5))))+S_max*(1-2^(-(MIN(4,C5))))+S_max*(1-2^(-(MIN(5,C5))))+S_max*(1-2^(-(MIN(6,C5))))-Cost_r*C5+$A5*S_max*(1-2^(-(C5))) -> 505 | K5: =Const_c+S_max*(1-2^(-(MIN(1,D5))))+S_max*(1-2^(-(MIN(2,D5))))+S_max*(1-2^(-(MIN(3,D5))))+S_max*(1-2^(-(MIN(4,D5))))+S_max*(1-2^(-(MIN(5,D5))))+S_max*(1-2^(-(MIN(6,D5))))-Cost_r*D5+$A5*S_max*(1-2^(-(D5))) -> 505 | L5: =Const_c+S_max*(1-2^(-(MIN(1,E5))))+S_max*(1-2^(-(MIN(2,E5))))+S_max*(1-2^(-(MIN(3,E5))))+S_max*(1-2^(-(MIN(4,E5))))+S_max*(1-2^(-(MIN(5,E5))))+S_max*(1-2^(-(MIN(6,E5))))-Cost_r*E5+$A5*S_max*(1-2^(-(E5))) -> 455 | M5: =Const_c+S_max*(1-2^(-(MIN(1,F5))))+S_max*(1-2^(-(MIN(2,F5))))+S_max*(1-2^(-(MIN(3,F5))))+S_max*(1-2^(-(MIN(4,F5))))+S_max*(1-2^(-(MIN(5,F5))))+S_max*(1-2^(-(MIN(6,F5))))-Cost_r*F5+$A5*S_max*(1-2^(-(F5))) -> 361.25 | N5: =Const_c+S_max*(1-2^(-(MIN(1,G5))))+S_max*(1-2^(-(MIN(2,G5))))+S_max*(1-2^(-(MIN(3,G5))))+S_max*(1-2^(-(MIN(4,G5))))+S_max*(1-2^(-(MIN(5,G5))))+S_max*(1-2^(-(MIN(6,G5))))-Cost_r*G5+$A5*S_max*(1-2^(-(G5))) -> 250 | O5: =Const_c+S_max*(1-2^(-(MIN(1,H5))))+S_max*(1-2^(-(MIN(2,H5))))+S_max*(1-2^(-(MIN(3,H5))))+S_max*(1-2^(-(MIN(4,H5))))+S_max*(1-2^(-(MIN(5,H5))))+S_max*(1-2^(-(MIN(6,H5))))-Cost_r*H5+$A5*S_max*(1-2^(-(H5))) -> 132.1875 | P5: =MAX(I5:O5) -> 505 | Q5: =INDEX(B5:H5,MATCH(P5,I5:O5,0)) -> 2 | R5: =LumpyPlans!AR82 -> 505 | S5: =LumpyPlans!AR83 -> 2 | T5: =P5-R5 -> 0 | U5: =INT(Q5+0.5) -> 2 | V5: =IF(U5=S5,"right","wrong") -> right
A6: 5 | B6: =MIN(1,MAX(0,LOG(Slope_s*(Years_n-0+$A6)/Cost_r,2))) -> 1 | C6: =MIN(2,MAX(1,LOG(Slope_s*(Years_n-1+$A6)/Cost_r,2))) -> 2 | D6: =MIN(3,MAX(2,LOG(Slope_s*(Years_n-2+$A6)/Cost_r,2))) -> 2.863551 | E6: =MIN(4,MAX(3,LOG(Slope_s*(Years_n-3+$A6)/Cost_r,2))) -> 3 | F6: =MIN(5,MAX(4,LOG(Slope_s*(Years_n-4+$A6)/Cost_r,2))) -> 4 | G6: =MIN(6,MAX(5,LOG(Slope_s*(Years_n-5+$A6)/Cost_r,2))) -> 5 | H6: =Years_n -> 6 | I6: =Const_c+S_max*(1-2^(-(MIN(1,B6))))+S_max*(1-2^(-(MIN(2,B6))))+S_max*(1-2^(-(MIN(3,B6))))+S_max*(1-2^(-(MIN(4,B6))))+S_max*(1-2^(-(MIN(5,B6))))+S_max*(1-2^(-(MIN(6,B6))))-Cost_r*B6+$A6*S_max*(1-2^(-(B6))) -> 800 | J6: =Const_c+S_max*(1-2^(-(MIN(1,C6))))+S_max*(1-2^(-(MIN(2,C6))))+S_max*(1-2^(-(MIN(3,C6))))+S_max*(1-2^(-(MIN(4,C6))))+S_max*(1-2^(-(MIN(5,C6))))+S_max*(1-2^(-(MIN(6,C6))))-Cost_r*C6+$A6*S_max*(1-2^(-(C6))) -> 1030 | K6: =Const_c+S_max*(1-2^(-(MIN(1,D6))))+S_max*(1-2^(-(MIN(2,D6))))+S_max*(1-2^(-(MIN(3,D6))))+S_max*(1-2^(-(MIN(4,D6))))+S_max*(1-2^(-(MIN(5,D6))))+S_max*(1-2^(-(MIN(6,D6))))-Cost_r*D6+$A6*S_max*(1-2^(-(D6))) -> 1068.2505 | L6: =Const_c+S_max*(1-2^(-(MIN(1,E6))))+S_max*(1-2^(-(MIN(2,E6))))+S_max*(1-2^(-(MIN(3,E6))))+S_max*(1-2^(-(MIN(4,E6))))+S_max*(1-2^(-(MIN(5,E6))))+S_max*(1-2^(-(MIN(6,E6))))-Cost_r*E6+$A6*S_max*(1-2^(-(E6))) -> 1067.5 | M6: =Const_c+S_max*(1-2^(-(MIN(1,F6))))+S_max*(1-2^(-(MIN(2,F6))))+S_max*(1-2^(-(MIN(3,F6))))+S_max*(1-2^(-(MIN(4,F6))))+S_max*(1-2^(-(MIN(5,F6))))+S_max*(1-2^(-(MIN(6,F6))))-Cost_r*F6+$A6*S_max*(1-2^(-(F6))) -> 1017.5 | N6: =Const_c+S_max*(1-2^(-(MIN(1,G6))))+S_max*(1-2^(-(MIN(2,G6))))+S_max*(1-2^(-(MIN(3,G6))))+S_max*(1-2^(-(MIN(4,G6))))+S_max*(1-2^(-(MIN(5,G6))))+S_max*(1-2^(-(MIN(6,G6))))-Cost_r*G6+$A6*S_max*(1-2^(-(G6))) -> 928.125 | O6: =Const_c+S_max*(1-2^(-(MIN(1,H6))))+S_max*(1-2^(-(MIN(2,H6))))+S_max*(1-2^(-(MIN(3,H6))))+S_max*(1-2^(-(MIN(4,H6))))+S_max*(1-2^(-(MIN(5,H6))))+S_max*(1-2^(-(MIN(6,H6))))-Cost_r*H6+$A6*S_max*(1-2^(-(H6))) -> 821.25 | P6: =MAX(I6:O6) -> 1068.2505 | Q6: =INDEX(B6:H6,MATCH(P6,I6:O6,0)) -> 2.863551 | R6: =LumpyPlans!AS82 -> 1067.5 | S6: =LumpyPlans!AS83 -> 3 | T6: =P6-R6 -> 0.75046911 | U6: =INT(Q6+0.5) -> 3 | V6: =IF(U6=S6,"right","wrong") -> right
A7: 10 | B7: =MIN(1,MAX(0,LOG(Slope_s*(Years_n-0+$A7)/Cost_r,2))) -> 1 | C7: =MIN(2,MAX(1,LOG(Slope_s*(Years_n-1+$A7)/Cost_r,2))) -> 2 | D7: =MIN(3,MAX(2,LOG(Slope_s*(Years_n-2+$A7)/Cost_r,2))) -> 3 | E7: =MIN(4,MAX(3,LOG(Slope_s*(Years_n-3+$A7)/Cost_r,2))) -> 3.3940658 | F7: =MIN(5,MAX(4,LOG(Slope_s*(Years_n-4+$A7)/Cost_r,2))) -> 4 | G7: =MIN(6,MAX(5,LOG(Slope_s*(Years_n-5+$A7)/Cost_r,2))) -> 5 | H7: =Years_n -> 6 | I7: =Const_c+S_max*(1-2^(-(MIN(1,B7))))+S_max*(1-2^(-(MIN(2,B7))))+S_max*(1-2^(-(MIN(3,B7))))+S_max*(1-2^(-(MIN(4,B7))))+S_max*(1-2^(-(MIN(5,B7))))+S_max*(1-2^(-(MIN(6,B7))))-Cost_r*B7+$A7*S_max*(1-2^(-(B7))) -> 1150 | J7: =Const_c+S_max*(1-2^(-(MIN(1,C7))))+S_max*(1-2^(-(MIN(2,C7))))+S_max*(1-2^(-(MIN(3,C7))))+S_max*(1-2^(-(MIN(4,C7))))+S_max*(1-2^(-(MIN(5,C7))))+S_max*(1-2^(-(MIN(6,C7))))-Cost_r*C7+$A7*S_max*(1-2^(-(C7))) -> 1555 | K7: =Const_c+S_max*(1-2^(-(MIN(1,D7))))+S_max*(1-2^(-(MIN(2,D7))))+S_max*(1-2^(-(MIN(3,D7))))+S_max*(1-2^(-(MIN(4,D7))))+S_max*(1-2^(-(MIN(5,D7))))+S_max*(1-2^(-(MIN(6,D7))))-Cost_r*D7+$A7*S_max*(1-2^(-(D7))) -> 1680 | L7: =Const_c+S_max*(1-2^(-(MIN(1,E7))))+S_max*(1-2^(-(MIN(2,E7))))+S_max*(1-2^(-(MIN(3,E7))))+S_max*(1-2^(-(MIN(4,E7))))+S_max*(1-2^(-(MIN(5,E7))))+S_max*(1-2^(-(MIN(6,E7))))-Cost_r*E7+$A7*S_max*(1-2^(-(E7))) -> 1687.0887 | M7: =Const_c+S_max*(1-2^(-(MIN(1,F7))))+S_max*(1-2^(-(MIN(2,F7))))+S_max*(1-2^(-(MIN(3,F7))))+S_max*(1-2^(-(MIN(4,F7))))+S_max*(1-2^(-(MIN(5,F7))))+S_max*(1-2^(-(MIN(6,F7))))-Cost_r*F7+$A7*S_max*(1-2^(-(F7))) -> 1673.75 | N7: =Const_c+S_max*(1-2^(-(MIN(1,G7))))+S_max*(1-2^(-(MIN(2,G7))))+S_max*(1-2^(-(MIN(3,G7))))+S_max*(1-2^(-(MIN(4,G7))))+S_max*(1-2^(-(MIN(5,G7))))+S_max*(1-2^(-(MIN(6,G7))))-Cost_r*G7+$A7*S_max*(1-2^(-(G7))) -> 1606.25 | O7: =Const_c+S_max*(1-2^(-(MIN(1,H7))))+S_max*(1-2^(-(MIN(2,H7))))+S_max*(1-2^(-(MIN(3,H7))))+S_max*(1-2^(-(MIN(4,H7))))+S_max*(1-2^(-(MIN(5,H7))))+S_max*(1-2^(-(MIN(6,H7))))-Cost_r*H7+$A7*S_max*(1-2^(-(H7))) -> 1510.3125 | P7: =MAX(I7:O7) -> 1687.0887 | Q7: =INDEX(B7:H7,MATCH(P7,I7:O7,0)) -> 3.3940658 | R7: =LumpyPlans!AT82 -> 1680 | S7: =LumpyPlans!AT83 -> 3 | T7: =P7-R7 -> 7.0887031 | U7: =INT(Q7+0.5) -> 3 | V7: =IF(U7=S7,"right","wrong") -> right
A8: 20 | B8: =MIN(1,MAX(0,LOG(Slope_s*(Years_n-0+$A8)/Cost_r,2))) -> 1 | C8: =MIN(2,MAX(1,LOG(Slope_s*(Years_n-1+$A8)/Cost_r,2))) -> 2 | D8: =MIN(3,MAX(2,LOG(Slope_s*(Years_n-2+$A8)/Cost_r,2))) -> 3 | E8: =MIN(4,MAX(3,LOG(Slope_s*(Years_n-3+$A8)/Cost_r,2))) -> 4 | F8: =MIN(5,MAX(4,LOG(Slope_s*(Years_n-4+$A8)/Cost_r,2))) -> 4.1530577 | G8: =MIN(6,MAX(5,LOG(Slope_s*(Years_n-5+$A8)/Cost_r,2))) -> 5 | H8: =Years_n -> 6 | I8: =Const_c+S_max*(1-2^(-(MIN(1,B8))))+S_max*(1-2^(-(MIN(2,B8))))+S_max*(1-2^(-(MIN(3,B8))))+S_max*(1-2^(-(MIN(4,B8))))+S_max*(1-2^(-(MIN(5,B8))))+S_max*(1-2^(-(MIN(6,B8))))-Cost_r*B8+$A8*S_max*(1-2^(-(B8))) -> 1850 | J8: =Const_c+S_max*(1-2^(-(MIN(1,C8))))+S_max*(1-2^(-(MIN(2,C8))))+S_max*(1-2^(-(MIN(3,C8))))+S_max*(1-2^(-(MIN(4,C8))))+S_max*(1-2^(-(MIN(5,C8))))+S_max*(1-2^(-(MIN(6,C8))))-Cost_r*C8+$A8*S_max*(1-2^(-(C8))) -> 2605 | K8: =Const_c+S_max*(1-2^(-(MIN(1,D8))))+S_max*(1-2^(-(MIN(2,D8))))+S_max*(1-2^(-(MIN(3,D8))))+S_max*(1-2^(-(MIN(4,D8))))+S_max*(1-2^(-(MIN(5,D8))))+S_max*(1-2^(-(MIN(6,D8))))-Cost_r*D8+$A8*S_max*(1-2^(-(D8))) -> 2905 | L8: =Const_c+S_max*(1-2^(-(MIN(1,E8))))+S_max*(1-2^(-(MIN(2,E8))))+S_max*(1-2^(-(MIN(3,E8))))+S_max*(1-2^(-(MIN(4,E8))))+S_max*(1-2^(-(MIN(5,E8))))+S_max*(1-2^(-(MIN(6,E8))))-Cost_r*E8+$A8*S_max*(1-2^(-(E8))) -> 2986.25 | M8: =Const_c+S_max*(1-2^(-(MIN(1,F8))))+S_max*(1-2^(-(MIN(2,F8))))+S_max*(1-2^(-(MIN(3,F8))))+S_max*(1-2^(-(MIN(4,F8))))+S_max*(1-2^(-(MIN(5,F8))))+S_max*(1-2^(-(MIN(6,F8))))-Cost_r*F8+$A8*S_max*(1-2^(-(F8))) -> 2987.2597 | N8: =Const_c+S_max*(1-2^(-(MIN(1,G8))))+S_max*(1-2^(-(MIN(2,G8))))+S_max*(1-2^(-(MIN(3,G8))))+S_max*(1-2^(-(MIN(4,G8))))+S_max*(1-2^(-(MIN(5,G8))))+S_max*(1-2^(-(MIN(6,G8))))-Cost_r*G8+$A8*S_max*(1-2^(-(G8))) -> 2962.5 | O8: =Const_c+S_max*(1-2^(-(MIN(1,H8))))+S_max*(1-2^(-(MIN(2,H8))))+S_max*(1-2^(-(MIN(3,H8))))+S_max*(1-2^(-(MIN(4,H8))))+S_max*(1-2^(-(MIN(5,H8))))+S_max*(1-2^(-(MIN(6,H8))))-Cost_r*H8+$A8*S_max*(1-2^(-(H8))) -> 2888.4375 | P8: =MAX(I8:O8) -> 2987.2597 | Q8: =INDEX(B8:H8,MATCH(P8,I8:O8,0)) -> 4.1530577 | R8: =LumpyPlans!AU82 -> 2986.25 | S8: =LumpyPlans!AU83 -> 4 | T8: =P8-R8 -> 1.009675 | U8: =INT(Q8+0.5) -> 4 | V8: =IF(U8=S8,"right","wrong") -> right
A9: 40 | B9: =MIN(1,MAX(0,LOG(Slope_s*(Years_n-0+$A9)/Cost_r,2))) -> 1 | C9: =MIN(2,MAX(1,LOG(Slope_s*(Years_n-1+$A9)/Cost_r,2))) -> 2 | D9: =MIN(3,MAX(2,LOG(Slope_s*(Years_n-2+$A9)/Cost_r,2))) -> 3 | E9: =MIN(4,MAX(3,LOG(Slope_s*(Years_n-3+$A9)/Cost_r,2))) -> 4 | F9: =MIN(5,MAX(4,LOG(Slope_s*(Years_n-4+$A9)/Cost_r,2))) -> 5 | G9: =MIN(6,MAX(5,LOG(Slope_s*(Years_n-5+$A9)/Cost_r,2))) -> 5.0511781 | H9: =Years_n -> 6 | I9: =Const_c+S_max*(1-2^(-(MIN(1,B9))))+S_max*(1-2^(-(MIN(2,B9))))+S_max*(1-2^(-(MIN(3,B9))))+S_max*(1-2^(-(MIN(4,B9))))+S_max*(1-2^(-(MIN(5,B9))))+S_max*(1-2^(-(MIN(6,B9))))-Cost_r*B9+$A9*S_max*(1-2^(-(B9))) -> 3250 | J9: =Const_c+S_max*(1-2^(-(MIN(1,C9))))+S_max*(1-2^(-(MIN(2,C9))))+S_max*(1-2^(-(MIN(3,C9))))+S_max*(1-2^(-(MIN(4,C9))))+S_max*(1-2^(-(MIN(5,C9))))+S_max*(1-2^(-(MIN(6,C9))))-Cost_r*C9+$A9*S_max*(1-2^(-(C9))) -> 4705 | K9: =Const_c+S_max*(1-2^(-(MIN(1,D9))))+S_max*(1-2^(-(MIN(2,D9))))+S_max*(1-2^(-(MIN(3,D9))))+S_max*(1-2^(-(MIN(4,D9))))+S_max*(1-2^(-(MIN(5,D9))))+S_max*(1-2^(-(MIN(6,D9))))-Cost_r*D9+$A9*S_max*(1-2^(-(D9))) -> 5355 | L9: =Const_c+S_max*(1-2^(-(MIN(1,E9))))+S_max*(1-2^(-(MIN(2,E9))))+S_max*(1-2^(-(MIN(3,E9))))+S_max*(1-2^(-(MIN(4,E9))))+S_max*(1-2^(-(MIN(5,E9))))+S_max*(1-2^(-(MIN(6,E9))))-Cost_r*E9+$A9*S_max*(1-2^(-(E9))) -> 5611.25 | M9: =Const_c+S_max*(1-2^(-(MIN(1,F9))))+S_max*(1-2^(-(MIN(2,F9))))+S_max*(1-2^(-(MIN(3,F9))))+S_max*(1-2^(-(MIN(4,F9))))+S_max*(1-2^(-(MIN(5,F9))))+S_max*(1-2^(-(MIN(6,F9))))-Cost_r*F9+$A9*S_max*(1-2^(-(F9))) -> 5675 | N9: =Const_c+S_max*(1-2^(-(MIN(1,G9))))+S_max*(1-2^(-(MIN(2,G9))))+S_max*(1-2^(-(MIN(3,G9))))+S_max*(1-2^(-(MIN(4,G9))))+S_max*(1-2^(-(MIN(5,G9))))+S_max*(1-2^(-(MIN(6,G9))))-Cost_r*G9+$A9*S_max*(1-2^(-(G9))) -> 5675.1102 | O9: =Const_c+S_max*(1-2^(-(MIN(1,H9))))+S_max*(1-2^(-(MIN(2,H9))))+S_max*(1-2^(-(MIN(3,H9))))+S_max*(1-2^(-(MIN(4,H9))))+S_max*(1-2^(-(MIN(5,H9))))+S_max*(1-2^(-(MIN(6,H9))))-Cost_r*H9+$A9*S_max*(1-2^(-(H9))) -> 5644.6875 | P9: =MAX(I9:O9) -> 5675.1102 | Q9: =INDEX(B9:H9,MATCH(P9,I9:O9,0)) -> 5.0511781 | R9: =LumpyPlans!AV82 -> 5675 | S9: =LumpyPlans!AV83 -> 5 | T9: =P9-R9 -> 0.11022873 | U9: =INT(Q9+0.5) -> 5 | V9: =IF(U9=S9,"right","wrong") -> right
