Workbook

Sheet README
B1: DCT Laboratory — Vol II, Ch 14: Artificial Intelligence for Enterprise Optimization
B2: Seed 26214 · Companion to DCT_V2_Ch14_Lab.ipynb and AXIOM Lab 2.14 (module AXIOM-14). Money in $ million.
B4: Worked Example 14.1, Should Meridian Let an Agent Learn Its Hiring Rule?, with the book's declarations: Chapter 7's law and costs on the agent's quarter-point grid; the AI team's agent (tabular Q-learning, one random decision in ten, step 1/(1 + (1 - beta) n), untried decisions at zero); the board's guardrail; the audit committee's certification. Seeds as in Online Appendix Remark 14.B.1.
B5: Declarations: the costs, the discount, the swings and the record, the grid, the new declarations, the seeds.
B6: Grid: the 2,113 admissible decisions and the 1,152 inside the guardrail, by formula (AXIOM Lab 2.14, step 1).
B7: BestRule: one Bellman step on the engine's values of the best rule at all 201 levels: decision values, best hires, the residual, planned capability, the guardrail check; the rule's cost from 58 and its shape.
B8: Rules: Volume I's rule and the worst rules, by formula against the engine; their costs and excess.
B9: Certify: the ten learned rules' breaches of the guardrail at every capability (Step 6).
B10: QLearning: step sizes, Equation 14.2 for one trial, every agent's excess cost and the summaries, Theorem 14.1(ii)'s bound, and the greedy learners (Steps 2-3; Figure 14.1).
B11: Bandit: thirteen target rules, the regret decomposition, Theorem 14.2(iii)'s bound and the optimistic rule's index (Step 3; Figure 14.2(a)).
B12: Swings and Practice: simulators learned from records of swings and from a record kept under Volume I's rule, with Theorem 14.3's bounds, LINEST and the collinearity of hiring and capability (Step 4; Figure 14.3).
B13: Company: learning on the company with and without the guardrail (Step 5; Figure 14.2(b)). Table14_3: the Worked Example's table, linked to the sheets. Examples: the appendices' small examples.
... B21: Cross-sheet link: green.

Sheet Declarations
A1: Declarations (Worked Example 14.1, Step 1; Chapter 7's law and costs; the agent's grid; Online Appendix Remark 14.B.1). Money in $ million; capability in points.
A3: Quantity | B3: Value | C3: Source
A4: Discount rate a year | B4: 0.1 | C4: The board's 10 percent
A5: Discount factor a quarter, beta | B5: =(1+B4)^(-1/4) -> 0.97645409 | C5: beta = 1.1^(-1/4)
A6: Effective horizon 1/(1 - beta), quarters | B6: =1/(1-B5) -> 42.47022 | C6: 42 quarters (Section 14.2)
A7: Capability kept each quarter, alpha | B7: 0.975 | C7: Chapter 7
A8: Cost of a point hired and trained, k | B8: 4 | C8: $4 million a point
A9: Hiring cap a quarter (points) | B9: 2.5
A10: Capability floor | B10: 55
A11: Cost of a point-quarter short, p | B11: 1.6 | C11: $1.6 million (Chapter 7)
A12: Lowest capability on the agent's grid | B12: 30
A13: Highest capability on the grid | B13: 80
A14: Grid step (points) | B14: 0.25 | C14: The engineering office counts quarter-points
A15: Levels | B15: =ROUND((B13-B12)/B14,0)+1 -> 201 | C15: 201
A16: Hire step (points) | B16: 0.25 | C16: Human resources hires in quarter-points
A17: Hires a quarter may take | B17: =ROUND(B9/B16,0)+1 -> 11 | C17: 0, 0.25, ..., 2.5
A18: Starting capability | B18: 58 | C18: Every rule is priced from 58
A19: Chance of a random decision | B19: 0.1 | C19: One time in ten
A20: Untried decisions start at | B20: 0 | C20: The software's default
A21: Chapter 7's best rule, cost from 58 (0.05-point grid) | B21: 230.755 | C21: Worked Example 7.1
A22: Range of a quarter's value, rbar = k x cap + p x (floor - lowest) | B22: =B8*B9+B11*(B10-B12) -> 50 | C22: From -50 (capability 30, hiring at the cap) to 0
A24: Swing w (points lost) | B24: Chance | C24: The record: count (40 quarters) | D24: The record: frequency | E24: Grid steps, w / step
A25: 1.5 | B25: 0.05 | C25: 2 | D25: =C25/SUM($C$25:$C$29) -> 0.05 | E25: =ROUND(A25/$B$14,0) -> 6
A26: 0.75 | B26: 0.2 | C26: 8 | D26: =C26/SUM($C$25:$C$29) -> 0.2 | E26: =ROUND(A26/$B$14,0) -> 3
A27: 0 | B27: 0.5 | C27: 20 | D27: =C27/SUM($C$25:$C$29) -> 0.5 | E27: =ROUND(A27/$B$14,0) -> 0
A28: -0.75 | B28: 0.2 | C28: 8 | D28: =C28/SUM($C$25:$C$29) -> 0.2 | E28: =ROUND(A28/$B$14,0) -> -3
A29: -1.5 | B29: 0.05 | C29: 2 | D29: =C29/SUM($C$25:$C$29) -> 0.05 | E29: =ROUND(A29/$B$14,0) -> -6
A30: Total | B30: =SUM(B25:B29) -> 1 | C30: =SUM(C25:C29) -> 40
A31: Mean swing | B31: =SUMPRODUCT(A25:A29,B25:B29) -> 0
A32: Standard deviation of a swing | B32: =SQRT(SUMPRODUCT(A25:A29,A25:A29,B25:B29)-B31^2) -> 0.67082039
A33: c' = 0.975c + h - w; the next capability is placed on the grid by unbiased rounding: the upper neighbour with chance equal to its fractional position (Chapter 7's interpolation).
A35: New declarations (Chapter 14)
A36: The agent: tabular Q-learning (Equation 14.2), one random admissible decision in ten, step size 1/(1 + (1 - beta) n) after n trials of a pair, untried decisions at zero, ties to the smallest hire; it knows the costs and the discount, not the law of the swings.
A37: The board's guardrail: never plan below 55 unless hiring at the cap.
A38: The audit committee: adopt a learned rule only after exact evaluation under the declared model, with the guardrail checked at every capability.
A40: Seeds (Online Appendix Remark 14.B.1)
A41: Q-learning in the simulator: the first million quarters | B41: 1400 | C41: 25 agents
A42: the declared-step agents' second million | B42: 1401 | C42: 10 agents
A43: Greedy learners | B43: 1403 | C43: 20 agents, 100,000 quarters
A44: Bandit: pools of simulated decades | B44: 1407 | C44: 50,000 decades a target
...

Sheet Grid
A1: The agent's grid: admissible decisions and the board's guardrail (Worked Example 14.1, Step 1; Definition 14.2; AXIOM Lab 2.14, step 1)
A2: A hire h at capability c is admissible when 0.975c + h - w stays within [30, 80] for every swing w; it is inside the guardrail when it plans at least 55, or hires at the cap where no admissible hire plans 55.
B3: hire h: | C3: =0*Step_h -> 0 | D3: =1*Step_h -> 0.25 | E3: =2*Step_h -> 0.5 | F3: =3*Step_h -> 0.75 | G3: =4*Step_h -> 1 | H3: =5*Step_h -> 1.25 | I3: =6*Step_h -> 1.5 | J3: =7*Step_h -> 1.75 | K3: =8*Step_h -> 2 | L3: =9*Step_h -> 2.25 | M3: =10*Step_h -> 2.5 | N3: =C3 -> 0 | O3: =D3 -> 0.25 | P3: =E3 -> 0.5 | Q3: =F3 -> 0.75 | R3: =G3 -> 1 | S3: =H3 -> 1.25 | T3: =I3 -> 1.5 | U3: =J3 -> 1.75 | ... X3: =M3 -> 2.5 | AD3: Summary | AE3: Value
A4: Capability c | B4: Can plan 55 (1 = yes) | C4: Admissible, h = 0 | D4: Admissible, h = 0.25 | E4: Admissible, h = 0.5 | F4: Admissible, h = 0.75 | G4: Admissible, h = 1 | H4: Admissible, h = 1.25 | I4: Admissible, h = 1.5 | J4: Admissible, h = 1.75 | K4: Admissible, h = 2 | L4: Admissible, h = 2.25 | M4: Admissible, h = 2.5 | N4: Guarded, h = 0 | O4: Guarded, h = 0.25 | P4: Guarded, h = 0.5 | Q4: Guarded, h = 0.75 | R4: Guarded, h = 1 | S4: Guarded, h = 1.25 | T4: Guarded, h = 1.5 | U4: Guarded, h = 1.75 | V4: Guarded, h = 2 | W4: Guarded, h = 2.25 | X4: Guarded, h = 2.5 | Y4: Admissible hires | Z4: Guarded hires | AA4: Lowest admissible hire | AB4: Highest guarded hire | AD4: Admissible decisions | AE4: =SUM(Y5:Y205) -> 2113 | AF4: 2,113
A5: =Lo_c -> 30 | B5: =IF(SUMPRODUCT((Alpha_keep*$A5+$C$3:$M$3>=Floor_c-0.000000001)*(C5:M5))>0,1,0) -> 0 | C5: =IF(AND(Alpha_keep*$A5+C$3-MAX(Loss_w)>=Lo_c-0.000000001,Alpha_keep*$A5+C$3-MIN(Loss_w)<=Hi_c+0.000000001),1,0) -> 0 | D5: =IF(AND(Alpha_keep*$A5+D$3-MAX(Loss_w)>=Lo_c-0.000000001,Alpha_keep*$A5+D$3-MIN(Loss_w)<=Hi_c+0.000000001),1,0) -> 0 | E5: =IF(AND(Alpha_keep*$A5+E$3-MAX(Loss_w)>=Lo_c-0.000000001,Alpha_keep*$A5+E$3-MIN(Loss_w)<=Hi_c+0.000000001),1,0) -> 0 | F5: =IF(AND(Alpha_keep*$A5+F$3-MAX(Loss_w)>=Lo_c-0.000000001,Alpha_keep*$A5+F$3-MIN(Loss_w)<=Hi_c+0.000000001),1,0) -> 0 | G5: =IF(AND(Alpha_keep*$A5+G$3-MAX(Loss_w)>=Lo_c-0.000000001,Alpha_keep*$A5+G$3-MIN(Loss_w)<=Hi_c+0.000000001),1,0) -> 0 | H5: =IF(AND(Alpha_keep*$A5+H$3-MAX(Loss_w)>=Lo_c-0.000000001,Alpha_keep*$A5+H$3-MIN(Loss_w)<=Hi_c+0.000000001),1,0) -> 0 | I5: =IF(AND(Alpha_keep*$A5+I$3-MAX(Loss_w)>=Lo_c-0.000000001,Alpha_keep*$A5+I$3-MIN(Loss_w)<=Hi_c+0.000000001),1,0) -> 0 | J5: =IF(AND(Alpha_keep*$A5+J$3-MAX(Loss_w)>=Lo_c-0.000000001,Alpha_keep*$A5+J$3-MIN(Loss_w)<=Hi_c+0.000000001),1,0) -> 0 | ... M5: =IF(AND(Alpha_keep*$A5+M$3-MAX(Loss_w)>=Lo_c-0.000000001,Alpha_keep*$A5+M$3-MIN(Loss_w)<=Hi_c+0.000000001),1,0) -> 1 | N5: =IF(C5=1,IF(OR(Alpha_keep*$A5+N$3>=Floor_c-0.000000001,AND($B5=0,N$3>=Cap_h-0.000000001)),1,0),0) -> 0 | O5: =IF(D5=1,IF(OR(Alpha_keep*$A5+O$3>=Floor_c-0.000000001,AND($B5=0,O$3>=Cap_h-0.000000001)),1,0),0) -> 0 | P5: =IF(E5=1,IF(OR(Alpha_keep*$A5+P$3>=Floor_c-0.000000001,AND($B5=0,P$3>=Cap_h-0.000000001)),1,0),0) -> 0 | Q5: =IF(F5=1,IF(OR(Alpha_keep*$A5+Q$3>=Floor_c-0.000000001,AND($B5=0,Q$3>=Cap_h-0.000000001)),1,0),0) -> 0 | R5: =IF(G5=1,IF(OR(Alpha_keep*$A5+R$3>=Floor_c-0.000000001,AND($B5=0,R$3>=Cap_h-0.000000001)),1,0),0) -> 0 | S5: =IF(H5=1,IF(OR(Alpha_keep*$A5+S$3>=Floor_c-0.000000001,AND($B5=0,S$3>=Cap_h-0.000000001)),1,0),0) -> 0 | T5: =IF(I5=1,IF(OR(Alpha_keep*$A5+T$3>=Floor_c-0.000000001,AND($B5=0,T$3>=Cap_h-0.000000001)),1,0),0) -> 0 | U5: =IF(J5=1,IF(OR(Alpha_keep*$A5+U$3>=Floor_c-0.000000001,AND($B5=0,U$3>=Cap_h-0.000000001)),1,0),0) -> 0 | ... X5: =IF(M5=1,IF(OR(Alpha_keep*$A5+X$3>=Floor_c-0.000000001,AND($B5=0,X$3>=Cap_h-0.000000001)),1,0),0) -> 1 | Y5: =SUM(C5:M5) -> 2 | Z5: =SUM(N5:X5) -> 1 | AA5: =INDEX($C$3:$M$3,MATCH(1,C5:M5,0)) -> 2.25 | AB5: =INDEX($N$3:$X$3,MATCH(1,N5:X5,0))+(Z5-1)*Step_h -> 2.5 | AD5: Decisions inside the guardrail | AE5: =SUM(Z5:Z205) -> 1152 | AF5: 1,152
A6: =A5+Step_c -> 30.25 | B6: =IF(SUMPRODUCT((Alpha_keep*$A6+$C$3:$M$3>=Floor_c-0.000000001)*(C6:M6))>0,1,0) -> 0 | C6: =IF(AND(Alpha_keep*$A6+C$3-MAX(Loss_w)>=Lo_c-0.000000001,Alpha_keep*$A6+C$3-MIN(Loss_w)<=Hi_c+0.000000001),1,0) -> 0 | D6: =IF(AND(Alpha_keep*$A6+D$3-MAX(Loss_w)>=Lo_c-0.000000001,Alpha_keep*$A6+D$3-MIN(Loss_w)<=Hi_c+0.000000001),1,0) -> 0 | E6: =IF(AND(Alpha_keep*$A6+E$3-MAX(Loss_w)>=Lo_c-0.000000001,Alpha_keep*$A6+E$3-MIN(Loss_w)<=Hi_c+0.000000001),1,0) -> 0 | F6: =IF(AND(Alpha_keep*$A6+F$3-MAX(Loss_w)>=Lo_c-0.000000001,Alpha_keep*$A6+F$3-MIN(Loss_w)<=Hi_c+0.000000001),1,0) -> 0 | G6: =IF(AND(Alpha_keep*$A6+G$3-MAX(Loss_w)>=Lo_c-0.000000001,Alpha_keep*$A6+G$3-MIN(Loss_w)<=Hi_c+0.000000001),1,0) -> 0 | H6: =IF(AND(Alpha_keep*$A6+H$3-MAX(Loss_w)>=Lo_c-0.000000001,Alpha_keep*$A6+H$3-MIN(Loss_w)<=Hi_c+0.000000001),1,0) -> 0 | I6: =IF(AND(Alpha_keep*$A6+I$3-MAX(Loss_w)>=Lo_c-0.000000001,Alpha_keep*$A6+I$3-MIN(Loss_w)<=Hi_c+0.000000001),1,0) -> 0 | J6: =IF(AND(Alpha_keep*$A6+J$3-MAX(Loss_w)>=Lo_c-0.000000001,Alpha_keep*$A6+J$3-MIN(Loss_w)<=Hi_c+0.000000001),1,0) -> 0 | ... M6: =IF(AND(Alpha_keep*$A6+M$3-MAX(Loss_w)>=Lo_c-0.000000001,Alpha_keep*$A6+M$3-MIN(Loss_w)<=Hi_c+0.000000001),1,0) -> 1 | N6: =IF(C6=1,IF(OR(Alpha_keep*$A6+N$3>=Floor_c-0.000000001,AND($B6=0,N$3>=Cap_h-0.000000001)),1,0),0) -> 0 | O6: =IF(D6=1,IF(OR(Alpha_keep*$A6+O$3>=Floor_c-0.000000001,AND($B6=0,O$3>=Cap_h-0.000000001)),1,0),0) -> 0 | P6: =IF(E6=1,IF(OR(Alpha_keep*$A6+P$3>=Floor_c-0.000000001,AND($B6=0,P$3>=Cap_h-0.000000001)),1,0),0) -> 0 | Q6: =IF(F6=1,IF(OR(Alpha_keep*$A6+Q$3>=Floor_c-0.000000001,AND($B6=0,Q$3>=Cap_h-0.000000001)),1,0),0) -> 0 | R6: =IF(G6=1,IF(OR(Alpha_keep*$A6+R$3>=Floor_c-0.000000001,AND($B6=0,R$3>=Cap_h-0.000000001)),1,0),0) -> 0 | S6: =IF(H6=1,IF(OR(Alpha_keep*$A6+S$3>=Floor_c-0.000000001,AND($B6=0,S$3>=Cap_h-0.000000001)),1,0),0) -> 0 | T6: =IF(I6=1,IF(OR(Alpha_keep*$A6+T$3>=Floor_c-0.000000001,AND($B6=0,T$3>=Cap_h-0.000000001)),1,0),0) -> 0 | U6: =IF(J6=1,IF(OR(Alpha_keep*$A6+U$3>=Floor_c-0.000000001,AND($B6=0,U$3>=Cap_h-0.000000001)),1,0),0) -> 0 | ... X6: =IF(M6=1,IF(OR(Alpha_keep*$A6+X$3>=Floor_c-0.000000001,AND($B6=0,X$3>=Cap_h-0.000000001)),1,0),0) -> 1 | Y6: =SUM(C6:M6) -> 2 | Z6: =SUM(N6:X6) -> 1 | AA6: =INDEX($C$3:$M$3,MATCH(1,C6:M6,0)) -> 2.25 | AB6: =INDEX($N$3:$X$3,MATCH(1,N6:X6,0))+(Z6-1)*Step_h -> 2.5 | AD6: Levels that cannot plan 55 | AE6: =COUNTIF(B5:B205,0) -> 96 | AF6: There the guardrail asks for the cap
A7: =A6+Step_c -> 30.5 | B7: =IF(SUMPRODUCT((Alpha_keep*$A7+$C$3:$M$3>=Floor_c-0.000000001)*(C7:M7))>0,1,0) -> 0 | C7: =IF(AND(Alpha_keep*$A7+C$3-MAX(Loss_w)>=Lo_c-0.000000001,Alpha_keep*$A7+C$3-MIN(Loss_w)<=Hi_c+0.000000001),1,0) -> 0 | D7: =IF(AND(Alpha_keep*$A7+D$3-MAX(Loss_w)>=Lo_c-0.000000001,Alpha_keep*$A7+D$3-MIN(Loss_w)<=Hi_c+0.000000001),1,0) -> 0 | E7: =IF(AND(Alpha_keep*$A7+E$3-MAX(Loss_w)>=Lo_c-0.000000001,Alpha_keep*$A7+E$3-MIN(Loss_w)<=Hi_c+0.000000001),1,0) -> 0 | F7: =IF(AND(Alpha_keep*$A7+F$3-MAX(Loss_w)>=Lo_c-0.000000001,Alpha_keep*$A7+F$3-MIN(Loss_w)<=Hi_c+0.000000001),1,0) -> 0 | G7: =IF(AND(Alpha_keep*$A7+G$3-MAX(Loss_w)>=Lo_c-0.000000001,Alpha_keep*$A7+G$3-MIN(Loss_w)<=Hi_c+0.000000001),1,0) -> 0 | H7: =IF(AND(Alpha_keep*$A7+H$3-MAX(Loss_w)>=Lo_c-0.000000001,Alpha_keep*$A7+H$3-MIN(Loss_w)<=Hi_c+0.000000001),1,0) -> 0 | I7: =IF(AND(Alpha_keep*$A7+I$3-MAX(Loss_w)>=Lo_c-0.000000001,Alpha_keep*$A7+I$3-MIN(Loss_w)<=Hi_c+0.000000001),1,0) -> 0 | J7: =IF(AND(Alpha_keep*$A7+J$3-MAX(Loss_w)>=Lo_c-0.000000001,Alpha_keep*$A7+J$3-MIN(Loss_w)<=Hi_c+0.000000001),1,0) -> 0 | ... M7: =IF(AND(Alpha_keep*$A7+M$3-MAX(Loss_w)>=Lo_c-0.000000001,Alpha_keep*$A7+M$3-MIN(Loss_w)<=Hi_c+0.000000001),1,0) -> 1 | N7: =IF(C7=1,IF(OR(Alpha_keep*$A7+N$3>=Floor_c-0.000000001,AND($B7=0,N$3>=Cap_h-0.000000001)),1,0),0) -> 0 | O7: =IF(D7=1,IF(OR(Alpha_keep*$A7+O$3>=Floor_c-0.000000001,AND($B7=0,O$3>=Cap_h-0.000000001)),1,0),0) -> 0 | P7: =IF(E7=1,IF(OR(Alpha_keep*$A7+P$3>=Floor_c-0.000000001,AND($B7=0,P$3>=Cap_h-0.000000001)),1,0),0) -> 0 | Q7: =IF(F7=1,IF(OR(Alpha_keep*$A7+Q$3>=Floor_c-0.000000001,AND($B7=0,Q$3>=Cap_h-0.000000001)),1,0),0) -> 0 | R7: =IF(G7=1,IF(OR(Alpha_keep*$A7+R$3>=Floor_c-0.000000001,AND($B7=0,R$3>=Cap_h-0.000000001)),1,0),0) -> 0 | S7: =IF(H7=1,IF(OR(Alpha_keep*$A7+S$3>=Floor_c-0.000000001,AND($B7=0,S$3>=Cap_h-0.000000001)),1,0),0) -> 0 | T7: =IF(I7=1,IF(OR(Alpha_keep*$A7+T$3>=Floor_c-0.000000001,AND($B7=0,T$3>=Cap_h-0.000000001)),1,0),0) -> 0 | U7: =IF(J7=1,IF(OR(Alpha_keep*$A7+U$3>=Floor_c-0.000000001,AND($B7=0,U$3>=Cap_h-0.000000001)),1,0),0) -> 0 | ... X7: =IF(M7=1,IF(OR(Alpha_keep*$A7+X$3>=Floor_c-0.000000001,AND($B7=0,X$3>=Cap_h-0.000000001)),1,0),0) -> 1 | Y7: =SUM(C7:M7) -> 3 | Z7: =SUM(N7:X7) -> 1 | AA7: =INDEX($C$3:$M$3,MATCH(1,C7:M7,0)) -> 2 | AB7: =INDEX($N$3:$X$3,MATCH(1,N7:X7,0))+(Z7-1)*Step_h -> 2.5 | AD7: the highest of them | AE7: =_xlfn.MAXIFS($A$5:$A$205,B5:B205,0) -> 53.75
A8: =A7+Step_c -> 30.75 | B8: =IF(SUMPRODUCT((Alpha_keep*$A8+$C$3:$M$3>=Floor_c-0.000000001)*(C8:M8))>0,1,0) -> 0 | C8: =IF(AND(Alpha_keep*$A8+C$3-MAX(Loss_w)>=Lo_c-0.000000001,Alpha_keep*$A8+C$3-MIN(Loss_w)<=Hi_c+0.000000001),1,0) -> 0 | D8: =IF(AND(Alpha_keep*$A8+D$3-MAX(Loss_w)>=Lo_c-0.000000001,Alpha_keep*$A8+D$3-MIN(Loss_w)<=Hi_c+0.000000001),1,0) -> 0 | E8: =IF(AND(Alpha_keep*$A8+E$3-MAX(Loss_w)>=Lo_c-0.000000001,Alpha_keep*$A8+E$3-MIN(Loss_w)<=Hi_c+0.000000001),1,0) -> 0 | F8: =IF(AND(Alpha_keep*$A8+F$3-MAX(Loss_w)>=Lo_c-0.000000001,Alpha_keep*$A8+F$3-MIN(Loss_w)<=Hi_c+0.000000001),1,0) -> 0 | G8: =IF(AND(Alpha_keep*$A8+G$3-MAX(Loss_w)>=Lo_c-0.000000001,Alpha_keep*$A8+G$3-MIN(Loss_w)<=Hi_c+0.000000001),1,0) -> 0 | H8: =IF(AND(Alpha_keep*$A8+H$3-MAX(Loss_w)>=Lo_c-0.000000001,Alpha_keep*$A8+H$3-MIN(Loss_w)<=Hi_c+0.000000001),1,0) -> 0 | I8: =IF(AND(Alpha_keep*$A8+I$3-MAX(Loss_w)>=Lo_c-0.000000001,Alpha_keep*$A8+I$3-MIN(Loss_w)<=Hi_c+0.000000001),1,0) -> 0 | J8: =IF(AND(Alpha_keep*$A8+J$3-MAX(Loss_w)>=Lo_c-0.000000001,Alpha_keep*$A8+J$3-MIN(Loss_w)<=Hi_c+0.000000001),1,0) -> 1 | ... M8: =IF(AND(Alpha_keep*$A8+M$3-MAX(Loss_w)>=Lo_c-0.000000001,Alpha_keep*$A8+M$3-MIN(Loss_w)<=Hi_c+0.000000001),1,0) -> 1 | N8: =IF(C8=1,IF(OR(Alpha_keep*$A8+N$3>=Floor_c-0.000000001,AND($B8=0,N$3>=Cap_h-0.000000001)),1,0),0) -> 0 | O8: =IF(D8=1,IF(OR(Alpha_keep*$A8+O$3>=Floor_c-0.000000001,AND($B8=0,O$3>=Cap_h-0.000000001)),1,0),0) -> 0 | P8: =IF(E8=1,IF(OR(Alpha_keep*$A8+P$3>=Floor_c-0.000000001,AND($B8=0,P$3>=Cap_h-0.000000001)),1,0),0) -> 0 | Q8: =IF(F8=1,IF(OR(Alpha_keep*$A8+Q$3>=Floor_c-0.000000001,AND($B8=0,Q$3>=Cap_h-0.000000001)),1,0),0) -> 0 | R8: =IF(G8=1,IF(OR(Alpha_keep*$A8+R$3>=Floor_c-0.000000001,AND($B8=0,R$3>=Cap_h-0.000000001)),1,0),0) -> 0 | S8: =IF(H8=1,IF(OR(Alpha_keep*$A8+S$3>=Floor_c-0.000000001,AND($B8=0,S$3>=Cap_h-0.000000001)),1,0),0) -> 0 | T8: =IF(I8=1,IF(OR(Alpha_keep*$A8+T$3>=Floor_c-0.000000001,AND($B8=0,T$3>=Cap_h-0.000000001)),1,0),0) -> 0 | U8: =IF(J8=1,IF(OR(Alpha_keep*$A8+U$3>=Floor_c-0.000000001,AND($B8=0,U$3>=Cap_h-0.000000001)),1,0),0) -> 0 | ... X8: =IF(M8=1,IF(OR(Alpha_keep*$A8+X$3>=Floor_c-0.000000001,AND($B8=0,X$3>=Cap_h-0.000000001)),1,0),0) -> 1 | Y8: =SUM(C8:M8) -> 4 | Z8: =SUM(N8:X8) -> 1 | AA8: =INDEX($C$3:$M$3,MATCH(1,C8:M8,0)) -> 1.75 | AB8: =INDEX($N$3:$X$3,MATCH(1,N8:X8,0))+(Z8-1)*Step_h -> 2.5
A9: =A8+Step_c -> 31 | B9: =IF(SUMPRODUCT((Alpha_keep*$A9+$C$3:$M$3>=Floor_c-0.000000001)*(C9:M9))>0,1,0) -> 0 | C9: =IF(AND(Alpha_keep*$A9+C$3-MAX(Loss_w)>=Lo_c-0.000000001,Alpha_keep*$A9+C$3-MIN(Loss_w)<=Hi_c+0.000000001),1,0) -> 0 | D9: =IF(AND(Alpha_keep*$A9+D$3-MAX(Loss_w)>=Lo_c-0.000000001,Alpha_keep*$A9+D$3-MIN(Loss_w)<=Hi_c+0.000000001),1,0) -> 0 | E9: =IF(AND(Alpha_keep*$A9+E$3-MAX(Loss_w)>=Lo_c-0.000000001,Alpha_keep*$A9+E$3-MIN(Loss_w)<=Hi_c+0.000000001),1,0) -> 0 | F9: =IF(AND(Alpha_keep*$A9+F$3-MAX(Loss_w)>=Lo_c-0.000000001,Alpha_keep*$A9+F$3-MIN(Loss_w)<=Hi_c+0.000000001),1,0) -> 0 | G9: =IF(AND(Alpha_keep*$A9+G$3-MAX(Loss_w)>=Lo_c-0.000000001,Alpha_keep*$A9+G$3-MIN(Loss_w)<=Hi_c+0.000000001),1,0) -> 0 | H9: =IF(AND(Alpha_keep*$A9+H$3-MAX(Loss_w)>=Lo_c-0.000000001,Alpha_keep*$A9+H$3-MIN(Loss_w)<=Hi_c+0.000000001),1,0) -> 0 | I9: =IF(AND(Alpha_keep*$A9+I$3-MAX(Loss_w)>=Lo_c-0.000000001,Alpha_keep*$A9+I$3-MIN(Loss_w)<=Hi_c+0.000000001),1,0) -> 1 | J9: =IF(AND(Alpha_keep*$A9+J$3-MAX(Loss_w)>=Lo_c-0.000000001,Alpha_keep*$A9+J$3-MIN(Loss_w)<=Hi_c+0.000000001),1,0) -> 1 | ... M9: =IF(AND(Alpha_keep*$A9+M$3-MAX(Loss_w)>=Lo_c-0.000000001,Alpha_keep*$A9+M$3-MIN(Loss_w)<=Hi_c+0.000000001),1,0) -> 1 | N9: =IF(C9=1,IF(OR(Alpha_keep*$A9+N$3>=Floor_c-0.000000001,AND($B9=0,N$3>=Cap_h-0.000000001)),1,0),0) -> 0 | O9: =IF(D9=1,IF(OR(Alpha_keep*$A9+O$3>=Floor_c-0.000000001,AND($B9=0,O$3>=Cap_h-0.000000001)),1,0),0) -> 0 | P9: =IF(E9=1,IF(OR(Alpha_keep*$A9+P$3>=Floor_c-0.000000001,AND($B9=0,P$3>=Cap_h-0.000000001)),1,0),0) -> 0 | Q9: =IF(F9=1,IF(OR(Alpha_keep*$A9+Q$3>=Floor_c-0.000000001,AND($B9=0,Q$3>=Cap_h-0.000000001)),1,0),0) -> 0 | R9: =IF(G9=1,IF(OR(Alpha_keep*$A9+R$3>=Floor_c-0.000000001,AND($B9=0,R$3>=Cap_h-0.000000001)),1,0),0) -> 0 | S9: =IF(H9=1,IF(OR(Alpha_keep*$A9+S$3>=Floor_c-0.000000001,AND($B9=0,S$3>=Cap_h-0.000000001)),1,0),0) -> 0 | T9: =IF(I9=1,IF(OR(Alpha_keep*$A9+T$3>=Floor_c-0.000000001,AND($B9=0,T$3>=Cap_h-0.000000001)),1,0),0) -> 0 | U9: =IF(J9=1,IF(OR(Alpha_keep*$A9+U$3>=Floor_c-0.000000001,AND($B9=0,U$3>=Cap_h-0.000000001)),1,0),0) -> 0 | ... X9: =IF(M9=1,IF(OR(Alpha_keep*$A9+X$3>=Floor_c-0.000000001,AND($B9=0,X$3>=Cap_h-0.000000001)),1,0),0) -> 1 | Y9: =SUM(C9:M9) -> 5 | Z9: =SUM(N9:X9) -> 1 | AA9: =INDEX($C$3:$M$3,MATCH(1,C9:M9,0)) -> 1.5 | AB9: =INDEX($N$3:$X$3,MATCH(1,N9:X9,0))+(Z9-1)*Step_h -> 2.5 | AD9: Admissible hires form a run of quarter-points, and the guarded ones end at the highest admissible hire: the highest guarded hire is the lowest guarded hire plus the run's length.
A10: =A9+Step_c -> 31.25 | B10: =IF(SUMPRODUCT((Alpha_keep*$A10+$C$3:$M$3>=Floor_c-0.000000001)*(C10:M10))>0,1,0) -> 0 | C10: =IF(AND(Alpha_keep*$A10+C$3-MAX(Loss_w)>=Lo_c-0.000000001,Alpha_keep*$A10+C$3-MIN(Loss_w)<=Hi_c+0.000000001),1,0) -> 0 | D10: =IF(AND(Alpha_keep*$A10+D$3-MAX(Loss_w)>=Lo_c-0.000000001,Alpha_keep*$A10+D$3-MIN(Loss_w)<=Hi_c+0.000000001),1,0) -> 0 | E10: =IF(AND(Alpha_keep*$A10+E$3-MAX(Loss_w)>=Lo_c-0.000000001,Alpha_keep*$A10+E$3-MIN(Loss_w)<=Hi_c+0.000000001),1,0) -> 0 | F10: =IF(AND(Alpha_keep*$A10+F$3-MAX(Loss_w)>=Lo_c-0.000000001,Alpha_keep*$A10+F$3-MIN(Loss_w)<=Hi_c+0.000000001),1,0) -> 0 | G10: =IF(AND(Alpha_keep*$A10+G$3-MAX(Loss_w)>=Lo_c-0.000000001,Alpha_keep*$A10+G$3-MIN(Loss_w)<=Hi_c+0.000000001),1,0) -> 0 | H10: =IF(AND(Alpha_keep*$A10+H$3-MAX(Loss_w)>=Lo_c-0.000000001,Alpha_keep*$A10+H$3-MIN(Loss_w)<=Hi_c+0.000000001),1,0) -> 1 | I10: =IF(AND(Alpha_keep*$A10+I$3-MAX(Loss_w)>=Lo_c-0.000000001,Alpha_keep*$A10+I$3-MIN(Loss_w)<=Hi_c+0.000000001),1,0) -> 1 | J10: =IF(AND(Alpha_keep*$A10+J$3-MAX(Loss_w)>=Lo_c-0.000000001,Alpha_keep*$A10+J$3-MIN(Loss_w)<=Hi_c+0.000000001),1,0) -> 1 | ... M10: =IF(AND(Alpha_keep*$A10+M$3-MAX(Loss_w)>=Lo_c-0.000000001,Alpha_keep*$A10+M$3-MIN(Loss_w)<=Hi_c+0.000000001),1,0) -> 1 | N10: =IF(C10=1,IF(OR(Alpha_keep*$A10+N$3>=Floor_c-0.000000001,AND($B10=0,N$3>=Cap_h-0.000000001)),1,0),0) -> 0 | O10: =IF(D10=1,IF(OR(Alpha_keep*$A10+O$3>=Floor_c-0.000000001,AND($B10=0,O$3>=Cap_h-0.000000001)),1,0),0) -> 0 | P10: =IF(E10=1,IF(OR(Alpha_keep*$A10+P$3>=Floor_c-0.000000001,AND($B10=0,P$3>=Cap_h-0.000000001)),1,0),0) -> 0 | Q10: =IF(F10=1,IF(OR(Alpha_keep*$A10+Q$3>=Floor_c-0.000000001,AND($B10=0,Q$3>=Cap_h-0.000000001)),1,0),0) -> 0 | R10: =IF(G10=1,IF(OR(Alpha_keep*$A10+R$3>=Floor_c-0.000000001,AND($B10=0,R$3>=Cap_h-0.000000001)),1,0),0) -> 0 | S10: =IF(H10=1,IF(OR(Alpha_keep*$A10+S$3>=Floor_c-0.000000001,AND($B10=0,S$3>=Cap_h-0.000000001)),1,0),0) -> 0 | T10: =IF(I10=1,IF(OR(Alpha_keep*$A10+T$3>=Floor_c-0.000000001,AND($B10=0,T$3>=Cap_h-0.000000001)),1,0),0) -> 0 | U10: =IF(J10=1,IF(OR(Alpha_keep*$A10+U$3>=Floor_c-0.000000001,AND($B10=0,U$3>=Cap_h-0.000000001)),1,0),0) -> 0 | ... X10: =IF(M10=1,IF(OR(Alpha_keep*$A10+X$3>=Floor_c-0.000000001,AND($B10=0,X$3>=Cap_h-0.000000001)),1,0),0) -> 1 | Y10: =SUM(C10:M10) -> 6 | Z10: =SUM(N10:X10) -> 1 | AA10: =INDEX($C$3:$M$3,MATCH(1,C10:M10,0)) -> 1.25 | AB10: =INDEX($N$3:$X$3,MATCH(1,N10:X10,0))+(Z10-1)*Step_h -> 2.5
A11: =A10+Step_c -> 31.5 | B11: =IF(SUMPRODUCT((Alpha_keep*$A11+$C$3:$M$3>=Floor_c-0.000000001)*(C11:M11))>0,1,0) -> 0 | C11: =IF(AND(Alpha_keep*$A11+C$3-MAX(Loss_w)>=Lo_c-0.000000001,Alpha_keep*$A11+C$3-MIN(Loss_w)<=Hi_c+0.000000001),1,0) -> 0 | D11: =IF(AND(Alpha_keep*$A11+D$3-MAX(Loss_w)>=Lo_c-0.000000001,Alpha_keep*$A11+D$3-MIN(Loss_w)<=Hi_c+0.000000001),1,0) -> 0 | E11: =IF(AND(Alpha_keep*$A11+E$3-MAX(Loss_w)>=Lo_c-0.000000001,Alpha_keep*$A11+E$3-MIN(Loss_w)<=Hi_c+0.000000001),1,0) -> 0 | F11: =IF(AND(Alpha_keep*$A11+F$3-MAX(Loss_w)>=Lo_c-0.000000001,Alpha_keep*$A11+F$3-MIN(Loss_w)<=Hi_c+0.000000001),1,0) -> 0 | G11: =IF(AND(Alpha_keep*$A11+G$3-MAX(Loss_w)>=Lo_c-0.000000001,Alpha_keep*$A11+G$3-MIN(Loss_w)<=Hi_c+0.000000001),1,0) -> 1 | H11: =IF(AND(Alpha_keep*$A11+H$3-MAX(Loss_w)>=Lo_c-0.000000001,Alpha_keep*$A11+H$3-MIN(Loss_w)<=Hi_c+0.000000001),1,0) -> 1 | I11: =IF(AND(Alpha_keep*$A11+I$3-MAX(Loss_w)>=Lo_c-0.000000001,Alpha_keep*$A11+I$3-MIN(Loss_w)<=Hi_c+0.000000001),1,0) -> 1 | J11: =IF(AND(Alpha_keep*$A11+J$3-MAX(Loss_w)>=Lo_c-0.000000001,Alpha_keep*$A11+J$3-MIN(Loss_w)<=Hi_c+0.000000001),1,0) -> 1 | ... M11: =IF(AND(Alpha_keep*$A11+M$3-MAX(Loss_w)>=Lo_c-0.000000001,Alpha_keep*$A11+M$3-MIN(Loss_w)<=Hi_c+0.000000001),1,0) -> 1 | N11: =IF(C11=1,IF(OR(Alpha_keep*$A11+N$3>=Floor_c-0.000000001,AND($B11=0,N$3>=Cap_h-0.000000001)),1,0),0) -> 0 | O11: =IF(D11=1,IF(OR(Alpha_keep*$A11+O$3>=Floor_c-0.000000001,AND($B11=0,O$3>=Cap_h-0.000000001)),1,0),0) -> 0 | P11: =IF(E11=1,IF(OR(Alpha_keep*$A11+P$3>=Floor_c-0.000000001,AND($B11=0,P$3>=Cap_h-0.000000001)),1,0),0) -> 0 | Q11: =IF(F11=1,IF(OR(Alpha_keep*$A11+Q$3>=Floor_c-0.000000001,AND($B11=0,Q$3>=Cap_h-0.000000001)),1,0),0) -> 0 | R11: =IF(G11=1,IF(OR(Alpha_keep*$A11+R$3>=Floor_c-0.000000001,AND($B11=0,R$3>=Cap_h-0.000000001)),1,0),0) -> 0 | S11: =IF(H11=1,IF(OR(Alpha_keep*$A11+S$3>=Floor_c-0.000000001,AND($B11=0,S$3>=Cap_h-0.000000001)),1,0),0) -> 0 | T11: =IF(I11=1,IF(OR(Alpha_keep*$A11+T$3>=Floor_c-0.000000001,AND($B11=0,T$3>=Cap_h-0.000000001)),1,0),0) -> 0 | U11: =IF(J11=1,IF(OR(Alpha_keep*$A11+U$3>=Floor_c-0.000000001,AND($B11=0,U$3>=Cap_h-0.000000001)),1,0),0) -> 0 | ... X11: =IF(M11=1,IF(OR(Alpha_keep*$A11+X$3>=Floor_c-0.000000001,AND($B11=0,X$3>=Cap_h-0.000000001)),1,0),0) -> 1 | Y11: =SUM(C11:M11) -> 7 | Z11: =SUM(N11:X11) -> 1 | AA11: =INDEX($C$3:$M$3,MATCH(1,C11:M11,0)) -> 1 | AB11: =INDEX($N$3:$X$3,MATCH(1,N11:X11,0))+(Z11-1)*Step_h -> 2.5
A12: =A11+Step_c -> 31.75 | B12: =IF(SUMPRODUCT((Alpha_keep*$A12+$C$3:$M$3>=Floor_c-0.000000001)*(C12:M12))>0,1,0) -> 0 | C12: =IF(AND(Alpha_keep*$A12+C$3-MAX(Loss_w)>=Lo_c-0.000000001,Alpha_keep*$A12+C$3-MIN(Loss_w)<=Hi_c+0.000000001),1,0) -> 0 | D12: =IF(AND(Alpha_keep*$A12+D$3-MAX(Loss_w)>=Lo_c-0.000000001,Alpha_keep*$A12+D$3-MIN(Loss_w)<=Hi_c+0.000000001),1,0) -> 0 | E12: =IF(AND(Alpha_keep*$A12+E$3-MAX(Loss_w)>=Lo_c-0.000000001,Alpha_keep*$A12+E$3-MIN(Loss_w)<=Hi_c+0.000000001),1,0) -> 0 | F12: =IF(AND(Alpha_keep*$A12+F$3-MAX(Loss_w)>=Lo_c-0.000000001,Alpha_keep*$A12+F$3-MIN(Loss_w)<=Hi_c+0.000000001),1,0) -> 1 | G12: =IF(AND(Alpha_keep*$A12+G$3-MAX(Loss_w)>=Lo_c-0.000000001,Alpha_keep*$A12+G$3-MIN(Loss_w)<=Hi_c+0.000000001),1,0) -> 1 | H12: =IF(AND(Alpha_keep*$A12+H$3-MAX(Loss_w)>=Lo_c-0.000000001,Alpha_keep*$A12+H$3-MIN(Loss_w)<=Hi_c+0.000000001),1,0) -> 1 | I12: =IF(AND(Alpha_keep*$A12+I$3-MAX(Loss_w)>=Lo_c-0.000000001,Alpha_keep*$A12+I$3-MIN(Loss_w)<=Hi_c+0.000000001),1,0) -> 1 | J12: =IF(AND(Alpha_keep*$A12+J$3-MAX(Loss_w)>=Lo_c-0.000000001,Alpha_keep*$A12+J$3-MIN(Loss_w)<=Hi_c+0.000000001),1,0) -> 1 | ... M12: =IF(AND(Alpha_keep*$A12+M$3-MAX(Loss_w)>=Lo_c-0.000000001,Alpha_keep*$A12+M$3-MIN(Loss_w)<=Hi_c+0.000000001),1,0) -> 1 | N12: =IF(C12=1,IF(OR(Alpha_keep*$A12+N$3>=Floor_c-0.000000001,AND($B12=0,N$3>=Cap_h-0.000000001)),1,0),0) -> 0 | O12: =IF(D12=1,IF(OR(Alpha_keep*$A12+O$3>=Floor_c-0.000000001,AND($B12=0,O$3>=Cap_h-0.000000001)),1,0),0) -> 0 | P12: =IF(E12=1,IF(OR(Alpha_keep*$A12+P$3>=Floor_c-0.000000001,AND($B12=0,P$3>=Cap_h-0.000000001)),1,0),0) -> 0 | Q12: =IF(F12=1,IF(OR(Alpha_keep*$A12+Q$3>=Floor_c-0.000000001,AND($B12=0,Q$3>=Cap_h-0.000000001)),1,0),0) -> 0 | R12: =IF(G12=1,IF(OR(Alpha_keep*$A12+R$3>=Floor_c-0.000000001,AND($B12=0,R$3>=Cap_h-0.000000001)),1,0),0) -> 0 | S12: =IF(H12=1,IF(OR(Alpha_keep*$A12+S$3>=Floor_c-0.000000001,AND($B12=0,S$3>=Cap_h-0.000000001)),1,0),0) -> 0 | T12: =IF(I12=1,IF(OR(Alpha_keep*$A12+T$3>=Floor_c-0.000000001,AND($B12=0,T$3>=Cap_h-0.000000001)),1,0),0) -> 0 | U12: =IF(J12=1,IF(OR(Alpha_keep*$A12+U$3>=Floor_c-0.000000001,AND($B12=0,U$3>=Cap_h-0.000000001)),1,0),0) -> 0 | ... X12: =IF(M12=1,IF(OR(Alpha_keep*$A12+X$3>=Floor_c-0.000000001,AND($B12=0,X$3>=Cap_h-0.000000001)),1,0),0) -> 1 | Y12: =SUM(C12:M12) -> 8 | Z12: =SUM(N12:X12) -> 1 | AA12: =INDEX($C$3:$M$3,MATCH(1,C12:M12,0)) -> 0.75 | AB12: =INDEX($N$3:$X$3,MATCH(1,N12:X12,0))+(Z12-1)*Step_h -> 2.5
A13: =A12+Step_c -> 32 | B13: =IF(SUMPRODUCT((Alpha_keep*$A13+$C$3:$M$3>=Floor_c-0.000000001)*(C13:M13))>0,1,0) -> 0 | C13: =IF(AND(Alpha_keep*$A13+C$3-MAX(Loss_w)>=Lo_c-0.000000001,Alpha_keep*$A13+C$3-MIN(Loss_w)<=Hi_c+0.000000001),1,0) -> 0 | D13: =IF(AND(Alpha_keep*$A13+D$3-MAX(Loss_w)>=Lo_c-0.000000001,Alpha_keep*$A13+D$3-MIN(Loss_w)<=Hi_c+0.000000001),1,0) -> 0 | E13: =IF(AND(Alpha_keep*$A13+E$3-MAX(Loss_w)>=Lo_c-0.000000001,Alpha_keep*$A13+E$3-MIN(Loss_w)<=Hi_c+0.000000001),1,0) -> 1 | F13: =IF(AND(Alpha_keep*$A13+F$3-MAX(Loss_w)>=Lo_c-0.000000001,Alpha_keep*$A13+F$3-MIN(Loss_w)<=Hi_c+0.000000001),1,0) -> 1 | G13: =IF(AND(Alpha_keep*$A13+G$3-MAX(Loss_w)>=Lo_c-0.000000001,Alpha_keep*$A13+G$3-MIN(Loss_w)<=Hi_c+0.000000001),1,0) -> 1 | H13: =IF(AND(Alpha_keep*$A13+H$3-MAX(Loss_w)>=Lo_c-0.000000001,Alpha_keep*$A13+H$3-MIN(Loss_w)<=Hi_c+0.000000001),1,0) -> 1 | I13: =IF(AND(Alpha_keep*$A13+I$3-MAX(Loss_w)>=Lo_c-0.000000001,Alpha_keep*$A13+I$3-MIN(Loss_w)<=Hi_c+0.000000001),1,0) -> 1 | J13: =IF(AND(Alpha_keep*$A13+J$3-MAX(Loss_w)>=Lo_c-0.000000001,Alpha_keep*$A13+J$3-MIN(Loss_w)<=Hi_c+0.000000001),1,0) -> 1 | ... M13: =IF(AND(Alpha_keep*$A13+M$3-MAX(Loss_w)>=Lo_c-0.000000001,Alpha_keep*$A13+M$3-MIN(Loss_w)<=Hi_c+0.000000001),1,0) -> 1 | N13: =IF(C13=1,IF(OR(Alpha_keep*$A13+N$3>=Floor_c-0.000000001,AND($B13=0,N$3>=Cap_h-0.000000001)),1,0),0) -> 0 | O13: =IF(D13=1,IF(OR(Alpha_keep*$A13+O$3>=Floor_c-0.000000001,AND($B13=0,O$3>=Cap_h-0.000000001)),1,0),0) -> 0 | P13: =IF(E13=1,IF(OR(Alpha_keep*$A13+P$3>=Floor_c-0.000000001,AND($B13=0,P$3>=Cap_h-0.000000001)),1,0),0) -> 0 | Q13: =IF(F13=1,IF(OR(Alpha_keep*$A13+Q$3>=Floor_c-0.000000001,AND($B13=0,Q$3>=Cap_h-0.000000001)),1,0),0) -> 0 | R13: =IF(G13=1,IF(OR(Alpha_keep*$A13+R$3>=Floor_c-0.000000001,AND($B13=0,R$3>=Cap_h-0.000000001)),1,0),0) -> 0 | S13: =IF(H13=1,IF(OR(Alpha_keep*$A13+S$3>=Floor_c-0.000000001,AND($B13=0,S$3>=Cap_h-0.000000001)),1,0),0) -> 0 | T13: =IF(I13=1,IF(OR(Alpha_keep*$A13+T$3>=Floor_c-0.000000001,AND($B13=0,T$3>=Cap_h-0.000000001)),1,0),0) -> 0 | U13: =IF(J13=1,IF(OR(Alpha_keep*$A13+U$3>=Floor_c-0.000000001,AND($B13=0,U$3>=Cap_h-0.000000001)),1,0),0) -> 0 | ... X13: =IF(M13=1,IF(OR(Alpha_keep*$A13+X$3>=Floor_c-0.000000001,AND($B13=0,X$3>=Cap_h-0.000000001)),1,0),0) -> 1 | Y13: =SUM(C13:M13) -> 9 | Z13: =SUM(N13:X13) -> 1 | AA13: =INDEX($C$3:$M$3,MATCH(1,C13:M13,0)) -> 0.5 | AB13: =INDEX($N$3:$X$3,MATCH(1,N13:X13,0))+(Z13-1)*Step_h -> 2.5
A14: =A13+Step_c -> 32.25 | B14: =IF(SUMPRODUCT((Alpha_keep*$A14+$C$3:$M$3>=Floor_c-0.000000001)*(C14:M14))>0,1,0) -> 0 | C14: =IF(AND(Alpha_keep*$A14+C$3-MAX(Loss_w)>=Lo_c-0.000000001,Alpha_keep*$A14+C$3-MIN(Loss_w)<=Hi_c+0.000000001),1,0) -> 0 | D14: =IF(AND(Alpha_keep*$A14+D$3-MAX(Loss_w)>=Lo_c-0.000000001,Alpha_keep*$A14+D$3-MIN(Loss_w)<=Hi_c+0.000000001),1,0) -> 1 | E14: =IF(AND(Alpha_keep*$A14+E$3-MAX(Loss_w)>=Lo_c-0.000000001,Alpha_keep*$A14+E$3-MIN(Loss_w)<=Hi_c+0.000000001),1,0) -> 1 | F14: =IF(AND(Alpha_keep*$A14+F$3-MAX(Loss_w)>=Lo_c-0.000000001,Alpha_keep*$A14+F$3-MIN(Loss_w)<=Hi_c+0.000000001),1,0) -> 1 | G14: =IF(AND(Alpha_keep*$A14+G$3-MAX(Loss_w)>=Lo_c-0.000000001,Alpha_keep*$A14+G$3-MIN(Loss_w)<=Hi_c+0.000000001),1,0) -> 1 | H14: =IF(AND(Alpha_keep*$A14+H$3-MAX(Loss_w)>=Lo_c-0.000000001,Alpha_keep*$A14+H$3-MIN(Loss_w)<=Hi_c+0.000000001),1,0) -> 1 | I14: =IF(AND(Alpha_keep*$A14+I$3-MAX(Loss_w)>=Lo_c-0.000000001,Alpha_keep*$A14+I$3-MIN(Loss_w)<=Hi_c+0.000000001),1,0) -> 1 | J14: =IF(AND(Alpha_keep*$A14+J$3-MAX(Loss_w)>=Lo_c-0.000000001,Alpha_keep*$A14+J$3-MIN(Loss_w)<=Hi_c+0.000000001),1,0) -> 1 | ... M14: =IF(AND(Alpha_keep*$A14+M$3-MAX(Loss_w)>=Lo_c-0.000000001,Alpha_keep*$A14+M$3-MIN(Loss_w)<=Hi_c+0.000000001),1,0) -> 1 | N14: =IF(C14=1,IF(OR(Alpha_keep*$A14+N$3>=Floor_c-0.000000001,AND($B14=0,N$3>=Cap_h-0.000000001)),1,0),0) -> 0 | O14: =IF(D14=1,IF(OR(Alpha_keep*$A14+O$3>=Floor_c-0.000000001,AND($B14=0,O$3>=Cap_h-0.000000001)),1,0),0) -> 0 | P14: =IF(E14=1,IF(OR(Alpha_keep*$A14+P$3>=Floor_c-0.000000001,AND($B14=0,P$3>=Cap_h-0.000000001)),1,0),0) -> 0 | Q14: =IF(F14=1,IF(OR(Alpha_keep*$A14+Q$3>=Floor_c-0.000000001,AND($B14=0,Q$3>=Cap_h-0.000000001)),1,0),0) -> 0 | R14: =IF(G14=1,IF(OR(Alpha_keep*$A14+R$3>=Floor_c-0.000000001,AND($B14=0,R$3>=Cap_h-0.000000001)),1,0),0) -> 0 | S14: =IF(H14=1,IF(OR(Alpha_keep*$A14+S$3>=Floor_c-0.000000001,AND($B14=0,S$3>=Cap_h-0.000000001)),1,0),0) -> 0 | T14: =IF(I14=1,IF(OR(Alpha_keep*$A14+T$3>=Floor_c-0.000000001,AND($B14=0,T$3>=Cap_h-0.000000001)),1,0),0) -> 0 | U14: =IF(J14=1,IF(OR(Alpha_keep*$A14+U$3>=Floor_c-0.000000001,AND($B14=0,U$3>=Cap_h-0.000000001)),1,0),0) -> 0 | ... X14: =IF(M14=1,IF(OR(Alpha_keep*$A14+X$3>=Floor_c-0.000000001,AND($B14=0,X$3>=Cap_h-0.000000001)),1,0),0) -> 1 | Y14: =SUM(C14:M14) -> 10 | Z14: =SUM(N14:X14) -> 1 | AA14: =INDEX($C$3:$M$3,MATCH(1,C14:M14,0)) -> 0.25 | AB14: =INDEX($N$3:$X$3,MATCH(1,N14:X14,0))+(Z14-1)*Step_h -> 2.5
A15: =A14+Step_c -> 32.5 | B15: =IF(SUMPRODUCT((Alpha_keep*$A15+$C$3:$M$3>=Floor_c-0.000000001)*(C15:M15))>0,1,0) -> 0 | C15: =IF(AND(Alpha_keep*$A15+C$3-MAX(Loss_w)>=Lo_c-0.000000001,Alpha_keep*$A15+C$3-MIN(Loss_w)<=Hi_c+0.000000001),1,0) -> 1 | D15: =IF(AND(Alpha_keep*$A15+D$3-MAX(Loss_w)>=Lo_c-0.000000001,Alpha_keep*$A15+D$3-MIN(Loss_w)<=Hi_c+0.000000001),1,0) -> 1 | E15: =IF(AND(Alpha_keep*$A15+E$3-MAX(Loss_w)>=Lo_c-0.000000001,Alpha_keep*$A15+E$3-MIN(Loss_w)<=Hi_c+0.000000001),1,0) -> 1 | F15: =IF(AND(Alpha_keep*$A15+F$3-MAX(Loss_w)>=Lo_c-0.000000001,Alpha_keep*$A15+F$3-MIN(Loss_w)<=Hi_c+0.000000001),1,0) -> 1 | G15: =IF(AND(Alpha_keep*$A15+G$3-MAX(Loss_w)>=Lo_c-0.000000001,Alpha_keep*$A15+G$3-MIN(Loss_w)<=Hi_c+0.000000001),1,0) -> 1 | H15: =IF(AND(Alpha_keep*$A15+H$3-MAX(Loss_w)>=Lo_c-0.000000001,Alpha_keep*$A15+H$3-MIN(Loss_w)<=Hi_c+0.000000001),1,0) -> 1 | I15: =IF(AND(Alpha_keep*$A15+I$3-MAX(Loss_w)>=Lo_c-0.000000001,Alpha_keep*$A15+I$3-MIN(Loss_w)<=Hi_c+0.000000001),1,0) -> 1 | J15: =IF(AND(Alpha_keep*$A15+J$3-MAX(Loss_w)>=Lo_c-0.000000001,Alpha_keep*$A15+J$3-MIN(Loss_w)<=Hi_c+0.000000001),1,0) -> 1 | ... M15: =IF(AND(Alpha_keep*$A15+M$3-MAX(Loss_w)>=Lo_c-0.000000001,Alpha_keep*$A15+M$3-MIN(Loss_w)<=Hi_c+0.000000001),1,0) -> 1 | N15: =IF(C15=1,IF(OR(Alpha_keep*$A15+N$3>=Floor_c-0.000000001,AND($B15=0,N$3>=Cap_h-0.000000001)),1,0),0) -> 0 | O15: =IF(D15=1,IF(OR(Alpha_keep*$A15+O$3>=Floor_c-0.000000001,AND($B15=0,O$3>=Cap_h-0.000000001)),1,0),0) -> 0 | P15: =IF(E15=1,IF(OR(Alpha_keep*$A15+P$3>=Floor_c-0.000000001,AND($B15=0,P$3>=Cap_h-0.000000001)),1,0),0) -> 0 | Q15: =IF(F15=1,IF(OR(Alpha_keep*$A15+Q$3>=Floor_c-0.000000001,AND($B15=0,Q$3>=Cap_h-0.000000001)),1,0),0) -> 0 | R15: =IF(G15=1,IF(OR(Alpha_keep*$A15+R$3>=Floor_c-0.000000001,AND($B15=0,R$3>=Cap_h-0.000000001)),1,0),0) -> 0 | S15: =IF(H15=1,IF(OR(Alpha_keep*$A15+S$3>=Floor_c-0.000000001,AND($B15=0,S$3>=Cap_h-0.000000001)),1,0),0) -> 0 | T15: =IF(I15=1,IF(OR(Alpha_keep*$A15+T$3>=Floor_c-0.000000001,AND($B15=0,T$3>=Cap_h-0.000000001)),1,0),0) -> 0 | U15: =IF(J15=1,IF(OR(Alpha_keep*$A15+U$3>=Floor_c-0.000000001,AND($B15=0,U$3>=Cap_h-0.000000001)),1,0),0) -> 0 | ... X15: =IF(M15=1,IF(OR(Alpha_keep*$A15+X$3>=Floor_c-0.000000001,AND($B15=0,X$3>=Cap_h-0.000000001)),1,0),0) -> 1 | Y15: =SUM(C15:M15) -> 11 | Z15: =SUM(N15:X15) -> 1 | AA15: =INDEX($C$3:$M$3,MATCH(1,C15:M15,0)) -> 0 | AB15: =INDEX($N$3:$X$3,MATCH(1,N15:X15,0))+(Z15-1)*Step_h -> 2.5
A16: =A15+Step_c -> 32.75 | B16: =IF(SUMPRODUCT((Alpha_keep*$A16+$C$3:$M$3>=Floor_c-0.000000001)*(C16:M16))>0,1,0) -> 0 | C16: =IF(AND(Alpha_keep*$A16+C$3-MAX(Loss_w)>=Lo_c-0.000000001,Alpha_keep*$A16+C$3-MIN(Loss_w)<=Hi_c+0.000000001),1,0) -> 1 | D16: =IF(AND(Alpha_keep*$A16+D$3-MAX(Loss_w)>=Lo_c-0.000000001,Alpha_keep*$A16+D$3-MIN(Loss_w)<=Hi_c+0.000000001),1,0) -> 1 | E16: =IF(AND(Alpha_keep*$A16+E$3-MAX(Loss_w)>=Lo_c-0.000000001,Alpha_keep*$A16+E$3-MIN(Loss_w)<=Hi_c+0.000000001),1,0) -> 1 | F16: =IF(AND(Alpha_keep*$A16+F$3-MAX(Loss_w)>=Lo_c-0.000000001,Alpha_keep*$A16+F$3-MIN(Loss_w)<=Hi_c+0.000000001),1,0) -> 1 | G16: =IF(AND(Alpha_keep*$A16+G$3-MAX(Loss_w)>=Lo_c-0.000000001,Alpha_keep*$A16+G$3-MIN(Loss_w)<=Hi_c+0.000000001),1,0) -> 1 | H16: =IF(AND(Alpha_keep*$A16+H$3-MAX(Loss_w)>=Lo_c-0.000000001,Alpha_keep*$A16+H$3-MIN(Loss_w)<=Hi_c+0.000000001),1,0) -> 1 | I16: =IF(AND(Alpha_keep*$A16+I$3-MAX(Loss_w)>=Lo_c-0.000000001,Alpha_keep*$A16+I$3-MIN(Loss_w)<=Hi_c+0.000000001),1,0) -> 1 | J16: =IF(AND(Alpha_keep*$A16+J$3-MAX(Loss_w)>=Lo_c-0.000000001,Alpha_keep*$A16+J$3-MIN(Loss_w)<=Hi_c+0.000000001),1,0) -> 1 | ... M16: =IF(AND(Alpha_keep*$A16+M$3-MAX(Loss_w)>=Lo_c-0.000000001,Alpha_keep*$A16+M$3-MIN(Loss_w)<=Hi_c+0.000000001),1,0) -> 1 | N16: =IF(C16=1,IF(OR(Alpha_keep*$A16+N$3>=Floor_c-0.000000001,AND($B16=0,N$3>=Cap_h-0.000000001)),1,0),0) -> 0 | O16: =IF(D16=1,IF(OR(Alpha_keep*$A16+O$3>=Floor_c-0.000000001,AND($B16=0,O$3>=Cap_h-0.000000001)),1,0),0) -> 0 | P16: =IF(E16=1,IF(OR(Alpha_keep*$A16+P$3>=Floor_c-0.000000001,AND($B16=0,P$3>=Cap_h-0.000000001)),1,0),0) -> 0 | Q16: =IF(F16=1,IF(OR(Alpha_keep*$A16+Q$3>=Floor_c-0.000000001,AND($B16=0,Q$3>=Cap_h-0.000000001)),1,0),0) -> 0 | R16: =IF(G16=1,IF(OR(Alpha_keep*$A16+R$3>=Floor_c-0.000000001,AND($B16=0,R$3>=Cap_h-0.000000001)),1,0),0) -> 0 | S16: =IF(H16=1,IF(OR(Alpha_keep*$A16+S$3>=Floor_c-0.000000001,AND($B16=0,S$3>=Cap_h-0.000000001)),1,0),0) -> 0 | T16: =IF(I16=1,IF(OR(Alpha_keep*$A16+T$3>=Floor_c-0.000000001,AND($B16=0,T$3>=Cap_h-0.000000001)),1,0),0) -> 0 | U16: =IF(J16=1,IF(OR(Alpha_keep*$A16+U$3>=Floor_c-0.000000001,AND($B16=0,U$3>=Cap_h-0.000000001)),1,0),0) -> 0 | ... X16: =IF(M16=1,IF(OR(Alpha_keep*$A16+X$3>=Floor_c-0.000000001,AND($B16=0,X$3>=Cap_h-0.000000001)),1,0),0) -> 1 | Y16: =SUM(C16:M16) -> 11 | Z16: =SUM(N16:X16) -> 1 | AA16: =INDEX($C$3:$M$3,MATCH(1,C16:M16,0)) -> 0 | AB16: =INDEX($N$3:$X$3,MATCH(1,N16:X16,0))+(Z16-1)*Step_h -> 2.5
A17: =A16+Step_c -> 33 | B17: =IF(SUMPRODUCT((Alpha_keep*$A17+$C$3:$M$3>=Floor_c-0.000000001)*(C17:M17))>0,1,0) -> 0 | C17: =IF(AND(Alpha_keep*$A17+C$3-MAX(Loss_w)>=Lo_c-0.000000001,Alpha_keep*$A17+C$3-MIN(Loss_w)<=Hi_c+0.000000001),1,0) -> 1 | D17: =IF(AND(Alpha_keep*$A17+D$3-MAX(Loss_w)>=Lo_c-0.000000001,Alpha_keep*$A17+D$3-MIN(Loss_w)<=Hi_c+0.000000001),1,0) -> 1 | E17: =IF(AND(Alpha_keep*$A17+E$3-MAX(Loss_w)>=Lo_c-0.000000001,Alpha_keep*$A17+E$3-MIN(Loss_w)<=Hi_c+0.000000001),1,0) -> 1 | F17: =IF(AND(Alpha_keep*$A17+F$3-MAX(Loss_w)>=Lo_c-0.000000001,Alpha_keep*$A17+F$3-MIN(Loss_w)<=Hi_c+0.000000001),1,0) -> 1 | G17: =IF(AND(Alpha_keep*$A17+G$3-MAX(Loss_w)>=Lo_c-0.000000001,Alpha_keep*$A17+G$3-MIN(Loss_w)<=Hi_c+0.000000001),1,0) -> 1 | H17: =IF(AND(Alpha_keep*$A17+H$3-MAX(Loss_w)>=Lo_c-0.000000001,Alpha_keep*$A17+H$3-MIN(Loss_w)<=Hi_c+0.000000001),1,0) -> 1 | I17: =IF(AND(Alpha_keep*$A17+I$3-MAX(Loss_w)>=Lo_c-0.000000001,Alpha_keep*$A17+I$3-MIN(Loss_w)<=Hi_c+0.000000001),1,0) -> 1 | J17: =IF(AND(Alpha_keep*$A17+J$3-MAX(Loss_w)>=Lo_c-0.000000001,Alpha_keep*$A17+J$3-MIN(Loss_w)<=Hi_c+0.000000001),1,0) -> 1 | ... M17: =IF(AND(Alpha_keep*$A17+M$3-MAX(Loss_w)>=Lo_c-0.000000001,Alpha_keep*$A17+M$3-MIN(Loss_w)<=Hi_c+0.000000001),1,0) -> 1 | N17: =IF(C17=1,IF(OR(Alpha_keep*$A17+N$3>=Floor_c-0.000000001,AND($B17=0,N$3>=Cap_h-0.000000001)),1,0),0) -> 0 | O17: =IF(D17=1,IF(OR(Alpha_keep*$A17+O$3>=Floor_c-0.000000001,AND($B17=0,O$3>=Cap_h-0.000000001)),1,0),0) -> 0 | P17: =IF(E17=1,IF(OR(Alpha_keep*$A17+P$3>=Floor_c-0.000000001,AND($B17=0,P$3>=Cap_h-0.000000001)),1,0),0) -> 0 | Q17: =IF(F17=1,IF(OR(Alpha_keep*$A17+Q$3>=Floor_c-0.000000001,AND($B17=0,Q$3>=Cap_h-0.000000001)),1,0),0) -> 0 | R17: =IF(G17=1,IF(OR(Alpha_keep*$A17+R$3>=Floor_c-0.000000001,AND($B17=0,R$3>=Cap_h-0.000000001)),1,0),0) -> 0 | S17: =IF(H17=1,IF(OR(Alpha_keep*$A17+S$3>=Floor_c-0.000000001,AND($B17=0,S$3>=Cap_h-0.000000001)),1,0),0) -> 0 | T17: =IF(I17=1,IF(OR(Alpha_keep*$A17+T$3>=Floor_c-0.000000001,AND($B17=0,T$3>=Cap_h-0.000000001)),1,0),0) -> 0 | U17: =IF(J17=1,IF(OR(Alpha_keep*$A17+U$3>=Floor_c-0.000000001,AND($B17=0,U$3>=Cap_h-0.000000001)),1,0),0) -> 0 | ... X17: =IF(M17=1,IF(OR(Alpha_keep*$A17+X$3>=Floor_c-0.000000001,AND($B17=0,X$3>=Cap_h-0.000000001)),1,0),0) -> 1 | Y17: =SUM(C17:M17) -> 11 | Z17: =SUM(N17:X17) -> 1 | AA17: =INDEX($C$3:$M$3,MATCH(1,C17:M17,0)) -> 0 | AB17: =INDEX($N$3:$X$3,MATCH(1,N17:X17,0))+(Z17-1)*Step_h -> 2.5
A18: =A17+Step_c -> 33.25 | B18: =IF(SUMPRODUCT((Alpha_keep*$A18+$C$3:$M$3>=Floor_c-0.000000001)*(C18:M18))>0,1,0) -> 0 | C18: =IF(AND(Alpha_keep*$A18+C$3-MAX(Loss_w)>=Lo_c-0.000000001,Alpha_keep*$A18+C$3-MIN(Loss_w)<=Hi_c+0.000000001),1,0) -> 1 | D18: =IF(AND(Alpha_keep*$A18+D$3-MAX(Loss_w)>=Lo_c-0.000000001,Alpha_keep*$A18+D$3-MIN(Loss_w)<=Hi_c+0.000000001),1,0) -> 1 | E18: =IF(AND(Alpha_keep*$A18+E$3-MAX(Loss_w)>=Lo_c-0.000000001,Alpha_keep*$A18+E$3-MIN(Loss_w)<=Hi_c+0.000000001),1,0) -> 1 | F18: =IF(AND(Alpha_keep*$A18+F$3-MAX(Loss_w)>=Lo_c-0.000000001,Alpha_keep*$A18+F$3-MIN(Loss_w)<=Hi_c+0.000000001),1,0) -> 1 | G18: =IF(AND(Alpha_keep*$A18+G$3-MAX(Loss_w)>=Lo_c-0.000000001,Alpha_keep*$A18+G$3-MIN(Loss_w)<=Hi_c+0.000000001),1,0) -> 1 | H18: =IF(AND(Alpha_keep*$A18+H$3-MAX(Loss_w)>=Lo_c-0.000000001,Alpha_keep*$A18+H$3-MIN(Loss_w)<=Hi_c+0.000000001),1,0) -> 1 | I18: =IF(AND(Alpha_keep*$A18+I$3-MAX(Loss_w)>=Lo_c-0.000000001,Alpha_keep*$A18+I$3-MIN(Loss_w)<=Hi_c+0.000000001),1,0) -> 1 | J18: =IF(AND(Alpha_keep*$A18+J$3-MAX(Loss_w)>=Lo_c-0.000000001,Alpha_keep*$A18+J$3-MIN(Loss_w)<=Hi_c+0.000000001),1,0) -> 1 | ... M18: =IF(AND(Alpha_keep*$A18+M$3-MAX(Loss_w)>=Lo_c-0.000000001,Alpha_keep*$A18+M$3-MIN(Loss_w)<=Hi_c+0.000000001),1,0) -> 1 | N18: =IF(C18=1,IF(OR(Alpha_keep*$A18+N$3>=Floor_c-0.000000001,AND($B18=0,N$3>=Cap_h-0.000000001)),1,0),0) -> 0 | O18: =IF(D18=1,IF(OR(Alpha_keep*$A18+O$3>=Floor_c-0.000000001,AND($B18=0,O$3>=Cap_h-0.000000001)),1,0),0) -> 0 | P18: =IF(E18=1,IF(OR(Alpha_keep*$A18+P$3>=Floor_c-0.000000001,AND($B18=0,P$3>=Cap_h-0.000000001)),1,0),0) -> 0 | Q18: =IF(F18=1,IF(OR(Alpha_keep*$A18+Q$3>=Floor_c-0.000000001,AND($B18=0,Q$3>=Cap_h-0.000000001)),1,0),0) -> 0 | R18: =IF(G18=1,IF(OR(Alpha_keep*$A18+R$3>=Floor_c-0.000000001,AND($B18=0,R$3>=Cap_h-0.000000001)),1,0),0) -> 0 | S18: =IF(H18=1,IF(OR(Alpha_keep*$A18+S$3>=Floor_c-0.000000001,AND($B18=0,S$3>=Cap_h-0.000000001)),1,0),0) -> 0 | T18: =IF(I18=1,IF(OR(Alpha_keep*$A18+T$3>=Floor_c-0.000000001,AND($B18=0,T$3>=Cap_h-0.000000001)),1,0),0) -> 0 | U18: =IF(J18=1,IF(OR(Alpha_keep*$A18+U$3>=Floor_c-0.000000001,AND($B18=0,U$3>=Cap_h-0.000000001)),1,0),0) -> 0 | ... X18: =IF(M18=1,IF(OR(Alpha_keep*$A18+X$3>=Floor_c-0.000000001,AND($B18=0,X$3>=Cap_h-0.000000001)),1,0),0) -> 1 | Y18: =SUM(C18:M18) -> 11 | Z18: =SUM(N18:X18) -> 1 | AA18: =INDEX($C$3:$M$3,MATCH(1,C18:M18,0)) -> 0 | AB18: =INDEX($N$3:$X$3,MATCH(1,N18:X18,0))+(Z18-1)*Step_h -> 2.5
A19: =A18+Step_c -> 33.5 | B19: =IF(SUMPRODUCT((Alpha_keep*$A19+$C$3:$M$3>=Floor_c-0.000000001)*(C19:M19))>0,1,0) -> 0 | C19: =IF(AND(Alpha_keep*$A19+C$3-MAX(Loss_w)>=Lo_c-0.000000001,Alpha_keep*$A19+C$3-MIN(Loss_w)<=Hi_c+0.000000001),1,0) -> 1 | D19: =IF(AND(Alpha_keep*$A19+D$3-MAX(Loss_w)>=Lo_c-0.000000001,Alpha_keep*$A19+D$3-MIN(Loss_w)<=Hi_c+0.000000001),1,0) -> 1 | E19: =IF(AND(Alpha_keep*$A19+E$3-MAX(Loss_w)>=Lo_c-0.000000001,Alpha_keep*$A19+E$3-MIN(Loss_w)<=Hi_c+0.000000001),1,0) -> 1 | F19: =IF(AND(Alpha_keep*$A19+F$3-MAX(Loss_w)>=Lo_c-0.000000001,Alpha_keep*$A19+F$3-MIN(Loss_w)<=Hi_c+0.000000001),1,0) -> 1 | G19: =IF(AND(Alpha_keep*$A19+G$3-MAX(Loss_w)>=Lo_c-0.000000001,Alpha_keep*$A19+G$3-MIN(Loss_w)<=Hi_c+0.000000001),1,0) -> 1 | H19: =IF(AND(Alpha_keep*$A19+H$3-MAX(Loss_w)>=Lo_c-0.000000001,Alpha_keep*$A19+H$3-MIN(Loss_w)<=Hi_c+0.000000001),1,0) -> 1 | I19: =IF(AND(Alpha_keep*$A19+I$3-MAX(Loss_w)>=Lo_c-0.000000001,Alpha_keep*$A19+I$3-MIN(Loss_w)<=Hi_c+0.000000001),1,0) -> 1 | J19: =IF(AND(Alpha_keep*$A19+J$3-MAX(Loss_w)>=Lo_c-0.000000001,Alpha_keep*$A19+J$3-MIN(Loss_w)<=Hi_c+0.000000001),1,0) -> 1 | ... M19: =IF(AND(Alpha_keep*$A19+M$3-MAX(Loss_w)>=Lo_c-0.000000001,Alpha_keep*$A19+M$3-MIN(Loss_w)<=Hi_c+0.000000001),1,0) -> 1 | N19: =IF(C19=1,IF(OR(Alpha_keep*$A19+N$3>=Floor_c-0.000000001,AND($B19=0,N$3>=Cap_h-0.000000001)),1,0),0) -> 0 | O19: =IF(D19=1,IF(OR(Alpha_keep*$A19+O$3>=Floor_c-0.000000001,AND($B19=0,O$3>=Cap_h-0.000000001)),1,0),0) -> 0 | P19: =IF(E19=1,IF(OR(Alpha_keep*$A19+P$3>=Floor_c-0.000000001,AND($B19=0,P$3>=Cap_h-0.000000001)),1,0),0) -> 0 | Q19: =IF(F19=1,IF(OR(Alpha_keep*$A19+Q$3>=Floor_c-0.000000001,AND($B19=0,Q$3>=Cap_h-0.000000001)),1,0),0) -> 0 | R19: =IF(G19=1,IF(OR(Alpha_keep*$A19+R$3>=Floor_c-0.000000001,AND($B19=0,R$3>=Cap_h-0.000000001)),1,0),0) -> 0 | S19: =IF(H19=1,IF(OR(Alpha_keep*$A19+S$3>=Floor_c-0.000000001,AND($B19=0,S$3>=Cap_h-0.000000001)),1,0),0) -> 0 | T19: =IF(I19=1,IF(OR(Alpha_keep*$A19+T$3>=Floor_c-0.000000001,AND($B19=0,T$3>=Cap_h-0.000000001)),1,0),0) -> 0 | U19: =IF(J19=1,IF(OR(Alpha_keep*$A19+U$3>=Floor_c-0.000000001,AND($B19=0,U$3>=Cap_h-0.000000001)),1,0),0) -> 0 | ... X19: =IF(M19=1,IF(OR(Alpha_keep*$A19+X$3>=Floor_c-0.000000001,AND($B19=0,X$3>=Cap_h-0.000000001)),1,0),0) -> 1 | Y19: =SUM(C19:M19) -> 11 | Z19: =SUM(N19:X19) -> 1 | AA19: =INDEX($C$3:$M$3,MATCH(1,C19:M19,0)) -> 0 | AB19: =INDEX($N$3:$X$3,MATCH(1,N19:X19,0))+(Z19-1)*Step_h -> 2.5
A20: =A19+Step_c -> 33.75 | B20: =IF(SUMPRODUCT((Alpha_keep*$A20+$C$3:$M$3>=Floor_c-0.000000001)*(C20:M20))>0,1,0) -> 0 | C20: =IF(AND(Alpha_keep*$A20+C$3-MAX(Loss_w)>=Lo_c-0.000000001,Alpha_keep*$A20+C$3-MIN(Loss_w)<=Hi_c+0.000000001),1,0) -> 1 | D20: =IF(AND(Alpha_keep*$A20+D$3-MAX(Loss_w)>=Lo_c-0.000000001,Alpha_keep*$A20+D$3-MIN(Loss_w)<=Hi_c+0.000000001),1,0) -> 1 | E20: =IF(AND(Alpha_keep*$A20+E$3-MAX(Loss_w)>=Lo_c-0.000000001,Alpha_keep*$A20+E$3-MIN(Loss_w)<=Hi_c+0.000000001),1,0) -> 1 | F20: =IF(AND(Alpha_keep*$A20+F$3-MAX(Loss_w)>=Lo_c-0.000000001,Alpha_keep*$A20+F$3-MIN(Loss_w)<=Hi_c+0.000000001),1,0) -> 1 | G20: =IF(AND(Alpha_keep*$A20+G$3-MAX(Loss_w)>=Lo_c-0.000000001,Alpha_keep*$A20+G$3-MIN(Loss_w)<=Hi_c+0.000000001),1,0) -> 1 | H20: =IF(AND(Alpha_keep*$A20+H$3-MAX(Loss_w)>=Lo_c-0.000000001,Alpha_keep*$A20+H$3-MIN(Loss_w)<=Hi_c+0.000000001),1,0) -> 1 | I20: =IF(AND(Alpha_keep*$A20+I$3-MAX(Loss_w)>=Lo_c-0.000000001,Alpha_keep*$A20+I$3-MIN(Loss_w)<=Hi_c+0.000000001),1,0) -> 1 | J20: =IF(AND(Alpha_keep*$A20+J$3-MAX(Loss_w)>=Lo_c-0.000000001,Alpha_keep*$A20+J$3-MIN(Loss_w)<=Hi_c+0.000000001),1,0) -> 1 | ... M20: =IF(AND(Alpha_keep*$A20+M$3-MAX(Loss_w)>=Lo_c-0.000000001,Alpha_keep*$A20+M$3-MIN(Loss_w)<=Hi_c+0.000000001),1,0) -> 1 | N20: =IF(C20=1,IF(OR(Alpha_keep*$A20+N$3>=Floor_c-0.000000001,AND($B20=0,N$3>=Cap_h-0.000000001)),1,0),0) -> 0 | O20: =IF(D20=1,IF(OR(Alpha_keep*$A20+O$3>=Floor_c-0.000000001,AND($B20=0,O$3>=Cap_h-0.000000001)),1,0),0) -> 0 | P20: =IF(E20=1,IF(OR(Alpha_keep*$A20+P$3>=Floor_c-0.000000001,AND($B20=0,P$3>=Cap_h-0.000000001)),1,0),0) -> 0 | Q20: =IF(F20=1,IF(OR(Alpha_keep*$A20+Q$3>=Floor_c-0.000000001,AND($B20=0,Q$3>=Cap_h-0.000000001)),1,0),0) -> 0 | R20: =IF(G20=1,IF(OR(Alpha_keep*$A20+R$3>=Floor_c-0.000000001,AND($B20=0,R$3>=Cap_h-0.000000001)),1,0),0) -> 0 | S20: =IF(H20=1,IF(OR(Alpha_keep*$A20+S$3>=Floor_c-0.000000001,AND($B20=0,S$3>=Cap_h-0.000000001)),1,0),0) -> 0 | T20: =IF(I20=1,IF(OR(Alpha_keep*$A20+T$3>=Floor_c-0.000000001,AND($B20=0,T$3>=Cap_h-0.000000001)),1,0),0) -> 0 | U20: =IF(J20=1,IF(OR(Alpha_keep*$A20+U$3>=Floor_c-0.000000001,AND($B20=0,U$3>=Cap_h-0.000000001)),1,0),0) -> 0 | ... X20: =IF(M20=1,IF(OR(Alpha_keep*$A20+X$3>=Floor_c-0.000000001,AND($B20=0,X$3>=Cap_h-0.000000001)),1,0),0) -> 1 | Y20: =SUM(C20:M20) -> 11 | Z20: =SUM(N20:X20) -> 1 | AA20: =INDEX($C$3:$M$3,MATCH(1,C20:M20,0)) -> 0 | AB20: =INDEX($N$3:$X$3,MATCH(1,N20:X20,0))+(Z20-1)*Step_h -> 2.5
A21: =A20+Step_c -> 34 | B21: =IF(SUMPRODUCT((Alpha_keep*$A21+$C$3:$M$3>=Floor_c-0.000000001)*(C21:M21))>0,1,0) -> 0 | C21: =IF(AND(Alpha_keep*$A21+C$3-MAX(Loss_w)>=Lo_c-0.000000001,Alpha_keep*$A21+C$3-MIN(Loss_w)<=Hi_c+0.000000001),1,0) -> 1 | D21: =IF(AND(Alpha_keep*$A21+D$3-MAX(Loss_w)>=Lo_c-0.000000001,Alpha_keep*$A21+D$3-MIN(Loss_w)<=Hi_c+0.000000001),1,0) -> 1 | E21: =IF(AND(Alpha_keep*$A21+E$3-MAX(Loss_w)>=Lo_c-0.000000001,Alpha_keep*$A21+E$3-MIN(Loss_w)<=Hi_c+0.000000001),1,0) -> 1 | F21: =IF(AND(Alpha_keep*$A21+F$3-MAX(Loss_w)>=Lo_c-0.000000001,Alpha_keep*$A21+F$3-MIN(Loss_w)<=Hi_c+0.000000001),1,0) -> 1 | G21: =IF(AND(Alpha_keep*$A21+G$3-MAX(Loss_w)>=Lo_c-0.000000001,Alpha_keep*$A21+G$3-MIN(Loss_w)<=Hi_c+0.000000001),1,0) -> 1 | H21: =IF(AND(Alpha_keep*$A21+H$3-MAX(Loss_w)>=Lo_c-0.000000001,Alpha_keep*$A21+H$3-MIN(Loss_w)<=Hi_c+0.000000001),1,0) -> 1 | I21: =IF(AND(Alpha_keep*$A21+I$3-MAX(Loss_w)>=Lo_c-0.000000001,Alpha_keep*$A21+I$3-MIN(Loss_w)<=Hi_c+0.000000001),1,0) -> 1 | J21: =IF(AND(Alpha_keep*$A21+J$3-MAX(Loss_w)>=Lo_c-0.000000001,Alpha_keep*$A21+J$3-MIN(Loss_w)<=Hi_c+0.000000001),1,0) -> 1 | ... M21: =IF(AND(Alpha_keep*$A21+M$3-MAX(Loss_w)>=Lo_c-0.000000001,Alpha_keep*$A21+M$3-MIN(Loss_w)<=Hi_c+0.000000001),1,0) -> 1 | N21: =IF(C21=1,IF(OR(Alpha_keep*$A21+N$3>=Floor_c-0.000000001,AND($B21=0,N$3>=Cap_h-0.000000001)),1,0),0) -> 0 | O21: =IF(D21=1,IF(OR(Alpha_keep*$A21+O$3>=Floor_c-0.000000001,AND($B21=0,O$3>=Cap_h-0.000000001)),1,0),0) -> 0 | P21: =IF(E21=1,IF(OR(Alpha_keep*$A21+P$3>=Floor_c-0.000000001,AND($B21=0,P$3>=Cap_h-0.000000001)),1,0),0) -> 0 | Q21: =IF(F21=1,IF(OR(Alpha_keep*$A21+Q$3>=Floor_c-0.000000001,AND($B21=0,Q$3>=Cap_h-0.000000001)),1,0),0) -> 0 | R21: =IF(G21=1,IF(OR(Alpha_keep*$A21+R$3>=Floor_c-0.000000001,AND($B21=0,R$3>=Cap_h-0.000000001)),1,0),0) -> 0 | S21: =IF(H21=1,IF(OR(Alpha_keep*$A21+S$3>=Floor_c-0.000000001,AND($B21=0,S$3>=Cap_h-0.000000001)),1,0),0) -> 0 | T21: =IF(I21=1,IF(OR(Alpha_keep*$A21+T$3>=Floor_c-0.000000001,AND($B21=0,T$3>=Cap_h-0.000000001)),1,0),0) -> 0 | U21: =IF(J21=1,IF(OR(Alpha_keep*$A21+U$3>=Floor_c-0.000000001,AND($B21=0,U$3>=Cap_h-0.000000001)),1,0),0) -> 0 | ... X21: =IF(M21=1,IF(OR(Alpha_keep*$A21+X$3>=Floor_c-0.000000001,AND($B21=0,X$3>=Cap_h-0.000000001)),1,0),0) -> 1 | Y21: =SUM(C21:M21) -> 11 | Z21: =SUM(N21:X21) -> 1 | AA21: =INDEX($C$3:$M$3,MATCH(1,C21:M21,0)) -> 0 | AB21: =INDEX($N$3:$X$3,MATCH(1,N21:X21,0))+(Z21-1)*Step_h -> 2.5
... A205: =A204+Step_c -> 80 | B205: =IF(SUMPRODUCT((Alpha_keep*$A205+$C$3:$M$3>=Floor_c-0.000000001)*(C205:M205))>0,1,0) -> 1 | C205: =IF(AND(Alpha_keep*$A205+C$3-MAX(Loss_w)>=Lo_c-0.000000001,Alpha_keep*$A205+C$3-MIN(Loss_w)<=Hi_c+0.000000001),1,0) -> 1 | D205: =IF(AND(Alpha_keep*$A205+D$3-MAX(Loss_w)>=Lo_c-0.000000001,Alpha_keep*$A205+D$3-MIN(Loss_w)<=Hi_c+0.000000001),1,0) -> 1 | E205: =IF(AND(Alpha_keep*$A205+E$3-MAX(Loss_w)>=Lo_c-0.000000001,Alpha_keep*$A205+E$3-MIN(Loss_w)<=Hi_c+0.000000001),1,0) -> 1 | F205: =IF(AND(Alpha_keep*$A205+F$3-MAX(Loss_w)>=Lo_c-0.000000001,Alpha_keep*$A205+F$3-MIN(Loss_w)<=Hi_c+0.000000001),1,0) -> 0 | G205: =IF(AND(Alpha_keep*$A205+G$3-MAX(Loss_w)>=Lo_c-0.000000001,Alpha_keep*$A205+G$3-MIN(Loss_w)<=Hi_c+0.000000001),1,0) -> 0 | H205: =IF(AND(Alpha_keep*$A205+H$3-MAX(Loss_w)>=Lo_c-0.000000001,Alpha_keep*$A205+H$3-MIN(Loss_w)<=Hi_c+0.000000001),1,0) -> 0 | I205: =IF(AND(Alpha_keep*$A205+I$3-MAX(Loss_w)>=Lo_c-0.000000001,Alpha_keep*$A205+I$3-MIN(Loss_w)<=Hi_c+0.000000001),1,0) -> 0 | J205: =IF(AND(Alpha_keep*$A205+J$3-MAX(Loss_w)>=Lo_c-0.000000001,Alpha_keep*$A205+J$3-MIN(Loss_w)<=Hi_c+0.000000001),1,0) -> 0 | ... M205: =IF(AND(Alpha_keep*$A205+M$3-MAX(Loss_w)>=Lo_c-0.000000001,Alpha_keep*$A205+M$3-MIN(Loss_w)<=Hi_c+0.000000001),1,0) -> 0 | N205: =IF(C205=1,IF(OR(Alpha_keep*$A205+N$3>=Floor_c-0.000000001,AND($B205=0,N$3>=Cap_h-0.000000001)),1,0),0) -> 1 | O205: =IF(D205=1,IF(OR(Alpha_keep*$A205+O$3>=Floor_c-0.000000001,AND($B205=0,O$3>=Cap_h-0.000000001)),1,0),0) -> 1 | P205: =IF(E205=1,IF(OR(Alpha_keep*$A205+P$3>=Floor_c-0.000000001,AND($B205=0,P$3>=Cap_h-0.000000001)),1,0),0) -> 1 | Q205: =IF(F205=1,IF(OR(Alpha_keep*$A205+Q$3>=Floor_c-0.000000001,AND($B205=0,Q$3>=Cap_h-0.000000001)),1,0),0) -> 0 | R205: =IF(G205=1,IF(OR(Alpha_keep*$A205+R$3>=Floor_c-0.000000001,AND($B205=0,R$3>=Cap_h-0.000000001)),1,0),0) -> 0 | S205: =IF(H205=1,IF(OR(Alpha_keep*$A205+S$3>=Floor_c-0.000000001,AND($B205=0,S$3>=Cap_h-0.000000001)),1,0),0) -> 0 | T205: =IF(I205=1,IF(OR(Alpha_keep*$A205+T$3>=Floor_c-0.000000001,AND($B205=0,T$3>=Cap_h-0.000000001)),1,0),0) -> 0 | U205: =IF(J205=1,IF(OR(Alpha_keep*$A205+U$3>=Floor_c-0.000000001,AND($B205=0,U$3>=Cap_h-0.000000001)),1,0),0) -> 0 | ... X205: =IF(M205=1,IF(OR(Alpha_keep*$A205+X$3>=Floor_c-0.000000001,AND($B205=0,X$3>=Cap_h-0.000000001)),1,0),0) -> 0 | Y205: =SUM(C205:M205) -> 3 | Z205: =SUM(N205:X205) -> 3 | AA205: =INDEX($C$3:$M$3,MATCH(1,C205:M205,0)) -> 0 | AB205: =INDEX($N$3:$X$3,MATCH(1,N205:X205,0))+(Z205-1)*Step_h -> 0.5

Sheet BestRule
A1: One Bellman step on the best rule's values: decision values, best decisions, the residual and the guardrail (Definition 14.1; Equation 14.1; Proposition 14.2(ii); Worked Example 14.1, Step 1; AXIOM Lab 2.14, step 1)
A2: Column B is the engine's values of the best rule (policy iteration, exact). G = the sum of p_w V(node - w/step) at each node; Q(c, h) = -k h - p (55 - c)^+ + beta [(1 - t) G(j) + t G(j + 1)] where 0.975c + h = 30 + (j + t) x step: the value of deciding h at c and acting best afterwards. A residual near zero certifies the values, and the best decisions are the rule.
D3: hire h: | E3: =Grid!C3 -> 0 | F3: =Grid!D3 -> 0.25 | G3: =Grid!E3 -> 0.5 | H3: =Grid!F3 -> 0.75 | I3: =Grid!G3 -> 1 | J3: =Grid!H3 -> 1.25 | K3: =Grid!I3 -> 1.5 | L3: =Grid!J3 -> 1.75 | ... O3: =Grid!M3 -> 2.5 | Z3: The best rule on the agent's grid | AA3: Value | AB3: Book
A4: c | B4: V*(c) (engine) | C4: Node | D4: G at the node | E4: Q(c, 0) | F4: Q(c, 0.25) | G4: Q(c, 0.5) | H4: Q(c, 0.75) | I4: Q(c, 1) | J4: Q(c, 1.25) | K4: Q(c, 1.5) | L4: Q(c, 1.75) | M4: Q(c, 2) | N4: Q(c, 2.25) | O4: Q(c, 2.5) | P4: Best value, max Q | Q4: Best hire (formula) | R4: Engine's hire | S4: Same (1 = yes) | T4: |max Q - V*| | U4: Planned 0.975c + h | V4: In the guardrail (1 = yes) | W4: Long-run share (engine) | Z4: Cost from 58: minus the best value at 58 | AA4: =-INDEX(P5:P205,MATCH(Start_c,$A$5:$A$205,0)) -> 231.1784 | AB4: 231.18
A5: =Grid!A5 -> 30 | B5: -611.53872 | C5: 0 | D5: =IF(AND($C5>=6,$C5<=194),Declarations!$B$25*INDEX($B$5:$B$205,$C5+1-Declarations!$E$25)+Declarations!$B$26*INDEX($B$5:$B$205,$C5+1-Declarations!$E$26)+Declarations!$B$27*INDEX($B$5:$B$205,$C5+1-Declarations!$E$27)+Declarations!$B$28*INDEX($B$5:$B$205,$C5+1-Declarations!$E$28)+Declarations!$B$29*INDEX($B$5:$B$205,$C5+1-Declarations!$E$29),"") | E5: =IF(Grid!C5=1,-Cost_k*E$3-Short_p*MAX(0,Floor_c-$A5)+Beta_q*((1-(((Alpha_keep*$A5+E$3-Lo_c)/Step_c)-MAX(6,MIN(INT(((Alpha_keep*$A5+E$3-Lo_c)/Step_c)+0.00000001),193))))*INDEX($D$5:$D$205,MAX(6,MIN(INT(((Alpha_keep*$A5+E$3-Lo_c)/Step_c)+0.00000001),193))+1)+(((Alpha_keep*$A5+E$3-Lo_c)/Step_c)-MAX(6,MIN(INT(((Alpha_keep*$A5+E$3-Lo_c)/Step_c)+0.00000001),193)))*INDEX($D$5:$D$205,MAX(6,MIN(INT(((Alpha_keep*$A5+E$3-Lo_c)/Step_c)+0.00000001),193))+2)),"") | F5: =IF(Grid!D5=1,-Cost_k*F$3-Short_p*MAX(0,Floor_c-$A5)+Beta_q*((1-(((Alpha_keep*$A5+F$3-Lo_c)/Step_c)-MAX(6,MIN(INT(((Alpha_keep*$A5+F$3-Lo_c)/Step_c)+0.00000001),193))))*INDEX($D$5:$D$205,MAX(6,MIN(INT(((Alpha_keep*$A5+F$3-Lo_c)/Step_c)+0.00000001),193))+1)+(((Alpha_keep*$A5+F$3-Lo_c)/Step_c)-MAX(6,MIN(INT(((Alpha_keep*$A5+F$3-Lo_c)/Step_c)+0.00000001),193)))*INDEX($D$5:$D$205,MAX(6,MIN(INT(((Alpha_keep*$A5+F$3-Lo_c)/Step_c)+0.00000001),193))+2)),"") | G5: =IF(Grid!E5=1,-Cost_k*G$3-Short_p*MAX(0,Floor_c-$A5)+Beta_q*((1-(((Alpha_keep*$A5+G$3-Lo_c)/Step_c)-MAX(6,MIN(INT(((Alpha_keep*$A5+G$3-Lo_c)/Step_c)+0.00000001),193))))*INDEX($D$5:$D$205,MAX(6,MIN(INT(((Alpha_keep*$A5+G$3-Lo_c)/Step_c)+0.00000001),193))+1)+(((Alpha_keep*$A5+G$3-Lo_c)/Step_c)-MAX(6,MIN(INT(((Alpha_keep*$A5+G$3-Lo_c)/Step_c)+0.00000001),193)))*INDEX($D$5:$D$205,MAX(6,MIN(INT(((Alpha_keep*$A5+G$3-Lo_c)/Step_c)+0.00000001),193))+2)),"") | H5: =IF(Grid!F5=1,-Cost_k*H$3-Short_p*MAX(0,Floor_c-$A5)+Beta_q*((1-(((Alpha_keep*$A5+H$3-Lo_c)/Step_c)-MAX(6,MIN(INT(((Alpha_keep*$A5+H$3-Lo_c)/Step_c)+0.00000001),193))))*INDEX($D$5:$D$205,MAX(6,MIN(INT(((Alpha_keep*$A5+H$3-Lo_c)/Step_c)+0.00000001),193))+1)+(((Alpha_keep*$A5+H$3-Lo_c)/Step_c)-MAX(6,MIN(INT(((Alpha_keep*$A5+H$3-Lo_c)/Step_c)+0.00000001),193)))*INDEX($D$5:$D$205,MAX(6,MIN(INT(((Alpha_keep*$A5+H$3-Lo_c)/Step_c)+0.00000001),193))+2)),"") | I5: =IF(Grid!G5=1,-Cost_k*I$3-Short_p*MAX(0,Floor_c-$A5)+Beta_q*((1-(((Alpha_keep*$A5+I$3-Lo_c)/Step_c)-MAX(6,MIN(INT(((Alpha_keep*$A5+I$3-Lo_c)/Step_c)+0.00000001),193))))*INDEX($D$5:$D$205,MAX(6,MIN(INT(((Alpha_keep*$A5+I$3-Lo_c)/Step_c)+0.00000001),193))+1)+(((Alpha_keep*$A5+I$3-Lo_c)/Step_c)-MAX(6,MIN(INT(((Alpha_keep*$A5+I$3-Lo_c)/Step_c)+0.00000001),193)))*INDEX($D$5:$D$205,MAX(6,MIN(INT(((Alpha_keep*$A5+I$3-Lo_c)/Step_c)+0.00000001),193))+2)),"") | J5: =IF(Grid!H5=1,-Cost_k*J$3-Short_p*MAX(0,Floor_c-$A5)+Beta_q*((1-(((Alpha_keep*$A5+J$3-Lo_c)/Step_c)-MAX(6,MIN(INT(((Alpha_keep*$A5+J$3-Lo_c)/Step_c)+0.00000001),193))))*INDEX($D$5:$D$205,MAX(6,MIN(INT(((Alpha_keep*$A5+J$3-Lo_c)/Step_c)+0.00000001),193))+1)+(((Alpha_keep*$A5+J$3-Lo_c)/Step_c)-MAX(6,MIN(INT(((Alpha_keep*$A5+J$3-Lo_c)/Step_c)+0.00000001),193)))*INDEX($D$5:$D$205,MAX(6,MIN(INT(((Alpha_keep*$A5+J$3-Lo_c)/Step_c)+0.00000001),193))+2)),"") | K5: =IF(Grid!I5=1,-Cost_k*K$3-Short_p*MAX(0,Floor_c-$A5)+Beta_q*((1-(((Alpha_keep*$A5+K$3-Lo_c)/Step_c)-MAX(6,MIN(INT(((Alpha_keep*$A5+K$3-Lo_c)/Step_c)+0.00000001),193))))*INDEX($D$5:$D$205,MAX(6,MIN(INT(((Alpha_keep*$A5+K$3-Lo_c)/Step_c)+0.00000001),193))+1)+(((Alpha_keep*$A5+K$3-Lo_c)/Step_c)-MAX(6,MIN(INT(((Alpha_keep*$A5+K$3-Lo_c)/Step_c)+0.00000001),193)))*INDEX($D$5:$D$205,MAX(6,MIN(INT(((Alpha_keep*$A5+K$3-Lo_c)/Step_c)+0.00000001),193))+2)),"") | L5: =IF(Grid!J5=1,-Cost_k*L$3-Short_p*MAX(0,Floor_c-$A5)+Beta_q*((1-(((Alpha_keep*$A5+L$3-Lo_c)/Step_c)-MAX(6,MIN(INT(((Alpha_keep*$A5+L$3-Lo_c)/Step_c)+0.00000001),193))))*INDEX($D$5:$D$205,MAX(6,MIN(INT(((Alpha_keep*$A5+L$3-Lo_c)/Step_c)+0.00000001),193))+1)+(((Alpha_keep*$A5+L$3-Lo_c)/Step_c)-MAX(6,MIN(INT(((Alpha_keep*$A5+L$3-Lo_c)/Step_c)+0.00000001),193)))*INDEX($D$5:$D$205,MAX(6,MIN(INT(((Alpha_keep*$A5+L$3-Lo_c)/Step_c)+0.00000001),193))+2)),"") | ... O5: =IF(Grid!M5=1,-Cost_k*O$3-Short_p*MAX(0,Floor_c-$A5)+Beta_q*((1-(((Alpha_keep*$A5+O$3-Lo_c)/Step_c)-MAX(6,MIN(INT(((Alpha_keep*$A5+O$3-Lo_c)/Step_c)+0.00000001),193))))*INDEX($D$5:$D$205,MAX(6,MIN(INT(((Alpha_keep*$A5+O$3-Lo_c)/Step_c)+0.00000001),193))+1)+(((Alpha_keep*$A5+O$3-Lo_c)/Step_c)-MAX(6,MIN(INT(((Alpha_keep*$A5+O$3-Lo_c)/Step_c)+0.00000001),193)))*INDEX($D$5:$D$205,MAX(6,MIN(INT(((Alpha_keep*$A5+O$3-Lo_c)/Step_c)+0.00000001),193))+2)),"") -> -611.53872 | P5: =MAX(E5:O5) -> -611.53872 | Q5: =INDEX($E$3:$O$3,MATCH(P5,E5:O5,0)) -> 2.5 | R5: 2.5 | S5: =IF(ABS(Q5-R5)<0.000000001,1,0) -> 1 | T5: =ABS(P5-B5) -> 0 | U5: =Alpha_keep*A5+Q5 -> 31.75 | V5: =INDEX(GuardBlock,1,ROUND(Q5/Step_h,0)+1) -> 1 | W5: 0 | Z5: Above Chapter 7's 230.755 (hires in quarter-points) | AA5: =AA4-Ch7_cost -> 0.4233985 | AB5: 0.42
