Workbook

Sheet README
B1: DCT Laboratory — Vol II, Ch 6: Optimal Control of Enterprise Systems
B2: Seed 26206 · Companion to DCT_V2_Ch06_Lab.ipynb and AXIOM Lab 2.6 (module AXIOM-06). Money in $ million.
B4: Worked Example 6.1, What Is Meridian's Engineering Team Worth?, with the book's declarations.
B5: Declarations: the inputs of Step 1. Simulate: the race, the drift and Volume I's schedules over three years (Figure 6.3(a)). Plans: Table 6.3.
B6: Hamiltonian: the part hiring moves at three prices (Figure 6.1(b)) and the switching function along each plan.
B7: Floor: the rent and the floor's price, the user cost. Prices: the value of a position and the price of a point, with finite differences (Figure 6.1(a)).
B8: Shooting: the starting prices by bisection. Transcription: the linear program's best plan on weekly and daily calendars, in closed form, beside the HiGHS solutions the notebook computes.
B9: Certify: c_a, the dynamic-programming condition, and the team's value. Compare: the declarations tested (Step 6).
B10: CapitalProblems: the chapter's two small capital problems, with a rising and a linear cost (Figure 6.2).
B11: The state simulator, the HiGHS solves and the random-plan test of the certificate run in the notebook.
B12: Reference_Values and Checks: the engine's numbers and a PASS/FAIL comparison with this workbook's formulas.
B14: LEGEND
... B18: Cross-sheet link: green.

Sheet Declarations
A1: Declarations (Worked Example 6.1, Step 1). Money in $ million; capability in points; time in years.
A3: Quantity | B3: Value | C3: Source
A4: Attrition a quarter | B4: 0.025 | C4: 2.5 percent a quarter (Volume I, Chapter 10)
A5: Attrition a year in continuous time, delta | B5: =-4*LN(1-B4) -> 0.10127123 | C5: delta = 4 ln(1/0.975) = 0.101
A6: Hiring cap a quarter (points) | B6: 2.5 | C6: At most 2.5 points a quarter (Volume I, Chapter 10)
A7: Volume I's ceiling (points) | B7: =B6/B4 -> 100 | C7: 2.5 / 0.025 = 100
A8: Hiring cap a year, u bar = ceiling x delta | B8: =B7*B5 -> 10.127123 | C8: 10.13 points a year: keeps Volume I's ceiling and its time to build exactly
A9: Cost of hiring and training a point, k | B9: 4 | C9: $4 million a point (Volume I, Worked Example 10.1)
A10: Capability floor of the digital build | B10: 55 | C10: The build runs from the first moment capability reaches 55; from then on capability stays at or above 55
A11: A quarter of delay | B11: 8 | C11: $8 million (Volume I, Chapter 15)
A12: Delay a year while the build waits, D | B12: =4*B11 -> 32 | C12: $32 million a year
A13: Hurdle rate a year | B13: 0.1 | C13: The board's 10 percent (Chapter 5)
A14: rho = ln(1 + hurdle rate) | B14: =LN(1+B13) -> 0.09531018 | C14: 9.5 percent in continuous time
A15: Capability with the engineering team | B15: 58 | C15: Team kept
A16: Capability without it | B16: 53 | C16: Team gone: below the floor
A17: Proceeds with the team kept | B17: 92 | C17: $92 million net
A18: Proceeds with the team gone | B18: 112 | C18: $112 million net
A19: rho + delta | B19: =B14+B5 -> 0.19658141 | C19: Off the floor the price of a point grows at 19.7 percent a year
A21: State: capability c, with dc/dt = u - delta c. Decision: hiring and training u in [0, u bar]. Value of a position: minus the present value of hiring and delay over an open horizon.

Sheet Simulate
A1: Simulate: Volume I's schedules and the race-and-rent plan (AXIOM Lab 2.6, step 1; Figure 6.3(a))
A3: Quantity | B3: Years | C3: Quarters | D3: Reading
A4: Race from 53 to the floor at the cap | B4: =LN((Cap_top-C_gone)/(Cap_top-Floor_F))/Delta_a -> 0.42939254 | C4: =4*B4 -> 1.7175702 | D4: Volume I's time to build: the build starts
A5: Drift from 58 to the floor, hiring nothing | B5: =LN(C_kept/Floor_F)/Delta_a -> 0.52443151 | C5: =4*B5 -> 2.097726 | D5: Then pay the rent
A6: Rebuild from 53 to 58 at the cap | B6: =LN((Cap_top-C_gone)/(Cap_top-C_kept))/Delta_a -> 1.1106608 | C6: =4*B6 -> 4.442643 | D6: Volume I's schedule
A7: Build starts, team kept | B7: 0 | C7: =4*B7 -> 0 | D7: Capability is above the floor at once
A8: Build starts, team gone (race or rebuild) | B8: =B4 -> 0.42939254 | C8: =4*B8 -> 1.7175702 | D8: Both pass 55 at the cap
A10: Years after the sale | B10: Team kept: drift, then the rent | C10: Team gone: race, then the rent | D10: Volume I: hold 58 | E10: Volume I: rebuild to 58 | F10: Hiring, team kept | G10: Hiring, team gone | H10: Hiring, hold 58 | I10: Hiring, rebuild
A11: 0 | B11: =IF(A11<Tau_drift,C_kept*EXP(-Delta_a*A11),Floor_F) -> 58 | C11: =IF(A11<Tau_race,Cap_top-(Cap_top-C_gone)*EXP(-Delta_a*A11),Floor_F) -> 53 | D11: =C_kept -> 58 | E11: =IF(A11<Time_58,Cap_top-(Cap_top-C_gone)*EXP(-Delta_a*A11),C_kept) -> 53 | F11: =IF(A11<Tau_drift,0,Delta_a*Floor_F) -> 0 | G11: =IF(A11<Tau_race,Ubar_a,Delta_a*Floor_F) -> 10.127123 | H11: =Delta_a*C_kept -> 5.8737315 | I11: =IF(A11<Time_58,Ubar_a,Delta_a*C_kept) -> 10.127123
A12: 0.05 | B12: =IF(A12<Tau_drift,C_kept*EXP(-Delta_a*A12),Floor_F) -> 57.707056 | C12: =IF(A12<Tau_race,Cap_top-(Cap_top-C_gone)*EXP(-Delta_a*A12),Floor_F) -> 53.237386 | D12: =C_kept -> 58 | E12: =IF(A12<Time_58,Cap_top-(Cap_top-C_gone)*EXP(-Delta_a*A12),C_kept) -> 53.237386 | F12: =IF(A12<Tau_drift,0,Delta_a*Floor_F) -> 0 | G12: =IF(A12<Tau_race,Ubar_a,Delta_a*Floor_F) -> 10.127123 | H12: =Delta_a*C_kept -> 5.8737315 | I12: =IF(A12<Time_58,Ubar_a,Delta_a*C_kept) -> 10.127123
A13: 0.1 | B13: =IF(A13<Tau_drift,C_kept*EXP(-Delta_a*A13),Floor_F) -> 57.415591 | C13: =IF(A13<Tau_race,Cap_top-(Cap_top-C_gone)*EXP(-Delta_a*A13),Floor_F) -> 53.473573 | D13: =C_kept -> 58 | E13: =IF(A13<Time_58,Cap_top-(Cap_top-C_gone)*EXP(-Delta_a*A13),C_kept) -> 53.473573 | F13: =IF(A13<Tau_drift,0,Delta_a*Floor_F) -> 0 | G13: =IF(A13<Tau_race,Ubar_a,Delta_a*Floor_F) -> 10.127123 | H13: =Delta_a*C_kept -> 5.8737315 | I13: =IF(A13<Time_58,Ubar_a,Delta_a*C_kept) -> 10.127123
A14: 0.15 | B14: =IF(A14<Tau_drift,C_kept*EXP(-Delta_a*A14),Floor_F) -> 57.125598 | C14: =IF(A14<Tau_race,Cap_top-(Cap_top-C_gone)*EXP(-Delta_a*A14),Floor_F) -> 53.708567 | D14: =C_kept -> 58 | E14: =IF(A14<Time_58,Cap_top-(Cap_top-C_gone)*EXP(-Delta_a*A14),C_kept) -> 53.708567 | F14: =IF(A14<Tau_drift,0,Delta_a*Floor_F) -> 0 | G14: =IF(A14<Tau_race,Ubar_a,Delta_a*Floor_F) -> 10.127123 | H14: =Delta_a*C_kept -> 5.8737315 | I14: =IF(A14<Time_58,Ubar_a,Delta_a*C_kept) -> 10.127123
A15: 0.2 | B15: =IF(A15<Tau_drift,C_kept*EXP(-Delta_a*A15),Floor_F) -> 56.837071 | C15: =IF(A15<Tau_race,Cap_top-(Cap_top-C_gone)*EXP(-Delta_a*A15),Floor_F) -> 53.942374 | D15: =C_kept -> 58 | E15: =IF(A15<Time_58,Cap_top-(Cap_top-C_gone)*EXP(-Delta_a*A15),C_kept) -> 53.942374 | F15: =IF(A15<Tau_drift,0,Delta_a*Floor_F) -> 0 | G15: =IF(A15<Tau_race,Ubar_a,Delta_a*Floor_F) -> 10.127123 | H15: =Delta_a*C_kept -> 5.8737315 | I15: =IF(A15<Time_58,Ubar_a,Delta_a*C_kept) -> 10.127123
A16: 0.25 | B16: =IF(A16<Tau_drift,C_kept*EXP(-Delta_a*A16),Floor_F) -> 56.55 | C16: =IF(A16<Tau_race,Cap_top-(Cap_top-C_gone)*EXP(-Delta_a*A16),Floor_F) -> 54.175 | D16: =C_kept -> 58 | E16: =IF(A16<Time_58,Cap_top-(Cap_top-C_gone)*EXP(-Delta_a*A16),C_kept) -> 54.175 | F16: =IF(A16<Tau_drift,0,Delta_a*Floor_F) -> 0 | G16: =IF(A16<Tau_race,Ubar_a,Delta_a*Floor_F) -> 10.127123 | H16: =Delta_a*C_kept -> 5.8737315 | I16: =IF(A16<Time_58,Ubar_a,Delta_a*C_kept) -> 10.127123
A17: 0.3 | B17: =IF(A17<Tau_drift,C_kept*EXP(-Delta_a*A17),Floor_F) -> 56.264379 | C17: =IF(A17<Tau_race,Cap_top-(Cap_top-C_gone)*EXP(-Delta_a*A17),Floor_F) -> 54.406451 | D17: =C_kept -> 58 | E17: =IF(A17<Time_58,Cap_top-(Cap_top-C_gone)*EXP(-Delta_a*A17),C_kept) -> 54.406451 | F17: =IF(A17<Tau_drift,0,Delta_a*Floor_F) -> 0 | G17: =IF(A17<Tau_race,Ubar_a,Delta_a*Floor_F) -> 10.127123 | H17: =Delta_a*C_kept -> 5.8737315 | I17: =IF(A17<Time_58,Ubar_a,Delta_a*C_kept) -> 10.127123
A18: 0.35 | B18: =IF(A18<Tau_drift,C_kept*EXP(-Delta_a*A18),Floor_F) -> 55.980201 | C18: =IF(A18<Tau_race,Cap_top-(Cap_top-C_gone)*EXP(-Delta_a*A18),Floor_F) -> 54.636733 | D18: =C_kept -> 58 | E18: =IF(A18<Time_58,Cap_top-(Cap_top-C_gone)*EXP(-Delta_a*A18),C_kept) -> 54.636733 | F18: =IF(A18<Tau_drift,0,Delta_a*Floor_F) -> 0 | G18: =IF(A18<Tau_race,Ubar_a,Delta_a*Floor_F) -> 10.127123 | H18: =Delta_a*C_kept -> 5.8737315 | I18: =IF(A18<Time_58,Ubar_a,Delta_a*C_kept) -> 10.127123
A19: 0.4 | B19: =IF(A19<Tau_drift,C_kept*EXP(-Delta_a*A19),Floor_F) -> 55.697459 | C19: =IF(A19<Tau_race,Cap_top-(Cap_top-C_gone)*EXP(-Delta_a*A19),Floor_F) -> 54.865853 | D19: =C_kept -> 58 | E19: =IF(A19<Time_58,Cap_top-(Cap_top-C_gone)*EXP(-Delta_a*A19),C_kept) -> 54.865853 | F19: =IF(A19<Tau_drift,0,Delta_a*Floor_F) -> 0 | G19: =IF(A19<Tau_race,Ubar_a,Delta_a*Floor_F) -> 10.127123 | H19: =Delta_a*C_kept -> 5.8737315 | I19: =IF(A19<Time_58,Ubar_a,Delta_a*C_kept) -> 10.127123
A20: 0.45 | B20: =IF(A20<Tau_drift,C_kept*EXP(-Delta_a*A20),Floor_F) -> 55.416144 | C20: =IF(A20<Tau_race,Cap_top-(Cap_top-C_gone)*EXP(-Delta_a*A20),Floor_F) -> 55 | D20: =C_kept -> 58 | E20: =IF(A20<Time_58,Cap_top-(Cap_top-C_gone)*EXP(-Delta_a*A20),C_kept) -> 55.093814 | F20: =IF(A20<Tau_drift,0,Delta_a*Floor_F) -> 0 | G20: =IF(A20<Tau_race,Ubar_a,Delta_a*Floor_F) -> 5.5699178 | H20: =Delta_a*C_kept -> 5.8737315 | I20: =IF(A20<Time_58,Ubar_a,Delta_a*C_kept) -> 10.127123
A21: 0.5 | B21: =IF(A21<Tau_drift,C_kept*EXP(-Delta_a*A21),Floor_F) -> 55.13625 | C21: =IF(A21<Tau_race,Cap_top-(Cap_top-C_gone)*EXP(-Delta_a*A21),Floor_F) -> 55 | D21: =C_kept -> 58 | E21: =IF(A21<Time_58,Cap_top-(Cap_top-C_gone)*EXP(-Delta_a*A21),C_kept) -> 55.320625 | F21: =IF(A21<Tau_drift,0,Delta_a*Floor_F) -> 0 | G21: =IF(A21<Tau_race,Ubar_a,Delta_a*Floor_F) -> 5.5699178 | H21: =Delta_a*C_kept -> 5.8737315 | I21: =IF(A21<Time_58,Ubar_a,Delta_a*C_kept) -> 10.127123
A22: 0.55 | B22: =IF(A22<Tau_drift,C_kept*EXP(-Delta_a*A22),Floor_F) -> 55 | C22: =IF(A22<Tau_race,Cap_top-(Cap_top-C_gone)*EXP(-Delta_a*A22),Floor_F) -> 55 | D22: =C_kept -> 58 | E22: =IF(A22<Time_58,Cap_top-(Cap_top-C_gone)*EXP(-Delta_a*A22),C_kept) -> 55.54629 | F22: =IF(A22<Tau_drift,0,Delta_a*Floor_F) -> 5.5699178 | G22: =IF(A22<Tau_race,Ubar_a,Delta_a*Floor_F) -> 5.5699178 | H22: =Delta_a*C_kept -> 5.8737315 | I22: =IF(A22<Time_58,Ubar_a,Delta_a*C_kept) -> 10.127123
... A71: 3 | B71: =IF(A71<Tau_drift,C_kept*EXP(-Delta_a*A71),Floor_F) -> 55 | C71: =IF(A71<Tau_race,Cap_top-(Cap_top-C_gone)*EXP(-Delta_a*A71),Floor_F) -> 55 | D71: =C_kept -> 58 | E71: =IF(A71<Time_58,Cap_top-(Cap_top-C_gone)*EXP(-Delta_a*A71),C_kept) -> 58 | F71: =IF(A71<Tau_drift,0,Delta_a*Floor_F) -> 5.5699178 | G71: =IF(A71<Tau_race,Ubar_a,Delta_a*Floor_F) -> 5.5699178 | H71: =Delta_a*C_kept -> 5.8737315 | I71: =IF(A71<Time_58,Ubar_a,Delta_a*C_kept) -> 5.8737315
A73: Capability at the cap: 100 - (100 - c0) e^(-delta t); with no hiring: c0 e^(-delta t); the rent delta x 55 holds the floor. Hiring in points a year.

Sheet Plans
A1: Table 6.3: the plans compared ($ million, present values at 10 percent over an open horizon)
A3: Plan | B3: Build starts (quarters) | C3: Hiring | D3: Delay | E3: Total cost | F3: Proceeds | G3: Proceeds less costs
A4: Team kept: drift to 55, pay the rent | B4: =4*Simulate!B7 -> 0 | C4: =EXP(-Rho_a*Tau_drift)*Cost_k*Delta_a*Floor_F/Rho_a -> 222.36266 | D4: 0 | E4: =C4+D4 -> 222.36266 | F4: =Proc_kept -> 92 | G4: =F4-E4 -> -130.36266
A5: Team gone: race to 55, pay the rent | B5: =4*Tau_race -> 1.7175702 | C5: =Cost_k*Ubar_a*(1-EXP(-Rho_a*Tau_race))/Rho_a+EXP(-Rho_a*Tau_race)*Cost_k*Delta_a*Floor_F/Rho_a -> 241.42893 | D5: =Delay_D*(1-EXP(-Rho_a*Tau_race))/Rho_a -> 13.463189 | E5: =C5+D5 -> 254.89212 | F5: =Proc_gone -> 112 | G5: =F5-E5 -> -142.89212
A6: Volume I's schedules
A7: Team kept: hold 58 | B7: 0 | C7: =Cost_k*Delta_a*C_kept/Rho_a -> 246.51014 | D7: 0 | E7: =C7+D7 -> 246.51014 | F7: =Proc_kept -> 92 | G7: =F7-E7 -> -154.51014
A8: Team gone: rebuild to 58, hold it | B8: =4*Tau_race -> 1.7175702 | C8: =Cost_k*Ubar_a*(1-EXP(-Rho_a*Time_58))/Rho_a+EXP(-Rho_a*Time_58)*Cost_k*Delta_a*C_kept/Rho_a -> 264.44066 | D8: =Delay_D*(1-EXP(-Rho_a*Tau_race))/Rho_a -> 13.463189 | E8: =C8+D8 -> 277.90385 | F8: =Proc_gone -> 112 | G8: =F8-E8 -> -165.90385
A10: Holding 58 costs more than the drift | B10: =C7-C4 -> 24.147483 | C10: Step 4: $24.1 million
A11: Rebuilding to 58 costs more than the race | B11: =E8-E5 -> 23.011732 | C11: Step 4: $23.0 million
A12: Keeping the team leads by (best plans) | B12: =G4-G5 -> 12.529461 | C12: Step 5: $12.5 million
A13: Keeping the team leads by (Volume I's schedules) | B13: =G7-G8 -> 11.393711 | C13: Online Appendix 6.B.3: 11.39
A14: The team: V(58) - V(53) | B14: =E5-E4 -> 32.529461 | C14: $32.5 million

Sheet Floor
A1: Price the floor: the rent and the user cost (Worked Example 6.1, Step 3; Proposition 6.3(ii))
A3: Quantity | B3: Value | C3: Reading
A4: The rent: points a year that hold capability at 55, delta x 55 | B4: =Delta_a*Floor_F -> 5.5699178 | C4: 5.57 points a year
A5: The rent in $ million a year | B5: =Cost_k*B4 -> 22.279671 | C5: $22.3 million
A6: V(55): paying the rent forever | B6: =-B5/Rho_a -> -233.75962 | C6: -$233.8 million
A7: Interest on a point's $4 million, rho k | B7: =Rho_a*Cost_k -> 0.38124072 | C7: $0.38 million a year
A8: Attrition of a point, delta k | B8: =Delta_a*Cost_k -> 0.40508493 | C8: $0.41 million a year
A9: The floor's price: the user cost (rho + delta) k | B9: =B7+B8 -> 0.78632565 | C9: $0.79 million a point a year
A10: Costate equation on the floor: (rho + delta) x 4 - 0 - the floor's price | B10: =Rho_delta*Cost_k-B9 -> 0 | C10: Zero: the price stays at $4 million
A11: Five points of margin over the floor, a year | B11: =5*B9 -> 3.9316282 | C11: $3.9 million a year
A13: On the floor the build runs and a point earns nothing directly; the floor's price is what one more point saves in rent (Proposition 6.3(ii): eta = (rho + delta) k less the marginal earnings).

Sheet Prices
A1: Price capability: the value of a position and the price of a point, checked by finite differences (AXIOM Lab 2.6, step 3; Theorem 6.1; Figure 6.1(a))
A3: Capability c | B3: V(c) | C3: Price m = V'(c) | D3: Central finite difference | E3: Tobin's q | F3: Reading
A4: 53 | B4: =IF(A4<Floor_F,-(Cost_k*Ubar_a+Delay_D)*(1-EXP(-Rho_a*LN((Cap_top-A4)/(Cap_top-Floor_F))/Delta_a))/Rho_a+EXP(-Rho_a*LN((Cap_top-A4)/(Cap_top-Floor_F))/Delta_a)*(-Cost_k*Delta_a*Floor_F/Rho_a),EXP(-Rho_a*LN(A4/Floor_F)/Delta_a)*(-Cost_k*Delta_a*Floor_F/Rho_a)) -> -254.89212 | C4: =IF(A4<Floor_F,EXP(-Rho_a*LN((Cap_top-A4)/(Cap_top-Floor_F))/Delta_a)*(Cost_k*Ubar_a+Delay_D+Rho_a*(-Cost_k*Delta_a*Floor_F/Rho_a))/(Ubar_a-Delta_a*A4),IF(A4=Floor_F,Cost_k,EXP(-Rho_a*LN(A4/Floor_F)/Delta_a)*(-Rho_a*(-Cost_k*Delta_a*Floor_F/Rho_a))/(Delta_a*A4))) -> 10.129671 | D4: =(IF((A4+0.0001)<Floor_F,-(Cost_k*Ubar_a+Delay_D)*(1-EXP(-Rho_a*LN((Cap_top-(A4+0.0001))/(Cap_top-Floor_F))/Delta_a))/Rho_a+EXP(-Rho_a*LN((Cap_top-(A4+0.0001))/(Cap_top-Floor_F))/Delta_a)*(-Cost_k*Delta_a*Floor_F/Rho_a),EXP(-Rho_a*LN((A4+0.0001)/Floor_F)/Delta_a)*(-Cost_k*Delta_a*Floor_F/Rho_a))-IF((A4-0.0001)<Floor_F,-(Cost_k*Ubar_a+Delay_D)*(1-EXP(-Rho_a*LN((Cap_top-(A4-0.0001))/(Cap_top-Floor_F))/Delta_a))/Rho_a+EXP(-Rho_a*LN((Cap_top-(A4-0.0001))/(Cap_top-Floor_F))/Delta_a)*(-Cost_k*Delta_a*Floor_F/Rho_a),EXP(-Rho_a*LN((A4-0.0001)/Floor_F)/Delta_a)*(-Cost_k*Delta_a*Floor_F/Rho_a)))/(2*0.0001) -> 10.129671 | E4: =C4/Cost_k -> 2.5324177 | F4: Team gone: hire at the cap
A5: 54 | B5: =IF(A5<Floor_F,-(Cost_k*Ubar_a+Delay_D)*(1-EXP(-Rho_a*LN((Cap_top-A5)/(Cap_top-Floor_F))/Delta_a))/Rho_a+EXP(-Rho_a*LN((Cap_top-A5)/(Cap_top-Floor_F))/Delta_a)*(-Cost_k*Delta_a*Floor_F/Rho_a),EXP(-Rho_a*LN(A5/Floor_F)/Delta_a)*(-Cost_k*Delta_a*Floor_F/Rho_a)) -> -244.54881 | C5: =IF(A5<Floor_F,EXP(-Rho_a*LN((Cap_top-A5)/(Cap_top-Floor_F))/Delta_a)*(Cost_k*Ubar_a+Delay_D+Rho_a*(-Cost_k*Delta_a*Floor_F/Rho_a))/(Ubar_a-Delta_a*A5),IF(A5=Floor_F,Cost_k,EXP(-Rho_a*LN(A5/Floor_F)/Delta_a)*(-Rho_a*(-Cost_k*Delta_a*Floor_F/Rho_a))/(Delta_a*A5))) -> 10.5615 | D5: =(IF((A5+0.0001)<Floor_F,-(Cost_k*Ubar_a+Delay_D)*(1-EXP(-Rho_a*LN((Cap_top-(A5+0.0001))/(Cap_top-Floor_F))/Delta_a))/Rho_a+EXP(-Rho_a*LN((Cap_top-(A5+0.0001))/(Cap_top-Floor_F))/Delta_a)*(-Cost_k*Delta_a*Floor_F/Rho_a),EXP(-Rho_a*LN((A5+0.0001)/Floor_F)/Delta_a)*(-Cost_k*Delta_a*Floor_F/Rho_a))-IF((A5-0.0001)<Floor_F,-(Cost_k*Ubar_a+Delay_D)*(1-EXP(-Rho_a*LN((Cap_top-(A5-0.0001))/(Cap_top-Floor_F))/Delta_a))/Rho_a+EXP(-Rho_a*LN((Cap_top-(A5-0.0001))/(Cap_top-Floor_F))/Delta_a)*(-Cost_k*Delta_a*Floor_F/Rho_a),EXP(-Rho_a*LN((A5-0.0001)/Floor_F)/Delta_a)*(-Cost_k*Delta_a*Floor_F/Rho_a)))/(2*0.0001) -> 10.5615 | E5: =C5/Cost_k -> 2.640375
A6: 54.999 | B6: =IF(A6<Floor_F,-(Cost_k*Ubar_a+Delay_D)*(1-EXP(-Rho_a*LN((Cap_top-A6)/(Cap_top-Floor_F))/Delta_a))/Rho_a+EXP(-Rho_a*LN((Cap_top-A6)/(Cap_top-Floor_F))/Delta_a)*(-Cost_k*Delta_a*Floor_F/Rho_a),EXP(-Rho_a*LN(A6/Floor_F)/Delta_a)*(-Cost_k*Delta_a*Floor_F/Rho_a)) -> -233.77064 | C6: =IF(A6<Floor_F,EXP(-Rho_a*LN((Cap_top-A6)/(Cap_top-Floor_F))/Delta_a)*(Cost_k*Ubar_a+Delay_D+Rho_a*(-Cost_k*Delta_a*Floor_F/Rho_a))/(Ubar_a-Delta_a*A6),IF(A6=Floor_F,Cost_k,EXP(-Rho_a*LN(A6/Floor_F)/Delta_a)*(-Rho_a*(-Cost_k*Delta_a*Floor_F/Rho_a))/(Delta_a*A6))) -> 11.021372 | D6: =(IF((A6+0.0001)<Floor_F,-(Cost_k*Ubar_a+Delay_D)*(1-EXP(-Rho_a*LN((Cap_top-(A6+0.0001))/(Cap_top-Floor_F))/Delta_a))/Rho_a+EXP(-Rho_a*LN((Cap_top-(A6+0.0001))/(Cap_top-Floor_F))/Delta_a)*(-Cost_k*Delta_a*Floor_F/Rho_a),EXP(-Rho_a*LN((A6+0.0001)/Floor_F)/Delta_a)*(-Cost_k*Delta_a*Floor_F/Rho_a))-IF((A6-0.0001)<Floor_F,-(Cost_k*Ubar_a+Delay_D)*(1-EXP(-Rho_a*LN((Cap_top-(A6-0.0001))/(Cap_top-Floor_F))/Delta_a))/Rho_a+EXP(-Rho_a*LN((Cap_top-(A6-0.0001))/(Cap_top-Floor_F))/Delta_a)*(-Cost_k*Delta_a*Floor_F/Rho_a),EXP(-Rho_a*LN((A6-0.0001)/Floor_F)/Delta_a)*(-Cost_k*Delta_a*Floor_F/Rho_a)))/(2*0.0001) -> 11.021372 | E6: =C6/Cost_k -> 2.7553429 | F6: Just below the floor
A7: 55 | B7: =IF(A7<Floor_F,-(Cost_k*Ubar_a+Delay_D)*(1-EXP(-Rho_a*LN((Cap_top-A7)/(Cap_top-Floor_F))/Delta_a))/Rho_a+EXP(-Rho_a*LN((Cap_top-A7)/(Cap_top-Floor_F))/Delta_a)*(-Cost_k*Delta_a*Floor_F/Rho_a),EXP(-Rho_a*LN(A7/Floor_F)/Delta_a)*(-Cost_k*Delta_a*Floor_F/Rho_a)) -> -233.75962 | C7: =IF(A7<Floor_F,EXP(-Rho_a*LN((Cap_top-A7)/(Cap_top-Floor_F))/Delta_a)*(Cost_k*Ubar_a+Delay_D+Rho_a*(-Cost_k*Delta_a*Floor_F/Rho_a))/(Ubar_a-Delta_a*A7),IF(A7=Floor_F,Cost_k,EXP(-Rho_a*LN(A7/Floor_F)/Delta_a)*(-Rho_a*(-Cost_k*Delta_a*Floor_F/Rho_a))/(Delta_a*A7))) -> 4 | E7: =C7/Cost_k -> 1 | F7: On the floor, build running: the cost
A8: 56 | B8: =IF(A8<Floor_F,-(Cost_k*Ubar_a+Delay_D)*(1-EXP(-Rho_a*LN((Cap_top-A8)/(Cap_top-Floor_F))/Delta_a))/Rho_a+EXP(-Rho_a*LN((Cap_top-A8)/(Cap_top-Floor_F))/Delta_a)*(-Cost_k*Delta_a*Floor_F/Rho_a),EXP(-Rho_a*LN(A8/Floor_F)/Delta_a)*(-Cost_k*Delta_a*Floor_F/Rho_a)) -> -229.82897 | C8: =IF(A8<Floor_F,EXP(-Rho_a*LN((Cap_top-A8)/(Cap_top-Floor_F))/Delta_a)*(Cost_k*Ubar_a+Delay_D+Rho_a*(-Cost_k*Delta_a*Floor_F/Rho_a))/(Ubar_a-Delta_a*A8),IF(A8=Floor_F,Cost_k,EXP(-Rho_a*LN(A8/Floor_F)/Delta_a)*(-Rho_a*(-Cost_k*Delta_a*Floor_F/Rho_a))/(Delta_a*A8))) -> 3.8625128 | D8: =(IF((A8+0.0001)<Floor_F,-(Cost_k*Ubar_a+Delay_D)*(1-EXP(-Rho_a*LN((Cap_top-(A8+0.0001))/(Cap_top-Floor_F))/Delta_a))/Rho_a+EXP(-Rho_a*LN((Cap_top-(A8+0.0001))/(Cap_top-Floor_F))/Delta_a)*(-Cost_k*Delta_a*Floor_F/Rho_a),EXP(-Rho_a*LN((A8+0.0001)/Floor_F)/Delta_a)*(-Cost_k*Delta_a*Floor_F/Rho_a))-IF((A8-0.0001)<Floor_F,-(Cost_k*Ubar_a+Delay_D)*(1-EXP(-Rho_a*LN((Cap_top-(A8-0.0001))/(Cap_top-Floor_F))/Delta_a))/Rho_a+EXP(-Rho_a*LN((Cap_top-(A8-0.0001))/(Cap_top-Floor_F))/Delta_a)*(-Cost_k*Delta_a*Floor_F/Rho_a),EXP(-Rho_a*LN((A8-0.0001)/Floor_F)/Delta_a)*(-Cost_k*Delta_a*Floor_F/Rho_a)))/(2*0.0001) -> 3.8625128 | E8: =C8/Cost_k -> 0.9656282
A9: 58 | B9: =IF(A9<Floor_F,-(Cost_k*Ubar_a+Delay_D)*(1-EXP(-Rho_a*LN((Cap_top-A9)/(Cap_top-Floor_F))/Delta_a))/Rho_a+EXP(-Rho_a*LN((Cap_top-A9)/(Cap_top-Floor_F))/Delta_a)*(-Cost_k*Delta_a*Floor_F/Rho_a),EXP(-Rho_a*LN(A9/Floor_F)/Delta_a)*(-Cost_k*Delta_a*Floor_F/Rho_a)) -> -222.36266 | C9: =IF(A9<Floor_F,EXP(-Rho_a*LN((Cap_top-A9)/(Cap_top-Floor_F))/Delta_a)*(Cost_k*Ubar_a+Delay_D+Rho_a*(-Cost_k*Delta_a*Floor_F/Rho_a))/(Ubar_a-Delta_a*A9),IF(A9=Floor_F,Cost_k,EXP(-Rho_a*LN(A9/Floor_F)/Delta_a)*(-Rho_a*(-Cost_k*Delta_a*Floor_F/Rho_a))/(Delta_a*A9))) -> 3.6081706 | D9: =(IF((A9+0.0001)<Floor_F,-(Cost_k*Ubar_a+Delay_D)*(1-EXP(-Rho_a*LN((Cap_top-(A9+0.0001))/(Cap_top-Floor_F))/Delta_a))/Rho_a+EXP(-Rho_a*LN((Cap_top-(A9+0.0001))/(Cap_top-Floor_F))/Delta_a)*(-Cost_k*Delta_a*Floor_F/Rho_a),EXP(-Rho_a*LN((A9+0.0001)/Floor_F)/Delta_a)*(-Cost_k*Delta_a*Floor_F/Rho_a))-IF((A9-0.0001)<Floor_F,-(Cost_k*Ubar_a+Delay_D)*(1-EXP(-Rho_a*LN((Cap_top-(A9-0.0001))/(Cap_top-Floor_F))/Delta_a))/Rho_a+EXP(-Rho_a*LN((Cap_top-(A9-0.0001))/(Cap_top-Floor_F))/Delta_a)*(-Cost_k*Delta_a*Floor_F/Rho_a),EXP(-Rho_a*LN((A9-0.0001)/Floor_F)/Delta_a)*(-Cost_k*Delta_a*Floor_F/Rho_a)))/(2*0.0001) -> 3.6081706 | E9: =C9/Cost_k -> 0.90204264 | F9: Team kept: hire nothing
A10: 60 | B10: =IF(A10<Floor_F,-(Cost_k*Ubar_a+Delay_D)*(1-EXP(-Rho_a*LN((Cap_top-A10)/(Cap_top-Floor_F))/Delta_a))/Rho_a+EXP(-Rho_a*LN((Cap_top-A10)/(Cap_top-Floor_F))/Delta_a)*(-Cost_k*Delta_a*Floor_F/Rho_a),EXP(-Rho_a*LN(A10/Floor_F)/Delta_a)*(-Cost_k*Delta_a*Floor_F/Rho_a)) -> -215.37994 | C10: =IF(A10<Floor_F,EXP(-Rho_a*LN((Cap_top-A10)/(Cap_top-Floor_F))/Delta_a)*(Cost_k*Ubar_a+Delay_D+Rho_a*(-Cost_k*Delta_a*Floor_F/Rho_a))/(Ubar_a-Delta_a*A10),IF(A10=Floor_F,Cost_k,EXP(-Rho_a*LN(A10/Floor_F)/Delta_a)*(-Rho_a*(-Cost_k*Delta_a*Floor_F/Rho_a))/(Delta_a*A10))) -> 3.3783698 | D10: =(IF((A10+0.0001)<Floor_F,-(Cost_k*Ubar_a+Delay_D)*(1-EXP(-Rho_a*LN((Cap_top-(A10+0.0001))/(Cap_top-Floor_F))/Delta_a))/Rho_a+EXP(-Rho_a*LN((Cap_top-(A10+0.0001))/(Cap_top-Floor_F))/Delta_a)*(-Cost_k*Delta_a*Floor_F/Rho_a),EXP(-Rho_a*LN((A10+0.0001)/Floor_F)/Delta_a)*(-Cost_k*Delta_a*Floor_F/Rho_a))-IF((A10-0.0001)<Floor_F,-(Cost_k*Ubar_a+Delay_D)*(1-EXP(-Rho_a*LN((Cap_top-(A10-0.0001))/(Cap_top-Floor_F))/Delta_a))/Rho_a+EXP(-Rho_a*LN((Cap_top-(A10-0.0001))/(Cap_top-Floor_F))/Delta_a)*(-Cost_k*Delta_a*Floor_F/Rho_a),EXP(-Rho_a*LN((A10-0.0001)/Floor_F)/Delta_a)*(-Cost_k*Delta_a*Floor_F/Rho_a)))/(2*0.0001) -> 3.3783698 | E10: =C10/Cost_k -> 0.84459246
A12: Price as capability reaches 55: the cost plus the delay a point saves, 4 + D/(u bar - 55 delta) | C12: =Cost_k+Delay_D/(Ubar_a-Delta_a*Floor_F) -> 11.021847
A13: Years sooner the build starts with one more point, 1/(u bar - 55 delta) | C13: =1/(Ubar_a-Delta_a*Floor_F) -> 0.21943272
A14: Price at 53 grown at rho + delta over the race | C14: =C4*EXP(Rho_delta*Tau_race) -> 11.021847
A15: Price at 58 grown at rho + delta over the drift | C15: =C9*EXP(Rho_delta*Tau_drift) -> 4
A16: The floor's price as earnings from the drift's end, discounted at rho + delta | C16: =Eta_floor*EXP(-Rho_delta*Tau_drift)/Rho_delta -> 3.6081706
A17: The team: V(58) - V(53) | C17: =B9-B4 -> 32.529461
A19: Theorem 6.1(iii): along a best plan the price is the slope of the best value. Off the floor it grows at rho + delta; it falls to the $4 million cost the moment the build starts.
A21: Capability today | B21: PV of hiring and delay, -V(c) | C21: Price m | D21: Central finite difference
A22: 50 | B22: =-IF(A22<Floor_F,-(Cost_k*Ubar_a+Delay_D)*(1-EXP(-Rho_a*LN((Cap_top-A22)/(Cap_top-Floor_F))/Delta_a))/Rho_a+EXP(-Rho_a*LN((Cap_top-A22)/(Cap_top-Floor_F))/Delta_a)*(-Cost_k*Delta_a*Floor_F/Rho_a),EXP(-Rho_a*LN(A22/Floor_F)/Delta_a)*(-Cost_k*Delta_a*Floor_F/Rho_a)) -> 283.50934 | C22: =IF(A22<Floor_F,EXP(-Rho_a*LN((Cap_top-A22)/(Cap_top-Floor_F))/Delta_a)*(Cost_k*Ubar_a+Delay_D+Rho_a*(-Cost_k*Delta_a*Floor_F/Rho_a))/(Ubar_a-Delta_a*A22),IF(A22=Floor_F,Cost_k,EXP(-Rho_a*LN(A22/Floor_F)/Delta_a)*(-Rho_a*(-Cost_k*Delta_a*Floor_F/Rho_a))/(Delta_a*A22))) -> 8.9832356 | D22: =(IF((A22+0.0001)<Floor_F,-(Cost_k*Ubar_a+Delay_D)*(1-EXP(-Rho_a*LN((Cap_top-(A22+0.0001))/(Cap_top-Floor_F))/Delta_a))/Rho_a+EXP(-Rho_a*LN((Cap_top-(A22+0.0001))/(Cap_top-Floor_F))/Delta_a)*(-Cost_k*Delta_a*Floor_F/Rho_a),EXP(-Rho_a*LN((A22+0.0001)/Floor_F)/Delta_a)*(-Cost_k*Delta_a*Floor_F/Rho_a))-IF((A22-0.0001)<Floor_F,-(Cost_k*Ubar_a+Delay_D)*(1-EXP(-Rho_a*LN((Cap_top-(A22-0.0001))/(Cap_top-Floor_F))/Delta_a))/Rho_a+EXP(-Rho_a*LN((Cap_top-(A22-0.0001))/(Cap_top-Floor_F))/Delta_a)*(-Cost_k*Delta_a*Floor_F/Rho_a),EXP(-Rho_a*LN((A22-0.0001)/Floor_F)/Delta_a)*(-Cost_k*Delta_a*Floor_F/Rho_a)))/(2*0.0001) -> 8.9832356
A23: 50.25 | B23: =-IF(A23<Floor_F,-(Cost_k*Ubar_a+Delay_D)*(1-EXP(-Rho_a*LN((Cap_top-A23)/(Cap_top-Floor_F))/Delta_a))/Rho_a+EXP(-Rho_a*LN((Cap_top-A23)/(Cap_top-Floor_F))/Delta_a)*(-Cost_k*Delta_a*Floor_F/Rho_a),EXP(-Rho_a*LN(A23/Floor_F)/Delta_a)*(-Cost_k*Delta_a*Floor_F/Rho_a)) -> 281.25258 | C23: =IF(A23<Floor_F,EXP(-Rho_a*LN((Cap_top-A23)/(Cap_top-Floor_F))/Delta_a)*(Cost_k*Ubar_a+Delay_D+Rho_a*(-Cost_k*Delta_a*Floor_F/Rho_a))/(Ubar_a-Delta_a*A23),IF(A23=Floor_F,Cost_k,EXP(-Rho_a*LN(A23/Floor_F)/Delta_a)*(-Rho_a*(-Cost_k*Delta_a*Floor_F/Rho_a))/(Delta_a*A23))) -> 9.0710694 | D23: =(IF((A23+0.0001)<Floor_F,-(Cost_k*Ubar_a+Delay_D)*(1-EXP(-Rho_a*LN((Cap_top-(A23+0.0001))/(Cap_top-Floor_F))/Delta_a))/Rho_a+EXP(-Rho_a*LN((Cap_top-(A23+0.0001))/(Cap_top-Floor_F))/Delta_a)*(-Cost_k*Delta_a*Floor_F/Rho_a),EXP(-Rho_a*LN((A23+0.0001)/Floor_F)/Delta_a)*(-Cost_k*Delta_a*Floor_F/Rho_a))-IF((A23-0.0001)<Floor_F,-(Cost_k*Ubar_a+Delay_D)*(1-EXP(-Rho_a*LN((Cap_top-(A23-0.0001))/(Cap_top-Floor_F))/Delta_a))/Rho_a+EXP(-Rho_a*LN((Cap_top-(A23-0.0001))/(Cap_top-Floor_F))/Delta_a)*(-Cost_k*Delta_a*Floor_F/Rho_a),EXP(-Rho_a*LN((A23-0.0001)/Floor_F)/Delta_a)*(-Cost_k*Delta_a*Floor_F/Rho_a)))/(2*0.0001) -> 9.0710694
A24: 50.5 | B24: =-IF(A24<Floor_F,-(Cost_k*Ubar_a+Delay_D)*(1-EXP(-Rho_a*LN((Cap_top-A24)/(Cap_top-Floor_F))/Delta_a))/Rho_a+EXP(-Rho_a*LN((Cap_top-A24)/(Cap_top-Floor_F))/Delta_a)*(-Cost_k*Delta_a*Floor_F/Rho_a),EXP(-Rho_a*LN(A24/Floor_F)/Delta_a)*(-Cost_k*Delta_a*Floor_F/Rho_a)) -> 278.97369 | C24: =IF(A24<Floor_F,EXP(-Rho_a*LN((Cap_top-A24)/(Cap_top-Floor_F))/Delta_a)*(Cost_k*Ubar_a+Delay_D+Rho_a*(-Cost_k*Delta_a*Floor_F/Rho_a))/(Ubar_a-Delta_a*A24),IF(A24=Floor_F,Cost_k,EXP(-Rho_a*LN(A24/Floor_F)/Delta_a)*(-Rho_a*(-Cost_k*Delta_a*Floor_F/Rho_a))/(Delta_a*A24))) -> 9.1602111 | D24: =(IF((A24+0.0001)<Floor_F,-(Cost_k*Ubar_a+Delay_D)*(1-EXP(-Rho_a*LN((Cap_top-(A24+0.0001))/(Cap_top-Floor_F))/Delta_a))/Rho_a+EXP(-Rho_a*LN((Cap_top-(A24+0.0001))/(Cap_top-Floor_F))/Delta_a)*(-Cost_k*Delta_a*Floor_F/Rho_a),EXP(-Rho_a*LN((A24+0.0001)/Floor_F)/Delta_a)*(-Cost_k*Delta_a*Floor_F/Rho_a))-IF((A24-0.0001)<Floor_F,-(Cost_k*Ubar_a+Delay_D)*(1-EXP(-Rho_a*LN((Cap_top-(A24-0.0001))/(Cap_top-Floor_F))/Delta_a))/Rho_a+EXP(-Rho_a*LN((Cap_top-(A24-0.0001))/(Cap_top-Floor_F))/Delta_a)*(-Cost_k*Delta_a*Floor_F/Rho_a),EXP(-Rho_a*LN((A24-0.0001)/Floor_F)/Delta_a)*(-Cost_k*Delta_a*Floor_F/Rho_a)))/(2*0.0001) -> 9.1602111
A25: 50.75 | B25: =-IF(A25<Floor_F,-(Cost_k*Ubar_a+Delay_D)*(1-EXP(-Rho_a*LN((Cap_top-A25)/(Cap_top-Floor_F))/Delta_a))/Rho_a+EXP(-Rho_a*LN((Cap_top-A25)/(Cap_top-Floor_F))/Delta_a)*(-Cost_k*Delta_a*Floor_F/Rho_a),EXP(-Rho_a*LN(A25/Floor_F)/Delta_a)*(-Cost_k*Delta_a*Floor_F/Rho_a)) -> 276.67236 | C25: =IF(A25<Floor_F,EXP(-Rho_a*LN((Cap_top-A25)/(Cap_top-Floor_F))/Delta_a)*(Cost_k*Ubar_a+Delay_D+Rho_a*(-Cost_k*Delta_a*Floor_F/Rho_a))/(Ubar_a-Delta_a*A25),IF(A25=Floor_F,Cost_k,EXP(-Rho_a*LN(A25/Floor_F)/Delta_a)*(-Rho_a*(-Cost_k*Delta_a*Floor_F/Rho_a))/(Delta_a*A25))) -> 9.2506867 | D25: =(IF((A25+0.0001)<Floor_F,-(Cost_k*Ubar_a+Delay_D)*(1-EXP(-Rho_a*LN((Cap_top-(A25+0.0001))/(Cap_top-Floor_F))/Delta_a))/Rho_a+EXP(-Rho_a*LN((Cap_top-(A25+0.0001))/(Cap_top-Floor_F))/Delta_a)*(-Cost_k*Delta_a*Floor_F/Rho_a),EXP(-Rho_a*LN((A25+0.0001)/Floor_F)/Delta_a)*(-Cost_k*Delta_a*Floor_F/Rho_a))-IF((A25-0.0001)<Floor_F,-(Cost_k*Ubar_a+Delay_D)*(1-EXP(-Rho_a*LN((Cap_top-(A25-0.0001))/(Cap_top-Floor_F))/Delta_a))/Rho_a+EXP(-Rho_a*LN((Cap_top-(A25-0.0001))/(Cap_top-Floor_F))/Delta_a)*(-Cost_k*Delta_a*Floor_F/Rho_a),EXP(-Rho_a*LN((A25-0.0001)/Floor_F)/Delta_a)*(-Cost_k*Delta_a*Floor_F/Rho_a)))/(2*0.0001) -> 9.2506867
A26: 51 | B26: =-IF(A26<Floor_F,-(Cost_k*Ubar_a+Delay_D)*(1-EXP(-Rho_a*LN((Cap_top-A26)/(Cap_top-Floor_F))/Delta_a))/Rho_a+EXP(-Rho_a*LN((Cap_top-A26)/(Cap_top-Floor_F))/Delta_a)*(-Cost_k*Delta_a*Floor_F/Rho_a),EXP(-Rho_a*LN(A26/Floor_F)/Delta_a)*(-Cost_k*Delta_a*Floor_F/Rho_a)) -> 274.34824 | C26: =IF(A26<Floor_F,EXP(-Rho_a*LN((Cap_top-A26)/(Cap_top-Floor_F))/Delta_a)*(Cost_k*Ubar_a+Delay_D+Rho_a*(-Cost_k*Delta_a*Floor_F/Rho_a))/(Ubar_a-Delta_a*A26),IF(A26=Floor_F,Cost_k,EXP(-Rho_a*LN(A26/Floor_F)/Delta_a)*(-Rho_a*(-Cost_k*Delta_a*Floor_F/Rho_a))/(Delta_a*A26))) -> 9.3425232 | D26: =(IF((A26+0.0001)<Floor_F,-(Cost_k*Ubar_a+Delay_D)*(1-EXP(-Rho_a*LN((Cap_top-(A26+0.0001))/(Cap_top-Floor_F))/Delta_a))/Rho_a+EXP(-Rho_a*LN((Cap_top-(A26+0.0001))/(Cap_top-Floor_F))/Delta_a)*(-Cost_k*Delta_a*Floor_F/Rho_a),EXP(-Rho_a*LN((A26+0.0001)/Floor_F)/Delta_a)*(-Cost_k*Delta_a*Floor_F/Rho_a))-IF((A26-0.0001)<Floor_F,-(Cost_k*Ubar_a+Delay_D)*(1-EXP(-Rho_a*LN((Cap_top-(A26-0.0001))/(Cap_top-Floor_F))/Delta_a))/Rho_a+EXP(-Rho_a*LN((Cap_top-(A26-0.0001))/(Cap_top-Floor_F))/Delta_a)*(-Cost_k*Delta_a*Floor_F/Rho_a),EXP(-Rho_a*LN((A26-0.0001)/Floor_F)/Delta_a)*(-Cost_k*Delta_a*Floor_F/Rho_a)))/(2*0.0001) -> 9.3425232
A27: 51.25 | B27: =-IF(A27<Floor_F,-(Cost_k*Ubar_a+Delay_D)*(1-EXP(-Rho_a*LN((Cap_top-A27)/(Cap_top-Floor_F))/Delta_a))/Rho_a+EXP(-Rho_a*LN((Cap_top-A27)/(Cap_top-Floor_F))/Delta_a)*(-Cost_k*Delta_a*Floor_F/Rho_a),EXP(-Rho_a*LN(A27/Floor_F)/Delta_a)*(-Cost_k*Delta_a*Floor_F/Rho_a)) -> 272.00098 | C27: =IF(A27<Floor_F,EXP(-Rho_a*LN((Cap_top-A27)/(Cap_top-Floor_F))/Delta_a)*(Cost_k*Ubar_a+Delay_D+Rho_a*(-Cost_k*Delta_a*Floor_F/Rho_a))/(Ubar_a-Delta_a*A27),IF(A27=Floor_F,Cost_k,EXP(-Rho_a*LN(A27/Floor_F)/Delta_a)*(-Rho_a*(-Cost_k*Delta_a*Floor_F/Rho_a))/(Delta_a*A27))) -> 9.4357483 | D27: =(IF((A27+0.0001)<Floor_F,-(Cost_k*Ubar_a+Delay_D)*(1-EXP(-Rho_a*LN((Cap_top-(A27+0.0001))/(Cap_top-Floor_F))/Delta_a))/Rho_a+EXP(-Rho_a*LN((Cap_top-(A27+0.0001))/(Cap_top-Floor_F))/Delta_a)*(-Cost_k*Delta_a*Floor_F/Rho_a),EXP(-Rho_a*LN((A27+0.0001)/Floor_F)/Delta_a)*(-Cost_k*Delta_a*Floor_F/Rho_a))-IF((A27-0.0001)<Floor_F,-(Cost_k*Ubar_a+Delay_D)*(1-EXP(-Rho_a*LN((Cap_top-(A27-0.0001))/(Cap_top-Floor_F))/Delta_a))/Rho_a+EXP(-Rho_a*LN((Cap_top-(A27-0.0001))/(Cap_top-Floor_F))/Delta_a)*(-Cost_k*Delta_a*Floor_F/Rho_a),EXP(-Rho_a*LN((A27-0.0001)/Floor_F)/Delta_a)*(-Cost_k*Delta_a*Floor_F/Rho_a)))/(2*0.0001) -> 9.4357483
A28: 51.5 | B28: =-IF(A28<Floor_F,-(Cost_k*Ubar_a+Delay_D)*(1-EXP(-Rho_a*LN((Cap_top-A28)/(Cap_top-Floor_F))/Delta_a))/Rho_a+EXP(-Rho_a*LN((Cap_top-A28)/(Cap_top-Floor_F))/Delta_a)*(-Cost_k*Delta_a*Floor_F/Rho_a),EXP(-Rho_a*LN(A28/Floor_F)/Delta_a)*(-Cost_k*Delta_a*Floor_F/Rho_a)) -> 269.63024 | C28: =IF(A28<Floor_F,EXP(-Rho_a*LN((Cap_top-A28)/(Cap_top-Floor_F))/Delta_a)*(Cost_k*Ubar_a+Delay_D+Rho_a*(-Cost_k*Delta_a*Floor_F/Rho_a))/(Ubar_a-Delta_a*A28),IF(A28=Floor_F,Cost_k,EXP(-Rho_a*LN(A28/Floor_F)/Delta_a)*(-Rho_a*(-Cost_k*Delta_a*Floor_F/Rho_a))/(Delta_a*A28))) -> 9.5303901 | D28: =(IF((A28+0.0001)<Floor_F,-(Cost_k*Ubar_a+Delay_D)*(1-EXP(-Rho_a*LN((Cap_top-(A28+0.0001))/(Cap_top-Floor_F))/Delta_a))/Rho_a+EXP(-Rho_a*LN((Cap_top-(A28+0.0001))/(Cap_top-Floor_F))/Delta_a)*(-Cost_k*Delta_a*Floor_F/Rho_a),EXP(-Rho_a*LN((A28+0.0001)/Floor_F)/Delta_a)*(-Cost_k*Delta_a*Floor_F/Rho_a))-IF((A28-0.0001)<Floor_F,-(Cost_k*Ubar_a+Delay_D)*(1-EXP(-Rho_a*LN((Cap_top-(A28-0.0001))/(Cap_top-Floor_F))/Delta_a))/Rho_a+EXP(-Rho_a*LN((Cap_top-(A28-0.0001))/(Cap_top-Floor_F))/Delta_a)*(-Cost_k*Delta_a*Floor_F/Rho_a),EXP(-Rho_a*LN((A28-0.0001)/Floor_F)/Delta_a)*(-Cost_k*Delta_a*Floor_F/Rho_a)))/(2*0.0001) -> 9.5303901
A29: 51.75 | B29: =-IF(A29<Floor_F,-(Cost_k*Ubar_a+Delay_D)*(1-EXP(-Rho_a*LN((Cap_top-A29)/(Cap_top-Floor_F))/Delta_a))/Rho_a+EXP(-Rho_a*LN((Cap_top-A29)/(Cap_top-Floor_F))/Delta_a)*(-Cost_k*Delta_a*Floor_F/Rho_a),EXP(-Rho_a*LN(A29/Floor_F)/Delta_a)*(-Cost_k*Delta_a*Floor_F/Rho_a)) -> 267.23567 | C29: =IF(A29<Floor_F,EXP(-Rho_a*LN((Cap_top-A29)/(Cap_top-Floor_F))/Delta_a)*(Cost_k*Ubar_a+Delay_D+Rho_a*(-Cost_k*Delta_a*Floor_F/Rho_a))/(Ubar_a-Delta_a*A29),IF(A29=Floor_F,Cost_k,EXP(-Rho_a*LN(A29/Floor_F)/Delta_a)*(-Rho_a*(-Cost_k*Delta_a*Floor_F/Rho_a))/(Delta_a*A29))) -> 9.6264777 | D29: =(IF((A29+0.0001)<Floor_F,-(Cost_k*Ubar_a+Delay_D)*(1-EXP(-Rho_a*LN((Cap_top-(A29+0.0001))/(Cap_top-Floor_F))/Delta_a))/Rho_a+EXP(-Rho_a*LN((Cap_top-(A29+0.0001))/(Cap_top-Floor_F))/Delta_a)*(-Cost_k*Delta_a*Floor_F/Rho_a),EXP(-Rho_a*LN((A29+0.0001)/Floor_F)/Delta_a)*(-Cost_k*Delta_a*Floor_F/Rho_a))-IF((A29-0.0001)<Floor_F,-(Cost_k*Ubar_a+Delay_D)*(1-EXP(-Rho_a*LN((Cap_top-(A29-0.0001))/(Cap_top-Floor_F))/Delta_a))/Rho_a+EXP(-Rho_a*LN((Cap_top-(A29-0.0001))/(Cap_top-Floor_F))/Delta_a)*(-Cost_k*Delta_a*Floor_F/Rho_a),EXP(-Rho_a*LN((A29-0.0001)/Floor_F)/Delta_a)*(-Cost_k*Delta_a*Floor_F/Rho_a)))/(2*0.0001) -> 9.6264777
A30: 52 | B30: =-IF(A30<Floor_F,-(Cost_k*Ubar_a+Delay_D)*(1-EXP(-Rho_a*LN((Cap_top-A30)/(Cap_top-Floor_F))/Delta_a))/Rho_a+EXP(-Rho_a*LN((Cap_top-A30)/(Cap_top-Floor_F))/Delta_a)*(-Cost_k*Delta_a*Floor_F/Rho_a),EXP(-Rho_a*LN(A30/Floor_F)/Delta_a)*(-Cost_k*Delta_a*Floor_F/Rho_a)) -> 264.81688 | C30: =IF(A30<Floor_F,EXP(-Rho_a*LN((Cap_top-A30)/(Cap_top-Floor_F))/Delta_a)*(Cost_k*Ubar_a+Delay_D+Rho_a*(-Cost_k*Delta_a*Floor_F/Rho_a))/(Ubar_a-Delta_a*A30),IF(A30=Floor_F,Cost_k,EXP(-Rho_a*LN(A30/Floor_F)/Delta_a)*(-Rho_a*(-Cost_k*Delta_a*Floor_F/Rho_a))/(Delta_a*A30))) -> 9.7240408 | D30: =(IF((A30+0.0001)<Floor_F,-(Cost_k*Ubar_a+Delay_D)*(1-EXP(-Rho_a*LN((Cap_top-(A30+0.0001))/(Cap_top-Floor_F))/Delta_a))/Rho_a+EXP(-Rho_a*LN((Cap_top-(A30+0.0001))/(Cap_top-Floor_F))/Delta_a)*(-Cost_k*Delta_a*Floor_F/Rho_a),EXP(-Rho_a*LN((A30+0.0001)/Floor_F)/Delta_a)*(-Cost_k*Delta_a*Floor_F/Rho_a))-IF((A30-0.0001)<Floor_F,-(Cost_k*Ubar_a+Delay_D)*(1-EXP(-Rho_a*LN((Cap_top-(A30-0.0001))/(Cap_top-Floor_F))/Delta_a))/Rho_a+EXP(-Rho_a*LN((Cap_top-(A30-0.0001))/(Cap_top-Floor_F))/Delta_a)*(-Cost_k*Delta_a*Floor_F/Rho_a),EXP(-Rho_a*LN((A30-0.0001)/Floor_F)/Delta_a)*(-Cost_k*Delta_a*Floor_F/Rho_a)))/(2*0.0001) -> 9.7240408
A31: 52.25 | B31: =-IF(A31<Floor_F,-(Cost_k*Ubar_a+Delay_D)*(1-EXP(-Rho_a*LN((Cap_top-A31)/(Cap_top-Floor_F))/Delta_a))/Rho_a+EXP(-Rho_a*LN((Cap_top-A31)/(Cap_top-Floor_F))/Delta_a)*(-Cost_k*Delta_a*Floor_F/Rho_a),EXP(-Rho_a*LN(A31/Floor_F)/Delta_a)*(-Cost_k*Delta_a*Floor_F/Rho_a)) -> 262.37352 | C31: =IF(A31<Floor_F,EXP(-Rho_a*LN((Cap_top-A31)/(Cap_top-Floor_F))/Delta_a)*(Cost_k*Ubar_a+Delay_D+Rho_a*(-Cost_k*Delta_a*Floor_F/Rho_a))/(Ubar_a-Delta_a*A31),IF(A31=Floor_F,Cost_k,EXP(-Rho_a*LN(A31/Floor_F)/Delta_a)*(-Rho_a*(-Cost_k*Delta_a*Floor_F/Rho_a))/(Delta_a*A31))) -> 9.8231099 | D31: =(IF((A31+0.0001)<Floor_F,-(Cost_k*Ubar_a+Delay_D)*(1-EXP(-Rho_a*LN((Cap_top-(A31+0.0001))/(Cap_top-Floor_F))/Delta_a))/Rho_a+EXP(-Rho_a*LN((Cap_top-(A31+0.0001))/(Cap_top-Floor_F))/Delta_a)*(-Cost_k*Delta_a*Floor_F/Rho_a),EXP(-Rho_a*LN((A31+0.0001)/Floor_F)/Delta_a)*(-Cost_k*Delta_a*Floor_F/Rho_a))-IF((A31-0.0001)<Floor_F,-(Cost_k*Ubar_a+Delay_D)*(1-EXP(-Rho_a*LN((Cap_top-(A31-0.0001))/(Cap_top-Floor_F))/Delta_a))/Rho_a+EXP(-Rho_a*LN((Cap_top-(A31-0.0001))/(Cap_top-Floor_F))/Delta_a)*(-Cost_k*Delta_a*Floor_F/Rho_a),EXP(-Rho_a*LN((A31-0.0001)/Floor_F)/Delta_a)*(-Cost_k*Delta_a*Floor_F/Rho_a)))/(2*0.0001) -> 9.8231099
A32: 52.5 | B32: =-IF(A32<Floor_F,-(Cost_k*Ubar_a+Delay_D)*(1-EXP(-Rho_a*LN((Cap_top-A32)/(Cap_top-Floor_F))/Delta_a))/Rho_a+EXP(-Rho_a*LN((Cap_top-A32)/(Cap_top-Floor_F))/Delta_a)*(-Cost_k*Delta_a*Floor_F/Rho_a),EXP(-Rho_a*LN(A32/Floor_F)/Delta_a)*(-Cost_k*Delta_a*Floor_F/Rho_a)) -> 259.9052 | C32: =IF(A32<Floor_F,EXP(-Rho_a*LN((Cap_top-A32)/(Cap_top-Floor_F))/Delta_a)*(Cost_k*Ubar_a+Delay_D+Rho_a*(-Cost_k*Delta_a*Floor_F/Rho_a))/(Ubar_a-Delta_a*A32),IF(A32=Floor_F,Cost_k,EXP(-Rho_a*LN(A32/Floor_F)/Delta_a)*(-Rho_a*(-Cost_k*Delta_a*Floor_F/Rho_a))/(Delta_a*A32))) -> 9.9237163 | D32: =(IF((A32+0.0001)<Floor_F,-(Cost_k*Ubar_a+Delay_D)*(1-EXP(-Rho_a*LN((Cap_top-(A32+0.0001))/(Cap_top-Floor_F))/Delta_a))/Rho_a+EXP(-Rho_a*LN((Cap_top-(A32+0.0001))/(Cap_top-Floor_F))/Delta_a)*(-Cost_k*Delta_a*Floor_F/Rho_a),EXP(-Rho_a*LN((A32+0.0001)/Floor_F)/Delta_a)*(-Cost_k*Delta_a*Floor_F/Rho_a))-IF((A32-0.0001)<Floor_F,-(Cost_k*Ubar_a+Delay_D)*(1-EXP(-Rho_a*LN((Cap_top-(A32-0.0001))/(Cap_top-Floor_F))/Delta_a))/Rho_a+EXP(-Rho_a*LN((Cap_top-(A32-0.0001))/(Cap_top-Floor_F))/Delta_a)*(-Cost_k*Delta_a*Floor_F/Rho_a),EXP(-Rho_a*LN((A32-0.0001)/Floor_F)/Delta_a)*(-Cost_k*Delta_a*Floor_F/Rho_a)))/(2*0.0001) -> 9.9237163
A33: 52.75 | B33: =-IF(A33<Floor_F,-(Cost_k*Ubar_a+Delay_D)*(1-EXP(-Rho_a*LN((Cap_top-A33)/(Cap_top-Floor_F))/Delta_a))/Rho_a+EXP(-Rho_a*LN((Cap_top-A33)/(Cap_top-Floor_F))/Delta_a)*(-Cost_k*Delta_a*Floor_F/Rho_a),EXP(-Rho_a*LN(A33/Floor_F)/Delta_a)*(-Cost_k*Delta_a*Floor_F/Rho_a)) -> 257.41153 | C33: =IF(A33<Floor_F,EXP(-Rho_a*LN((Cap_top-A33)/(Cap_top-Floor_F))/Delta_a)*(Cost_k*Ubar_a+Delay_D+Rho_a*(-Cost_k*Delta_a*Floor_F/Rho_a))/(Ubar_a-Delta_a*A33),IF(A33=Floor_F,Cost_k,EXP(-Rho_a*LN(A33/Floor_F)/Delta_a)*(-Rho_a*(-Cost_k*Delta_a*Floor_F/Rho_a))/(Delta_a*A33))) -> 10.025892 | D33: =(IF((A33+0.0001)<Floor_F,-(Cost_k*Ubar_a+Delay_D)*(1-EXP(-Rho_a*LN((Cap_top-(A33+0.0001))/(Cap_top-Floor_F))/Delta_a))/Rho_a+EXP(-Rho_a*LN((Cap_top-(A33+0.0001))/(Cap_top-Floor_F))/Delta_a)*(-Cost_k*Delta_a*Floor_F/Rho_a),EXP(-Rho_a*LN((A33+0.0001)/Floor_F)/Delta_a)*(-Cost_k*Delta_a*Floor_F/Rho_a))-IF((A33-0.0001)<Floor_F,-(Cost_k*Ubar_a+Delay_D)*(1-EXP(-Rho_a*LN((Cap_top-(A33-0.0001))/(Cap_top-Floor_F))/Delta_a))/Rho_a+EXP(-Rho_a*LN((Cap_top-(A33-0.0001))/(Cap_top-Floor_F))/Delta_a)*(-Cost_k*Delta_a*Floor_F/Rho_a),EXP(-Rho_a*LN((A33-0.0001)/Floor_F)/Delta_a)*(-Cost_k*Delta_a*Floor_F/Rho_a)))/(2*0.0001) -> 10.025892
... A41: 54.75 | B41: =-IF(A41<Floor_F,-(Cost_k*Ubar_a+Delay_D)*(1-EXP(-Rho_a*LN((Cap_top-A41)/(Cap_top-Floor_F))/Delta_a))/Rho_a+EXP(-Rho_a*LN((Cap_top-A41)/(Cap_top-Floor_F))/Delta_a)*(-Cost_k*Delta_a*Floor_F/Rho_a),EXP(-Rho_a*LN(A41/Floor_F)/Delta_a)*(-Cost_k*Delta_a*Floor_F/Rho_a)) -> 236.5003 | C41: =IF(A41<Floor_F,EXP(-Rho_a*LN((Cap_top-A41)/(Cap_top-Floor_F))/Delta_a)*(Cost_k*Ubar_a+Delay_D+Rho_a*(-Cost_k*Delta_a*Floor_F/Rho_a))/(Ubar_a-Delta_a*A41),IF(A41=Floor_F,Cost_k,EXP(-Rho_a*LN(A41/Floor_F)/Delta_a)*(-Rho_a*(-Cost_k*Delta_a*Floor_F/Rho_a))/(Delta_a*A41))) -> 10.90395 | D41: =(IF((A41+0.0001)<Floor_F,-(Cost_k*Ubar_a+Delay_D)*(1-EXP(-Rho_a*LN((Cap_top-(A41+0.0001))/(Cap_top-Floor_F))/Delta_a))/Rho_a+EXP(-Rho_a*LN((Cap_top-(A41+0.0001))/(Cap_top-Floor_F))/Delta_a)*(-Cost_k*Delta_a*Floor_F/Rho_a),EXP(-Rho_a*LN((A41+0.0001)/Floor_F)/Delta_a)*(-Cost_k*Delta_a*Floor_F/Rho_a))-IF((A41-0.0001)<Floor_F,-(Cost_k*Ubar_a+Delay_D)*(1-EXP(-Rho_a*LN((Cap_top-(A41-0.0001))/(Cap_top-Floor_F))/Delta_a))/Rho_a+EXP(-Rho_a*LN((Cap_top-(A41-0.0001))/(Cap_top-Floor_F))/Delta_a)*(-Cost_k*Delta_a*Floor_F/Rho_a),EXP(-Rho_a*LN((A41-0.0001)/Floor_F)/Delta_a)*(-Cost_k*Delta_a*Floor_F/Rho_a)))/(2*0.0001) -> 10.90395
A42: 55 | B42: =-IF(A42<Floor_F,-(Cost_k*Ubar_a+Delay_D)*(1-EXP(-Rho_a*LN((Cap_top-A42)/(Cap_top-Floor_F))/Delta_a))/Rho_a+EXP(-Rho_a*LN((Cap_top-A42)/(Cap_top-Floor_F))/Delta_a)*(-Cost_k*Delta_a*Floor_F/Rho_a),EXP(-Rho_a*LN(A42/Floor_F)/Delta_a)*(-Cost_k*Delta_a*Floor_F/Rho_a)) -> 233.75962 | C42: =IF(A42<Floor_F,EXP(-Rho_a*LN((Cap_top-A42)/(Cap_top-Floor_F))/Delta_a)*(Cost_k*Ubar_a+Delay_D+Rho_a*(-Cost_k*Delta_a*Floor_F/Rho_a))/(Ubar_a-Delta_a*A42),IF(A42=Floor_F,Cost_k,EXP(-Rho_a*LN(A42/Floor_F)/Delta_a)*(-Rho_a*(-Cost_k*Delta_a*Floor_F/Rho_a))/(Delta_a*A42))) -> 4
A43: 55.25 | B43: =-IF(A43<Floor_F,-(Cost_k*Ubar_a+Delay_D)*(1-EXP(-Rho_a*LN((Cap_top-A43)/(Cap_top-Floor_F))/Delta_a))/Rho_a+EXP(-Rho_a*LN((Cap_top-A43)/(Cap_top-Floor_F))/Delta_a)*(-Cost_k*Delta_a*Floor_F/Rho_a),EXP(-Rho_a*LN(A43/Floor_F)/Delta_a)*(-Cost_k*Delta_a*Floor_F/Rho_a)) -> 232.76401 | C43: =IF(A43<Floor_F,EXP(-Rho_a*LN((Cap_top-A43)/(Cap_top-Floor_F))/Delta_a)*(Cost_k*Ubar_a+Delay_D+Rho_a*(-Cost_k*Delta_a*Floor_F/Rho_a))/(Ubar_a-Delta_a*A43),IF(A43=Floor_F,Cost_k,EXP(-Rho_a*LN(A43/Floor_F)/Delta_a)*(-Rho_a*(-Cost_k*Delta_a*Floor_F/Rho_a))/(Delta_a*A43))) -> 3.9649411 | D43: =(IF((A43+0.0001)<Floor_F,-(Cost_k*Ubar_a+Delay_D)*(1-EXP(-Rho_a*LN((Cap_top-(A43+0.0001))/(Cap_top-Floor_F))/Delta_a))/Rho_a+EXP(-Rho_a*LN((Cap_top-(A43+0.0001))/(Cap_top-Floor_F))/Delta_a)*(-Cost_k*Delta_a*Floor_F/Rho_a),EXP(-Rho_a*LN((A43+0.0001)/Floor_F)/Delta_a)*(-Cost_k*Delta_a*Floor_F/Rho_a))-IF((A43-0.0001)<Floor_F,-(Cost_k*Ubar_a+Delay_D)*(1-EXP(-Rho_a*LN((Cap_top-(A43-0.0001))/(Cap_top-Floor_F))/Delta_a))/Rho_a+EXP(-Rho_a*LN((Cap_top-(A43-0.0001))/(Cap_top-Floor_F))/Delta_a)*(-Cost_k*Delta_a*Floor_F/Rho_a),EXP(-Rho_a*LN((A43-0.0001)/Floor_F)/Delta_a)*(-Cost_k*Delta_a*Floor_F/Rho_a)))/(2*0.0001) -> 3.9649411
A44: 55.5 | B44: =-IF(A44<Floor_F,-(Cost_k*Ubar_a+Delay_D)*(1-EXP(-Rho_a*LN((Cap_top-A44)/(Cap_top-Floor_F))/Delta_a))/Rho_a+EXP(-Rho_a*LN((Cap_top-A44)/(Cap_top-Floor_F))/Delta_a)*(-Cost_k*Delta_a*Floor_F/Rho_a),EXP(-Rho_a*LN(A44/Floor_F)/Delta_a)*(-Cost_k*Delta_a*Floor_F/Rho_a)) -> 231.77711 | C44: =IF(A44<Floor_F,EXP(-Rho_a*LN((Cap_top-A44)/(Cap_top-Floor_F))/Delta_a)*(Cost_k*Ubar_a+Delay_D+Rho_a*(-Cost_k*Delta_a*Floor_F/Rho_a))/(Ubar_a-Delta_a*A44),IF(A44=Floor_F,Cost_k,EXP(-Rho_a*LN(A44/Floor_F)/Delta_a)*(-Rho_a*(-Cost_k*Delta_a*Floor_F/Rho_a))/(Delta_a*A44))) -> 3.9303457 | D44: =(IF((A44+0.0001)<Floor_F,-(Cost_k*Ubar_a+Delay_D)*(1-EXP(-Rho_a*LN((Cap_top-(A44+0.0001))/(Cap_top-Floor_F))/Delta_a))/Rho_a+EXP(-Rho_a*LN((Cap_top-(A44+0.0001))/(Cap_top-Floor_F))/Delta_a)*(-Cost_k*Delta_a*Floor_F/Rho_a),EXP(-Rho_a*LN((A44+0.0001)/Floor_F)/Delta_a)*(-Cost_k*Delta_a*Floor_F/Rho_a))-IF((A44-0.0001)<Floor_F,-(Cost_k*Ubar_a+Delay_D)*(1-EXP(-Rho_a*LN((Cap_top-(A44-0.0001))/(Cap_top-Floor_F))/Delta_a))/Rho_a+EXP(-Rho_a*LN((Cap_top-(A44-0.0001))/(Cap_top-Floor_F))/Delta_a)*(-Cost_k*Delta_a*Floor_F/Rho_a),EXP(-Rho_a*LN((A44-0.0001)/Floor_F)/Delta_a)*(-Cost_k*Delta_a*Floor_F/Rho_a)))/(2*0.0001) -> 3.9303457
A45: 55.75 | B45: =-IF(A45<Floor_F,-(Cost_k*Ubar_a+Delay_D)*(1-EXP(-Rho_a*LN((Cap_top-A45)/(Cap_top-Floor_F))/Delta_a))/Rho_a+EXP(-Rho_a*LN((Cap_top-A45)/(Cap_top-Floor_F))/Delta_a)*(-Cost_k*Delta_a*Floor_F/Rho_a),EXP(-Rho_a*LN(A45/Floor_F)/Delta_a)*(-Cost_k*Delta_a*Floor_F/Rho_a)) -> 230.7988 | C45: =IF(A45<Floor_F,EXP(-Rho_a*LN((Cap_top-A45)/(Cap_top-Floor_F))/Delta_a)*(Cost_k*Ubar_a+Delay_D+Rho_a*(-Cost_k*Delta_a*Floor_F/Rho_a))/(Ubar_a-Delta_a*A45),IF(A45=Floor_F,Cost_k,EXP(-Rho_a*LN(A45/Floor_F)/Delta_a)*(-Rho_a*(-Cost_k*Delta_a*Floor_F/Rho_a))/(Delta_a*A45))) -> 3.8962056 | D45: =(IF((A45+0.0001)<Floor_F,-(Cost_k*Ubar_a+Delay_D)*(1-EXP(-Rho_a*LN((Cap_top-(A45+0.0001))/(Cap_top-Floor_F))/Delta_a))/Rho_a+EXP(-Rho_a*LN((Cap_top-(A45+0.0001))/(Cap_top-Floor_F))/Delta_a)*(-Cost_k*Delta_a*Floor_F/Rho_a),EXP(-Rho_a*LN((A45+0.0001)/Floor_F)/Delta_a)*(-Cost_k*Delta_a*Floor_F/Rho_a))-IF((A45-0.0001)<Floor_F,-(Cost_k*Ubar_a+Delay_D)*(1-EXP(-Rho_a*LN((Cap_top-(A45-0.0001))/(Cap_top-Floor_F))/Delta_a))/Rho_a+EXP(-Rho_a*LN((Cap_top-(A45-0.0001))/(Cap_top-Floor_F))/Delta_a)*(-Cost_k*Delta_a*Floor_F/Rho_a),EXP(-Rho_a*LN((A45-0.0001)/Floor_F)/Delta_a)*(-Cost_k*Delta_a*Floor_F/Rho_a)))/(2*0.0001) -> 3.8962056
A46: 56 | B46: =-IF(A46<Floor_F,-(Cost_k*Ubar_a+Delay_D)*(1-EXP(-Rho_a*LN((Cap_top-A46)/(Cap_top-Floor_F))/Delta_a))/Rho_a+EXP(-Rho_a*LN((Cap_top-A46)/(Cap_top-Floor_F))/Delta_a)*(-Cost_k*Delta_a*Floor_F/Rho_a),EXP(-Rho_a*LN(A46/Floor_F)/Delta_a)*(-Cost_k*Delta_a*Floor_F/Rho_a)) -> 229.82897 | C46: =IF(A46<Floor_F,EXP(-Rho_a*LN((Cap_top-A46)/(Cap_top-Floor_F))/Delta_a)*(Cost_k*Ubar_a+Delay_D+Rho_a*(-Cost_k*Delta_a*Floor_F/Rho_a))/(Ubar_a-Delta_a*A46),IF(A46=Floor_F,Cost_k,EXP(-Rho_a*LN(A46/Floor_F)/Delta_a)*(-Rho_a*(-Cost_k*Delta_a*Floor_F/Rho_a))/(Delta_a*A46))) -> 3.8625128 | D46: =(IF((A46+0.0001)<Floor_F,-(Cost_k*Ubar_a+Delay_D)*(1-EXP(-Rho_a*LN((Cap_top-(A46+0.0001))/(Cap_top-Floor_F))/Delta_a))/Rho_a+EXP(-Rho_a*LN((Cap_top-(A46+0.0001))/(Cap_top-Floor_F))/Delta_a)*(-Cost_k*Delta_a*Floor_F/Rho_a),EXP(-Rho_a*LN((A46+0.0001)/Floor_F)/Delta_a)*(-Cost_k*Delta_a*Floor_F/Rho_a))-IF((A46-0.0001)<Floor_F,-(Cost_k*Ubar_a+Delay_D)*(1-EXP(-Rho_a*LN((Cap_top-(A46-0.0001))/(Cap_top-Floor_F))/Delta_a))/Rho_a+EXP(-Rho_a*LN((Cap_top-(A46-0.0001))/(Cap_top-Floor_F))/Delta_a)*(-Cost_k*Delta_a*Floor_F/Rho_a),EXP(-Rho_a*LN((A46-0.0001)/Floor_F)/Delta_a)*(-Cost_k*Delta_a*Floor_F/Rho_a)))/(2*0.0001) -> 3.8625128
A47: 56.25 | B47: =-IF(A47<Floor_F,-(Cost_k*Ubar_a+Delay_D)*(1-EXP(-Rho_a*LN((Cap_top-A47)/(Cap_top-Floor_F))/Delta_a))/Rho_a+EXP(-Rho_a*LN((Cap_top-A47)/(Cap_top-Floor_F))/Delta_a)*(-Cost_k*Delta_a*Floor_F/Rho_a),EXP(-Rho_a*LN(A47/Floor_F)/Delta_a)*(-Cost_k*Delta_a*Floor_F/Rho_a)) -> 228.8675 | C47: =IF(A47<Floor_F,EXP(-Rho_a*LN((Cap_top-A47)/(Cap_top-Floor_F))/Delta_a)*(Cost_k*Ubar_a+Delay_D+Rho_a*(-Cost_k*Delta_a*Floor_F/Rho_a))/(Ubar_a-Delta_a*A47),IF(A47=Floor_F,Cost_k,EXP(-Rho_a*LN(A47/Floor_F)/Delta_a)*(-Rho_a*(-Cost_k*Delta_a*Floor_F/Rho_a))/(Delta_a*A47))) -> 3.8292595 | D47: =(IF((A47+0.0001)<Floor_F,-(Cost_k*Ubar_a+Delay_D)*(1-EXP(-Rho_a*LN((Cap_top-(A47+0.0001))/(Cap_top-Floor_F))/Delta_a))/Rho_a+EXP(-Rho_a*LN((Cap_top-(A47+0.0001))/(Cap_top-Floor_F))/Delta_a)*(-Cost_k*Delta_a*Floor_F/Rho_a),EXP(-Rho_a*LN((A47+0.0001)/Floor_F)/Delta_a)*(-Cost_k*Delta_a*Floor_F/Rho_a))-IF((A47-0.0001)<Floor_F,-(Cost_k*Ubar_a+Delay_D)*(1-EXP(-Rho_a*LN((Cap_top-(A47-0.0001))/(Cap_top-Floor_F))/Delta_a))/Rho_a+EXP(-Rho_a*LN((Cap_top-(A47-0.0001))/(Cap_top-Floor_F))/Delta_a)*(-Cost_k*Delta_a*Floor_F/Rho_a),EXP(-Rho_a*LN((A47-0.0001)/Floor_F)/Delta_a)*(-Cost_k*Delta_a*Floor_F/Rho_a)))/(2*0.0001) -> 3.8292595
A48: 56.5 | B48: =-IF(A48<Floor_F,-(Cost_k*Ubar_a+Delay_D)*(1-EXP(-Rho_a*LN((Cap_top-A48)/(Cap_top-Floor_F))/Delta_a))/Rho_a+EXP(-Rho_a*LN((Cap_top-A48)/(Cap_top-Floor_F))/Delta_a)*(-Cost_k*Delta_a*Floor_F/Rho_a),EXP(-Rho_a*LN(A48/Floor_F)/Delta_a)*(-Cost_k*Delta_a*Floor_F/Rho_a)) -> 227.9143 | C48: =IF(A48<Floor_F,EXP(-Rho_a*LN((Cap_top-A48)/(Cap_top-Floor_F))/Delta_a)*(Cost_k*Ubar_a+Delay_D+Rho_a*(-Cost_k*Delta_a*Floor_F/Rho_a))/(Ubar_a-Delta_a*A48),IF(A48=Floor_F,Cost_k,EXP(-Rho_a*LN(A48/Floor_F)/Delta_a)*(-Rho_a*(-Cost_k*Delta_a*Floor_F/Rho_a))/(Delta_a*A48))) -> 3.7964381 | D48: =(IF((A48+0.0001)<Floor_F,-(Cost_k*Ubar_a+Delay_D)*(1-EXP(-Rho_a*LN((Cap_top-(A48+0.0001))/(Cap_top-Floor_F))/Delta_a))/Rho_a+EXP(-Rho_a*LN((Cap_top-(A48+0.0001))/(Cap_top-Floor_F))/Delta_a)*(-Cost_k*Delta_a*Floor_F/Rho_a),EXP(-Rho_a*LN((A48+0.0001)/Floor_F)/Delta_a)*(-Cost_k*Delta_a*Floor_F/Rho_a))-IF((A48-0.0001)<Floor_F,-(Cost_k*Ubar_a+Delay_D)*(1-EXP(-Rho_a*LN((Cap_top-(A48-0.0001))/(Cap_top-Floor_F))/Delta_a))/Rho_a+EXP(-Rho_a*LN((Cap_top-(A48-0.0001))/(Cap_top-Floor_F))/Delta_a)*(-Cost_k*Delta_a*Floor_F/Rho_a),EXP(-Rho_a*LN((A48-0.0001)/Floor_F)/Delta_a)*(-Cost_k*Delta_a*Floor_F/Rho_a)))/(2*0.0001) -> 3.7964381
A49: 56.75 | B49: =-IF(A49<Floor_F,-(Cost_k*Ubar_a+Delay_D)*(1-EXP(-Rho_a*LN((Cap_top-A49)/(Cap_top-Floor_F))/Delta_a))/Rho_a+EXP(-Rho_a*LN((Cap_top-A49)/(Cap_top-Floor_F))/Delta_a)*(-Cost_k*Delta_a*Floor_F/Rho_a),EXP(-Rho_a*LN(A49/Floor_F)/Delta_a)*(-Cost_k*Delta_a*Floor_F/Rho_a)) -> 226.96925 | C49: =IF(A49<Floor_F,EXP(-Rho_a*LN((Cap_top-A49)/(Cap_top-Floor_F))/Delta_a)*(Cost_k*Ubar_a+Delay_D+Rho_a*(-Cost_k*Delta_a*Floor_F/Rho_a))/(Ubar_a-Delta_a*A49),IF(A49=Floor_F,Cost_k,EXP(-Rho_a*LN(A49/Floor_F)/Delta_a)*(-Rho_a*(-Cost_k*Delta_a*Floor_F/Rho_a))/(Delta_a*A49))) -> 3.7640411 | D49: =(IF((A49+0.0001)<Floor_F,-(Cost_k*Ubar_a+Delay_D)*(1-EXP(-Rho_a*LN((Cap_top-(A49+0.0001))/(Cap_top-Floor_F))/Delta_a))/Rho_a+EXP(-Rho_a*LN((Cap_top-(A49+0.0001))/(Cap_top-Floor_F))/Delta_a)*(-Cost_k*Delta_a*Floor_F/Rho_a),EXP(-Rho_a*LN((A49+0.0001)/Floor_F)/Delta_a)*(-Cost_k*Delta_a*Floor_F/Rho_a))-IF((A49-0.0001)<Floor_F,-(Cost_k*Ubar_a+Delay_D)*(1-EXP(-Rho_a*LN((Cap_top-(A49-0.0001))/(Cap_top-Floor_F))/Delta_a))/Rho_a+EXP(-Rho_a*LN((Cap_top-(A49-0.0001))/(Cap_top-Floor_F))/Delta_a)*(-Cost_k*Delta_a*Floor_F/Rho_a),EXP(-Rho_a*LN((A49-0.0001)/Floor_F)/Delta_a)*(-Cost_k*Delta_a*Floor_F/Rho_a)))/(2*0.0001) -> 3.7640411
A50: 57 | B50: =-IF(A50<Floor_F,-(Cost_k*Ubar_a+Delay_D)*(1-EXP(-Rho_a*LN((Cap_top-A50)/(Cap_top-Floor_F))/Delta_a))/Rho_a+EXP(-Rho_a*LN((Cap_top-A50)/(Cap_top-Floor_F))/Delta_a)*(-Cost_k*Delta_a*Floor_F/Rho_a),EXP(-Rho_a*LN(A50/Floor_F)/Delta_a)*(-Cost_k*Delta_a*Floor_F/Rho_a)) -> 226.03225 | C50: =IF(A50<Floor_F,EXP(-Rho_a*LN((Cap_top-A50)/(Cap_top-Floor_F))/Delta_a)*(Cost_k*Ubar_a+Delay_D+Rho_a*(-Cost_k*Delta_a*Floor_F/Rho_a))/(Ubar_a-Delta_a*A50),IF(A50=Floor_F,Cost_k,EXP(-Rho_a*LN(A50/Floor_F)/Delta_a)*(-Rho_a*(-Cost_k*Delta_a*Floor_F/Rho_a))/(Delta_a*A50))) -> 3.7320611 | D50: =(IF((A50+0.0001)<Floor_F,-(Cost_k*Ubar_a+Delay_D)*(1-EXP(-Rho_a*LN((Cap_top-(A50+0.0001))/(Cap_top-Floor_F))/Delta_a))/Rho_a+EXP(-Rho_a*LN((Cap_top-(A50+0.0001))/(Cap_top-Floor_F))/Delta_a)*(-Cost_k*Delta_a*Floor_F/Rho_a),EXP(-Rho_a*LN((A50+0.0001)/Floor_F)/Delta_a)*(-Cost_k*Delta_a*Floor_F/Rho_a))-IF((A50-0.0001)<Floor_F,-(Cost_k*Ubar_a+Delay_D)*(1-EXP(-Rho_a*LN((Cap_top-(A50-0.0001))/(Cap_top-Floor_F))/Delta_a))/Rho_a+EXP(-Rho_a*LN((Cap_top-(A50-0.0001))/(Cap_top-Floor_F))/Delta_a)*(-Cost_k*Delta_a*Floor_F/Rho_a),EXP(-Rho_a*LN((A50-0.0001)/Floor_F)/Delta_a)*(-Cost_k*Delta_a*Floor_F/Rho_a)))/(2*0.0001) -> 3.7320611
A51: 57.25 | B51: =-IF(A51<Floor_F,-(Cost_k*Ubar_a+Delay_D)*(1-EXP(-Rho_a*LN((Cap_top-A51)/(Cap_top-Floor_F))/Delta_a))/Rho_a+EXP(-Rho_a*LN((Cap_top-A51)/(Cap_top-Floor_F))/Delta_a)*(-Cost_k*Delta_a*Floor_F/Rho_a),EXP(-Rho_a*LN(A51/Floor_F)/Delta_a)*(-Cost_k*Delta_a*Floor_F/Rho_a)) -> 225.10319 | C51: =IF(A51<Floor_F,EXP(-Rho_a*LN((Cap_top-A51)/(Cap_top-Floor_F))/Delta_a)*(Cost_k*Ubar_a+Delay_D+Rho_a*(-Cost_k*Delta_a*Floor_F/Rho_a))/(Ubar_a-Delta_a*A51),IF(A51=Floor_F,Cost_k,EXP(-Rho_a*LN(A51/Floor_F)/Delta_a)*(-Rho_a*(-Cost_k*Delta_a*Floor_F/Rho_a))/(Delta_a*A51))) -> 3.7004909 | D51: =(IF((A51+0.0001)<Floor_F,-(Cost_k*Ubar_a+Delay_D)*(1-EXP(-Rho_a*LN((Cap_top-(A51+0.0001))/(Cap_top-Floor_F))/Delta_a))/Rho_a+EXP(-Rho_a*LN((Cap_top-(A51+0.0001))/(Cap_top-Floor_F))/Delta_a)*(-Cost_k*Delta_a*Floor_F/Rho_a),EXP(-Rho_a*LN((A51+0.0001)/Floor_F)/Delta_a)*(-Cost_k*Delta_a*Floor_F/Rho_a))-IF((A51-0.0001)<Floor_F,-(Cost_k*Ubar_a+Delay_D)*(1-EXP(-Rho_a*LN((Cap_top-(A51-0.0001))/(Cap_top-Floor_F))/Delta_a))/Rho_a+EXP(-Rho_a*LN((Cap_top-(A51-0.0001))/(Cap_top-Floor_F))/Delta_a)*(-Cost_k*Delta_a*Floor_F/Rho_a),EXP(-Rho_a*LN((A51-0.0001)/Floor_F)/Delta_a)*(-Cost_k*Delta_a*Floor_F/Rho_a)))/(2*0.0001) -> 3.7004909
...

Sheet Hamiltonian
A1: Read the Hamiltonian: hire at the cap, nothing, or the rent (AXIOM Lab 2.6, step 2; Theorem 6.2; Figure 6.1(b))
A2: H = -4u - 32 1{c < 55} + m(u - delta c): the value earned now plus the value banked. Hiring moves only (m - 4)u, so the switching function m - 4 decides: the cap above 0, nothing below, any rate at 0.
A4: Where | B4: Price m | C4: Switching function m - 4 | D4: Best hiring | E4: Best rate on the grid
A5: At 53, team gone | B5: =Prices!C4 -> 10.129671 | C5: =B5-Cost_k -> 6.1296707 | D5: =IF(C5>0.000000001,"the cap",IF(C5<-0.000000001,"nothing","any rate: the rent")) -> the cap | E5: =INDEX($A$10:$A$31,MATCH(MAX(B10:B31),B10:B31,0)) -> 10.127123
A6: On the floor, build running | B6: =Cost_k -> 4 | C6: =B6-Cost_k -> 0 | D6: =IF(C6>0.000000001,"the cap",IF(C6<-0.000000001,"nothing","any rate: the rent")) -> any rate: the rent | E6: =INDEX($A$10:$A$31,MATCH(MAX(C10:C31),C10:C31,0)) -> 0
A7: At 58, team kept | B7: =Prices!C9 -> 3.6081706 | C7: =B7-Cost_k -> -0.39182944 | D7: =IF(C7>0.000000001,"the cap",IF(C7<-0.000000001,"nothing","any rate: the rent")) -> nothing | E7: =INDEX($A$10:$A$31,MATCH(MAX(D10:D31),D10:D31,0)) -> 0
A9: Hiring u (points a year) | B9: (m - 4)u at 53 | C9: (m - 4)u on the floor | D9: (m - 4)u at 58
A10: 0 | B10: =($B$5-Cost_k)*$A10 -> 0 | C10: =($B$6-Cost_k)*$A10 -> 0 | D10: =($B$7-Cost_k)*$A10 -> 0
A11: 0.5 | B11: =($B$5-Cost_k)*$A11 -> 3.0648354 | C11: =($B$6-Cost_k)*$A11 -> 0 | D11: =($B$7-Cost_k)*$A11 -> -0.19591472
A12: 1 | B12: =($B$5-Cost_k)*$A12 -> 6.1296707 | C12: =($B$6-Cost_k)*$A12 -> 0 | D12: =($B$7-Cost_k)*$A12 -> -0.39182944
A13: 1.5 | B13: =($B$5-Cost_k)*$A13 -> 9.1945061 | C13: =($B$6-Cost_k)*$A13 -> 0 | D13: =($B$7-Cost_k)*$A13 -> -0.58774416
A14: 2 | B14: =($B$5-Cost_k)*$A14 -> 12.259341 | C14: =($B$6-Cost_k)*$A14 -> 0 | D14: =($B$7-Cost_k)*$A14 -> -0.78365888
A15: 2.5 | B15: =($B$5-Cost_k)*$A15 -> 15.324177 | C15: =($B$6-Cost_k)*$A15 -> 0 | D15: =($B$7-Cost_k)*$A15 -> -0.9795736
A16: 3 | B16: =($B$5-Cost_k)*$A16 -> 18.389012 | C16: =($B$6-Cost_k)*$A16 -> 0 | D16: =($B$7-Cost_k)*$A16 -> -1.1754883
A17: 3.5 | B17: =($B$5-Cost_k)*$A17 -> 21.453848 | C17: =($B$6-Cost_k)*$A17 -> 0 | D17: =($B$7-Cost_k)*$A17 -> -1.371403
A18: 4 | B18: =($B$5-Cost_k)*$A18 -> 24.518683 | C18: =($B$6-Cost_k)*$A18 -> 0 | D18: =($B$7-Cost_k)*$A18 -> -1.5673178
A19: 4.5 | B19: =($B$5-Cost_k)*$A19 -> 27.583518 | C19: =($B$6-Cost_k)*$A19 -> 0 | D19: =($B$7-Cost_k)*$A19 -> -1.7632325
A20: 5 | B20: =($B$5-Cost_k)*$A20 -> 30.648354 | C20: =($B$6-Cost_k)*$A20 -> 0 | D20: =($B$7-Cost_k)*$A20 -> -1.9591472
A21: 5.5 | B21: =($B$5-Cost_k)*$A21 -> 33.713189 | C21: =($B$6-Cost_k)*$A21 -> 0 | D21: =($B$7-Cost_k)*$A21 -> -2.1550619
... A30: 10 | B30: =($B$5-Cost_k)*$A30 -> 61.296707 | C30: =($B$6-Cost_k)*$A30 -> 0 | D30: =($B$7-Cost_k)*$A30 -> -3.9182944
A31: =Ubar_a -> 10.127123 | B31: =($B$5-Cost_k)*$A31 -> 62.075931 | C31: =($B$6-Cost_k)*$A31 -> 0 | D31: =($B$7-Cost_k)*$A31 -> -3.968105
A34: Quarter | B34: Years | C34: Gone: capability | D34: Gone: price | E34: Gone: m - 4 | F34: Gone: hiring | G34: Gone: max H | H34: Gone: rho V(c) | I34: Gone: |max H - rho V| | J34: Kept: capability | K34: Kept: price | L34: Kept: m - 4 | M34: Kept: hiring | N34: Kept: max H | O34: Kept: rho V(c) | P34: Kept: |max H - rho V|
A35: 0 | B35: =A35/4 -> 0 | C35: =IF(B35<Tau_race,Cap_top-(Cap_top-C_gone)*EXP(-Delta_a*B35),Floor_F) -> 53 | D35: =IF(B35<Tau_race,IF(C35<Floor_F,EXP(-Rho_a*LN((Cap_top-C35)/(Cap_top-Floor_F))/Delta_a)*(Cost_k*Ubar_a+Delay_D+Rho_a*(-Cost_k*Delta_a*Floor_F/Rho_a))/(Ubar_a-Delta_a*C35),IF(C35=Floor_F,Cost_k,EXP(-Rho_a*LN(C35/Floor_F)/Delta_a)*(-Rho_a*(-Cost_k*Delta_a*Floor_F/Rho_a))/(Delta_a*C35))),Cost_k) -> 10.129671 | E35: =D35-Cost_k -> 6.1296707 | F35: =IF(E35>0.000000001,Ubar_a,IF(E35<-0.000000001,0,Delta_a*Floor_F)) -> 10.127123 | G35: =MAX(-Delay_D*IF(B35<Tau_race,1,0)-D35*Delta_a*C35,-Cost_k*Ubar_a-Delay_D*IF(B35<Tau_race,1,0)+D35*(Ubar_a-Delta_a*C35)) -> -24.293814 | H35: =Rho_a*IF(B35<Tau_race,IF(C35<Floor_F,-(Cost_k*Ubar_a+Delay_D)*(1-EXP(-Rho_a*LN((Cap_top-C35)/(Cap_top-Floor_F))/Delta_a))/Rho_a+EXP(-Rho_a*LN((Cap_top-C35)/(Cap_top-Floor_F))/Delta_a)*(-Cost_k*Delta_a*Floor_F/Rho_a),EXP(-Rho_a*LN(C35/Floor_F)/Delta_a)*(-Cost_k*Delta_a*Floor_F/Rho_a)),V_F) -> -24.293814 | I35: =ABS(G35-H35) -> 0 | J35: =IF(B35<Tau_drift,C_kept*EXP(-Delta_a*B35),Floor_F) -> 58 | K35: =IF(B35<Tau_drift,IF(J35<Floor_F,EXP(-Rho_a*LN((Cap_top-J35)/(Cap_top-Floor_F))/Delta_a)*(Cost_k*Ubar_a+Delay_D+Rho_a*(-Cost_k*Delta_a*Floor_F/Rho_a))/(Ubar_a-Delta_a*J35),IF(J35=Floor_F,Cost_k,EXP(-Rho_a*LN(J35/Floor_F)/Delta_a)*(-Rho_a*(-Cost_k*Delta_a*Floor_F/Rho_a))/(Delta_a*J35))),Cost_k) -> 3.6081706 | L35: =K35-Cost_k -> -0.39182944 | M35: =IF(L35>0.000000001,Ubar_a,IF(L35<-0.000000001,0,Delta_a*Floor_F)) -> 0 | N35: =MAX(-Delay_D*0-K35*Delta_a*J35,-Cost_k*Ubar_a-Delay_D*0+K35*(Ubar_a-Delta_a*J35)) -> -21.193425 | O35: =Rho_a*IF(B35<Tau_drift,IF(J35<Floor_F,-(Cost_k*Ubar_a+Delay_D)*(1-EXP(-Rho_a*LN((Cap_top-J35)/(Cap_top-Floor_F))/Delta_a))/Rho_a+EXP(-Rho_a*LN((Cap_top-J35)/(Cap_top-Floor_F))/Delta_a)*(-Cost_k*Delta_a*Floor_F/Rho_a),EXP(-Rho_a*LN(J35/Floor_F)/Delta_a)*(-Cost_k*Delta_a*Floor_F/Rho_a)),V_F) -> -21.193425 | P35: =ABS(N35-O35) -> 0
A36: 0.5 | B36: =A36/4 -> 0.125 | C36: =IF(B36<Tau_race,Cap_top-(Cap_top-C_gone)*EXP(-Delta_a*B36),Floor_F) -> 53.591219 | D36: =IF(B36<Tau_race,IF(C36<Floor_F,EXP(-Rho_a*LN((Cap_top-C36)/(Cap_top-Floor_F))/Delta_a)*(Cost_k*Ubar_a+Delay_D+Rho_a*(-Cost_k*Delta_a*Floor_F/Rho_a))/(Ubar_a-Delta_a*C36),IF(C36=Floor_F,Cost_k,EXP(-Rho_a*LN(C36/Floor_F)/Delta_a)*(-Rho_a*(-Cost_k*Delta_a*Floor_F/Rho_a))/(Delta_a*C36))),Cost_k) -> 10.381667 | E36: =D36-Cost_k -> 6.3816673 | F36: =IF(E36>0.000000001,Ubar_a,IF(E36<-0.000000001,0,Delta_a*Floor_F)) -> 10.127123 | G36: =MAX(-Delay_D*IF(B36<Tau_race,1,0)-D36*Delta_a*C36,-Cost_k*Ubar_a-Delay_D*IF(B36<Tau_race,1,0)+D36*(Ubar_a-Delta_a*C36)) -> -23.71596 | H36: =Rho_a*IF(B36<Tau_race,IF(C36<Floor_F,-(Cost_k*Ubar_a+Delay_D)*(1-EXP(-Rho_a*LN((Cap_top-C36)/(Cap_top-Floor_F))/Delta_a))/Rho_a+EXP(-Rho_a*LN((Cap_top-C36)/(Cap_top-Floor_F))/Delta_a)*(-Cost_k*Delta_a*Floor_F/Rho_a),EXP(-Rho_a*LN(C36/Floor_F)/Delta_a)*(-Cost_k*Delta_a*Floor_F/Rho_a)),V_F) -> -23.71596 | I36: =ABS(G36-H36) -> 0 | J36: =IF(B36<Tau_drift,C_kept*EXP(-Delta_a*B36),Floor_F) -> 57.270411 | K36: =IF(B36<Tau_drift,IF(J36<Floor_F,EXP(-Rho_a*LN((Cap_top-J36)/(Cap_top-Floor_F))/Delta_a)*(Cost_k*Ubar_a+Delay_D+Rho_a*(-Cost_k*Delta_a*Floor_F/Rho_a))/(Ubar_a-Delta_a*J36),IF(J36=Floor_F,Cost_k,EXP(-Rho_a*LN(J36/Floor_F)/Delta_a)*(-Rho_a*(-Cost_k*Delta_a*Floor_F/Rho_a))/(Delta_a*J36))),Cost_k) -> 3.6979313 | L36: =K36-Cost_k -> -0.30206872 | M36: =IF(L36>0.000000001,Ubar_a,IF(L36<-0.000000001,0,Delta_a*Floor_F)) -> 0 | N36: =MAX(-Delay_D*0-K36*Delta_a*J36,-Cost_k*Ubar_a-Delay_D*0+K36*(Ubar_a-Delta_a*J36)) -> -21.447429 | O36: =Rho_a*IF(B36<Tau_drift,IF(J36<Floor_F,-(Cost_k*Ubar_a+Delay_D)*(1-EXP(-Rho_a*LN((Cap_top-J36)/(Cap_top-Floor_F))/Delta_a))/Rho_a+EXP(-Rho_a*LN((Cap_top-J36)/(Cap_top-Floor_F))/Delta_a)*(-Cost_k*Delta_a*Floor_F/Rho_a),EXP(-Rho_a*LN(J36/Floor_F)/Delta_a)*(-Cost_k*Delta_a*Floor_F/Rho_a)),V_F) -> -21.447429 | P36: =ABS(N36-O36) -> 0
A37: 1 | B37: =A37/4 -> 0.25 | C37: =IF(B37<Tau_race,Cap_top-(Cap_top-C_gone)*EXP(-Delta_a*B37),Floor_F) -> 54.175 | D37: =IF(B37<Tau_race,IF(C37<Floor_F,EXP(-Rho_a*LN((Cap_top-C37)/(Cap_top-Floor_F))/Delta_a)*(Cost_k*Ubar_a+Delay_D+Rho_a*(-Cost_k*Delta_a*Floor_F/Rho_a))/(Ubar_a-Delta_a*C37),IF(C37=Floor_F,Cost_k,EXP(-Rho_a*LN(C37/Floor_F)/Delta_a)*(-Rho_a*(-Cost_k*Delta_a*Floor_F/Rho_a))/(Delta_a*C37))),Cost_k) -> 10.639933 | E37: =D37-Cost_k -> 6.6399328 | F37: =IF(E37>0.000000001,Ubar_a,IF(E37<-0.000000001,0,Delta_a*Floor_F)) -> 10.127123 | G37: =MAX(-Delay_D*IF(B37<Tau_race,1,0)-D37*Delta_a*C37,-Cost_k*Ubar_a-Delay_D*IF(B37<Tau_race,1,0)+D37*(Ubar_a-Delta_a*C37)) -> -23.13118 | H37: =Rho_a*IF(B37<Tau_race,IF(C37<Floor_F,-(Cost_k*Ubar_a+Delay_D)*(1-EXP(-Rho_a*LN((Cap_top-C37)/(Cap_top-Floor_F))/Delta_a))/Rho_a+EXP(-Rho_a*LN((Cap_top-C37)/(Cap_top-Floor_F))/Delta_a)*(-Cost_k*Delta_a*Floor_F/Rho_a),EXP(-Rho_a*LN(C37/Floor_F)/Delta_a)*(-Cost_k*Delta_a*Floor_F/Rho_a)),V_F) -> -23.13118 | I37: =ABS(G37-H37) -> 0 | J37: =IF(B37<Tau_drift,C_kept*EXP(-Delta_a*B37),Floor_F) -> 56.55 | K37: =IF(B37<Tau_drift,IF(J37<Floor_F,EXP(-Rho_a*LN((Cap_top-J37)/(Cap_top-Floor_F))/Delta_a)*(Cost_k*Ubar_a+Delay_D+Rho_a*(-Cost_k*Delta_a*Floor_F/Rho_a))/(Ubar_a-Delta_a*J37),IF(J37=Floor_F,Cost_k,EXP(-Rho_a*LN(J37/Floor_F)/Delta_a)*(-Rho_a*(-Cost_k*Delta_a*Floor_F/Rho_a))/(Delta_a*J37))),Cost_k) -> 3.789925 | L37: =K37-Cost_k -> -0.21007501 | M37: =IF(L37>0.000000001,Ubar_a,IF(L37<-0.000000001,0,Delta_a*Floor_F)) -> 0 | N37: =MAX(-Delay_D*0-K37*Delta_a*J37,-Cost_k*Ubar_a-Delay_D*0+K37*(Ubar_a-Delta_a*J37)) -> -21.704477 | O37: =Rho_a*IF(B37<Tau_drift,IF(J37<Floor_F,-(Cost_k*Ubar_a+Delay_D)*(1-EXP(-Rho_a*LN((Cap_top-J37)/(Cap_top-Floor_F))/Delta_a))/Rho_a+EXP(-Rho_a*LN((Cap_top-J37)/(Cap_top-Floor_F))/Delta_a)*(-Cost_k*Delta_a*Floor_F/Rho_a),EXP(-Rho_a*LN(J37/Floor_F)/Delta_a)*(-Cost_k*Delta_a*Floor_F/Rho_a)),V_F) -> -21.704477 | P37: =ABS(N37-O37) -> 0
