Workbook

Sheet README
B1: DCT Laboratory — Vol II, Ch 13: Machine Learning for Enterprise Transformation
B2: Seed 26213 · Companion to DCT_V2_Ch13_Lab.ipynb and AXIOM Lab 2.13 (module AXIOM-13). Money in $ million.
B4: Worked Example 13.1, Is the Market Desk's Warning Worth Paying For?, with the book's declarations: Chapter 9's law, levers and floor on its 100,000 book paths (seed 8) and 100,000 fresh paths (seed 26209); the market desk's five readings and its record of 1,000 windows (seed 1300); the book paths' readings (seed 1309) and the fresh paths' (seed 26213, the lab's); two packages, one for warning and one for all clear, with the 5 percent appetite counted over both; the audit committee's one-sided 95 percent confidence.
B5: Declarations: the levers and their prices, Volume I's package, the readings' loadings and shifts, the seeds.
B6: Record: the desk's record, its means and variances, and the subsets' shares of the variance (step 1).
B7: Law: the readings' covariance, the declared law's coefficients Sigma^-1 s, the separation and the AUC, the ceiling's split of programs and a threshold to try, the value against the AUC, and subsets (Step 1; Figure 13.1(b)).
B8: Components and Model: the record's principal components and what they keep, the fitted model's chance for any reading, and its attributions under two games (Step 5; Figure 13.3).
B9: Accuracy: confusion counts, accuracy and shares for every rule (Steps 2-4; Table 13.2).
B10: Designs and Table13_3: for every warning, the closure shares (point estimates or Clopper-Pearson bounds), the two packages and their costs, the value promised, the design's chance of a breach from the paths' breach counts, and the fresh check; Table 13.3 (Steps 1-4).
B11: Study200, Stages and Sweep: the 200 records' fresh checks, the boosting stage curve, and the logistic warning at every threshold (Figures 13.1(a) and 13.2).
B12: Examples: the appendices' small examples and calculators for the honest checks (Theorems 13.2-13.3, Proposition 13.2).
B13: Engine values (green) are what needs the simulated paths or a learner: the packages' lines and delays, breach counts, the learned coefficients and scores, the conditional attributions. Everything else is a formula.
... B20: Cross-sheet link: green.

Sheet Declarations
A1: Declarations (Worked Example 13.1, Step 1; Chapter 9's law and levers; the market desk's readings; Online Appendix Remark 13.B.1). Money in $ million.
A3: Quantity | B3: Value | C3: Source
A4: Paths: the book's (seed 8) and the fresh (seed 26209), each | B4: 100000 | C4: Chapter 9's law: 12 quarters, the $350 million floor
A5: Funding-window closures a year | B5: 0.1 | C5: Chapter 9's law
A6: Years in the program | B6: 3 | C6: Twelve quarters
A7: A closure ahead under the law, 1 - e^(-0.10 x 3) | B7: =1-EXP(-B5*B6) -> 0.25918178 | C7: 25.92 percent (Remark 13.B.1)
A8: The book's paths with a closure ahead, n1 | B8: 25912 | C8: 25.91 percent of 100,000
A9: The book's paths without, n0 | B9: =B4-B8 -> 74088
A10: The fresh paths with a closure ahead | B10: 25960 | C10: 25.96 percent of 100,000
A11: Line fees over the program, per $ of line | B11: 0.03 | C11: The treasury
A12: A quarter of committed delay ($ million) | B12: 8 | C12: The transformation office
A13: The draw's depth (index points) | B13: 28 | C13: A path survives when its critical depth is at least 28 - 4 x delay
A14: Points a quarter of delay takes off the depth | B14: 4
A15: The appetite: chance of a breach in some quarter, at most | B15: 0.05 | C15: Counted over both packages
A16: Volume I's package: line | B16: 170 | C16: Volume I, Worked Example 15.1
A17: Volume I's package: delay (quarters) | B17: 0.66757636 | C17: The least delay keeping 5 percent on the book's paths: 0.668
A18: Volume I's package: cost | B18: =B11*B16+B12*B17 -> 10.440611 | C18: $10.44 million: the value of a warning is measured from it
A19: The all-clear group's chance of a breach: grid step | B19: 0.0025 | C19: A quarter of a point ...
A20: up to | B20: 0.1 | C20: ... to 10 percent; the warned group's fills the appetite
A21: The desk's record: windows | B21: 1000 | C21: Three-year windows of comparable issuers
A22: The audit committee's confidence, one-sided | B22: 0.95 | C22: Clopper-Pearson upper bounds
A24: The market desk's five readings (standard units; Worked Example 13.1, Step 1)
A25: Reading | B25: bond | C25: high yield | D25: volatility | E25: lending | F25: funding
A26: Indicator | B26: Meridian's bond spread | C26: High-yield spread | D26: Equity volatility | E26: Banks' lending standards | F26: Bank-funding spread
A27: Loading on the common financial-conditions factor, lambda | B27: 0.9 | C27: 0.85 | D27: 0.8 | E27: 0.6 | F27: 0.3
A28: How much higher programs with a closure ahead start, s | B28: 0.25 | C28: 0.25 | D28: 0.15 | E28: 0.7 | F28: 1.9
A29: Own noise, standard deviation sqrt(1 - lambda^2) | B29: =SQRT(1-B27^2) -> 0.43588989 | C29: =SQRT(1-C27^2) -> 0.52678269 | D29: =SQRT(1-D27^2) -> 0.6 | E29: =SQRT(1-E27^2) -> 0.8 | F29: =SQRT(1-F27^2) -> 0.9539392
A30: Each program's readings: F lambda + e sqrt(1 - lambda^2) + Y s, with F and e independent standard normal and Y = 1 for a closure ahead; given Y, the readings say nothing more about the path.
A32: Seeds (Online Appendix Remark 13.B.1)
A33: Chapter 9's book paths | B33: 8 | C33: Volume I, Chapter 8's stream
A34: Chapter 9's fresh paths | B34: 26209 | C34: Chapter 9's lab seed
A35: The desk's record (also the folds' shuffle and the boosting's random state) | B35: 1300
A36: The book paths' readings | B36: 1309
A37: The fresh paths' readings: the lab's seed | B37: 26213
A38: The study's 200 records: from | B38: 913000 | C38: 913000-913199
A39: The 20,000 fresh programs of the boosting stage curve | B39: 26214

Sheet Record
A1: Read the record: the desk's 1,000 windows (AXIOM Lab 2.13, step 1; Online Appendix Example 13.B.2)
A2: The record is drawn with seed 1300 (engine values); the shares of the variance are formulas.
B3: bond | C3: high yield | D3: volatility | E3: lending | F3: funding
A4: Mean reading, windows with a closure (engine) | B4: 0.17900911 | C4: 0.29201376 | D4: 0.17173245 | E4: 0.7347812 | F4: 1.995345
A5: Mean reading, windows without (engine) | B5: -0.017115449 | C5: 0.0078875304 | D5: -0.016251553 | E5: -0.060478761 | F5: -0.016721811
A6: Mean reading, all windows (engine) | B6: 0.035445934 | C6: 0.08403336 | D6: 0.034128158 | E6: 0.15265091 | F6: 0.5225121
A7: Variance of each reading (engine; sample, n - 1) | B7: 1.0145708 | C7: 0.99535761 | D7: 0.9622865 | E7: 1.0914191 | F7: 1.7532583
A8: Share of the total variance | B8: =B7/SUM($B$7:$F$7) -> 0.17441802 | C8: =C7/SUM($B$7:$F$7) -> 0.17111501 | D8: =D7/SUM($B$7:$F$7) -> 0.16542966 | E8: =E7/SUM($B$7:$F$7) -> 0.18762924 | F8: =F7/SUM($B$7:$F$7) -> 0.30140807
A10: Windows (engine) | B10: 1000
A11: with a closure (engine) | B11: 268 | C11: 268
A12: share | B12: =B11/B10 -> 0.268 | C12: Against 25.92 percent under the law
A13: The three market readings' share of the variance | B13: =SUM(B7:D7)/SUM(B7:F7) -> 0.51096269 | C13: 51.1 percent
A14: Lending standards and the funding spread | B14: =SUM(E7:F7)/SUM(B7:F7) -> 0.48903731 | C14: 48.9 percent
A15: The funding spread alone | B15: =F7/SUM(B7:F7) -> 0.30140807 | C15: 30.1 percent
A16: All but the funding spread | B16: =SUM(B7:E7)/SUM(B7:F7) -> 0.69859193 | C16: 69.9 percent

Sheet Law
A1: The declared law: what the five readings can tell (Theorem 13.2(iii); Online Appendix Remark 13.B.1; Worked Example 13.1, Step 1; Figure 13.1(b))
A2: Given closure or not the readings share the covariance Sigma, so the log-odds of a closure ahead is linear: beta = Sigma^-1 s; the log-likelihood ratio z = beta'x - Delta^2/2 is normal, mean +Delta^2/2 (closure ahead) or -Delta^2/2, variance Delta^2.
A4: Sigma = lambda lambda' + diag(1 - lambda^2) | B4: bond | C4: high yield | D4: volatility | E4: lending | F4: funding
A5: bond | B5: =Declarations!$B$27*Declarations!$B$27+(1-Declarations!$B$27^2) -> 1 | C5: =Declarations!$B$27*Declarations!$C$27 -> 0.765 | D5: =Declarations!$B$27*Declarations!$D$27 -> 0.72 | E5: =Declarations!$B$27*Declarations!$E$27 -> 0.54 | F5: =Declarations!$B$27*Declarations!$F$27 -> 0.27
A6: high yield | B6: =Declarations!$C$27*Declarations!$B$27 -> 0.765 | C6: =Declarations!$C$27*Declarations!$C$27+(1-Declarations!$C$27^2) -> 1 | D6: =Declarations!$C$27*Declarations!$D$27 -> 0.68 | E6: =Declarations!$C$27*Declarations!$E$27 -> 0.51 | F6: =Declarations!$C$27*Declarations!$F$27 -> 0.255
A7: volatility | B7: =Declarations!$D$27*Declarations!$B$27 -> 0.72 | C7: =Declarations!$D$27*Declarations!$C$27 -> 0.68 | D7: =Declarations!$D$27*Declarations!$D$27+(1-Declarations!$D$27^2) -> 1 | E7: =Declarations!$D$27*Declarations!$E$27 -> 0.48 | F7: =Declarations!$D$27*Declarations!$F$27 -> 0.24
A8: lending | B8: =Declarations!$E$27*Declarations!$B$27 -> 0.54 | C8: =Declarations!$E$27*Declarations!$C$27 -> 0.51 | D8: =Declarations!$E$27*Declarations!$D$27 -> 0.48 | E8: =Declarations!$E$27*Declarations!$E$27+(1-Declarations!$E$27^2) -> 1 | F8: =Declarations!$E$27*Declarations!$F$27 -> 0.18
A9: funding | B9: =Declarations!$F$27*Declarations!$B$27 -> 0.27 | C9: =Declarations!$F$27*Declarations!$C$27 -> 0.255 | D9: =Declarations!$F$27*Declarations!$D$27 -> 0.24 | E9: =Declarations!$F$27*Declarations!$E$27 -> 0.18 | F9: =Declarations!$F$27*Declarations!$F$27+(1-Declarations!$F$27^2) -> 1
A11: Sigma^-1 (MINVERSE) | B11: bond | C11: high yield | D11: volatility | E11: lending | F11: funding
A12: bond | B12: =INDEX(MINVERSE($B$5:$F$9),1,1) -> 3.0859987 | C12: =INDEX(MINVERSE($B$5:$F$9),1,2) -> -1.4078527 | D12: =INDEX(MINVERSE($B$5:$F$9),1,3) -> -1.0213833 | E12: =INDEX(MINVERSE($B$5:$F$9),1,4) -> -0.4308961 | F12: =INDEX(MINVERSE($B$5:$F$9),1,5) -> -0.1515239
A13: high yield | B13: =INDEX(MINVERSE($B$5:$F$9),2,1) -> -1.4078527 | C13: =INDEX(MINVERSE($B$5:$F$9),2,2) -> 2.6932204 | D13: =INDEX(MINVERSE($B$5:$F$9),2,3) -> -0.66047411 | E13: =INDEX(MINVERSE($B$5:$F$9),2,4) -> -0.27863752 | F13: =INDEX(MINVERSE($B$5:$F$9),2,5) -> -0.097982423
A14: volatility | B14: =INDEX(MINVERSE($B$5:$F$9),3,1) -> -1.0213833 | C14: =INDEX(MINVERSE($B$5:$F$9),3,2) -> -0.66047411 | D14: =INDEX(MINVERSE($B$5:$F$9),3,3) -> 2.2986103 | E14: =INDEX(MINVERSE($B$5:$F$9),3,4) -> -0.20214879 | F14: =INDEX(MINVERSE($B$5:$F$9),3,5) -> -0.071085287
A15: lending | B15: =INDEX(MINVERSE($B$5:$F$9),4,1) -> -0.4308961 | C15: =INDEX(MINVERSE($B$5:$F$9),4,2) -> -0.27863752 | D15: =INDEX(MINVERSE($B$5:$F$9),4,3) -> -0.20214879 | E15: =INDEX(MINVERSE($B$5:$F$9),4,4) -> 1.4772185 | F15: =INDEX(MINVERSE($B$5:$F$9),4,5) -> -0.029989106
A16: funding | B16: =INDEX(MINVERSE($B$5:$F$9),5,1) -> -0.1515239 | C16: =INDEX(MINVERSE($B$5:$F$9),5,2) -> -0.097982423 | D16: =INDEX(MINVERSE($B$5:$F$9),5,3) -> -0.071085287 | E16: =INDEX(MINVERSE($B$5:$F$9),5,4) -> -0.029989106 | F16: =INDEX(MINVERSE($B$5:$F$9),5,5) -> 1.0883555
A18: beta = Sigma^-1 s: the law's log-odds coefficients | B18: =SUMPRODUCT($B$12:$F$12,Shift) -> -0.32319369 | C18: =SUMPRODUCT($B$13:$F$13,Shift) -> -0.15894207 | D18: =SUMPRODUCT($B$14:$F$14,Shift) -> -0.35223902 | E18: =SUMPRODUCT($B$15:$F$15,Shift) -> 0.76936792 | F18: =SUMPRODUCT($B$16:$F$16,Shift) -> 1.9738437
A19: Separation Delta = (s' Sigma^-1 s)^(1/2) | B19: =SQRT(SUMPRODUCT(B18:F18,Shift)) -> 2.0286672 | C19: 2.029
A20: AUC = Phi(Delta / sqrt 2) | B20: =NORMSDIST(B19/SQRT(2)) -> 0.92428295 | C20: 0.924: the readings rank a closure above a non-closure with this chance
A22: The ceiling: the best warning reads z, a threshold splits programs (engine: the threshold, the best of 241 candidates)
A23: Threshold on z, t (engine) | B23: -1.8258005 | C23: -1.826
A24: as a multiple of Delta | B24: =B23/Delta -> -0.9 | C24: Candidates from -6 Delta to 6 Delta, step 0.05
A25: Share of the book's paths with a closure ahead, pi | B25: =NClose/NPaths -> 0.25912
A26: P(warned | closure ahead) = 1 - Phi((t - Delta^2/2) / Delta) | B26: =1-NORMSDIST((B23-Delta^2/2)/Delta) -> 0.97221123
A27: P(warned | no closure ahead) = 1 - Phi((t + Delta^2/2) / Delta) | B27: =1-NORMSDIST((B23+Delta^2/2)/Delta) -> 0.45448667
A28: Share warned | B28: =B25*B26+(1-B25)*B27 -> 0.58863946 | C28: 58.86 percent
A29: Closure share among the warned | B29: =B25*B26/B28 -> 0.42796889 | C29: 42.80 percent
A30: Closure share among the all clear | B30: =B25*(1-B26)/(1-B28) -> 0.017504417 | C30: 1.75 percent
A32: Try a threshold of your own
A33: t (input) | B33: 0 | C33: Programs with z at or above t are warned
A34: Share warned | B34: =B25*(1-NORMSDIST((B33-Delta^2/2)/Delta))+(1-B25)*(1-NORMSDIST((B33+Delta^2/2)/Delta)) -> 0.33389483
A35: Closure share among the warned | B35: =B25*(1-NORMSDIST((B33-Delta^2/2)/Delta))/B34 -> 0.6556002
A36: Closure share among the all clear | B36: =B25*NORMSDIST((B33-Delta^2/2)/Delta)/(1-B34) -> 0.060378575
A38: The most a warning is worth against its readings' AUC: all five shifts scaled (Figure 13.1(b))
A39: Shifts x | B39: Delta | C39: AUC = Phi(Delta / sqrt 2) | D39: Most a warning is worth (engine)
A40: 0.25 | B40: =A40*Delta -> 0.50716681 | C40: =NORMSDIST(B40/SQRT(2)) -> 0.64006072 | D40: 0.048700627
A41: 0.5 | B41: =A41*Delta -> 1.0143336 | C41: =NORMSDIST(B41/SQRT(2)) -> 0.76338766 | D41: 0.22069606
A42: 0.75 | B42: =A42*Delta -> 1.5215004 | C42: =NORMSDIST(B42/SQRT(2)) -> 0.85900579 | D42: 0.627713
A43: 1 | B43: =A43*Delta -> 2.0286672 | C43: =NORMSDIST(B43/SQRT(2)) -> 0.92428295 | D43: 1.4368818
A44: 1.25 | B44: =A44*Delta -> 2.535834 | C44: =NORMSDIST(B44/SQRT(2)) -> 0.96352197 | D44: 2.237414
A45: 1.5 | B45: =A45*Delta -> 3.0430008 | C45: =NORMSDIST(B45/SQRT(2)) -> 0.98429055 | D45: 2.879566
A46: 2 | B46: =A46*Delta -> 4.0573344 | C46: =NORMSDIST(B46/SQRT(2)) -> 0.99794094 | D46: 3.693467
...

Sheet Components
A1: Compress: the record's principal components and what they keep (Proposition 13.3(i)-(ii); Worked Example 13.1, Step 5; Figure 13.3(a); AXIOM Lab 2.13, step 5)
A2: A warning on the top r components reads W'x (W: the first r eigenvectors); under the declared law its separation is Delta_r = (a' M^-1 a)^(1/2), a = W's, M = W' Sigma W. Eigenvalues and eigenvectors of the record's covariance are the engine's.
B3: 1 | C3: 2 | D3: 3 | E3: 4 | F3: 5
A4: Eigenvalue (engine) | B4: 3.2546654 | C4: 1.4270853 | D4: 0.58652541 | E4: 0.32072076 | F4: 0.2278954
A5: Share of the variance kept by the top r | B5: =SUM($B$4:B4)/SUM($B$4:$F$4) -> 0.55951963 | C5: =SUM($B$4:C4)/SUM($B$4:$F$4) -> 0.80485429 | D5: =SUM($B$4:D4)/SUM($B$4:$F$4) -> 0.90568569 | E5: =SUM($B$4:E4)/SUM($B$4:$F$4) -> 0.96082179 | F5: =SUM($B$4:F4)/SUM($B$4:$F$4) -> 1
A7: Eigenvectors V, rows = readings (engine) | B7: PC1 | C7: PC2 | D7: PC3 | E7: PC4 | F7: PC5
A8: bond | B8: 0.47341258 | C8: 0.28239486 | D8: -0.17597963 | E8: -0.13043957 | F8: -0.80507786
A9: high yield | B9: 0.45991251 | C9: 0.22828417 | D9: -0.28020107 | E9: -0.62783933 | F9: 0.51348998
A10: volatility | B10: 0.43114092 | C10: 0.27780927 | D10: -0.26242783 | E10: 0.76636819 | F10: 0.28416712
A11: lending | B11: 0.43454252 | C11: 0.064080272 | D11: 0.89466421 | E11: 0.008616503 | F11: 0.081044612
A12: funding | B12: 0.43548975 | C12: -0.88704859 | D12: -0.14569187 | E12: 0.037534689 | F12: -0.029300083
A14: V' (formulas) | B14: bond | C14: high yield | D14: volatility | E14: lending | F14: funding
A15: PC1 | B15: =INDEX($B$8:$F$12,1,1) -> 0.47341258 | C15: =INDEX($B$8:$F$12,2,1) -> 0.45991251 | D15: =INDEX($B$8:$F$12,3,1) -> 0.43114092 | E15: =INDEX($B$8:$F$12,4,1) -> 0.43454252 | F15: =INDEX($B$8:$F$12,5,1) -> 0.43548975
A16: PC2 | B16: =INDEX($B$8:$F$12,1,2) -> 0.28239486 | C16: =INDEX($B$8:$F$12,2,2) -> 0.22828417 | D16: =INDEX($B$8:$F$12,3,2) -> 0.27780927 | E16: =INDEX($B$8:$F$12,4,2) -> 0.064080272 | F16: =INDEX($B$8:$F$12,5,2) -> -0.88704859
A17: PC3 | B17: =INDEX($B$8:$F$12,1,3) -> -0.17597963 | C17: =INDEX($B$8:$F$12,2,3) -> -0.28020107 | D17: =INDEX($B$8:$F$12,3,3) -> -0.26242783 | E17: =INDEX($B$8:$F$12,4,3) -> 0.89466421 | F17: =INDEX($B$8:$F$12,5,3) -> -0.14569187
A18: PC4 | B18: =INDEX($B$8:$F$12,1,4) -> -0.13043957 | C18: =INDEX($B$8:$F$12,2,4) -> -0.62783933 | D18: =INDEX($B$8:$F$12,3,4) -> 0.76636819 | E18: =INDEX($B$8:$F$12,4,4) -> 0.008616503 | F18: =INDEX($B$8:$F$12,5,4) -> 0.037534689
A19: PC5 | B19: =INDEX($B$8:$F$12,1,5) -> -0.80507786 | C19: =INDEX($B$8:$F$12,2,5) -> 0.51348998 | D19: =INDEX($B$8:$F$12,3,5) -> 0.28416712 | E19: =INDEX($B$8:$F$12,4,5) -> 0.081044612 | F19: =INDEX($B$8:$F$12,5,5) -> -0.029300083
A21: Sigma V (MMULT) | B21: PC1 | C21: PC2 | D21: PC3 | E21: PC4 | F21: PC5
A22: bond | B22: =INDEX(MMULT(Law!$B$5:$F$9,$B$8:$F$12),1,1) -> 1.4879023 | C22: =INDEX(MMULT(Law!$B$5:$F$9,$B$8:$F$12),1,2) -> 0.45215515 | D22: =INDEX(MMULT(Law!$B$5:$F$9,$B$8:$F$12),1,3) -> -0.13549961 | E22: =INDEX(MMULT(Law!$B$5:$F$9,$B$8:$F$12),1,4) -> -0.044164286 | F22: =INDEX(MMULT(Law!$B$5:$F$9,$B$8:$F$12),1,5) -> -0.17180463
A23: high yield | B23: =INDEX(MMULT(Law!$B$5:$F$9,$B$8:$F$12),2,1) -> 1.4479155 | C23: =INDEX(MMULT(Law!$B$5:$F$9,$B$8:$F$12),2,2) -> 0.43971009 | D23: =INDEX(MMULT(Law!$B$5:$F$9,$B$8:$F$12),2,3) -> -0.17414909 | E23: =INDEX(MMULT(Law!$B$5:$F$9,$B$8:$F$12),2,4) -> -0.19252947 | F23: =INDEX(MMULT(Law!$B$5:$F$9,$B$8:$F$12),2,5) -> 0.12470029
A24: volatility | B24: =INDEX(MMULT(Law!$B$5:$F$9,$B$8:$F$12),3,1) -> 1.3978364 | C24: =INDEX(MMULT(Law!$B$5:$F$9,$B$8:$F$12),3,2) -> 0.45423368 | D24: =INDEX(MMULT(Law!$B$5:$F$9,$B$8:$F$12),3,3) -> -0.18519711 | E24: =INDEX(MMULT(Law!$B$5:$F$9,$B$8:$F$12),3,4) -> 0.2586652 | F24: =INDEX(MMULT(Law!$B$5:$F$9,$B$8:$F$12),3,5) -> 0.085553644
A25: lending | B25: =INDEX(MMULT(Law!$B$5:$F$9,$B$8:$F$12),4,1) -> 1.2100765 | C25: =INDEX(MMULT(Law!$B$5:$F$9,$B$8:$F$12),4,2) -> 0.30667813 | D25: =INDEX(MMULT(Law!$B$5:$F$9,$B$8:$F$12),4,3) -> 0.50454277 | E25: =INDEX(MMULT(Law!$B$5:$F$9,$B$8:$F$12),4,4) -> -0.0074059501 | F25: =INDEX(MMULT(Law!$B$5:$F$9,$B$8:$F$12),4,5) -> 0.039308661
A26: funding | B26: =INDEX(MMULT(Law!$B$5:$F$9,$B$8:$F$12),5,1) -> 0.86228031 | C26: =INDEX(MMULT(Law!$B$5:$F$9,$B$8:$F$12),5,2) -> -0.67438084 | D26: =INDEX(MMULT(Law!$B$5:$F$9,$B$8:$F$12),5,3) -> -0.16660076 | E26: =INDEX(MMULT(Law!$B$5:$F$9,$B$8:$F$12),5,4) -> 0.027696311 | F26: =INDEX(MMULT(Law!$B$5:$F$9,$B$8:$F$12),5,5) -> -0.032943021
A28: M = V' Sigma V (MMULT) | B28: PC1 | C28: PC2 | D28: PC3 | E28: PC4 | F28: PC5
A29: PC1 | B29: =INDEX(MMULT($B$15:$F$19,$B$22:$F$26),1,1) -> 2.8743145 | C29: =INDEX(MMULT($B$15:$F$19,$B$22:$F$26),1,2) -> 0.45170157 | D29: =INDEX(MMULT($B$15:$F$19,$B$22:$F$26),1,3) -> -0.077394257 | E29: =INDEX(MMULT($B$15:$F$19,$B$22:$F$26),1,4) -> 0.010909769 | F29: =INDEX(MMULT($B$15:$F$19,$B$22:$F$26),1,5) -> 0.015637365
A30: PC2 | B30: =INDEX(MMULT($B$15:$F$19,$B$22:$F$26),2,1) -> 0.45170157 | C30: =INDEX(MMULT($B$15:$F$19,$B$22:$F$26),2,2) -> 0.97211607 | D30: =INDEX(MMULT($B$15:$F$19,$B$22:$F$26),2,3) -> 0.050644861 | E30: =INDEX(MMULT($B$15:$F$19,$B$22:$F$26),2,4) -> -0.0096061564 | F30: =INDEX(MMULT($B$15:$F$19,$B$22:$F$26),2,5) -> 0.035458923
A31: PC3 | B31: =INDEX(MMULT($B$15:$F$19,$B$22:$F$26),3,1) -> -0.077394257 | C31: =INDEX(MMULT($B$15:$F$19,$B$22:$F$26),3,2) -> 0.050644861 | D31: =INDEX(MMULT($B$15:$F$19,$B$22:$F$26),3,3) -> 0.59691154 | E31: =INDEX(MMULT($B$15:$F$19,$B$22:$F$26),3,4) -> -0.016822932 | F31: =INDEX(MMULT($B$15:$F$19,$B$22:$F$26),3,5) -> 0.012808886
A32: PC4 | B32: =INDEX(MMULT($B$15:$F$19,$B$22:$F$26),4,1) -> 0.010909769 | C32: =INDEX(MMULT($B$15:$F$19,$B$22:$F$26),4,2) -> -0.0096061564 | D32: =INDEX(MMULT($B$15:$F$19,$B$22:$F$26),4,3) -> -0.016822932 | E32: =INDEX(MMULT($B$15:$F$19,$B$22:$F$26),4,4) -> 0.32584688 | F32: =INDEX(MMULT($B$15:$F$19,$B$22:$F$26),4,5) -> 0.0087861629
A33: PC5 | B33: =INDEX(MMULT($B$15:$F$19,$B$22:$F$26),5,1) -> 0.015637365 | C33: =INDEX(MMULT($B$15:$F$19,$B$22:$F$26),5,2) -> 0.035458923 | D33: =INDEX(MMULT($B$15:$F$19,$B$22:$F$26),5,3) -> 0.012808886 | E33: =INDEX(MMULT($B$15:$F$19,$B$22:$F$26),5,4) -> 0.0087861629 | F33: =INDEX(MMULT($B$15:$F$19,$B$22:$F$26),5,5) -> 0.23081097
A35: a = V' s | B35: =SUMPRODUCT($B$15:$F$15,Shift) -> 1.4296127 | C35: =SUMPRODUCT($B$16:$F$16,Shift) -> -1.471195 | D35: =SUMPRODUCT($B$17:$F$17,Shift) -> 0.19604105 | E35: =SUMPRODUCT($B$18:$F$18,Shift) -> 0.0027329636 | F35: =SUMPRODUCT($B$19:$F$19,Shift) -> -0.029210831
A37: Top r components | B37: Delta_r | C37: AUC | D37: Most a warning is worth (engine) | E37: Variance kept
A38: 1 | B38: =SQRT(SUMPRODUCT(MMULT($B$35:B$35,MINVERSE($B$29:B29)),$B$35:B$35)) -> 0.8432401 | C38: =NORMSDIST(B38/SQRT(2)) -> 0.72449949 | D38: 0.14086946 | E38: =B5 -> 0.55951963
A39: 2 | B39: =SQRT(SUMPRODUCT(MMULT($B$35:C$35,MINVERSE($B$29:C30)),$B$35:C$35)) -> 1.9754835 | C39: =NORMSDIST(B39/SQRT(2)) -> 0.91877484 | D39: 1.3390198 | E39: =C5 -> 0.80485429
A40: 3 | B40: =SQRT(SUMPRODUCT(MMULT($B$35:D$35,MINVERSE($B$29:D31)),$B$35:D$35)) -> 2.0281168 | C40: =NORMSDIST(B40/SQRT(2)) -> 0.92422744 | D40: 1.4363771 | E40: =D5 -> 0.90568569
A41: 4 | B41: =SQRT(SUMPRODUCT(MMULT($B$35:E$35,MINVERSE($B$29:E32)),$B$35:E$35)) -> 2.0282782 | C41: =NORMSDIST(B41/SQRT(2)) -> 0.92424373 | D41: 1.4365153 | E41: =E5 -> 0.96082179
A42: 5 | B42: =SQRT(SUMPRODUCT(MMULT($B$35:F$35,MINVERSE($B$29:F33)),$B$35:F$35)) -> 2.0286672 | C42: =NORMSDIST(B42/SQRT(2)) -> 0.92428295 | D42: 1.4368818 | E42: =F5 -> 1
A44: The first component is an equal-weighted financial-conditions index: it keeps 56 percent of the variance and allows at most $0.14 million; the funding spread alone keeps 30 percent and $1.21 million (Proposition 13.3(ii)).

Sheet Model
A1: Explain: the fitted logistic model and two games of attribution (Proposition 13.3(iii)-(iv); Worked Example 13.1, Step 5; Figure 13.3(b); AXIOM Lab 2.13, step 5)
A2: The coefficients are the engine's (unpenalized maximum likelihood on the record). Under the interventional game a linear model's Shapley value is beta_j (x_j - mean_j); the conditional game's (32 coalitions, a Gaussian fit to the record) is the engine's.
B3: bond | C3: high yield | D3: volatility | E3: lending | F3: funding
A4: Fitted log-odds coefficients (engine) | B4: -0.42800628 | C4: -0.26408824 | D4: -0.18253257 | E4: 0.96750858 | F4: 2.1803618
A5: Intercept (engine) | B5: -3.4345696 | C5: -3.435
A6: The reading x (input) | B6: 1 | C6: 1 | D6: 1 | E6: 1 | F6: 1.5
A7: The record's mean reading | B7: =Record!B6 -> 0.035445934 | C7: =Record!C6 -> 0.08403336 | D7: =Record!D6 -> 0.034128158 | E7: =Record!E6 -> 0.15265091 | F7: =Record!F6 -> 0.5225121
A9: Log-odds of the reading | B9: =B5+SUMPRODUCT(B4:F4,B6:F6) -> -0.071145433 | C9: -0.071
A10: Chance of a closure ahead | B10: =1/(1+EXP(-B9)) -> 0.48222114 | C10: 48.2 percent
A11: The best threshold, a chance (engine) | B11: 0.040934632 | C11: 4.09 percent: where the packages are cheapest
A12: Warned at the best threshold? (1 = yes) | B12: =IF(B10>=B11,1,0) -> 1 | C12: Yes
A13: Warned at 0.5, accuracy's threshold? (1 = yes) | B13: =IF(B10>=0.5,1,0) -> 0 | C13: No
A15: Interventional Shapley values, beta_j (x_j - mean_j) | B15: =B4*(B6-B7) -> -0.4128352 | C15: =C4*(C6-C7) -> -0.24189602 | D15: =D4*(D6-D7) -> -0.17630307 | E15: =E4*(E6-E7) -> 0.81981752 | F15: =F4*(F6-F7) -> 2.1312773
A16: Conditional Shapley values (engine) | B16: 0.048356591 | C16: 0.097952731 | D16: 0.043409405 | E16: 0.4615409 | F16: 1.4688009
A18: Sum of the interventional values | B18: =SUM(B15:F15) -> 2.1200605 | C18: 2.120
A19: Sum of the conditional values | B19: =SUM(B16:F16) -> 2.1200605 | C19: 2.120
A20: What both must sum to: f(x) - f(mean) | B20: =SUMPRODUCT(B4:F4,B6:F6)-SUMPRODUCT(B4:F4,B7:F7) -> 2.1200605 | C20: Efficiency (Proposition 13.3(iii))
A21: The three market readings, interventional | B21: =SUM(B15:D15) -> -0.83103429 | C21: -0.83: they net out the common factor
A22: The three market readings, conditional | B22: =SUM(B16:D16) -> 0.18971873 | C22: Every reading gets positive credit
A24: Proposition 13.3(ii): variance is not relevance
A25: Variance of X1 (independent of Y) | B25: 4
A26: Variance of X2 (Y = X2) | B26: 1
A27: Share of the variance the first component (X1) keeps | B27: =B25/(B25+B26) -> 0.8 | C27: 80 percent, and none of the information about Y
A29: Proposition 13.3(iv): f(x) = x1 and X2 = X1; the conditional game credits x2
A30: Mean of X1, mu (input) | B30: 0
A31: x1 (input) | B31: 2
A32: v(empty) = mu | B32: =B30 -> 0
A33: v({1}) = x1 | B33: =B31 -> 2
A34: v({2}) = E[X1 | X2 = x2] = x1 | B34: =B31 -> 2
A35: v({1, 2}) = x1 | B35: =B31 -> 2
A36: Shapley value of x2: (v({2}) - v(empty))/2 + (v({1,2}) - v({1}))/2 | B36: =0.5*(B34-B32)+0.5*(B35-B33) -> 1 | C36: Positive although f ignores x2
A37: equals (x1 - mu) / 2 | B37: =(B31-B30)/2 -> 1

Sheet Accuracy
A1: Accuracy is not value: confusion counts (Theorem 13.2(ii); Worked Example 13.1, Steps 2-4; Table 13.2)
A2: Counts are the engine's (the record's 1,000 windows, or the 100,000 fresh programs, each with its own readings); the rates are formulas. Accuracy counts a false alarm and a miss as equal; the packages do not.
A3: Rule | B3: Warned, closure ahead | C3: Warned, none | D3: All clear, closure ahead | E3: All clear, none | F3: Total | G3: Accuracy | H3: Share warned | I3: Closures among the warned | J3: Closures among the all clear
A4: Logistic at 0.5, the record | B4: 206 | C4: 45 | D4: 62 | E4: 687 | F4: =SUM(B4:E4) -> 1000 | G4: =(B4+E4)/F4 -> 0.893 | H4: =(B4+C4)/F4 -> 0.251 | I4: =IF(B4+C4>0,B4/(B4+C4),"") -> 0.82071713 | J4: =D4/(D4+E4) -> 0.082777036
A5: Logistic at 0.5, fresh programs | B5: 18104 | C5: 4820 | D5: 7856 | E5: 69220 | F5: =SUM(B5:E5) -> 100000 | G5: =(B5+E5)/F5 -> 0.87324 | H5: =(B5+C5)/F5 -> 0.22924 | I5: =IF(B5+C5>0,B5/(B5+C5),"") -> 0.78974001 | J5: =D5/(D5+E5) -> 0.10192537
A6: Logistic where cheapest (a 4.09% chance), fresh | B6: 25234 | C6: 33412 | D6: 726 | E6: 40628 | F6: =SUM(B6:E6) -> 100000 | G6: =(B6+E6)/F6 -> 0.65862 | H6: =(B6+C6)/F6 -> 0.58646 | I6: =IF(B6+C6>0,B6/(B6+C6),"") -> 0.43027657 | J6: =D6/(D6+E6) -> 0.017555738
A7: Logistic at the held-out design's threshold (3.48%), fresh | B7: 25354 | C7: 35537 | D7: 606 | E7: 38503 | F7: =SUM(B7:E7) -> 100000 | G7: =(B7+E7)/F7 -> 0.63857 | H7: =(B7+C7)/F7 -> 0.60891 | I7: =IF(B7+C7>0,B7/(B7+C7),"") -> 0.41638337 | J7: =D7/(D7+E7) -> 0.015495155
A8: Never warn, fresh | B8: 0 | C8: 0 | D8: =NCloseF -> 25960 | E8: =NPaths-NCloseF -> 74040 | F8: =SUM(B8:E8) -> 100000 | G8: =(B8+E8)/F8 -> 0.7404 | H8: =(B8+C8)/F8 -> 0 | I8: =IF(B8+C8>0,B8/(B8+C8),"") | J8: =D8/(D8+E8) -> 0.2596
A9: Boosting at 0.5, the record | B9: 268 | C9: 0 | D9: 0 | E9: 732 | F9: =SUM(B9:E9) -> 1000 | G9: =(B9+E9)/F9 -> 1 | H9: =(B9+C9)/F9 -> 0.268 | I9: =IF(B9+C9>0,B9/(B9+C9),"") -> 1 | J9: =D9/(D9+E9) -> 0
A10: Boosting at 0.5, fresh programs | B10: 17069 | C10: 5465 | D10: 8891 | E10: 68575 | F10: =SUM(B10:E10) -> 100000 | G10: =(B10+E10)/F10 -> 0.85644 | H10: =(B10+C10)/F10 -> 0.22534 | I10: =IF(B10+C10>0,B10/(B10+C10),"") -> 0.75747759 | J10: =D10/(D10+E10) -> 0.11477293
A11: Boosting, trusted design's threshold, fresh | B11: 21327 | C11: 14393 | D11: 4633 | E11: 59647 | F11: =SUM(B11:E11) -> 100000 | G11: =(B11+E11)/F11 -> 0.80974 | H11: =(B11+C11)/F11 -> 0.3572 | I11: =IF(B11+C11>0,B11/(B11+C11),"") -> 0.59706047 | J11: =D11/(D11+E11) -> 0.072075296
A12: Boosting, held-out design's threshold, fresh | B12: 24868 | C12: 43441 | D12: 1092 | E12: 30599 | F12: =SUM(B12:E12) -> 100000 | G12: =(B12+E12)/F12 -> 0.55467 | H12: =(B12+C12)/F12 -> 0.68309 | I12: =IF(B12+C12>0,B12/(B12+C12),"") -> 0.36405159 | J12: =D12/(D12+E12) -> 0.034457732
A14: Where the packages are cheapest the warning is right 65.9 percent of the time, less than never warning (74.0 percent), and worth $1.44 million; at 0.5 it is right 87.3 percent and worth $0.53 million.

Sheet Designs
A1: The two-package arithmetic for every warning (Worked Example 13.1, Steps 1-4; Online Appendix Remark 13.B.1; Table 13.3; AXIOM Lab 2.13, steps 3-4)
A2: A group with closure share pi is designed on the book's paths weighted pi / n1 on the closure paths and (1 - pi) / n0 on the others; its chance of a breach is pi x (closure paths breaching) / n1 + (1 - pi) x (others breaching) / n0. Value = Volume I's $10.44 million less the expected cost.
A4: Design | B4: Shares from | C4: Closures among the warned | D4: Warned | E4: Closures among the all clear | F4: All clear | G4: Share warned | H4: Closure share, warned | I4: Closure share, all clear | J4: All clear: line (engine) | K4: All clear: delay (engine) | L4: All clear: cost | M4: Warned: line (engine) | N4: Warned: delay (engine) | O4: Warned: cost | P4: Expected cost | Q4: Value promised | R4: Book paths breaching the all-clear package: closure ahead (engine) | S4: no closure ahead (engine) | T4: Book paths breaching the warned package: closure ahead (engine) | U4: no closure ahead (engine) | V4: The all-clear group's chance, as designed | W4: The warned group's chance, as designed | X4: The design's chance of a breach | Y4: Fresh programs warned (engine) | Z4: Share of fresh programs warned | AA4: Fresh breaches, warned (engine) | AB4: Fresh breaches, all clear (engine) | AC4: Fresh chance of a breach | AD4: Fresh expected cost | AE4: Fresh value
A5: None (Volume I) | B5: one package for every program | C5: 0 | D5: 0 | E5: =NClose -> 25912 | F5: =NPaths -> 100000 | G5: =D5/(D5+F5) -> 0 | H5: =IF(D5>0,C5/D5,0) -> 0 | I5: =IF(F5>0,E5/F5,0) -> 0.25912 | J5: 170 | K5: 0.66757636 | L5: =Fee*J5+VQ*K5 -> 10.440611 | M5: -- | N5: -- | O5: -- | P5: =IF(G5>0,G5*O5,0)+(1-G5)*L5 -> 10.440611 | Q5: =CostV1-P5 -> 0 | R5: 1675 | S5: 3325 | T5: -- | U5: -- | V5: =I5*R5/NClose+(1-I5)*S5/NOpen -> 0.05 | W5: -- | X5: =IF(G5>0,G5*W5,0)+(1-G5)*V5 -> 0.05 | Y5: 0 | Z5: =Y5/NPaths -> 0 | AA5: 0 | AB5: 4907 | AC5: =(AA5+AB5)/NPaths -> 0.04907 | AD5: =IF(Z5>0,Z5*O5,0)+(1-Z5)*L5 -> 10.440611 | AE5: =CostV1-AD5 -> 0
A6: Perfect warning (Chapter 9) | B6: the paths: closure ahead or not | C6: =NClose -> 25912 | D6: =NClose -> 25912 | E6: 0 | F6: =NOpen -> 74088 | G6: =D6/(D6+F6) -> 0.25912 | H6: =IF(D6>0,C6/D6,0) -> 1 | I6: =IF(F6>0,E6/F6,0) -> 0 | J6: 0 | K6: 0.60835428 | L6: =Fee*J6+VQ*K6 -> 4.8668342 | M6: 215 | N6: 0.50438261 | O6: =Fee*M6+VQ*N6 -> 10.485061 | P6: =IF(G6>0,G6*O6,0)+(1-G6)*L6 -> 6.3226291 | Q6: =CostV1-P6 -> 4.1179818 | R6: 16556 | S6: 3519 | T6: 1480 | U6: 3909 | V6: =I6*R6/NClose+(1-I6)*S6/NOpen -> 0.04749757 | W6: =H6*T6/NClose+(1-H6)*U6/NOpen -> 0.057116394 | X6: =IF(G6>0,G6*W6,0)+(1-G6)*V6 -> 0.04999 | Y6: =NCloseF -> 25960 | Z6: =Y6/NPaths -> 0.2596 | AA6: 1530 | AB6: 3383 | AC6: =(AA6+AB6)/NPaths -> 0.04913 | AD6: =IF(Z6>0,Z6*O6,0)+(1-Z6)*L6 -> 6.3253258 | AE6: =CostV1-AD6 -> 4.115285
A7: Declared law (ceiling) | B7: the law (sheet Law) | C7: law | D7: law | E7: law | F7: law | G7: =Law!B28 -> 0.58863946 | H7: =Law!B29 -> 0.42796889 | I7: =Law!B30 -> 0.017504417 | J7: 0 | K7: 0.67076033 | L7: =Fee*J7+VQ*K7 -> 5.3660826 | M7: 190 | N7: 0.73072946 | O7: =Fee*M7+VQ*N7 -> 11.545836 | P7: =IF(G7>0,G7*O7,0)+(1-G7)*L7 -> 9.0037291 | Q7: =CostV1-P7 -> 1.4368818 | R7: 16360 | S7: 3314 | T7: 1353 | U7: 3127 | V7: =I7*R7/NClose+(1-I7)*S7/NOpen -> 0.054999331 | W7: =H7*T7/NClose+(1-H7)*U7/NOpen -> 0.046489945 | X7: =IF(G7>0,G7*W7,0)+(1-G7)*V7 -> 0.049990371 | Y7: 58940 | Z7: =Y7/NPaths -> 0.5894 | AA7: 2664 | AB7: 2234 | AC7: =(AA7+AB7)/NPaths -> 0.04898 | AD7: =IF(Z7>0,Z7*O7,0)+(1-Z7)*L7 -> 9.0084291 | AE7: =CostV1-AD7 -> 1.4321818
A8: Logistic at 0.5, the law's shares | B8: the book's paths, their own readings | C8: 18034 | D8: 23012 | E8: 7878 | F8: 76988 | G8: =D8/(D8+F8) -> 0.23012 | H8: =IF(D8>0,C8/D8,0) -> 0.78367808 | I8: =IF(F8>0,E8/F8,0) -> 0.10232764 | J8: 125 | K8: 0.71211629 | L8: =Fee*J8+VQ*K8 -> 9.4469303 | M8: 205 | N8: 0.66543435 | O8: =Fee*M8+VQ*N8 -> 11.473475 | P8: =IF(G8>0,G8*O8,0)+(1-G8)*L8 -> 9.9132787 | Q8: =CostV1-P8 -> 0.52733217 | R8: 2890 | S8: 3184 | T8: 1331 | U8: 3337 | V8: =I8*R8/NClose+(1-I8)*S8/NOpen -> 0.049991034 | W8: =H8*T8/NClose+(1-H8)*U8/NOpen -> 0.049997898 | X8: =IF(G8>0,G8*W8,0)+(1-G8)*V8 -> 0.049992614 | Y8: 22924 | Z8: =Y8/NPaths -> 0.22924 | AA8: 1174 | AB8: 3724 | AC8: =(AA8+AB8)/NPaths -> 0.04898 | AD8: =IF(Z8>0,Z8*O8,0)+(1-Z8)*L8 -> 9.9114954 | AE8: =CostV1-AD8 -> 0.52911553
A9: Logistic where cheapest, the law's shares | B9: the book's paths, their own readings | C9: 25201 | D9: 59000 | E9: 711 | F9: 41000 | G9: =D9/(D9+F9) -> 0.59 | H9: =IF(D9>0,C9/D9,0) -> 0.42713559 | I9: =IF(F9>0,E9/F9,0) -> 0.017341463 | J9: 0 | K9: 0.66870503 | L9: =Fee*J9+VQ*K9 -> 5.3496402 | M9: 190 | N9: 0.73046138 | O9: =Fee*M9+VQ*N9 -> 11.543691 | P9: =IF(G9>0,G9*O9,0)+(1-G9)*L9 -> 9.0041302 | Q9: =CostV1-P9 -> 1.4364807 | R9: 16367 | S9: 3320 | T9: 1355 | U9: 3127 | V9: =I9*R9/NClose+(1-I9)*S9/NOpen -> 0.054988002 | W9: =H9*T9/NClose+(1-H9)*U9/NOpen -> 0.046514573 | X9: =IF(G9>0,G9*W9,0)+(1-G9)*V9 -> 0.049988679 | Y9: 58646 | Z9: =Y9/NPaths -> 0.58646 | AA9: 2643 | AB9: 2285 | AC9: =(AA9+AB9)/NPaths -> 0.04928 | AD9: =IF(Z9>0,Z9*O9,0)+(1-Z9)*L9 -> 8.9822033 | AE9: =CostV1-AD9 -> 1.4584076
A10: Logistic, held-out shares | B10: the record, out-of-fold scores | C10: 264 | D10: 590 | E10: 4 | F10: 410 | G10: =D10/(D10+F10) -> 0.59 | H10: =IF(D10>0,C10/D10,0) -> 0.44745763 | I10: =IF(F10>0,E10/F10,0) -> 0.0097560976 | J10: 0 | K10: 0.68303527 | L10: =Fee*J10+VQ*K10 -> 5.4642822 | M10: 185 | N10: 0.67675253 | O10: =Fee*M10+VQ*N10 -> 10.96402 | P10: =IF(G10>0,G10*O10,0)+(1-G10)*L10 -> 8.7091276 | Q10: =CostV1-P10 -> 1.7314833 | R10: 16321 | S10: 3281 | T10: 1471 | U10: 3297 | V10: =I10*R10/NClose+(1-I10)*S10/NOpen -> 0.049998125 | W10: =H10*T10/NClose+(1-H10)*U10/NOpen -> 0.049990513 | X10: =IF(G10>0,G10*W10,0)+(1-G10)*V10 -> 0.049993634 | Y10: 60891 | Z10: =Y10/NPaths -> 0.60891 | AA10: 2916 | AB10: 2103 | AC10: =(AA10+AB10)/NPaths -> 0.05019 | AD10: =IF(Z10>0,Z10*O10,0)+(1-Z10)*L10 -> 8.8131277 | AE10: =CostV1-AD10 -> 1.6274832
A11: Logistic, certified | B11: the record, out-of-fold: 95% upper bounds | C11: 264 | D11: 590 | E11: 4 | F11: 410 | G11: =D11/(D11+F11) -> 0.59 | H11: =_xlfn.BETA.INV(Conf,C11+1,D11-C11) -> 0.48211678 | I11: =_xlfn.BETA.INV(Conf,E11+1,F11-E11) -> 0.022185633 | J11: 0 | K11: 0.73399402 | L11: =Fee*J11+VQ*K11 -> 5.8719521 | M11: 190 | N11: 0.74191894 | O11: =Fee*M11+VQ*N11 -> 11.635351 | P11: =IF(G11>0,G11*O11,0)+(1-G11)*L11 -> 9.2723578 | Q11: =CostV1-P11 -> 1.1682531 | R11: 16151 | S11: 3119 | T11: 1338 | U11: 3094 | V11: =I11*R11/NClose+(1-I11)*S11/NOpen -> 0.05499295 | W11: =H11*T11/NClose+(1-H11)*U11/NOpen -> 0.046522129 | X11: =IF(G11>0,G11*W11,0)+(1-G11)*V11 -> 0.049995165 | Y11: 60891 | Z11: =Y11/NPaths -> 0.60891 | AA11: 2708 | AB11: 2018 | AC11: =(AA11+AB11)/NPaths -> 0.04726 | AD11: =IF(Z11>0,Z11*O11,0)+(1-Z11)*L11 -> 9.3813436 | AE11: =CostV1-AD11 -> 1.0592673
A12: Logistic at 0.5, held-out shares | B12: the record, out-of-fold scores | C12: 206 | D12: 252 | E12: 62 | F12: 748 | G12: =D12/(D12+F12) -> 0.252 | H12: =IF(D12>0,C12/D12,0) -> 0.81746032 | I12: =IF(F12>0,E12/F12,0) -> 0.082887701 | J12: 115 | K12: 0.71751906 | L12: =Fee*J12+VQ*K12 -> 9.1901525 | M12: 205 | N12: 0.66988062 | O12: =Fee*M12+VQ*N12 -> 11.509045 | P12: =IF(G12>0,G12*O12,0)+(1-G12)*L12 -> 9.7745134 | Q12: =CostV1-P12 -> 0.66609751 | R12: 3380 | S12: 3165 | T12: 1325 | U12: 3319 | V12: =I12*R12/NClose+(1-I12)*S12/NOpen -> 0.049990546 | W12: =H12*T12/NClose+(1-H12)*U12/NOpen -> 0.049977941 | X12: =IF(G12>0,G12*W12,0)+(1-G12)*V12 -> 0.049987369 | Y12: 22924 | Z12: =Y12/NPaths -> 0.22924 | AA12: 1169 | AB12: 3864 | AC12: =(AA12+AB12)/NPaths -> 0.05033 | AD12: =IF(Z12>0,Z12*O12,0)+(1-Z12)*L12 -> 9.7217354 | AE12: =CostV1-AD12 -> 0.7188755
A13: Boosting, trusted | B13: the record, in-sample scores | C13: 268 | D13: 270 | E13: 0 | F13: 730 | G13: =D13/(D13+F13) -> 0.27 | H13: =IF(D13>0,C13/D13,0) -> 0.99259259 | I13: =IF(F13>0,E13/F13,0) -> 0 | J13: 0 | K13: 0.60835428 | L13: =Fee*J13+VQ*K13 -> 4.8668342 | M13: 215 | N13: 0.51323302 | O13: =Fee*M13+VQ*N13 -> 10.555864 | P13: =IF(G13>0,G13*O13,0)+(1-G13)*L13 -> 6.4028723 | Q13: =CostV1-P13 -> 4.0377386 | R13: 16556 | S13: 3519 | T13: 1471 | U13: 3866 | V13: =I13*R13/NClose+(1-I13)*S13/NOpen -> 0.04749757 | W13: =H13*T13/NClose+(1-H13)*U13/NOpen -> 0.05673508 | X13: =IF(G13>0,G13*W13,0)+(1-G13)*V13 -> 0.049991698 | Y13: 35720 | Z13: =Y13/NPaths -> 0.3572 | AA13: 1911 | AB13: 5765 | AC13: =(AA13+AB13)/NPaths -> 0.07676 | AD13: =IF(Z13>0,Z13*O13,0)+(1-Z13)*L13 -> 6.8989557 | AE13: =CostV1-AD13 -> 3.5416552
A14: Boosting, held-out shares | B14: the record, out-of-fold scores | C14: 258 | D14: 580 | E14: 10 | F14: 420 | G14: =D14/(D14+F14) -> 0.58 | H14: =IF(D14>0,C14/D14,0) -> 0.44482759 | I14: =IF(F14>0,E14/F14,0) -> 0.023809524 | J14: 0 | K14: 0.75742985 | L14: =Fee*J14+VQ*K14 -> 6.0594388 | M14: 190 | N14: 0.73853144 | O14: =Fee*M14+VQ*N14 -> 11.608251 | P14: =IF(G14>0,G14*O14,0)+(1-G14)*L14 -> 9.2777502 | Q14: =CostV1-P14 -> 1.1628607 | R14: 16075 | S14: 3053 | T14: 1345 | U14: 3107 | V14: =I14*R14/NClose+(1-I14)*S14/NOpen -> 0.054997305 | W14: =H14*T14/NClose+(1-H14)*U14/NOpen -> 0.046371474 | X14: =IF(G14>0,G14*W14,0)+(1-G14)*V14 -> 0.049994323 | Y14: 68309 | Z14: =Y14/NPaths -> 0.68309 | AA14: 3061 | AB14: 1899 | AC14: =(AA14+AB14)/NPaths -> 0.0496 | AD14: =IF(Z14>0,Z14*O14,0)+(1-Z14)*L14 -> 9.8497773 | AE14: =CostV1-AD14 -> 0.59083363
A16: The design's chance of a breach is the appetite as the design believes it (at most 5 percent); the fresh chance is the truth on the 100,000 fresh programs. The trusted boosted design believes its all-clear group has no closures; on the fresh paths it breaches 7.68 percent.

Sheet Table13_3
A1: Table 13.3: warnings, their packages, and their checks on Chapter 9's fresh paths (Worked Example 13.1)
A2: Warned: share of the 100,000 fresh programs warned; packages: line ($ million), delay (quarters); promised value: Volume I's $10.44 million less the expected cost the design expects; fresh: the true chance of a breach and the value on the fresh paths. Every cell links to sheet Designs.
A4: Warning | B4: Warned (%) | C4: All clear: line | D4: All clear: delay | E4: Warned: line | F4: Warned: delay | G4: Promised value | H4: Fresh breach (%) | I4: Fresh value
A5: None (Volume I) | B5: =100*Designs!Z5 -> 0 | C5: =Designs!J5 -> 170 | D5: =Designs!K5 -> 0.66757636 | E5: -- | F5: -- | G5: =Designs!Q5 -> 0 | H5: =100*Designs!AC5 -> 4.907 | I5: =Designs!AE5 -> 0
A6: Perfect (Chapter 9) | B6: =100*Designs!Z6 -> 25.96 | C6: =Designs!J6 -> 0 | D6: =Designs!K6 -> 0.60835428 | E6: =Designs!M6 -> 215 | F6: =Designs!N6 -> 0.50438261 | G6: =Designs!Q6 -> 4.1179818 | H6: =100*Designs!AC6 -> 4.913 | I6: =Designs!AE6 -> 4.115285
A7: Declared law (ceiling) | B7: =100*Designs!Z7 -> 58.94 | C7: =Designs!J7 -> 0 | D7: =Designs!K7 -> 0.67076033 | E7: =Designs!M7 -> 190 | F7: =Designs!N7 -> 0.73072946 | G7: =Designs!Q7 -> 1.4368818 | H7: =100*Designs!AC7 -> 4.898 | I7: =Designs!AE7 -> 1.4321818
A8: Logistic, at 0.5 (law's shares) | B8: =100*Designs!Z8 -> 22.924 | C8: =Designs!J8 -> 125 | D8: =Designs!K8 -> 0.71211629 | E8: =Designs!M8 -> 205 | F8: =Designs!N8 -> 0.66543435 | G8: =Designs!Q8 -> 0.52733217 | H8: =100*Designs!AC8 -> 4.898 | I8: =Designs!AE8 -> 0.52911553
A9: Logistic, cheapest (law's shares) | B9: =100*Designs!Z9 -> 58.646 | C9: =Designs!J9 -> 0 | D9: =Designs!K9 -> 0.66870503 | E9: =Designs!M9 -> 190 | F9: =Designs!N9 -> 0.73046138 | G9: =Designs!Q9 -> 1.4364807 | H9: =100*Designs!AC9 -> 4.928 | I9: =Designs!AE9 -> 1.4584076
A10: Logistic, held-out | B10: =100*Designs!Z10 -> 60.891 | C10: =Designs!J10 -> 0 | D10: =Designs!K10 -> 0.68303527 | E10: =Designs!M10 -> 185 | F10: =Designs!N10 -> 0.67675253 | G10: =Designs!Q10 -> 1.7314833 | H10: =100*Designs!AC10 -> 5.019 | I10: =Designs!AE10 -> 1.6274832
A11: Logistic, certified | B11: =100*Designs!Z11 -> 60.891 | C11: =Designs!J11 -> 0 | D11: =Designs!K11 -> 0.73399402 | E11: =Designs!M11 -> 190 | F11: =Designs!N11 -> 0.74191894 | G11: =Designs!Q11 -> 1.1682531 | H11: =100*Designs!AC11 -> 4.726 | I11: =Designs!AE11 -> 1.0592673
A12: Boosting, trusted | B12: =100*Designs!Z13 -> 35.72 | C12: =Designs!J13 -> 0 | D12: =Designs!K13 -> 0.60835428 | E12: =Designs!M13 -> 215 | F12: =Designs!N13 -> 0.51323302 | G12: =Designs!Q13 -> 4.0377386 | H12: =100*Designs!AC13 -> 7.676 | I12: --
A13: Boosting, held-out | B13: =100*Designs!Z14 -> 68.309 | C13: =Designs!J14 -> 0 | D13: =Designs!K14 -> 0.75742985 | E13: =Designs!M14 -> 190 | F13: =Designs!N14 -> 0.73853144 | G13: =Designs!Q14 -> 1.1628607 | H13: =100*Designs!AC14 -> 4.96 | I13: =Designs!AE14 -> 0.59083363
A15: The two logistic rows marked law's shares take each group's closure share from the law; the other logistic and boosting rows estimate it from the desk's record. A fresh value is shown only where the fresh breach is near the appetite.

Sheet Study200
A1: Repeat on 200 records of 1,000 windows (Theorem 13.3(i); Worked Example 13.1, Step 4; Figure 13.2(b); AXIOM Lab 2.13, step 4)
A2: For each record (seeds 913000-913199) the engine fits the logistic model, scores it out of fold, designs the held-out and the certified warnings and checks both on the fresh paths; the summaries are formulas.
A4: Record seed | B4: Held-out: fresh chance of a breach | C4: Held-out: fresh value | D4: Certified: fresh chance of a breach | E4: Certified: fresh value | G4: Summary | H4: Held-out shares | I4: Certified
A5: 913000 | B5: 0.04967 | C5: 1.493347 | D5: 0.0481 | E5: 0.91950453 | G5: Records keeping 5 percent | H5: =COUNTIF(B5:B204,"<="&Alpha)/COUNT(B5:B204) -> 0.475 | I5: =COUNTIF(D5:D204,"<="&Alpha)/COUNT(D5:D204) -> 0.98
A6: 913001 | B6: 0.05381 | C6: 1.6119612 | D6: 0.04919 | E6: 0.97666697 | G6: Mean true chance of a breach | H6: =AVERAGE(B5:B204) -> 0.05019745 | I6: =AVERAGE(D5:D204) -> 0.04754545
A7: 913002 | B7: 0.05079 | C7: 1.6762126 | D7: 0.04746 | E7: 1.0870853 | G7: 90th percentile | H7: =PERCENTILE(B5:B204,0.9) -> 0.052131 | I7: =PERCENTILE(D5:D204,0.9) -> 0.048911
A8: 913003 | B8: 0.04995 | C8: 1.4435469 | D8: 0.04681 | E8: 0.81879114 | G8: Mean value on the fresh paths | H8: =AVERAGE(C5:C204) -> 1.5333125 | I8: =AVERAGE(E5:E204) -> 0.95020598
A9: 913004 | B9: 0.04798 | C9: 1.187255 | D9: 0.04642 | E9: 0.68502192
A10: 913005 | B10: 0.05049 | C10: 1.6817853 | D10: 0.04737 | E10: 1.1058872 | G10: Held-out designs keep the appetite in 47.5 percent of records; certified designs in 98.0 percent, at an average value of $0.95 million.
A11: 913006 | B11: 0.05255 | C11: 2.0543709 | D11: 0.04975 | E11: 1.5554338
A12: 913007 | B12: 0.05102 | C12: 1.5966661 | D12: 0.04581 | E12: 0.81977734
A13: 913008 | B13: 0.05158 | C13: 1.9082894 | D13: 0.04879 | E13: 1.3791643
A14: 913009 | B14: 0.05082 | C14: 1.7329516 | D14: 0.04852 | E14: 1.2512102
A15: 913010 | B15: 0.05017 | C15: 1.6202325 | D15: 0.04678 | E15: 0.99887081
A16: 913011 | B16: 0.04921 | C16: 1.3184999 | D16: 0.04607 | E16: 0.72228121
A17: 913012 | B17: 0.05031 | C17: 1.6238807 | D17: 0.04746 | E17: 1.0494965
A18: 913013 | B18: 0.04855 | C18: 1.2284204 | D18: 0.04774 | E18: 0.81638164
A19: 913014 | B19: 0.0476 | C19: 1.0223372 | D19: 0.04706 | E19: 0.5205478
A20: 913015 | B20: 0.05091 | C20: 1.7219356 | D20: 0.04761 | E20: 1.1287167
A21: 913016 | B21: 0.05006 | C21: 1.6119171 | D21: 0.04776 | E21: 1.0941005
A22: 913017 | B22: 0.05031 | C22: 1.5323678 | D22: 0.04838 | E22: 0.87939637
... A204: 913199 | B204: 0.05149 | C204: 1.6688411 | D204: 0.04821 | E204: 0.96025249

Sheet Stages
A1: Boosting stage by stage: AUC on the record and on 20,000 fresh programs (Theorem 13.1(iii); Proposition 13.2(iv); Worked Example 13.1, Step 3; Figure 13.2(a); AXIOM Lab 2.13, step 2)
A2: Gradient boosting, depth-4 trees, learning rate 0.1, 500 stages (engine). The record's AUC rises to 1; the fresh AUC peaks early and falls: stopping early is a form of regularization.
A4: Stage | B4: AUC on the record (engine) | C4: AUC on fresh programs (engine) | E4: Summary | F4: Value
A5: 1 | B5: 0.94512071 | C5: 0.88793933 | E5: The fresh AUC's peak | F5: =MAX(C5:C504) -> 0.9102993 | G5: 0.910
A6: 2 | B6: 0.95546091 | C6: 0.90297027 | E6: after stages | F6: =INDEX(A5:A504,MATCH(F5,C5:C504,0)) -> 24 | G6: 24
A7: 3 | B7: 0.95531818 | C7: 0.90464119 | E7: The fresh AUC after 500 stages | F7: =C504 -> 0.88848332 | G7: 0.888
A8: 4 | B8: 0.95665627 | C8: 0.90609091 | E8: The record's AUC after 500 stages | F8: =B504 -> 1 | G8: 1.000
A9: 5 | B9: 0.95837411 | C9: 0.90607955 | E9: The record's AUC at the fresh peak | F9: =INDEX(B5:B504,F6) -> 0.9757743
A10: 6 | B10: 0.95922539 | C10: 0.90750206
A11: 7 | B11: 0.95940125 | C11: 0.90710209
A12: 8 | B12: 0.96145043 | C12: 0.90780702
A13: 9 | B13: 0.96299751 | C13: 0.907752
A14: 10 | B14: 0.96340531 | C14: 0.90861479
A15: 11 | B15: 0.96289811 | C15: 0.90876514
A16: 12 | B16: 0.9639278 | C16: 0.90925787
A17: 13 | B17: 0.96731761 | C17: 0.90793395
A18: 14 | B18: 0.96759797 | C18: 0.90781443
A19: 15 | B19: 0.9682479 | C19: 0.90825142
A20: 16 | B20: 0.96952991 | C20: 0.90935522
A21: 17 | B21: 0.97148479 | C21: 0.90950664
... A504: 500 | B504: 1 | C504: 0.88848332

Sheet Sweep
A1: Price the warning: the logistic warning at every threshold, each group's closure share as the law gives it (Theorem 13.2(ii); Worked Example 13.1, Step 2; Figure 13.1(a); AXIOM Lab 2.13, step 3)
A2: 51 thresholds: the scores' quantiles that warn 0, 2, ..., 100 percent of the book's paths (engine). Value is the packages' (Volume I's $10.44 million less their expected cost); accuracy is on the fresh paths.
A4: Share warned | B4: Accuracy, fresh (engine) | C4: Value of its packages (engine) | D4: Value on the fresh paths (engine) | E4: Fresh chance of a breach (engine) | G4: On this grid | H4: Value
A5: 0 | B5: 0.7404 | C5: 0 | D5: 0 | E5: 0.04907 | G5: Most accurate | H5: =MAX(B5:B55) -> 0.87313
A6: 0.02 | B6: 0.76097 | C6: 0.047169041 | D6: 0.045885703 | E6: 0.04912 | G6: share warned there | H6: =INDEX(A5:A55,MATCH(H5,B5:B55,0)) -> 0.22
A7: 0.04 | B7: 0.78018 | C7: 0.079516592 | D7: 0.077265783 | E7: 0.04921 | G7: Most valuable packages | H7: =MAX(C5:C55) -> 1.4326524
A8: 0.06 | B8: 0.79717 | C8: 0.10919242 | D8: 0.10768227 | E8: 0.04906 | G8: share warned there | H8: =INDEX(A5:A55,MATCH(H7,C5:C55,0)) -> 0.6
A9: 0.08 | B9: 0.81313 | C9: 0.15878703 | D9: 0.15759 | E9: 0.04905 | G9: accuracy there | H9: =INDEX(B5:B55,MATCH(H7,C5:C55,0)) -> 0.64997 | I9: Below never warning
A10: 0.1 | B10: 0.82744 | C10: 0.18660827 | D10: 0.1866387 | E10: 0.04916
A11: 0.12 | B11: 0.8401 | C11: 0.23677772 | D11: 0.23649237 | E11: 0.04903
A12: 0.14 | B12: 0.85093 | C12: 0.27460758 | D12: 0.27455773 | E12: 0.04898
A13: 0.16 | B13: 0.86003 | C13: 0.31788474 | D13: 0.31724305 | E13: 0.04902
A14: 0.18 | B14: 0.86665 | C14: 0.37135107 | D14: 0.37076238 | E14: 0.04907
A15: 0.2 | B15: 0.8713 | C15: 0.44651908 | D15: 0.44538008 | E15: 0.04925
A16: 0.22 | B16: 0.87313 | C16: 0.4953823 | D16: 0.49647256 | E16: 0.04898
A17: 0.24 | B17: 0.87245 | C17: 0.55598121 | D17: 0.55703091 | E17: 0.04912
A18: 0.26 | B18: 0.86947 | C18: 0.60197805 | D18: 0.60324835 | E18: 0.04916
A19: 0.28 | B19: 0.86509 | C19: 0.6541215 | D19: 0.6543256 | E19: 0.04929
A20: 0.3 | B20: 0.85923 | C20: 0.70857963 | D20: 0.71023473 | E20: 0.04897
A21: 0.32 | B21: 0.85213 | C21: 0.75367481 | D21: 0.75754365 | E21: 0.04905
... A55: 1 | B55: 0.2596 | C55: 0 | D55: 0 | E55: 0.04907

Sheet Examples
A1: The appendices' small examples and the honest checks (Theorems 13.2-13.3; Proposition 13.2)
A2: Inputs in blue can be changed; the book's values are the defaults.
A3: Theorem 13.2(iv): a smaller squared error, a costlier decision
A4: Cost of each unit ordered above the outcome, c_o | B4: 1
A5: Cost of each unit short, c_u | B5: 9
A6: Outcome Y: low (chance 1/2) | B6: 0
A7: Outcome Y: high (chance 1/2) | B7: 10
A8: Prediction A | B8: 5 | C8: The mean
A9: squared error | B9: =0.5*(B8-B6)^2+0.5*(B8-B7)^2 -> 25 | C9: 25
A10: cost of its decision | B10: =0.5*(B4*MAX(B8-B6,0)+B5*MAX(B6-B8,0))+0.5*(B4*MAX(B8-B7,0)+B5*MAX(B7-B8,0)) -> 25 | C10: 25
A11: Prediction B | B11: 10
A12: squared error | B12: =0.5*(B11-B6)^2+0.5*(B11-B7)^2 -> 50 | C12: 50
A13: cost of its decision | B13: =0.5*(B4*MAX(B11-B6,0)+B5*MAX(B6-B11,0))+0.5*(B4*MAX(B11-B7,0)+B5*MAX(B7-B11,0)) -> 5 | C13: 5: the cost is not affine in Y, so plugging in the mean need not be best
A15: Proposition 13.2(iii): three classifiers each right on 60 percent, a majority vote right on 40 percent
A16: Case | B16: Classifier 1 right | C16: Classifier 2 right | D16: Classifier 3 right | E16: Majority right
A17: 1 | B17: 1 | C17: 1 | D17: 1 | E17: =IF(SUM(B17:D17)>=2,1,0) -> 1
A18: 2 | B18: 1 | C18: 1 | D18: 1 | E18: =IF(SUM(B18:D18)>=2,1,0) -> 1
A19: 3 | B19: 1 | C19: 1 | D19: 1 | E19: =IF(SUM(B19:D19)>=2,1,0) -> 1
A20: 4 | B20: 1 | C20: 1 | D20: 1 | E20: =IF(SUM(B20:D20)>=2,1,0) -> 1
A21: 5 | B21: 1 | C21: 1 | D21: 1 | E21: =IF(SUM(B21:D21)>=2,1,0) -> 1
A22: 6 | B22: 1 | C22: 1 | D22: 1 | E22: =IF(SUM(B22:D22)>=2,1,0) -> 1
A23: 7 | B23: 1 | C23: 0 | D23: 0 | E23: =IF(SUM(B23:D23)>=2,1,0) -> 0
A24: 8 | B24: 1 | C24: 0 | D24: 0 | E24: =IF(SUM(B24:D24)>=2,1,0) -> 0
A25: 9 | B25: 1 | C25: 0 | D25: 0 | E25: =IF(SUM(B25:D25)>=2,1,0) -> 0
A26: 10 | B26: 0 | C26: 1 | D26: 0 | E26: =IF(SUM(B26:D26)>=2,1,0) -> 0
A27: 11 | B27: 0 | C27: 1 | D27: 0 | E27: =IF(SUM(B27:D27)>=2,1,0) -> 0
A28: 12 | B28: 0 | C28: 1 | D28: 0 | E28: =IF(SUM(B28:D28)>=2,1,0) -> 0
... A31: 15 | B31: 0 | C31: 0 | D31: 1 | E31: =IF(SUM(B31:D31)>=2,1,0) -> 0
A32: Share of cases right | B32: =AVERAGE(B17:B31) -> 0.6 | C32: =AVERAGE(C17:C31) -> 0.6 | D32: =AVERAGE(D17:D31) -> 0.6 | E32: =AVERAGE(E17:E31) -> 0.4
A34: Theorem 13.2(i): the plug-in decision's regret can reach twice L times the error
A35: L, the cost's sensitivity to the unknown | B35: 1 | C35: J(a, c) = L c, J(b, c) = -L c
A36: The error e: the prediction is 0, the truth -e | B36: 0.5 | C36: At 0 both cost 0; ties go to b
A37: Cost of the plug-in decision b at the truth | B37: =-B35*(-B36) -> 0.5
A38: Cost of the best decision a at the truth | B38: =B35*(-B36) -> -0.5
A39: Regret | B39: =B37-B38 -> 1 | C39: Equals the bound 2 L e
A41: Proposition 13.2(ii): averaging B predictors with variance sigma^2 and correlation rho
A42: sigma^2 | B42: 1
A43: rho | B43: 0.3
A44: Members B | B44: Variance of the average
A45: 1 | B45: =$B$43*$B$42+(1-$B$43)*$B$42/A45 -> 1
...

Sheet Reference_Values
A1: Checkpoint | B1: Engine value | C1: Meaning (where in the book)
A2: A closure ahead under the law | B2: 0.25918178 | C2: Remark 13.B.1: 25.92 percent
A3: Volume I's package: cost | B3: 10.440611 | C3: $10.44 million
A4: No warning: chance of a breach on the book's paths | B4: 0.05 | C4: 5.00 percent
A5: No warning: chance on the fresh paths | B5: 0.04907 | C5: 4.91 percent
A6: Perfect warning: all-clear cost | B6: 4.8668342 | C6: $4.87 million
A7: Perfect warning: warned cost | B7: 10.485061 | C7: $10.49 million
A8: Perfect warning: all-clear chance | B8: 0.04749757 | C8: 4.75 percent
A9: Perfect warning: warned chance | B9: 0.057116394 | C9: 5.71 percent
A10: Perfect warning: expected cost | B10: 6.3226291 | C10: $6.32 million
A11: Perfect warning: value | B11: 4.1179818 | C11: $4.12 million
A12: Perfect warning: fresh cost | B12: 6.3253258 | C12: $6.33 million
A13: The declared law: beta, bond | B13: -0.32319369 | C13: Remark 13.B.1
... A204: Table 13.3, Boosting, held-out: fresh value | B204: 0.59083363 | C204: Table 13.3

Sheet Checks
A1: Checkpoint | B1: Workbook formula value | C1: Engine value | D1: |diff| | E1: Tolerance | F1: Status
A2: A closure ahead under the law | B2: =PClose -> 0.25918178 | C2: =Reference_Values!B2 -> 0.25918178 | D2: =ABS(B2-C2) -> 0 | E2: 1e-12 | F2: =IF(D2<=E2,"PASS","FAIL") -> PASS
A3: Volume I's package: cost | B3: =CostV1 -> 10.440611 | C3: =Reference_Values!B3 -> 10.440611 | D3: =ABS(B3-C3) -> 0 | E3: 1e-09 | F3: =IF(D3<=E3,"PASS","FAIL") -> PASS
A4: No warning: chance of a breach on the book's paths | B4: =Designs!X5 -> 0.05 | C4: =Reference_Values!B4 -> 0.05 | D4: =ABS(B4-C4) -> 0 | E4: 1e-12 | F4: =IF(D4<=E4,"PASS","FAIL") -> PASS
A5: No warning: chance on the fresh paths | B5: =Designs!AC5 -> 0.04907 | C5: =Reference_Values!B5 -> 0.04907 | D5: =ABS(B5-C5) -> 0 | E5: 1e-12 | F5: =IF(D5<=E5,"PASS","FAIL") -> PASS
A6: Perfect warning: all-clear cost | B6: =Designs!L6 -> 4.8668342 | C6: =Reference_Values!B6 -> 4.8668342 | D6: =ABS(B6-C6) -> 0 | E6: 1e-09 | F6: =IF(D6<=E6,"PASS","FAIL") -> PASS
A7: Perfect warning: warned cost | B7: =Designs!O6 -> 10.485061 | C7: =Reference_Values!B7 -> 10.485061 | D7: =ABS(B7-C7) -> 4.6185278e-14 | E7: 1e-09 | F7: =IF(D7<=E7,"PASS","FAIL") -> PASS
A8: Perfect warning: all-clear chance | B8: =Designs!V6 -> 0.04749757 | C8: =Reference_Values!B8 -> 0.04749757 | D8: =ABS(B8-C8) -> 0 | E8: 1e-12 | F8: =IF(D8<=E8,"PASS","FAIL") -> PASS
A9: Perfect warning: warned chance | B9: =Designs!W6 -> 0.057116394 | C9: =Reference_Values!B9 -> 0.057116394 | D9: =ABS(B9-C9) -> 0 | E9: 1e-12 | F9: =IF(D9<=E9,"PASS","FAIL") -> PASS
A10: Perfect warning: expected cost | B10: =Designs!P6 -> 6.3226291 | C10: =Reference_Values!B10 -> 6.3226291 | D10: =ABS(B10-C10) -> 0 | E10: 1e-09 | F10: =IF(D10<=E10,"PASS","FAIL") -> PASS
A11: Perfect warning: value | B11: =Designs!Q6 -> 4.1179818 | C11: =Reference_Values!B11 -> 4.1179818 | D11: =ABS(B11-C11) -> 0 | E11: 1e-09 | F11: =IF(D11<=E11,"PASS","FAIL") -> PASS
A12: Perfect warning: fresh cost | B12: =Designs!AD6 -> 6.3253258 | C12: =Reference_Values!B12 -> 6.3253258 | D12: =ABS(B12-C12) -> 0 | E12: 1e-09 | F12: =IF(D12<=E12,"PASS","FAIL") -> PASS
A13: The declared law: beta, bond | B13: =Law!B18 -> -0.32319369 | C13: =Reference_Values!B13 -> -0.32319369 | D13: =ABS(B13-C13) -> 0 | E13: 1e-09 | F13: =IF(D13<=E13,"PASS","FAIL") -> PASS
A14: The declared law: beta, high yield | B14: =Law!C18 -> -0.15894207 | C14: =Reference_Values!B14 -> -0.15894207 | D14: =ABS(B14-C14) -> 0 | E14: 1e-09 | F14: =IF(D14<=E14,"PASS","FAIL") -> PASS
A15: The declared law: beta, volatility | B15: =Law!D18 -> -0.35223902 | C15: =Reference_Values!B15 -> -0.35223902 | D15: =ABS(B15-C15) -> 0 | E15: 1e-09 | F15: =IF(D15<=E15,"PASS","FAIL") -> PASS
A16: The declared law: beta, lending | B16: =Law!E18 -> 0.76936792 | C16: =Reference_Values!B16 -> 0.76936792 | D16: =ABS(B16-C16) -> 0 | E16: 1e-09 | F16: =IF(D16<=E16,"PASS","FAIL") -> PASS
A17: The declared law: beta, funding | B17: =Law!F18 -> 1.9738437 | C17: =Reference_Values!B17 -> 1.9738437 | D17: =ABS(B17-C17) -> 0 | E17: 1e-09 | F17: =IF(D17<=E17,"PASS","FAIL") -> PASS
A18: The declared law: separation Delta | B18: =Law!B19 -> 2.0286672 | C18: =Reference_Values!B18 -> 2.0286672 | D18: =ABS(B18-C18) -> 0 | E18: 1e-09 | F18: =IF(D18<=E18,"PASS","FAIL") -> PASS
A19: The declared law: AUC | B19: =Law!B20 -> 0.92428295 | C19: =Reference_Values!B19 -> 0.92428295 | D19: =ABS(B19-C19) -> 0 | E19: 1e-09 | F19: =IF(D19<=E19,"PASS","FAIL") -> PASS
A20: Ceiling: share warned | B20: =Law!B28 -> 0.58863946 | C20: =Reference_Values!B20 -> 0.58863946 | D20: =ABS(B20-C20) -> 0 | E20: 1e-09 | F20: =IF(D20<=E20,"PASS","FAIL") -> PASS
A21: Ceiling: closure share, warned | B21: =Law!B29 -> 0.42796889 | C21: =Reference_Values!B21 -> 0.42796889 | D21: =ABS(B21-C21) -> 0 | E21: 1e-09 | F21: =IF(D21<=E21,"PASS","FAIL") -> PASS
A22: Ceiling: closure share, all clear | B22: =Law!B30 -> 0.017504417 | C22: =Reference_Values!B22 -> 0.017504417 | D22: =ABS(B22-C22) -> 0 | E22: 1e-09 | F22: =IF(D22<=E22,"PASS","FAIL") -> PASS
A23: Ceiling: all-clear cost | B23: =Designs!L7 -> 5.3660826 | C23: =Reference_Values!B23 -> 5.3660826 | D23: =ABS(B23-C23) -> 0 | E23: 1e-09 | F23: =IF(D23<=E23,"PASS","FAIL") -> PASS
A24: Ceiling: warned cost | B24: =Designs!O7 -> 11.545836 | C24: =Reference_Values!B24 -> 11.545836 | D24: =ABS(B24-C24) -> 0 | E24: 1e-09 | F24: =IF(D24<=E24,"PASS","FAIL") -> PASS
A25: Ceiling: expected cost | B25: =Designs!P7 -> 9.0037291 | C25: =Reference_Values!B25 -> 9.0037291 | D25: =ABS(B25-C25) -> 0 | E25: 1e-07 | F25: =IF(D25<=E25,"PASS","FAIL") -> PASS
A26: Ceiling: value | B26: =Designs!Q7 -> 1.4368818 | C26: =Reference_Values!B26 -> 1.4368818 | D26: =ABS(B26-C26) -> 5.1070259e-15 | E26: 1e-07 | F26: =IF(D26<=E26,"PASS","FAIL") -> PASS
A27: Ceiling: the design's chance of a breach | B27: =Designs!X7 -> 0.049990371 | C27: =Reference_Values!B27 -> 0.049990371 | D27: =ABS(B27-C27) -> 0 | E27: 1e-09 | F27: =IF(D27<=E27,"PASS","FAIL") -> PASS
A28: Ceiling: fresh programs warned | B28: =Designs!Z7 -> 0.5894 | C28: =Reference_Values!B28 -> 0.5894 | D28: =ABS(B28-C28) -> 0 | E28: 1e-12 | F28: =IF(D28<=E28,"PASS","FAIL") -> PASS
A29: Ceiling: fresh chance of a breach | B29: =Designs!AC7 -> 0.04898 | C29: =Reference_Values!B29 -> 0.04898 | D29: =ABS(B29-C29) -> 0 | E29: 1e-12 | F29: =IF(D29<=E29,"PASS","FAIL") -> PASS
A30: Ceiling: fresh value | B30: =Designs!AE7 -> 1.4321818 | C30: =Reference_Values!B30 -> 1.4321818 | D30: =ABS(B30-C30) -> 0 | E30: 1e-09 | F30: =IF(D30<=E30,"PASS","FAIL") -> PASS
A31: Value against AUC: AUC with the shifts x 0.25 | B31: =Law!C40 -> 0.64006072 | C31: =Reference_Values!B31 -> 0.64006072 | D31: =ABS(B31-C31) -> 0 | E31: 1e-09 | F31: =IF(D31<=E31,"PASS","FAIL") -> PASS
A32: Value against AUC: AUC with the shifts x 0.5 | B32: =Law!C41 -> 0.76338766 | C32: =Reference_Values!B32 -> 0.76338766 | D32: =ABS(B32-C32) -> 0 | E32: 1e-09 | F32: =IF(D32<=E32,"PASS","FAIL") -> PASS
A33: Value against AUC: AUC with the shifts x 0.75 | B33: =Law!C42 -> 0.85900579 | C33: =Reference_Values!B33 -> 0.85900579 | D33: =ABS(B33-C33) -> 0 | E33: 1e-09 | F33: =IF(D33<=E33,"PASS","FAIL") -> PASS
A34: Value against AUC: AUC with the shifts x 1 | B34: =Law!C43 -> 0.92428295 | C34: =Reference_Values!B34 -> 0.92428295 | D34: =ABS(B34-C34) -> 0 | E34: 1e-09 | F34: =IF(D34<=E34,"PASS","FAIL") -> PASS
A35: Value against AUC: AUC with the shifts x 1.25 | B35: =Law!C44 -> 0.96352197 | C35: =Reference_Values!B35 -> 0.96352197 | D35: =ABS(B35-C35) -> 0 | E35: 1e-09 | F35: =IF(D35<=E35,"PASS","FAIL") -> PASS
A36: Value against AUC: AUC with the shifts x 1.5 | B36: =Law!C45 -> 0.98429055 | C36: =Reference_Values!B36 -> 0.98429055 | D36: =ABS(B36-C36) -> 0 | E36: 1e-09 | F36: =IF(D36<=E36,"PASS","FAIL") -> PASS
A37: Value against AUC: AUC with the shifts x 2 | B37: =Law!C46 -> 0.99794094 | C37: =Reference_Values!B37 -> 0.99794094 | D37: =ABS(B37-C37) -> 0 | E37: 1e-09 | F37: =IF(D37<=E37,"PASS","FAIL") -> PASS
A38: Value against AUC: AUC with the shifts x 2.5 | B38: =Law!C47 -> 0.99983224 | C38: =Reference_Values!B38 -> 0.99983224 | D38: =ABS(B38-C38) -> 0 | E38: 1e-09 | F38: =IF(D38<=E38,"PASS","FAIL") -> PASS
A39: Value against AUC: AUC with the shifts x 3 | B39: =Law!C48 -> 0.99999159 | C39: =Reference_Values!B39 -> 0.99999159 | D39: =ABS(B39-C39) -> 0 | E39: 1e-09 | F39: =IF(D39<=E39,"PASS","FAIL") -> PASS
A40: Value against AUC: AUC with the shifts x 4 | B40: =Law!C49 -> 1 | C40: =Reference_Values!B40 -> 1 | D40: =ABS(B40-C40) -> 0 | E40: 1e-09 | F40: =IF(D40<=E40,"PASS","FAIL") -> PASS
...
