Workbook

Sheet README
B1: DCT Laboratory — Vol I, Ch 9: Enterprise State Architecture
B2: Seed 26109 · Companion to DCT_V1_Ch09_Lab.ipynb and AXIOM Lab 1.9 (module AXIOM-09). Money in $ million.
B4: Worked Example 9.1, How Fast Can a Demand Shock Reach the Covenant?, with the book's declarations, and the five steps of AXIOM Lab 1.9, Wiring Meridian.
B5: Declarations: the seven components, the fourteen typed arrows and the constraints with their scopes (Tables 9.1-9.3; Figure 9.1). Change an arrow or a scope and every sheet recalculates.
B6: Wiring: the adjacency matrix, the interface check, the counts, density and cycle measure (lab step 1).
B7: Core: routes of each length, reachability, the strongly connected components, the causal layers, the loops inside the core, and Online Appendix 9.B.1's offsetting channels (lab step 2).
B8: Shock: Table 9.7's distances and shortest routes, the wavefront, the path counter, and a positive linear company whose arrows can be switched off (lab step 3).
B9: Paths: every simple path from the market to treasury and every cut of one, two or three arrows.
B10: SummaryMap: the two-box map and the causal map, with the connections each invents (lab step 4).
B11: Constraints: the constraint graph, its cycle measure and its joint review; the planning rules and the carve-out timetable by the cycle test; the strategic-risk peak on the digital plan (lab step 5).
B12: Metrics: the complexity panel (Table 9.5) and the validation checklist (Table 9.4). WhatIf: treasury funds Materials.
B13: Engine values (green) are the sensitivities the notebook drew with the lab's seed and the paths it enumerated. Reference_Values and Checks: the notebook engine's numbers and a PASS/FAIL comparison.
... B19: Cross-sheet link: green.

Sheet Declarations
A1: Declarations (Worked Example 9.1, Step 1; Tables 9.1-9.3). Money in $ million; the model runs in quarters.
A3: Component | B3: Name | C3: Org chart (two-box map) | D3: Interface: readings it exposes | E3: Source
A4: MKT | B4: Market | C4: market | D4: demand | E4: named by the arrow's type
A5: GOV | B5: Governance | C5: center | D5: policy | E5: named by the arrow's type
A6: MAT | B6: Materials | C6: divisions | D6: cash and EBITDA | E6: Step 1: the divisions report cash and EBITDA along the cash arrows
A7: IND | B7: Industrial Systems | C7: divisions | D7: cash and EBITDA; capability | E7: named by the arrow's type
A8: DIG | B8: Digital | C8: divisions | D8: cash and EBITDA; capability | E8: named by the arrow's type
A9: ENG | B9: Shared engineering | C9: center | D9: workforce-capability index | E9: Table 9.1: engineering exposes the workforce-capability index
A10: TRS | B10: Treasury | C10: center | D10: funding capacity | E10: Table 9.1: treasury exposes funding capacity
A12: Arrow | B12: From | C12: To | D12: Type | E12: Class (Table 9.2) | F12: Reading carried | G12: Source exposes it (1 = yes)
A13: 1 | B13: MKT | C13: IND | D13: demand | E13: =VLOOKUP(D13,$A$30:$C$34,2,FALSE()) -> dynamic | F13: =IF(D13="capability",IF(B13="ENG","workforce-capability index","capability"),VLOOKUP(D13,$A$30:$C$34,3,FALSE())) -> demand | G13: =IF(ISNUMBER(SEARCH("; "&F13&";","; "&VLOOKUP(B13,$A$4:$D$10,4,FALSE())&";")),1,0) -> 1
A14: 2 | B14: MKT | C14: DIG | D14: demand | E14: =VLOOKUP(D14,$A$30:$C$34,2,FALSE()) -> dynamic | F14: =IF(D14="capability",IF(B14="ENG","workforce-capability index","capability"),VLOOKUP(D14,$A$30:$C$34,3,FALSE())) -> demand | G14: =IF(ISNUMBER(SEARCH("; "&F14&";","; "&VLOOKUP(B14,$A$4:$D$10,4,FALSE())&";")),1,0) -> 1
A15: 3 | B15: MKT | C15: MAT | D15: demand | E15: =VLOOKUP(D15,$A$30:$C$34,2,FALSE()) -> dynamic | F15: =IF(D15="capability",IF(B15="ENG","workforce-capability index","capability"),VLOOKUP(D15,$A$30:$C$34,3,FALSE())) -> demand | G15: =IF(ISNUMBER(SEARCH("; "&F15&";","; "&VLOOKUP(B15,$A$4:$D$10,4,FALSE())&";")),1,0) -> 1
A16: 4 | B16: IND | C16: TRS | D16: cash | E16: =VLOOKUP(D16,$A$30:$C$34,2,FALSE()) -> resource flow | F16: =IF(D16="capability",IF(B16="ENG","workforce-capability index","capability"),VLOOKUP(D16,$A$30:$C$34,3,FALSE())) -> cash and EBITDA | G16: =IF(ISNUMBER(SEARCH("; "&F16&";","; "&VLOOKUP(B16,$A$4:$D$10,4,FALSE())&";")),1,0) -> 1
A17: 5 | B17: DIG | C17: TRS | D17: cash | E17: =VLOOKUP(D17,$A$30:$C$34,2,FALSE()) -> resource flow | F17: =IF(D17="capability",IF(B17="ENG","workforce-capability index","capability"),VLOOKUP(D17,$A$30:$C$34,3,FALSE())) -> cash and EBITDA | G17: =IF(ISNUMBER(SEARCH("; "&F17&";","; "&VLOOKUP(B17,$A$4:$D$10,4,FALSE())&";")),1,0) -> 1
A18: 6 | B18: MAT | C18: TRS | D18: cash | E18: =VLOOKUP(D18,$A$30:$C$34,2,FALSE()) -> resource flow | F18: =IF(D18="capability",IF(B18="ENG","workforce-capability index","capability"),VLOOKUP(D18,$A$30:$C$34,3,FALSE())) -> cash and EBITDA | G18: =IF(ISNUMBER(SEARCH("; "&F18&";","; "&VLOOKUP(B18,$A$4:$D$10,4,FALSE())&";")),1,0) -> 1
A19: 7 | B19: TRS | C19: IND | D19: funding | E19: =VLOOKUP(D19,$A$30:$C$34,2,FALSE()) -> resource flow | F19: =IF(D19="capability",IF(B19="ENG","workforce-capability index","capability"),VLOOKUP(D19,$A$30:$C$34,3,FALSE())) -> funding capacity | G19: =IF(ISNUMBER(SEARCH("; "&F19&";","; "&VLOOKUP(B19,$A$4:$D$10,4,FALSE())&";")),1,0) -> 1
A20: 8 | B20: TRS | C20: DIG | D20: funding | E20: =VLOOKUP(D20,$A$30:$C$34,2,FALSE()) -> resource flow | F20: =IF(D20="capability",IF(B20="ENG","workforce-capability index","capability"),VLOOKUP(D20,$A$30:$C$34,3,FALSE())) -> funding capacity | G20: =IF(ISNUMBER(SEARCH("; "&F20&";","; "&VLOOKUP(B20,$A$4:$D$10,4,FALSE())&";")),1,0) -> 1
A21: 9 | B21: ENG | C21: IND | D21: capability | E21: =VLOOKUP(D21,$A$30:$C$34,2,FALSE()) -> resource flow | F21: =IF(D21="capability",IF(B21="ENG","workforce-capability index","capability"),VLOOKUP(D21,$A$30:$C$34,3,FALSE())) -> workforce-capability index | G21: =IF(ISNUMBER(SEARCH("; "&F21&";","; "&VLOOKUP(B21,$A$4:$D$10,4,FALSE())&";")),1,0) -> 1
A22: 10 | B22: IND | C22: ENG | D22: capability | E22: =VLOOKUP(D22,$A$30:$C$34,2,FALSE()) -> resource flow | F22: =IF(D22="capability",IF(B22="ENG","workforce-capability index","capability"),VLOOKUP(D22,$A$30:$C$34,3,FALSE())) -> capability | G22: =IF(ISNUMBER(SEARCH("; "&F22&";","; "&VLOOKUP(B22,$A$4:$D$10,4,FALSE())&";")),1,0) -> 1
A23: 11 | B23: ENG | C23: DIG | D23: capability | E23: =VLOOKUP(D23,$A$30:$C$34,2,FALSE()) -> resource flow | F23: =IF(D23="capability",IF(B23="ENG","workforce-capability index","capability"),VLOOKUP(D23,$A$30:$C$34,3,FALSE())) -> workforce-capability index | G23: =IF(ISNUMBER(SEARCH("; "&F23&";","; "&VLOOKUP(B23,$A$4:$D$10,4,FALSE())&";")),1,0) -> 1
A24: 12 | B24: DIG | C24: ENG | D24: capability | E24: =VLOOKUP(D24,$A$30:$C$34,2,FALSE()) -> resource flow | F24: =IF(D24="capability",IF(B24="ENG","workforce-capability index","capability"),VLOOKUP(D24,$A$30:$C$34,3,FALSE())) -> capability | G24: =IF(ISNUMBER(SEARCH("; "&F24&";","; "&VLOOKUP(B24,$A$4:$D$10,4,FALSE())&";")),1,0) -> 1
... A26: 14 | B26: GOV | C26: DIG | D26: policy | E26: =VLOOKUP(D26,$A$30:$C$34,2,FALSE()) -> informational | F26: =IF(D26="capability",IF(B26="ENG","workforce-capability index","capability"),VLOOKUP(D26,$A$30:$C$34,3,FALSE())) -> policy | G26: =IF(ISNUMBER(SEARCH("; "&F26&";","; "&VLOOKUP(B26,$A$4:$D$10,4,FALSE())&";")),1,0) -> 1
A29: Arrow type | B29: Class (Table 9.2) | C29: Reading carried
A30: demand | B30: dynamic | C30: demand
A31: cash | B31: resource flow | C31: cash and EBITDA
A32: funding | B32: resource flow | C32: funding capacity
A33: capability | B33: resource flow | C33: capability | D33: Capability arrows from engineering carry the workforce-capability index (Table 9.1).
A34: policy | B34: informational | C34: policy
A35: Constraint (Table 9.3) | B35: MKT | C35: GOV | D35: MAT | E35: IND | F35: DIG | G35: ENG | H35: TRS | I35: Components in scope | J35: Class (Table 9.3) | K35: Limit | L35: Who can change it
A36: Loan covenant: net leverage at most 4.5x EBITDA | B36: 0 | C36: 0 | D36: 0 | E36: 0 | F36: 0 | G36: 0 | H36: 1 | I36: =SUM(B36:H36) -> 1 | J36: =IF(I36=1,"local",IF(I36=2,"pairwise coupling","group coupling")) -> local | K36: 4.5 | L36: only the lenders (Table 5.4)
A37: Liquidity floor: at least $350 million | B37: 0 | C37: 0 | D37: 0 | E37: 0 | F37: 0 | G37: 0 | H37: 1 | I37: =SUM(B37:H37) -> 1 | J37: =IF(I37=1,"local",IF(I37=2,"pairwise coupling","group coupling")) -> local | K37: 350 | L37: the board: a revisable policy
A38: Plant capacity | B38: 0 | C38: 0 | D38: 0 | E38: 1 | F38: 0 | G38: 0 | H38: 0 | I38: =SUM(B38:H38) -> 1 | J38: =IF(I38=1,"local",IF(I38=2,"pairwise coupling","group coupling")) -> local | L38: a physical limit (Table 5.4)
A39: Strategic-risk ceiling | B39: 0 | C39: 0 | D39: 1 | E39: 1 | F39: 1 | G39: 0 | H39: 0 | I39: =SUM(B39:H39) -> 3 | J39: =IF(I39=1,"local",IF(I39=2,"pairwise coupling","group coupling")) -> group coupling | K39: 75 | L39: the board: a revisable policy
A40: Workforce capability for the digital build | B40: 0 | C40: 0 | D40: 0 | E40: 0 | F40: 1 | G40: 1 | H40: 0 | I40: =SUM(B40:H40) -> 2 | J40: =IF(I40=1,"local",IF(I40=2,"pairwise coupling","group coupling")) -> pairwise coupling | K40: 55 | L40: the digital build (Worked Example 3.1)
A41: Index bounds are local too (Table 9.3); local constraints add no link to the constraint graph.
A43: Declared value | B43: Value | C43: Source
A44: Strategic-risk ceiling | B44: 75 | C44: Table 5.4: a board policy
A45: Risk committee's measurement error (+/-) | B45: 6 | C45: Table 5.2
A46: Strategic risk today | B46: 64 | C46: Table 3.1
...

Sheet Wiring
A1: Declare the architecture: the dependency graph and its counts (Worked Example 9.1, Step 1; Definitions 9.1-9.3; AXIOM Lab 1.9, step 1)
A2: Rows send, columns receive: A = 1 where an arrow runs from the row's component to the column's. Everything below recalculates from the arrow list on Declarations.
A4: Adjacency A (Figure 9.1)
A5: from \ to | B5: MKT | C5: GOV | D5: MAT | E5: IND | F5: DIG | G5: ENG | H5: TRS | I5: out-degree | K5: Quantity | L5: Value | M5: Reading
A6: MKT | B6: =IF(COUNTIFS(Arr_from,$A6,Arr_to,B$5)>0,1,0) -> 0 | C6: =IF(COUNTIFS(Arr_from,$A6,Arr_to,C$5)>0,1,0) -> 0 | D6: =IF(COUNTIFS(Arr_from,$A6,Arr_to,D$5)>0,1,0) -> 1 | E6: =IF(COUNTIFS(Arr_from,$A6,Arr_to,E$5)>0,1,0) -> 1 | F6: =IF(COUNTIFS(Arr_from,$A6,Arr_to,F$5)>0,1,0) -> 1 | G6: =IF(COUNTIFS(Arr_from,$A6,Arr_to,G$5)>0,1,0) -> 0 | H6: =IF(COUNTIFS(Arr_from,$A6,Arr_to,H$5)>0,1,0) -> 0 | I6: =SUM($B$6:$H$6) -> 3 | K6: Components |V| | L6: =COUNTA(Comp) -> 7 | M6: Table 9.1: seven
A7: GOV | B7: =IF(COUNTIFS(Arr_from,$A7,Arr_to,B$5)>0,1,0) -> 0 | C7: =IF(COUNTIFS(Arr_from,$A7,Arr_to,C$5)>0,1,0) -> 0 | D7: =IF(COUNTIFS(Arr_from,$A7,Arr_to,D$5)>0,1,0) -> 0 | E7: =IF(COUNTIFS(Arr_from,$A7,Arr_to,E$5)>0,1,0) -> 0 | F7: =IF(COUNTIFS(Arr_from,$A7,Arr_to,F$5)>0,1,0) -> 1 | G7: =IF(COUNTIFS(Arr_from,$A7,Arr_to,G$5)>0,1,0) -> 0 | H7: =IF(COUNTIFS(Arr_from,$A7,Arr_to,H$5)>0,1,0) -> 1 | I7: =SUM($B$7:$H$7) -> 2 | K7: Arrows |E| | L7: =SUM($B$6:$H$12) -> 14 | M7: Figure 9.1: fourteen
A8: MAT | B8: =IF(COUNTIFS(Arr_from,$A8,Arr_to,B$5)>0,1,0) -> 0 | C8: =IF(COUNTIFS(Arr_from,$A8,Arr_to,C$5)>0,1,0) -> 0 | D8: =IF(COUNTIFS(Arr_from,$A8,Arr_to,D$5)>0,1,0) -> 0 | E8: =IF(COUNTIFS(Arr_from,$A8,Arr_to,E$5)>0,1,0) -> 0 | F8: =IF(COUNTIFS(Arr_from,$A8,Arr_to,F$5)>0,1,0) -> 0 | G8: =IF(COUNTIFS(Arr_from,$A8,Arr_to,G$5)>0,1,0) -> 0 | H8: =IF(COUNTIFS(Arr_from,$A8,Arr_to,H$5)>0,1,0) -> 1 | I8: =SUM($B$8:$H$8) -> 1 | K8: Possible arrows |V|(|V| - 1) | L8: =L6*(L6-1) -> 42
A9: IND | B9: =IF(COUNTIFS(Arr_from,$A9,Arr_to,B$5)>0,1,0) -> 0 | C9: =IF(COUNTIFS(Arr_from,$A9,Arr_to,C$5)>0,1,0) -> 0 | D9: =IF(COUNTIFS(Arr_from,$A9,Arr_to,D$5)>0,1,0) -> 0 | E9: =IF(COUNTIFS(Arr_from,$A9,Arr_to,E$5)>0,1,0) -> 0 | F9: =IF(COUNTIFS(Arr_from,$A9,Arr_to,F$5)>0,1,0) -> 0 | G9: =IF(COUNTIFS(Arr_from,$A9,Arr_to,G$5)>0,1,0) -> 1 | H9: =IF(COUNTIFS(Arr_from,$A9,Arr_to,H$5)>0,1,0) -> 1 | I9: =SUM($B$9:$H$9) -> 2 | K9: Density |E| / (|V|(|V| - 1)) | L9: =L7/L8 -> 0.33333333 | M9: Section 9.8: 14/42 = 0.33
A10: DIG | B10: =IF(COUNTIFS(Arr_from,$A10,Arr_to,B$5)>0,1,0) -> 0 | C10: =IF(COUNTIFS(Arr_from,$A10,Arr_to,C$5)>0,1,0) -> 0 | D10: =IF(COUNTIFS(Arr_from,$A10,Arr_to,D$5)>0,1,0) -> 0 | E10: =IF(COUNTIFS(Arr_from,$A10,Arr_to,E$5)>0,1,0) -> 0 | F10: =IF(COUNTIFS(Arr_from,$A10,Arr_to,F$5)>0,1,0) -> 0 | G10: =IF(COUNTIFS(Arr_from,$A10,Arr_to,G$5)>0,1,0) -> 1 | H10: =IF(COUNTIFS(Arr_from,$A10,Arr_to,H$5)>0,1,0) -> 1 | I10: =SUM($B$10:$H$10) -> 2 | K10: Two-way relationships | L10: =SUMPRODUCT($B$6:$H$12,$B$18:$H$24)/2 -> 4 | M10: cash and funding with treasury; capability
A11: ENG | B11: =IF(COUNTIFS(Arr_from,$A11,Arr_to,B$5)>0,1,0) -> 0 | C11: =IF(COUNTIFS(Arr_from,$A11,Arr_to,C$5)>0,1,0) -> 0 | D11: =IF(COUNTIFS(Arr_from,$A11,Arr_to,D$5)>0,1,0) -> 0 | E11: =IF(COUNTIFS(Arr_from,$A11,Arr_to,E$5)>0,1,0) -> 1 | F11: =IF(COUNTIFS(Arr_from,$A11,Arr_to,F$5)>0,1,0) -> 1 | G11: =IF(COUNTIFS(Arr_from,$A11,Arr_to,G$5)>0,1,0) -> 0 | H11: =IF(COUNTIFS(Arr_from,$A11,Arr_to,H$5)>0,1,0) -> 0 | I11: =SUM($B$11:$H$11) -> 2 | K11: Pairs joined, directions ignored | L11: =L7-L10 -> 10
A12: TRS | B12: =IF(COUNTIFS(Arr_from,$A12,Arr_to,B$5)>0,1,0) -> 0 | C12: =IF(COUNTIFS(Arr_from,$A12,Arr_to,C$5)>0,1,0) -> 0 | D12: =IF(COUNTIFS(Arr_from,$A12,Arr_to,D$5)>0,1,0) -> 0 | E12: =IF(COUNTIFS(Arr_from,$A12,Arr_to,E$5)>0,1,0) -> 1 | F12: =IF(COUNTIFS(Arr_from,$A12,Arr_to,F$5)>0,1,0) -> 1 | G12: =IF(COUNTIFS(Arr_from,$A12,Arr_to,G$5)>0,1,0) -> 0 | H12: =IF(COUNTIFS(Arr_from,$A12,Arr_to,H$5)>0,1,0) -> 0 | I12: =SUM($B$12:$H$12) -> 2 | K12: Separate pieces p, directions ignored | L12: =SUMPRODUCT(1/I73:I79) -> 1 | M12: one piece
A13: in-degree | B13: =SUM($B$6:$B$12) -> 0 | C13: =SUM($C$6:$C$12) -> 0 | D13: =SUM($D$6:$D$12) -> 1 | E13: =SUM($E$6:$E$12) -> 3 | F13: =SUM($F$6:$F$12) -> 4 | G13: =SUM($G$6:$G$12) -> 2 | H13: =SUM($H$6:$H$12) -> 4 | K13: Cycle measure beta = |E| - |V| + p | L13: =L7-L6+L12 -> 8 | M13: Section 9.8: 14 - 7 + 1 = 8
K14: loops from the two-way relationships | L14: =L10 -> 4 | M14: Online Appendix 9.B.7: four
K15: loops with directions ignored | L15: =L11-L6+L12 -> 4 | M15: and the remaining four
A16: A transposed (the same arrows, columns sending) | K16: Missing arrows: claims of independence | L16: =L8-L7 -> 28
A17: to \ from | B17: MKT | C17: GOV | D17: MAT | E17: IND | F17: DIG | G17: ENG | H17: TRS | K17: Arrows into the market | L17: =B13 -> 0 | M17: nothing Meridian does moves its demand
A18: MKT | B18: =$B$6 -> 0 | C18: =$B$7 -> 0 | D18: =$B$8 -> 0 | E18: =$B$9 -> 0 | F18: =$B$10 -> 0 | G18: =$B$11 -> 0 | H18: =$B$12 -> 0 | K18: Arrows into governance | L18: =C13 -> 0
A19: GOV | B19: =$C$6 -> 0 | C19: =$C$7 -> 0 | D19: =$C$8 -> 0 | E19: =$C$9 -> 0 | F19: =$C$10 -> 0 | G19: =$C$11 -> 0 | H19: =$C$12 -> 0 | K19: Funding arrows into Materials | L19: =COUNTIFS(Arr_to,"MAT",Arr_type,"funding") -> 0 | M19: Materials funds itself
A20: MAT | B20: =$D$6 -> 1 | C20: =$D$7 -> 0 | D20: =$D$8 -> 0 | E20: =$D$9 -> 0 | F20: =$D$10 -> 0 | G20: =$D$11 -> 0 | H20: =$D$12 -> 0 | K20: Arrows interface-backed | L20: =SUM(Declarations!$G$13:$G$26) -> 14 | M20: every one: the components assemble
A21: IND | B21: =$E$6 -> 1 | C21: =$E$7 -> 0 | D21: =$E$8 -> 0 | E21: =$E$9 -> 0 | F21: =$E$10 -> 0 | G21: =$E$11 -> 1 | H21: =$E$12 -> 1 | K21: Demand arrows | L21: =COUNTIF(Arr_type,"demand") -> 3 | M21: market to each division
A22: DIG | B22: =$F$6 -> 1 | C22: =$F$7 -> 1 | D22: =$F$8 -> 0 | E22: =$F$9 -> 0 | F22: =$F$10 -> 0 | G22: =$F$11 -> 1 | H22: =$F$12 -> 1 | K22: Cash arrows | L22: =COUNTIF(Arr_type,"cash") -> 3 | M22: each division to treasury
A23: ENG | B23: =$G$6 -> 0 | C23: =$G$7 -> 0 | D23: =$G$8 -> 0 | E23: =$G$9 -> 1 | F23: =$G$10 -> 1 | G23: =$G$11 -> 0 | H23: =$G$12 -> 0 | K23: Funding arrows | L23: =COUNTIF(Arr_type,"funding") -> 2 | M23: treasury to IND and DIG
A24: TRS | B24: =$H$6 -> 0 | C24: =$H$7 -> 1 | D24: =$H$8 -> 1 | E24: =$H$9 -> 1 | F24: =$H$10 -> 1 | G24: =$H$11 -> 0 | H24: =$H$12 -> 0 | K24: Capability arrows | L24: =COUNTIF(Arr_type,"capability") -> 4 | M24: both ways, engineering with IND and DIG
K25: Policy arrows | L25: =COUNTIF(Arr_type,"policy") -> 2 | M25: governance to treasury and Digital
A27: Joined in either direction, SIGN(A + transposed): directions ignored
B28: MKT | C28: GOV | D28: MAT | E28: IND | F28: DIG | G28: ENG | H28: TRS
A29: MKT | B29: =SIGN($B$6+$B$18) -> 0 | C29: =SIGN($C$6+$C$18) -> 0 | D29: =SIGN($D$6+$D$18) -> 1 | E29: =SIGN($E$6+$E$18) -> 1 | F29: =SIGN($F$6+$F$18) -> 1 | G29: =SIGN($G$6+$G$18) -> 0 | H29: =SIGN($H$6+$H$18) -> 0
A30: GOV | B30: =SIGN($B$7+$B$19) -> 0 | C30: =SIGN($C$7+$C$19) -> 0 | D30: =SIGN($D$7+$D$19) -> 0 | E30: =SIGN($E$7+$E$19) -> 0 | F30: =SIGN($F$7+$F$19) -> 1 | G30: =SIGN($G$7+$G$19) -> 0 | H30: =SIGN($H$7+$H$19) -> 1
A31: MAT | B31: =SIGN($B$8+$B$20) -> 1 | C31: =SIGN($C$8+$C$20) -> 0 | D31: =SIGN($D$8+$D$20) -> 0 | E31: =SIGN($E$8+$E$20) -> 0 | F31: =SIGN($F$8+$F$20) -> 0 | G31: =SIGN($G$8+$G$20) -> 0 | H31: =SIGN($H$8+$H$20) -> 1
A32: IND | B32: =SIGN($B$9+$B$21) -> 1 | C32: =SIGN($C$9+$C$21) -> 0 | D32: =SIGN($D$9+$D$21) -> 0 | E32: =SIGN($E$9+$E$21) -> 0 | F32: =SIGN($F$9+$F$21) -> 0 | G32: =SIGN($G$9+$G$21) -> 1 | H32: =SIGN($H$9+$H$21) -> 1
A33: DIG | B33: =SIGN($B$10+$B$22) -> 1 | C33: =SIGN($C$10+$C$22) -> 1 | D33: =SIGN($D$10+$D$22) -> 0 | E33: =SIGN($E$10+$E$22) -> 0 | F33: =SIGN($F$10+$F$22) -> 0 | G33: =SIGN($G$10+$G$22) -> 1 | H33: =SIGN($H$10+$H$22) -> 1
A34: ENG | B34: =SIGN($B$11+$B$23) -> 0 | C34: =SIGN($C$11+$C$23) -> 0 | D34: =SIGN($D$11+$D$23) -> 0 | E34: =SIGN($E$11+$E$23) -> 1 | F34: =SIGN($F$11+$F$23) -> 1 | G34: =SIGN($G$11+$G$23) -> 0 | H34: =SIGN($H$11+$H$23) -> 0
A35: TRS | B35: =SIGN($B$12+$B$24) -> 0 | C35: =SIGN($C$12+$C$24) -> 1 | D35: =SIGN($D$12+$D$24) -> 1 | E35: =SIGN($E$12+$E$24) -> 1 | F35: =SIGN($F$12+$F$24) -> 1 | G35: =SIGN($G$12+$G$24) -> 0 | H35: =SIGN($H$12+$H$24) -> 0
A38: I + U: a component joined to itself and its neighbors
B39: MKT | C39: GOV | D39: MAT | E39: IND | F39: DIG | G39: ENG | H39: TRS
A40: MKT | B40: 1 | C40: =$C$29 -> 0 | D40: =$D$29 -> 1 | E40: =$E$29 -> 1 | F40: =$F$29 -> 1 | G40: =$G$29 -> 0 | H40: =$H$29 -> 0
A41: GOV | B41: =$B$30 -> 0 | C41: 1 | D41: =$D$30 -> 0 | E41: =$E$30 -> 0 | F41: =$F$30 -> 1 | G41: =$G$30 -> 0 | H41: =$H$30 -> 1
A42: MAT | B42: =$B$31 -> 1 | C42: =$C$31 -> 0 | D42: 1 | E42: =$E$31 -> 0 | F42: =$F$31 -> 0 | G42: =$G$31 -> 0 | H42: =$H$31 -> 1
A43: IND | B43: =$B$32 -> 1 | C43: =$C$32 -> 0 | D43: =$D$32 -> 0 | E43: 1 | F43: =$F$32 -> 0 | G43: =$G$32 -> 1 | H43: =$H$32 -> 1
A44: DIG | B44: =$B$33 -> 1 | C44: =$C$33 -> 1 | D44: =$D$33 -> 0 | E44: =$E$33 -> 0 | F44: 1 | G44: =$G$33 -> 1 | H44: =$H$33 -> 1
...

Sheet Core
A1: Find the core: routes, reachability, strongly connected components and causal layers (Worked Example 9.1, Step 2; Theorem 9.2(iii); Proposition 9.3; AXIOM Lab 1.9, step 2)
A2: Tarjan's algorithm in the notebook; here the same answer from matrix powers: two components are strongly connected when each reaches the other.
A4: A^2: routes of 2 steps from the row to the column
B5: MKT | C5: GOV | D5: MAT | E5: IND | F5: DIG | G5: ENG | H5: TRS | M5: Result | N5: Value | O5: Reading
A6: MKT | B6: =Wiring!$B$6*Wiring!$B$6+Wiring!$C$6*Wiring!$B$7+Wiring!$D$6*Wiring!$B$8+Wiring!$E$6*Wiring!$B$9+Wiring!$F$6*Wiring!$B$10+Wiring!$G$6*Wiring!$B$11+Wiring!$H$6*Wiring!$B$12 -> 0 | C6: =Wiring!$B$6*Wiring!$C$6+Wiring!$C$6*Wiring!$C$7+Wiring!$D$6*Wiring!$C$8+Wiring!$E$6*Wiring!$C$9+Wiring!$F$6*Wiring!$C$10+Wiring!$G$6*Wiring!$C$11+Wiring!$H$6*Wiring!$C$12 -> 0 | D6: =Wiring!$B$6*Wiring!$D$6+Wiring!$C$6*Wiring!$D$7+Wiring!$D$6*Wiring!$D$8+Wiring!$E$6*Wiring!$D$9+Wiring!$F$6*Wiring!$D$10+Wiring!$G$6*Wiring!$D$11+Wiring!$H$6*Wiring!$D$12 -> 0 | E6: =Wiring!$B$6*Wiring!$E$6+Wiring!$C$6*Wiring!$E$7+Wiring!$D$6*Wiring!$E$8+Wiring!$E$6*Wiring!$E$9+Wiring!$F$6*Wiring!$E$10+Wiring!$G$6*Wiring!$E$11+Wiring!$H$6*Wiring!$E$12 -> 0 | F6: =Wiring!$B$6*Wiring!$F$6+Wiring!$C$6*Wiring!$F$7+Wiring!$D$6*Wiring!$F$8+Wiring!$E$6*Wiring!$F$9+Wiring!$F$6*Wiring!$F$10+Wiring!$G$6*Wiring!$F$11+Wiring!$H$6*Wiring!$F$12 -> 0 | G6: =Wiring!$B$6*Wiring!$G$6+Wiring!$C$6*Wiring!$G$7+Wiring!$D$6*Wiring!$G$8+Wiring!$E$6*Wiring!$G$9+Wiring!$F$6*Wiring!$G$10+Wiring!$G$6*Wiring!$G$11+Wiring!$H$6*Wiring!$G$12 -> 2 | H6: =Wiring!$B$6*Wiring!$H$6+Wiring!$C$6*Wiring!$H$7+Wiring!$D$6*Wiring!$H$8+Wiring!$E$6*Wiring!$H$9+Wiring!$F$6*Wiring!$H$10+Wiring!$G$6*Wiring!$H$11+Wiring!$H$6*Wiring!$H$12 -> 3 | M6: Feedback cores (components of more than one member) | N6: =SUMPRODUCT($K$94:$K$100/$J$94:$J$100) -> 1 | O6: one: {IND, DIG, ENG, TRS}
A7: GOV | B7: =Wiring!$B$7*Wiring!$B$6+Wiring!$C$7*Wiring!$B$7+Wiring!$D$7*Wiring!$B$8+Wiring!$E$7*Wiring!$B$9+Wiring!$F$7*Wiring!$B$10+Wiring!$G$7*Wiring!$B$11+Wiring!$H$7*Wiring!$B$12 -> 0 | C7: =Wiring!$B$7*Wiring!$C$6+Wiring!$C$7*Wiring!$C$7+Wiring!$D$7*Wiring!$C$8+Wiring!$E$7*Wiring!$C$9+Wiring!$F$7*Wiring!$C$10+Wiring!$G$7*Wiring!$C$11+Wiring!$H$7*Wiring!$C$12 -> 0 | D7: =Wiring!$B$7*Wiring!$D$6+Wiring!$C$7*Wiring!$D$7+Wiring!$D$7*Wiring!$D$8+Wiring!$E$7*Wiring!$D$9+Wiring!$F$7*Wiring!$D$10+Wiring!$G$7*Wiring!$D$11+Wiring!$H$7*Wiring!$D$12 -> 0 | E7: =Wiring!$B$7*Wiring!$E$6+Wiring!$C$7*Wiring!$E$7+Wiring!$D$7*Wiring!$E$8+Wiring!$E$7*Wiring!$E$9+Wiring!$F$7*Wiring!$E$10+Wiring!$G$7*Wiring!$E$11+Wiring!$H$7*Wiring!$E$12 -> 1 | F7: =Wiring!$B$7*Wiring!$F$6+Wiring!$C$7*Wiring!$F$7+Wiring!$D$7*Wiring!$F$8+Wiring!$E$7*Wiring!$F$9+Wiring!$F$7*Wiring!$F$10+Wiring!$G$7*Wiring!$F$11+Wiring!$H$7*Wiring!$F$12 -> 1 | G7: =Wiring!$B$7*Wiring!$G$6+Wiring!$C$7*Wiring!$G$7+Wiring!$D$7*Wiring!$G$8+Wiring!$E$7*Wiring!$G$9+Wiring!$F$7*Wiring!$G$10+Wiring!$G$7*Wiring!$G$11+Wiring!$H$7*Wiring!$G$12 -> 1 | H7: =Wiring!$B$7*Wiring!$H$6+Wiring!$C$7*Wiring!$H$7+Wiring!$D$7*Wiring!$H$8+Wiring!$E$7*Wiring!$H$9+Wiring!$F$7*Wiring!$H$10+Wiring!$G$7*Wiring!$H$11+Wiring!$H$7*Wiring!$H$12 -> 1 | M7: Members of the largest core | N7: =MAX($J$94:$J$100) -> 4 | O7: four
A8: MAT | B8: =Wiring!$B$8*Wiring!$B$6+Wiring!$C$8*Wiring!$B$7+Wiring!$D$8*Wiring!$B$8+Wiring!$E$8*Wiring!$B$9+Wiring!$F$8*Wiring!$B$10+Wiring!$G$8*Wiring!$B$11+Wiring!$H$8*Wiring!$B$12 -> 0 | C8: =Wiring!$B$8*Wiring!$C$6+Wiring!$C$8*Wiring!$C$7+Wiring!$D$8*Wiring!$C$8+Wiring!$E$8*Wiring!$C$9+Wiring!$F$8*Wiring!$C$10+Wiring!$G$8*Wiring!$C$11+Wiring!$H$8*Wiring!$C$12 -> 0 | D8: =Wiring!$B$8*Wiring!$D$6+Wiring!$C$8*Wiring!$D$7+Wiring!$D$8*Wiring!$D$8+Wiring!$E$8*Wiring!$D$9+Wiring!$F$8*Wiring!$D$10+Wiring!$G$8*Wiring!$D$11+Wiring!$H$8*Wiring!$D$12 -> 0 | E8: =Wiring!$B$8*Wiring!$E$6+Wiring!$C$8*Wiring!$E$7+Wiring!$D$8*Wiring!$E$8+Wiring!$E$8*Wiring!$E$9+Wiring!$F$8*Wiring!$E$10+Wiring!$G$8*Wiring!$E$11+Wiring!$H$8*Wiring!$E$12 -> 1 | F8: =Wiring!$B$8*Wiring!$F$6+Wiring!$C$8*Wiring!$F$7+Wiring!$D$8*Wiring!$F$8+Wiring!$E$8*Wiring!$F$9+Wiring!$F$8*Wiring!$F$10+Wiring!$G$8*Wiring!$F$11+Wiring!$H$8*Wiring!$F$12 -> 1 | G8: =Wiring!$B$8*Wiring!$G$6+Wiring!$C$8*Wiring!$G$7+Wiring!$D$8*Wiring!$G$8+Wiring!$E$8*Wiring!$G$9+Wiring!$F$8*Wiring!$G$10+Wiring!$G$8*Wiring!$G$11+Wiring!$H$8*Wiring!$G$12 -> 0 | H8: =Wiring!$B$8*Wiring!$H$6+Wiring!$C$8*Wiring!$H$7+Wiring!$D$8*Wiring!$H$8+Wiring!$E$8*Wiring!$H$9+Wiring!$F$8*Wiring!$H$10+Wiring!$G$8*Wiring!$H$11+Wiring!$H$8*Wiring!$H$12 -> 0 | M8: Components in a core | N8: =SUM($K$94:$K$100) -> 4
A9: IND | B9: =Wiring!$B$9*Wiring!$B$6+Wiring!$C$9*Wiring!$B$7+Wiring!$D$9*Wiring!$B$8+Wiring!$E$9*Wiring!$B$9+Wiring!$F$9*Wiring!$B$10+Wiring!$G$9*Wiring!$B$11+Wiring!$H$9*Wiring!$B$12 -> 0 | C9: =Wiring!$B$9*Wiring!$C$6+Wiring!$C$9*Wiring!$C$7+Wiring!$D$9*Wiring!$C$8+Wiring!$E$9*Wiring!$C$9+Wiring!$F$9*Wiring!$C$10+Wiring!$G$9*Wiring!$C$11+Wiring!$H$9*Wiring!$C$12 -> 0 | D9: =Wiring!$B$9*Wiring!$D$6+Wiring!$C$9*Wiring!$D$7+Wiring!$D$9*Wiring!$D$8+Wiring!$E$9*Wiring!$D$9+Wiring!$F$9*Wiring!$D$10+Wiring!$G$9*Wiring!$D$11+Wiring!$H$9*Wiring!$D$12 -> 0 | E9: =Wiring!$B$9*Wiring!$E$6+Wiring!$C$9*Wiring!$E$7+Wiring!$D$9*Wiring!$E$8+Wiring!$E$9*Wiring!$E$9+Wiring!$F$9*Wiring!$E$10+Wiring!$G$9*Wiring!$E$11+Wiring!$H$9*Wiring!$E$12 -> 2 | F9: =Wiring!$B$9*Wiring!$F$6+Wiring!$C$9*Wiring!$F$7+Wiring!$D$9*Wiring!$F$8+Wiring!$E$9*Wiring!$F$9+Wiring!$F$9*Wiring!$F$10+Wiring!$G$9*Wiring!$F$11+Wiring!$H$9*Wiring!$F$12 -> 2 | G9: =Wiring!$B$9*Wiring!$G$6+Wiring!$C$9*Wiring!$G$7+Wiring!$D$9*Wiring!$G$8+Wiring!$E$9*Wiring!$G$9+Wiring!$F$9*Wiring!$G$10+Wiring!$G$9*Wiring!$G$11+Wiring!$H$9*Wiring!$G$12 -> 0 | H9: =Wiring!$B$9*Wiring!$H$6+Wiring!$C$9*Wiring!$H$7+Wiring!$D$9*Wiring!$H$8+Wiring!$E$9*Wiring!$H$9+Wiring!$F$9*Wiring!$H$10+Wiring!$G$9*Wiring!$H$11+Wiring!$H$9*Wiring!$H$12 -> 0 | M9: Causal layers | N9: =MAX($H$127:$H$133) -> 3 | O9: drivers, feeder, core
A10: DIG | B10: =Wiring!$B$10*Wiring!$B$6+Wiring!$C$10*Wiring!$B$7+Wiring!$D$10*Wiring!$B$8+Wiring!$E$10*Wiring!$B$9+Wiring!$F$10*Wiring!$B$10+Wiring!$G$10*Wiring!$B$11+Wiring!$H$10*Wiring!$B$12 -> 0 | C10: =Wiring!$B$10*Wiring!$C$6+Wiring!$C$10*Wiring!$C$7+Wiring!$D$10*Wiring!$C$8+Wiring!$E$10*Wiring!$C$9+Wiring!$F$10*Wiring!$C$10+Wiring!$G$10*Wiring!$C$11+Wiring!$H$10*Wiring!$C$12 -> 0 | D10: =Wiring!$B$10*Wiring!$D$6+Wiring!$C$10*Wiring!$D$7+Wiring!$D$10*Wiring!$D$8+Wiring!$E$10*Wiring!$D$9+Wiring!$F$10*Wiring!$D$10+Wiring!$G$10*Wiring!$D$11+Wiring!$H$10*Wiring!$D$12 -> 0 | E10: =Wiring!$B$10*Wiring!$E$6+Wiring!$C$10*Wiring!$E$7+Wiring!$D$10*Wiring!$E$8+Wiring!$E$10*Wiring!$E$9+Wiring!$F$10*Wiring!$E$10+Wiring!$G$10*Wiring!$E$11+Wiring!$H$10*Wiring!$E$12 -> 2 | F10: =Wiring!$B$10*Wiring!$F$6+Wiring!$C$10*Wiring!$F$7+Wiring!$D$10*Wiring!$F$8+Wiring!$E$10*Wiring!$F$9+Wiring!$F$10*Wiring!$F$10+Wiring!$G$10*Wiring!$F$11+Wiring!$H$10*Wiring!$F$12 -> 2 | G10: =Wiring!$B$10*Wiring!$G$6+Wiring!$C$10*Wiring!$G$7+Wiring!$D$10*Wiring!$G$8+Wiring!$E$10*Wiring!$G$9+Wiring!$F$10*Wiring!$G$10+Wiring!$G$10*Wiring!$G$11+Wiring!$H$10*Wiring!$G$12 -> 0 | H10: =Wiring!$B$10*Wiring!$H$6+Wiring!$C$10*Wiring!$H$7+Wiring!$D$10*Wiring!$H$8+Wiring!$E$10*Wiring!$H$9+Wiring!$F$10*Wiring!$H$10+Wiring!$G$10*Wiring!$H$11+Wiring!$H$10*Wiring!$H$12 -> 0 | M10: Condensation depth: longest chain of one-way arrows | N10: =N9-1 -> 2 | O10: two
A11: ENG | B11: =Wiring!$B$11*Wiring!$B$6+Wiring!$C$11*Wiring!$B$7+Wiring!$D$11*Wiring!$B$8+Wiring!$E$11*Wiring!$B$9+Wiring!$F$11*Wiring!$B$10+Wiring!$G$11*Wiring!$B$11+Wiring!$H$11*Wiring!$B$12 -> 0 | C11: =Wiring!$B$11*Wiring!$C$6+Wiring!$C$11*Wiring!$C$7+Wiring!$D$11*Wiring!$C$8+Wiring!$E$11*Wiring!$C$9+Wiring!$F$11*Wiring!$C$10+Wiring!$G$11*Wiring!$C$11+Wiring!$H$11*Wiring!$C$12 -> 0 | D11: =Wiring!$B$11*Wiring!$D$6+Wiring!$C$11*Wiring!$D$7+Wiring!$D$11*Wiring!$D$8+Wiring!$E$11*Wiring!$D$9+Wiring!$F$11*Wiring!$D$10+Wiring!$G$11*Wiring!$D$11+Wiring!$H$11*Wiring!$D$12 -> 0 | E11: =Wiring!$B$11*Wiring!$E$6+Wiring!$C$11*Wiring!$E$7+Wiring!$D$11*Wiring!$E$8+Wiring!$E$11*Wiring!$E$9+Wiring!$F$11*Wiring!$E$10+Wiring!$G$11*Wiring!$E$11+Wiring!$H$11*Wiring!$E$12 -> 0 | F11: =Wiring!$B$11*Wiring!$F$6+Wiring!$C$11*Wiring!$F$7+Wiring!$D$11*Wiring!$F$8+Wiring!$E$11*Wiring!$F$9+Wiring!$F$11*Wiring!$F$10+Wiring!$G$11*Wiring!$F$11+Wiring!$H$11*Wiring!$F$12 -> 0 | G11: =Wiring!$B$11*Wiring!$G$6+Wiring!$C$11*Wiring!$G$7+Wiring!$D$11*Wiring!$G$8+Wiring!$E$11*Wiring!$G$9+Wiring!$F$11*Wiring!$G$10+Wiring!$G$11*Wiring!$G$11+Wiring!$H$11*Wiring!$G$12 -> 2 | H11: =Wiring!$B$11*Wiring!$H$6+Wiring!$C$11*Wiring!$H$7+Wiring!$D$11*Wiring!$H$8+Wiring!$E$11*Wiring!$H$9+Wiring!$F$11*Wiring!$H$10+Wiring!$G$11*Wiring!$H$11+Wiring!$H$11*Wiring!$H$12 -> 2 | M11: Layer of the market | N11: =$H$127 -> 1 | O11: a driver
A12: TRS | B12: =Wiring!$B$12*Wiring!$B$6+Wiring!$C$12*Wiring!$B$7+Wiring!$D$12*Wiring!$B$8+Wiring!$E$12*Wiring!$B$9+Wiring!$F$12*Wiring!$B$10+Wiring!$G$12*Wiring!$B$11+Wiring!$H$12*Wiring!$B$12 -> 0 | C12: =Wiring!$B$12*Wiring!$C$6+Wiring!$C$12*Wiring!$C$7+Wiring!$D$12*Wiring!$C$8+Wiring!$E$12*Wiring!$C$9+Wiring!$F$12*Wiring!$C$10+Wiring!$G$12*Wiring!$C$11+Wiring!$H$12*Wiring!$C$12 -> 0 | D12: =Wiring!$B$12*Wiring!$D$6+Wiring!$C$12*Wiring!$D$7+Wiring!$D$12*Wiring!$D$8+Wiring!$E$12*Wiring!$D$9+Wiring!$F$12*Wiring!$D$10+Wiring!$G$12*Wiring!$D$11+Wiring!$H$12*Wiring!$D$12 -> 0 | E12: =Wiring!$B$12*Wiring!$E$6+Wiring!$C$12*Wiring!$E$7+Wiring!$D$12*Wiring!$E$8+Wiring!$E$12*Wiring!$E$9+Wiring!$F$12*Wiring!$E$10+Wiring!$G$12*Wiring!$E$11+Wiring!$H$12*Wiring!$E$12 -> 0 | F12: =Wiring!$B$12*Wiring!$F$6+Wiring!$C$12*Wiring!$F$7+Wiring!$D$12*Wiring!$F$8+Wiring!$E$12*Wiring!$F$9+Wiring!$F$12*Wiring!$F$10+Wiring!$G$12*Wiring!$F$11+Wiring!$H$12*Wiring!$F$12 -> 0 | G12: =Wiring!$B$12*Wiring!$G$6+Wiring!$C$12*Wiring!$G$7+Wiring!$D$12*Wiring!$G$8+Wiring!$E$12*Wiring!$G$9+Wiring!$F$12*Wiring!$G$10+Wiring!$G$12*Wiring!$G$11+Wiring!$H$12*Wiring!$G$12 -> 2 | H12: =Wiring!$B$12*Wiring!$H$6+Wiring!$C$12*Wiring!$H$7+Wiring!$D$12*Wiring!$H$8+Wiring!$E$12*Wiring!$H$9+Wiring!$F$12*Wiring!$H$10+Wiring!$G$12*Wiring!$H$11+Wiring!$H$12*Wiring!$H$12 -> 2 | M12: Layer of governance | N12: =$H$128 -> 1 | O12: a driver
M13: Layer of Materials | N13: =$H$129 -> 2 | O13: the feeder
M14: Layer of the core | N14: =$H$133 -> 3
A15: A^3: routes of 3 steps from the row to the column | M15: Core members among the divisions | N15: =COUNTIFS(Box,"divisions",$K$94:$K$100,1) -> 2 | O15: IND and DIG
B16: MKT | C16: GOV | D16: MAT | E16: IND | F16: DIG | G16: ENG | H16: TRS | M16: Core members in the corporate center | N16: =COUNTIFS(Box,"center",$K$94:$K$100,1) -> 2 | O16: ENG and TRS
A17: MKT | B17: =$B$6*Wiring!$B$6+$C$6*Wiring!$B$7+$D$6*Wiring!$B$8+$E$6*Wiring!$B$9+$F$6*Wiring!$B$10+$G$6*Wiring!$B$11+$H$6*Wiring!$B$12 -> 0 | C17: =$B$6*Wiring!$C$6+$C$6*Wiring!$C$7+$D$6*Wiring!$C$8+$E$6*Wiring!$C$9+$F$6*Wiring!$C$10+$G$6*Wiring!$C$11+$H$6*Wiring!$C$12 -> 0 | D17: =$B$6*Wiring!$D$6+$C$6*Wiring!$D$7+$D$6*Wiring!$D$8+$E$6*Wiring!$D$9+$F$6*Wiring!$D$10+$G$6*Wiring!$D$11+$H$6*Wiring!$D$12 -> 0 | E17: =$B$6*Wiring!$E$6+$C$6*Wiring!$E$7+$D$6*Wiring!$E$8+$E$6*Wiring!$E$9+$F$6*Wiring!$E$10+$G$6*Wiring!$E$11+$H$6*Wiring!$E$12 -> 5 | F17: =$B$6*Wiring!$F$6+$C$6*Wiring!$F$7+$D$6*Wiring!$F$8+$E$6*Wiring!$F$9+$F$6*Wiring!$F$10+$G$6*Wiring!$F$11+$H$6*Wiring!$F$12 -> 5 | G17: =$B$6*Wiring!$G$6+$C$6*Wiring!$G$7+$D$6*Wiring!$G$8+$E$6*Wiring!$G$9+$F$6*Wiring!$G$10+$G$6*Wiring!$G$11+$H$6*Wiring!$G$12 -> 0 | H17: =$B$6*Wiring!$H$6+$C$6*Wiring!$H$7+$D$6*Wiring!$H$8+$E$6*Wiring!$H$9+$F$6*Wiring!$H$10+$G$6*Wiring!$H$11+$H$6*Wiring!$H$12 -> 0
A18: GOV | B18: =$B$7*Wiring!$B$6+$C$7*Wiring!$B$7+$D$7*Wiring!$B$8+$E$7*Wiring!$B$9+$F$7*Wiring!$B$10+$G$7*Wiring!$B$11+$H$7*Wiring!$B$12 -> 0 | C18: =$B$7*Wiring!$C$6+$C$7*Wiring!$C$7+$D$7*Wiring!$C$8+$E$7*Wiring!$C$9+$F$7*Wiring!$C$10+$G$7*Wiring!$C$11+$H$7*Wiring!$C$12 -> 0 | D18: =$B$7*Wiring!$D$6+$C$7*Wiring!$D$7+$D$7*Wiring!$D$8+$E$7*Wiring!$D$9+$F$7*Wiring!$D$10+$G$7*Wiring!$D$11+$H$7*Wiring!$D$12 -> 0 | E18: =$B$7*Wiring!$E$6+$C$7*Wiring!$E$7+$D$7*Wiring!$E$8+$E$7*Wiring!$E$9+$F$7*Wiring!$E$10+$G$7*Wiring!$E$11+$H$7*Wiring!$E$12 -> 2 | F18: =$B$7*Wiring!$F$6+$C$7*Wiring!$F$7+$D$7*Wiring!$F$8+$E$7*Wiring!$F$9+$F$7*Wiring!$F$10+$G$7*Wiring!$F$11+$H$7*Wiring!$F$12 -> 2 | G18: =$B$7*Wiring!$G$6+$C$7*Wiring!$G$7+$D$7*Wiring!$G$8+$E$7*Wiring!$G$9+$F$7*Wiring!$G$10+$G$7*Wiring!$G$11+$H$7*Wiring!$G$12 -> 2 | H18: =$B$7*Wiring!$H$6+$C$7*Wiring!$H$7+$D$7*Wiring!$H$8+$E$7*Wiring!$H$9+$F$7*Wiring!$H$10+$G$7*Wiring!$H$11+$H$7*Wiring!$H$12 -> 2
A19: MAT | B19: =$B$8*Wiring!$B$6+$C$8*Wiring!$B$7+$D$8*Wiring!$B$8+$E$8*Wiring!$B$9+$F$8*Wiring!$B$10+$G$8*Wiring!$B$11+$H$8*Wiring!$B$12 -> 0 | C19: =$B$8*Wiring!$C$6+$C$8*Wiring!$C$7+$D$8*Wiring!$C$8+$E$8*Wiring!$C$9+$F$8*Wiring!$C$10+$G$8*Wiring!$C$11+$H$8*Wiring!$C$12 -> 0 | D19: =$B$8*Wiring!$D$6+$C$8*Wiring!$D$7+$D$8*Wiring!$D$8+$E$8*Wiring!$D$9+$F$8*Wiring!$D$10+$G$8*Wiring!$D$11+$H$8*Wiring!$D$12 -> 0 | E19: =$B$8*Wiring!$E$6+$C$8*Wiring!$E$7+$D$8*Wiring!$E$8+$E$8*Wiring!$E$9+$F$8*Wiring!$E$10+$G$8*Wiring!$E$11+$H$8*Wiring!$E$12 -> 0 | F19: =$B$8*Wiring!$F$6+$C$8*Wiring!$F$7+$D$8*Wiring!$F$8+$E$8*Wiring!$F$9+$F$8*Wiring!$F$10+$G$8*Wiring!$F$11+$H$8*Wiring!$F$12 -> 0 | G19: =$B$8*Wiring!$G$6+$C$8*Wiring!$G$7+$D$8*Wiring!$G$8+$E$8*Wiring!$G$9+$F$8*Wiring!$G$10+$G$8*Wiring!$G$11+$H$8*Wiring!$G$12 -> 2 | H19: =$B$8*Wiring!$H$6+$C$8*Wiring!$H$7+$D$8*Wiring!$H$8+$E$8*Wiring!$H$9+$F$8*Wiring!$H$10+$G$8*Wiring!$H$11+$H$8*Wiring!$H$12 -> 2
A20: IND | B20: =$B$9*Wiring!$B$6+$C$9*Wiring!$B$7+$D$9*Wiring!$B$8+$E$9*Wiring!$B$9+$F$9*Wiring!$B$10+$G$9*Wiring!$B$11+$H$9*Wiring!$B$12 -> 0 | C20: =$B$9*Wiring!$C$6+$C$9*Wiring!$C$7+$D$9*Wiring!$C$8+$E$9*Wiring!$C$9+$F$9*Wiring!$C$10+$G$9*Wiring!$C$11+$H$9*Wiring!$C$12 -> 0 | D20: =$B$9*Wiring!$D$6+$C$9*Wiring!$D$7+$D$9*Wiring!$D$8+$E$9*Wiring!$D$9+$F$9*Wiring!$D$10+$G$9*Wiring!$D$11+$H$9*Wiring!$D$12 -> 0 | E20: =$B$9*Wiring!$E$6+$C$9*Wiring!$E$7+$D$9*Wiring!$E$8+$E$9*Wiring!$E$9+$F$9*Wiring!$E$10+$G$9*Wiring!$E$11+$H$9*Wiring!$E$12 -> 0 | F20: =$B$9*Wiring!$F$6+$C$9*Wiring!$F$7+$D$9*Wiring!$F$8+$E$9*Wiring!$F$9+$F$9*Wiring!$F$10+$G$9*Wiring!$F$11+$H$9*Wiring!$F$12 -> 0 | G20: =$B$9*Wiring!$G$6+$C$9*Wiring!$G$7+$D$9*Wiring!$G$8+$E$9*Wiring!$G$9+$F$9*Wiring!$G$10+$G$9*Wiring!$G$11+$H$9*Wiring!$G$12 -> 4 | H20: =$B$9*Wiring!$H$6+$C$9*Wiring!$H$7+$D$9*Wiring!$H$8+$E$9*Wiring!$H$9+$F$9*Wiring!$H$10+$G$9*Wiring!$H$11+$H$9*Wiring!$H$12 -> 4 | M20: Loops inside the core: every candidate on its members (Worked Example 9.1, Step 2)
A21: DIG | B21: =$B$10*Wiring!$B$6+$C$10*Wiring!$B$7+$D$10*Wiring!$B$8+$E$10*Wiring!$B$9+$F$10*Wiring!$B$10+$G$10*Wiring!$B$11+$H$10*Wiring!$B$12 -> 0 | C21: =$B$10*Wiring!$C$6+$C$10*Wiring!$C$7+$D$10*Wiring!$C$8+$E$10*Wiring!$C$9+$F$10*Wiring!$C$10+$G$10*Wiring!$C$11+$H$10*Wiring!$C$12 -> 0 | D21: =$B$10*Wiring!$D$6+$C$10*Wiring!$D$7+$D$10*Wiring!$D$8+$E$10*Wiring!$D$9+$F$10*Wiring!$D$10+$G$10*Wiring!$D$11+$H$10*Wiring!$D$12 -> 0 | E21: =$B$10*Wiring!$E$6+$C$10*Wiring!$E$7+$D$10*Wiring!$E$8+$E$10*Wiring!$E$9+$F$10*Wiring!$E$10+$G$10*Wiring!$E$11+$H$10*Wiring!$E$12 -> 0 | F21: =$B$10*Wiring!$F$6+$C$10*Wiring!$F$7+$D$10*Wiring!$F$8+$E$10*Wiring!$F$9+$F$10*Wiring!$F$10+$G$10*Wiring!$F$11+$H$10*Wiring!$F$12 -> 0 | G21: =$B$10*Wiring!$G$6+$C$10*Wiring!$G$7+$D$10*Wiring!$G$8+$E$10*Wiring!$G$9+$F$10*Wiring!$G$10+$G$10*Wiring!$G$11+$H$10*Wiring!$G$12 -> 4 | H21: =$B$10*Wiring!$H$6+$C$10*Wiring!$H$7+$D$10*Wiring!$H$8+$E$10*Wiring!$H$9+$F$10*Wiring!$H$10+$G$10*Wiring!$H$11+$H$10*Wiring!$H$12 -> 4 | M21: Component | O21: Running count of core members
A22: ENG | B22: =$B$11*Wiring!$B$6+$C$11*Wiring!$B$7+$D$11*Wiring!$B$8+$E$11*Wiring!$B$9+$F$11*Wiring!$B$10+$G$11*Wiring!$B$11+$H$11*Wiring!$B$12 -> 0 | C22: =$B$11*Wiring!$C$6+$C$11*Wiring!$C$7+$D$11*Wiring!$C$8+$E$11*Wiring!$C$9+$F$11*Wiring!$C$10+$G$11*Wiring!$C$11+$H$11*Wiring!$C$12 -> 0 | D22: =$B$11*Wiring!$D$6+$C$11*Wiring!$D$7+$D$11*Wiring!$D$8+$E$11*Wiring!$D$9+$F$11*Wiring!$D$10+$G$11*Wiring!$D$11+$H$11*Wiring!$D$12 -> 0 | E22: =$B$11*Wiring!$E$6+$C$11*Wiring!$E$7+$D$11*Wiring!$E$8+$E$11*Wiring!$E$9+$F$11*Wiring!$E$10+$G$11*Wiring!$E$11+$H$11*Wiring!$E$12 -> 4 | F22: =$B$11*Wiring!$F$6+$C$11*Wiring!$F$7+$D$11*Wiring!$F$8+$E$11*Wiring!$F$9+$F$11*Wiring!$F$10+$G$11*Wiring!$F$11+$H$11*Wiring!$F$12 -> 4 | G22: =$B$11*Wiring!$G$6+$C$11*Wiring!$G$7+$D$11*Wiring!$G$8+$E$11*Wiring!$G$9+$F$11*Wiring!$G$10+$G$11*Wiring!$G$11+$H$11*Wiring!$G$12 -> 0 | H22: =$B$11*Wiring!$H$6+$C$11*Wiring!$H$7+$D$11*Wiring!$H$8+$E$11*Wiring!$H$9+$F$11*Wiring!$H$10+$G$11*Wiring!$H$11+$H$11*Wiring!$H$12 -> 0 | M22: MKT | O22: =COUNTIF($K$94:$K$94,1)*$K$94 -> 0
A23: TRS | B23: =$B$12*Wiring!$B$6+$C$12*Wiring!$B$7+$D$12*Wiring!$B$8+$E$12*Wiring!$B$9+$F$12*Wiring!$B$10+$G$12*Wiring!$B$11+$H$12*Wiring!$B$12 -> 0 | C23: =$B$12*Wiring!$C$6+$C$12*Wiring!$C$7+$D$12*Wiring!$C$8+$E$12*Wiring!$C$9+$F$12*Wiring!$C$10+$G$12*Wiring!$C$11+$H$12*Wiring!$C$12 -> 0 | D23: =$B$12*Wiring!$D$6+$C$12*Wiring!$D$7+$D$12*Wiring!$D$8+$E$12*Wiring!$D$9+$F$12*Wiring!$D$10+$G$12*Wiring!$D$11+$H$12*Wiring!$D$12 -> 0 | E23: =$B$12*Wiring!$E$6+$C$12*Wiring!$E$7+$D$12*Wiring!$E$8+$E$12*Wiring!$E$9+$F$12*Wiring!$E$10+$G$12*Wiring!$E$11+$H$12*Wiring!$E$12 -> 4 | F23: =$B$12*Wiring!$F$6+$C$12*Wiring!$F$7+$D$12*Wiring!$F$8+$E$12*Wiring!$F$9+$F$12*Wiring!$F$10+$G$12*Wiring!$F$11+$H$12*Wiring!$F$12 -> 4 | G23: =$B$12*Wiring!$G$6+$C$12*Wiring!$G$7+$D$12*Wiring!$G$8+$E$12*Wiring!$G$9+$F$12*Wiring!$G$10+$G$12*Wiring!$G$11+$H$12*Wiring!$G$12 -> 0 | H23: =$B$12*Wiring!$H$6+$C$12*Wiring!$H$7+$D$12*Wiring!$H$8+$E$12*Wiring!$H$9+$F$12*Wiring!$H$10+$G$12*Wiring!$H$11+$H$12*Wiring!$H$12 -> 0 | M23: GOV | O23: =COUNTIF($K$94:$K$95,1)*$K$95 -> 0
M24: MAT | O24: =COUNTIF($K$94:$K$96,1)*$K$96 -> 0
M25: IND | O25: =COUNTIF($K$94:$K$97,1)*$K$97 -> 1
A26: A^4: routes of 4 steps from the row to the column | M26: DIG | O26: =COUNTIF($K$94:$K$98,1)*$K$98 -> 2
B27: MKT | C27: GOV | D27: MAT | E27: IND | F27: DIG | G27: ENG | H27: TRS | M27: ENG | O27: =COUNTIF($K$94:$K$99,1)*$K$99 -> 3
A28: MKT | B28: =$B$17*Wiring!$B$6+$C$17*Wiring!$B$7+$D$17*Wiring!$B$8+$E$17*Wiring!$B$9+$F$17*Wiring!$B$10+$G$17*Wiring!$B$11+$H$17*Wiring!$B$12 -> 0 | C28: =$B$17*Wiring!$C$6+$C$17*Wiring!$C$7+$D$17*Wiring!$C$8+$E$17*Wiring!$C$9+$F$17*Wiring!$C$10+$G$17*Wiring!$C$11+$H$17*Wiring!$C$12 -> 0 | D28: =$B$17*Wiring!$D$6+$C$17*Wiring!$D$7+$D$17*Wiring!$D$8+$E$17*Wiring!$D$9+$F$17*Wiring!$D$10+$G$17*Wiring!$D$11+$H$17*Wiring!$D$12 -> 0 | E28: =$B$17*Wiring!$E$6+$C$17*Wiring!$E$7+$D$17*Wiring!$E$8+$E$17*Wiring!$E$9+$F$17*Wiring!$E$10+$G$17*Wiring!$E$11+$H$17*Wiring!$E$12 -> 0 | F28: =$B$17*Wiring!$F$6+$C$17*Wiring!$F$7+$D$17*Wiring!$F$8+$E$17*Wiring!$F$9+$F$17*Wiring!$F$10+$G$17*Wiring!$F$11+$H$17*Wiring!$F$12 -> 0 | G28: =$B$17*Wiring!$G$6+$C$17*Wiring!$G$7+$D$17*Wiring!$G$8+$E$17*Wiring!$G$9+$F$17*Wiring!$G$10+$G$17*Wiring!$G$11+$H$17*Wiring!$G$12 -> 10 | H28: =$B$17*Wiring!$H$6+$C$17*Wiring!$H$7+$D$17*Wiring!$H$8+$E$17*Wiring!$H$9+$F$17*Wiring!$H$10+$G$17*Wiring!$H$11+$H$17*Wiring!$H$12 -> 10 | M28: TRS | O28: =COUNTIF($K$94:$K$100,1)*$K$100 -> 4
A29: GOV | B29: =$B$18*Wiring!$B$6+$C$18*Wiring!$B$7+$D$18*Wiring!$B$8+$E$18*Wiring!$B$9+$F$18*Wiring!$B$10+$G$18*Wiring!$B$11+$H$18*Wiring!$B$12 -> 0 | C29: =$B$18*Wiring!$C$6+$C$18*Wiring!$C$7+$D$18*Wiring!$C$8+$E$18*Wiring!$C$9+$F$18*Wiring!$C$10+$G$18*Wiring!$C$11+$H$18*Wiring!$C$12 -> 0 | D29: =$B$18*Wiring!$D$6+$C$18*Wiring!$D$7+$D$18*Wiring!$D$8+$E$18*Wiring!$D$9+$F$18*Wiring!$D$10+$G$18*Wiring!$D$11+$H$18*Wiring!$D$12 -> 0 | E29: =$B$18*Wiring!$E$6+$C$18*Wiring!$E$7+$D$18*Wiring!$E$8+$E$18*Wiring!$E$9+$F$18*Wiring!$E$10+$G$18*Wiring!$E$11+$H$18*Wiring!$E$12 -> 4 | F29: =$B$18*Wiring!$F$6+$C$18*Wiring!$F$7+$D$18*Wiring!$F$8+$E$18*Wiring!$F$9+$F$18*Wiring!$F$10+$G$18*Wiring!$F$11+$H$18*Wiring!$F$12 -> 4 | G29: =$B$18*Wiring!$G$6+$C$18*Wiring!$G$7+$D$18*Wiring!$G$8+$E$18*Wiring!$G$9+$F$18*Wiring!$G$10+$G$18*Wiring!$G$11+$H$18*Wiring!$G$12 -> 4 | H29: =$B$18*Wiring!$H$6+$C$18*Wiring!$H$7+$D$18*Wiring!$H$8+$E$18*Wiring!$H$9+$F$18*Wiring!$H$10+$G$18*Wiring!$H$11+$H$18*Wiring!$H$12 -> 4 | M29: k | N29: k-th member of the core
A30: MAT | B30: =$B$19*Wiring!$B$6+$C$19*Wiring!$B$7+$D$19*Wiring!$B$8+$E$19*Wiring!$B$9+$F$19*Wiring!$B$10+$G$19*Wiring!$B$11+$H$19*Wiring!$B$12 -> 0 | C30: =$B$19*Wiring!$C$6+$C$19*Wiring!$C$7+$D$19*Wiring!$C$8+$E$19*Wiring!$C$9+$F$19*Wiring!$C$10+$G$19*Wiring!$C$11+$H$19*Wiring!$C$12 -> 0 | D30: =$B$19*Wiring!$D$6+$C$19*Wiring!$D$7+$D$19*Wiring!$D$8+$E$19*Wiring!$D$9+$F$19*Wiring!$D$10+$G$19*Wiring!$D$11+$H$19*Wiring!$D$12 -> 0 | E30: =$B$19*Wiring!$E$6+$C$19*Wiring!$E$7+$D$19*Wiring!$E$8+$E$19*Wiring!$E$9+$F$19*Wiring!$E$10+$G$19*Wiring!$E$11+$H$19*Wiring!$E$12 -> 4 | F30: =$B$19*Wiring!$F$6+$C$19*Wiring!$F$7+$D$19*Wiring!$F$8+$E$19*Wiring!$F$9+$F$19*Wiring!$F$10+$G$19*Wiring!$F$11+$H$19*Wiring!$F$12 -> 4 | G30: =$B$19*Wiring!$G$6+$C$19*Wiring!$G$7+$D$19*Wiring!$G$8+$E$19*Wiring!$G$9+$F$19*Wiring!$G$10+$G$19*Wiring!$G$11+$H$19*Wiring!$G$12 -> 0 | H30: =$B$19*Wiring!$H$6+$C$19*Wiring!$H$7+$D$19*Wiring!$H$8+$E$19*Wiring!$H$9+$F$19*Wiring!$H$10+$G$19*Wiring!$H$11+$H$19*Wiring!$H$12 -> 0 | M30: 1 | N30: =INDEX($M$22:$M$28,MATCH(1,$O$22:$O$28,0)) -> IND
A31: IND | B31: =$B$20*Wiring!$B$6+$C$20*Wiring!$B$7+$D$20*Wiring!$B$8+$E$20*Wiring!$B$9+$F$20*Wiring!$B$10+$G$20*Wiring!$B$11+$H$20*Wiring!$B$12 -> 0 | C31: =$B$20*Wiring!$C$6+$C$20*Wiring!$C$7+$D$20*Wiring!$C$8+$E$20*Wiring!$C$9+$F$20*Wiring!$C$10+$G$20*Wiring!$C$11+$H$20*Wiring!$C$12 -> 0 | D31: =$B$20*Wiring!$D$6+$C$20*Wiring!$D$7+$D$20*Wiring!$D$8+$E$20*Wiring!$D$9+$F$20*Wiring!$D$10+$G$20*Wiring!$D$11+$H$20*Wiring!$D$12 -> 0 | E31: =$B$20*Wiring!$E$6+$C$20*Wiring!$E$7+$D$20*Wiring!$E$8+$E$20*Wiring!$E$9+$F$20*Wiring!$E$10+$G$20*Wiring!$E$11+$H$20*Wiring!$E$12 -> 8 | F31: =$B$20*Wiring!$F$6+$C$20*Wiring!$F$7+$D$20*Wiring!$F$8+$E$20*Wiring!$F$9+$F$20*Wiring!$F$10+$G$20*Wiring!$F$11+$H$20*Wiring!$F$12 -> 8 | G31: =$B$20*Wiring!$G$6+$C$20*Wiring!$G$7+$D$20*Wiring!$G$8+$E$20*Wiring!$G$9+$F$20*Wiring!$G$10+$G$20*Wiring!$G$11+$H$20*Wiring!$G$12 -> 0 | H31: =$B$20*Wiring!$H$6+$C$20*Wiring!$H$7+$D$20*Wiring!$H$8+$E$20*Wiring!$H$9+$F$20*Wiring!$H$10+$G$20*Wiring!$H$11+$H$20*Wiring!$H$12 -> 0 | M31: 2 | N31: =INDEX($M$22:$M$28,MATCH(2,$O$22:$O$28,0)) -> DIG
A32: DIG | B32: =$B$21*Wiring!$B$6+$C$21*Wiring!$B$7+$D$21*Wiring!$B$8+$E$21*Wiring!$B$9+$F$21*Wiring!$B$10+$G$21*Wiring!$B$11+$H$21*Wiring!$B$12 -> 0 | C32: =$B$21*Wiring!$C$6+$C$21*Wiring!$C$7+$D$21*Wiring!$C$8+$E$21*Wiring!$C$9+$F$21*Wiring!$C$10+$G$21*Wiring!$C$11+$H$21*Wiring!$C$12 -> 0 | D32: =$B$21*Wiring!$D$6+$C$21*Wiring!$D$7+$D$21*Wiring!$D$8+$E$21*Wiring!$D$9+$F$21*Wiring!$D$10+$G$21*Wiring!$D$11+$H$21*Wiring!$D$12 -> 0 | E32: =$B$21*Wiring!$E$6+$C$21*Wiring!$E$7+$D$21*Wiring!$E$8+$E$21*Wiring!$E$9+$F$21*Wiring!$E$10+$G$21*Wiring!$E$11+$H$21*Wiring!$E$12 -> 8 | F32: =$B$21*Wiring!$F$6+$C$21*Wiring!$F$7+$D$21*Wiring!$F$8+$E$21*Wiring!$F$9+$F$21*Wiring!$F$10+$G$21*Wiring!$F$11+$H$21*Wiring!$F$12 -> 8 | G32: =$B$21*Wiring!$G$6+$C$21*Wiring!$G$7+$D$21*Wiring!$G$8+$E$21*Wiring!$G$9+$F$21*Wiring!$G$10+$G$21*Wiring!$G$11+$H$21*Wiring!$G$12 -> 0 | H32: =$B$21*Wiring!$H$6+$C$21*Wiring!$H$7+$D$21*Wiring!$H$8+$E$21*Wiring!$H$9+$F$21*Wiring!$H$10+$G$21*Wiring!$H$11+$H$21*Wiring!$H$12 -> 0 | M32: 3 | N32: =INDEX($M$22:$M$28,MATCH(3,$O$22:$O$28,0)) -> ENG
A33: ENG | B33: =$B$22*Wiring!$B$6+$C$22*Wiring!$B$7+$D$22*Wiring!$B$8+$E$22*Wiring!$B$9+$F$22*Wiring!$B$10+$G$22*Wiring!$B$11+$H$22*Wiring!$B$12 -> 0 | C33: =$B$22*Wiring!$C$6+$C$22*Wiring!$C$7+$D$22*Wiring!$C$8+$E$22*Wiring!$C$9+$F$22*Wiring!$C$10+$G$22*Wiring!$C$11+$H$22*Wiring!$C$12 -> 0 | D33: =$B$22*Wiring!$D$6+$C$22*Wiring!$D$7+$D$22*Wiring!$D$8+$E$22*Wiring!$D$9+$F$22*Wiring!$D$10+$G$22*Wiring!$D$11+$H$22*Wiring!$D$12 -> 0 | E33: =$B$22*Wiring!$E$6+$C$22*Wiring!$E$7+$D$22*Wiring!$E$8+$E$22*Wiring!$E$9+$F$22*Wiring!$E$10+$G$22*Wiring!$E$11+$H$22*Wiring!$E$12 -> 0 | F33: =$B$22*Wiring!$F$6+$C$22*Wiring!$F$7+$D$22*Wiring!$F$8+$E$22*Wiring!$F$9+$F$22*Wiring!$F$10+$G$22*Wiring!$F$11+$H$22*Wiring!$F$12 -> 0 | G33: =$B$22*Wiring!$G$6+$C$22*Wiring!$G$7+$D$22*Wiring!$G$8+$E$22*Wiring!$G$9+$F$22*Wiring!$G$10+$G$22*Wiring!$G$11+$H$22*Wiring!$G$12 -> 8 | H33: =$B$22*Wiring!$H$6+$C$22*Wiring!$H$7+$D$22*Wiring!$H$8+$E$22*Wiring!$H$9+$F$22*Wiring!$H$10+$G$22*Wiring!$H$11+$H$22*Wiring!$H$12 -> 8 | M33: 4 | N33: =INDEX($M$22:$M$28,MATCH(4,$O$22:$O$28,0)) -> TRS
A34: TRS | B34: =$B$23*Wiring!$B$6+$C$23*Wiring!$B$7+$D$23*Wiring!$B$8+$E$23*Wiring!$B$9+$F$23*Wiring!$B$10+$G$23*Wiring!$B$11+$H$23*Wiring!$B$12 -> 0 | C34: =$B$23*Wiring!$C$6+$C$23*Wiring!$C$7+$D$23*Wiring!$C$8+$E$23*Wiring!$C$9+$F$23*Wiring!$C$10+$G$23*Wiring!$C$11+$H$23*Wiring!$C$12 -> 0 | D34: =$B$23*Wiring!$D$6+$C$23*Wiring!$D$7+$D$23*Wiring!$D$8+$E$23*Wiring!$D$9+$F$23*Wiring!$D$10+$G$23*Wiring!$D$11+$H$23*Wiring!$D$12 -> 0 | E34: =$B$23*Wiring!$E$6+$C$23*Wiring!$E$7+$D$23*Wiring!$E$8+$E$23*Wiring!$E$9+$F$23*Wiring!$E$10+$G$23*Wiring!$E$11+$H$23*Wiring!$E$12 -> 0 | F34: =$B$23*Wiring!$F$6+$C$23*Wiring!$F$7+$D$23*Wiring!$F$8+$E$23*Wiring!$F$9+$F$23*Wiring!$F$10+$G$23*Wiring!$F$11+$H$23*Wiring!$F$12 -> 0 | G34: =$B$23*Wiring!$G$6+$C$23*Wiring!$G$7+$D$23*Wiring!$G$8+$E$23*Wiring!$G$9+$F$23*Wiring!$G$10+$G$23*Wiring!$G$11+$H$23*Wiring!$G$12 -> 8 | H34: =$B$23*Wiring!$H$6+$C$23*Wiring!$H$7+$D$23*Wiring!$H$8+$E$23*Wiring!$H$9+$F$23*Wiring!$H$10+$G$23*Wiring!$H$11+$H$23*Wiring!$H$12 -> 8
M35: Candidate loop | N35: Kind | O35: All its arrows present
M36: =$N$30&" > "&$N$31&" > "&$N$30 -> IND > DIG > IND | N36: two-way | O36: =INDEX(Wiring!$B$6:$H$12,MATCH($N$30,Wiring!$A$6:$A$12,0),MATCH($N$31,Wiring!$B$5:$H$5,0))*INDEX(Wiring!$B$6:$H$12,MATCH($N$31,Wiring!$A$6:$A$12,0),MATCH($N$30,Wiring!$B$5:$H$5,0)) -> 0
A37: A^5: routes of 5 steps from the row to the column | M37: =$N$30&" > "&$N$32&" > "&$N$30 -> IND > ENG > IND | N37: two-way | O37: =INDEX(Wiring!$B$6:$H$12,MATCH($N$30,Wiring!$A$6:$A$12,0),MATCH($N$32,Wiring!$B$5:$H$5,0))*INDEX(Wiring!$B$6:$H$12,MATCH($N$32,Wiring!$A$6:$A$12,0),MATCH($N$30,Wiring!$B$5:$H$5,0)) -> 1
B38: MKT | C38: GOV | D38: MAT | E38: IND | F38: DIG | G38: ENG | H38: TRS | M38: =$N$30&" > "&$N$33&" > "&$N$30 -> IND > TRS > IND | N38: two-way | O38: =INDEX(Wiring!$B$6:$H$12,MATCH($N$30,Wiring!$A$6:$A$12,0),MATCH($N$33,Wiring!$B$5:$H$5,0))*INDEX(Wiring!$B$6:$H$12,MATCH($N$33,Wiring!$A$6:$A$12,0),MATCH($N$30,Wiring!$B$5:$H$5,0)) -> 1
A39: MKT | B39: =$B$28*Wiring!$B$6+$C$28*Wiring!$B$7+$D$28*Wiring!$B$8+$E$28*Wiring!$B$9+$F$28*Wiring!$B$10+$G$28*Wiring!$B$11+$H$28*Wiring!$B$12 -> 0 | C39: =$B$28*Wiring!$C$6+$C$28*Wiring!$C$7+$D$28*Wiring!$C$8+$E$28*Wiring!$C$9+$F$28*Wiring!$C$10+$G$28*Wiring!$C$11+$H$28*Wiring!$C$12 -> 0 | D39: =$B$28*Wiring!$D$6+$C$28*Wiring!$D$7+$D$28*Wiring!$D$8+$E$28*Wiring!$D$9+$F$28*Wiring!$D$10+$G$28*Wiring!$D$11+$H$28*Wiring!$D$12 -> 0 | E39: =$B$28*Wiring!$E$6+$C$28*Wiring!$E$7+$D$28*Wiring!$E$8+$E$28*Wiring!$E$9+$F$28*Wiring!$E$10+$G$28*Wiring!$E$11+$H$28*Wiring!$E$12 -> 20 | F39: =$B$28*Wiring!$F$6+$C$28*Wiring!$F$7+$D$28*Wiring!$F$8+$E$28*Wiring!$F$9+$F$28*Wiring!$F$10+$G$28*Wiring!$F$11+$H$28*Wiring!$F$12 -> 20 | G39: =$B$28*Wiring!$G$6+$C$28*Wiring!$G$7+$D$28*Wiring!$G$8+$E$28*Wiring!$G$9+$F$28*Wiring!$G$10+$G$28*Wiring!$G$11+$H$28*Wiring!$G$12 -> 0 | H39: =$B$28*Wiring!$H$6+$C$28*Wiring!$H$7+$D$28*Wiring!$H$8+$E$28*Wiring!$H$9+$F$28*Wiring!$H$10+$G$28*Wiring!$H$11+$H$28*Wiring!$H$12 -> 0 | M39: =$N$31&" > "&$N$32&" > "&$N$31 -> DIG > ENG > DIG | N39: two-way | O39: =INDEX(Wiring!$B$6:$H$12,MATCH($N$31,Wiring!$A$6:$A$12,0),MATCH($N$32,Wiring!$B$5:$H$5,0))*INDEX(Wiring!$B$6:$H$12,MATCH($N$32,Wiring!$A$6:$A$12,0),MATCH($N$31,Wiring!$B$5:$H$5,0)) -> 1
A40: GOV | B40: =$B$29*Wiring!$B$6+$C$29*Wiring!$B$7+$D$29*Wiring!$B$8+$E$29*Wiring!$B$9+$F$29*Wiring!$B$10+$G$29*Wiring!$B$11+$H$29*Wiring!$B$12 -> 0 | C40: =$B$29*Wiring!$C$6+$C$29*Wiring!$C$7+$D$29*Wiring!$C$8+$E$29*Wiring!$C$9+$F$29*Wiring!$C$10+$G$29*Wiring!$C$11+$H$29*Wiring!$C$12 -> 0 | D40: =$B$29*Wiring!$D$6+$C$29*Wiring!$D$7+$D$29*Wiring!$D$8+$E$29*Wiring!$D$9+$F$29*Wiring!$D$10+$G$29*Wiring!$D$11+$H$29*Wiring!$D$12 -> 0 | E40: =$B$29*Wiring!$E$6+$C$29*Wiring!$E$7+$D$29*Wiring!$E$8+$E$29*Wiring!$E$9+$F$29*Wiring!$E$10+$G$29*Wiring!$E$11+$H$29*Wiring!$E$12 -> 8 | F40: =$B$29*Wiring!$F$6+$C$29*Wiring!$F$7+$D$29*Wiring!$F$8+$E$29*Wiring!$F$9+$F$29*Wiring!$F$10+$G$29*Wiring!$F$11+$H$29*Wiring!$F$12 -> 8 | G40: =$B$29*Wiring!$G$6+$C$29*Wiring!$G$7+$D$29*Wiring!$G$8+$E$29*Wiring!$G$9+$F$29*Wiring!$G$10+$G$29*Wiring!$G$11+$H$29*Wiring!$G$12 -> 8 | H40: =$B$29*Wiring!$H$6+$C$29*Wiring!$H$7+$D$29*Wiring!$H$8+$E$29*Wiring!$H$9+$F$29*Wiring!$H$10+$G$29*Wiring!$H$11+$H$29*Wiring!$H$12 -> 8 | M40: =$N$31&" > "&$N$33&" > "&$N$31 -> DIG > TRS > DIG | N40: two-way | O40: =INDEX(Wiring!$B$6:$H$12,MATCH($N$31,Wiring!$A$6:$A$12,0),MATCH($N$33,Wiring!$B$5:$H$5,0))*INDEX(Wiring!$B$6:$H$12,MATCH($N$33,Wiring!$A$6:$A$12,0),MATCH($N$31,Wiring!$B$5:$H$5,0)) -> 1
A41: MAT | B41: =$B$30*Wiring!$B$6+$C$30*Wiring!$B$7+$D$30*Wiring!$B$8+$E$30*Wiring!$B$9+$F$30*Wiring!$B$10+$G$30*Wiring!$B$11+$H$30*Wiring!$B$12 -> 0 | C41: =$B$30*Wiring!$C$6+$C$30*Wiring!$C$7+$D$30*Wiring!$C$8+$E$30*Wiring!$C$9+$F$30*Wiring!$C$10+$G$30*Wiring!$C$11+$H$30*Wiring!$C$12 -> 0 | D41: =$B$30*Wiring!$D$6+$C$30*Wiring!$D$7+$D$30*Wiring!$D$8+$E$30*Wiring!$D$9+$F$30*Wiring!$D$10+$G$30*Wiring!$D$11+$H$30*Wiring!$D$12 -> 0 | E41: =$B$30*Wiring!$E$6+$C$30*Wiring!$E$7+$D$30*Wiring!$E$8+$E$30*Wiring!$E$9+$F$30*Wiring!$E$10+$G$30*Wiring!$E$11+$H$30*Wiring!$E$12 -> 0 | F41: =$B$30*Wiring!$F$6+$C$30*Wiring!$F$7+$D$30*Wiring!$F$8+$E$30*Wiring!$F$9+$F$30*Wiring!$F$10+$G$30*Wiring!$F$11+$H$30*Wiring!$F$12 -> 0 | G41: =$B$30*Wiring!$G$6+$C$30*Wiring!$G$7+$D$30*Wiring!$G$8+$E$30*Wiring!$G$9+$F$30*Wiring!$G$10+$G$30*Wiring!$G$11+$H$30*Wiring!$G$12 -> 8 | H41: =$B$30*Wiring!$H$6+$C$30*Wiring!$H$7+$D$30*Wiring!$H$8+$E$30*Wiring!$H$9+$F$30*Wiring!$H$10+$G$30*Wiring!$H$11+$H$30*Wiring!$H$12 -> 8 | M41: =$N$32&" > "&$N$33&" > "&$N$32 -> ENG > TRS > ENG | N41: two-way | O41: =INDEX(Wiring!$B$6:$H$12,MATCH($N$32,Wiring!$A$6:$A$12,0),MATCH($N$33,Wiring!$B$5:$H$5,0))*INDEX(Wiring!$B$6:$H$12,MATCH($N$33,Wiring!$A$6:$A$12,0),MATCH($N$32,Wiring!$B$5:$H$5,0)) -> 0
...

Sheet Shock
A1: Put floors under arrival times and send a shock (Worked Example 9.1, Step 3; Theorem 9.2; Table 9.7; Online Appendix 9.B.2; AXIOM Lab 1.9, step 3)
A2: A demand shock to the market can change a component no sooner than its distance, the fewest arrows from the market: a floor, not a forecast.
A5: Component | B5: Distance from the market | C5: Reached at all
A6: MKT | B6: 0 | C6: =IF(ISNUMBER(B6),1,0) -> 1 | F6: Reached after one quarter | G6: =C43 -> 3 | H6: the three divisions
A7: GOV | B7: =IF(Wiring!$C$6>0,1,IF(Core!$C$6>0,2,IF(Core!$C$17>0,3,IF(Core!$C$28>0,4,IF(Core!$C$39>0,5,IF(Core!$C$50>0,6,"never")))))) -> never | C7: =IF(ISNUMBER(B7),1,0) -> 0 | F7: Reached after two quarters | G7: =D43 -> 5 | H7: and engineering and treasury
A8: MAT | B8: =IF(Wiring!$D$6>0,1,IF(Core!$D$6>0,2,IF(Core!$D$17>0,3,IF(Core!$D$28>0,4,IF(Core!$D$39>0,5,IF(Core!$D$50>0,6,"never")))))) -> 1 | C8: =IF(ISNUMBER(B8),1,0) -> 1 | F8: Reached after three quarters | G8: =E43 -> 5 | H8: no one else
A9: IND | B9: =IF(Wiring!$E$6>0,1,IF(Core!$E$6>0,2,IF(Core!$E$17>0,3,IF(Core!$E$28>0,4,IF(Core!$E$39>0,5,IF(Core!$E$50>0,6,"never")))))) -> 1 | C9: =IF(ISNUMBER(B9),1,0) -> 1 | F9: Never reached | G9: =COUNTIF($B$6:$B$12,"never") -> 1 | H9: governance: no path
A10: DIG | B10: =IF(Wiring!$F$6>0,1,IF(Core!$F$6>0,2,IF(Core!$F$17>0,3,IF(Core!$F$28>0,4,IF(Core!$F$39>0,5,IF(Core!$F$50>0,6,"never")))))) -> 1 | C10: =IF(ISNUMBER(B10),1,0) -> 1 | F10: Routes of two steps | G10: =B48 -> 3 | H10: Section 9.8: 3
A11: ENG | B11: =IF(Wiring!$G$6>0,1,IF(Core!$G$6>0,2,IF(Core!$G$17>0,3,IF(Core!$G$28>0,4,IF(Core!$G$39>0,5,IF(Core!$G$50>0,6,"never")))))) -> 2 | C11: =IF(ISNUMBER(B11),1,0) -> 1 | F11: Routes of four steps | G11: =B50 -> 10 | H11: Section 9.8: 10
A12: TRS | B12: =IF(Wiring!$H$6>0,1,IF(Core!$H$6>0,2,IF(Core!$H$17>0,3,IF(Core!$H$28>0,4,IF(Core!$H$39>0,5,IF(Core!$H$50>0,6,"never")))))) -> 2 | C12: =IF(ISNUMBER(B12),1,0) -> 1 | F12: Routes of six steps | G12: =B52 -> 40 | H12: Section 9.8: 40
F13: Routes of odd length (1, 3, 5, 7) | G13: =B47+B49+B51+B53 -> 0 | H13: none: routes alternate between two groups
A15: Component (Table 9.7) | B15: Earliest quarter | C15: A shortest route | D15: Shortest routes
A16: Industrial Systems (IND) | B16: =$B$9 -> 1 | C16: =IF(ISNUMBER($B$9),IF($B$9=1,"MKT → IND",IF($B$9=2,"MKT → "&$E$33&" → IND",IF($B$9=3,"MKT → "&INDEX($B$33:$H$33,MATCH($E$33,$B$25:$H$25,0))&" → "&$E$33&" → IND","longer"))),"no path") -> MKT → IND | D16: =IF(ISNUMBER(B16),CHOOSE(B16,Wiring!$E$6,Core!$E$6,Core!$E$17,Core!$E$28,Core!$E$39,Core!$E$50),0) -> 1
A17: Digital (DIG) | B17: =$B$10 -> 1 | C17: =IF(ISNUMBER($B$10),IF($B$10=1,"MKT → DIG",IF($B$10=2,"MKT → "&$F$33&" → DIG",IF($B$10=3,"MKT → "&INDEX($B$33:$H$33,MATCH($F$33,$B$25:$H$25,0))&" → "&$F$33&" → DIG","longer"))),"no path") -> MKT → DIG | D17: =IF(ISNUMBER(B17),CHOOSE(B17,Wiring!$F$6,Core!$F$6,Core!$F$17,Core!$F$28,Core!$F$39,Core!$F$50),0) -> 1
A18: Materials (MAT) | B18: =$B$8 -> 1 | C18: =IF(ISNUMBER($B$8),IF($B$8=1,"MKT → MAT",IF($B$8=2,"MKT → "&$D$33&" → MAT",IF($B$8=3,"MKT → "&INDEX($B$33:$H$33,MATCH($D$33,$B$25:$H$25,0))&" → "&$D$33&" → MAT","longer"))),"no path") -> MKT → MAT | D18: =IF(ISNUMBER(B18),CHOOSE(B18,Wiring!$D$6,Core!$D$6,Core!$D$17,Core!$D$28,Core!$D$39,Core!$D$50),0) -> 1
A19: Shared engineering (ENG) | B19: =$B$11 -> 2 | C19: =IF(ISNUMBER($B$11),IF($B$11=1,"MKT → ENG",IF($B$11=2,"MKT → "&$G$33&" → ENG",IF($B$11=3,"MKT → "&INDEX($B$33:$H$33,MATCH($G$33,$B$25:$H$25,0))&" → "&$G$33&" → ENG","longer"))),"no path") -> MKT → IND → ENG | D19: =IF(ISNUMBER(B19),CHOOSE(B19,Wiring!$G$6,Core!$G$6,Core!$G$17,Core!$G$28,Core!$G$39,Core!$G$50),0) -> 2
A20: Treasury (TRS), covenant | B20: =$B$12 -> 2 | C20: =IF(ISNUMBER($B$12),IF($B$12=1,"MKT → TRS",IF($B$12=2,"MKT → "&$H$33&" → TRS",IF($B$12=3,"MKT → "&INDEX($B$33:$H$33,MATCH($H$33,$B$25:$H$25,0))&" → "&$H$33&" → TRS","longer"))),"no path") -> MKT → IND → TRS | D20: =IF(ISNUMBER(B20),CHOOSE(B20,Wiring!$H$6,Core!$H$6,Core!$H$17,Core!$H$28,Core!$H$39,Core!$H$50),0) -> 3
A21: Governance (GOV) | B21: =$B$7 -> never | C21: =IF(ISNUMBER($B$7),IF($B$7=1,"MKT → GOV",IF($B$7=2,"MKT → "&$C$33&" → GOV",IF($B$7=3,"MKT → "&INDEX($B$33:$H$33,MATCH($C$33,$B$25:$H$25,0))&" → "&$C$33&" → GOV","longer"))),"no path") -> no path | D21: =IF(ISNUMBER(B21),CHOOSE(B21,Wiring!$C$6,Core!$C$6,Core!$C$17,Core!$C$28,Core!$C$39,Core!$C$50),0) -> 0
A22: The covenant is a reading of treasury: it cannot move before the second quarter-end after the shock (Theorem 9.2(ii)), and three routes of two steps lead there.
A24: A predecessor on a shortest route: 1 if the row is one step closer to the market and sends an arrow to the column
A25: from \ to | B25: MKT | C25: GOV | D25: MAT | E25: IND | F25: DIG | G25: ENG | H25: TRS
A26: IND | B26: =IF(AND(ISNUMBER($B$9),ISNUMBER($B$6)),IF(AND($B$9=$B$6-1,Wiring!$B$9=1),1,0),0) -> 0 | C26: =IF(AND(ISNUMBER($B$9),ISNUMBER($B$7)),IF(AND($B$9=$B$7-1,Wiring!$C$9=1),1,0),0) -> 0 | D26: =IF(AND(ISNUMBER($B$9),ISNUMBER($B$8)),IF(AND($B$9=$B$8-1,Wiring!$D$9=1),1,0),0) -> 0 | E26: =IF(AND(ISNUMBER($B$9),ISNUMBER($B$9)),IF(AND($B$9=$B$9-1,Wiring!$E$9=1),1,0),0) -> 0 | F26: =IF(AND(ISNUMBER($B$9),ISNUMBER($B$10)),IF(AND($B$9=$B$10-1,Wiring!$F$9=1),1,0),0) -> 0 | G26: =IF(AND(ISNUMBER($B$9),ISNUMBER($B$11)),IF(AND($B$9=$B$11-1,Wiring!$G$9=1),1,0),0) -> 1 | H26: =IF(AND(ISNUMBER($B$9),ISNUMBER($B$12)),IF(AND($B$9=$B$12-1,Wiring!$H$9=1),1,0),0) -> 1
A27: DIG | B27: =IF(AND(ISNUMBER($B$10),ISNUMBER($B$6)),IF(AND($B$10=$B$6-1,Wiring!$B$10=1),1,0),0) -> 0 | C27: =IF(AND(ISNUMBER($B$10),ISNUMBER($B$7)),IF(AND($B$10=$B$7-1,Wiring!$C$10=1),1,0),0) -> 0 | D27: =IF(AND(ISNUMBER($B$10),ISNUMBER($B$8)),IF(AND($B$10=$B$8-1,Wiring!$D$10=1),1,0),0) -> 0 | E27: =IF(AND(ISNUMBER($B$10),ISNUMBER($B$9)),IF(AND($B$10=$B$9-1,Wiring!$E$10=1),1,0),0) -> 0 | F27: =IF(AND(ISNUMBER($B$10),ISNUMBER($B$10)),IF(AND($B$10=$B$10-1,Wiring!$F$10=1),1,0),0) -> 0 | G27: =IF(AND(ISNUMBER($B$10),ISNUMBER($B$11)),IF(AND($B$10=$B$11-1,Wiring!$G$10=1),1,0),0) -> 1 | H27: =IF(AND(ISNUMBER($B$10),ISNUMBER($B$12)),IF(AND($B$10=$B$12-1,Wiring!$H$10=1),1,0),0) -> 1
A28: MAT | B28: =IF(AND(ISNUMBER($B$8),ISNUMBER($B$6)),IF(AND($B$8=$B$6-1,Wiring!$B$8=1),1,0),0) -> 0 | C28: =IF(AND(ISNUMBER($B$8),ISNUMBER($B$7)),IF(AND($B$8=$B$7-1,Wiring!$C$8=1),1,0),0) -> 0 | D28: =IF(AND(ISNUMBER($B$8),ISNUMBER($B$8)),IF(AND($B$8=$B$8-1,Wiring!$D$8=1),1,0),0) -> 0 | E28: =IF(AND(ISNUMBER($B$8),ISNUMBER($B$9)),IF(AND($B$8=$B$9-1,Wiring!$E$8=1),1,0),0) -> 0 | F28: =IF(AND(ISNUMBER($B$8),ISNUMBER($B$10)),IF(AND($B$8=$B$10-1,Wiring!$F$8=1),1,0),0) -> 0 | G28: =IF(AND(ISNUMBER($B$8),ISNUMBER($B$11)),IF(AND($B$8=$B$11-1,Wiring!$G$8=1),1,0),0) -> 0 | H28: =IF(AND(ISNUMBER($B$8),ISNUMBER($B$12)),IF(AND($B$8=$B$12-1,Wiring!$H$8=1),1,0),0) -> 1
A29: ENG | B29: =IF(AND(ISNUMBER($B$11),ISNUMBER($B$6)),IF(AND($B$11=$B$6-1,Wiring!$B$11=1),1,0),0) -> 0 | C29: =IF(AND(ISNUMBER($B$11),ISNUMBER($B$7)),IF(AND($B$11=$B$7-1,Wiring!$C$11=1),1,0),0) -> 0 | D29: =IF(AND(ISNUMBER($B$11),ISNUMBER($B$8)),IF(AND($B$11=$B$8-1,Wiring!$D$11=1),1,0),0) -> 0 | E29: =IF(AND(ISNUMBER($B$11),ISNUMBER($B$9)),IF(AND($B$11=$B$9-1,Wiring!$E$11=1),1,0),0) -> 0 | F29: =IF(AND(ISNUMBER($B$11),ISNUMBER($B$10)),IF(AND($B$11=$B$10-1,Wiring!$F$11=1),1,0),0) -> 0 | G29: =IF(AND(ISNUMBER($B$11),ISNUMBER($B$11)),IF(AND($B$11=$B$11-1,Wiring!$G$11=1),1,0),0) -> 0 | H29: =IF(AND(ISNUMBER($B$11),ISNUMBER($B$12)),IF(AND($B$11=$B$12-1,Wiring!$H$11=1),1,0),0) -> 0
A30: TRS | B30: =IF(AND(ISNUMBER($B$12),ISNUMBER($B$6)),IF(AND($B$12=$B$6-1,Wiring!$B$12=1),1,0),0) -> 0 | C30: =IF(AND(ISNUMBER($B$12),ISNUMBER($B$7)),IF(AND($B$12=$B$7-1,Wiring!$C$12=1),1,0),0) -> 0 | D30: =IF(AND(ISNUMBER($B$12),ISNUMBER($B$8)),IF(AND($B$12=$B$8-1,Wiring!$D$12=1),1,0),0) -> 0 | E30: =IF(AND(ISNUMBER($B$12),ISNUMBER($B$9)),IF(AND($B$12=$B$9-1,Wiring!$E$12=1),1,0),0) -> 0 | F30: =IF(AND(ISNUMBER($B$12),ISNUMBER($B$10)),IF(AND($B$12=$B$10-1,Wiring!$F$12=1),1,0),0) -> 0 | G30: =IF(AND(ISNUMBER($B$12),ISNUMBER($B$11)),IF(AND($B$12=$B$11-1,Wiring!$G$12=1),1,0),0) -> 0 | H30: =IF(AND(ISNUMBER($B$12),ISNUMBER($B$12)),IF(AND($B$12=$B$12-1,Wiring!$H$12=1),1,0),0) -> 0
A31: MKT | B31: =IF(AND(ISNUMBER($B$6),ISNUMBER($B$6)),IF(AND($B$6=$B$6-1,Wiring!$B$6=1),1,0),0) -> 0 | C31: =IF(AND(ISNUMBER($B$6),ISNUMBER($B$7)),IF(AND($B$6=$B$7-1,Wiring!$C$6=1),1,0),0) -> 0 | D31: =IF(AND(ISNUMBER($B$6),ISNUMBER($B$8)),IF(AND($B$6=$B$8-1,Wiring!$D$6=1),1,0),0) -> 1 | E31: =IF(AND(ISNUMBER($B$6),ISNUMBER($B$9)),IF(AND($B$6=$B$9-1,Wiring!$E$6=1),1,0),0) -> 1 | F31: =IF(AND(ISNUMBER($B$6),ISNUMBER($B$10)),IF(AND($B$6=$B$10-1,Wiring!$F$6=1),1,0),0) -> 1 | G31: =IF(AND(ISNUMBER($B$6),ISNUMBER($B$11)),IF(AND($B$6=$B$11-1,Wiring!$G$6=1),1,0),0) -> 0 | H31: =IF(AND(ISNUMBER($B$6),ISNUMBER($B$12)),IF(AND($B$6=$B$12-1,Wiring!$H$6=1),1,0),0) -> 0
A32: GOV | B32: =IF(AND(ISNUMBER($B$7),ISNUMBER($B$6)),IF(AND($B$7=$B$6-1,Wiring!$B$7=1),1,0),0) -> 0 | C32: =IF(AND(ISNUMBER($B$7),ISNUMBER($B$7)),IF(AND($B$7=$B$7-1,Wiring!$C$7=1),1,0),0) -> 0 | D32: =IF(AND(ISNUMBER($B$7),ISNUMBER($B$8)),IF(AND($B$7=$B$8-1,Wiring!$D$7=1),1,0),0) -> 0 | E32: =IF(AND(ISNUMBER($B$7),ISNUMBER($B$9)),IF(AND($B$7=$B$9-1,Wiring!$E$7=1),1,0),0) -> 0 | F32: =IF(AND(ISNUMBER($B$7),ISNUMBER($B$10)),IF(AND($B$7=$B$10-1,Wiring!$F$7=1),1,0),0) -> 0 | G32: =IF(AND(ISNUMBER($B$7),ISNUMBER($B$11)),IF(AND($B$7=$B$11-1,Wiring!$G$7=1),1,0),0) -> 0 | H32: =IF(AND(ISNUMBER($B$7),ISNUMBER($B$12)),IF(AND($B$7=$B$12-1,Wiring!$H$7=1),1,0),0) -> 0
A33: predecessor | B33: =IFERROR(INDEX($A$26:$A$32,MATCH(1,B26:B32,0)),"") | C33: =IFERROR(INDEX($A$26:$A$32,MATCH(1,C26:C32,0)),"") | D33: =IFERROR(INDEX($A$26:$A$32,MATCH(1,D26:D32,0)),"") -> MKT | E33: =IFERROR(INDEX($A$26:$A$32,MATCH(1,E26:E32,0)),"") -> MKT | F33: =IFERROR(INDEX($A$26:$A$32,MATCH(1,F26:F32,0)),"") -> MKT | G33: =IFERROR(INDEX($A$26:$A$32,MATCH(1,G26:G32,0)),"") -> IND | H33: =IFERROR(INDEX($A$26:$A$32,MATCH(1,H26:H32,0)),"") -> IND
A35: The wavefront: 1 once the shock can have reached the component (AXIOM Lab 1.9, step 3)
A36: Component | B36: quarter 0 | C36: quarter 1 | D36: quarter 2 | E36: quarter 3 | F36: quarter 4
A37: IND | B37: =IF(ISNUMBER($B$9),IF($B$9<=0,1,0),0) -> 0 | C37: =IF(ISNUMBER($B$9),IF($B$9<=1,1,0),0) -> 1 | D37: =IF(ISNUMBER($B$9),IF($B$9<=2,1,0),0) -> 1 | E37: =IF(ISNUMBER($B$9),IF($B$9<=3,1,0),0) -> 1 | F37: =IF(ISNUMBER($B$9),IF($B$9<=4,1,0),0) -> 1
A38: DIG | B38: =IF(ISNUMBER($B$10),IF($B$10<=0,1,0),0) -> 0 | C38: =IF(ISNUMBER($B$10),IF($B$10<=1,1,0),0) -> 1 | D38: =IF(ISNUMBER($B$10),IF($B$10<=2,1,0),0) -> 1 | E38: =IF(ISNUMBER($B$10),IF($B$10<=3,1,0),0) -> 1 | F38: =IF(ISNUMBER($B$10),IF($B$10<=4,1,0),0) -> 1
A39: MAT | B39: =IF(ISNUMBER($B$8),IF($B$8<=0,1,0),0) -> 0 | C39: =IF(ISNUMBER($B$8),IF($B$8<=1,1,0),0) -> 1 | D39: =IF(ISNUMBER($B$8),IF($B$8<=2,1,0),0) -> 1 | E39: =IF(ISNUMBER($B$8),IF($B$8<=3,1,0),0) -> 1 | F39: =IF(ISNUMBER($B$8),IF($B$8<=4,1,0),0) -> 1
