Workbook

Sheet README
B1: DCT Laboratory — Vol I, Ch 2: Enterprise Systems and Transformation
B2: Seed 26102 · Companion to DCT_V1_Ch02_Lab.ipynb and AXIOM Lab 1.2 (module AXIOM-02). Money in $ million a year.
B4: Worked Example 2.1, Where Does Meridian End?, with the book's declarations.
B5: Declarations: the inputs of Step 1, the six entities with boundary A, boundary B and one you draw, and the nine flows of Table 2.6; for the feedback bench, Meridian's efficiency and the turnaround's target and speed.
B6: Boundaries: every flow classified under each boundary (Definition 2.3) and checked against Table 2.6; the counts, the goods output and the $308 million gap.
B7: AllBoundaries: the 64 ways to draw the line; each classifies the same nine flows (Theorem 2.2), and flows by type show which entities can move freely (Corollary 2.B.2).
B8: Levels: Meridian's group, divisions and units (Figure 2.3), the environment of a subsystem you choose, and the coupling classified level by level.
B9: Feedback: the turnaround's efficiency program as a feedback rule, a gain to explore, and Proposition 2.2's closed-loop map.
B10: Adaptation: the bench's adaptive rule after a shift in the environment (bench settings, not book numbers), and Online Appendix 2.B's adaptive company as one map of the augmented state (Proposition 2.3).
B11: OutputFeedback: Remark 2.B.1's algebraic loops. Loops: the migration loop and the efficiency program, signed.
B12: The checks over 1,000 random histories (seed 26102) run in the notebook.
B13: Reference_Values and Checks: the engine's numbers and a PASS/FAIL comparison with this workbook's formulas.
... B19: Cross-sheet link: green.

Sheet Declarations
A1: Declarations (Worked Example 2.1, Step 1). Money in $ million a year.
A3: Quantity | B3: Value | C3: Source
A4: Meridian's revenue | B4: 4200 | C4: Chapter 1: $4.2 billion
A5: Industrial Systems' share of revenue | B5: 0.61 | C5: Chapter 1: 61 percent
A6: Industrial Systems' sales | B6: =B4*B5 -> 2562 | C6: $2.56 billion
A7: Shipped to independent dealers | B7: 1540 | C7: Worked Example 2.1: $1.54 billion
A8: Share of Industrial Systems' sales shipped to dealers | B8: =B7/B6 -> 0.6010929 | C8: about 60 percent
A9: Dealers' resale price above Meridian's | B9: 0.2 | C9: about 20 percent
A10: Dealers' sales to end customers | B10: =B7*(1+B9) -> 1848 | C10: $1,848 million (flow F5)
A11: Dealers' gross margin | B11: =B10-B7 -> 308 | C11: $308 million
A12: The feedback bench (AXIOM Lab 1.2, step 4): Meridian's efficiency under the turnaround's program
A13: Operational efficiency today (index, 0-100) | B13: 71 | C13: Table 3.1
A14: The turnaround's efficiency target | B14: 79 | C14: Online Appendix Table 1.B.1 (Chapter 1 model)
A15: The turnaround's speed of adjustment a year | B15: 0.6 | C15: Online Appendix Table 1.B.1
A16: Share of the gap closed a year, K = 1 - exp(-speed) | B16: =1-EXP(-B15) -> 0.45118836 | C16: 45 percent (Worked Example 5.1)
A17: Gap factor a year, 1 - K | B17: =1-B16 -> 0.54881164 | C17: 0.549 (Worked Example 5.1)
A19: Entity | B19: Inside boundary A | C19: Inside boundary B | D19: Inside your boundary
A20: Suppliers | B20: 0 | C20: 0 | D20: 0
A21: Meridian | B21: 1 | C21: 1 | D21: 1
A22: Dealer network | B22: 0 | C22: 1 | D22: 0
A23: End customers | B23: 0 | C23: 0 | D23: 0
A24: Capital markets | B24: 0 | C24: 0 | D24: 0
A25: Regulator | B25: 0 | C25: 0 | D25: 0
A26: 1 = inside the perimeter, 0 = outside. Boundary A: only Meridian; boundary B: Meridian and the dealer network. Draw your own in column D.
A28: Flow | B28: From | C28: To | D28: What flows | E28: Type | F28: Value a year | G28: Table 2.6: boundary A | H28: Table 2.6: boundary B
A29: F1 | B29: Suppliers | C29: Meridian | D29: components | E29: goods | G29: input | H29: input
A30: F2 | B30: Meridian | C30: Suppliers | D30: payments | E30: capital | G30: output | H30: output
A31: F3 | B31: Meridian | C31: Dealer network | D31: shipments | E31: goods | F31: =B7 -> 1540 | G31: output | H31: interior
A32: F4 | B32: Dealer network | C32: Meridian | D32: payments | E32: capital | F32: =B7 -> 1540 | G32: input | H32: interior
A33: F5 | B33: Dealer network | C33: End customers | D33: sales | E33: goods | F33: =B10 -> 1848 | G33: environmental | H33: output
A34: F6 | B34: End customers | C34: Dealer network | D34: payments | E34: capital | F34: =B10 -> 1848 | G34: environmental | H34: input
A35: F7 | B35: Dealer network | C35: Meridian | D35: market intelligence | E35: information | G35: input | H35: interior
A36: F8 | B36: Capital markets | C36: Meridian | D36: funding | E36: capital | G36: input | H36: input
A37: F9 | B37: Regulator | C37: Meridian | D37: rules | E37: information | G37: input | H37: input
A39: Types from Definition 2.3's list (capital, goods, services, information, personnel). The book values four flows; the others carry no value in Table 2.6.

Sheet Boundaries
A1: Draw boundary A, move the dealers inside (Worked Example 2.1, Steps 2-5; Theorem 2.2; AXIOM Lab 1.2, steps 1-2)
A2: Definition 2.3: a flow is interior if both ends lie inside the boundary, an input if it enters, an output if it leaves, environmental if neither end is inside. 1 = inside, 0 = outside.
A4: Flow | B4: From inside A | C4: To inside A | D4: Class under A | E4: Table 2.6 | F4: Match | G4: From inside B | H4: To inside B | I4: Class under B | J4: Table 2.6 | K4: Match | L4: Relabeled A to B | M4: From inside yours | N4: To inside yours | O4: Class under yours
A5: =Declarations!A29 -> F1 | B5: =INDEX(Flags_A,MATCH(Declarations!$B29,Entities,0)) -> 0 | C5: =INDEX(Flags_A,MATCH(Declarations!$C29,Entities,0)) -> 1 | D5: =IF(AND(B5=1,C5=1),"interior",IF(AND(B5=0,C5=1),"input",IF(AND(B5=1,C5=0),"output","environmental"))) -> input | E5: =Declarations!G29 -> input | F5: =IF(D5=E5,1,0) -> 1 | G5: =INDEX(Flags_B,MATCH(Declarations!$B29,Entities,0)) -> 0 | H5: =INDEX(Flags_B,MATCH(Declarations!$C29,Entities,0)) -> 1 | I5: =IF(AND(G5=1,H5=1),"interior",IF(AND(G5=0,H5=1),"input",IF(AND(G5=1,H5=0),"output","environmental"))) -> input | J5: =Declarations!H29 -> input | K5: =IF(I5=J5,1,0) -> 1 | L5: =IF(D5<>I5,1,0) -> 0 | M5: =INDEX(Flags_you,MATCH(Declarations!$B29,Entities,0)) -> 0 | N5: =INDEX(Flags_you,MATCH(Declarations!$C29,Entities,0)) -> 1 | O5: =IF(AND(M5=1,N5=1),"interior",IF(AND(M5=0,N5=1),"input",IF(AND(M5=1,N5=0),"output","environmental"))) -> input
A6: =Declarations!A30 -> F2 | B6: =INDEX(Flags_A,MATCH(Declarations!$B30,Entities,0)) -> 1 | C6: =INDEX(Flags_A,MATCH(Declarations!$C30,Entities,0)) -> 0 | D6: =IF(AND(B6=1,C6=1),"interior",IF(AND(B6=0,C6=1),"input",IF(AND(B6=1,C6=0),"output","environmental"))) -> output | E6: =Declarations!G30 -> output | F6: =IF(D6=E6,1,0) -> 1 | G6: =INDEX(Flags_B,MATCH(Declarations!$B30,Entities,0)) -> 1 | H6: =INDEX(Flags_B,MATCH(Declarations!$C30,Entities,0)) -> 0 | I6: =IF(AND(G6=1,H6=1),"interior",IF(AND(G6=0,H6=1),"input",IF(AND(G6=1,H6=0),"output","environmental"))) -> output | J6: =Declarations!H30 -> output | K6: =IF(I6=J6,1,0) -> 1 | L6: =IF(D6<>I6,1,0) -> 0 | M6: =INDEX(Flags_you,MATCH(Declarations!$B30,Entities,0)) -> 1 | N6: =INDEX(Flags_you,MATCH(Declarations!$C30,Entities,0)) -> 0 | O6: =IF(AND(M6=1,N6=1),"interior",IF(AND(M6=0,N6=1),"input",IF(AND(M6=1,N6=0),"output","environmental"))) -> output
A7: =Declarations!A31 -> F3 | B7: =INDEX(Flags_A,MATCH(Declarations!$B31,Entities,0)) -> 1 | C7: =INDEX(Flags_A,MATCH(Declarations!$C31,Entities,0)) -> 0 | D7: =IF(AND(B7=1,C7=1),"interior",IF(AND(B7=0,C7=1),"input",IF(AND(B7=1,C7=0),"output","environmental"))) -> output | E7: =Declarations!G31 -> output | F7: =IF(D7=E7,1,0) -> 1 | G7: =INDEX(Flags_B,MATCH(Declarations!$B31,Entities,0)) -> 1 | H7: =INDEX(Flags_B,MATCH(Declarations!$C31,Entities,0)) -> 1 | I7: =IF(AND(G7=1,H7=1),"interior",IF(AND(G7=0,H7=1),"input",IF(AND(G7=1,H7=0),"output","environmental"))) -> interior | J7: =Declarations!H31 -> interior | K7: =IF(I7=J7,1,0) -> 1 | L7: =IF(D7<>I7,1,0) -> 1 | M7: =INDEX(Flags_you,MATCH(Declarations!$B31,Entities,0)) -> 1 | N7: =INDEX(Flags_you,MATCH(Declarations!$C31,Entities,0)) -> 0 | O7: =IF(AND(M7=1,N7=1),"interior",IF(AND(M7=0,N7=1),"input",IF(AND(M7=1,N7=0),"output","environmental"))) -> output
A8: =Declarations!A32 -> F4 | B8: =INDEX(Flags_A,MATCH(Declarations!$B32,Entities,0)) -> 0 | C8: =INDEX(Flags_A,MATCH(Declarations!$C32,Entities,0)) -> 1 | D8: =IF(AND(B8=1,C8=1),"interior",IF(AND(B8=0,C8=1),"input",IF(AND(B8=1,C8=0),"output","environmental"))) -> input | E8: =Declarations!G32 -> input | F8: =IF(D8=E8,1,0) -> 1 | G8: =INDEX(Flags_B,MATCH(Declarations!$B32,Entities,0)) -> 1 | H8: =INDEX(Flags_B,MATCH(Declarations!$C32,Entities,0)) -> 1 | I8: =IF(AND(G8=1,H8=1),"interior",IF(AND(G8=0,H8=1),"input",IF(AND(G8=1,H8=0),"output","environmental"))) -> interior | J8: =Declarations!H32 -> interior | K8: =IF(I8=J8,1,0) -> 1 | L8: =IF(D8<>I8,1,0) -> 1 | M8: =INDEX(Flags_you,MATCH(Declarations!$B32,Entities,0)) -> 0 | N8: =INDEX(Flags_you,MATCH(Declarations!$C32,Entities,0)) -> 1 | O8: =IF(AND(M8=1,N8=1),"interior",IF(AND(M8=0,N8=1),"input",IF(AND(M8=1,N8=0),"output","environmental"))) -> input
A9: =Declarations!A33 -> F5 | B9: =INDEX(Flags_A,MATCH(Declarations!$B33,Entities,0)) -> 0 | C9: =INDEX(Flags_A,MATCH(Declarations!$C33,Entities,0)) -> 0 | D9: =IF(AND(B9=1,C9=1),"interior",IF(AND(B9=0,C9=1),"input",IF(AND(B9=1,C9=0),"output","environmental"))) -> environmental | E9: =Declarations!G33 -> environmental | F9: =IF(D9=E9,1,0) -> 1 | G9: =INDEX(Flags_B,MATCH(Declarations!$B33,Entities,0)) -> 1 | H9: =INDEX(Flags_B,MATCH(Declarations!$C33,Entities,0)) -> 0 | I9: =IF(AND(G9=1,H9=1),"interior",IF(AND(G9=0,H9=1),"input",IF(AND(G9=1,H9=0),"output","environmental"))) -> output | J9: =Declarations!H33 -> output | K9: =IF(I9=J9,1,0) -> 1 | L9: =IF(D9<>I9,1,0) -> 1 | M9: =INDEX(Flags_you,MATCH(Declarations!$B33,Entities,0)) -> 0 | N9: =INDEX(Flags_you,MATCH(Declarations!$C33,Entities,0)) -> 0 | O9: =IF(AND(M9=1,N9=1),"interior",IF(AND(M9=0,N9=1),"input",IF(AND(M9=1,N9=0),"output","environmental"))) -> environmental
A10: =Declarations!A34 -> F6 | B10: =INDEX(Flags_A,MATCH(Declarations!$B34,Entities,0)) -> 0 | C10: =INDEX(Flags_A,MATCH(Declarations!$C34,Entities,0)) -> 0 | D10: =IF(AND(B10=1,C10=1),"interior",IF(AND(B10=0,C10=1),"input",IF(AND(B10=1,C10=0),"output","environmental"))) -> environmental | E10: =Declarations!G34 -> environmental | F10: =IF(D10=E10,1,0) -> 1 | G10: =INDEX(Flags_B,MATCH(Declarations!$B34,Entities,0)) -> 0 | H10: =INDEX(Flags_B,MATCH(Declarations!$C34,Entities,0)) -> 1 | I10: =IF(AND(G10=1,H10=1),"interior",IF(AND(G10=0,H10=1),"input",IF(AND(G10=1,H10=0),"output","environmental"))) -> input | J10: =Declarations!H34 -> input | K10: =IF(I10=J10,1,0) -> 1 | L10: =IF(D10<>I10,1,0) -> 1 | M10: =INDEX(Flags_you,MATCH(Declarations!$B34,Entities,0)) -> 0 | N10: =INDEX(Flags_you,MATCH(Declarations!$C34,Entities,0)) -> 0 | O10: =IF(AND(M10=1,N10=1),"interior",IF(AND(M10=0,N10=1),"input",IF(AND(M10=1,N10=0),"output","environmental"))) -> environmental
A11: =Declarations!A35 -> F7 | B11: =INDEX(Flags_A,MATCH(Declarations!$B35,Entities,0)) -> 0 | C11: =INDEX(Flags_A,MATCH(Declarations!$C35,Entities,0)) -> 1 | D11: =IF(AND(B11=1,C11=1),"interior",IF(AND(B11=0,C11=1),"input",IF(AND(B11=1,C11=0),"output","environmental"))) -> input | E11: =Declarations!G35 -> input | F11: =IF(D11=E11,1,0) -> 1 | G11: =INDEX(Flags_B,MATCH(Declarations!$B35,Entities,0)) -> 1 | H11: =INDEX(Flags_B,MATCH(Declarations!$C35,Entities,0)) -> 1 | I11: =IF(AND(G11=1,H11=1),"interior",IF(AND(G11=0,H11=1),"input",IF(AND(G11=1,H11=0),"output","environmental"))) -> interior | J11: =Declarations!H35 -> interior | K11: =IF(I11=J11,1,0) -> 1 | L11: =IF(D11<>I11,1,0) -> 1 | M11: =INDEX(Flags_you,MATCH(Declarations!$B35,Entities,0)) -> 0 | N11: =INDEX(Flags_you,MATCH(Declarations!$C35,Entities,0)) -> 1 | O11: =IF(AND(M11=1,N11=1),"interior",IF(AND(M11=0,N11=1),"input",IF(AND(M11=1,N11=0),"output","environmental"))) -> input
A12: =Declarations!A36 -> F8 | B12: =INDEX(Flags_A,MATCH(Declarations!$B36,Entities,0)) -> 0 | C12: =INDEX(Flags_A,MATCH(Declarations!$C36,Entities,0)) -> 1 | D12: =IF(AND(B12=1,C12=1),"interior",IF(AND(B12=0,C12=1),"input",IF(AND(B12=1,C12=0),"output","environmental"))) -> input | E12: =Declarations!G36 -> input | F12: =IF(D12=E12,1,0) -> 1 | G12: =INDEX(Flags_B,MATCH(Declarations!$B36,Entities,0)) -> 0 | H12: =INDEX(Flags_B,MATCH(Declarations!$C36,Entities,0)) -> 1 | I12: =IF(AND(G12=1,H12=1),"interior",IF(AND(G12=0,H12=1),"input",IF(AND(G12=1,H12=0),"output","environmental"))) -> input | J12: =Declarations!H36 -> input | K12: =IF(I12=J12,1,0) -> 1 | L12: =IF(D12<>I12,1,0) -> 0 | M12: =INDEX(Flags_you,MATCH(Declarations!$B36,Entities,0)) -> 0 | N12: =INDEX(Flags_you,MATCH(Declarations!$C36,Entities,0)) -> 1 | O12: =IF(AND(M12=1,N12=1),"interior",IF(AND(M12=0,N12=1),"input",IF(AND(M12=1,N12=0),"output","environmental"))) -> input
A13: =Declarations!A37 -> F9 | B13: =INDEX(Flags_A,MATCH(Declarations!$B37,Entities,0)) -> 0 | C13: =INDEX(Flags_A,MATCH(Declarations!$C37,Entities,0)) -> 1 | D13: =IF(AND(B13=1,C13=1),"interior",IF(AND(B13=0,C13=1),"input",IF(AND(B13=1,C13=0),"output","environmental"))) -> input | E13: =Declarations!G37 -> input | F13: =IF(D13=E13,1,0) -> 1 | G13: =INDEX(Flags_B,MATCH(Declarations!$B37,Entities,0)) -> 0 | H13: =INDEX(Flags_B,MATCH(Declarations!$C37,Entities,0)) -> 1 | I13: =IF(AND(G13=1,H13=1),"interior",IF(AND(G13=0,H13=1),"input",IF(AND(G13=1,H13=0),"output","environmental"))) -> input | J13: =Declarations!H37 -> input | K13: =IF(I13=J13,1,0) -> 1 | L13: =IF(D13<>I13,1,0) -> 0 | M13: =INDEX(Flags_you,MATCH(Declarations!$B37,Entities,0)) -> 0 | N13: =INDEX(Flags_you,MATCH(Declarations!$C37,Entities,0)) -> 1 | O13: =IF(AND(M13=1,N13=1),"interior",IF(AND(M13=0,N13=1),"input",IF(AND(M13=1,N13=0),"output","environmental"))) -> input
A16: Class | B16: Boundary A | C16: Boundary B | D16: Your boundary
A17: interior | B17: =COUNTIF(D$5:D$13,$A17) -> 0 | C17: =COUNTIF(I$5:I$13,$A17) -> 3 | D17: =COUNTIF(O$5:O$13,$A17) -> 0
A18: input | B18: =COUNTIF(D$5:D$13,$A18) -> 5 | C18: =COUNTIF(I$5:I$13,$A18) -> 4 | D18: =COUNTIF(O$5:O$13,$A18) -> 5
A19: output | B19: =COUNTIF(D$5:D$13,$A19) -> 2 | C19: =COUNTIF(I$5:I$13,$A19) -> 2 | D19: =COUNTIF(O$5:O$13,$A19) -> 2
A20: environmental | B20: =COUNTIF(D$5:D$13,$A20) -> 2 | C20: =COUNTIF(I$5:I$13,$A20) -> 0 | D20: =COUNTIF(O$5:O$13,$A20) -> 2
A21: Total: the same nine flows | B21: =SUM(B17:B20) -> 9 | C21: =SUM(C17:C20) -> 9 | D21: =SUM(D17:D20) -> 9
A22: Rows that reproduce Table 2.6 (of 9) | B22: =SUM(F5:F13) -> 9 | C22: =SUM(K5:K13) -> 9
A23: Flows relabeled by moving the dealers inside | C23: =SUM(L5:L13) -> 5
A24: Goods output: valued goods flows leaving the boundary | B24: =SUMIFS(Declarations!$F$29:$F$37,D$5:D$13,"output",Declarations!$E$29:$E$37,"goods") -> 1540 | C24: =SUMIFS(Declarations!$F$29:$F$37,I$5:I$13,"output",Declarations!$E$29:$E$37,"goods") -> 1848 | D24: =SUMIFS(Declarations!$F$29:$F$37,O$5:O$13,"output",Declarations!$E$29:$E$37,"goods") -> 1540
A25: Difference from boundary A | C25: =C24-B24 -> 308 | D25: =D24-B24 -> 0
A26: Difference as a share of boundary A's goods output | C26: =C25/B24 -> 0.2
A27: The dealers' gross margin (Declarations) | C27: =Margin -> 308
A29: Valued flows by class ($ million a year) | B29: Boundary A | C29: Boundary B | D29: Your boundary
A30: interior | B30: =SUMIFS(Declarations!$F$29:$F$37,D$5:D$13,$A30) -> 0 | C30: =SUMIFS(Declarations!$F$29:$F$37,I$5:I$13,$A30) -> 3080 | D30: =SUMIFS(Declarations!$F$29:$F$37,O$5:O$13,$A30) -> 0
A31: input | B31: =SUMIFS(Declarations!$F$29:$F$37,D$5:D$13,$A31) -> 1540 | C31: =SUMIFS(Declarations!$F$29:$F$37,I$5:I$13,$A31) -> 1848 | D31: =SUMIFS(Declarations!$F$29:$F$37,O$5:O$13,$A31) -> 1540
A32: output | B32: =SUMIFS(Declarations!$F$29:$F$37,D$5:D$13,$A32) -> 1540 | C32: =SUMIFS(Declarations!$F$29:$F$37,I$5:I$13,$A32) -> 1848 | D32: =SUMIFS(Declarations!$F$29:$F$37,O$5:O$13,$A32) -> 1540
A33: environmental | B33: =SUMIFS(Declarations!$F$29:$F$37,D$5:D$13,$A33) -> 3696 | C33: =SUMIFS(Declarations!$F$29:$F$37,I$5:I$13,$A33) -> 0 | D33: =SUMIFS(Declarations!$F$29:$F$37,O$5:O$13,$A33) -> 3696
A34: Total: the money is the same money | B34: =SUM(B30:B33) -> 6776 | C34: =SUM(C30:C33) -> 6776 | D34: =SUM(D30:D33) -> 6776
A36: The $308 million gap is a boundary difference, not a performance difference: compare options under one declared boundary (Worked Example 2.1, Step 6). Drawing the dealers inside does not give Meridian control of their prices.

Sheet AllBoundaries
A1: Every boundary: the 64 ways to draw the line around six entities (Theorem 2.2; Corollary 2.B.2)
A2: Boundary n puts entity j inside when bit j of n is 1. Codes: I interior, N input, O output, E environmental. Rows 3-4: each flow's two ends, as entity numbers.
A3: from (entity no.) | H3: =MATCH(Declarations!B29,Entities,0) -> 1 | I3: =MATCH(Declarations!B30,Entities,0) -> 2 | J3: =MATCH(Declarations!B31,Entities,0) -> 2 | K3: =MATCH(Declarations!B32,Entities,0) -> 3 | L3: =MATCH(Declarations!B33,Entities,0) -> 3 | M3: =MATCH(Declarations!B34,Entities,0) -> 4 | N3: =MATCH(Declarations!B35,Entities,0) -> 3 | O3: =MATCH(Declarations!B36,Entities,0) -> 5 | P3: =MATCH(Declarations!B37,Entities,0) -> 6
A4: to (entity no.) | H4: =MATCH(Declarations!C29,Entities,0) -> 2 | I4: =MATCH(Declarations!C30,Entities,0) -> 1 | J4: =MATCH(Declarations!C31,Entities,0) -> 3 | K4: =MATCH(Declarations!C32,Entities,0) -> 2 | L4: =MATCH(Declarations!C33,Entities,0) -> 4 | M4: =MATCH(Declarations!C34,Entities,0) -> 3 | N4: =MATCH(Declarations!C35,Entities,0) -> 2 | O4: =MATCH(Declarations!C36,Entities,0) -> 2 | P4: =MATCH(Declarations!C37,Entities,0) -> 2
A5: n | B5: Suppliers | C5: Meridian | D5: Dealer network | E5: End customers | F5: Capital markets | G5: Regulator | H5: F1 | I5: F2 | J5: F3 | K5: F4 | L5: F5 | M5: F6 | N5: F7 | O5: F8 | P5: F9 | Q5: interior | R5: input | S5: output | T5: environmental | U5: total | V5: signature | W5: goods | X5: capital | Y5: information | AA5: Summary | AB5: Value
A6: 0 | B6: =MOD(INT($A6/2^0),2) -> 0 | C6: =MOD(INT($A6/2^1),2) -> 0 | D6: =MOD(INT($A6/2^2),2) -> 0 | E6: =MOD(INT($A6/2^3),2) -> 0 | F6: =MOD(INT($A6/2^4),2) -> 0 | G6: =MOD(INT($A6/2^5),2) -> 0 | H6: =CHOOSE(1+2*INDEX($B6:$G6,H$3)+INDEX($B6:$G6,H$4),"E","N","O","I") -> E | I6: =CHOOSE(1+2*INDEX($B6:$G6,I$3)+INDEX($B6:$G6,I$4),"E","N","O","I") -> E | J6: =CHOOSE(1+2*INDEX($B6:$G6,J$3)+INDEX($B6:$G6,J$4),"E","N","O","I") -> E | K6: =CHOOSE(1+2*INDEX($B6:$G6,K$3)+INDEX($B6:$G6,K$4),"E","N","O","I") -> E | L6: =CHOOSE(1+2*INDEX($B6:$G6,L$3)+INDEX($B6:$G6,L$4),"E","N","O","I") -> E | M6: =CHOOSE(1+2*INDEX($B6:$G6,M$3)+INDEX($B6:$G6,M$4),"E","N","O","I") -> E | N6: =CHOOSE(1+2*INDEX($B6:$G6,N$3)+INDEX($B6:$G6,N$4),"E","N","O","I") -> E | O6: =CHOOSE(1+2*INDEX($B6:$G6,O$3)+INDEX($B6:$G6,O$4),"E","N","O","I") -> E | P6: =CHOOSE(1+2*INDEX($B6:$G6,P$3)+INDEX($B6:$G6,P$4),"E","N","O","I") -> E | Q6: =COUNTIF($H6:$P6,"I") -> 0 | R6: =COUNTIF($H6:$P6,"N") -> 0 | S6: =COUNTIF($H6:$P6,"O") -> 0 | T6: =COUNTIF($H6:$P6,"E") -> 9 | U6: =SUM(Q6:T6) -> 9 | V6: =H6&I6&J6&K6&L6&M6&N6&O6&P6 -> EEEEEEEEE | W6: =IF(Declarations!$E$29="goods",H6,"")&IF(Declarations!$E$30="goods",I6,"")&IF(Declarations!$E$31="goods",J6,"")&IF(Declarations!$E$32="goods",K6,"")&IF(Declarations!$E$33="goods",L6,"")&IF(Declarations!$E$34="goods",M6,"")&IF(Declarations!$E$35="goods",N6,"")&IF(Declarations!$E$36="goods",O6,"")&IF(Declarations!$E$37="goods",P6,"") -> EEE | X6: =IF(Declarations!$E$29="capital",H6,"")&IF(Declarations!$E$30="capital",I6,"")&IF(Declarations!$E$31="capital",J6,"")&IF(Declarations!$E$32="capital",K6,"")&IF(Declarations!$E$33="capital",L6,"")&IF(Declarations!$E$34="capital",M6,"")&IF(Declarations!$E$35="capital",N6,"")&IF(Declarations!$E$36="capital",O6,"")&IF(Declarations!$E$37="capital",P6,"") -> EEEE | Y6: =IF(Declarations!$E$29="information",H6,"")&IF(Declarations!$E$30="information",I6,"")&IF(Declarations!$E$31="information",J6,"")&IF(Declarations!$E$32="information",K6,"")&IF(Declarations!$E$33="information",L6,"")&IF(Declarations!$E$34="information",M6,"")&IF(Declarations!$E$35="information",N6,"")&IF(Declarations!$E$36="information",O6,"")&IF(Declarations!$E$37="information",P6,"") -> EE | AA6: Boundaries | AB6: =COUNT(A6:A69) -> 64
A7: 1 | B7: =MOD(INT($A7/2^0),2) -> 1 | C7: =MOD(INT($A7/2^1),2) -> 0 | D7: =MOD(INT($A7/2^2),2) -> 0 | E7: =MOD(INT($A7/2^3),2) -> 0 | F7: =MOD(INT($A7/2^4),2) -> 0 | G7: =MOD(INT($A7/2^5),2) -> 0 | H7: =CHOOSE(1+2*INDEX($B7:$G7,H$3)+INDEX($B7:$G7,H$4),"E","N","O","I") -> O | I7: =CHOOSE(1+2*INDEX($B7:$G7,I$3)+INDEX($B7:$G7,I$4),"E","N","O","I") -> N | J7: =CHOOSE(1+2*INDEX($B7:$G7,J$3)+INDEX($B7:$G7,J$4),"E","N","O","I") -> E | K7: =CHOOSE(1+2*INDEX($B7:$G7,K$3)+INDEX($B7:$G7,K$4),"E","N","O","I") -> E | L7: =CHOOSE(1+2*INDEX($B7:$G7,L$3)+INDEX($B7:$G7,L$4),"E","N","O","I") -> E | M7: =CHOOSE(1+2*INDEX($B7:$G7,M$3)+INDEX($B7:$G7,M$4),"E","N","O","I") -> E | N7: =CHOOSE(1+2*INDEX($B7:$G7,N$3)+INDEX($B7:$G7,N$4),"E","N","O","I") -> E | O7: =CHOOSE(1+2*INDEX($B7:$G7,O$3)+INDEX($B7:$G7,O$4),"E","N","O","I") -> E | P7: =CHOOSE(1+2*INDEX($B7:$G7,P$3)+INDEX($B7:$G7,P$4),"E","N","O","I") -> E | Q7: =COUNTIF($H7:$P7,"I") -> 0 | R7: =COUNTIF($H7:$P7,"N") -> 1 | S7: =COUNTIF($H7:$P7,"O") -> 1 | T7: =COUNTIF($H7:$P7,"E") -> 7 | U7: =SUM(Q7:T7) -> 9 | V7: =H7&I7&J7&K7&L7&M7&N7&O7&P7 -> ONEEEEEEE | W7: =IF(Declarations!$E$29="goods",H7,"")&IF(Declarations!$E$30="goods",I7,"")&IF(Declarations!$E$31="goods",J7,"")&IF(Declarations!$E$32="goods",K7,"")&IF(Declarations!$E$33="goods",L7,"")&IF(Declarations!$E$34="goods",M7,"")&IF(Declarations!$E$35="goods",N7,"")&IF(Declarations!$E$36="goods",O7,"")&IF(Declarations!$E$37="goods",P7,"") -> OEE | X7: =IF(Declarations!$E$29="capital",H7,"")&IF(Declarations!$E$30="capital",I7,"")&IF(Declarations!$E$31="capital",J7,"")&IF(Declarations!$E$32="capital",K7,"")&IF(Declarations!$E$33="capital",L7,"")&IF(Declarations!$E$34="capital",M7,"")&IF(Declarations!$E$35="capital",N7,"")&IF(Declarations!$E$36="capital",O7,"")&IF(Declarations!$E$37="capital",P7,"") -> NEEE | Y7: =IF(Declarations!$E$29="information",H7,"")&IF(Declarations!$E$30="information",I7,"")&IF(Declarations!$E$31="information",J7,"")&IF(Declarations!$E$32="information",K7,"")&IF(Declarations!$E$33="information",L7,"")&IF(Declarations!$E$34="information",M7,"")&IF(Declarations!$E$35="information",N7,"")&IF(Declarations!$E$36="information",O7,"")&IF(Declarations!$E$37="information",P7,"") -> EE | AA7: Flows under every boundary: fewest | AB7: =MIN(U6:U69) -> 9
A8: 2 | B8: =MOD(INT($A8/2^0),2) -> 0 | C8: =MOD(INT($A8/2^1),2) -> 1 | D8: =MOD(INT($A8/2^2),2) -> 0 | E8: =MOD(INT($A8/2^3),2) -> 0 | F8: =MOD(INT($A8/2^4),2) -> 0 | G8: =MOD(INT($A8/2^5),2) -> 0 | H8: =CHOOSE(1+2*INDEX($B8:$G8,H$3)+INDEX($B8:$G8,H$4),"E","N","O","I") -> N | I8: =CHOOSE(1+2*INDEX($B8:$G8,I$3)+INDEX($B8:$G8,I$4),"E","N","O","I") -> O | J8: =CHOOSE(1+2*INDEX($B8:$G8,J$3)+INDEX($B8:$G8,J$4),"E","N","O","I") -> O | K8: =CHOOSE(1+2*INDEX($B8:$G8,K$3)+INDEX($B8:$G8,K$4),"E","N","O","I") -> N | L8: =CHOOSE(1+2*INDEX($B8:$G8,L$3)+INDEX($B8:$G8,L$4),"E","N","O","I") -> E | M8: =CHOOSE(1+2*INDEX($B8:$G8,M$3)+INDEX($B8:$G8,M$4),"E","N","O","I") -> E | N8: =CHOOSE(1+2*INDEX($B8:$G8,N$3)+INDEX($B8:$G8,N$4),"E","N","O","I") -> N | O8: =CHOOSE(1+2*INDEX($B8:$G8,O$3)+INDEX($B8:$G8,O$4),"E","N","O","I") -> N | P8: =CHOOSE(1+2*INDEX($B8:$G8,P$3)+INDEX($B8:$G8,P$4),"E","N","O","I") -> N | Q8: =COUNTIF($H8:$P8,"I") -> 0 | R8: =COUNTIF($H8:$P8,"N") -> 5 | S8: =COUNTIF($H8:$P8,"O") -> 2 | T8: =COUNTIF($H8:$P8,"E") -> 2 | U8: =SUM(Q8:T8) -> 9 | V8: =H8&I8&J8&K8&L8&M8&N8&O8&P8 -> NOONEENNN | W8: =IF(Declarations!$E$29="goods",H8,"")&IF(Declarations!$E$30="goods",I8,"")&IF(Declarations!$E$31="goods",J8,"")&IF(Declarations!$E$32="goods",K8,"")&IF(Declarations!$E$33="goods",L8,"")&IF(Declarations!$E$34="goods",M8,"")&IF(Declarations!$E$35="goods",N8,"")&IF(Declarations!$E$36="goods",O8,"")&IF(Declarations!$E$37="goods",P8,"") -> NOE | X8: =IF(Declarations!$E$29="capital",H8,"")&IF(Declarations!$E$30="capital",I8,"")&IF(Declarations!$E$31="capital",J8,"")&IF(Declarations!$E$32="capital",K8,"")&IF(Declarations!$E$33="capital",L8,"")&IF(Declarations!$E$34="capital",M8,"")&IF(Declarations!$E$35="capital",N8,"")&IF(Declarations!$E$36="capital",O8,"")&IF(Declarations!$E$37="capital",P8,"") -> ONEN | Y8: =IF(Declarations!$E$29="information",H8,"")&IF(Declarations!$E$30="information",I8,"")&IF(Declarations!$E$31="information",J8,"")&IF(Declarations!$E$32="information",K8,"")&IF(Declarations!$E$33="information",L8,"")&IF(Declarations!$E$34="information",M8,"")&IF(Declarations!$E$35="information",N8,"")&IF(Declarations!$E$36="information",O8,"")&IF(Declarations!$E$37="information",P8,"") -> NN | AA8: Flows under every boundary: most | AB8: =MAX(U6:U69) -> 9
A9: 3 | B9: =MOD(INT($A9/2^0),2) -> 1 | C9: =MOD(INT($A9/2^1),2) -> 1 | D9: =MOD(INT($A9/2^2),2) -> 0 | E9: =MOD(INT($A9/2^3),2) -> 0 | F9: =MOD(INT($A9/2^4),2) -> 0 | G9: =MOD(INT($A9/2^5),2) -> 0 | H9: =CHOOSE(1+2*INDEX($B9:$G9,H$3)+INDEX($B9:$G9,H$4),"E","N","O","I") -> I | I9: =CHOOSE(1+2*INDEX($B9:$G9,I$3)+INDEX($B9:$G9,I$4),"E","N","O","I") -> I | J9: =CHOOSE(1+2*INDEX($B9:$G9,J$3)+INDEX($B9:$G9,J$4),"E","N","O","I") -> O | K9: =CHOOSE(1+2*INDEX($B9:$G9,K$3)+INDEX($B9:$G9,K$4),"E","N","O","I") -> N | L9: =CHOOSE(1+2*INDEX($B9:$G9,L$3)+INDEX($B9:$G9,L$4),"E","N","O","I") -> E | M9: =CHOOSE(1+2*INDEX($B9:$G9,M$3)+INDEX($B9:$G9,M$4),"E","N","O","I") -> E | N9: =CHOOSE(1+2*INDEX($B9:$G9,N$3)+INDEX($B9:$G9,N$4),"E","N","O","I") -> N | O9: =CHOOSE(1+2*INDEX($B9:$G9,O$3)+INDEX($B9:$G9,O$4),"E","N","O","I") -> N | P9: =CHOOSE(1+2*INDEX($B9:$G9,P$3)+INDEX($B9:$G9,P$4),"E","N","O","I") -> N | Q9: =COUNTIF($H9:$P9,"I") -> 2 | R9: =COUNTIF($H9:$P9,"N") -> 4 | S9: =COUNTIF($H9:$P9,"O") -> 1 | T9: =COUNTIF($H9:$P9,"E") -> 2 | U9: =SUM(Q9:T9) -> 9 | V9: =H9&I9&J9&K9&L9&M9&N9&O9&P9 -> IIONEENNN | W9: =IF(Declarations!$E$29="goods",H9,"")&IF(Declarations!$E$30="goods",I9,"")&IF(Declarations!$E$31="goods",J9,"")&IF(Declarations!$E$32="goods",K9,"")&IF(Declarations!$E$33="goods",L9,"")&IF(Declarations!$E$34="goods",M9,"")&IF(Declarations!$E$35="goods",N9,"")&IF(Declarations!$E$36="goods",O9,"")&IF(Declarations!$E$37="goods",P9,"") -> IOE | X9: =IF(Declarations!$E$29="capital",H9,"")&IF(Declarations!$E$30="capital",I9,"")&IF(Declarations!$E$31="capital",J9,"")&IF(Declarations!$E$32="capital",K9,"")&IF(Declarations!$E$33="capital",L9,"")&IF(Declarations!$E$34="capital",M9,"")&IF(Declarations!$E$35="capital",N9,"")&IF(Declarations!$E$36="capital",O9,"")&IF(Declarations!$E$37="capital",P9,"") -> INEN | Y9: =IF(Declarations!$E$29="information",H9,"")&IF(Declarations!$E$30="information",I9,"")&IF(Declarations!$E$31="information",J9,"")&IF(Declarations!$E$32="information",K9,"")&IF(Declarations!$E$33="information",L9,"")&IF(Declarations!$E$34="information",M9,"")&IF(Declarations!$E$35="information",N9,"")&IF(Declarations!$E$36="information",O9,"")&IF(Declarations!$E$37="information",P9,"") -> NN | AA9: Flows not in exactly one class, all boundaries (Theorem 2.2(i)) | AB9: =SUMPRODUCT(ABS(U6:U69-9)) -> 0
A10: 4 | B10: =MOD(INT($A10/2^0),2) -> 0 | C10: =MOD(INT($A10/2^1),2) -> 0 | D10: =MOD(INT($A10/2^2),2) -> 1 | E10: =MOD(INT($A10/2^3),2) -> 0 | F10: =MOD(INT($A10/2^4),2) -> 0 | G10: =MOD(INT($A10/2^5),2) -> 0 | H10: =CHOOSE(1+2*INDEX($B10:$G10,H$3)+INDEX($B10:$G10,H$4),"E","N","O","I") -> E | I10: =CHOOSE(1+2*INDEX($B10:$G10,I$3)+INDEX($B10:$G10,I$4),"E","N","O","I") -> E | J10: =CHOOSE(1+2*INDEX($B10:$G10,J$3)+INDEX($B10:$G10,J$4),"E","N","O","I") -> N | K10: =CHOOSE(1+2*INDEX($B10:$G10,K$3)+INDEX($B10:$G10,K$4),"E","N","O","I") -> O | L10: =CHOOSE(1+2*INDEX($B10:$G10,L$3)+INDEX($B10:$G10,L$4),"E","N","O","I") -> O | M10: =CHOOSE(1+2*INDEX($B10:$G10,M$3)+INDEX($B10:$G10,M$4),"E","N","O","I") -> N | N10: =CHOOSE(1+2*INDEX($B10:$G10,N$3)+INDEX($B10:$G10,N$4),"E","N","O","I") -> O | O10: =CHOOSE(1+2*INDEX($B10:$G10,O$3)+INDEX($B10:$G10,O$4),"E","N","O","I") -> E | P10: =CHOOSE(1+2*INDEX($B10:$G10,P$3)+INDEX($B10:$G10,P$4),"E","N","O","I") -> E | Q10: =COUNTIF($H10:$P10,"I") -> 0 | R10: =COUNTIF($H10:$P10,"N") -> 2 | S10: =COUNTIF($H10:$P10,"O") -> 3 | T10: =COUNTIF($H10:$P10,"E") -> 4 | U10: =SUM(Q10:T10) -> 9 | V10: =H10&I10&J10&K10&L10&M10&N10&O10&P10 -> EENOONOEE | W10: =IF(Declarations!$E$29="goods",H10,"")&IF(Declarations!$E$30="goods",I10,"")&IF(Declarations!$E$31="goods",J10,"")&IF(Declarations!$E$32="goods",K10,"")&IF(Declarations!$E$33="goods",L10,"")&IF(Declarations!$E$34="goods",M10,"")&IF(Declarations!$E$35="goods",N10,"")&IF(Declarations!$E$36="goods",O10,"")&IF(Declarations!$E$37="goods",P10,"") -> ENO | X10: =IF(Declarations!$E$29="capital",H10,"")&IF(Declarations!$E$30="capital",I10,"")&IF(Declarations!$E$31="capital",J10,"")&IF(Declarations!$E$32="capital",K10,"")&IF(Declarations!$E$33="capital",L10,"")&IF(Declarations!$E$34="capital",M10,"")&IF(Declarations!$E$35="capital",N10,"")&IF(Declarations!$E$36="capital",O10,"")&IF(Declarations!$E$37="capital",P10,"") -> EONE | Y10: =IF(Declarations!$E$29="information",H10,"")&IF(Declarations!$E$30="information",I10,"")&IF(Declarations!$E$31="information",J10,"")&IF(Declarations!$E$32="information",K10,"")&IF(Declarations!$E$33="information",L10,"")&IF(Declarations!$E$34="information",M10,"")&IF(Declarations!$E$35="information",N10,"")&IF(Declarations!$E$36="information",O10,"")&IF(Declarations!$E$37="information",P10,"") -> OE | AA10: Distinct classifications of the nine flows (Theorem 2.2(iii)) | AB10: =SUMPRODUCT(1/COUNTIF(V6:V69,V6:V69)) -> 64
A11: 5 | B11: =MOD(INT($A11/2^0),2) -> 1 | C11: =MOD(INT($A11/2^1),2) -> 0 | D11: =MOD(INT($A11/2^2),2) -> 1 | E11: =MOD(INT($A11/2^3),2) -> 0 | F11: =MOD(INT($A11/2^4),2) -> 0 | G11: =MOD(INT($A11/2^5),2) -> 0 | H11: =CHOOSE(1+2*INDEX($B11:$G11,H$3)+INDEX($B11:$G11,H$4),"E","N","O","I") -> O | I11: =CHOOSE(1+2*INDEX($B11:$G11,I$3)+INDEX($B11:$G11,I$4),"E","N","O","I") -> N | J11: =CHOOSE(1+2*INDEX($B11:$G11,J$3)+INDEX($B11:$G11,J$4),"E","N","O","I") -> N | K11: =CHOOSE(1+2*INDEX($B11:$G11,K$3)+INDEX($B11:$G11,K$4),"E","N","O","I") -> O | L11: =CHOOSE(1+2*INDEX($B11:$G11,L$3)+INDEX($B11:$G11,L$4),"E","N","O","I") -> O | M11: =CHOOSE(1+2*INDEX($B11:$G11,M$3)+INDEX($B11:$G11,M$4),"E","N","O","I") -> N | N11: =CHOOSE(1+2*INDEX($B11:$G11,N$3)+INDEX($B11:$G11,N$4),"E","N","O","I") -> O | O11: =CHOOSE(1+2*INDEX($B11:$G11,O$3)+INDEX($B11:$G11,O$4),"E","N","O","I") -> E | P11: =CHOOSE(1+2*INDEX($B11:$G11,P$3)+INDEX($B11:$G11,P$4),"E","N","O","I") -> E | Q11: =COUNTIF($H11:$P11,"I") -> 0 | R11: =COUNTIF($H11:$P11,"N") -> 3 | S11: =COUNTIF($H11:$P11,"O") -> 4 | T11: =COUNTIF($H11:$P11,"E") -> 2 | U11: =SUM(Q11:T11) -> 9 | V11: =H11&I11&J11&K11&L11&M11&N11&O11&P11 -> ONNOONOEE | W11: =IF(Declarations!$E$29="goods",H11,"")&IF(Declarations!$E$30="goods",I11,"")&IF(Declarations!$E$31="goods",J11,"")&IF(Declarations!$E$32="goods",K11,"")&IF(Declarations!$E$33="goods",L11,"")&IF(Declarations!$E$34="goods",M11,"")&IF(Declarations!$E$35="goods",N11,"")&IF(Declarations!$E$36="goods",O11,"")&IF(Declarations!$E$37="goods",P11,"") -> ONO | X11: =IF(Declarations!$E$29="capital",H11,"")&IF(Declarations!$E$30="capital",I11,"")&IF(Declarations!$E$31="capital",J11,"")&IF(Declarations!$E$32="capital",K11,"")&IF(Declarations!$E$33="capital",L11,"")&IF(Declarations!$E$34="capital",M11,"")&IF(Declarations!$E$35="capital",N11,"")&IF(Declarations!$E$36="capital",O11,"")&IF(Declarations!$E$37="capital",P11,"") -> NONE | Y11: =IF(Declarations!$E$29="information",H11,"")&IF(Declarations!$E$30="information",I11,"")&IF(Declarations!$E$31="information",J11,"")&IF(Declarations!$E$32="information",K11,"")&IF(Declarations!$E$33="information",L11,"")&IF(Declarations!$E$34="information",M11,"")&IF(Declarations!$E$35="information",N11,"")&IF(Declarations!$E$36="information",O11,"")&IF(Declarations!$E$37="information",P11,"") -> OE | AA11: Distinct classifications of the goods flows | AB11: =SUMPRODUCT(1/COUNTIF(W6:W69,W6:W69)) -> 16
A12: 6 | B12: =MOD(INT($A12/2^0),2) -> 0 | C12: =MOD(INT($A12/2^1),2) -> 1 | D12: =MOD(INT($A12/2^2),2) -> 1 | E12: =MOD(INT($A12/2^3),2) -> 0 | F12: =MOD(INT($A12/2^4),2) -> 0 | G12: =MOD(INT($A12/2^5),2) -> 0 | H12: =CHOOSE(1+2*INDEX($B12:$G12,H$3)+INDEX($B12:$G12,H$4),"E","N","O","I") -> N | I12: =CHOOSE(1+2*INDEX($B12:$G12,I$3)+INDEX($B12:$G12,I$4),"E","N","O","I") -> O | J12: =CHOOSE(1+2*INDEX($B12:$G12,J$3)+INDEX($B12:$G12,J$4),"E","N","O","I") -> I | K12: =CHOOSE(1+2*INDEX($B12:$G12,K$3)+INDEX($B12:$G12,K$4),"E","N","O","I") -> I | L12: =CHOOSE(1+2*INDEX($B12:$G12,L$3)+INDEX($B12:$G12,L$4),"E","N","O","I") -> O | M12: =CHOOSE(1+2*INDEX($B12:$G12,M$3)+INDEX($B12:$G12,M$4),"E","N","O","I") -> N | N12: =CHOOSE(1+2*INDEX($B12:$G12,N$3)+INDEX($B12:$G12,N$4),"E","N","O","I") -> I | O12: =CHOOSE(1+2*INDEX($B12:$G12,O$3)+INDEX($B12:$G12,O$4),"E","N","O","I") -> N | P12: =CHOOSE(1+2*INDEX($B12:$G12,P$3)+INDEX($B12:$G12,P$4),"E","N","O","I") -> N | Q12: =COUNTIF($H12:$P12,"I") -> 3 | R12: =COUNTIF($H12:$P12,"N") -> 4 | S12: =COUNTIF($H12:$P12,"O") -> 2 | T12: =COUNTIF($H12:$P12,"E") -> 0 | U12: =SUM(Q12:T12) -> 9 | V12: =H12&I12&J12&K12&L12&M12&N12&O12&P12 -> NOIIONINN | W12: =IF(Declarations!$E$29="goods",H12,"")&IF(Declarations!$E$30="goods",I12,"")&IF(Declarations!$E$31="goods",J12,"")&IF(Declarations!$E$32="goods",K12,"")&IF(Declarations!$E$33="goods",L12,"")&IF(Declarations!$E$34="goods",M12,"")&IF(Declarations!$E$35="goods",N12,"")&IF(Declarations!$E$36="goods",O12,"")&IF(Declarations!$E$37="goods",P12,"") -> NIO | X12: =IF(Declarations!$E$29="capital",H12,"")&IF(Declarations!$E$30="capital",I12,"")&IF(Declarations!$E$31="capital",J12,"")&IF(Declarations!$E$32="capital",K12,"")&IF(Declarations!$E$33="capital",L12,"")&IF(Declarations!$E$34="capital",M12,"")&IF(Declarations!$E$35="capital",N12,"")&IF(Declarations!$E$36="capital",O12,"")&IF(Declarations!$E$37="capital",P12,"") -> OINN | Y12: =IF(Declarations!$E$29="information",H12,"")&IF(Declarations!$E$30="information",I12,"")&IF(Declarations!$E$31="information",J12,"")&IF(Declarations!$E$32="information",K12,"")&IF(Declarations!$E$33="information",L12,"")&IF(Declarations!$E$34="information",M12,"")&IF(Declarations!$E$35="information",N12,"")&IF(Declarations!$E$36="information",O12,"")&IF(Declarations!$E$37="information",P12,"") -> IN | AA12: Distinct classifications of the capital flows | AB12: =SUMPRODUCT(1/COUNTIF(X6:X69,X6:X69)) -> 32
A13: 7 | B13: =MOD(INT($A13/2^0),2) -> 1 | C13: =MOD(INT($A13/2^1),2) -> 1 | D13: =MOD(INT($A13/2^2),2) -> 1 | E13: =MOD(INT($A13/2^3),2) -> 0 | F13: =MOD(INT($A13/2^4),2) -> 0 | G13: =MOD(INT($A13/2^5),2) -> 0 | H13: =CHOOSE(1+2*INDEX($B13:$G13,H$3)+INDEX($B13:$G13,H$4),"E","N","O","I") -> I | I13: =CHOOSE(1+2*INDEX($B13:$G13,I$3)+INDEX($B13:$G13,I$4),"E","N","O","I") -> I | J13: =CHOOSE(1+2*INDEX($B13:$G13,J$3)+INDEX($B13:$G13,J$4),"E","N","O","I") -> I | K13: =CHOOSE(1+2*INDEX($B13:$G13,K$3)+INDEX($B13:$G13,K$4),"E","N","O","I") -> I | L13: =CHOOSE(1+2*INDEX($B13:$G13,L$3)+INDEX($B13:$G13,L$4),"E","N","O","I") -> O | M13: =CHOOSE(1+2*INDEX($B13:$G13,M$3)+INDEX($B13:$G13,M$4),"E","N","O","I") -> N | N13: =CHOOSE(1+2*INDEX($B13:$G13,N$3)+INDEX($B13:$G13,N$4),"E","N","O","I") -> I | O13: =CHOOSE(1+2*INDEX($B13:$G13,O$3)+INDEX($B13:$G13,O$4),"E","N","O","I") -> N | P13: =CHOOSE(1+2*INDEX($B13:$G13,P$3)+INDEX($B13:$G13,P$4),"E","N","O","I") -> N | Q13: =COUNTIF($H13:$P13,"I") -> 5 | R13: =COUNTIF($H13:$P13,"N") -> 3 | S13: =COUNTIF($H13:$P13,"O") -> 1 | T13: =COUNTIF($H13:$P13,"E") -> 0 | U13: =SUM(Q13:T13) -> 9 | V13: =H13&I13&J13&K13&L13&M13&N13&O13&P13 -> IIIIONINN | W13: =IF(Declarations!$E$29="goods",H13,"")&IF(Declarations!$E$30="goods",I13,"")&IF(Declarations!$E$31="goods",J13,"")&IF(Declarations!$E$32="goods",K13,"")&IF(Declarations!$E$33="goods",L13,"")&IF(Declarations!$E$34="goods",M13,"")&IF(Declarations!$E$35="goods",N13,"")&IF(Declarations!$E$36="goods",O13,"")&IF(Declarations!$E$37="goods",P13,"") -> IIO | X13: =IF(Declarations!$E$29="capital",H13,"")&IF(Declarations!$E$30="capital",I13,"")&IF(Declarations!$E$31="capital",J13,"")&IF(Declarations!$E$32="capital",K13,"")&IF(Declarations!$E$33="capital",L13,"")&IF(Declarations!$E$34="capital",M13,"")&IF(Declarations!$E$35="capital",N13,"")&IF(Declarations!$E$36="capital",O13,"")&IF(Declarations!$E$37="capital",P13,"") -> IINN | Y13: =IF(Declarations!$E$29="information",H13,"")&IF(Declarations!$E$30="information",I13,"")&IF(Declarations!$E$31="information",J13,"")&IF(Declarations!$E$32="information",K13,"")&IF(Declarations!$E$33="information",L13,"")&IF(Declarations!$E$34="information",M13,"")&IF(Declarations!$E$35="information",N13,"")&IF(Declarations!$E$36="information",O13,"")&IF(Declarations!$E$37="information",P13,"") -> IN | AA13: Distinct classifications of the information flows | AB13: =SUMPRODUCT(1/COUNTIF(Y6:Y69,Y6:Y69)) -> 8
A14: 8 | B14: =MOD(INT($A14/2^0),2) -> 0 | C14: =MOD(INT($A14/2^1),2) -> 0 | D14: =MOD(INT($A14/2^2),2) -> 0 | E14: =MOD(INT($A14/2^3),2) -> 1 | F14: =MOD(INT($A14/2^4),2) -> 0 | G14: =MOD(INT($A14/2^5),2) -> 0 | H14: =CHOOSE(1+2*INDEX($B14:$G14,H$3)+INDEX($B14:$G14,H$4),"E","N","O","I") -> E | I14: =CHOOSE(1+2*INDEX($B14:$G14,I$3)+INDEX($B14:$G14,I$4),"E","N","O","I") -> E | J14: =CHOOSE(1+2*INDEX($B14:$G14,J$3)+INDEX($B14:$G14,J$4),"E","N","O","I") -> E | K14: =CHOOSE(1+2*INDEX($B14:$G14,K$3)+INDEX($B14:$G14,K$4),"E","N","O","I") -> E | L14: =CHOOSE(1+2*INDEX($B14:$G14,L$3)+INDEX($B14:$G14,L$4),"E","N","O","I") -> N | M14: =CHOOSE(1+2*INDEX($B14:$G14,M$3)+INDEX($B14:$G14,M$4),"E","N","O","I") -> O | N14: =CHOOSE(1+2*INDEX($B14:$G14,N$3)+INDEX($B14:$G14,N$4),"E","N","O","I") -> E | O14: =CHOOSE(1+2*INDEX($B14:$G14,O$3)+INDEX($B14:$G14,O$4),"E","N","O","I") -> E | P14: =CHOOSE(1+2*INDEX($B14:$G14,P$3)+INDEX($B14:$G14,P$4),"E","N","O","I") -> E | Q14: =COUNTIF($H14:$P14,"I") -> 0 | R14: =COUNTIF($H14:$P14,"N") -> 1 | S14: =COUNTIF($H14:$P14,"O") -> 1 | T14: =COUNTIF($H14:$P14,"E") -> 7 | U14: =SUM(Q14:T14) -> 9 | V14: =H14&I14&J14&K14&L14&M14&N14&O14&P14 -> EEEENOEEE | W14: =IF(Declarations!$E$29="goods",H14,"")&IF(Declarations!$E$30="goods",I14,"")&IF(Declarations!$E$31="goods",J14,"")&IF(Declarations!$E$32="goods",K14,"")&IF(Declarations!$E$33="goods",L14,"")&IF(Declarations!$E$34="goods",M14,"")&IF(Declarations!$E$35="goods",N14,"")&IF(Declarations!$E$36="goods",O14,"")&IF(Declarations!$E$37="goods",P14,"") -> EEN | X14: =IF(Declarations!$E$29="capital",H14,"")&IF(Declarations!$E$30="capital",I14,"")&IF(Declarations!$E$31="capital",J14,"")&IF(Declarations!$E$32="capital",K14,"")&IF(Declarations!$E$33="capital",L14,"")&IF(Declarations!$E$34="capital",M14,"")&IF(Declarations!$E$35="capital",N14,"")&IF(Declarations!$E$36="capital",O14,"")&IF(Declarations!$E$37="capital",P14,"") -> EEOE | Y14: =IF(Declarations!$E$29="information",H14,"")&IF(Declarations!$E$30="information",I14,"")&IF(Declarations!$E$31="information",J14,"")&IF(Declarations!$E$32="information",K14,"")&IF(Declarations!$E$33="information",L14,"")&IF(Declarations!$E$34="information",M14,"")&IF(Declarations!$E$35="information",N14,"")&IF(Declarations!$E$36="information",O14,"")&IF(Declarations!$E$37="information",P14,"") -> EE
A15: 9 | B15: =MOD(INT($A15/2^0),2) -> 1 | C15: =MOD(INT($A15/2^1),2) -> 0 | D15: =MOD(INT($A15/2^2),2) -> 0 | E15: =MOD(INT($A15/2^3),2) -> 1 | F15: =MOD(INT($A15/2^4),2) -> 0 | G15: =MOD(INT($A15/2^5),2) -> 0 | H15: =CHOOSE(1+2*INDEX($B15:$G15,H$3)+INDEX($B15:$G15,H$4),"E","N","O","I") -> O | I15: =CHOOSE(1+2*INDEX($B15:$G15,I$3)+INDEX($B15:$G15,I$4),"E","N","O","I") -> N | J15: =CHOOSE(1+2*INDEX($B15:$G15,J$3)+INDEX($B15:$G15,J$4),"E","N","O","I") -> E | K15: =CHOOSE(1+2*INDEX($B15:$G15,K$3)+INDEX($B15:$G15,K$4),"E","N","O","I") -> E | L15: =CHOOSE(1+2*INDEX($B15:$G15,L$3)+INDEX($B15:$G15,L$4),"E","N","O","I") -> N | M15: =CHOOSE(1+2*INDEX($B15:$G15,M$3)+INDEX($B15:$G15,M$4),"E","N","O","I") -> O | N15: =CHOOSE(1+2*INDEX($B15:$G15,N$3)+INDEX($B15:$G15,N$4),"E","N","O","I") -> E | O15: =CHOOSE(1+2*INDEX($B15:$G15,O$3)+INDEX($B15:$G15,O$4),"E","N","O","I") -> E | P15: =CHOOSE(1+2*INDEX($B15:$G15,P$3)+INDEX($B15:$G15,P$4),"E","N","O","I") -> E | Q15: =COUNTIF($H15:$P15,"I") -> 0 | R15: =COUNTIF($H15:$P15,"N") -> 2 | S15: =COUNTIF($H15:$P15,"O") -> 2 | T15: =COUNTIF($H15:$P15,"E") -> 5 | U15: =SUM(Q15:T15) -> 9 | V15: =H15&I15&J15&K15&L15&M15&N15&O15&P15 -> ONEENOEEE | W15: =IF(Declarations!$E$29="goods",H15,"")&IF(Declarations!$E$30="goods",I15,"")&IF(Declarations!$E$31="goods",J15,"")&IF(Declarations!$E$32="goods",K15,"")&IF(Declarations!$E$33="goods",L15,"")&IF(Declarations!$E$34="goods",M15,"")&IF(Declarations!$E$35="goods",N15,"")&IF(Declarations!$E$36="goods",O15,"")&IF(Declarations!$E$37="goods",P15,"") -> OEN | X15: =IF(Declarations!$E$29="capital",H15,"")&IF(Declarations!$E$30="capital",I15,"")&IF(Declarations!$E$31="capital",J15,"")&IF(Declarations!$E$32="capital",K15,"")&IF(Declarations!$E$33="capital",L15,"")&IF(Declarations!$E$34="capital",M15,"")&IF(Declarations!$E$35="capital",N15,"")&IF(Declarations!$E$36="capital",O15,"")&IF(Declarations!$E$37="capital",P15,"") -> NEOE | Y15: =IF(Declarations!$E$29="information",H15,"")&IF(Declarations!$E$30="information",I15,"")&IF(Declarations!$E$31="information",J15,"")&IF(Declarations!$E$32="information",K15,"")&IF(Declarations!$E$33="information",L15,"")&IF(Declarations!$E$34="information",M15,"")&IF(Declarations!$E$35="information",N15,"")&IF(Declarations!$E$36="information",O15,"")&IF(Declarations!$E$37="information",P15,"") -> EE | AA15: Move one entity, starting from boundary A | AB15: Flows relabeled
A16: 10 | B16: =MOD(INT($A16/2^0),2) -> 0 | C16: =MOD(INT($A16/2^1),2) -> 1 | D16: =MOD(INT($A16/2^2),2) -> 0 | E16: =MOD(INT($A16/2^3),2) -> 1 | F16: =MOD(INT($A16/2^4),2) -> 0 | G16: =MOD(INT($A16/2^5),2) -> 0 | H16: =CHOOSE(1+2*INDEX($B16:$G16,H$3)+INDEX($B16:$G16,H$4),"E","N","O","I") -> N | I16: =CHOOSE(1+2*INDEX($B16:$G16,I$3)+INDEX($B16:$G16,I$4),"E","N","O","I") -> O | J16: =CHOOSE(1+2*INDEX($B16:$G16,J$3)+INDEX($B16:$G16,J$4),"E","N","O","I") -> O | K16: =CHOOSE(1+2*INDEX($B16:$G16,K$3)+INDEX($B16:$G16,K$4),"E","N","O","I") -> N | L16: =CHOOSE(1+2*INDEX($B16:$G16,L$3)+INDEX($B16:$G16,L$4),"E","N","O","I") -> N | M16: =CHOOSE(1+2*INDEX($B16:$G16,M$3)+INDEX($B16:$G16,M$4),"E","N","O","I") -> O | N16: =CHOOSE(1+2*INDEX($B16:$G16,N$3)+INDEX($B16:$G16,N$4),"E","N","O","I") -> N | O16: =CHOOSE(1+2*INDEX($B16:$G16,O$3)+INDEX($B16:$G16,O$4),"E","N","O","I") -> N | P16: =CHOOSE(1+2*INDEX($B16:$G16,P$3)+INDEX($B16:$G16,P$4),"E","N","O","I") -> N | Q16: =COUNTIF($H16:$P16,"I") -> 0 | R16: =COUNTIF($H16:$P16,"N") -> 6 | S16: =COUNTIF($H16:$P16,"O") -> 3 | T16: =COUNTIF($H16:$P16,"E") -> 0 | U16: =SUM(Q16:T16) -> 9 | V16: =H16&I16&J16&K16&L16&M16&N16&O16&P16 -> NOONNONNN | W16: =IF(Declarations!$E$29="goods",H16,"")&IF(Declarations!$E$30="goods",I16,"")&IF(Declarations!$E$31="goods",J16,"")&IF(Declarations!$E$32="goods",K16,"")&IF(Declarations!$E$33="goods",L16,"")&IF(Declarations!$E$34="goods",M16,"")&IF(Declarations!$E$35="goods",N16,"")&IF(Declarations!$E$36="goods",O16,"")&IF(Declarations!$E$37="goods",P16,"") -> NON | X16: =IF(Declarations!$E$29="capital",H16,"")&IF(Declarations!$E$30="capital",I16,"")&IF(Declarations!$E$31="capital",J16,"")&IF(Declarations!$E$32="capital",K16,"")&IF(Declarations!$E$33="capital",L16,"")&IF(Declarations!$E$34="capital",M16,"")&IF(Declarations!$E$35="capital",N16,"")&IF(Declarations!$E$36="capital",O16,"")&IF(Declarations!$E$37="capital",P16,"") -> ONON | Y16: =IF(Declarations!$E$29="information",H16,"")&IF(Declarations!$E$30="information",I16,"")&IF(Declarations!$E$31="information",J16,"")&IF(Declarations!$E$32="information",K16,"")&IF(Declarations!$E$33="information",L16,"")&IF(Declarations!$E$34="information",M16,"")&IF(Declarations!$E$35="information",N16,"")&IF(Declarations!$E$36="information",O16,"")&IF(Declarations!$E$37="information",P16,"") -> NN | AA16: Suppliers inside (boundary 3) | AB16: =SUMPRODUCT(--($H$8:$P$8<>H9:P9)) -> 2
A17: 11 | B17: =MOD(INT($A17/2^0),2) -> 1 | C17: =MOD(INT($A17/2^1),2) -> 1 | D17: =MOD(INT($A17/2^2),2) -> 0 | E17: =MOD(INT($A17/2^3),2) -> 1 | F17: =MOD(INT($A17/2^4),2) -> 0 | G17: =MOD(INT($A17/2^5),2) -> 0 | H17: =CHOOSE(1+2*INDEX($B17:$G17,H$3)+INDEX($B17:$G17,H$4),"E","N","O","I") -> I | I17: =CHOOSE(1+2*INDEX($B17:$G17,I$3)+INDEX($B17:$G17,I$4),"E","N","O","I") -> I | J17: =CHOOSE(1+2*INDEX($B17:$G17,J$3)+INDEX($B17:$G17,J$4),"E","N","O","I") -> O | K17: =CHOOSE(1+2*INDEX($B17:$G17,K$3)+INDEX($B17:$G17,K$4),"E","N","O","I") -> N | L17: =CHOOSE(1+2*INDEX($B17:$G17,L$3)+INDEX($B17:$G17,L$4),"E","N","O","I") -> N | M17: =CHOOSE(1+2*INDEX($B17:$G17,M$3)+INDEX($B17:$G17,M$4),"E","N","O","I") -> O | N17: =CHOOSE(1+2*INDEX($B17:$G17,N$3)+INDEX($B17:$G17,N$4),"E","N","O","I") -> N | O17: =CHOOSE(1+2*INDEX($B17:$G17,O$3)+INDEX($B17:$G17,O$4),"E","N","O","I") -> N | P17: =CHOOSE(1+2*INDEX($B17:$G17,P$3)+INDEX($B17:$G17,P$4),"E","N","O","I") -> N | Q17: =COUNTIF($H17:$P17,"I") -> 2 | R17: =COUNTIF($H17:$P17,"N") -> 5 | S17: =COUNTIF($H17:$P17,"O") -> 2 | T17: =COUNTIF($H17:$P17,"E") -> 0 | U17: =SUM(Q17:T17) -> 9 | V17: =H17&I17&J17&K17&L17&M17&N17&O17&P17 -> IIONNONNN | W17: =IF(Declarations!$E$29="goods",H17,"")&IF(Declarations!$E$30="goods",I17,"")&IF(Declarations!$E$31="goods",J17,"")&IF(Declarations!$E$32="goods",K17,"")&IF(Declarations!$E$33="goods",L17,"")&IF(Declarations!$E$34="goods",M17,"")&IF(Declarations!$E$35="goods",N17,"")&IF(Declarations!$E$36="goods",O17,"")&IF(Declarations!$E$37="goods",P17,"") -> ION | X17: =IF(Declarations!$E$29="capital",H17,"")&IF(Declarations!$E$30="capital",I17,"")&IF(Declarations!$E$31="capital",J17,"")&IF(Declarations!$E$32="capital",K17,"")&IF(Declarations!$E$33="capital",L17,"")&IF(Declarations!$E$34="capital",M17,"")&IF(Declarations!$E$35="capital",N17,"")&IF(Declarations!$E$36="capital",O17,"")&IF(Declarations!$E$37="capital",P17,"") -> INON | Y17: =IF(Declarations!$E$29="information",H17,"")&IF(Declarations!$E$30="information",I17,"")&IF(Declarations!$E$31="information",J17,"")&IF(Declarations!$E$32="information",K17,"")&IF(Declarations!$E$33="information",L17,"")&IF(Declarations!$E$34="information",M17,"")&IF(Declarations!$E$35="information",N17,"")&IF(Declarations!$E$36="information",O17,"")&IF(Declarations!$E$37="information",P17,"") -> NN | AA17: Meridian outside (boundary 0) | AB17: =SUMPRODUCT(--($H$8:$P$8<>H6:P6)) -> 7
A18: 12 | B18: =MOD(INT($A18/2^0),2) -> 0 | C18: =MOD(INT($A18/2^1),2) -> 0 | D18: =MOD(INT($A18/2^2),2) -> 1 | E18: =MOD(INT($A18/2^3),2) -> 1 | F18: =MOD(INT($A18/2^4),2) -> 0 | G18: =MOD(INT($A18/2^5),2) -> 0 | H18: =CHOOSE(1+2*INDEX($B18:$G18,H$3)+INDEX($B18:$G18,H$4),"E","N","O","I") -> E | I18: =CHOOSE(1+2*INDEX($B18:$G18,I$3)+INDEX($B18:$G18,I$4),"E","N","O","I") -> E | J18: =CHOOSE(1+2*INDEX($B18:$G18,J$3)+INDEX($B18:$G18,J$4),"E","N","O","I") -> N | K18: =CHOOSE(1+2*INDEX($B18:$G18,K$3)+INDEX($B18:$G18,K$4),"E","N","O","I") -> O | L18: =CHOOSE(1+2*INDEX($B18:$G18,L$3)+INDEX($B18:$G18,L$4),"E","N","O","I") -> I | M18: =CHOOSE(1+2*INDEX($B18:$G18,M$3)+INDEX($B18:$G18,M$4),"E","N","O","I") -> I | N18: =CHOOSE(1+2*INDEX($B18:$G18,N$3)+INDEX($B18:$G18,N$4),"E","N","O","I") -> O | O18: =CHOOSE(1+2*INDEX($B18:$G18,O$3)+INDEX($B18:$G18,O$4),"E","N","O","I") -> E | P18: =CHOOSE(1+2*INDEX($B18:$G18,P$3)+INDEX($B18:$G18,P$4),"E","N","O","I") -> E | Q18: =COUNTIF($H18:$P18,"I") -> 2 | R18: =COUNTIF($H18:$P18,"N") -> 1 | S18: =COUNTIF($H18:$P18,"O") -> 2 | T18: =COUNTIF($H18:$P18,"E") -> 4 | U18: =SUM(Q18:T18) -> 9 | V18: =H18&I18&J18&K18&L18&M18&N18&O18&P18 -> EENOIIOEE | W18: =IF(Declarations!$E$29="goods",H18,"")&IF(Declarations!$E$30="goods",I18,"")&IF(Declarations!$E$31="goods",J18,"")&IF(Declarations!$E$32="goods",K18,"")&IF(Declarations!$E$33="goods",L18,"")&IF(Declarations!$E$34="goods",M18,"")&IF(Declarations!$E$35="goods",N18,"")&IF(Declarations!$E$36="goods",O18,"")&IF(Declarations!$E$37="goods",P18,"") -> ENI | X18: =IF(Declarations!$E$29="capital",H18,"")&IF(Declarations!$E$30="capital",I18,"")&IF(Declarations!$E$31="capital",J18,"")&IF(Declarations!$E$32="capital",K18,"")&IF(Declarations!$E$33="capital",L18,"")&IF(Declarations!$E$34="capital",M18,"")&IF(Declarations!$E$35="capital",N18,"")&IF(Declarations!$E$36="capital",O18,"")&IF(Declarations!$E$37="capital",P18,"") -> EOIE | Y18: =IF(Declarations!$E$29="information",H18,"")&IF(Declarations!$E$30="information",I18,"")&IF(Declarations!$E$31="information",J18,"")&IF(Declarations!$E$32="information",K18,"")&IF(Declarations!$E$33="information",L18,"")&IF(Declarations!$E$34="information",M18,"")&IF(Declarations!$E$35="information",N18,"")&IF(Declarations!$E$36="information",O18,"")&IF(Declarations!$E$37="information",P18,"") -> OE | AA18: Dealer network inside (boundary 6) | AB18: =SUMPRODUCT(--($H$8:$P$8<>H12:P12)) -> 5
A19: 13 | B19: =MOD(INT($A19/2^0),2) -> 1 | C19: =MOD(INT($A19/2^1),2) -> 0 | D19: =MOD(INT($A19/2^2),2) -> 1 | E19: =MOD(INT($A19/2^3),2) -> 1 | F19: =MOD(INT($A19/2^4),2) -> 0 | G19: =MOD(INT($A19/2^5),2) -> 0 | H19: =CHOOSE(1+2*INDEX($B19:$G19,H$3)+INDEX($B19:$G19,H$4),"E","N","O","I") -> O | I19: =CHOOSE(1+2*INDEX($B19:$G19,I$3)+INDEX($B19:$G19,I$4),"E","N","O","I") -> N | J19: =CHOOSE(1+2*INDEX($B19:$G19,J$3)+INDEX($B19:$G19,J$4),"E","N","O","I") -> N | K19: =CHOOSE(1+2*INDEX($B19:$G19,K$3)+INDEX($B19:$G19,K$4),"E","N","O","I") -> O | L19: =CHOOSE(1+2*INDEX($B19:$G19,L$3)+INDEX($B19:$G19,L$4),"E","N","O","I") -> I | M19: =CHOOSE(1+2*INDEX($B19:$G19,M$3)+INDEX($B19:$G19,M$4),"E","N","O","I") -> I | N19: =CHOOSE(1+2*INDEX($B19:$G19,N$3)+INDEX($B19:$G19,N$4),"E","N","O","I") -> O | O19: =CHOOSE(1+2*INDEX($B19:$G19,O$3)+INDEX($B19:$G19,O$4),"E","N","O","I") -> E | P19: =CHOOSE(1+2*INDEX($B19:$G19,P$3)+INDEX($B19:$G19,P$4),"E","N","O","I") -> E | Q19: =COUNTIF($H19:$P19,"I") -> 2 | R19: =COUNTIF($H19:$P19,"N") -> 2 | S19: =COUNTIF($H19:$P19,"O") -> 3 | T19: =COUNTIF($H19:$P19,"E") -> 2 | U19: =SUM(Q19:T19) -> 9 | V19: =H19&I19&J19&K19&L19&M19&N19&O19&P19 -> ONNOIIOEE | W19: =IF(Declarations!$E$29="goods",H19,"")&IF(Declarations!$E$30="goods",I19,"")&IF(Declarations!$E$31="goods",J19,"")&IF(Declarations!$E$32="goods",K19,"")&IF(Declarations!$E$33="goods",L19,"")&IF(Declarations!$E$34="goods",M19,"")&IF(Declarations!$E$35="goods",N19,"")&IF(Declarations!$E$36="goods",O19,"")&IF(Declarations!$E$37="goods",P19,"") -> ONI | X19: =IF(Declarations!$E$29="capital",H19,"")&IF(Declarations!$E$30="capital",I19,"")&IF(Declarations!$E$31="capital",J19,"")&IF(Declarations!$E$32="capital",K19,"")&IF(Declarations!$E$33="capital",L19,"")&IF(Declarations!$E$34="capital",M19,"")&IF(Declarations!$E$35="capital",N19,"")&IF(Declarations!$E$36="capital",O19,"")&IF(Declarations!$E$37="capital",P19,"") -> NOIE | Y19: =IF(Declarations!$E$29="information",H19,"")&IF(Declarations!$E$30="information",I19,"")&IF(Declarations!$E$31="information",J19,"")&IF(Declarations!$E$32="information",K19,"")&IF(Declarations!$E$33="information",L19,"")&IF(Declarations!$E$34="information",M19,"")&IF(Declarations!$E$35="information",N19,"")&IF(Declarations!$E$36="information",O19,"")&IF(Declarations!$E$37="information",P19,"") -> OE | AA19: End customers inside (boundary 10) | AB19: =SUMPRODUCT(--($H$8:$P$8<>H16:P16)) -> 2
A20: 14 | B20: =MOD(INT($A20/2^0),2) -> 0 | C20: =MOD(INT($A20/2^1),2) -> 1 | D20: =MOD(INT($A20/2^2),2) -> 1 | E20: =MOD(INT($A20/2^3),2) -> 1 | F20: =MOD(INT($A20/2^4),2) -> 0 | G20: =MOD(INT($A20/2^5),2) -> 0 | H20: =CHOOSE(1+2*INDEX($B20:$G20,H$3)+INDEX($B20:$G20,H$4),"E","N","O","I") -> N | I20: =CHOOSE(1+2*INDEX($B20:$G20,I$3)+INDEX($B20:$G20,I$4),"E","N","O","I") -> O | J20: =CHOOSE(1+2*INDEX($B20:$G20,J$3)+INDEX($B20:$G20,J$4),"E","N","O","I") -> I | K20: =CHOOSE(1+2*INDEX($B20:$G20,K$3)+INDEX($B20:$G20,K$4),"E","N","O","I") -> I | L20: =CHOOSE(1+2*INDEX($B20:$G20,L$3)+INDEX($B20:$G20,L$4),"E","N","O","I") -> I | M20: =CHOOSE(1+2*INDEX($B20:$G20,M$3)+INDEX($B20:$G20,M$4),"E","N","O","I") -> I | N20: =CHOOSE(1+2*INDEX($B20:$G20,N$3)+INDEX($B20:$G20,N$4),"E","N","O","I") -> I | O20: =CHOOSE(1+2*INDEX($B20:$G20,O$3)+INDEX($B20:$G20,O$4),"E","N","O","I") -> N | P20: =CHOOSE(1+2*INDEX($B20:$G20,P$3)+INDEX($B20:$G20,P$4),"E","N","O","I") -> N | Q20: =COUNTIF($H20:$P20,"I") -> 5 | R20: =COUNTIF($H20:$P20,"N") -> 3 | S20: =COUNTIF($H20:$P20,"O") -> 1 | T20: =COUNTIF($H20:$P20,"E") -> 0 | U20: =SUM(Q20:T20) -> 9 | V20: =H20&I20&J20&K20&L20&M20&N20&O20&P20 -> NOIIIIINN | W20: =IF(Declarations!$E$29="goods",H20,"")&IF(Declarations!$E$30="goods",I20,"")&IF(Declarations!$E$31="goods",J20,"")&IF(Declarations!$E$32="goods",K20,"")&IF(Declarations!$E$33="goods",L20,"")&IF(Declarations!$E$34="goods",M20,"")&IF(Declarations!$E$35="goods",N20,"")&IF(Declarations!$E$36="goods",O20,"")&IF(Declarations!$E$37="goods",P20,"") -> NII | X20: =IF(Declarations!$E$29="capital",H20,"")&IF(Declarations!$E$30="capital",I20,"")&IF(Declarations!$E$31="capital",J20,"")&IF(Declarations!$E$32="capital",K20,"")&IF(Declarations!$E$33="capital",L20,"")&IF(Declarations!$E$34="capital",M20,"")&IF(Declarations!$E$35="capital",N20,"")&IF(Declarations!$E$36="capital",O20,"")&IF(Declarations!$E$37="capital",P20,"") -> OIIN | Y20: =IF(Declarations!$E$29="information",H20,"")&IF(Declarations!$E$30="information",I20,"")&IF(Declarations!$E$31="information",J20,"")&IF(Declarations!$E$32="information",K20,"")&IF(Declarations!$E$33="information",L20,"")&IF(Declarations!$E$34="information",M20,"")&IF(Declarations!$E$35="information",N20,"")&IF(Declarations!$E$36="information",O20,"")&IF(Declarations!$E$37="information",P20,"") -> IN | AA20: Capital markets inside (boundary 18) | AB20: =SUMPRODUCT(--($H$8:$P$8<>H24:P24)) -> 1
A21: 15 | B21: =MOD(INT($A21/2^0),2) -> 1 | C21: =MOD(INT($A21/2^1),2) -> 1 | D21: =MOD(INT($A21/2^2),2) -> 1 | E21: =MOD(INT($A21/2^3),2) -> 1 | F21: =MOD(INT($A21/2^4),2) -> 0 | G21: =MOD(INT($A21/2^5),2) -> 0 | H21: =CHOOSE(1+2*INDEX($B21:$G21,H$3)+INDEX($B21:$G21,H$4),"E","N","O","I") -> I | I21: =CHOOSE(1+2*INDEX($B21:$G21,I$3)+INDEX($B21:$G21,I$4),"E","N","O","I") -> I | J21: =CHOOSE(1+2*INDEX($B21:$G21,J$3)+INDEX($B21:$G21,J$4),"E","N","O","I") -> I | K21: =CHOOSE(1+2*INDEX($B21:$G21,K$3)+INDEX($B21:$G21,K$4),"E","N","O","I") -> I | L21: =CHOOSE(1+2*INDEX($B21:$G21,L$3)+INDEX($B21:$G21,L$4),"E","N","O","I") -> I | M21: =CHOOSE(1+2*INDEX($B21:$G21,M$3)+INDEX($B21:$G21,M$4),"E","N","O","I") -> I | N21: =CHOOSE(1+2*INDEX($B21:$G21,N$3)+INDEX($B21:$G21,N$4),"E","N","O","I") -> I | O21: =CHOOSE(1+2*INDEX($B21:$G21,O$3)+INDEX($B21:$G21,O$4),"E","N","O","I") -> N | P21: =CHOOSE(1+2*INDEX($B21:$G21,P$3)+INDEX($B21:$G21,P$4),"E","N","O","I") -> N | Q21: =COUNTIF($H21:$P21,"I") -> 7 | R21: =COUNTIF($H21:$P21,"N") -> 2 | S21: =COUNTIF($H21:$P21,"O") -> 0 | T21: =COUNTIF($H21:$P21,"E") -> 0 | U21: =SUM(Q21:T21) -> 9 | V21: =H21&I21&J21&K21&L21&M21&N21&O21&P21 -> IIIIIIINN | W21: =IF(Declarations!$E$29="goods",H21,"")&IF(Declarations!$E$30="goods",I21,"")&IF(Declarations!$E$31="goods",J21,"")&IF(Declarations!$E$32="goods",K21,"")&IF(Declarations!$E$33="goods",L21,"")&IF(Declarations!$E$34="goods",M21,"")&IF(Declarations!$E$35="goods",N21,"")&IF(Declarations!$E$36="goods",O21,"")&IF(Declarations!$E$37="goods",P21,"") -> III | X21: =IF(Declarations!$E$29="capital",H21,"")&IF(Declarations!$E$30="capital",I21,"")&IF(Declarations!$E$31="capital",J21,"")&IF(Declarations!$E$32="capital",K21,"")&IF(Declarations!$E$33="capital",L21,"")&IF(Declarations!$E$34="capital",M21,"")&IF(Declarations!$E$35="capital",N21,"")&IF(Declarations!$E$36="capital",O21,"")&IF(Declarations!$E$37="capital",P21,"") -> IIIN | Y21: =IF(Declarations!$E$29="information",H21,"")&IF(Declarations!$E$30="information",I21,"")&IF(Declarations!$E$31="information",J21,"")&IF(Declarations!$E$32="information",K21,"")&IF(Declarations!$E$33="information",L21,"")&IF(Declarations!$E$34="information",M21,"")&IF(Declarations!$E$35="information",N21,"")&IF(Declarations!$E$36="information",O21,"")&IF(Declarations!$E$37="information",P21,"") -> IN | AA21: Regulator inside (boundary 34) | AB21: =SUMPRODUCT(--($H$8:$P$8<>H40:P40)) -> 1
A22: 16 | B22: =MOD(INT($A22/2^0),2) -> 0 | C22: =MOD(INT($A22/2^1),2) -> 0 | D22: =MOD(INT($A22/2^2),2) -> 0 | E22: =MOD(INT($A22/2^3),2) -> 0 | F22: =MOD(INT($A22/2^4),2) -> 1 | G22: =MOD(INT($A22/2^5),2) -> 0 | H22: =CHOOSE(1+2*INDEX($B22:$G22,H$3)+INDEX($B22:$G22,H$4),"E","N","O","I") -> E | I22: =CHOOSE(1+2*INDEX($B22:$G22,I$3)+INDEX($B22:$G22,I$4),"E","N","O","I") -> E | J22: =CHOOSE(1+2*INDEX($B22:$G22,J$3)+INDEX($B22:$G22,J$4),"E","N","O","I") -> E | K22: =CHOOSE(1+2*INDEX($B22:$G22,K$3)+INDEX($B22:$G22,K$4),"E","N","O","I") -> E | L22: =CHOOSE(1+2*INDEX($B22:$G22,L$3)+INDEX($B22:$G22,L$4),"E","N","O","I") -> E | M22: =CHOOSE(1+2*INDEX($B22:$G22,M$3)+INDEX($B22:$G22,M$4),"E","N","O","I") -> E | N22: =CHOOSE(1+2*INDEX($B22:$G22,N$3)+INDEX($B22:$G22,N$4),"E","N","O","I") -> E | O22: =CHOOSE(1+2*INDEX($B22:$G22,O$3)+INDEX($B22:$G22,O$4),"E","N","O","I") -> O | P22: =CHOOSE(1+2*INDEX($B22:$G22,P$3)+INDEX($B22:$G22,P$4),"E","N","O","I") -> E | Q22: =COUNTIF($H22:$P22,"I") -> 0 | R22: =COUNTIF($H22:$P22,"N") -> 0 | S22: =COUNTIF($H22:$P22,"O") -> 1 | T22: =COUNTIF($H22:$P22,"E") -> 8 | U22: =SUM(Q22:T22) -> 9 | V22: =H22&I22&J22&K22&L22&M22&N22&O22&P22 -> EEEEEEEOE | W22: =IF(Declarations!$E$29="goods",H22,"")&IF(Declarations!$E$30="goods",I22,"")&IF(Declarations!$E$31="goods",J22,"")&IF(Declarations!$E$32="goods",K22,"")&IF(Declarations!$E$33="goods",L22,"")&IF(Declarations!$E$34="goods",M22,"")&IF(Declarations!$E$35="goods",N22,"")&IF(Declarations!$E$36="goods",O22,"")&IF(Declarations!$E$37="goods",P22,"") -> EEE | X22: =IF(Declarations!$E$29="capital",H22,"")&IF(Declarations!$E$30="capital",I22,"")&IF(Declarations!$E$31="capital",J22,"")&IF(Declarations!$E$32="capital",K22,"")&IF(Declarations!$E$33="capital",L22,"")&IF(Declarations!$E$34="capital",M22,"")&IF(Declarations!$E$35="capital",N22,"")&IF(Declarations!$E$36="capital",O22,"")&IF(Declarations!$E$37="capital",P22,"") -> EEEO | Y22: =IF(Declarations!$E$29="information",H22,"")&IF(Declarations!$E$30="information",I22,"")&IF(Declarations!$E$31="information",J22,"")&IF(Declarations!$E$32="information",K22,"")&IF(Declarations!$E$33="information",L22,"")&IF(Declarations!$E$34="information",M22,"")&IF(Declarations!$E$35="information",N22,"")&IF(Declarations!$E$36="information",O22,"")&IF(Declarations!$E$37="information",P22,"") -> EE
