Workbook

Sheet README
B1: DCT Laboratory — Vol I, Ch 15: Mathematical Formulation of Enterprise Optimization
B2: Seed 26115 · Companion to DCT_V1_Ch15_Lab.ipynb and AXIOM Lab 1.15 (module AXIOM-15). Money in $ million.
B4: Worked Example 15.1, What Does the Board's Appetite Cost?, with the book's declarations, and the five steps of AXIOM Lab 1.15, Pricing Meridian's Commitments.
B5: Declarations: the GEOP's elements, the lever prices, the commitments and Chapter 8's uncertainty.
B6: Plan: the plan quarter by quarter, the deepest draws, the certainty-equivalent mean path and Chapter 13's joint check as the robust formulation (Step 2).
B7: Quantiles: the one simulation output, from the book's 100,000 paths (seed 8): each line's critical depth at each appetite. Delay and Cost turn it into the least delay and the cost of every package.
B8: Solve: the cheapest package at 5 percent, its binding set, the equal margins and the price of the appetite (Steps 3-4). Sensitivity: the price at other values of delay.
B9: Frontier: the least cost of every appetite (floors), the offices alone, Chapter 8's package, the bank's cap, and Table 15.5 (Step 5). WeightSweep: the same frontier by weights (lab step 4).
B10: Audit: consistency, viability, the capped levers' minimal infeasible set and emptying date (lab step 2).
B11: Allocation: the lab's small allocation (its data are this workbook's declaration), its corner and multipliers (lab step 3).
B12: RollingPlans: Figure 15.1. Architecture: the price of the stability budget and a twitchy optimum.
B13: Reference_Values and Checks: the notebook engine's numbers and a PASS/FAIL comparison with this workbook's formulas.
... B19: Cross-sheet link: green.

Sheet Declarations
A1: Declarations (Worked Example 15.1, Step 1; the plan and its uncertainty are Worked Example 8.1's). Money in $ million.
A3: Quantity | B3: Value | C3: Source | D3: Name
A4: Liquidity today | B4: 620 | C4: Table 5.4; Worked Example 8.1 | D4: Liq0
A5: The board's liquidity floor | B5: 350 | C5: Table 5.4 | D5: Floor_m
A6: Cash above the floor | B6: =B4-B5 -> 270 | C6: Chapter 13's joint check: 270 | D6: Pool
A7: Liquidity per index point | B7: 6.2 | C7: Chapter 1: index 100 = $620 million | D7: Usd_pt
A8: Chapter 1's liquidity target (index) | B8: 112 | C8: Online Appendix 1.B.4 | D8: Liq_target
A9: Relaxation toward the target, a year | B9: 0.35 | C9: Online Appendix 1.B.4 | D9: Relax
A10: Depth of the program's draw, as planned (index points) | B10: 28 | C10: Chapter 1's digital program | D10: Depth0
A11: Years to the deepest draw | B11: 2 | C11: Chapter 1's digital program | D11: Tau
A12: Depth cut by a quarter of delay (index points) | B12: 4 | C12: Chapter 8's phased build: depth 20 for two quarters of delay | D12: Depth_per_q
A13: Standby-line fees a year (share of the line) | B13: 0.01 | C13: Worked Example 15.1: about 1 percent | D13: Fee_year
A14: Program length (years) | B14: 3 | C14: Twelve quarters | D14: Years
A15: Fees over the program (share of the line) | B15: =B13*B14 -> 0.03 | C15: $3 million per $100 million | D15: Fee
A16: Value of a quarter of delay | B16: 8 | C16: The transformation office: Digital Solutions' contribution | D16: Vq
A17: The board's appetite: chance of a breach in some quarter | B17: 0.05 | C17: Chapter 8; a chance constraint | D17: Appetite
A18: Revenue | B18: 4200 | C18: Chapter 1 | D18: Revenue
A19: EBITDA margin | B19: 0.118 | C19: Chapter 1 | D19: Margin
A20: EBITDA | B20: =B18*B19 -> 495.6 | C20: $495.6 million | D20: Ebitda
A21: Net leverage today (net debt / EBITDA) | B21: 3.4 | C21: Table 5.4 | D21: Lev0
A22: Net debt | B22: =B21*B20 -> 1685.04 | C22: $1,685 million | D22: Net_debt
A23: Covenant: net leverage at most | B23: 4.5 | C23: Table 5.4; the CFO | D23: Covenant
A24: Workforce capability today | B24: 58 | C24: Table 5.2 | D24: Capability
A25: Capability floor for the digital build | B25: 55 | C25: Worked Example 3.1; HR and the CTO | D25: Cap_floor
A26: Persistence of the execution and market deviation | B26: 0.6 | C26: Worked Example 8.1 | D26: A_e
A27: Surprise a quarter: standard deviation | B27: 50 | C27: Worked Example 8.1 | D27: Sd_w
A28: Funding-window closures a year | B28: 0.1 | C28: Worked Example 8.1 | D28: Lam
A29: Closure size: mean | B29: 120 | C29: Worked Example 8.1 | D29: J_mean
A30: Closure size: standard deviation | B30: 50 | C30: Worked Example 8.1 | D30: J_sd
A31: Gamma shape of a closure | B31: =(B29/B30)^2 -> 5.76 | C31: 5.76 | D31: G_shape
A32: Gamma scale of a closure | B32: =B30^2/B29 -> 20.833333 | C32: 20.83 | D32: G_scale
A33: Paths | B33: 100000 | C33: Worked Example 8.1 | D33: N_paths
A34: Random seed of the book's paths | B34: 8 | C34: Volume II, Online Appendix 1.B.4 | D34: Book_seed
A36: Decisions: the standby line l (owned by the CFO) replaces up to l of any closure; the delay phi of the platform (owned by the transformation office) sets the draw's depth at 28 - 4 phi. Objective: minimize Fee x l + Vq x phi. Commitments: the appetite (board), the covenant (CFO), the capability floor (HR, CTO).

Sheet Plan
A1: The plan, the deepest draws and the three formulations (Worked Example 15.1, Step 2; Proposition 15.7)
A2: Liquidity = $6.2 million x (Chapter 1's index less the draw D x s(t)), s(t) = (t/2) e^(1 - t/2). The mean path is the plan less the closures' expected drain (no line): the certainty equivalent.
A5: Quarter | B5: Years t | C5: Index without the draw | D5: Draw shape s(t) | E5: Plan as drawn (D = 28) | F5: Phased build (D = 20) | G5: At the cheapest package's depth | H5: Expected closures so far | I5: Mean path (plan less the drain)
A6: 0 | B6: =A6/4 -> 0 | C6: =Liq_target+(100-Liq_target)*EXP(-Relax*B6) -> 100 | D6: =(B6/Tau)*EXP(1-B6/Tau) -> 0 | E6: =Usd_pt*(C6-Depth0*D6) -> 620 | F6: =Usd_pt*(C6-(Depth0-2*Depth_per_q)*D6) -> 620 | G6: =Usd_pt*(C6-Solve!$B$8*D6) -> 620 | H6: =Lam/4*A6*J_mean -> 0 | I6: =E6-H6 -> 620
A7: 1 | B7: =A7/4 -> 0.25 | C7: =Liq_target+(100-Liq_target)*EXP(-Relax*B7) -> 101.00537 | D7: =(B7/Tau)*EXP(1-B7/Tau) -> 0.29985941 | E7: =Usd_pt*(C7-Depth0*D7) -> 574.17772 | F7: =Usd_pt*(C7-(Depth0-2*Depth_per_q)*D7) -> 589.05075 | G7: =Usd_pt*(C7-Solve!$B$8*D7) -> 579.14216 | H7: =Lam/4*A7*J_mean -> 3 | I7: =E7-H7 -> 571.17772
A8: 2 | B8: =A8/4 -> 0.5 | C8: =Liq_target+(100-Liq_target)*EXP(-Relax*B8) -> 101.92652 | D8: =(B8/Tau)*EXP(1-B8/Tau) -> 0.52925 | E8: =Usd_pt*(C8-Depth0*D8) -> 540.0666 | F8: =Usd_pt*(C8-(Depth0-2*Depth_per_q)*D8) -> 566.3174 | G8: =Usd_pt*(C8-Solve!$B$8*D8) -> 548.8288 | H8: =Lam/4*A8*J_mean -> 6 | I8: =E8-H8 -> 534.0666
A9: 3 | B9: =A9/4 -> 0.75 | C9: =Liq_target+(100-Liq_target)*EXP(-Relax*B9) -> 102.77048 | D9: =(B9/Tau)*EXP(1-B9/Tau) -> 0.70059223 | E9: =Usd_pt*(C9-Depth0*D9) -> 515.55419 | F9: =Usd_pt*(C9-(Depth0-2*Depth_per_q)*D9) -> 550.30356 | G9: =Usd_pt*(C9-Solve!$B$8*D9) -> 527.15312 | H9: =Lam/4*A9*J_mean -> 9 | I9: =E9-H9 -> 506.55419
A10: 4 | B10: =A10/4 -> 1 | C10: =Liq_target+(100-Liq_target)*EXP(-Relax*B10) -> 103.54374 | D10: =(B10/Tau)*EXP(1-B10/Tau) -> 0.82436064 | E10: =Usd_pt*(C10-Depth0*D10) -> 498.8622 | F10: =Usd_pt*(C10-(Depth0-2*Depth_per_q)*D10) -> 539.75049 | G10: =Usd_pt*(C10-Solve!$B$8*D10) -> 512.51023 | H10: =Lam/4*A10*J_mean -> 12 | I10: =E10-H10 -> 486.8622
A11: 5 | B11: =A11/4 -> 1.25 | C11: =Liq_target+(100-Liq_target)*EXP(-Relax*B11) -> 104.25222 | D11: =(B11/Tau)*EXP(1-B11/Tau) -> 0.90936963 | E11: =Usd_pt*(C11-Depth0*D11) -> 488.49718 | F11: =Usd_pt*(C11-(Depth0-2*Depth_per_q)*D11) -> 533.60192 | G11: =Usd_pt*(C11-Solve!$B$8*D11) -> 503.55261 | H11: =Lam/4*A11*J_mean -> 15 | I11: =E11-H11 -> 473.49718
A12: 6 | B12: =A12/4 -> 1.5 | C12: =Liq_target+(100-Liq_target)*EXP(-Relax*B12) -> 104.90134 | D12: =(B12/Tau)*EXP(1-B12/Tau) -> 0.96301906 | E12: =Usd_pt*(C12-Depth0*D12) -> 483.20817 | F12: =Usd_pt*(C12-(Depth0-2*Depth_per_q)*D12) -> 530.97392 | G12: =Usd_pt*(C12-Solve!$B$8*D12) -> 499.15181 | H12: =Lam/4*A12*J_mean -> 18 | I12: =E12-H12 -> 465.20817
A13: 7 | B13: =A13/4 -> 1.75 | C13: =Liq_target+(100-Liq_target)*EXP(-Relax*B13) -> 105.49607 | D13: =(B13/Tau)*EXP(1-B13/Tau) -> 0.9915049 | E13: =Usd_pt*(C13-Depth0*D13) -> 481.95038 | F13: =Usd_pt*(C13-(Depth0-2*Depth_per_q)*D13) -> 531.12903 | G13: =Usd_pt*(C13-Solve!$B$8*D13) -> 498.36563 | H13: =Lam/4*A13*J_mean -> 21 | I13: =E13-H13 -> 460.95038
A14: 8 | B14: =A14/4 -> 2 | C14: =Liq_target+(100-Liq_target)*EXP(-Relax*B14) -> 106.04098 | D14: =(B14/Tau)*EXP(1-B14/Tau) -> 1 | E14: =Usd_pt*(C14-Depth0*D14) -> 483.85405 | F14: =Usd_pt*(C14-(Depth0-2*Depth_per_q)*D14) -> 533.45405 | G14: =Usd_pt*(C14-Solve!$B$8*D14) -> 500.40995 | H14: =Lam/4*A14*J_mean -> 24 | I14: =E14-H14 -> 459.85405
A15: 9 | B15: =A15/4 -> 2.25 | C15: =Liq_target+(100-Liq_target)*EXP(-Relax*B15) -> 106.54023 | D15: =(B15/Tau)*EXP(1-B15/Tau) -> 0.99280902 | E15: =Usd_pt*(C15-Depth0*D15) -> 488.19778 | F15: =Usd_pt*(C15-(Depth0-2*Depth_per_q)*D15) -> 537.44111 | G15: =Usd_pt*(C15-Solve!$B$8*D15) -> 504.63462 | H15: =Lam/4*A15*J_mean -> 27 | I15: =E15-H15 -> 461.19778
A16: 10 | B16: =A16/4 -> 2.5 | C16: =Liq_target+(100-Liq_target)*EXP(-Relax*B16) -> 106.99766 | D16: =(B16/Tau)*EXP(1-B16/Tau) -> 0.97350098 | E16: =Usd_pt*(C16-Depth0*D16) -> 494.3857 | F16: =Usd_pt*(C16-(Depth0-2*Depth_per_q)*D16) -> 542.67134 | G16: =Usd_pt*(C16-Solve!$B$8*D16) -> 510.50287 | H16: =Lam/4*A16*J_mean -> 30 | I16: =E16-H16 -> 464.3857
A17: 11 | B17: =A17/4 -> 2.75 | C17: =Liq_target+(100-Liq_target)*EXP(-Relax*B17) -> 107.41676 | D17: =(B17/Tau)*EXP(1-B17/Tau) -> 0.94502276 | E17: =Usd_pt*(C17-Depth0*D17) -> 501.92795 | F17: =Usd_pt*(C17-(Depth0-2*Depth_per_q)*D17) -> 548.80108 | G17: =Usd_pt*(C17-Solve!$B$8*D17) -> 517.57364 | H17: =Lam/4*A17*J_mean -> 33 | I17: =E17-H17 -> 468.92795
A18: 12 | B18: =A18/4 -> 3 | C18: =Liq_target+(100-Liq_target)*EXP(-Relax*B18) -> 107.80075 | D18: =(B18/Tau)*EXP(1-B18/Tau) -> 0.90979599 | E18: =Usd_pt*(C18-Depth0*D18) -> 510.42405 | F18: =Usd_pt*(C18-(Depth0-2*Depth_per_q)*D18) -> 555.54993 | G18: =Usd_pt*(C18-Solve!$B$8*D18) -> 525.48653 | H18: =Lam/4*A18*J_mean -> 36 | I18: =E18-H18 -> 474.42405
A21: Deepest draw, plan as drawn | B21: =Liq0-MIN(E6:E18) -> 138.04962 | C21: Worked Example 8.1: 620 - 482 = 138
A22: Deepest draw, Chapter 8's phased build | B22: =Liq0-MIN(F6:F18) -> 89.026083 | C22: 89
A23: The phased build's draw is smaller by | B23: =B21-B22 -> 49.023535 | C23: $49 million
A24: Deepest draw at the cheapest package | B24: =Liq0-MIN(G6:G18) -> 121.63437 | C24: Online Appendix 15.B.4: 121.6
A25: Smaller than the plan's by | B25: =B21-B24 -> 16.41525 | C25: Step 3: $16 million
A27: Certainty equivalent: the mean path's trough | B27: =MIN(I6:I18) -> 459.85405 | C27: Step 2: $460 million, above the floor: no levers
A28: Is the mean path above the floor? | B28: =IF(B27>=Floor_m,"yes: buys nothing","no") -> yes: buys nothing
A30: 90th-percentile closure (gamma) | B30: =GAMMAINV(0.9,G_shape,G_scale) -> 186.86698 | C30: Chapter 12: 187
A31: Robust: the joint check's least line, draw + (P90 - line) <= 270 | B31: =MAX(B30-(Pool-B21),0) -> 54.916594 | C31: Step 2: a $55 million line
A32: Robust: its cost | B32: =Fee*B31 -> 1.6474978 | C32: Step 2: $1.6 million (Online Appendix 15.B.4: 1.65)
A34: Joint check at the cheapest package: draw + buffer | B34: =B24+MAX(B30-Solve!$B$5,0) -> 138.50134 | C34: Fits in the 270 above the floor
A35: Joint check, no levers: draw + buffer | B35: =B21+B30 -> 324.91659 | C35: Chapter 13: 325, the same cash promised twice

Sheet Quantiles
A1: The decision table from the book's 100,000 paths (seed 8): each line's critical depth at each appetite
A2: Engine values. For a line l, a path stays above the floor exactly when the draw's depth D is at most its critical depth. Sorted over the paths, the value at the appetite's quantile is the deepest draw that meets it (Online Appendix 15.B.4). Negative: no delay can meet the appetite with that line.
A3: Quantile index (paths allowed to breach) | B3: 1000 | C3: 1250 | D3: 1500 | E3: 1750 | F3: 2000 | G3: 2250 | H3: 2500 | I3: 2750 | J3: 3000 | K3: 3250 | L3: 3500 | M3: 3750 | N3: 4000 | O3: 4250 | P3: 4500 | Q3: 4750 | R3: 5000 | S3: 5250 | T3: 5500 | U3: 5750 | V3: 6000 | W3: 6250 | X3: 6500 | Y3: 6750 | Z3: 7000 | AA3: 7250 | AB3: 7500 | AC3: 7750 | AD3: 8000 | AE3: 8250 | AF3: 8500 | AG3: 8750 | AH3: 9000 | AI3: 9250 | AJ3: 9500 | AK3: 9750 | AL3: 10000 | AM3: 10250 | AN3: 10500 | AO3: 10750 | AP3: 11000 | AQ3: 11250 | AR3: 11500 | AS3: 11750 | AT3: 12000 | AU3: 12250 | AV3: 12500 | AW3: 12750 | AX3: 13000 | AY3: 13250 | AZ3: 13500 | BA3: 13750 | BB3: 14000 | BC3: 14250 | BD3: 14500 | BE3: 14750 | BF3: 15000 | BG3: 15250 | BH3: 15500 | BI3: 15750 | BJ3: 16000 | BK3: 16250 | BL3: 16500 | BM3: 16750 | BN3: 17000 | BO3: 17250 | BP3: 17500 | BQ3: 17750 | BR3: 18000 | BS3: 18250 | BT3: 18500 | BU3: 18750 | BV3: 19000 | BW3: 19250 | BX3: 19500 | BY3: 19750 | BZ3: 20000 | CA3: 20250 | CB3: 20500 | CC3: 20750 | CD3: 21000 | CE3: 21250 | CF3: 21500 | CG3: 21750 | CH3: 22000 | CI3: 22250 | CJ3: 22500 | CK3: 22750 | CL3: 23000 | CM3: 23250 | CN3: 23500 | CO3: 23750 | CP3: 24000 | CQ3: 24250 | CR3: 24500 | CS3: 24600 | CT3: 3003
A4: Line ($ million) | B4: 0.01 | C4: 0.0125 | D4: 0.015 | E4: 0.0175 | F4: 0.02 | G4: 0.0225 | H4: 0.025 | I4: 0.0275 | J4: 0.03 | K4: 0.0325 | L4: 0.035 | M4: 0.0375 | N4: 0.04 | O4: 0.0425 | P4: 0.045 | Q4: 0.0475 | R4: 0.05 | S4: 0.0525 | T4: 0.055 | U4: 0.0575 | V4: 0.06 | W4: 0.0625 | X4: 0.065 | Y4: 0.0675 | Z4: 0.07 | AA4: 0.0725 | AB4: 0.075 | AC4: 0.0775 | AD4: 0.08 | AE4: 0.0825 | AF4: 0.085 | AG4: 0.0875 | AH4: 0.09 | AI4: 0.0925 | AJ4: 0.095 | AK4: 0.0975 | AL4: 0.1 | AM4: 0.1025 | AN4: 0.105 | AO4: 0.1075 | AP4: 0.11 | AQ4: 0.1125 | AR4: 0.115 | AS4: 0.1175 | AT4: 0.12 | AU4: 0.1225 | AV4: 0.125 | AW4: 0.1275 | AX4: 0.13 | AY4: 0.1325 | AZ4: 0.135 | BA4: 0.1375 | BB4: 0.14 | BC4: 0.1425 | BD4: 0.145 | BE4: 0.1475 | BF4: 0.15 | BG4: 0.1525 | BH4: 0.155 | BI4: 0.1575 | BJ4: 0.16 | BK4: 0.1625 | BL4: 0.165 | BM4: 0.1675 | BN4: 0.17 | BO4: 0.1725 | BP4: 0.175 | BQ4: 0.1775 | BR4: 0.18 | BS4: 0.1825 | BT4: 0.185 | BU4: 0.1875 | BV4: 0.19 | BW4: 0.1925 | BX4: 0.195 | BY4: 0.1975 | BZ4: 0.2 | CA4: 0.2025 | CB4: 0.205 | CC4: 0.2075 | CD4: 0.21 | CE4: 0.2125 | CF4: 0.215 | CG4: 0.2175 | CH4: 0.22 | CI4: 0.2225 | CJ4: 0.225 | CK4: 0.2275 | CL4: 0.23 | CM4: 0.2325 | CN4: 0.235 | CO4: 0.2375 | CP4: 0.24 | CQ4: 0.2425 | CR4: 0.245 | CS4: 0.246 | CT4: 0.03003
A5: 0 | B5: -10.428898 | C5: -8.1975309 | D5: -6.1467259 | E5: -4.5596059 | F5: -2.9213446 | G5: -1.6168311 | H5: -0.56064135 | I5: 0.40980974 | J5: 1.5251766 | K5: 2.4512433 | L5: 3.4138825 | M5: 4.2881335 | N5: 4.9924129 | O5: 5.7406531 | P5: 6.3852114 | Q5: 6.9729905 | R5: 7.6213073 | S5: 8.2326001 | T5: 8.8090794 | U5: 9.3430054 | V5: 9.9140304 | W5: 10.389977 | X5: 10.854323 | Y5: 11.312355 | Z5: 11.787398 | AA5: 12.224687 | AB5: 12.602123 | AC5: 13.031977 | AD5: 13.458882 | AE5: 13.878716 | AF5: 14.253942 | AG5: 14.630825 | AH5: 15.043588 | AI5: 15.346347 | AJ5: 15.737983 | AK5: 16.081349 | AL5: 16.396308 | AM5: 16.700888 | AN5: 17.042457 | AO5: 17.365168 | AP5: 17.654636 | AQ5: 17.960489 | AR5: 18.265361 | AS5: 18.55838 | AT5: 18.855917 | AU5: 19.16187 | AV5: 19.432254 | AW5: 19.679805 | AX5: 19.932454 | AY5: 20.209724 | AZ5: 20.443721 | BA5: 20.660888 | BB5: 20.898265 | BC5: 21.135645 | BD5: 21.394029 | BE5: 21.619886 | BF5: 21.842499 | BG5: 22.050541 | BH5: 22.259603 | BI5: 22.467612 | BJ5: 22.660701 | BK5: 22.860596 | BL5: 23.043192 | BM5: 23.248413 | BN5: 23.459355 | BO5: 23.642021 | BP5: 23.817029 | BQ5: 24.01739 | BR5: 24.19322 | BS5: 24.370725 | BT5: 24.527411 | BU5: 24.697869 | BV5: 24.873384 | BW5: 25.048633 | BX5: 25.206091 | BY5: 25.357191 | BZ5: 25.514969 | CA5: 25.671086 | CB5: 25.81834 | CC5: 25.961262 | CD5: 26.112259 | CE5: 26.25641 | CF5: 26.39051 | CG5: 26.529321 | CH5: 26.662415 | CI5: 26.803343 | CJ5: 26.936134 | CK5: 27.064292 | CL5: 27.197502 | CM5: 27.325626 | CN5: 27.457815 | CO5: 27.578564 | CP5: 27.706134 | CQ5: 27.832592 | CR5: 27.942179 | CS5: 27.990059 | CT5: 1.5474426
A6: 5 | B6: -8.8589893 | C6: -6.7127668 | D6: -4.8394197 | E6: -3.2184509 | F6: -1.5805759 | G6: -0.37568334 | H6: 0.63248342 | I6: 1.671603 | J6: 2.6816093 | K6: 3.6294245 | L6: 4.5435081 | M6: 5.3957061 | N6: 6.08762 | O6: 6.7760686 | P6: 7.426928 | Q6: 8.0251189 | R6: 8.677322 | S6: 9.2867331 | T6: 9.8233242 | U6: 10.314963 | V6: 10.858411 | W6: 11.350467 | X6: 11.820537 | Y6: 12.290065 | Z6: 12.734725 | AA6: 13.159817 | AB6: 13.534312 | AC6: 13.938507 | AD6: 14.356096 | AE6: 14.773424 | AF6: 15.150062 | AG6: 15.505793 | AH6: 15.877098 | AI6: 16.185939 | AJ6: 16.535858 | AK6: 16.885318 | AL6: 17.198121 | AM6: 17.504279 | AN6: 17.815821 | AO6: 18.113715 | AP6: 18.398593 | AQ6: 18.690858 | AR6: 19.010513 | AS6: 19.30005 | AT6: 19.565729 | AU6: 19.852081 | AV6: 20.140192 | AW6: 20.361038 | AX6: 20.583501 | AY6: 20.831153 | AZ6: 21.087774 | BA6: 21.321789 | BB6: 21.532552 | BC6: 21.746005 | BD6: 21.957316 | BE6: 22.213204 | BF6: 22.419242 | BG6: 22.627432 | BH6: 22.823388 | BI6: 23.004762 | BJ6: 23.183709 | BK6: 23.37418 | BL6: 23.556133 | BM6: 23.739182 | BN6: 23.923849 | BO6: 24.117406 | BP6: 24.3007 | BQ6: 24.467581 | BR6: 24.639391 | BS6: 24.788162 | BT6: 24.974104 | BU6: 25.148021 | BV6: 25.304317 | BW6: 25.463435 | BX6: 25.613946 | BY6: 25.77317 | BZ6: 25.914495 | CA6: 26.051372 | CB6: 26.187214 | CC6: 26.32391 | CD6: 26.465659 | CE6: 26.604005 | CF6: 26.737255 | CG6: 26.878023 | CH6: 27.006571 | CI6: 27.131655 | CJ6: 27.248296 | CK6: 27.374733 | CL6: 27.494456 | CM6: 27.618821 | CN6: 27.74916 | CO6: 27.868557 | CP6: 27.989154 | CQ6: 28.113402 | CR6: 28.250777 | CS6: 28.299357 | CT6: 2.6936105
A7: 10 | B7: -7.4620926 | C7: -5.2164457 | D7: -3.4188031 | E7: -1.9571485 | F7: -0.45142712 | G7: 0.80801708 | H7: 1.8629889 | I7: 2.8533561 | J7: 3.8178989 | K7: 4.7793862 | L7: 5.688022 | M7: 6.4590172 | N7: 7.1975049 | O7: 7.8408326 | P7: 8.4910737 | Q7: 9.0728566 | R7: 9.6807638 | S7: 10.284728 | T7: 10.813042 | U7: 11.329219 | V7: 11.811212 | W7: 12.312591 | X7: 12.765264 | Y7: 13.246717 | Z7: 13.691167 | AA7: 14.074964 | AB7: 14.464566 | AC7: 14.839787 | AD7: 15.248533 | AE7: 15.622843 | AF7: 15.982573 | AG7: 16.331114 | AH7: 16.699261 | AI7: 17.003099 | AJ7: 17.354557 | AK7: 17.684437 | AL7: 17.971624 | AM7: 18.242656 | AN7: 18.579102 | AO7: 18.868222 | AP7: 19.147811 | AQ7: 19.433507 | AR7: 19.724056 | AS7: 19.992695 | AT7: 20.2688 | AU7: 20.5137 | AV7: 20.76829 | AW7: 21.021382 | AX7: 21.250732 | AY7: 21.466301 | AZ7: 21.703119 | BA7: 21.921302 | BB7: 22.147822 | BC7: 22.339004 | BD7: 22.540741 | BE7: 22.71921 | BF7: 22.93901 | BG7: 23.132032 | BH7: 23.326027 | BI7: 23.523627 | BJ7: 23.70278 | BK7: 23.882959 | BL7: 24.056508 | BM7: 24.237275 | BN7: 24.398646 | BO7: 24.559909 | BP7: 24.728131 | BQ7: 24.901538 | BR7: 25.081741 | BS7: 25.235136 | BT7: 25.396136 | BU7: 25.558968 | BV7: 25.694363 | BW7: 25.850091 | BX7: 26.000591 | BY7: 26.140493 | BZ7: 26.278317 | CA7: 26.40907 | CB7: 26.553572 | CC7: 26.688145 | CD7: 26.821442 | CE7: 26.949379 | CF7: 27.068952 | CG7: 27.197725 | CH7: 27.312085 | CI7: 27.444979 | CJ7: 27.567951 | CK7: 27.681298 | CL7: 27.818627 | CM7: 27.936243 | CN7: 28.043369 | CO7: 28.162256 | CP7: 28.293335 | CQ7: 28.400146 | CR7: 28.514218 | CS7: 28.557349 | CT7: 3.8281618
A8: 15 | B8: -5.9977035 | C8: -3.7998011 | D8: -2.0946811 | E8: -0.57975678 | F8: 0.79780446 | G8: 2.030654 | H8: 3.05205 | I8: 4.0967438 | J8: 4.9974674 | K8: 5.8721154 | L8: 6.8233661 | M8: 7.5778283 | N8: 8.2833495 | O8: 8.9272981 | P8: 9.5089735 | Q8: 10.133568 | R8: 10.685397 | S8: 11.267158 | T8: 11.76437 | U8: 12.300508 | V8: 12.759756 | W8: 13.257586 | X8: 13.701293 | Y8: 14.154662 | Z8: 14.5902 | AA8: 14.981629 | AB8: 15.370134 | AC8: 15.723149 | AD8: 16.128522 | AE8: 16.462179 | AF8: 16.806358 | AG8: 17.140174 | AH8: 17.489793 | AI8: 17.782517 | AJ8: 18.11778 | AK8: 18.437846 | AL8: 18.731488 | AM8: 19.025539 | AN8: 19.30663 | AO8: 19.57829 | AP8: 19.842131 | AQ8: 20.13007 | AR8: 20.385188 | AS8: 20.63598 | AT8: 20.895465 | AU8: 21.161129 | AV8: 21.394899 | AW8: 21.635947 | AX8: 21.870996 | AY8: 22.077051 | AZ8: 22.278596 | BA8: 22.497692 | BB8: 22.703526 | BC8: 22.905539 | BD8: 23.080339 | BE8: 23.266556 | BF8: 23.445896 | BG8: 23.62691 | BH8: 23.832371 | BI8: 24.017994 | BJ8: 24.188737 | BK8: 24.36579 | BL8: 24.515977 | BM8: 24.687977 | BN8: 24.840725 | BO8: 25.017853 | BP8: 25.168326 | BQ8: 25.321571 | BR8: 25.480398 | BS8: 25.639104 | BT8: 25.795511 | BU8: 25.945918 | BV8: 26.081548 | BW8: 26.216028 | BX8: 26.3562 | BY8: 26.483357 | BZ8: 26.619768 | CA8: 26.755375 | CB8: 26.896391 | CC8: 27.019241 | CD8: 27.149435 | CE8: 27.258738 | CF8: 27.396202 | CG8: 27.523972 | CH8: 27.642602 | CI8: 27.766649 | CJ8: 27.879139 | CK8: 27.98977 | CL8: 28.108204 | CM8: 28.235717 | CN8: 28.352244 | CO8: 28.462761 | CP8: 28.579045 | CQ8: 28.696526 | CR8: 28.81928 | CS8: 28.856184 | CT8: 5.0043178
A9: 20 | B9: -4.6837047 | C9: -2.4708725 | D9: -0.7207286 | E9: 0.71663083 | F9: 1.9759966 | G9: 3.1615545 | H9: 4.2856351 | I9: 5.2522873 | J9: 6.1071262 | K9: 7.0157498 | L9: 7.8980708 | M9: 8.6719557 | N9: 9.3242281 | O9: 9.9926587 | P9: 10.541698 | Q9: 11.142709 | R9: 11.725286 | S9: 12.281344 | T9: 12.752734 | U9: 13.251987 | V9: 13.711347 | W9: 14.179992 | X9: 14.623232 | Y9: 15.083375 | Z9: 15.482509 | AA9: 15.832707 | AB9: 16.228767 | AC9: 16.572401 | AD9: 16.957826 | AE9: 17.29572 | AF9: 17.636741 | AG9: 17.940447 | AH9: 18.256112 | AI9: 18.554284 | AJ9: 18.857548 | AK9: 19.162732 | AL9: 19.471773 | AM9: 19.749189 | AN9: 20.020637 | AO9: 20.287077 | AP9: 20.553823 | AQ9: 20.774655 | AR9: 21.027239 | AS9: 21.275023 | AT9: 21.516468 | AU9: 21.751309 | AV9: 21.97269 | AW9: 22.216671 | AX9: 22.432964 | AY9: 22.654583 | AZ9: 22.860596 | BA9: 23.030589 | BB9: 23.213991 | BC9: 23.418639 | BD9: 23.605551 | BE9: 23.78208 | BF9: 23.96374 | BG9: 24.130279 | BH9: 24.298143 | BI9: 24.463309 | BJ9: 24.645534 | BK9: 24.798517 | BL9: 24.970076 | BM9: 25.143532 | BN9: 25.297586 | BO9: 25.447802 | BP9: 25.608476 | BQ9: 25.744508 | BR9: 25.885645 | BS9: 26.017486 | BT9: 26.154039 | BU9: 26.278317 | BV9: 26.424268 | BW9: 26.566418 | BX9: 26.706809 | BY9: 26.841007 | BZ9: 26.970113 | CA9: 27.090968 | CB9: 27.217326 | CC9: 27.325824 | CD9: 27.459809 | CE9: 27.584491 | CF9: 27.706216 | CG9: 27.830769 | CH9: 27.942228 | CI9: 28.058855 | CJ9: 28.170724 | CK9: 28.30588 | CL9: 28.415201 | CM9: 28.526288 | CN9: 28.63596 | CO9: 28.747053 | CP9: 28.864072 | CQ9: 28.974038 | CR9: 29.087622 | CS9: 29.129193 | CT9: 6.1116362
A10: 25 | B10: -3.2017679 | C10: -1.1929082 | D10: 0.51210045 | E10: 2.0403795 | F10: 3.1409217 | G10: 4.2768229 | H10: 5.4188013 | I10: 6.413746 | J10: 7.2717097 | K10: 8.1741085 | L10: 8.9661609 | M10: 9.6969247 | N10: 10.37074 | O10: 10.980399 | P10: 11.546097 | Q10: 12.139905 | R10: 12.73204 | S10: 13.233692 | T10: 13.714837 | U10: 14.180466 | V10: 14.647295 | W10: 15.113367 | X10: 15.513389 | Y10: 15.920744 | Z10: 16.333515 | AA10: 16.679326 | AB10: 17.026125 | AC10: 17.374729 | AD10: 17.74841 | AE10: 18.071112 | AF10: 18.392063 | AG10: 18.706436 | AH10: 19.040628 | AI10: 19.326275 | AJ10: 19.599277 | AK10: 19.891539 | AL10: 20.18372 | AM10: 20.422889 | AN10: 20.668046 | AO10: 20.931954 | AP10: 21.177887 | AQ10: 21.428141 | AR10: 21.662178 | AS10: 21.883609 | AT10: 22.115108 | AU10: 22.34184 | AV10: 22.563226 | AW10: 22.753043 | AX10: 22.955322 | AY10: 23.146225 | AZ10: 23.357938 | BA10: 23.555566 | BB10: 23.730364 | BC10: 23.905163 | BD10: 24.092974 | BE10: 24.279403 | BF10: 24.442867 | BG10: 24.61182 | BH10: 24.76381 | BI10: 24.918535 | BJ10: 25.078504 | BK10: 25.231023 | BL10: 25.389346 | BM10: 25.566583 | BN10: 25.70494 | BO10: 25.847908 | BP10: 25.992875 | BQ10: 26.135494 | BR10: 26.269022 | BS10: 26.400143 | BT10: 26.527971 | BU10: 26.65777 | BV10: 26.789505 | BW10: 26.916587 | BX10: 27.040098 | BY10: 27.158107 | BZ10: 27.275633 | CA10: 27.411892 | CB10: 27.537932 | CC10: 27.650929 | CD10: 27.775527 | CE10: 27.89121 | CF10: 28.006839 | CG10: 28.118 | CH10: 28.247478 | CI10: 28.36058 | CJ10: 28.477878 | CK10: 28.590527 | CL10: 28.697527 | CM10: 28.81782 | CN10: 28.929208 | CO10: 29.037033 | CP10: 29.145603 | CQ10: 29.242129 | CR10: 29.343947 | CS10: 29.382682 | CT10: 7.2806758
A11: 30 | B11: -1.8011761 | C11: 0.014961723 | D11: 1.821427 | E11: 3.2956255 | F11: 4.3828108 | G11: 5.4579222 | H11: 6.5482783 | I11: 7.5421765 | J11: 8.3684529 | K11: 9.2776571 | L11: 10.037469 | M11: 10.742593 | N11: 11.360122 | O11: 11.966457 | P11: 12.538499 | Q11: 13.131319 | R11: 13.684965 | S11: 14.181159 | T11: 14.682351 | U11: 15.112572 | V11: 15.562709 | W11: 15.960554 | X11: 16.36965 | Y11: 16.751689 | Z11: 17.156578 | AA11: 17.501331 | AB11: 17.826701 | AC11: 18.15022 | AD11: 18.493324 | AE11: 18.838502 | AF11: 19.1197 | AG11: 19.45739 | AH11: 19.750805 | AI11: 20.043755 | AJ11: 20.305883 | AK11: 20.572523 | AL11: 20.83271 | AM11: 21.114808 | AN11: 21.360385 | AO11: 21.576985 | AP11: 21.801047 | AQ11: 22.022879 | AR11: 22.24863 | AS11: 22.458839 | AT11: 22.656976 | AU11: 22.882973 | AV11: 23.073274 | AW11: 23.280909 | AX11: 23.481945 | AY11: 23.670412 | AZ11: 23.855531 | BA11: 24.029877 | BB11: 24.228362 | BC11: 24.39558 | BD11: 24.548742 | BE11: 24.712456 | BF11: 24.87996 | BG11: 25.052169 | BH11: 25.217988 | BI11: 25.365528 | BJ11: 25.519593 | BK11: 25.665421 | BL11: 25.803549 | BM11: 25.945918 | BN11: 26.079251 | BO11: 26.216028 | BP11: 26.360723 | BQ11: 26.496392 | BR11: 26.618875 | BS11: 26.751813 | BT11: 26.894082 | BU11: 27.014578 | BV11: 27.142746 | BW11: 27.255737 | BX11: 27.37511 | BY11: 27.496201 | BZ11: 27.614668 | CA11: 27.728827 | CB11: 27.849411 | CC11: 27.954962 | CD11: 28.06916 | CE11: 28.182129 | CF11: 28.318341 | CG11: 28.426353 | CH11: 28.537957 | CI11: 28.643621 | CJ11: 28.758121 | CK11: 28.878028 | CL11: 28.986075 | CM11: 29.095197 | CN11: 29.200872 | CO11: 29.29764 | CP11: 29.391942 | CQ11: 29.497697 | CR11: 29.593552 | CS11: 29.629189 | CT11: 8.3768794
A12: 35 | B12: -0.35451338 | C12: 1.3858309 | D12: 3.1177457 | E12: 4.5264713 | F12: 5.6026464 | G12: 6.5976872 | H12: 7.6654205 | I12: 8.6072807 | J12: 9.5471067 | K12: 10.338432 | L12: 11.088493 | M12: 11.710857 | N12: 12.341926 | O12: 12.937072 | P12: 13.534125 | Q12: 14.10858 | R12: 14.61185 | S12: 15.113806 | T12: 15.598537 | U12: 15.974702 | V12: 16.398552 | W12: 16.805355 | X12: 17.202264 | Y12: 17.573636 | Z12: 17.930853 | AA12: 18.261685 | AB12: 18.611777 | AC12: 18.918593 | AD12: 19.234733 | AE12: 19.58362 | AF12: 19.860438 | AG12: 20.161962 | AH12: 20.428825 | AI12: 20.705079 | AJ12: 20.949356 | AK12: 21.212444 | AL12: 21.467959 | AM12: 21.734394 | AN12: 21.96608 | AO12: 22.193262 | AP12: 22.405186 | AQ12: 22.620775 | AR12: 22.824444 | AS12: 23.030258 | AT12: 23.202263 | AU12: 23.395904 | AV12: 23.577184 | AW12: 23.780448 | AX12: 23.968744 | AY12: 24.156159 | AZ12: 24.329482 | BA12: 24.490615 | BB12: 24.672182 | BC12: 24.828315 | BD12: 25.013657 | BE12: 25.172099 | BF12: 25.337002 | BG12: 25.48537 | BH12: 25.639104 | BI12: 25.779968 | BJ12: 25.925434 | BK12: 26.070552 | BL12: 26.198194 | BM12: 26.321944 | BN12: 26.456685 | BO12: 26.582343 | BP12: 26.710137 | BQ12: 26.837356 | BR12: 26.965303 | BS12: 27.097387 | BT12: 27.216913 | BU12: 27.338074 | BV12: 27.463362 | BW12: 27.577045 | BX12: 27.698968 | BY12: 27.819929 | BZ12: 27.932029 | CA12: 28.05082 | CB12: 28.160143 | CC12: 28.287705 | CD12: 28.389061 | CE12: 28.502696 | CF12: 28.612936 | CG12: 28.712447 | CH12: 28.828828 | CI12: 28.943911 | CJ12: 29.048455 | CK12: 29.156591 | CL12: 29.249606 | CM12: 29.348719 | CN12: 29.455617 | CO12: 29.555437 | CP12: 29.644863 | CQ12: 29.739408 | CR12: 29.842481 | CS12: 29.881021 | CT12: 9.5542854
A13: 40 | B13: 0.84604229 | C13: 2.7386597 | D13: 4.3555081 | E13: 5.6060547 | F13: 6.7608071 | G13: 7.7783116 | H13: 8.8049963 | I13: 9.6806851 | J13: 10.611446 | K13: 11.401269 | L13: 12.081808 | M13: 12.739189 | N13: 13.309707 | O13: 13.88868 | P13: 14.459524 | Q13: 15.04408 | R13: 15.573581 | S13: 15.96727 | T13: 16.429356 | U13: 16.819242 | V13: 17.239292 | W13: 17.63201 | X13: 17.961183 | Y13: 18.333007 | Z13: 18.686388 | AA13: 19.02126 | AB13: 19.35166 | AC13: 19.626263 | AD13: 19.93733 | AE13: 20.258821 | AF13: 20.545921 | AG13: 20.784034 | AH13: 21.070294 | AI13: 21.337437 | AJ13: 21.597938 | AK13: 21.815047 | AL13: 22.051941 | AM13: 22.285006 | AN13: 22.523669 | AO13: 22.74596 | AP13: 22.95412 | AQ13: 23.137527 | AR13: 23.362244 | AS13: 23.54686 | AT13: 23.725676 | AU13: 23.919638 | AV13: 24.08694 | AW13: 24.264923 | AX13: 24.440708 | AY13: 24.627457 | AZ13: 24.78573 | BA13: 24.951861 | BB13: 25.122945 | BC13: 25.271107 | BD13: 25.4385 | BE13: 25.600069 | BF13: 25.740377 | BG13: 25.889214 | BH13: 26.025392 | BI13: 26.1669 | BJ13: 26.290606 | BK13: 26.431312 | BL13: 26.571892 | BM13: 26.70047 | BN13: 26.831819 | BO13: 26.964261 | BP13: 27.082565 | BQ13: 27.199611 | BR13: 27.309294 | BS13: 27.428145 | BT13: 27.546254 | BU13: 27.65753 | BV13: 27.778069 | BW13: 27.89621 | BX13: 28.007625 | BY13: 28.12026 | BZ13: 28.246778 | CA13: 28.360659 | CB13: 28.468939 | CC13: 28.574426 | CD13: 28.673748 | CE13: 28.804222 | CF13: 28.912615 | CG13: 29.020533 | CH13: 29.121474 | CI13: 29.224627 | CJ13: 29.312698 | CK13: 29.419615 | CL13: 29.51472 | CM13: 29.608268 | CN13: 29.697982 | CO13: 29.798618 | CP13: 29.898037 | CQ13: 29.994657 | CR13: 30.087808 | CS13: 30.129234 | CT13: 10.620755
A14: 45 | B14: 1.9533922 | C14: 3.909728 | D14: 5.5530003 | E14: 6.8047313 | F14: 7.8731831 | G14: 8.9736185 | H14: 9.9103931 | I14: 10.752087 | J14: 11.61158 | K14: 12.407993 | L14: 13.102142 | M14: 13.718584 | N14: 14.274677 | O14: 14.819896 | P14: 15.335646 | Q14: 15.88223 | R14: 16.389965 | S14: 16.789717 | T14: 17.253341 | U14: 17.62902 | V14: 17.997908 | W14: 18.368037 | X14: 18.731508 | Y14: 19.10613 | Z14: 19.422612 | AA14: 19.733244 | AB14: 20.066229 | AC14: 20.323799 | AD14: 20.582129 | AE14: 20.869321 | AF14: 21.170588 | AG14: 21.424258 | AH14: 21.669738 | AI14: 21.912631 | AJ14: 22.174895 | AK14: 22.401245 | AL14: 22.61586 | AM14: 22.840088 | AN14: 23.040241 | AO14: 23.252556 | AP14: 23.461172 | AQ14: 23.656852 | AR14: 23.836763 | AS14: 24.021634 | AT14: 24.216611 | AU14: 24.38822 | AV14: 24.561773 | AW14: 24.735606 | AX14: 24.894139 | AY14: 25.064801 | AZ14: 25.218419 | BA14: 25.380737 | BB14: 25.558074 | BC14: 25.69494 | BD14: 25.844611 | BE14: 25.992654 | BF14: 26.132248 | BG14: 26.270327 | BH14: 26.405788 | BI14: 26.542242 | BJ14: 26.671675 | BK14: 26.797156 | BL14: 26.920988 | BM14: 27.04276 | BN14: 27.173265 | BO14: 27.281964 | BP14: 27.414099 | BQ14: 27.53091 | BR14: 27.645972 | BS14: 27.776772 | BT14: 27.889378 | BU14: 27.989768 | BV14: 28.103277 | BW14: 28.217051 | BX14: 28.331438 | BY14: 28.439572 | BZ14: 28.543287 | CA14: 28.649883 | CB14: 28.768205 | CC14: 28.881233 | CD14: 28.98428 | CE14: 29.092588 | CF14: 29.193618 | CG14: 29.287882 | CH14: 29.383886 | CI14: 29.4852 | CJ14: 29.584418 | CK14: 29.672925 | CL14: 29.773906 | CM14: 29.872209 | CN14: 29.963957 | CO14: 30.055882 | CP14: 30.15133 | CQ14: 30.23844 | CR14: 30.320761 | CS14: 30.355913 | CT14: 11.625358
A15: 50 | B15: 3.1821207 | C15: 5.1341257 | D15: 6.6995752 | E15: 7.8941042 | F15: 9.0600608 | G15: 10.061229 | H15: 10.992817 | I15: 11.846807 | J15: 12.661727 | K15: 13.3633 | L15: 14.090583 | M15: 14.653339 | N15: 15.206647 | O15: 15.712756 | P15: 16.222545 | Q15: 16.717763 | R15: 17.196095 | S15: 17.576054 | T15: 18.001074 | U15: 18.366233 | V15: 18.753686 | W15: 19.097675 | X15: 19.459438 | Y15: 19.803793 | Z15: 20.139724 | AA15: 20.412862 | AB15: 20.696101 | AC15: 20.994049 | AD15: 21.252239 | AE15: 21.482346 | AF15: 21.748018 | AG15: 22.005057 | AH15: 22.249506 | AI15: 22.473672 | AJ15: 22.700788 | AK15: 22.916121 | AL15: 23.121795 | AM15: 23.324729 | AN15: 23.530399 | AO15: 23.727259 | AP15: 23.929929 | AQ15: 24.120081 | AR15: 24.318917 | AS15: 24.49162 | AT15: 24.660942 | AU15: 24.816501 | AV15: 24.995225 | AW15: 25.160767 | AX15: 25.331109 | AY15: 25.484343 | AZ15: 25.640672 | BA15: 25.781998 | BB15: 25.932904 | BC15: 26.074214 | BD15: 26.213748 | BE15: 26.357306 | BF15: 26.495048 | BG15: 26.622896 | BH15: 26.760166 | BI15: 26.895561 | BJ15: 27.0174 | BK15: 27.143311 | BL15: 27.254523 | BM15: 27.385066 | BN15: 27.50561 | BO15: 27.616446 | BP15: 27.736385 | BQ15: 27.852682 | BR15: 27.966609 | BS15: 28.079239 | BT15: 28.19634 | BU15: 28.321957 | BV15: 28.425419 | BW15: 28.537129 | BX15: 28.643621 | BY15: 28.754963 | BZ15: 28.859008 | CA15: 28.966437 | CB15: 29.067988 | CC15: 29.167623 | CD15: 29.261762 | CE15: 29.351037 | CF15: 29.461284 | CG15: 29.554673 | CH15: 29.645448 | CI15: 29.735962 | CJ15: 29.837641 | CK15: 29.936154 | CL15: 30.029911 | CM15: 30.127923 | CN15: 30.213258 | CO15: 30.289951 | CP15: 30.375635 | CQ15: 30.463968 | CR15: 30.553487 | CS15: 30.590835 | CT15: 12.665393
A16: 55 | B16: 4.4268588 | C16: 6.3128749 | D16: 7.8256163 | E16: 9.0325851 | F16: 10.152809 | G16: 11.14879 | H16: 12.019769 | I16: 12.835696 | J16: 13.636454 | K16: 14.334096 | L16: 14.986506 | M16: 15.541431 | N16: 16.100603 | O16: 16.581595 | P16: 17.056024 | Q16: 17.518384 | R16: 17.951515 | S16: 18.32115 | T16: 18.705128 | U16: 19.097263 | V16: 19.458712 | W16: 19.799354 | X16: 20.148477 | Y16: 20.444634 | Z16: 20.740393 | AA16: 21.050535 | AB16: 21.337453 | AC16: 21.576778 | AD16: 21.850185 | AE16: 22.087586 | AF16: 22.317418 | AG16: 22.558732 | AH16: 22.785182 | AI16: 23.021312 | AJ16: 23.215089 | AK16: 23.408605 | AL16: 23.615629 | AM16: 23.814114 | AN16: 24.010005 | AO16: 24.194838 | AP16: 24.376549 | AQ16: 24.549902 | AR16: 24.730212 | AS16: 24.906983 | AT16: 25.08123 | AU16: 25.252446 | AV16: 25.421205 | AW16: 25.57717 | AX16: 25.713292 | AY16: 25.872568 | AZ16: 26.013152 | BA16: 26.159746 | BB16: 26.288267 | BC16: 26.427699 | BD16: 26.561934 | BE16: 26.687127 | BF16: 26.829089 | BG16: 26.95237 | BH16: 27.090167 | BI16: 27.213634 | BJ16: 27.329637 | BK16: 27.458667 | BL16: 27.577045 | BM16: 27.696444 | BN16: 27.828842 | BO16: 27.939314 | BP16: 28.046391 | BQ16: 28.160451 | BR16: 28.292743 | BS16: 28.393315 | BT16: 28.504228 | BU16: 28.612569 | BV16: 28.716091 | BW16: 28.835106 | BX16: 28.944995 | BY16: 29.053269 | BZ16: 29.154232 | CA16: 29.249606 | CB16: 29.345174 | CC16: 29.453976 | CD16: 29.544641 | CE16: 29.634114 | CF16: 29.720598 | CG16: 29.816588 | CH16: 29.913105 | CI16: 30.004173 | CJ16: 30.098666 | CK16: 30.182842 | CL16: 30.265465 | CM16: 30.352031 | CN16: 30.436328 | CO16: 30.524762 | CP16: 30.609394 | CQ16: 30.690389 | CR16: 30.773975 | CS16: 30.809956 | CT16: 13.649299
... A85: 400 | B85: 19.827608 | C85: 20.574445 | D85: 21.230334 | E85: 21.778141 | F85: 22.256328 | G85: 22.684328 | H85: 23.05701 | I85: 23.419515 | J85: 23.725676 | K85: 24.041667 | L85: 24.349259 | M85: 24.605478 | N85: 24.856075 | O85: 25.116243 | P85: 25.351449 | Q85: 25.578589 | R85: 25.781569 | S85: 25.98247 | T85: 26.163908 | U85: 26.344006 | V85: 26.517224 | W85: 26.699145 | X85: 26.875398 | Y85: 27.025731 | Z85: 27.182078 | AA85: 27.329704 | AB85: 27.492836 | AC85: 27.636453 | AD85: 27.786149 | AE85: 27.919033 | AF85: 28.052907 | AG85: 28.192798 | AH85: 28.339244 | AI85: 28.460476 | AJ85: 28.588337 | AK85: 28.713684 | AL85: 28.847785 | AM85: 28.97453 | AN85: 29.090721 | AO85: 29.20885 | AP85: 29.308103 | AQ85: 29.420841 | AR85: 29.534378 | AS85: 29.64005 | AT85: 29.744437 | AU85: 29.865003 | AV85: 29.965334 | AW85: 30.068155 | AX85: 30.166729 | AY85: 30.256101 | AZ85: 30.350484 | BA85: 30.444159 | BB85: 30.536562 | BC85: 30.627623 | BD85: 30.716168 | BE85: 30.79833 | BF85: 30.894832 | BG85: 30.982573 | BH85: 31.062176 | BI85: 31.145788 | BJ85: 31.232821 | BK85: 31.312531 | BL85: 31.390263 | BM85: 31.475537 | BN85: 31.556151 | BO85: 31.628961 | BP85: 31.706783 | BQ85: 31.792946 | BR85: 31.872191 | BS85: 31.955717 | BT85: 32.03212 | BU85: 32.109986 | BV85: 32.184184 | BW85: 32.255141 | BX85: 32.326509 | BY85: 32.396269 | BZ85: 32.47766 | CA85: 32.549948 | CB85: 32.617763 | CC85: 32.681997 | CD85: 32.747033 | CE85: 32.815102 | CF85: 32.886377 | CG85: 32.952964 | CH85: 33.019641 | CI85: 33.092465 | CJ85: 33.155847 | CK85: 33.210313 | CL85: 33.273206 | CM85: 33.347037 | CN85: 33.413948 | CO85: 33.482951 | CP85: 33.55019 | CQ85: 33.616955 | CR85: 33.681944 | CS85: 33.70648 | CT85: 23.732449

Sheet Delay
A1: The least delay that meets each appetite with each line (quarters): (28 - the critical depth) / 4
A2: Blank where no delay can meet the appetite with that line. Depth = 28 - 4 x delay, never below 0.
A4: Line ($ million) | B4: =Quantiles!B4 -> 0.01 | C4: =Quantiles!C4 -> 0.0125 | D4: =Quantiles!D4 -> 0.015 | E4: =Quantiles!E4 -> 0.0175 | F4: =Quantiles!F4 -> 0.02 | G4: =Quantiles!G4 -> 0.0225 | H4: =Quantiles!H4 -> 0.025 | I4: =Quantiles!I4 -> 0.0275 | ... CT4: =Quantiles!CT4 -> 0.03003
A5: =Quantiles!A5 -> 0 | B5: =IF(Quantiles!B5<0,"",(Depth0-MIN(Depth0,Quantiles!B5))/Depth_per_q) | C5: =IF(Quantiles!C5<0,"",(Depth0-MIN(Depth0,Quantiles!C5))/Depth_per_q) | D5: =IF(Quantiles!D5<0,"",(Depth0-MIN(Depth0,Quantiles!D5))/Depth_per_q) | E5: =IF(Quantiles!E5<0,"",(Depth0-MIN(Depth0,Quantiles!E5))/Depth_per_q) | F5: =IF(Quantiles!F5<0,"",(Depth0-MIN(Depth0,Quantiles!F5))/Depth_per_q) | G5: =IF(Quantiles!G5<0,"",(Depth0-MIN(Depth0,Quantiles!G5))/Depth_per_q) | H5: =IF(Quantiles!H5<0,"",(Depth0-MIN(Depth0,Quantiles!H5))/Depth_per_q) | I5: =IF(Quantiles!I5<0,"",(Depth0-MIN(Depth0,Quantiles!I5))/Depth_per_q) -> 6.8975476 | ... CT5: =IF(Quantiles!CT5<0,"",(Depth0-MIN(Depth0,Quantiles!CT5))/Depth_per_q) -> 6.6131394
A6: =Quantiles!A6 -> 5 | B6: =IF(Quantiles!B6<0,"",(Depth0-MIN(Depth0,Quantiles!B6))/Depth_per_q) | C6: =IF(Quantiles!C6<0,"",(Depth0-MIN(Depth0,Quantiles!C6))/Depth_per_q) | D6: =IF(Quantiles!D6<0,"",(Depth0-MIN(Depth0,Quantiles!D6))/Depth_per_q) | E6: =IF(Quantiles!E6<0,"",(Depth0-MIN(Depth0,Quantiles!E6))/Depth_per_q) | F6: =IF(Quantiles!F6<0,"",(Depth0-MIN(Depth0,Quantiles!F6))/Depth_per_q) | G6: =IF(Quantiles!G6<0,"",(Depth0-MIN(Depth0,Quantiles!G6))/Depth_per_q) | H6: =IF(Quantiles!H6<0,"",(Depth0-MIN(Depth0,Quantiles!H6))/Depth_per_q) -> 6.8418791 | I6: =IF(Quantiles!I6<0,"",(Depth0-MIN(Depth0,Quantiles!I6))/Depth_per_q) -> 6.5820992 | ... CT6: =IF(Quantiles!CT6<0,"",(Depth0-MIN(Depth0,Quantiles!CT6))/Depth_per_q) -> 6.3265974
A7: =Quantiles!A7 -> 10 | B7: =IF(Quantiles!B7<0,"",(Depth0-MIN(Depth0,Quantiles!B7))/Depth_per_q) | C7: =IF(Quantiles!C7<0,"",(Depth0-MIN(Depth0,Quantiles!C7))/Depth_per_q) | D7: =IF(Quantiles!D7<0,"",(Depth0-MIN(Depth0,Quantiles!D7))/Depth_per_q) | E7: =IF(Quantiles!E7<0,"",(Depth0-MIN(Depth0,Quantiles!E7))/Depth_per_q) | F7: =IF(Quantiles!F7<0,"",(Depth0-MIN(Depth0,Quantiles!F7))/Depth_per_q) | G7: =IF(Quantiles!G7<0,"",(Depth0-MIN(Depth0,Quantiles!G7))/Depth_per_q) -> 6.7979957 | H7: =IF(Quantiles!H7<0,"",(Depth0-MIN(Depth0,Quantiles!H7))/Depth_per_q) -> 6.5342528 | I7: =IF(Quantiles!I7<0,"",(Depth0-MIN(Depth0,Quantiles!I7))/Depth_per_q) -> 6.286661 | ... CT7: =IF(Quantiles!CT7<0,"",(Depth0-MIN(Depth0,Quantiles!CT7))/Depth_per_q) -> 6.0429595
A8: =Quantiles!A8 -> 15 | B8: =IF(Quantiles!B8<0,"",(Depth0-MIN(Depth0,Quantiles!B8))/Depth_per_q) | C8: =IF(Quantiles!C8<0,"",(Depth0-MIN(Depth0,Quantiles!C8))/Depth_per_q) | D8: =IF(Quantiles!D8<0,"",(Depth0-MIN(Depth0,Quantiles!D8))/Depth_per_q) | E8: =IF(Quantiles!E8<0,"",(Depth0-MIN(Depth0,Quantiles!E8))/Depth_per_q) | F8: =IF(Quantiles!F8<0,"",(Depth0-MIN(Depth0,Quantiles!F8))/Depth_per_q) -> 6.8005489 | G8: =IF(Quantiles!G8<0,"",(Depth0-MIN(Depth0,Quantiles!G8))/Depth_per_q) -> 6.4923365 | H8: =IF(Quantiles!H8<0,"",(Depth0-MIN(Depth0,Quantiles!H8))/Depth_per_q) -> 6.2369875 | I8: =IF(Quantiles!I8<0,"",(Depth0-MIN(Depth0,Quantiles!I8))/Depth_per_q) -> 5.975814 | ... CT8: =IF(Quantiles!CT8<0,"",(Depth0-MIN(Depth0,Quantiles!CT8))/Depth_per_q) -> 5.7489205
A9: =Quantiles!A9 -> 20 | B9: =IF(Quantiles!B9<0,"",(Depth0-MIN(Depth0,Quantiles!B9))/Depth_per_q) | C9: =IF(Quantiles!C9<0,"",(Depth0-MIN(Depth0,Quantiles!C9))/Depth_per_q) | D9: =IF(Quantiles!D9<0,"",(Depth0-MIN(Depth0,Quantiles!D9))/Depth_per_q) | E9: =IF(Quantiles!E9<0,"",(Depth0-MIN(Depth0,Quantiles!E9))/Depth_per_q) -> 6.8208423 | F9: =IF(Quantiles!F9<0,"",(Depth0-MIN(Depth0,Quantiles!F9))/Depth_per_q) -> 6.5060009 | G9: =IF(Quantiles!G9<0,"",(Depth0-MIN(Depth0,Quantiles!G9))/Depth_per_q) -> 6.2096114 | H9: =IF(Quantiles!H9<0,"",(Depth0-MIN(Depth0,Quantiles!H9))/Depth_per_q) -> 5.9285912 | I9: =IF(Quantiles!I9<0,"",(Depth0-MIN(Depth0,Quantiles!I9))/Depth_per_q) -> 5.6869282 | ... CT9: =IF(Quantiles!CT9<0,"",(Depth0-MIN(Depth0,Quantiles!CT9))/Depth_per_q) -> 5.472091
A10: =Quantiles!A10 -> 25 | B10: =IF(Quantiles!B10<0,"",(Depth0-MIN(Depth0,Quantiles!B10))/Depth_per_q) | C10: =IF(Quantiles!C10<0,"",(Depth0-MIN(Depth0,Quantiles!C10))/Depth_per_q) | D10: =IF(Quantiles!D10<0,"",(Depth0-MIN(Depth0,Quantiles!D10))/Depth_per_q) -> 6.8719749 | E10: =IF(Quantiles!E10<0,"",(Depth0-MIN(Depth0,Quantiles!E10))/Depth_per_q) -> 6.4899051 | F10: =IF(Quantiles!F10<0,"",(Depth0-MIN(Depth0,Quantiles!F10))/Depth_per_q) -> 6.2147696 | G10: =IF(Quantiles!G10<0,"",(Depth0-MIN(Depth0,Quantiles!G10))/Depth_per_q) -> 5.9307943 | H10: =IF(Quantiles!H10<0,"",(Depth0-MIN(Depth0,Quantiles!H10))/Depth_per_q) -> 5.6452997 | I10: =IF(Quantiles!I10<0,"",(Depth0-MIN(Depth0,Quantiles!I10))/Depth_per_q) -> 5.3965635 | ... CT10: =IF(Quantiles!CT10<0,"",(Depth0-MIN(Depth0,Quantiles!CT10))/Depth_per_q) -> 5.179831
A11: =Quantiles!A11 -> 30 | B11: =IF(Quantiles!B11<0,"",(Depth0-MIN(Depth0,Quantiles!B11))/Depth_per_q) | C11: =IF(Quantiles!C11<0,"",(Depth0-MIN(Depth0,Quantiles!C11))/Depth_per_q) -> 6.9962596 | D11: =IF(Quantiles!D11<0,"",(Depth0-MIN(Depth0,Quantiles!D11))/Depth_per_q) -> 6.5446432 | E11: =IF(Quantiles!E11<0,"",(Depth0-MIN(Depth0,Quantiles!E11))/Depth_per_q) -> 6.1760936 | F11: =IF(Quantiles!F11<0,"",(Depth0-MIN(Depth0,Quantiles!F11))/Depth_per_q) -> 5.9042973 | G11: =IF(Quantiles!G11<0,"",(Depth0-MIN(Depth0,Quantiles!G11))/Depth_per_q) -> 5.6355195 | H11: =IF(Quantiles!H11<0,"",(Depth0-MIN(Depth0,Quantiles!H11))/Depth_per_q) -> 5.3629304 | I11: =IF(Quantiles!I11<0,"",(Depth0-MIN(Depth0,Quantiles!I11))/Depth_per_q) -> 5.1144559 | ... CT11: =IF(Quantiles!CT11<0,"",(Depth0-MIN(Depth0,Quantiles!CT11))/Depth_per_q) -> 4.9057801
A12: =Quantiles!A12 -> 35 | B12: =IF(Quantiles!B12<0,"",(Depth0-MIN(Depth0,Quantiles!B12))/Depth_per_q) | C12: =IF(Quantiles!C12<0,"",(Depth0-MIN(Depth0,Quantiles!C12))/Depth_per_q) -> 6.6535423 | D12: =IF(Quantiles!D12<0,"",(Depth0-MIN(Depth0,Quantiles!D12))/Depth_per_q) -> 6.2205636 | E12: =IF(Quantiles!E12<0,"",(Depth0-MIN(Depth0,Quantiles!E12))/Depth_per_q) -> 5.8683822 | F12: =IF(Quantiles!F12<0,"",(Depth0-MIN(Depth0,Quantiles!F12))/Depth_per_q) -> 5.5993384 | G12: =IF(Quantiles!G12<0,"",(Depth0-MIN(Depth0,Quantiles!G12))/Depth_per_q) -> 5.3505782 | H12: =IF(Quantiles!H12<0,"",(Depth0-MIN(Depth0,Quantiles!H12))/Depth_per_q) -> 5.0836449 | I12: =IF(Quantiles!I12<0,"",(Depth0-MIN(Depth0,Quantiles!I12))/Depth_per_q) -> 4.8481798 | ... CT12: =IF(Quantiles!CT12<0,"",(Depth0-MIN(Depth0,Quantiles!CT12))/Depth_per_q) -> 4.6114286
A13: =Quantiles!A13 -> 40 | B13: =IF(Quantiles!B13<0,"",(Depth0-MIN(Depth0,Quantiles!B13))/Depth_per_q) -> 6.7884894 | C13: =IF(Quantiles!C13<0,"",(Depth0-MIN(Depth0,Quantiles!C13))/Depth_per_q) -> 6.3153351 | D13: =IF(Quantiles!D13<0,"",(Depth0-MIN(Depth0,Quantiles!D13))/Depth_per_q) -> 5.911123 | E13: =IF(Quantiles!E13<0,"",(Depth0-MIN(Depth0,Quantiles!E13))/Depth_per_q) -> 5.5984863 | F13: =IF(Quantiles!F13<0,"",(Depth0-MIN(Depth0,Quantiles!F13))/Depth_per_q) -> 5.3097982 | G13: =IF(Quantiles!G13<0,"",(Depth0-MIN(Depth0,Quantiles!G13))/Depth_per_q) -> 5.0554221 | H13: =IF(Quantiles!H13<0,"",(Depth0-MIN(Depth0,Quantiles!H13))/Depth_per_q) -> 4.7987509 | I13: =IF(Quantiles!I13<0,"",(Depth0-MIN(Depth0,Quantiles!I13))/Depth_per_q) -> 4.5798287 | ... CT13: =IF(Quantiles!CT13<0,"",(Depth0-MIN(Depth0,Quantiles!CT13))/Depth_per_q) -> 4.3448112
A14: =Quantiles!A14 -> 45 | B14: =IF(Quantiles!B14<0,"",(Depth0-MIN(Depth0,Quantiles!B14))/Depth_per_q) -> 6.511652 | C14: =IF(Quantiles!C14<0,"",(Depth0-MIN(Depth0,Quantiles!C14))/Depth_per_q) -> 6.022568 | D14: =IF(Quantiles!D14<0,"",(Depth0-MIN(Depth0,Quantiles!D14))/Depth_per_q) -> 5.6117499 | E14: =IF(Quantiles!E14<0,"",(Depth0-MIN(Depth0,Quantiles!E14))/Depth_per_q) -> 5.2988172 | F14: =IF(Quantiles!F14<0,"",(Depth0-MIN(Depth0,Quantiles!F14))/Depth_per_q) -> 5.0317042 | G14: =IF(Quantiles!G14<0,"",(Depth0-MIN(Depth0,Quantiles!G14))/Depth_per_q) -> 4.7565954 | H14: =IF(Quantiles!H14<0,"",(Depth0-MIN(Depth0,Quantiles!H14))/Depth_per_q) -> 4.5224017 | I14: =IF(Quantiles!I14<0,"",(Depth0-MIN(Depth0,Quantiles!I14))/Depth_per_q) -> 4.3119783 | ... CT14: =IF(Quantiles!CT14<0,"",(Depth0-MIN(Depth0,Quantiles!CT14))/Depth_per_q) -> 4.0936604
A15: =Quantiles!A15 -> 50 | B15: =IF(Quantiles!B15<0,"",(Depth0-MIN(Depth0,Quantiles!B15))/Depth_per_q) -> 6.2044698 | C15: =IF(Quantiles!C15<0,"",(Depth0-MIN(Depth0,Quantiles!C15))/Depth_per_q) -> 5.7164686 | D15: =IF(Quantiles!D15<0,"",(Depth0-MIN(Depth0,Quantiles!D15))/Depth_per_q) -> 5.3251062 | E15: =IF(Quantiles!E15<0,"",(Depth0-MIN(Depth0,Quantiles!E15))/Depth_per_q) -> 5.026474 | F15: =IF(Quantiles!F15<0,"",(Depth0-MIN(Depth0,Quantiles!F15))/Depth_per_q) -> 4.7349848 | G15: =IF(Quantiles!G15<0,"",(Depth0-MIN(Depth0,Quantiles!G15))/Depth_per_q) -> 4.4846926 | H15: =IF(Quantiles!H15<0,"",(Depth0-MIN(Depth0,Quantiles!H15))/Depth_per_q) -> 4.2517959 | I15: =IF(Quantiles!I15<0,"",(Depth0-MIN(Depth0,Quantiles!I15))/Depth_per_q) -> 4.0382982 | ... CT15: =IF(Quantiles!CT15<0,"",(Depth0-MIN(Depth0,Quantiles!CT15))/Depth_per_q) -> 3.8336516
A16: =Quantiles!A16 -> 55 | B16: =IF(Quantiles!B16<0,"",(Depth0-MIN(Depth0,Quantiles!B16))/Depth_per_q) -> 5.8932853 | C16: =IF(Quantiles!C16<0,"",(Depth0-MIN(Depth0,Quantiles!C16))/Depth_per_q) -> 5.4217813 | D16: =IF(Quantiles!D16<0,"",(Depth0-MIN(Depth0,Quantiles!D16))/Depth_per_q) -> 5.0435959 | E16: =IF(Quantiles!E16<0,"",(Depth0-MIN(Depth0,Quantiles!E16))/Depth_per_q) -> 4.7418537 | F16: =IF(Quantiles!F16<0,"",(Depth0-MIN(Depth0,Quantiles!F16))/Depth_per_q) -> 4.4617978 | G16: =IF(Quantiles!G16<0,"",(Depth0-MIN(Depth0,Quantiles!G16))/Depth_per_q) -> 4.2128024 | H16: =IF(Quantiles!H16<0,"",(Depth0-MIN(Depth0,Quantiles!H16))/Depth_per_q) -> 3.9950578 | I16: =IF(Quantiles!I16<0,"",(Depth0-MIN(Depth0,Quantiles!I16))/Depth_per_q) -> 3.7910761 | ... CT16: =IF(Quantiles!CT16<0,"",(Depth0-MIN(Depth0,Quantiles!CT16))/Depth_per_q) -> 3.5876753
... A85: =Quantiles!A85 -> 400 | B85: =IF(Quantiles!B85<0,"",(Depth0-MIN(Depth0,Quantiles!B85))/Depth_per_q) -> 2.0430981 | C85: =IF(Quantiles!C85<0,"",(Depth0-MIN(Depth0,Quantiles!C85))/Depth_per_q) -> 1.8563889 | D85: =IF(Quantiles!D85<0,"",(Depth0-MIN(Depth0,Quantiles!D85))/Depth_per_q) -> 1.6924166 | E85: =IF(Quantiles!E85<0,"",(Depth0-MIN(Depth0,Quantiles!E85))/Depth_per_q) -> 1.5554648 | F85: =IF(Quantiles!F85<0,"",(Depth0-MIN(Depth0,Quantiles!F85))/Depth_per_q) -> 1.435918 | G85: =IF(Quantiles!G85<0,"",(Depth0-MIN(Depth0,Quantiles!G85))/Depth_per_q) -> 1.3289179 | H85: =IF(Quantiles!H85<0,"",(Depth0-MIN(Depth0,Quantiles!H85))/Depth_per_q) -> 1.2357476 | I85: =IF(Quantiles!I85<0,"",(Depth0-MIN(Depth0,Quantiles!I85))/Depth_per_q) -> 1.1451212 | ... CT85: =IF(Quantiles!CT85<0,"",(Depth0-MIN(Depth0,Quantiles!CT85))/Depth_per_q) -> 1.0668877

Sheet Cost
A1: The cost of that package: Fee x line + Vq x delay ($ million)
A2: Fees of 3 percent of the line over the program; $8 million a quarter of delay (Worked Example 15.1).
A4: Line ($ million) | B4: =Quantiles!B4 -> 0.01 | C4: =Quantiles!C4 -> 0.0125 | D4: =Quantiles!D4 -> 0.015 | E4: =Quantiles!E4 -> 0.0175 | F4: =Quantiles!F4 -> 0.02 | G4: =Quantiles!G4 -> 0.0225 | H4: =Quantiles!H4 -> 0.025 | I4: =Quantiles!I4 -> 0.0275 | ... CT4: =Quantiles!CT4 -> 0.03003
A5: =Quantiles!A5 -> 0 | B5: =IF(Delay!B5="","",Fee*$A5+Vq*Delay!B5) | C5: =IF(Delay!C5="","",Fee*$A5+Vq*Delay!C5) | D5: =IF(Delay!D5="","",Fee*$A5+Vq*Delay!D5) | E5: =IF(Delay!E5="","",Fee*$A5+Vq*Delay!E5) | F5: =IF(Delay!F5="","",Fee*$A5+Vq*Delay!F5) | G5: =IF(Delay!G5="","",Fee*$A5+Vq*Delay!G5) | H5: =IF(Delay!H5="","",Fee*$A5+Vq*Delay!H5) | I5: =IF(Delay!I5="","",Fee*$A5+Vq*Delay!I5) -> 55.180381 | ... CT5: =IF(Delay!CT5="","",Fee*$A5+Vq*Delay!CT5) -> 52.905115
A6: =Quantiles!A6 -> 5 | B6: =IF(Delay!B6="","",Fee*$A6+Vq*Delay!B6) | C6: =IF(Delay!C6="","",Fee*$A6+Vq*Delay!C6) | D6: =IF(Delay!D6="","",Fee*$A6+Vq*Delay!D6) | E6: =IF(Delay!E6="","",Fee*$A6+Vq*Delay!E6) | F6: =IF(Delay!F6="","",Fee*$A6+Vq*Delay!F6) | G6: =IF(Delay!G6="","",Fee*$A6+Vq*Delay!G6) | H6: =IF(Delay!H6="","",Fee*$A6+Vq*Delay!H6) -> 54.885033 | I6: =IF(Delay!I6="","",Fee*$A6+Vq*Delay!I6) -> 52.806794 | ... CT6: =IF(Delay!CT6="","",Fee*$A6+Vq*Delay!CT6) -> 50.762779
A7: =Quantiles!A7 -> 10 | B7: =IF(Delay!B7="","",Fee*$A7+Vq*Delay!B7) | C7: =IF(Delay!C7="","",Fee*$A7+Vq*Delay!C7) | D7: =IF(Delay!D7="","",Fee*$A7+Vq*Delay!D7) | E7: =IF(Delay!E7="","",Fee*$A7+Vq*Delay!E7) | F7: =IF(Delay!F7="","",Fee*$A7+Vq*Delay!F7) | G7: =IF(Delay!G7="","",Fee*$A7+Vq*Delay!G7) -> 54.683966 | H7: =IF(Delay!H7="","",Fee*$A7+Vq*Delay!H7) -> 52.574022 | I7: =IF(Delay!I7="","",Fee*$A7+Vq*Delay!I7) -> 50.593288 | ... CT7: =IF(Delay!CT7="","",Fee*$A7+Vq*Delay!CT7) -> 48.643676
A8: =Quantiles!A8 -> 15 | B8: =IF(Delay!B8="","",Fee*$A8+Vq*Delay!B8) | C8: =IF(Delay!C8="","",Fee*$A8+Vq*Delay!C8) | D8: =IF(Delay!D8="","",Fee*$A8+Vq*Delay!D8) | E8: =IF(Delay!E8="","",Fee*$A8+Vq*Delay!E8) | F8: =IF(Delay!F8="","",Fee*$A8+Vq*Delay!F8) -> 54.854391 | G8: =IF(Delay!G8="","",Fee*$A8+Vq*Delay!G8) -> 52.388692 | H8: =IF(Delay!H8="","",Fee*$A8+Vq*Delay!H8) -> 50.3459 | I8: =IF(Delay!I8="","",Fee*$A8+Vq*Delay!I8) -> 48.256512 | ... CT8: =IF(Delay!CT8="","",Fee*$A8+Vq*Delay!CT8) -> 46.441364
A9: =Quantiles!A9 -> 20 | B9: =IF(Delay!B9="","",Fee*$A9+Vq*Delay!B9) | C9: =IF(Delay!C9="","",Fee*$A9+Vq*Delay!C9) | D9: =IF(Delay!D9="","",Fee*$A9+Vq*Delay!D9) | E9: =IF(Delay!E9="","",Fee*$A9+Vq*Delay!E9) -> 55.166738 | F9: =IF(Delay!F9="","",Fee*$A9+Vq*Delay!F9) -> 52.648007 | G9: =IF(Delay!G9="","",Fee*$A9+Vq*Delay!G9) -> 50.276891 | H9: =IF(Delay!H9="","",Fee*$A9+Vq*Delay!H9) -> 48.02873 | I9: =IF(Delay!I9="","",Fee*$A9+Vq*Delay!I9) -> 46.095425 | ... CT9: =IF(Delay!CT9="","",Fee*$A9+Vq*Delay!CT9) -> 44.376728
A10: =Quantiles!A10 -> 25 | B10: =IF(Delay!B10="","",Fee*$A10+Vq*Delay!B10) | C10: =IF(Delay!C10="","",Fee*$A10+Vq*Delay!C10) | D10: =IF(Delay!D10="","",Fee*$A10+Vq*Delay!D10) -> 55.725799 | E10: =IF(Delay!E10="","",Fee*$A10+Vq*Delay!E10) -> 52.669241 | F10: =IF(Delay!F10="","",Fee*$A10+Vq*Delay!F10) -> 50.468157 | G10: =IF(Delay!G10="","",Fee*$A10+Vq*Delay!G10) -> 48.196354 | H10: =IF(Delay!H10="","",Fee*$A10+Vq*Delay!H10) -> 45.912397 | I10: =IF(Delay!I10="","",Fee*$A10+Vq*Delay!I10) -> 43.922508 | ... CT10: =IF(Delay!CT10="","",Fee*$A10+Vq*Delay!CT10) -> 42.188648
A11: =Quantiles!A11 -> 30 | B11: =IF(Delay!B11="","",Fee*$A11+Vq*Delay!B11) | C11: =IF(Delay!C11="","",Fee*$A11+Vq*Delay!C11) -> 56.870077 | D11: =IF(Delay!D11="","",Fee*$A11+Vq*Delay!D11) -> 53.257146 | E11: =IF(Delay!E11="","",Fee*$A11+Vq*Delay!E11) -> 50.308749 | F11: =IF(Delay!F11="","",Fee*$A11+Vq*Delay!F11) -> 48.134378 | G11: =IF(Delay!G11="","",Fee*$A11+Vq*Delay!G11) -> 45.984156 | H11: =IF(Delay!H11="","",Fee*$A11+Vq*Delay!H11) -> 43.803443 | I11: =IF(Delay!I11="","",Fee*$A11+Vq*Delay!I11) -> 41.815647 | ... CT11: =IF(Delay!CT11="","",Fee*$A11+Vq*Delay!CT11) -> 40.146241
A12: =Quantiles!A12 -> 35 | B12: =IF(Delay!B12="","",Fee*$A12+Vq*Delay!B12) | C12: =IF(Delay!C12="","",Fee*$A12+Vq*Delay!C12) -> 54.278338 | D12: =IF(Delay!D12="","",Fee*$A12+Vq*Delay!D12) -> 50.814509 | E12: =IF(Delay!E12="","",Fee*$A12+Vq*Delay!E12) -> 47.997057 | F12: =IF(Delay!F12="","",Fee*$A12+Vq*Delay!F12) -> 45.844707 | G12: =IF(Delay!G12="","",Fee*$A12+Vq*Delay!G12) -> 43.854626 | H12: =IF(Delay!H12="","",Fee*$A12+Vq*Delay!H12) -> 41.719159 | I12: =IF(Delay!I12="","",Fee*$A12+Vq*Delay!I12) -> 39.835439 | ... CT12: =IF(Delay!CT12="","",Fee*$A12+Vq*Delay!CT12) -> 37.941429
A13: =Quantiles!A13 -> 40 | B13: =IF(Delay!B13="","",Fee*$A13+Vq*Delay!B13) -> 55.507915 | C13: =IF(Delay!C13="","",Fee*$A13+Vq*Delay!C13) -> 51.722681 | D13: =IF(Delay!D13="","",Fee*$A13+Vq*Delay!D13) -> 48.488984 | E13: =IF(Delay!E13="","",Fee*$A13+Vq*Delay!E13) -> 45.987891 | F13: =IF(Delay!F13="","",Fee*$A13+Vq*Delay!F13) -> 43.678386 | G13: =IF(Delay!G13="","",Fee*$A13+Vq*Delay!G13) -> 41.643377 | H13: =IF(Delay!H13="","",Fee*$A13+Vq*Delay!H13) -> 39.590007 | I13: =IF(Delay!I13="","",Fee*$A13+Vq*Delay!I13) -> 37.83863 | ... CT13: =IF(Delay!CT13="","",Fee*$A13+Vq*Delay!CT13) -> 35.958489
A14: =Quantiles!A14 -> 45 | B14: =IF(Delay!B14="","",Fee*$A14+Vq*Delay!B14) -> 53.443216 | C14: =IF(Delay!C14="","",Fee*$A14+Vq*Delay!C14) -> 49.530544 | D14: =IF(Delay!D14="","",Fee*$A14+Vq*Delay!D14) -> 46.243999 | E14: =IF(Delay!E14="","",Fee*$A14+Vq*Delay!E14) -> 43.740537 | F14: =IF(Delay!F14="","",Fee*$A14+Vq*Delay!F14) -> 41.603634 | G14: =IF(Delay!G14="","",Fee*$A14+Vq*Delay!G14) -> 39.402763 | H14: =IF(Delay!H14="","",Fee*$A14+Vq*Delay!H14) -> 37.529214 | I14: =IF(Delay!I14="","",Fee*$A14+Vq*Delay!I14) -> 35.845826 | ... CT14: =IF(Delay!CT14="","",Fee*$A14+Vq*Delay!CT14) -> 34.099283
A15: =Quantiles!A15 -> 50 | B15: =IF(Delay!B15="","",Fee*$A15+Vq*Delay!B15) -> 51.135759 | C15: =IF(Delay!C15="","",Fee*$A15+Vq*Delay!C15) -> 47.231749 | D15: =IF(Delay!D15="","",Fee*$A15+Vq*Delay!D15) -> 44.10085 | E15: =IF(Delay!E15="","",Fee*$A15+Vq*Delay!E15) -> 41.711792 | F15: =IF(Delay!F15="","",Fee*$A15+Vq*Delay!F15) -> 39.379878 | G15: =IF(Delay!G15="","",Fee*$A15+Vq*Delay!G15) -> 37.377541 | H15: =IF(Delay!H15="","",Fee*$A15+Vq*Delay!H15) -> 35.514367 | I15: =IF(Delay!I15="","",Fee*$A15+Vq*Delay!I15) -> 33.806386 | ... CT15: =IF(Delay!CT15="","",Fee*$A15+Vq*Delay!CT15) -> 32.169213
A16: =Quantiles!A16 -> 55 | B16: =IF(Delay!B16="","",Fee*$A16+Vq*Delay!B16) -> 48.796282 | C16: =IF(Delay!C16="","",Fee*$A16+Vq*Delay!C16) -> 45.02425 | D16: =IF(Delay!D16="","",Fee*$A16+Vq*Delay!D16) -> 41.998767 | E16: =IF(Delay!E16="","",Fee*$A16+Vq*Delay!E16) -> 39.58483 | F16: =IF(Delay!F16="","",Fee*$A16+Vq*Delay!F16) -> 37.344382 | G16: =IF(Delay!G16="","",Fee*$A16+Vq*Delay!G16) -> 35.352419 | H16: =IF(Delay!H16="","",Fee*$A16+Vq*Delay!H16) -> 33.610462 | I16: =IF(Delay!I16="","",Fee*$A16+Vq*Delay!I16) -> 31.978609 | ... CT16: =IF(Delay!CT16="","",Fee*$A16+Vq*Delay!CT16) -> 30.351402
... A85: =Quantiles!A85 -> 400 | B85: =IF(Delay!B85="","",Fee*$A85+Vq*Delay!B85) -> 28.344784 | C85: =IF(Delay!C85="","",Fee*$A85+Vq*Delay!C85) -> 26.851111 | D85: =IF(Delay!D85="","",Fee*$A85+Vq*Delay!D85) -> 25.539333 | E85: =IF(Delay!E85="","",Fee*$A85+Vq*Delay!E85) -> 24.443719 | F85: =IF(Delay!F85="","",Fee*$A85+Vq*Delay!F85) -> 23.487344 | G85: =IF(Delay!G85="","",Fee*$A85+Vq*Delay!G85) -> 22.631343 | H85: =IF(Delay!H85="","",Fee*$A85+Vq*Delay!H85) -> 21.885981 | I85: =IF(Delay!I85="","",Fee*$A85+Vq*Delay!I85) -> 21.16097 | ... CT85: =IF(Delay!CT85="","",Fee*$A85+Vq*Delay!CT85) -> 20.535101

Sheet Frontier
A1: The frontier by floors: the least cost of every appetite (Theorem 15.5(iii); Figure 15.2, right; Worked Example 15.1, Step 5; AXIOM Lab 1.15, step 4)
A2: Each row minimizes the levers' cost subject to one appetite (a floor on safety): the column of the Cost sheet, its least value, its line and its delay. Phasing alone is the line-0 row.
A4: Appetite | B4: Least cost | C4: Its line | D4: Its delay | E4: Phasing alone: delay | F4: Phasing alone: cost | H4: Step 5 and Table 15.5 | I4: Value | J4: Reading
A5: =INDEX(Quantiles!$B$4:$CT$4,1,1) -> 0.01 | B5: =MIN(INDEX(Cost!$B$5:$CT$85,0,1)) -> 23.089332 | C5: =INDEX(Cost!$A$5:$A$85,MATCH(B5,INDEX(Cost!$B$5:$CT$85,0,1),0)) -> 190 | D5: =INDEX(Delay!$B$5:$CT$85,MATCH(B5,INDEX(Cost!$B$5:$CT$85,0,1),0),1) -> 2.1736665 | E5: =INDEX(Delay!$B$5:$CT$85,1,1) | F5: =IF(E5="","",Vq*E5) | H5: Line alone at $400 million: odds (engine) | I5: 0.08404 | J5: no line, however large, brings the odds below 8.4 percent
A6: =INDEX(Quantiles!$B$4:$CT$4,1,2) -> 0.0125 | B6: =MIN(INDEX(Cost!$B$5:$CT$85,0,2)) -> 21.337606 | C6: =INDEX(Cost!$A$5:$A$85,MATCH(B6,INDEX(Cost!$B$5:$CT$85,0,2),0)) -> 185 | D6: =INDEX(Delay!$B$5:$CT$85,MATCH(B6,INDEX(Cost!$B$5:$CT$85,0,2),0),2) -> 1.9734507 | E6: =INDEX(Delay!$B$5:$CT$85,1,2) | F6: =IF(E6="","",Vq*E6) | H6: Phasing alone at 5%: delay (quarters) | I6: =E21 -> 5.0946732 | J6: 5.1 quarters
A7: =INDEX(Quantiles!$B$4:$CT$4,1,3) -> 0.015 | B7: =MIN(INDEX(Cost!$B$5:$CT$85,0,3)) -> 20.122368 | C7: =INDEX(Cost!$A$5:$A$85,MATCH(B7,INDEX(Cost!$B$5:$CT$85,0,3),0)) -> 175 | D7: =INDEX(Delay!$B$5:$CT$85,MATCH(B7,INDEX(Cost!$B$5:$CT$85,0,3),0),3) -> 1.859046 | E7: =INDEX(Delay!$B$5:$CT$85,1,3) | F7: =IF(E7="","",Vq*E7) | H7: Phasing alone at 5%: depth | I7: =Depth0-Depth_per_q*I6 -> 7.6213073 | J7: Online Appendix 15.B.4: 7.62
A8: =INDEX(Quantiles!$B$4:$CT$4,1,4) -> 0.0175 | B8: =MIN(INDEX(Cost!$B$5:$CT$85,0,4)) -> 18.880368 | C8: =INDEX(Cost!$A$5:$A$85,MATCH(B8,INDEX(Cost!$B$5:$CT$85,0,4),0)) -> 185 | D8: =INDEX(Delay!$B$5:$CT$85,MATCH(B8,INDEX(Cost!$B$5:$CT$85,0,4),0),4) -> 1.6662959 | E8: =INDEX(Delay!$B$5:$CT$85,1,4) | F8: =IF(E8="","",Vq*E8) | H8: Phasing alone at 5%: cost | I8: =F21 -> 40.757385 | J8: $40.8 million
A9: =INDEX(Quantiles!$B$4:$CT$4,1,5) -> 0.02 | B9: =MIN(INDEX(Cost!$B$5:$CT$85,0,5)) -> 17.860851 | C9: =INDEX(Cost!$A$5:$A$85,MATCH(B9,INDEX(Cost!$B$5:$CT$85,0,5),0)) -> 170 | D9: =INDEX(Delay!$B$5:$CT$85,MATCH(B9,INDEX(Cost!$B$5:$CT$85,0,5),0),5) -> 1.5951064 | E9: =INDEX(Delay!$B$5:$CT$85,1,5) | F9: =IF(E9="","",Vq*E9) | H9: Both levers at 5%: least cost | I9: =B21 -> 10.440611 | J9: $10.4 million
A10: =INDEX(Quantiles!$B$4:$CT$4,1,6) -> 0.0225 | B10: =MIN(INDEX(Cost!$B$5:$CT$85,0,6)) -> 16.870376 | C10: =INDEX(Cost!$A$5:$A$85,MATCH(B10,INDEX(Cost!$B$5:$CT$85,0,6),0)) -> 175 | D10: =INDEX(Delay!$B$5:$CT$85,MATCH(B10,INDEX(Cost!$B$5:$CT$85,0,6),0),6) -> 1.452547 | E10: =INDEX(Delay!$B$5:$CT$85,1,6) | F10: =IF(E10="","",Vq*E10) | H10: Value of coordination (Theorem 15.6(iii)) | I10: =I8-I9 -> 30.316774 | J10: $30 million
A11: =INDEX(Quantiles!$B$4:$CT$4,1,7) -> 0.025 | B11: =MIN(INDEX(Cost!$B$5:$CT$85,0,7)) -> 16.079718 | C11: =INDEX(Cost!$A$5:$A$85,MATCH(B11,INDEX(Cost!$B$5:$CT$85,0,7),0)) -> 175 | D11: =INDEX(Delay!$B$5:$CT$85,MATCH(B11,INDEX(Cost!$B$5:$CT$85,0,7),0),7) -> 1.3537147 | E11: =INDEX(Delay!$B$5:$CT$85,1,7) | F11: =IF(E11="","",Vq*E11)
A12: =INDEX(Quantiles!$B$4:$CT$4,1,8) -> 0.0275 | B12: =MIN(INDEX(Cost!$B$5:$CT$85,0,8)) -> 15.338772 | C12: =INDEX(Cost!$A$5:$A$85,MATCH(B12,INDEX(Cost!$B$5:$CT$85,0,8),0)) -> 170 | D12: =INDEX(Delay!$B$5:$CT$85,MATCH(B12,INDEX(Cost!$B$5:$CT$85,0,8),0),8) -> 1.2798464 | E12: =INDEX(Delay!$B$5:$CT$85,1,8) -> 6.8975476 | F12: =IF(E12="","",Vq*E12) -> 55.180381 | H12: Chapter 8's package: line | I12: 100 | J12: Worked Example 8.1
A13: =INDEX(Quantiles!$B$4:$CT$4,1,9) -> 0.03 | B13: =MIN(INDEX(Cost!$B$5:$CT$85,0,9)) -> 14.684124 | C13: =INDEX(Cost!$A$5:$A$85,MATCH(B13,INDEX(Cost!$B$5:$CT$85,0,9),0)) -> 180 | D13: =INDEX(Delay!$B$5:$CT$85,MATCH(B13,INDEX(Cost!$B$5:$CT$85,0,9),0),9) -> 1.1605155 | E13: =INDEX(Delay!$B$5:$CT$85,1,9) -> 6.6187059 | F13: =IF(E13="","",Vq*E13) -> 52.949647 | H13: Chapter 8's package: delay (quarters) | I13: 2 | J13: the phased build
A14: =INDEX(Quantiles!$B$4:$CT$4,1,10) -> 0.0325 | B14: =MIN(INDEX(Cost!$B$5:$CT$85,0,10)) -> 14.077963 | C14: =INDEX(Cost!$A$5:$A$85,MATCH(B14,INDEX(Cost!$B$5:$CT$85,0,10),0)) -> 170 | D14: =INDEX(Delay!$B$5:$CT$85,MATCH(B14,INDEX(Cost!$B$5:$CT$85,0,10),0),10) -> 1.1222454 | E14: =INDEX(Delay!$B$5:$CT$85,1,10) -> 6.3871892 | F14: =IF(E14="","",Vq*E14) -> 51.097513 | H14: Chapter 8's package: cost | I14: =Fee*I12+Vq*I13 -> 19 | J14: $19.0 million
