Workbook

Sheet README
B1: DCT Laboratory — Vol I, Ch 8: Stochastic Enterprise Dynamics
B2: Seed 26108 · Companion to DCT_V1_Ch08_Lab.ipynb and AXIOM Lab 1.8 (module AXIOM-08). Money in $ million.
B4: Worked Example 8.1, Will the Digital Program Breach the Floor?, with the book's declarations, and the five steps of AXIOM Lab 1.8, Putting Odds on Meridian's Plan.
B5: Declarations: the plan, the two channels of uncertainty and the levers of Worked Example 8.1; Section 8.6's revenue deviation and Section 8.7's regulatory interventions.
B6: Plan: the plan quarter by quarter, the deviation's volatility budget, the closures' plan line and the mean path (Steps 1-2).
B7: Fan: the revenue fan's exact law, the volatility budget, the persistence sweep, and the two-reading Lyapunov equation (Theorems 8.2-8.3; Online Appendix 8.B.3-8.B.4; lab step 1).
B8: Compose: the program office's chain and the revenue fans compose (Chapman-Kolmogorov; Online Appendix 8.B.2; lab step 2).
B9: Events: the plan line and the risk line of an event risk, and memorylessness (Theorem 8.4; Figure 8.3; lab step 3).
B10: Averages: linear, convex and concave cases of the flaw of averages, and Proposition 8.5 (Theorem 8.5; Online Appendix 8.B.7; lab step 4).
B11: Odds: Table 8.5 from the book's 100,000 paths (seed 8), the reading of Step 4 and the decomposition of Online Appendix 8.B.6.
B12: Bench and Draws: 2,000 of the book's own paths rebuilt by formula from their draws: every scenario of Table 8.5 and the error bar as the paths accumulate, live under your declarations (lab step 5).
B13: ErrorBars: Section 8.9's error bars and the paths a precision needs (Online Appendix 8.B.5).
... B20: Cross-sheet link: green.

Sheet Declarations
A1: Declarations (Worked Example 8.1, Step 1; Sections 8.6 and 8.7). Money in $ million.
A3: Quantity | B3: Value | C3: Source
A4: Liquidity index today (Chapter 1) | B4: 100 | C4: Chapter 1's digital path; 100 = $620 million
A5: $ million per index point | B5: 6.2 | C5: Chapter 1: index 100 = $0.62 billion
A6: Index the plan relaxes toward | B6: 112 | C6: Chapter 1's digital option
A7: Relaxation rate a year | B7: 0.35
A8: Depth of the program's cash draw (index points) | B8: 28 | C8: the draw D (t/tau) e^(1 - t/tau)
A9: Years to the deepest draw, tau | B9: 2
A10: Liquidity today ($ million) | B10: =Idx_today*Usd_point -> 620 | C10: $620 million
A11: Board floor ($ million) | B11: 350 | C11: Table 5.4
A12: Board risk appetite: largest chance of breaching the floor | B12: 0.05 | C12: Worked Example 8.1: 5 percent during the program
A13: Program horizon (quarters) | B13: 12 | C13: three years
A14: Deviation carried into the next quarter, a | B14: 0.6 | C14: Step 1: 60 percent of a surprise
A15: Surprise a quarter: standard deviation | B15: 50 | C15: Step 1: execution and market deviation
A16: Funding-window closures a year, lambda | B16: 0.1 | C16: Step 1: about once a decade
A17: Closure size: mean | B17: 120 | C17: not recovered within the program
A18: Closure size: standard deviation | B18: 50
A19: Closure size: gamma shape, (mean / sd)^2 | B19: =(Close_mean/Close_sd)^2 -> 5.76 | C19: the book's engine draws gamma sizes with this mean and sd
A20: Closure size: gamma scale, sd^2 / mean | B20: =Close_sd^2/Close_mean -> 20.833333
A21: Standby line: most it replaces of any closure | B21: 100 | C21: Step 5
A22: Phased build: depth of the cash draw | B22: 20 | C22: Step 5: deepest draw $49 million smaller
A23: Paths simulated | B23: 100000 | C23: Step 3
A25: Section 8.6: Industrial Systems' quarterly revenue deviation from plan
A26: Persistence of the revenue deviation, a | B26: 0.7 | C26: R' = 0.7 R + w
A27: Revenue shock: standard deviation | B27: 15
A28: Deviation after a strong quarter, R0 | B28: 30 | C28: Figure 8.1
A29: Covenant test: shortfall below plan | B29: 45
A31: Section 8.7: regulatory interventions
A32: Regulatory interventions a year, lambda | B32: 0.15 | C32: about once every 6.7 years
A33: Intervention cost: mean | B33: 40
A34: Intervention cost: standard deviation | B34: 30
A36: Liquidity by quarter: L_k = plan_k + E_k - (closures to date), with E_k = a E_k-1 + w_k and closures arriving at lambda/4 a quarter. The plan is Chapter 1's digital index: target + (today - target) e^(-rate t) - depth (t/tau) e^(1 - t/tau), in $ million.

Sheet Plan
A1: Declare and size each channel: the plan, the deviation's budget, the closures' plan line (Worked Example 8.1, Steps 1-2)
A4: Quarter | B4: Years | C4: Plan index | D4: Plan ($ million) | E4: Phased index | F4: Phased plan | G4: Headroom above the floor | H4: Deviation sd (Theorem 8.3(i)) | I4: Headroom in sd | J4: Expected closures to date | K4: Mean path (Theorem 8.4(iii))
A5: 0 | B5: =A5/4 -> 0 | C5: =Idx_target+(Idx_today-Idx_target)*EXP(-Relax_rate*B5)-Draw_depth*(B5/Draw_tau)*EXP(1-B5/Draw_tau) -> 100 | D5: =Usd_point*C5 -> 620 | E5: =Idx_target+(Idx_today-Idx_target)*EXP(-Relax_rate*B5)-Depth_phased*(B5/Draw_tau)*EXP(1-B5/Draw_tau) -> 100 | F5: =Usd_point*E5 -> 620 | G5: =D5-Floor_L -> 270 | H5: =Shock_sd*SQRT((1-Persist_a^(2*A5))/(1-Persist_a^2)) -> 0 | J5: =Lam_c/4*A5*Close_mean -> 0 | K5: =D5-J5 -> 620
A6: 1 | B6: =A6/4 -> 0.25 | C6: =Idx_target+(Idx_today-Idx_target)*EXP(-Relax_rate*B6)-Draw_depth*(B6/Draw_tau)*EXP(1-B6/Draw_tau) -> 92.60931 | D6: =Usd_point*C6 -> 574.17772 | E6: =Idx_target+(Idx_today-Idx_target)*EXP(-Relax_rate*B6)-Depth_phased*(B6/Draw_tau)*EXP(1-B6/Draw_tau) -> 95.008185 | F6: =Usd_point*E6 -> 589.05075 | G6: =D6-Floor_L -> 224.17772 | H6: =Shock_sd*SQRT((1-Persist_a^(2*A6))/(1-Persist_a^2)) -> 50 | I6: =G6/H6 -> 4.4835544 | J6: =Lam_c/4*A6*Close_mean -> 3 | K6: =D6-J6 -> 571.17772
A7: 2 | B7: =A7/4 -> 0.5 | C7: =Idx_target+(Idx_today-Idx_target)*EXP(-Relax_rate*B7)-Draw_depth*(B7/Draw_tau)*EXP(1-B7/Draw_tau) -> 87.107516 | D7: =Usd_point*C7 -> 540.0666 | E7: =Idx_target+(Idx_today-Idx_target)*EXP(-Relax_rate*B7)-Depth_phased*(B7/Draw_tau)*EXP(1-B7/Draw_tau) -> 91.341516 | F7: =Usd_point*E7 -> 566.3174 | G7: =D7-Floor_L -> 190.0666 | H7: =Shock_sd*SQRT((1-Persist_a^(2*A7))/(1-Persist_a^2)) -> 58.309519 | I7: =G7/H7 -> 3.2596152 | J7: =Lam_c/4*A7*Close_mean -> 6 | K7: =D7-J7 -> 534.0666
A8: 3 | B8: =A8/4 -> 0.75 | C8: =Idx_target+(Idx_today-Idx_target)*EXP(-Relax_rate*B8)-Draw_depth*(B8/Draw_tau)*EXP(1-B8/Draw_tau) -> 83.153901 | D8: =Usd_point*C8 -> 515.55419 | E8: =Idx_target+(Idx_today-Idx_target)*EXP(-Relax_rate*B8)-Depth_phased*(B8/Draw_tau)*EXP(1-B8/Draw_tau) -> 88.758639 | F8: =Usd_point*E8 -> 550.30356 | G8: =D8-Floor_L -> 165.55419 | H8: =Shock_sd*SQRT((1-Persist_a^(2*A8))/(1-Persist_a^2)) -> 61.024585 | I8: =G8/H8 -> 2.7129097 | J8: =Lam_c/4*A8*Close_mean -> 9 | K8: =D8-J8 -> 506.55419
A9: 4 | B9: =A9/4 -> 1 | C9: =Idx_target+(Idx_today-Idx_target)*EXP(-Relax_rate*B9)-Draw_depth*(B9/Draw_tau)*EXP(1-B9/Draw_tau) -> 80.461645 | D9: =Usd_point*C9 -> 498.8622 | E9: =Idx_target+(Idx_today-Idx_target)*EXP(-Relax_rate*B9)-Depth_phased*(B9/Draw_tau)*EXP(1-B9/Draw_tau) -> 87.05653 | F9: =Usd_point*E9 -> 539.75049 | G9: =D9-Floor_L -> 148.8622 | H9: =Shock_sd*SQRT((1-Persist_a^(2*A9))/(1-Persist_a^2)) -> 61.972897 | I9: =G9/H9 -> 2.4020533 | J9: =Lam_c/4*A9*Close_mean -> 12 | K9: =D9-J9 -> 486.8622
A10: 5 | B10: =A10/4 -> 1.25 | C10: =Idx_target+(Idx_today-Idx_target)*EXP(-Relax_rate*B10)-Draw_depth*(B10/Draw_tau)*EXP(1-B10/Draw_tau) -> 78.789868 | D10: =Usd_point*C10 -> 488.49718 | E10: =Idx_target+(Idx_today-Idx_target)*EXP(-Relax_rate*B10)-Depth_phased*(B10/Draw_tau)*EXP(1-B10/Draw_tau) -> 86.064825 | F10: =Usd_point*E10 -> 533.60192 | G10: =D10-Floor_L -> 138.49718 | H10: =Shock_sd*SQRT((1-Persist_a^(2*A10))/(1-Persist_a^2)) -> 62.310757 | I10: =G10/H10 -> 2.222685 | J10: =Lam_c/4*A10*Close_mean -> 15 | K10: =D10-J10 -> 473.49718
A11: 6 | B11: =A11/4 -> 1.5 | C11: =Idx_target+(Idx_today-Idx_target)*EXP(-Relax_rate*B11)-Draw_depth*(B11/Draw_tau)*EXP(1-B11/Draw_tau) -> 77.936802 | D11: =Usd_point*C11 -> 483.20817 | E11: =Idx_target+(Idx_today-Idx_target)*EXP(-Relax_rate*B11)-Depth_phased*(B11/Draw_tau)*EXP(1-B11/Draw_tau) -> 85.640954 | F11: =Usd_point*E11 -> 530.97392 | G11: =D11-Floor_L -> 133.20817 | H11: =Shock_sd*SQRT((1-Persist_a^(2*A11))/(1-Persist_a^2)) -> 62.431938 | I11: =G11/H11 -> 2.1336543 | J11: =Lam_c/4*A11*Close_mean -> 18 | K11: =D11-J11 -> 465.20817
A12: 7 | B12: =A12/4 -> 1.75 | C12: =Idx_target+(Idx_today-Idx_target)*EXP(-Relax_rate*B12)-Draw_depth*(B12/Draw_tau)*EXP(1-B12/Draw_tau) -> 77.733933 | D12: =Usd_point*C12 -> 481.95038 | E12: =Idx_target+(Idx_today-Idx_target)*EXP(-Relax_rate*B12)-Depth_phased*(B12/Draw_tau)*EXP(1-B12/Draw_tau) -> 85.665972 | F12: =Usd_point*E12 -> 531.12903 | G12: =D12-Floor_L -> 131.95038 | H12: =Shock_sd*SQRT((1-Persist_a^(2*A12))/(1-Persist_a^2)) -> 62.475506 | I12: =G12/H12 -> 2.1120338 | J12: =Lam_c/4*A12*Close_mean -> 21 | K12: =D12-J12 -> 460.95038
A13: 8 | B13: =A13/4 -> 2 | C13: =Idx_target+(Idx_today-Idx_target)*EXP(-Relax_rate*B13)-Draw_depth*(B13/Draw_tau)*EXP(1-B13/Draw_tau) -> 78.040976 | D13: =Usd_point*C13 -> 483.85405 | E13: =Idx_target+(Idx_today-Idx_target)*EXP(-Relax_rate*B13)-Depth_phased*(B13/Draw_tau)*EXP(1-B13/Draw_tau) -> 86.040976 | F13: =Usd_point*E13 -> 533.45405 | G13: =D13-Floor_L -> 133.85405 | H13: =Shock_sd*SQRT((1-Persist_a^(2*A13))/(1-Persist_a^2)) -> 62.491183 | I13: =G13/H13 -> 2.141967 | J13: =Lam_c/4*A13*Close_mean -> 24 | K13: =D13-J13 -> 459.85405
A14: 9 | B14: =A14/4 -> 2.25 | C14: =Idx_target+(Idx_today-Idx_target)*EXP(-Relax_rate*B14)-Draw_depth*(B14/Draw_tau)*EXP(1-B14/Draw_tau) -> 78.741578 | D14: =Usd_point*C14 -> 488.19778 | E14: =Idx_target+(Idx_today-Idx_target)*EXP(-Relax_rate*B14)-Depth_phased*(B14/Draw_tau)*EXP(1-B14/Draw_tau) -> 86.68405 | F14: =Usd_point*E14 -> 537.44111 | G14: =D14-Floor_L -> 138.19778 | H14: =Shock_sd*SQRT((1-Persist_a^(2*A14))/(1-Persist_a^2)) -> 62.496826 | I14: =G14/H14 -> 2.2112768 | J14: =Lam_c/4*A14*Close_mean -> 27 | K14: =D14-J14 -> 461.19778
A15: 10 | B15: =A15/4 -> 2.5 | C15: =Idx_target+(Idx_today-Idx_target)*EXP(-Relax_rate*B15)-Draw_depth*(B15/Draw_tau)*EXP(1-B15/Draw_tau) -> 79.739628 | D15: =Usd_point*C15 -> 494.3857 | E15: =Idx_target+(Idx_today-Idx_target)*EXP(-Relax_rate*B15)-Depth_phased*(B15/Draw_tau)*EXP(1-B15/Draw_tau) -> 87.527636 | F15: =Usd_point*E15 -> 542.67134 | G15: =D15-Floor_L -> 144.3857 | H15: =Shock_sd*SQRT((1-Persist_a^(2*A15))/(1-Persist_a^2)) -> 62.498857 | I15: =G15/H15 -> 2.3102134 | J15: =Lam_c/4*A15*Close_mean -> 30 | K15: =D15-J15 -> 464.3857
A16: 11 | B16: =A16/4 -> 2.75 | C16: =Idx_target+(Idx_today-Idx_target)*EXP(-Relax_rate*B16)-Draw_depth*(B16/Draw_tau)*EXP(1-B16/Draw_tau) -> 80.956121 | D16: =Usd_point*C16 -> 501.92795 | E16: =Idx_target+(Idx_today-Idx_target)*EXP(-Relax_rate*B16)-Depth_phased*(B16/Draw_tau)*EXP(1-B16/Draw_tau) -> 88.516303 | F16: =Usd_point*E16 -> 548.80108 | G16: =D16-Floor_L -> 151.92795 | H16: =Shock_sd*SQRT((1-Persist_a^(2*A16))/(1-Persist_a^2)) -> 62.499589 | I16: =G16/H16 -> 2.4308632 | J16: =Lam_c/4*A16*Close_mean -> 33 | K16: =D16-J16 -> 468.92795
A17: 12 | B17: =A17/4 -> 3 | C17: =Idx_target+(Idx_today-Idx_target)*EXP(-Relax_rate*B17)-Draw_depth*(B17/Draw_tau)*EXP(1-B17/Draw_tau) -> 82.326459 | D17: =Usd_point*C17 -> 510.42405 | E17: =Idx_target+(Idx_today-Idx_target)*EXP(-Relax_rate*B17)-Depth_phased*(B17/Draw_tau)*EXP(1-B17/Draw_tau) -> 89.604827 | F17: =Usd_point*E17 -> 555.54993 | G17: =D17-Floor_L -> 160.42405 | H17: =Shock_sd*SQRT((1-Persist_a^(2*A17))/(1-Persist_a^2)) -> 62.499852 | I17: =G17/H17 -> 2.5667908 | J17: =Lam_c/4*A17*Close_mean -> 36 | K17: =D17-J17 -> 474.42405
A19: Steps 1-2 | B19: Value | C19: Reading
A20: Plan: trough ($ million) | B20: =MIN($D$5:$D$17) -> 481.95038 | C20: Step 1: $482 million
A21: Plan: quarter of the trough | B21: =MATCH(B20,$D$5:$D$17,0)-1 -> 7 | C21: quarter 7
A22: Plan: liquidity at the end of year 3 | B22: =D17 -> 510.42405 | C22: $510 million
A23: Headroom above the floor at the trough | B23: =B20-Floor_L -> 131.95038 | C23: $132 million
A24: Deviation's volatility budget, sd / sqrt(1 - a^2) | B24: =Shock_sd/SQRT(1-Persist_a^2) -> 62.5 | C24: Step 2: $62.5 million (Theorem 8.3(ii))
A25: Headroom at the trough in standard deviations | B25: =B23/B24 -> 2.1112061 | C25: only 2.1 standard deviations
A26: One quarter at the trough, deviation alone: Phi(-headroom / budget) | B26: =NORMSDIST(-B25) -> 0.0173773 | C26: a path has twelve quarters, and a second channel
A27: Closures: plan line, lambda E[J] ($ million a year) | B27: =Lam_c*Close_mean -> 12 | C27: Step 2: $12 million a year (Theorem 8.4(ii))
A28: Closures: risk line, lambda E[J^2] (variance a year) | B28: =Lam_c*(Close_mean^2+Close_sd^2) -> 1690
A29: Closures: chance of at least one in three years, 1 - e^(-3 lambda) | B29: =1-EXP(-Lam_c*Horizon_q/4) -> 0.25918178 | C29: Step 2: 26 percent
A30: Closures: chance of one by quarter 7 | B30: =1-EXP(-Lam_c*B21/4) -> 0.16054298
A31: Mean path: its trough (plan less the closures' plan line) | B31: =MIN($K$5:$K$17) -> 459.85405 | C31: Step 4: $460 million
A32: Mean path: quarter of its trough | B32: =MATCH(B31,$K$5:$K$17,0)-1 -> 8
A33: Phased build: trough | B33: =MIN($F$5:$F$17) -> 530.97392 | C33: Step 5: $531 million
A34: Deepest cash draw, plan as drawn | B34: =Liq_today-B20 -> 138.04962
A35: Deepest cash draw, phased build | B35: =Liq_today-B33 -> 89.026083
A36: Phasing makes the deepest draw smaller by | B36: =B34-B35 -> 49.023535 | C36: Step 5: $49 million

Sheet Fan
A1: Watch the fan form: Industrial Systems' revenue deviation (Theorems 8.2-8.3; Figures 8.1-8.2; Online Appendix 8.B.3-8.B.4; AXIOM Lab 1.8, step 1)
A3: The volatility budget | B3: Value | C3: Reading | J3: The saturator: persistence a | K3: Long-run sd | L3: Long-run chance of the shortfall | M3: sd after 40 quarters
A4: Long-run variance, sd^2 / (1 - a^2) | B4: =Rev_sd^2/(1-Rev_a^2) -> 441.17647 | C4: about 441 | J4: 0 | K4: =IF(J4<1,Rev_sd/SQRT(1-J4^2),"none") -> 15 | L4: =IF(J4<1,NORMSDIST(-Rev_cov/K4),"none") -> 0.001349898 | M4: =Rev_sd*SQRT(IF(J4<1,(1-J4^80)/(1-J4^2),40)) -> 15
A5: Volatility budget: the long-run standard deviation | B5: =SQRT(B4) -> 21.004201 | C5: $21 million, not $15 million | J5: 0.35 | K5: =IF(J5<1,Rev_sd/SQRT(1-J5^2),"none") -> 16.012815 | L5: =IF(J5<1,NORMSDIST(-Rev_cov/K5),"none") -> 0.0024751585 | M5: =Rev_sd*SQRT(IF(J5<1,(1-J5^80)/(1-J5^2),40)) -> 16.012815
A6: Persistence inflates the shock by 1 / sqrt(1 - a^2) | B6: =1/SQRT(1-Rev_a^2) -> 1.4002801 | C6: 1.40 | J6: 0.5 | K6: =IF(J6<1,Rev_sd/SQRT(1-J6^2),"none") -> 17.320508 | L6: =IF(J6<1,NORMSDIST(-Rev_cov/K6),"none") -> 0.0046873842 | M6: =Rev_sd*SQRT(IF(J6<1,(1-J6^80)/(1-J6^2),40)) -> 17.320508
A7: Long-run chance a quarter of a shortfall of 45 or more, Phi(-45/21) | B7: =NORMSDIST(-Rev_cov/B5) -> 0.016079507 | C7: 1.6 percent | J7: 0.7 | K7: =IF(J7<1,Rev_sd/SQRT(1-J7^2),"none") -> 21.004201 | L7: =IF(J7<1,NORMSDIST(-Rev_cov/K7),"none") -> 0.016079507 | M7: =Rev_sd*SQRT(IF(J7<1,(1-J7^80)/(1-J7^2),40)) -> 21.004201
A8: The same chance if persistence were ignored, Phi(-45/15) | B8: =NORMSDIST(-Rev_cov/Rev_sd) -> 0.001349898 | C8: 0.13 percent | J8: 0.9 | K8: =IF(J8<1,Rev_sd/SQRT(1-J8^2),"none") -> 34.41236 | L8: =IF(J8<1,NORMSDIST(-Rev_cov/K8),"none") -> 0.095492685 | M8: =Rev_sd*SQRT(IF(J8<1,(1-J8^80)/(1-J8^2),40)) -> 34.408601
A9: Halved persistence, a | B9: 0.35 | C9: Online Appendix 8.B.4 | J9: 0.95 | K9: =IF(J9<1,Rev_sd/SQRT(1-J9^2),"none") -> 48.038446 | L9: =IF(J9<1,NORMSDIST(-Rev_cov/K9),"none") -> 0.17444366 | M9: =Rev_sd*SQRT(IF(J9<1,(1-J9^80)/(1-J9^2),40)) -> 47.640108
A10: Its volatility budget | B10: =Rev_sd/SQRT(1-B9^2) -> 16.012815 | C10: $16.0 million | J10: 0.99 | K10: =IF(J10<1,Rev_sd/SQRT(1-J10^2),"none") -> 106.33218 | L10: =IF(J10<1,NORMSDIST(-Rev_cov/K10),"none") -> 0.33607391 | M10: =Rev_sd*SQRT(IF(J10<1,(1-J10^80)/(1-J10^2),40)) -> 79.035415
A11: Its chance of the shortfall a quarter | B11: =NORMSDIST(-Rev_cov/B10) -> 0.0024751585 | C11: 0.25 percent | J11: 1 | K11: =IF(J11<1,Rev_sd/SQRT(1-J11^2),"none") -> none | L11: =IF(J11<1,NORMSDIST(-Rev_cov/K11),"none") -> none | M11: =Rev_sd*SQRT(IF(J11<1,(1-J11^80)/(1-J11^2),40)) -> 94.86833
A12: How many times smaller | B12: =B7/B11 -> 6.4963546 | C12: sixfold, with no change in the market | J12: As a reaches one the band stops settling: with no restoring force it widens like 15 sqrt(k).
A14: Theorem 8.3(i): the law stays normal; its mean and variance follow exact recursions. From +30 the fan drifts back toward plan and widens until it settles (Figure 8.1); with a = 1 it never settles (Figure 8.2).
A15: Quarter k | B15: Mean, a^k R0 | C15: Variance, a^2 var + sd^2 | D15: Standard deviation | E15: Band: mean - 2 sd | F15: Band: mean + 2 sd | G15: Closed form of the variance | H15: No restoring force (a = 1): sd x sqrt(k) | J15: Online Appendix 8.B.3: two readings | K15: Value
A16: 0 | B16: =Rev_R0*Rev_a^A16 -> 30 | C16: 0 | D16: =SQRT(C16) -> 0 | E16: =B16-2*D16 -> 30 | F16: =B16+2*D16 -> 30 | G16: =Rev_sd^2*(1-Rev_a^(2*A16))/(1-Rev_a^2) -> 0 | H16: =Rev_sd*SQRT(A16) -> 0 | J16: a11 | K16: 0.8
A17: 1 | B17: =Rev_R0*Rev_a^A17 -> 21 | C17: =Rev_a^2*C16+Rev_sd^2 -> 225 | D17: =SQRT(C17) -> 15 | E17: =B17-2*D17 -> -9 | F17: =B17+2*D17 -> 51 | G17: =Rev_sd^2*(1-Rev_a^(2*A17))/(1-Rev_a^2) -> 225 | H17: =Rev_sd*SQRT(A17) -> 15 | J17: a12 | K17: 0.2
A18: 2 | B18: =Rev_R0*Rev_a^A18 -> 14.7 | C18: =Rev_a^2*C17+Rev_sd^2 -> 335.25 | D18: =SQRT(C18) -> 18.309833 | E18: =B18-2*D18 -> -21.919667 | F18: =B18+2*D18 -> 51.319667 | G18: =Rev_sd^2*(1-Rev_a^(2*A18))/(1-Rev_a^2) -> 335.25 | H18: =Rev_sd*SQRT(A18) -> 21.213203 | J18: a21 | K18: 0
A19: 3 | B19: =Rev_R0*Rev_a^A19 -> 10.29 | C19: =Rev_a^2*C18+Rev_sd^2 -> 389.2725 | D19: =SQRT(C19) -> 19.72999 | E19: =B19-2*D19 -> -29.16998 | F19: =B19+2*D19 -> 49.74998 | G19: =Rev_sd^2*(1-Rev_a^(2*A19))/(1-Rev_a^2) -> 389.2725 | H19: =Rev_sd*SQRT(A19) -> 25.980762 | J19: a22 | K19: 0.6
A20: 4 | B20: =Rev_R0*Rev_a^A20 -> 7.203 | C20: =Rev_a^2*C19+Rev_sd^2 -> 415.74352 | D20: =SQRT(C20) -> 20.38979 | E20: =B20-2*D20 -> -33.576579 | F20: =B20+2*D20 -> 47.982579 | G20: =Rev_sd^2*(1-Rev_a^(2*A20))/(1-Rev_a^2) -> 415.74352 | H20: =Rev_sd*SQRT(A20) -> 30 | J20: s11 | K20: 0.04
A21: 5 | B21: =Rev_R0*Rev_a^A21 -> 5.0421 | C21: =Rev_a^2*C20+Rev_sd^2 -> 428.71433 | D21: =SQRT(C21) -> 20.705418 | E21: =B21-2*D21 -> -36.368736 | F21: =B21+2*D21 -> 46.452936 | G21: =Rev_sd^2*(1-Rev_a^(2*A21))/(1-Rev_a^2) -> 428.71433 | H21: =Rev_sd*SQRT(A21) -> 33.54102 | J21: s22 | K21: 0.01
A22: 6 | B22: =Rev_R0*Rev_a^A22 -> 3.52947 | C22: =Rev_a^2*C21+Rev_sd^2 -> 435.07002 | D22: =SQRT(C22) -> 20.858332 | E22: =B22-2*D22 -> -38.187194 | F22: =B22+2*D22 -> 45.246134 | G22: =Rev_sd^2*(1-Rev_a^(2*A22))/(1-Rev_a^2) -> 435.07002 | H22: =Rev_sd*SQRT(A22) -> 36.742346 | J22: Closed form: sigma_22 = s22 / (1 - a22^2) | K22: =K21/(1-K19^2) -> 0.015625
A23: 7 | B23: =Rev_R0*Rev_a^A23 -> 2.470629 | C23: =Rev_a^2*C22+Rev_sd^2 -> 438.18431 | D23: =SQRT(C23) -> 20.932852 | E23: =B23-2*D23 -> -39.395076 | F23: =B23+2*D23 -> 44.336334 | G23: =Rev_sd^2*(1-Rev_a^(2*A23))/(1-Rev_a^2) -> 438.18431 | H23: =Rev_sd*SQRT(A23) -> 39.68627 | J23: Closed form: sigma_12 = a12 a22 sigma_22 / (1 - a11 a22) | K23: =K17*K19*K22/(1-K16*K19) -> 0.0036057692
A24: 8 | B24: =Rev_R0*Rev_a^A24 -> 1.7294403 | C24: =Rev_a^2*C23+Rev_sd^2 -> 439.71031 | D24: =SQRT(C24) -> 20.969271 | E24: =B24-2*D24 -> -40.209101 | F24: =B24+2*D24 -> 43.667982 | G24: =Rev_sd^2*(1-Rev_a^(2*A24))/(1-Rev_a^2) -> 439.71031 | H24: =Rev_sd*SQRT(A24) -> 42.426407 | J24: Closed form: sigma_11 = (2 a11 a12 sigma_12 + a12^2 sigma_22 + s11) / (1 - a11^2) | K24: =(2*K16*K17*K23+K17^2*K22+K20)/(1-K16^2) -> 0.11605235
A25: 9 | B25: =Rev_R0*Rev_a^A25 -> 1.2106082 | C25: =Rev_a^2*C24+Rev_sd^2 -> 440.45805 | D25: =SQRT(C25) -> 20.987093 | E25: =B25-2*D25 -> -40.763577 | F25: =B25+2*D25 -> 43.184793 | G25: =Rev_sd^2*(1-Rev_a^(2*A25))/(1-Rev_a^2) -> 440.45805 | H25: =Rev_sd*SQRT(A25) -> 45 | J25: Long-run sd of the first reading | K25: =SQRT(K24) -> 0.34066457
A26: 10 | B26: =Rev_R0*Rev_a^A26 -> 0.84742575 | C26: =Rev_a^2*C25+Rev_sd^2 -> 440.82445 | D26: =SQRT(C26) -> 20.99582 | E26: =B26-2*D26 -> -41.144214 | F26: =B26+2*D26 -> 42.839065 | G26: =Rev_sd^2*(1-Rev_a^(2*A26))/(1-Rev_a^2) -> 440.82445 | H26: =Rev_sd*SQRT(A26) -> 47.434165 | J26: Long-run sd of the second reading | K26: =SQRT(K22) -> 0.125
A27: 11 | B27: =Rev_R0*Rev_a^A27 -> 0.59319802 | C27: =Rev_a^2*C26+Rev_sd^2 -> 441.00398 | D27: =SQRT(C27) -> 21.000095 | E27: =B27-2*D27 -> -41.406991 | F27: =B27+2*D27 -> 42.593387 | G27: =Rev_sd^2*(1-Rev_a^(2*A27))/(1-Rev_a^2) -> 441.00398 | H27: =Rev_sd*SQRT(A27) -> 49.749372 | J27: The iteration below after 60 periods: sigma_11 | K27: =L90 -> 0.11605235
A28: 12 | B28: =Rev_R0*Rev_a^A28 -> 0.41523862 | C28: =Rev_a^2*C27+Rev_sd^2 -> 441.09195 | D28: =SQRT(C28) -> 21.002189 | E28: =B28-2*D28 -> -41.58914 | F28: =B28+2*D28 -> 42.419617 | G28: =Rev_sd^2*(1-Rev_a^(2*A28))/(1-Rev_a^2) -> 441.09195 | H28: =Rev_sd*SQRT(A28) -> 51.961524 | J28: Largest gap between the iteration and the closed form | K28: =MAX(ABS(L90-K24),ABS(M90-K23),ABS(N90-K22)) -> 3.2615577e-13
A29: 13 | B29: =Rev_R0*Rev_a^A29 -> 0.29066703 | C29: =Rev_a^2*C28+Rev_sd^2 -> 441.13506 | D29: =SQRT(C29) -> 21.003215 | E29: =B29-2*D29 -> -41.715764 | F29: =B29+2*D29 -> 42.297098 | G29: =Rev_sd^2*(1-Rev_a^(2*A29))/(1-Rev_a^2) -> 441.13506 | H29: =Rev_sd*SQRT(A29) -> 54.083269 | K29: Period | L29: sigma_11 | M29: sigma_12 | N29: sigma_22
A30: 14 | B30: =Rev_R0*Rev_a^A30 -> 0.20346692 | C30: =Rev_a^2*C29+Rev_sd^2 -> 441.15618 | D30: =SQRT(C30) -> 21.003718 | E30: =B30-2*D30 -> -41.803969 | F30: =B30+2*D30 -> 42.210903 | G30: =Rev_sd^2*(1-Rev_a^(2*A30))/(1-Rev_a^2) -> 441.15618 | H30: =Rev_sd*SQRT(A30) -> 56.124861 | K30: 0 | L30: 0 | M30: 0 | N30: 0
A31: 15 | B31: =Rev_R0*Rev_a^A31 -> 0.14242685 | C31: =Rev_a^2*C30+Rev_sd^2 -> 441.16653 | D31: =SQRT(C31) -> 21.003965 | E31: =B31-2*D31 -> -41.865502 | F31: =B31+2*D31 -> 42.150356 | G31: =Rev_sd^2*(1-Rev_a^(2*A31))/(1-Rev_a^2) -> 441.16653 | H31: =Rev_sd*SQRT(A31) -> 58.09475 | K31: 1 | L31: =$K$16^2*L30+2*$K$16*$K$17*M30+$K$17^2*N30+$K$20 -> 0.04 | M31: =$K$16*$K$18*L30+($K$16*$K$19+$K$17*$K$18)*M30+$K$17*$K$19*N30 -> 0 | N31: =$K$18^2*L30+2*$K$18*$K$19*M30+$K$19^2*N30+$K$21 -> 0.01
A32: 16 | B32: =Rev_R0*Rev_a^A32 -> 0.099698792 | C32: =Rev_a^2*C31+Rev_sd^2 -> 441.1716 | D32: =SQRT(C32) -> 21.004085 | E32: =B32-2*D32 -> -41.908472 | F32: =B32+2*D32 -> 42.107869 | G32: =Rev_sd^2*(1-Rev_a^(2*A32))/(1-Rev_a^2) -> 441.1716 | H32: =Rev_sd*SQRT(A32) -> 60 | K32: 2 | L32: =$K$16^2*L31+2*$K$16*$K$17*M31+$K$17^2*N31+$K$20 -> 0.066 | M32: =$K$16*$K$18*L31+($K$16*$K$19+$K$17*$K$18)*M31+$K$17*$K$19*N31 -> 0.0012 | N32: =$K$18^2*L31+2*$K$18*$K$19*M31+$K$19^2*N31+$K$21 -> 0.0136
A33: 17 | B33: =Rev_R0*Rev_a^A33 -> 0.069789154 | C33: =Rev_a^2*C32+Rev_sd^2 -> 441.17408 | D33: =SQRT(C33) -> 21.004144 | E33: =B33-2*D33 -> -41.9385 | F33: =B33+2*D33 -> 42.078078 | G33: =Rev_sd^2*(1-Rev_a^(2*A33))/(1-Rev_a^2) -> 441.17408 | H33: =Rev_sd*SQRT(A33) -> 61.846584 | K33: 3 | L33: =$K$16^2*L32+2*$K$16*$K$17*M32+$K$17^2*N32+$K$20 -> 0.083168 | M33: =$K$16*$K$18*L32+($K$16*$K$19+$K$17*$K$18)*M32+$K$17*$K$19*N32 -> 0.002208 | N33: =$K$18^2*L32+2*$K$18*$K$19*M32+$K$19^2*N32+$K$21 -> 0.014896
A34: 18 | B34: =Rev_R0*Rev_a^A34 -> 0.048852408 | C34: =Rev_a^2*C33+Rev_sd^2 -> 441.1753 | D34: =SQRT(C34) -> 21.004173 | E34: =B34-2*D34 -> -41.959494 | F34: =B34+2*D34 -> 42.057199 | G34: =Rev_sd^2*(1-Rev_a^(2*A34))/(1-Rev_a^2) -> 441.1753 | H34: =Rev_sd*SQRT(A34) -> 63.63961 | K34: 4 | L34: =$K$16^2*L33+2*$K$16*$K$17*M33+$K$17^2*N33+$K$20 -> 0.09452992 | M34: =$K$16*$K$18*L33+($K$16*$K$19+$K$17*$K$18)*M33+$K$17*$K$19*N33 -> 0.00284736 | N34: =$K$18^2*L33+2*$K$18*$K$19*M33+$K$19^2*N33+$K$21 -> 0.01536256
A35: 19 | B35: =Rev_R0*Rev_a^A35 -> 0.034196686 | C35: =Rev_a^2*C34+Rev_sd^2 -> 441.1759 | D35: =SQRT(C35) -> 21.004188 | E35: =B35-2*D35 -> -41.974179 | F35: =B35+2*D35 -> 42.042572 | G35: =Rev_sd^2*(1-Rev_a^(2*A35))/(1-Rev_a^2) -> 441.1759 | H35: =Rev_sd*SQRT(A35) -> 65.383484 | K35: 5 | L35: =$K$16^2*L34+2*$K$16*$K$17*M34+$K$17^2*N34+$K$20 -> 0.10202481 | M35: =$K$16*$K$18*L34+($K$16*$K$19+$K$17*$K$18)*M34+$K$17*$K$19*N34 -> 0.00321024 | N35: =$K$18^2*L34+2*$K$18*$K$19*M34+$K$19^2*N34+$K$21 -> 0.015530522
A36: 20 | B36: =Rev_R0*Rev_a^A36 -> 0.02393768 | C36: =Rev_a^2*C35+Rev_sd^2 -> 441.17619 | D36: =SQRT(C36) -> 21.004195 | E36: =B36-2*D36 -> -41.984451 | F36: =B36+2*D36 -> 42.032327 | G36: =Rev_sd^2*(1-Rev_a^(2*A36))/(1-Rev_a^2) -> 441.17619 | H36: =Rev_sd*SQRT(A36) -> 67.082039 | K36: 6 | L36: =$K$16^2*L35+2*$K$16*$K$17*M35+$K$17^2*N35+$K$20 -> 0.10694437 | M36: =$K$16*$K$18*L35+($K$16*$K$19+$K$17*$K$18)*M35+$K$17*$K$19*N35 -> 0.0034045778 | N36: =$K$18^2*L35+2*$K$18*$K$19*M35+$K$19^2*N35+$K$21 -> 0.015590988
A37: 21 | B37: =Rev_R0*Rev_a^A37 -> 0.016756376 | C37: =Rev_a^2*C36+Rev_sd^2 -> 441.17633 | D37: =SQRT(C37) -> 21.004198 | E37: =B37-2*D37 -> -41.99164 | F37: =B37+2*D37 -> 42.025152 | G37: =Rev_sd^2*(1-Rev_a^(2*A37))/(1-Rev_a^2) -> 441.17633 | H37: =Rev_sd*SQRT(A37) -> 68.738635 | K37: 7 | L37: =$K$16^2*L36+2*$K$16*$K$17*M36+$K$17^2*N36+$K$20 -> 0.1101575 | M37: =$K$16*$K$18*L36+($K$16*$K$19+$K$17*$K$18)*M36+$K$17*$K$19*N36 -> 0.0035051159 | N37: =$K$18^2*L36+2*$K$18*$K$19*M36+$K$19^2*N36+$K$21 -> 0.015612756
A38: 22 | B38: =Rev_R0*Rev_a^A38 -> 0.011729463 | C38: =Rev_a^2*C37+Rev_sd^2 -> 441.1764 | D38: =SQRT(C38) -> 21.0042 | E38: =B38-2*D38 -> -41.99667 | F38: =B38+2*D38 -> 42.020129 | G38: =Rev_sd^2*(1-Rev_a^(2*A38))/(1-Rev_a^2) -> 441.1764 | H38: =Rev_sd*SQRT(A38) -> 70.356236 | K38: 8 | L38: =$K$16^2*L37+2*$K$16*$K$17*M37+$K$17^2*N37+$K$20 -> 0.11224695 | M38: =$K$16*$K$18*L37+($K$16*$K$19+$K$17*$K$18)*M37+$K$17*$K$19*N37 -> 0.0035559863 | N38: =$K$18^2*L37+2*$K$18*$K$19*M37+$K$19^2*N37+$K$21 -> 0.015620592
A39: 23 | B39: =Rev_R0*Rev_a^A39 -> 0.0082106242 | C39: =Rev_a^2*C38+Rev_sd^2 -> 441.17644 | D39: =SQRT(C39) -> 21.0042 | E39: =B39-2*D39 -> -42.00019 | F39: =B39+2*D39 -> 42.016612 | G39: =Rev_sd^2*(1-Rev_a^(2*A39))/(1-Rev_a^2) -> 441.17644 | H39: =Rev_sd*SQRT(A39) -> 71.937473 | K39: 9 | L39: =$K$16^2*L38+2*$K$16*$K$17*M38+$K$17^2*N38+$K$20 -> 0.11360079 | M39: =$K$16*$K$18*L38+($K$16*$K$19+$K$17*$K$18)*M38+$K$17*$K$19*N38 -> 0.0035813445 | N39: =$K$18^2*L38+2*$K$18*$K$19*M38+$K$19^2*N38+$K$21 -> 0.015623413
A40: 24 | B40: =Rev_R0*Rev_a^A40 -> 0.0057474369 | C40: =Rev_a^2*C39+Rev_sd^2 -> 441.17645 | D40: =SQRT(C40) -> 21.004201 | E40: =B40-2*D40 -> -42.002654 | F40: =B40+2*D40 -> 42.014149 | G40: =Rev_sd^2*(1-Rev_a^(2*A40))/(1-Rev_a^2) -> 441.17645 | H40: =Rev_sd*SQRT(A40) -> 73.484692 | K40: 10 | L40: =$K$16^2*L39+2*$K$16*$K$17*M39+$K$17^2*N39+$K$20 -> 0.11447547 | M40: =$K$16*$K$18*L39+($K$16*$K$19+$K$17*$K$18)*M39+$K$17*$K$19*N39 -> 0.0035938549 | N40: =$K$18^2*L39+2*$K$18*$K$19*M39+$K$19^2*N39+$K$21 -> 0.015624429
A41: 25 | B41: =Rev_R0*Rev_a^A41 -> 0.0040232059 | C41: =Rev_a^2*C40+Rev_sd^2 -> 441.17646 | D41: =SQRT(C41) -> 21.004201 | E41: =B41-2*D41 -> -42.004379 | F41: =B41+2*D41 -> 42.012425 | G41: =Rev_sd^2*(1-Rev_a^(2*A41))/(1-Rev_a^2) -> 441.17646 | H41: =Rev_sd*SQRT(A41) -> 75 | K41: 11 | L41: =$K$16^2*L40+2*$K$16*$K$17*M40+$K$17^2*N40+$K$20 -> 0.11503931 | M41: =$K$16*$K$18*L40+($K$16*$K$19+$K$17*$K$18)*M40+$K$17*$K$19*N40 -> 0.0035999818 | N41: =$K$18^2*L40+2*$K$18*$K$19*M40+$K$19^2*N40+$K$21 -> 0.015624794
A42: 26 | B42: =Rev_R0*Rev_a^A42 -> 0.0028162441 | C42: =Rev_a^2*C41+Rev_sd^2 -> 441.17647 | D42: =SQRT(C42) -> 21.004201 | E42: =B42-2*D42 -> -42.005586 | F42: =B42+2*D42 -> 42.011219 | G42: =Rev_sd^2*(1-Rev_a^(2*A42))/(1-Rev_a^2) -> 441.17647 | H42: =Rev_sd*SQRT(A42) -> 76.485293 | K42: 12 | L42: =$K$16^2*L41+2*$K$16*$K$17*M41+$K$17^2*N41+$K$20 -> 0.11540215 | M42: =$K$16*$K$18*L41+($K$16*$K$19+$K$17*$K$18)*M41+$K$17*$K$19*N41 -> 0.0036029666 | N42: =$K$18^2*L41+2*$K$18*$K$19*M41+$K$19^2*N41+$K$21 -> 0.015624926
...

Sheet Compose
A1: Check the multi-year view: Chapman-Kolmogorov (Theorem 8.2(ii); Online Appendix 8.B.2; AXIOM Lab 1.8, step 2)
A2: The program office classifies each quarter as on plan or off plan. Multi-quarter odds must pass through every intermediate state: P^(j+k) = P^j P^k.
A4: One quarter, P | B4: to on plan | C4: to off plan | F4: Revenue fans compose (Section 8.6's deviation) | G4: Value | H4: Reading
A5: from on plan | B5: 0.9 | C5: =1-B5 -> 0.1 | F5: One-year fan: the mean's factor, a^4 | G5: =Rev_a^4 -> 0.2401
A6: from off plan | B6: 0.3 | C6: =1-B6 -> 0.7 | F6: One-year fan: variance, sd^2 (1 - a^8) / (1 - a^2) | G6: =Rev_sd^2*(1-Rev_a^8)/(1-Rev_a^2) -> 415.74352
F7: One-year fan: standard deviation | G7: =SQRT(G6) -> 20.38979
A8: Two quarters, P^2 = P P | B8: to on plan | C8: to off plan | F8: Three one-year fans compounded: the mean's factor | G8: =G5^3 -> 0.013841287
A9: from on plan | B9: =B5*B5+C5*B6 -> 0.84 | C9: =B5*C5+C5*C6 -> 0.16 | F9: Three one-year fans compounded: variance, v (1 + a^8 + a^16) | G9: =G6*(1+G5^2+G5^4) -> 441.09195
A10: from off plan | B10: =B6*B5+C6*B6 -> 0.48 | C10: =B6*C5+C6*C6 -> 0.52 | F10: The three-year fan directly: the mean's factor, a^12 | G10: =Rev_a^12 -> 0.013841287
F11: The three-year fan directly: variance, sd^2 (1 - a^24) / (1 - a^2) | G11: =Rev_sd^2*(1-Rev_a^24)/(1-Rev_a^2) -> 441.09195
A12: Three quarters, P^3 = P^2 P | B12: to on plan | C12: to off plan | F12: Gap between compounded and direct variance | G12: =ABS(G9-G11) -> 0 | H12: they compose
A13: from on plan | B13: =B9*B5+C9*B6 -> 0.804 | C13: =B9*C5+C9*C6 -> 0.196 | F13: A three-year fan stretched by the square-root law, sqrt(3) x one-year sd | G13: =SQRT(3)*G7 -> 35.316152 | H13: not this model's: it ignores the restoring force
A14: from off plan | B14: =B10*B5+C10*B6 -> 0.588 | C14: =B10*C5+C10*C6 -> 0.412 | F14: The model's three-year sd | G14: =SQRT(G11) -> 21.002189
A16: Three quarters, P P^2 | B16: to on plan | C16: to off plan
A17: from on plan | B17: =B5*B9+C5*B10 -> 0.804 | C17: =B5*C9+C5*C10 -> 0.196
A18: from off plan | B18: =B6*B9+C6*B10 -> 0.588 | C18: =B6*C9+C6*C10 -> 0.412
A20: Chapman-Kolmogorov: largest gap between P^2 P and P P^2 | B20: =MAX(ABS(B13-B17),ABS(C13-C17),ABS(B14-B18),ABS(C14-C18)) -> 0 | C20: they compose
A21: Off plan three quarters after being on plan | B21: =C13 -> 0.196 | C21: 19.6 percent
A22: A planning pack's three-quarter figure | B22: 0.3 | C22: Online Appendix 8.B.2
A23: Is the pack consistent with its own one-quarter view? | B23: =IF(ABS(B22-B21)<0.0005,"yes","no: the one-quarter view implies "&TEXT(B21,"0.0%")) -> no: the one-quarter view implies 19.6%
A24: Long-run share of quarters on plan, P(off to on) / (P(on to off) + P(off to on)) | B24: =B6/(C5+B6) -> 0.75 | C24: 0.75
A25: Average on-plan spell (quarters), 1 / P(on to off) | B25: =1/C5 -> 10 | C25: 10 quarters
A26: Average off-plan spell (quarters), 1 / P(off to on) | B26: =1/B6 -> 3.3333333 | C26: 3.3 quarters
A28: Quarter k, from on plan | B28: On plan | C28: Off plan
A29: 0 | B29: 1 | C29: 0
A30: 1 | B30: =B29*$B$5+C29*$B$6 -> 0.9 | C30: =B29*$C$5+C29*$C$6 -> 0.1
A31: 2 | B31: =B30*$B$5+C30*$B$6 -> 0.84 | C31: =B30*$C$5+C30*$C$6 -> 0.16
A32: 3 | B32: =B31*$B$5+C31*$B$6 -> 0.804 | C32: =B31*$C$5+C31*$C$6 -> 0.196
A33: 4 | B33: =B32*$B$5+C32*$B$6 -> 0.7824 | C33: =B32*$C$5+C32*$C$6 -> 0.2176
A34: 5 | B34: =B33*$B$5+C33*$B$6 -> 0.76944 | C34: =B33*$C$5+C33*$C$6 -> 0.23056
A35: 6 | B35: =B34*$B$5+C34*$B$6 -> 0.761664 | C35: =B34*$C$5+C34*$C$6 -> 0.238336
A36: 7 | B36: =B35*$B$5+C35*$B$6 -> 0.7569984 | C36: =B35*$C$5+C35*$C$6 -> 0.2430016
A37: 8 | B37: =B36*$B$5+C36*$B$6 -> 0.75419904 | C37: =B36*$C$5+C36*$C$6 -> 0.24580096
A38: 9 | B38: =B37*$B$5+C37*$B$6 -> 0.75251942 | C38: =B37*$C$5+C37*$C$6 -> 0.24748058
A39: 10 | B39: =B38*$B$5+C38*$B$6 -> 0.75151165 | C39: =B38*$C$5+C38*$C$6 -> 0.24848835
A40: 11 | B40: =B39*$B$5+C39*$B$6 -> 0.75090699 | C40: =B39*$C$5+C39*$C$6 -> 0.24909301
A41: 12 | B41: =B40*$B$5+C40*$B$6 -> 0.7505442 | C41: =B40*$C$5+C40*$C$6 -> 0.2494558

Sheet Events
A1: Price an event risk: two ledger lines (Theorem 8.4; Figure 8.3; AXIOM Lab 1.8, step 3)
A3: Regulatory interventions (Section 8.7) | B3: Value | C3: Reading
A4: E[J^2] = mean^2 + sd^2 | B4: =Reg_mean^2+Reg_sd^2 -> 2500 | C4: 2,500
A5: Plan line, lambda E[J] ($ million a year) | B5: =Reg_lam*Reg_mean -> 6 | C5: $6 million a year, quiet years included
A6: Risk line, lambda E[J^2] (variance a year) | B6: =Reg_lam*B4 -> 375 | C6: 375 a year
A7: Standard deviation over one year | B7: =SQRT(B6) -> 19.364917 | C7: about $19 million
A8: Standard deviation over five years | B8: =SQRT(5*B6) -> 43.30127 | C8: about $43 million
A9: Mean wait between interventions (years) | B9: =1/Reg_lam -> 6.6666667 | C9: about 6.7 years
A10: Chance of an intervention next year, 1 - e^(-lambda) | B10: =1-EXP(-Reg_lam) -> 0.13929202 | C10: 14 percent
A11: After five quiet years: 1 - P(quiet six years) / P(quiet five years) | B11: =1-EXP(-6*Reg_lam)/EXP(-5*Reg_lam) -> 0.13929202 | C11: the same: an event is never due (Theorem 8.4(i))
A12: Chance of at least one in five years | B12: =1-EXP(-5*Reg_lam) -> 0.52763345
A13: Half the frequency, twice the size: plan line | B13: =(Reg_lam/2)*(2*Reg_mean) -> 6 | C13: unchanged
A14: Half the frequency, twice the size: variance a year | B14: =(Reg_lam/2)*4*B4 -> 750 | C14: doubled
A15: Cost law: gamma shape, (mean / sd)^2 | B15: =(Reg_mean/Reg_sd)^2 -> 1.7777778
A16: Cost law: gamma scale, sd^2 / mean | B16: =Reg_sd^2/Reg_mean -> 22.5
A18: Funding-window closures (Worked Example 8.1, Step 2) | B18: Value | C18: Reading
A19: Plan line, lambda E[J] ($ million a year) | B19: =Lam_c*Close_mean -> 12 | C19: $12 million a year
A20: Risk line, lambda E[J^2] (variance a year) | B20: =Lam_c*(Close_mean^2+Close_sd^2) -> 1690
A21: Standard deviation over one year | B21: =SQRT(B20) -> 41.10961
A22: Chance of at least one closure in three years | B22: =1-EXP(-Lam_c*Horizon_q/4) -> 0.25918178 | C22: 26 percent
A25: Years | B25: Plan line | C25: Standard deviation | D25: Risk band: low | E25: Risk band: high
A26: 0 | B26: =Reg_lam*Reg_mean*A26 -> 0 | C26: =SQRT($B$6*A26) -> 0 | D26: =MAX(B26-2*C26,0) -> 0 | E26: =B26+2*C26 -> 0
A27: 0.5 | B27: =Reg_lam*Reg_mean*A27 -> 3 | C27: =SQRT($B$6*A27) -> 13.693064 | D27: =MAX(B27-2*C27,0) -> 0 | E27: =B27+2*C27 -> 30.386128
A28: 1 | B28: =Reg_lam*Reg_mean*A28 -> 6 | C28: =SQRT($B$6*A28) -> 19.364917 | D28: =MAX(B28-2*C28,0) -> 0 | E28: =B28+2*C28 -> 44.729833
A29: 1.5 | B29: =Reg_lam*Reg_mean*A29 -> 9 | C29: =SQRT($B$6*A29) -> 23.717082 | D29: =MAX(B29-2*C29,0) -> 0 | E29: =B29+2*C29 -> 56.434165
A30: 2 | B30: =Reg_lam*Reg_mean*A30 -> 12 | C30: =SQRT($B$6*A30) -> 27.386128 | D30: =MAX(B30-2*C30,0) -> 0 | E30: =B30+2*C30 -> 66.772256
A31: 2.5 | B31: =Reg_lam*Reg_mean*A31 -> 15 | C31: =SQRT($B$6*A31) -> 30.618622 | D31: =MAX(B31-2*C31,0) -> 0 | E31: =B31+2*C31 -> 76.237244
A32: 3 | B32: =Reg_lam*Reg_mean*A32 -> 18 | C32: =SQRT($B$6*A32) -> 33.54102 | D32: =MAX(B32-2*C32,0) -> 0 | E32: =B32+2*C32 -> 85.082039
A33: 3.5 | B33: =Reg_lam*Reg_mean*A33 -> 21 | C33: =SQRT($B$6*A33) -> 36.228442 | D33: =MAX(B33-2*C33,0) -> 0 | E33: =B33+2*C33 -> 93.456884
A34: 4 | B34: =Reg_lam*Reg_mean*A34 -> 24 | C34: =SQRT($B$6*A34) -> 38.729833 | D34: =MAX(B34-2*C34,0) -> 0 | E34: =B34+2*C34 -> 101.45967
A35: 4.5 | B35: =Reg_lam*Reg_mean*A35 -> 27 | C35: =SQRT($B$6*A35) -> 41.079192 | D35: =MAX(B35-2*C35,0) -> 0 | E35: =B35+2*C35 -> 109.15838
A36: 5 | B36: =Reg_lam*Reg_mean*A36 -> 30 | C36: =SQRT($B$6*A36) -> 43.30127 | D36: =MAX(B36-2*C36,0) -> 0 | E36: =B36+2*C36 -> 116.60254
A37: 5.5 | B37: =Reg_lam*Reg_mean*A37 -> 33 | C37: =SQRT($B$6*A37) -> 45.414755 | D37: =MAX(B37-2*C37,0) -> 0 | E37: =B37+2*C37 -> 123.82951
... A46: 10 | B46: =Reg_lam*Reg_mean*A46 -> 60 | C46: =SQRT($B$6*A46) -> 61.237244 | D46: =MAX(B46-2*C46,0) -> 0 | E46: =B46+2*C46 -> 182.47449
A48: Figure 8.3: the plan line accrues through quiet years and eventful ones alike; the risk band widens with the square root of time.

Sheet Averages
A1: Feel the flaw of averages (Theorem 8.5; Proposition 8.5; Online Appendix 8.B.7; AXIOM Lab 1.8, step 4)
A3: Linear: Worked Example 4.1's Unit A (Table 4.5) | B3: Legacy | C3: Software | D3: Total
A4: year 0 | B4: 400 | C4: 100 | D4: =B4+C4 -> 500 | F4: legacy engineers stay legacy | G4: 0.92
A5: year 1 | B5: =$G$4*B4 -> 368 | C5: =$G$6*C4+$G$5*B4 -> 108 | D5: =B5+C5 -> 476 | F5: legacy engineers retrained into software | G5: 0.03
A6: year 2 | B6: =$G$4*B5 -> 338.56 | C6: =$G$6*C5+$G$5*B5 -> 114.72 | D6: =B6+C6 -> 453.28 | F6: software engineers stay | G6: 0.96
A7: year 3 | B7: =$G$4*B6 -> 311.4752 | C7: =$G$6*C6+$G$5*B6 -> 120.288 | D7: =B7+C7 -> 431.7632
A8: year 4 | B8: =$G$4*B7 -> 286.55718 | C8: =$G$6*C7+$G$5*B7 -> 124.82074 | D8: =B8+C8 -> 411.37792
A9: year 5 | B9: =$G$4*B8 -> 263.63261 | C9: =$G$6*C8+$G$5*B8 -> 128.42462 | D9: =B9+C9 -> 392.05723
A10: Theorem 8.5(i): with random attrition restored, the mean workforce follows this roll-up exactly.
A12: Convex: Online Appendix 8.B.7's start-up | B12: Value | C12: Reading
A13: Growth near zero, r (a year) | B13: 0.9
A14: Demand volatility, sigma (a year) | B14: 0.6
A16: Years t | B16: Mean factor, e^(r t) | C16: Median factor, e^((r - sigma^2/2) t) | D16: Mean less median | E16: Paths below the mean, Phi(sigma sqrt(t) / 2)
A17: 1 | B17: =EXP($B$13*A17) -> 2.4596031 | C17: =EXP(($B$13-$B$14^2/2)*A17) -> 2.0544332 | D17: =B17-C17 -> 0.4051699 | E17: =NORMSDIST($B$14*SQRT(A17)/2) -> 0.61791142
A18: 2 | B18: =EXP($B$13*A18) -> 6.0496475 | C18: =EXP(($B$13-$B$14^2/2)*A18) -> 4.2206958 | D18: =B18-C18 -> 1.8289516 | E18: =NORMSDIST($B$14*SQRT(A18)/2) -> 0.66431338
A20: Bend the function: sigma | B20: Mean factor, one year | C20: Median factor | D20: Mean less median | E20: Paths below the mean
A21: 0 | B21: =EXP($B$13) -> 2.4596031 | C21: =EXP($B$13-A21^2/2) -> 2.4596031 | D21: =B21-C21 -> 0 | E21: =NORMSDIST(A21/2) -> 0.5
A22: 0.2 | B22: =EXP($B$13) -> 2.4596031 | C22: =EXP($B$13-A22^2/2) -> 2.4108997 | D22: =B22-C22 -> 0.048703405 | E22: =NORMSDIST(A22/2) -> 0.53982784
A23: 0.4 | B23: =EXP($B$13) -> 2.4596031 | C23: =EXP($B$13-A23^2/2) -> 2.2704998 | D23: =B23-C23 -> 0.18910327 | E23: =NORMSDIST(A23/2) -> 0.57925971
A24: 0.6 | B24: =EXP($B$13) -> 2.4596031 | C24: =EXP($B$13-A24^2/2) -> 2.0544332 | D24: =B24-C24 -> 0.4051699 | E24: =NORMSDIST(A24/2) -> 0.61791142
A25: 0.8 | B25: =EXP($B$13) -> 2.4596031 | C25: =EXP($B$13-A25^2/2) -> 1.7860384 | D25: =B25-C25 -> 0.67356468 | E25: =NORMSDIST(A25/2) -> 0.65542174
A26: The exponential is convex: the average of the outcomes runs ahead of the outcome at average inputs (the median), and the gap widens as the function bends; with no spread it closes (Proposition 8.3).
A28: Concave: Worked Example 8.1's trough | B28: Value | C28: Reading
A29: The plan's trough (Plan sheet) | B29: =Plan!B20 -> 481.95038 | C29: $482 million
A30: The mean path's trough (Plan sheet) | B30: =Plan!B31 -> 459.85405 | C30: $460 million
A31: The average of the path troughs (engine: the book's 100,000 paths, seed 8) | B31: 383.83151 | C31: $384 million
A32: The average trough lies below the plan's by | B32: =B29-B31 -> 98.11887 | C32: almost $100 million
A33: and below the mean path's trough by (Jensen: the low point is concave) | B33: =B30-B31 -> 76.022541
A35: Proposition 8.5: inherited spread | B35: Sensitivity L | C35: Steps | D35: Spread multiplied by up to L^(2k)
A36: three expansive steps | B36: 1.2 | C36: 3 | D36: =B36^(2*C36) -> 2.985984
A37: three consolidating steps | B37: 0.8 | C37: 3 | D37: =B37^(2*C37) -> 0.262144

Sheet Odds
A1: Read the answer and test the levers: Table 8.5 on the book's 100,000 paths (Worked Example 8.1, Steps 3-5; Online Appendix 8.B.6)
A2: Breach probabilities are engine values: the book's 100,000 paths, drawn with seed 8. Standard errors, troughs, the appetite test and the decomposition are formulas.
A4: Scenario (Table 8.5) | B4: Plan trough ($ million) | C4: Breach probability (engine, seed 8) | D4: Standard error, sqrt(p (1 - p) / N) | E4: Within the 5% appetite? | F4: Share of the plan's risk
A5: Plan as drawn, both channels | B5: =Plan!B20 -> 481.95038 | C5: 0.24622 | D5: =SQRT(C5*(1-C5)/N_paths) -> 0.0013623352 | E5: =IF(C5<=Appetite_p,"yes","no") -> no | F5: =C5/$C$5 -> 1
A6: Execution and market deviation only | B6: =Plan!B20 -> 481.95038 | C6: 0.08403 | D6: =SQRT(C6*(1-C6)/N_paths) -> 0.00087731955 | E6: =IF(C6<=Appetite_p,"yes","no") -> no | F6: =C6/$C$5 -> 0.34128016
A7: Funding-window events only | B7: =Plan!B20 -> 481.95038 | C7: 0.10619 | D7: =SQRT(C7*(1-C7)/N_paths) -> 0.00097423654 | E7: =IF(C7<=Appetite_p,"yes","no") -> no | F7: =C7/$C$5 -> 0.43128097
A8: Standby line (up to $100 million per closure) | B8: =Plan!B20 -> 481.95038 | C8: 0.12374 | D8: =SQRT(C8*(1-C8)/N_paths) -> 0.0010412896 | E8: =IF(C8<=Appetite_p,"yes","no") -> no | F8: =C8/$C$5 -> 0.50255869
A9: Phased build | B9: =Plan!B33 -> 530.97392 | C9: 0.13068 | D9: =SQRT(C9*(1-C9)/N_paths) -> 0.0010658459 | E9: =IF(C9<=Appetite_p,"yes","no") -> no | F9: =C9/$C$5 -> 0.53074486
A10: Standby line and phased build | B10: =Plan!B33 -> 530.97392 | C10: 0.03003 | D10: =SQRT(C10*(1-C10)/N_paths) -> 0.00053970547 | E10: =IF(C10<=Appetite_p,"yes","no") -> yes | F10: =C10/$C$5 -> 0.1219641
A12: Smallest standard error in the table | B12: =MIN(D5:D10) -> 0.00053970547 | C12: 0.05 percentage points
A13: Largest standard error in the table | B13: =MAX(D5:D10) -> 0.0013623352 | C13: 0.14 percentage points
A14: The two channels compound: together less the sum of each alone | B14: =C5-(C6+C7) -> 0.056 | C14: 8.4 + 10.6 < 24.6
A16: Read the answer (Step 4) | B16: Value | C16: Reading
A17: Planned trough (Plan sheet) | B17: =Plan!B20 -> 481.95038 | C17: $482 million
A18: The mean path's trough, exact (Plan sheet) | B18: =Plan!B31 -> 459.85405 | C18: $460 million
A19: The mean path's trough, simulated (engine, seed 8) | B19: 459.94151
A20: The average of the path troughs (engine, seed 8) | B20: 383.83151 | C20: $384 million
A21: The median path trough (engine, seed 8) | B21: 399.00265
A22: The average trough's shortfall from the plan's | B22: =B17-B20 -> 98.11887 | C22: almost $100 million
A24: Where the risk comes from (Online Appendix 8.B.6) | B24: Value | C24: Reading
A25: Paths with at least one closure (engine, seed 8) | B25: 0.25912 | C25: 25.9 percent
A26: Breach probability on those paths (engine) | B26: 0.70901513 | C26: 70.9 percent
A27: Breach probability on the others (engine) | B27: 0.08435914 | C27: 8.4 percent
A28: Total probability, pe p1 + (1 - pe) p0 | B28: =B25*B26+(1-B25)*B27 -> 0.24622 | C28: 0.246
A29: Share of breaches on paths with a closure, pe p1 / total | B29: =B25*B26/B28 -> 0.74616197 | C29: three in four
A30: Variance of the breach indicator, p (1 - p) | B30: =B28*(1-B28) -> 0.18559571 | C30: 0.186
A31: Within the two scenarios, pe p1 (1 - p1) + (1 - pe) p0 (1 - p0) | B31: =B25*B26*(1-B26)+(1-B25)*B27*(1-B27) -> 0.11068729 | C31: 0.111
A32: Between them, pe p1^2 + (1 - pe) p0^2 - p^2 | B32: =B25*B26^2+(1-B25)*B27^2-B28^2 -> 0.074908417 | C32: 0.075
A33: Share of the uncertainty that is whether a window closes | B33: =B32/B30 -> 0.40361071 | C33: 40 percent
A34: Check: within + between - total (Theorem 8.5(iii)) | B34: =B31+B32-B30 -> 0 | C34: zero

Sheet ErrorBars
A1: Vary the number of paths: the Monte Carlo error bar (Section 8.9; Online Appendix 8.B.5; AXIOM Lab 1.8, step 5)
A2: Estimates are engine values. The book's engine draws Section 8.9's three runs from their own streams, seeds 100 + N, and the worked example's 100,000 paths with seed 8.
A4: Paths N | B4: Seed (the book's engine) | C4: Estimate (engine) | D4: Standard error, sqrt(p (1 - p) / N) | E4: As printed
A5: 100 | B5: 200 | C5: 0.25 | D5: =SQRT(C5*(1-C5)/A5) -> 0.04330127 | E5: 25.0 ± 4.3
A6: 1000 | B6: 1100 | C6: 0.252 | D6: =SQRT(C6*(1-C6)/A6) -> 0.013729385 | E6: 25.2 ± 1.4
A7: 10000 | B7: 10100 | C7: 0.2449 | D7: =SQRT(C7*(1-C7)/A7) -> 0.0043002789 | E7: 24.5 ± 0.4
A8: 100000 | B8: 8 | C8: 0.24622 | D8: =SQRT(C8*(1-C8)/A8) -> 0.0013623352 | E8: 24.6, standard error 0.14
A10: Paths needed for a given error bar (Online Appendix 8.B.5) | B10: Value | C10: Reading
A11: Target standard error (one standard error, as a probability) | B11: 0.001 | C11: ±0.1 percentage point
A12: Paths needed near 5 percent, p (1 - p) / h^2 | B12: =0.05*0.95/B11^2 -> 47500 | C12: 47,500
A13: Paths needed near 25 percent | B13: =0.25*0.75/B11^2 -> 187500 | C13: 187,500
A14: One more decimal digit near 25 percent (h ten times smaller) | B14: =0.25*0.75/(B11/10)^2 -> 18750000 | C14: a hundredfold more paths

Sheet Draws
A1: The book's draws for the first 2,000 of its 100,000 paths (seed 8; engine values)
A2: z: the standard-normal surprises, quarter by quarter (the surprise is Shock_sd x z). Closure sizes ($ million) sit in the quarter they occur; a second column holds a second closure in the same quarter.
A4: Path | B4: z, q1 | C4: z, q2 | D4: z, q3 | E4: z, q4 | F4: z, q5 | G4: z, q6 | H4: z, q7 | I4: z, q8 | J4: z, q9 | K4: z, q10 | L4: z, q11 | M4: z, q12 | N4: Closure, q1 | O4: Closure, q2 | P4: Closure, q3 | Q4: Closure, q4 | R4: Closure, q5 | S4: Closure, q6 | T4: Closure, q7 | U4: Closure, q8 | V4: Closure, q9 | W4: Closure, q10 | X4: Closure, q11 | Y4: Closure, q12 | Z4: Second closure, q1 | AA4: Second closure, q2 | AB4: Second closure, q3 | AC4: Second closure, q4 | AD4: Second closure, q5 | AE4: Second closure, q6 | AF4: Second closure, q7 | AG4: Second closure, q8 | AH4: Second closure, q9 | AI4: Second closure, q10 | AJ4: Second closure, q11 | AK4: Second closure, q12
A5: 1 | B5: -1.7382664 | C5: -0.82354848 | D5: -0.260355 | E5: 0.58003543 | F5: 0.39911725 | G5: 2.2397873 | H5: -1.6917165 | I5: 0.29064117 | J5: -0.25269694 | K5: -0.0038833029 | L5: -0.3314423 | M5: 0.19350898 | V5: 116.26108
A6: 2 | B6: -1.3366428 | C6: -0.37969574 | D6: 0.68583911 | E6: 0.094085308 | F6: -0.054433325 | G6: 0.24535199 | H6: 1.2694226 | I6: 1.7533354 | J6: -0.98926548 | K6: -0.109239 | L6: 0.0017784229 | M6: 1.8297928
A7: 3 | B7: -1.3611067 | C7: -0.47413661 | D7: -0.87410914 | E7: 0.88459358 | F7: 0.42193529 | G7: -0.097711412 | H7: 2.0083556 | I7: -0.93889505 | J7: 0.21739186 | K7: -0.62781602 | L7: 0.66395739 | M7: 0.48929768 | W7: 88.73281
A8: 4 | B8: -0.35161713 | C8: -0.62123296 | D8: -1.1304902 | E8: 0.47792809 | F8: 1.0791084 | G8: -0.540004 | H8: 0.1843355 | I8: -0.36632148 | J8: 0.57479984 | K8: 0.94028261 | L8: -0.49384752 | M8: -0.058988741 | N8: 242.21484 | S8: 191.90951
A9: 5 | B9: -2.3125816 | C9: -0.87614562 | D9: 0.93472852 | E9: -0.91880822 | F9: -1.3538016 | G9: 1.0648268 | H9: -0.93036908 | I9: -0.81867701 | J9: -0.055544515 | K9: -0.33018557 | L9: -0.69210995 | M9: 0.27694639 | W9: 121.3002
A10: 6 | B10: -0.1888972 | C10: -0.82533463 | D10: 0.30435955 | E10: -1.0721117 | F10: 0.66908494 | G10: 0.66902029 | H10: 1.1400032 | I10: 0.77146776 | J10: -0.16495414 | K10: -0.15968186 | L10: 0.87990375 | M10: 0.070628452
A11: 7 | B11: -0.95722923 | C11: -1.0672263 | D11: 0.2747212 | E11: 0.21965761 | F11: -0.30603106 | G11: 0.2047837 | H11: -1.1257261 | I11: 0.22742389 | J11: -0.48652824 | K11: 0.79164028 | L11: 1.2303926 | M11: 0.63443749
A12: 8 | B12: 0.89360018 | C12: 1.5250506 | D12: -0.68604652 | E12: -0.87387587 | F12: -0.3056738 | G12: 0.12389298 | H12: -2.2931936 | I12: -0.39625968 | J12: -1.8088382 | K12: 0.16336043 | L12: 0.044452162 | M12: -0.4224667
A13: 9 | B13: 0.95684724 | C13: 1.5077485 | D13: 0.3038741 | E13: -0.5135625 | F13: -1.0482989 | G13: 0.99306082 | H13: -1.1221842 | I13: 0.12935058 | J13: -2.138555 | K13: -0.43363242 | L13: -1.2567893 | M13: 0.066334075
A14: 10 | B14: 1.3922582 | C14: -1.3722239 | D14: -1.3042378 | E14: -0.10477064 | F14: 1.0991665 | G14: 0.63781842 | H14: -0.67154445 | I14: 0.25731684 | J14: -0.68029507 | K14: 0.59353547 | L14: -0.22170183 | M14: 0.24815753
A15: 11 | B15: 0.76747011 | C15: -0.077507253 | D15: 1.0386132 | E15: -0.32818491 | F15: -0.58810705 | G15: 0.82239353 | H15: 0.086859798 | I15: -0.32775401 | J15: -1.0491233 | K15: 0.80530676 | L15: -0.585731 | M15: 0.17807018
A16: 12 | B16: -0.053029779 | C16: 0.38113762 | D16: 0.46539649 | E16: -0.26218292 | F16: 0.26255152 | G16: 1.2008831 | H16: 0.67385642 | I16: 0.45998436 | J16: 0.4114858 | K16: -0.26510618 | L16: -0.64598428 | M16: -1.3876461
A17: 13 | B17: 0.85979399 | C17: 0.66308316 | D17: -0.7522352 | E17: -0.84303665 | F17: 0.24448566 | G17: -0.18732032 | H17: -0.31006908 | I17: 0.67072159 | J17: -2.1103327 | K17: -1.0434403 | L17: 0.29247632 | M17: 0.69959199
A18: 14 | B18: 1.5054812 | C18: -0.43000558 | D18: 1.1410548 | E18: -1.1704546 | F18: -0.44465808 | G18: -0.38983784 | H18: 0.4719034 | I18: 0.97754161 | J18: -0.17388993 | K18: 1.755042 | L18: 0.32249052 | M18: 1.6437302
A19: 15 | B19: -0.65359453 | C19: 2.0188191 | D19: 1.0849329 | E19: 1.240262 | F19: -0.25307014 | G19: 0.48033246 | H19: -2.5271262 | I19: -0.4857648 | J19: -0.37904747 | K19: -0.094517476 | L19: -1.1994537 | M19: 0.84774565
A20: 16 | B20: 0.61035115 | C20: -0.32466212 | D20: 0.79434645 | E20: -0.40295322 | F20: 1.3729986 | G20: 0.88558477 | H20: -0.94336273 | I20: 2.0379258 | J20: -1.1897635 | K20: 0.78192832 | L20: 0.80578312 | M20: 0.3404807
A21: 17 | B21: -0.042673828 | C21: -0.5630373 | D21: -0.13080358 | E21: -0.35924693 | F21: -1.5251637 | G21: 0.36219806 | H21: 0.88436379 | I21: 0.3302539 | J21: 0.12722571 | K21: -0.26124176 | L21: 0.25097073 | M21: -1.7728565 | O21: 119.1164
A22: 18 | B22: 1.4400167 | C22: -1.0890433 | D22: 0.22779655 | E22: -0.22804724 | F22: -2.4002723 | G22: 0.50640216 | H22: -1.64674 | I22: 0.69228697 | J22: -0.9551003 | K22: -0.68057258 | L22: -0.79265371 | M22: -1.1080133
A23: 19 | B23: -0.83689502 | C23: -1.0016606 | D23: -1.3915319 | E23: -0.70471875 | F23: -0.27245839 | G23: -0.73536568 | H23: 0.48552357 | I23: 0.30292571 | J23: 0.74853127 | K23: -0.32809109 | L23: 1.3771913 | M23: 1.6131651
A24: 20 | B24: -0.30154661 | C24: -0.11306953 | D24: 1.5105408 | E24: -0.29865809 | F24: 0.54457046 | G24: 0.30640137 | H24: 0.22318232 | I24: -0.97404823 | J24: 0.43662899 | K24: -0.65568106 | L24: -0.74524536 | M24: 0.43836252
A25: 21 | B25: 0.36233859 | C25: 1.9546318 | D25: 0.70190004 | E25: 0.39762501 | F25: 0.22293001 | G25: 0.40561143 | H25: -0.1845148 | I25: -0.1606567 | J25: -0.27792924 | K25: 0.0035503185 | L25: -0.90803813 | M25: -1.2909422
A26: 22 | B26: 0.25811027 | C26: -0.05397466 | D26: 1.7459191 | E26: -0.48652664 | F26: 0.34512086 | G26: 0.62232344 | H26: 0.23298265 | I26: 1.0745317 | J26: -1.9230197 | K26: 1.0045463 | L26: -1.203042 | M26: -1.4001582 | O26: 157.21491
A27: 23 | B27: -1.639448 | C27: 0.36678993 | D27: -1.1217563 | E27: -1.1237523 | F27: 1.2377084 | G27: -0.9297783 | H27: -1.1205419 | I27: 0.77799023 | J27: 0.25830389 | K27: -1.4494293 | L27: 0.67129266 | M27: -0.24631105 | V27: 153.98212
A28: 24 | B28: 0.36015523 | C28: 0.85419272 | D28: 0.63797579 | E28: -1.6359479 | F28: 1.7179789 | G28: 0.61457506 | H28: 1.7040148 | I28: -1.1403921 | J28: 0.1039524 | K28: 0.27259031 | L28: -1.0154444 | M28: 0.45951136
A29: 25 | B29: -0.1184977 | C29: -1.3740505 | D29: 0.38244054 | E29: 1.8541291 | F29: 0.49033217 | G29: 2.3680212 | H29: -0.29925692 | I29: 0.6473022 | J29: 1.3048395 | K29: 1.5237408 | L29: 0.22880407 | M29: 1.4236186
A30: 26 | B30: -0.23974785 | C30: 0.84302651 | D30: -1.0076405 | E30: -0.2831061 | F30: -0.081591593 | G30: -0.60018208 | H30: -0.11625101 | I30: 0.29907574 | J30: 0.013173403 | K30: 0.53337239 | L30: 1.008456 | M30: 0.047877677
A31: 27 | B31: -0.15530166 | C31: 0.72121568 | D31: 1.1621103 | E31: -0.2607464 | F31: 1.0603844 | G31: -0.59688367 | H31: 0.20824279 | I31: 0.40997668 | J31: 3.1078846 | K31: -0.72604556 | L31: 1.3605644 | M31: -0.98204664
A32: 28 | B32: 0.21897171 | C32: -0.78340534 | D32: -0.79754202 | E32: -1.413726 | F32: 0.90146322 | G32: -0.62790777 | H32: 0.67381484 | I32: 0.26772388 | J32: -1.2986298 | K32: 0.25872484 | L32: -1.4566989 | M32: 0.30404282
A33: 29 | B33: -1.8163957 | C33: -0.31130444 | D33: 1.1071456 | E33: 0.64439487 | F33: -0.29172936 | G33: 1.166719 | H33: 0.16746234 | I33: 1.7995766 | J33: 0.38116882 | K33: -1.9143578 | L33: -0.87649229 | M33: 0.85689462
A34: 30 | B34: 1.5524666 | C34: 0.37600302 | D34: 0.28053956 | E34: 2.8309372 | F34: -0.65534255 | G34: -0.95454852 | H34: -1.5595603 | I34: 1.704306 | J34: 1.2067336 | K34: -2.6940877 | L34: -0.53945225 | M34: 2.7250905 | P34: 97.768573
A35: 31 | B35: -0.86144167 | C35: -1.036497 | D35: 1.7702363 | E35: -1.502233 | F35: -0.0066420739 | G35: 0.62314378 | H35: 0.70873886 | I35: -0.16780939 | J35: -0.77419047 | K35: 0.99190686 | L35: 1.2697079 | M35: -0.57828347
A36: 32 | B36: -2.2413679 | C36: -0.85749016 | D36: -0.65750104 | E36: -0.6456761 | F36: -0.65716711 | G36: -0.42925551 | H36: -0.79016307 | I36: 0.35268544 | J36: -1.2458507 | K36: -1.235833 | L36: 0.67753752 | M36: -0.21228045
A37: 33 | B37: -0.081974494 | C37: 1.3308017 | D37: -0.398613 | E37: -1.7936664 | F37: 0.13398024 | G37: -0.892404 | H37: -0.66361908 | I37: 0.43630047 | J37: -0.91677659 | K37: 0.20890049 | L37: 0.7887748 | M37: -1.0398757
A38: 34 | B38: 1.4574804 | C38: -0.72183961 | D38: -1.0042238 | E38: 2.2535116 | F38: 0.37766057 | G38: 0.694244 | H38: -0.21520048 | I38: 0.052689716 | J38: 1.591159 | K38: -0.25638344 | L38: -0.57244242 | M38: -1.4520774
A39: 35 | B39: -0.51860097 | C39: -0.73988894 | D39: -0.59120598 | E39: 0.35526562 | F39: -0.6556499 | G39: 0.035765795 | H39: -1.1056791 | I39: 0.61378888 | J39: 0.17885325 | K39: 0.15291506 | L39: -0.5592773 | M39: 1.0392428
A40: 36 | B40: 1.5512756 | C40: 1.0842411 | D40: 0.81950349 | E40: 0.34937313 | F40: -0.29416549 | G40: 0.05590571 | H40: 0.066272981 | I40: 1.4037748 | J40: 0.30564624 | K40: -0.061429556 | L40: 0.1069347 | M40: 0.56979732
A41: 37 | B41: 1.556942 | C41: -0.69835256 | D41: 0.52785454 | E41: -0.51916736 | F41: -0.94925876 | G41: -1.3446473 | H41: -1.0518601 | I41: -0.12100124 | J41: -0.048027386 | K41: -1.3482858 | L41: -1.0315833 | M41: -2.0022432
...

Sheet Bench
A1: Put odds on the program: 2,000 of the book's paths, rebuilt by formula (Worked Example 8.1, Steps 3-5; AXIOM Lab 1.8, step 5)
A2: Each row is one of the first 2,000 of the book's 100,000 paths (seed 8); its draws are on Draws. E_k = a E_k-1 + Shock_sd z_k; closures to date J_k, and net of the standby line; liquidity = plan + E + J. Change the floor, the persistence, the surprise, the line or the phasing on Declarations and every scenario recomputes.
A4: Scenario | B4: Breaches on these paths | C4: Breach probability | D4: Standard error | E4: The engine on the same paths | F4: The book's 100,000 paths (Table 8.5)
A5: Plan as drawn, both channels | B5: =COUNTIF($AL$26:$AL$2025,"<"&Floor_L) -> 521 | C5: =B5/2000 -> 0.2605 | D5: =SQRT(C5*(1-C5)/2000) -> 0.0098142689 | E5: 521 | F5: =Odds!C5 -> 0.24622
A6: Execution and market deviation only | B6: =COUNTIF($AM$26:$AM$2025,"<"&Floor_L) -> 180 | C6: =B6/2000 -> 0.09 | D6: =SQRT(C6*(1-C6)/2000) -> 0.0063992187 | E6: 180 | F6: =Odds!C6 -> 0.08403
A7: Funding-window events only | B7: =COUNTIF($AN$26:$AN$2025,"<"&Floor_L) -> 232 | C7: =B7/2000 -> 0.116 | D7: =SQRT(C7*(1-C7)/2000) -> 0.0071604469 | E7: 232 | F7: =Odds!C7 -> 0.10619
A8: Standby line (up to $100 million per closure) | B8: =COUNTIF($AO$26:$AO$2025,"<"&Floor_L) -> 267 | C8: =B8/2000 -> 0.1335 | D8: =SQRT(C8*(1-C8)/2000) -> 0.0076051874 | E8: 267 | F8: =Odds!C8 -> 0.12374
A9: Phased build | B9: =COUNTIF($AP$26:$AP$2025,"<"&Floor_L) -> 268 | C9: =B9/2000 -> 0.134 | D9: =SQRT(C9*(1-C9)/2000) -> 0.0076172173 | E9: 268 | F9: =Odds!C9 -> 0.13068
A10: Standby line and phased build | B10: =COUNTIF($AQ$26:$AQ$2025,"<"&Floor_L) -> 61 | C10: =B10/2000 -> 0.0305 | D10: =SQRT(C10*(1-C10)/2000) -> 0.0038451105 | E10: 61 | F10: =Odds!C10 -> 0.03003
A12: Paths with at least one closure | B12: =COUNTIF($AR$26:$AR$2025,1) -> 529 | C12: =B12/2000 -> 0.2645 | E12: 529
A13: Breaches on paths with a closure (plan as drawn) | B13: =COUNTIFS($AR$26:$AR$2025,1,$AL$26:$AL$2025,"<"&Floor_L) -> 380 | C13: =B13/B5 -> 0.7293666 | E13: 380
A15: Watch the error bar shrink: the first N paths | B15: Breaches | C15: Estimate | D15: Standard error | E15: The engine on the same paths | F15: 95% interval: low | G15: 95% interval: high
A16: 100 | B16: =COUNTIFS($A$26:$A$2025,"<="&A16,$AL$26:$AL$2025,"<"&Floor_L) -> 26 | C16: =B16/A16 -> 0.26 | D16: =SQRT(C16*(1-C16)/A16) -> 0.043863424 | E16: 26 | F16: =C16-1.96*D16 -> 0.17402769 | G16: =C16+1.96*D16 -> 0.34597231
A17: 250 | B17: =COUNTIFS($A$26:$A$2025,"<="&A17,$AL$26:$AL$2025,"<"&Floor_L) -> 70 | C17: =B17/A17 -> 0.28 | D17: =SQRT(C17*(1-C17)/A17) -> 0.028397183 | E17: 70 | F17: =C17-1.96*D17 -> 0.22434152 | G17: =C17+1.96*D17 -> 0.33565848
A18: 500 | B18: =COUNTIFS($A$26:$A$2025,"<="&A18,$AL$26:$AL$2025,"<"&Floor_L) -> 133 | C18: =B18/A18 -> 0.266 | D18: =SQRT(C18*(1-C18)/A18) -> 0.019760769 | E18: 133 | F18: =C18-1.96*D18 -> 0.22726889 | G18: =C18+1.96*D18 -> 0.30473111
A19: 1000 | B19: =COUNTIFS($A$26:$A$2025,"<="&A19,$AL$26:$AL$2025,"<"&Floor_L) -> 261 | C19: =B19/A19 -> 0.261 | D19: =SQRT(C19*(1-C19)/A19) -> 0.013888088 | E19: 261 | F19: =C19-1.96*D19 -> 0.23377935 | G19: =C19+1.96*D19 -> 0.28822065
A20: 2000 | B20: =COUNTIFS($A$26:$A$2025,"<="&A20,$AL$26:$AL$2025,"<"&Floor_L) -> 521 | C20: =B20/A20 -> 0.2605 | D20: =SQRT(C20*(1-C20)/A20) -> 0.0098142689 | E20: 521 | F20: =C20-1.96*D20 -> 0.24126403 | G20: =C20+1.96*D20 -> 0.27973597
A22: Plan, quarters 1-12 ($ million) | B22: =Plan!D6 -> 574.17772 | C22: =Plan!D7 -> 540.0666 | D22: =Plan!D8 -> 515.55419 | E22: =Plan!D9 -> 498.8622 | F22: =Plan!D10 -> 488.49718 | G22: =Plan!D11 -> 483.20817 | H22: =Plan!D12 -> 481.95038 | I22: =Plan!D13 -> 483.85405 | J22: =Plan!D14 -> 488.19778 | K22: =Plan!D15 -> 494.3857 | L22: =Plan!D16 -> 501.92795 | M22: =Plan!D17 -> 510.42405
A23: Phased plan, quarters 1-12 | B23: =Plan!F6 -> 589.05075 | C23: =Plan!F7 -> 566.3174 | D23: =Plan!F8 -> 550.30356 | E23: =Plan!F9 -> 539.75049 | F23: =Plan!F10 -> 533.60192 | G23: =Plan!F11 -> 530.97392 | H23: =Plan!F12 -> 531.12903 | I23: =Plan!F13 -> 533.45405 | J23: =Plan!F14 -> 537.44111 | K23: =Plan!F15 -> 542.67134 | L23: =Plan!F16 -> 548.80108 | M23: =Plan!F17 -> 555.54993
A25: Path | B25: E_1 | C25: E_2 | D25: E_3 | E25: E_4 | F25: E_5 | G25: E_6 | H25: E_7 | I25: E_8 | J25: E_9 | K25: E_10 | L25: E_11 | M25: E_12 | N25: J_1 | O25: J_2 | P25: J_3 | Q25: J_4 | R25: J_5 | S25: J_6 | T25: J_7 | U25: J_8 | V25: J_9 | W25: J_10 | X25: J_11 | Y25: J_12 | Z25: J_1, with the line | AA25: J_2, with the line | AB25: J_3, with the line | AC25: J_4, with the line | AD25: J_5, with the line | AE25: J_6, with the line | AF25: J_7, with the line | AG25: J_8, with the line | AH25: J_9, with the line | AI25: J_10, with the line | AJ25: J_11, with the line | AK25: J_12, with the line | AL25: Trough: both channels | AM25: Trough: deviation only | AN25: Trough: events only | AO25: Trough: standby line | AP25: Trough: phased build | AQ25: Trough: line and phasing | AR25: A closure?
