Workbook

Sheet README
B1: DCT Laboratory — Vol II, Ch 4: Nonlinear and Mixed-Integer Enterprise Optimization
B2: Seed 26204 · Companion to DCT_V2_Ch04_Lab.ipynb and AXIOM Lab 2.4 (module AXIOM-04). Money in $ million, undiscounted.
B4: Worked Example 4.1, Can Meridian Automate Part of a Line?, with the book's declarations: partial rounds, twenty years' credit for the year-6 savings.
B5: Declarations: the inputs of Step 1. Plans: the partial-round model for any plan (yours included), with its liquidity, its floors and its value in Chapter 3's relaxation.
B6: Schedules: the 64 plans of whole rounds, their marginal values and the corner test: three strict local maxima.
B7: Face: years 4 and 5 vary (AXIOM Lab 2.4, step 1): two peaks, the saddle at (0.75, 0.84) and its curvature.
B8: Multistart: the inventory of 100 local searches (step 2), from the notebook's engine.
B9: Audit: multipliers, residuals, LICQ and the reduced Hessian (step 3). Prices: the local prices of Step 3.
B10: Relaxation: Chapter 3's ceiling in closed form and each answer's distance from it (step 4).
B11: BranchAndBound: every node of the twenty-year and ten-year trees solved exactly by formulas (step 5).
B12: Credit: Step 6, the credit at which the best number of rounds changes. Cap: the $60m cap and its price list.
B13: Package: Worked Example 1.1's package by branch-and-bound (Section 4.5), breach odds from the engine.
... B20: Cross-sheet link: green.

Sheet Declarations
A1: Declarations (Worked Example 4.1, Step 1). Money in $ million, undiscounted; rounds as fractions of a round.
A3: Quantity | B3: Value | C3: Source
A4: Cost of a whole round | B4: 120 | C4: Volume I, Worked Example 6.1
A5: Operational efficiency today | B5: 71
A6: Efficiency ceiling | B6: 85
A7: Efficiency gap today (points) | B7: =B6-B5 -> 14 | C7: 14 points
A8: Savings a year per point of efficiency gained | B8: 10 | C8: From the year of the round on
A9: Share of the remaining gap a whole round closes | B9: 0.5 | C9: A fraction z of a round closes the fraction z/2 (the chief operating officer)
A10: Liquidity today | B10: 620
A11: Floor, after paying for a round and at each year end | B11: 350 | C11: The board
A12: End condition: liquidity at the end of year 6 | B12: 470 | C12: Cash for another round
A13: Credit for the year-6 savings (years) | B13: 20 | C13: The expected life of the automated lines
A14: Ten years' credit (Chapters 2 and 3) | B14: 10 | C14: For the comparisons at ten years
A15: Savings a year with the gap closed | B15: =B8*B7 -> 140 | C15: 140
A16: Cash above the end condition today | B16: =B10-B12 -> 150 | C16: 150: paid out if no round runs
A17: Chapter 3's relaxation: gap kept per round, 1 - share | B17: =1-B9 -> 0.5 | C17: Gap after Z rounds: 14 x 0.5^Z (agrees at whole rounds)
A18: Chapter 3's relaxation: slope of its savings at Z = 0 | B18: =-B15*LN(B17) -> 97.040605 | C18: 140 ln 2 = 97.04; the slope at Z is this times 0.5^Z
A20: Payouts are free and can wait, so the floors never bind: a plan z of rounds is worth V(z) = 150 + sum of S_k - 120 sum of z_k + credit x S_6, with S_k = 140 - 10 x gap_k.
A21: The gap after year k is 14 x the product of (1 - z_j/2) over j <= k: Volume I's recursion read for fractions, identical at whole rounds.

Sheet Plans
A1: The partial-round model: any plan of rounds (Worked Example 4.1, Step 1; Proposition 4.2(i))
A2: Each row is a plan z of rounds by year. Payouts deferred to year 6: liquidity and the smallest slack in the floors and the end condition. Columns AD-AK value the same plan in Chapter 3's relaxation (a ceiling).
A4: Plan | B4: z1 | C4: z2 | D4: z3 | E4: z4 | F4: z5 | G4: z6 | H4: gap 1 | I4: gap 2 | J4: gap 3 | K4: gap 4 | L4: gap 5 | M4: gap 6 | N4: S 1 | O4: S 2 | P4: S 3 | Q4: S 4 | R4: S 5 | S4: S 6 | T4: Rounds | U4: V, credit M | V4: V, ten years | W4: q 1 | X4: q 2 | Y4: q 3 | Z4: q 4 | AA4: q 5 | AB4: q 6 | AC4: Smallest slack | AD4: relaxed S 1 | AE4: relaxed S 2 | AF4: relaxed S 3 | AG4: relaxed S 4 | AH4: relaxed S 5 | AI4: relaxed S 6 | AJ4: Relaxation, credit M | AK4: Relaxation, ten years
A5: years 1–4 | B5: 1 | C5: 1 | D5: 1 | E5: 1 | F5: 0 | G5: 0 | H5: =Gap0*(1-Share*B5) -> 7 | I5: =H5*(1-Share*C5) -> 3.5 | J5: =I5*(1-Share*D5) -> 1.75 | K5: =J5*(1-Share*E5) -> 0.875 | L5: =K5*(1-Share*F5) -> 0.875 | M5: =L5*(1-Share*G5) -> 0.875 | N5: =Smax-Val_pt*H5 -> 70 | O5: =Smax-Val_pt*I5 -> 105 | P5: =Smax-Val_pt*J5 -> 122.5 | Q5: =Smax-Val_pt*K5 -> 131.25 | R5: =Smax-Val_pt*L5 -> 131.25 | S5: =Smax-Val_pt*M5 -> 131.25 | T5: =SUM(B5:G5) -> 4 | U5: =Cash0+SUM(N5:S5)-Cost_r*T5+Credit_M*S5 -> 2986.25 | V5: =Cash0+SUM(N5:S5)-Cost_r*T5+Credit_10*S5 -> 1673.75 | W5: =Liq0+N5-Cost_r*B5 -> 570 | X5: =W5+O5-Cost_r*C5 -> 555 | Y5: =X5+P5-Cost_r*D5 -> 557.5 | Z5: =Y5+Q5-Cost_r*E5 -> 568.75 | AA5: =Z5+R5-Cost_r*F5 -> 700 | AB5: =AA5+S5-Cost_r*G5 -> 831.25 | AC5: =MIN(MIN(Liq0-Cost_r*B5,W5-Cost_r*C5,X5-Cost_r*D5,Y5-Cost_r*E5,Z5-Cost_r*F5,AA5-Cost_r*G5,MIN(W5:AB5))-Floor_q,AB5-End_q) -> 85 | AD5: =Smax*(1-POWER(Keep,SUM($B5:B5))) -> 70 | AE5: =Smax*(1-POWER(Keep,SUM($B5:C5))) -> 105 | AF5: =Smax*(1-POWER(Keep,SUM($B5:D5))) -> 122.5 | AG5: =Smax*(1-POWER(Keep,SUM($B5:E5))) -> 131.25 | AH5: =Smax*(1-POWER(Keep,SUM($B5:F5))) -> 131.25 | AI5: =Smax*(1-POWER(Keep,SUM($B5:G5))) -> 131.25 | AJ5: =Cash0+SUM(AD5:AI5)-Cost_r*T5+Credit_M*AI5 -> 2986.25 | AK5: =Cash0+SUM(AD5:AI5)-Cost_r*T5+Credit_10*AI5 -> 1673.75
A6: years 1–3 and 5 | B6: 1 | C6: 1 | D6: 1 | E6: 0 | F6: 1 | G6: 0 | H6: =Gap0*(1-Share*B6) -> 7 | I6: =H6*(1-Share*C6) -> 3.5 | J6: =I6*(1-Share*D6) -> 1.75 | K6: =J6*(1-Share*E6) -> 1.75 | L6: =K6*(1-Share*F6) -> 0.875 | M6: =L6*(1-Share*G6) -> 0.875 | N6: =Smax-Val_pt*H6 -> 70 | O6: =Smax-Val_pt*I6 -> 105 | P6: =Smax-Val_pt*J6 -> 122.5 | Q6: =Smax-Val_pt*K6 -> 122.5 | R6: =Smax-Val_pt*L6 -> 131.25 | S6: =Smax-Val_pt*M6 -> 131.25 | T6: =SUM(B6:G6) -> 4 | U6: =Cash0+SUM(N6:S6)-Cost_r*T6+Credit_M*S6 -> 2977.5 | V6: =Cash0+SUM(N6:S6)-Cost_r*T6+Credit_10*S6 -> 1665 | W6: =Liq0+N6-Cost_r*B6 -> 570 | X6: =W6+O6-Cost_r*C6 -> 555 | Y6: =X6+P6-Cost_r*D6 -> 557.5 | Z6: =Y6+Q6-Cost_r*E6 -> 680 | AA6: =Z6+R6-Cost_r*F6 -> 691.25 | AB6: =AA6+S6-Cost_r*G6 -> 822.5 | AC6: =MIN(MIN(Liq0-Cost_r*B6,W6-Cost_r*C6,X6-Cost_r*D6,Y6-Cost_r*E6,Z6-Cost_r*F6,AA6-Cost_r*G6,MIN(W6:AB6))-Floor_q,AB6-End_q) -> 85 | AD6: =Smax*(1-POWER(Keep,SUM($B6:B6))) -> 70 | AE6: =Smax*(1-POWER(Keep,SUM($B6:C6))) -> 105 | AF6: =Smax*(1-POWER(Keep,SUM($B6:D6))) -> 122.5 | AG6: =Smax*(1-POWER(Keep,SUM($B6:E6))) -> 122.5 | AH6: =Smax*(1-POWER(Keep,SUM($B6:F6))) -> 131.25 | AI6: =Smax*(1-POWER(Keep,SUM($B6:G6))) -> 131.25 | AJ6: =Cash0+SUM(AD6:AI6)-Cost_r*T6+Credit_M*AI6 -> 2977.5 | AK6: =Cash0+SUM(AD6:AI6)-Cost_r*T6+Credit_10*AI6 -> 1665
A7: years 1–3 and 6 | B7: 1 | C7: 1 | D7: 1 | E7: 0 | F7: 0 | G7: 1 | H7: =Gap0*(1-Share*B7) -> 7 | I7: =H7*(1-Share*C7) -> 3.5 | J7: =I7*(1-Share*D7) -> 1.75 | K7: =J7*(1-Share*E7) -> 1.75 | L7: =K7*(1-Share*F7) -> 1.75 | M7: =L7*(1-Share*G7) -> 0.875 | N7: =Smax-Val_pt*H7 -> 70 | O7: =Smax-Val_pt*I7 -> 105 | P7: =Smax-Val_pt*J7 -> 122.5 | Q7: =Smax-Val_pt*K7 -> 122.5 | R7: =Smax-Val_pt*L7 -> 122.5 | S7: =Smax-Val_pt*M7 -> 131.25 | T7: =SUM(B7:G7) -> 4 | U7: =Cash0+SUM(N7:S7)-Cost_r*T7+Credit_M*S7 -> 2968.75 | V7: =Cash0+SUM(N7:S7)-Cost_r*T7+Credit_10*S7 -> 1656.25 | W7: =Liq0+N7-Cost_r*B7 -> 570 | X7: =W7+O7-Cost_r*C7 -> 555 | Y7: =X7+P7-Cost_r*D7 -> 557.5 | Z7: =Y7+Q7-Cost_r*E7 -> 680 | AA7: =Z7+R7-Cost_r*F7 -> 802.5 | AB7: =AA7+S7-Cost_r*G7 -> 813.75 | AC7: =MIN(MIN(Liq0-Cost_r*B7,W7-Cost_r*C7,X7-Cost_r*D7,Y7-Cost_r*E7,Z7-Cost_r*F7,AA7-Cost_r*G7,MIN(W7:AB7))-Floor_q,AB7-End_q) -> 85 | AD7: =Smax*(1-POWER(Keep,SUM($B7:B7))) -> 70 | AE7: =Smax*(1-POWER(Keep,SUM($B7:C7))) -> 105 | AF7: =Smax*(1-POWER(Keep,SUM($B7:D7))) -> 122.5 | AG7: =Smax*(1-POWER(Keep,SUM($B7:E7))) -> 122.5 | AH7: =Smax*(1-POWER(Keep,SUM($B7:F7))) -> 122.5 | AI7: =Smax*(1-POWER(Keep,SUM($B7:G7))) -> 131.25 | AJ7: =Cash0+SUM(AD7:AI7)-Cost_r*T7+Credit_M*AI7 -> 2968.75 | AK7: =Cash0+SUM(AD7:AI7)-Cost_r*T7+Credit_10*AI7 -> 1656.25
A8: years 1–3 | B8: 1 | C8: 1 | D8: 1 | E8: 0 | F8: 0 | G8: 0 | H8: =Gap0*(1-Share*B8) -> 7 | I8: =H8*(1-Share*C8) -> 3.5 | J8: =I8*(1-Share*D8) -> 1.75 | K8: =J8*(1-Share*E8) -> 1.75 | L8: =K8*(1-Share*F8) -> 1.75 | M8: =L8*(1-Share*G8) -> 1.75 | N8: =Smax-Val_pt*H8 -> 70 | O8: =Smax-Val_pt*I8 -> 105 | P8: =Smax-Val_pt*J8 -> 122.5 | Q8: =Smax-Val_pt*K8 -> 122.5 | R8: =Smax-Val_pt*L8 -> 122.5 | S8: =Smax-Val_pt*M8 -> 122.5 | T8: =SUM(B8:G8) -> 3 | U8: =Cash0+SUM(N8:S8)-Cost_r*T8+Credit_M*S8 -> 2905 | V8: =Cash0+SUM(N8:S8)-Cost_r*T8+Credit_10*S8 -> 1680 | W8: =Liq0+N8-Cost_r*B8 -> 570 | X8: =W8+O8-Cost_r*C8 -> 555 | Y8: =X8+P8-Cost_r*D8 -> 557.5 | Z8: =Y8+Q8-Cost_r*E8 -> 680 | AA8: =Z8+R8-Cost_r*F8 -> 802.5 | AB8: =AA8+S8-Cost_r*G8 -> 925 | AC8: =MIN(MIN(Liq0-Cost_r*B8,W8-Cost_r*C8,X8-Cost_r*D8,Y8-Cost_r*E8,Z8-Cost_r*F8,AA8-Cost_r*G8,MIN(W8:AB8))-Floor_q,AB8-End_q) -> 85 | AD8: =Smax*(1-POWER(Keep,SUM($B8:B8))) -> 70 | AE8: =Smax*(1-POWER(Keep,SUM($B8:C8))) -> 105 | AF8: =Smax*(1-POWER(Keep,SUM($B8:D8))) -> 122.5 | AG8: =Smax*(1-POWER(Keep,SUM($B8:E8))) -> 122.5 | AH8: =Smax*(1-POWER(Keep,SUM($B8:F8))) -> 122.5 | AI8: =Smax*(1-POWER(Keep,SUM($B8:G8))) -> 122.5 | AJ8: =Cash0+SUM(AD8:AI8)-Cost_r*T8+Credit_M*AI8 -> 2905 | AK8: =Cash0+SUM(AD8:AI8)-Cost_r*T8+Credit_10*AI8 -> 1680
A9: the saddle: years 1–3, x* in year 4, y* in year 5 | B9: 1 | C9: 1 | D9: 1 | E9: =Face!B17 -> 0.75324675 | F9: =Face!B18 -> 0.84415584 | G9: 0 | H9: =Gap0*(1-Share*B9) -> 7 | I9: =H9*(1-Share*C9) -> 3.5 | J9: =I9*(1-Share*D9) -> 1.75 | K9: =J9*(1-Share*E9) -> 1.0909091 | L9: =K9*(1-Share*F9) -> 0.63046045 | M9: =L9*(1-Share*G9) -> 0.63046045 | N9: =Smax-Val_pt*H9 -> 70 | O9: =Smax-Val_pt*I9 -> 105 | P9: =Smax-Val_pt*J9 -> 122.5 | Q9: =Smax-Val_pt*K9 -> 129.09091 | R9: =Smax-Val_pt*L9 -> 133.6954 | S9: =Smax-Val_pt*M9 -> 133.6954 | T9: =SUM(B9:G9) -> 4.5974026 | U9: =Cash0+SUM(N9:S9)-Cost_r*T9+Credit_M*S9 -> 2966.2013 | V9: =Cash0+SUM(N9:S9)-Cost_r*T9+Credit_10*S9 -> 1629.2473 | W9: =Liq0+N9-Cost_r*B9 -> 570 | X9: =W9+O9-Cost_r*C9 -> 555 | Y9: =X9+P9-Cost_r*D9 -> 557.5 | Z9: =Y9+Q9-Cost_r*E9 -> 596.2013 | AA9: =Z9+R9-Cost_r*F9 -> 628.59799 | AB9: =AA9+S9-Cost_r*G9 -> 762.29339 | AC9: =MIN(MIN(Liq0-Cost_r*B9,W9-Cost_r*C9,X9-Cost_r*D9,Y9-Cost_r*E9,Z9-Cost_r*F9,AA9-Cost_r*G9,MIN(W9:AB9))-Floor_q,AB9-End_q) -> 85 | AD9: =Smax*(1-POWER(Keep,SUM($B9:B9))) -> 70 | AE9: =Smax*(1-POWER(Keep,SUM($B9:C9))) -> 105 | AF9: =Smax*(1-POWER(Keep,SUM($B9:D9))) -> 122.5 | AG9: =Smax*(1-POWER(Keep,SUM($B9:E9))) -> 129.61783 | AH9: =Smax*(1-POWER(Keep,SUM($B9:F9))) -> 134.21675 | AI9: =Smax*(1-POWER(Keep,SUM($B9:G9))) -> 134.21675 | AJ9: =Cash0+SUM(AD9:AI9)-Cost_r*T9+Credit_M*AI9 -> 2978.198 | AK9: =Cash0+SUM(AD9:AI9)-Cost_r*T9+Credit_10*AI9 -> 1636.0305
A10: Chapter 3's relaxation at credit M (its plan) | B10: =Relaxation!B16 -> 1 | C10: =Relaxation!C16 -> 1 | D10: =Relaxation!D16 -> 1 | E10: =Relaxation!E16 -> 1 | F10: =Relaxation!F16 -> 0.15305767 | G10: =Relaxation!G16 -> 0 | H10: =Gap0*(1-Share*B10) -> 7 | I10: =H10*(1-Share*C10) -> 3.5 | J10: =I10*(1-Share*D10) -> 1.75 | K10: =J10*(1-Share*E10) -> 0.875 | L10: =K10*(1-Share*F10) -> 0.80803727 | M10: =L10*(1-Share*G10) -> 0.80803727 | N10: =Smax-Val_pt*H10 -> 70 | O10: =Smax-Val_pt*I10 -> 105 | P10: =Smax-Val_pt*J10 -> 122.5 | Q10: =Smax-Val_pt*K10 -> 131.25 | R10: =Smax-Val_pt*L10 -> 131.91963 | S10: =Smax-Val_pt*M10 -> 131.91963 | T10: =SUM(B10:G10) -> 4.1530577 | U10: =Cash0+SUM(N10:S10)-Cost_r*T10+Credit_M*S10 -> 2982.6149 | V10: =Cash0+SUM(N10:S10)-Cost_r*T10+Credit_10*S10 -> 1663.4186 | W10: =Liq0+N10-Cost_r*B10 -> 570 | X10: =W10+O10-Cost_r*C10 -> 555 | Y10: =X10+P10-Cost_r*D10 -> 557.5 | Z10: =Y10+Q10-Cost_r*E10 -> 568.75 | AA10: =Z10+R10-Cost_r*F10 -> 682.30271 | AB10: =AA10+S10-Cost_r*G10 -> 814.22233 | AC10: =MIN(MIN(Liq0-Cost_r*B10,W10-Cost_r*C10,X10-Cost_r*D10,Y10-Cost_r*E10,Z10-Cost_r*F10,AA10-Cost_r*G10,MIN(W10:AB10))-Floor_q,AB10-End_q) -> 85 | AD10: =Smax*(1-POWER(Keep,SUM($B10:B10))) -> 70 | AE10: =Smax*(1-POWER(Keep,SUM($B10:C10))) -> 105 | AF10: =Smax*(1-POWER(Keep,SUM($B10:D10))) -> 122.5 | AG10: =Smax*(1-POWER(Keep,SUM($B10:E10))) -> 131.25 | AH10: =Smax*(1-POWER(Keep,SUM($B10:F10))) -> 132.13075 | AI10: =Smax*(1-POWER(Keep,SUM($B10:G10))) -> 132.13075 | AJ10: =Cash0+SUM(AD10:AI10)-Cost_r*T10+Credit_M*AI10 -> 2987.2597 | AK10: =Cash0+SUM(AD10:AI10)-Cost_r*T10+Credit_10*AI10 -> 1665.9521
A11: Chapter 3's relaxation at ten years (its plan) | B11: =Relaxation!B32 -> 1 | C11: =Relaxation!C32 -> 1 | D11: =Relaxation!D32 -> 1 | E11: =Relaxation!E32 -> 0.39406577 | F11: =Relaxation!F32 -> 0 | G11: =Relaxation!G32 -> 0 | H11: =Gap0*(1-Share*B11) -> 7 | I11: =H11*(1-Share*C11) -> 3.5 | J11: =I11*(1-Share*D11) -> 1.75 | K11: =J11*(1-Share*E11) -> 1.4051925 | L11: =K11*(1-Share*F11) -> 1.4051925 | M11: =L11*(1-Share*G11) -> 1.4051925 | N11: =Smax-Val_pt*H11 -> 70 | O11: =Smax-Val_pt*I11 -> 105 | P11: =Smax-Val_pt*J11 -> 122.5 | Q11: =Smax-Val_pt*K11 -> 125.94808 | R11: =Smax-Val_pt*L11 -> 125.94808 | S11: =Smax-Val_pt*M11 -> 125.94808 | T11: =SUM(B11:G11) -> 3.3940658 | U11: =Cash0+SUM(N11:S11)-Cost_r*T11+Credit_M*S11 -> 2937.0178 | V11: =Cash0+SUM(N11:S11)-Cost_r*T11+Credit_10*S11 -> 1677.5371 | W11: =Liq0+N11-Cost_r*B11 -> 570 | X11: =W11+O11-Cost_r*C11 -> 555 | Y11: =X11+P11-Cost_r*D11 -> 557.5 | Z11: =Y11+Q11-Cost_r*E11 -> 636.16018 | AA11: =Z11+R11-Cost_r*F11 -> 762.10826 | AB11: =AA11+S11-Cost_r*G11 -> 888.05633 | AC11: =MIN(MIN(Liq0-Cost_r*B11,W11-Cost_r*C11,X11-Cost_r*D11,Y11-Cost_r*E11,Z11-Cost_r*F11,AA11-Cost_r*G11,MIN(W11:AB11))-Floor_q,AB11-End_q) -> 85 | AD11: =Smax*(1-POWER(Keep,SUM($B11:B11))) -> 70 | AE11: =Smax*(1-POWER(Keep,SUM($B11:C11))) -> 105 | AF11: =Smax*(1-POWER(Keep,SUM($B11:D11))) -> 122.5 | AG11: =Smax*(1-POWER(Keep,SUM($B11:E11))) -> 126.68282 | AH11: =Smax*(1-POWER(Keep,SUM($B11:F11))) -> 126.68282 | AI11: =Smax*(1-POWER(Keep,SUM($B11:G11))) -> 126.68282 | AJ11: =Cash0+SUM(AD11:AI11)-Cost_r*T11+Credit_M*AI11 -> 2953.9169 | AK11: =Cash0+SUM(AD11:AI11)-Cost_r*T11+Credit_10*AI11 -> 1687.0887
A12: half a round in year 1 | B12: 0.5 | C12: 0 | D12: 0 | E12: 0 | F12: 0 | G12: 0 | H12: =Gap0*(1-Share*B12) -> 10.5 | I12: =H12*(1-Share*C12) -> 10.5 | J12: =I12*(1-Share*D12) -> 10.5 | K12: =J12*(1-Share*E12) -> 10.5 | L12: =K12*(1-Share*F12) -> 10.5 | M12: =L12*(1-Share*G12) -> 10.5 | N12: =Smax-Val_pt*H12 -> 35 | O12: =Smax-Val_pt*I12 -> 35 | P12: =Smax-Val_pt*J12 -> 35 | Q12: =Smax-Val_pt*K12 -> 35 | R12: =Smax-Val_pt*L12 -> 35 | S12: =Smax-Val_pt*M12 -> 35 | T12: =SUM(B12:G12) -> 0.5 | U12: =Cash0+SUM(N12:S12)-Cost_r*T12+Credit_M*S12 -> 1000 | V12: =Cash0+SUM(N12:S12)-Cost_r*T12+Credit_10*S12 -> 650 | W12: =Liq0+N12-Cost_r*B12 -> 595 | X12: =W12+O12-Cost_r*C12 -> 630 | Y12: =X12+P12-Cost_r*D12 -> 665 | Z12: =Y12+Q12-Cost_r*E12 -> 700 | AA12: =Z12+R12-Cost_r*F12 -> 735 | AB12: =AA12+S12-Cost_r*G12 -> 770 | AC12: =MIN(MIN(Liq0-Cost_r*B12,W12-Cost_r*C12,X12-Cost_r*D12,Y12-Cost_r*E12,Z12-Cost_r*F12,AA12-Cost_r*G12,MIN(W12:AB12))-Floor_q,AB12-End_q) -> 210 | AD12: =Smax*(1-POWER(Keep,SUM($B12:B12))) -> 41.005051 | AE12: =Smax*(1-POWER(Keep,SUM($B12:C12))) -> 41.005051 | AF12: =Smax*(1-POWER(Keep,SUM($B12:D12))) -> 41.005051 | AG12: =Smax*(1-POWER(Keep,SUM($B12:E12))) -> 41.005051 | AH12: =Smax*(1-POWER(Keep,SUM($B12:F12))) -> 41.005051 | AI12: =Smax*(1-POWER(Keep,SUM($B12:G12))) -> 41.005051 | AJ12: =Cash0+SUM(AD12:AI12)-Cost_r*T12+Credit_M*AI12 -> 1156.1313 | AK12: =Cash0+SUM(AD12:AI12)-Cost_r*T12+Credit_10*AI12 -> 746.08081
A13: your plan (change the blue cells) | B13: 1 | C13: 1 | D13: 1 | E13: 0.5 | F13: 0.5 | G13: 0 | H13: =Gap0*(1-Share*B13) -> 7 | I13: =H13*(1-Share*C13) -> 3.5 | J13: =I13*(1-Share*D13) -> 1.75 | K13: =J13*(1-Share*E13) -> 1.3125 | L13: =K13*(1-Share*F13) -> 0.984375 | M13: =L13*(1-Share*G13) -> 0.984375 | N13: =Smax-Val_pt*H13 -> 70 | O13: =Smax-Val_pt*I13 -> 105 | P13: =Smax-Val_pt*J13 -> 122.5 | Q13: =Smax-Val_pt*K13 -> 126.875 | R13: =Smax-Val_pt*L13 -> 130.15625 | S13: =Smax-Val_pt*M13 -> 130.15625 | T13: =SUM(B13:G13) -> 4 | U13: =Cash0+SUM(N13:S13)-Cost_r*T13+Credit_M*S13 -> 2957.8125 | V13: =Cash0+SUM(N13:S13)-Cost_r*T13+Credit_10*S13 -> 1656.25 | W13: =Liq0+N13-Cost_r*B13 -> 570 | X13: =W13+O13-Cost_r*C13 -> 555 | Y13: =X13+P13-Cost_r*D13 -> 557.5 | Z13: =Y13+Q13-Cost_r*E13 -> 624.375 | AA13: =Z13+R13-Cost_r*F13 -> 694.53125 | AB13: =AA13+S13-Cost_r*G13 -> 824.6875 | AC13: =MIN(MIN(Liq0-Cost_r*B13,W13-Cost_r*C13,X13-Cost_r*D13,Y13-Cost_r*E13,Z13-Cost_r*F13,AA13-Cost_r*G13,MIN(W13:AB13))-Floor_q,AB13-End_q) -> 85 | AD13: =Smax*(1-POWER(Keep,SUM($B13:B13))) -> 70 | AE13: =Smax*(1-POWER(Keep,SUM($B13:C13))) -> 105 | AF13: =Smax*(1-POWER(Keep,SUM($B13:D13))) -> 122.5 | AG13: =Smax*(1-POWER(Keep,SUM($B13:E13))) -> 127.62563 | AH13: =Smax*(1-POWER(Keep,SUM($B13:F13))) -> 131.25 | AI13: =Smax*(1-POWER(Keep,SUM($B13:G13))) -> 131.25 | AJ13: =Cash0+SUM(AD13:AI13)-Cost_r*T13+Credit_M*AI13 -> 2982.6256 | AK13: =Cash0+SUM(AD13:AI13)-Cost_r*T13+Credit_10*AI13 -> 1670.1256
A14: your plan with no year-4 round | B14: =B13 -> 1 | C14: =C13 -> 1 | D14: =D13 -> 1 | E14: 0 | F14: =F13 -> 0.5 | G14: =G13 -> 0 | H14: =Gap0*(1-Share*B14) -> 7 | I14: =H14*(1-Share*C14) -> 3.5 | J14: =I14*(1-Share*D14) -> 1.75 | K14: =J14*(1-Share*E14) -> 1.75 | L14: =K14*(1-Share*F14) -> 1.3125 | M14: =L14*(1-Share*G14) -> 1.3125 | N14: =Smax-Val_pt*H14 -> 70 | O14: =Smax-Val_pt*I14 -> 105 | P14: =Smax-Val_pt*J14 -> 122.5 | Q14: =Smax-Val_pt*K14 -> 122.5 | R14: =Smax-Val_pt*L14 -> 126.875 | S14: =Smax-Val_pt*M14 -> 126.875 | T14: =SUM(B14:G14) -> 3.5 | U14: =Cash0+SUM(N14:S14)-Cost_r*T14+Credit_M*S14 -> 2941.25 | V14: =Cash0+SUM(N14:S14)-Cost_r*T14+Credit_10*S14 -> 1672.5 | W14: =Liq0+N14-Cost_r*B14 -> 570 | X14: =W14+O14-Cost_r*C14 -> 555 | Y14: =X14+P14-Cost_r*D14 -> 557.5 | Z14: =Y14+Q14-Cost_r*E14 -> 680 | AA14: =Z14+R14-Cost_r*F14 -> 746.875 | AB14: =AA14+S14-Cost_r*G14 -> 873.75 | AC14: =MIN(MIN(Liq0-Cost_r*B14,W14-Cost_r*C14,X14-Cost_r*D14,Y14-Cost_r*E14,Z14-Cost_r*F14,AA14-Cost_r*G14,MIN(W14:AB14))-Floor_q,AB14-End_q) -> 85 | AD14: =Smax*(1-POWER(Keep,SUM($B14:B14))) -> 70 | AE14: =Smax*(1-POWER(Keep,SUM($B14:C14))) -> 105 | AF14: =Smax*(1-POWER(Keep,SUM($B14:D14))) -> 122.5 | AG14: =Smax*(1-POWER(Keep,SUM($B14:E14))) -> 122.5 | AH14: =Smax*(1-POWER(Keep,SUM($B14:F14))) -> 127.62563 | AI14: =Smax*(1-POWER(Keep,SUM($B14:G14))) -> 127.62563 | AJ14: =Cash0+SUM(AD14:AI14)-Cost_r*T14+Credit_M*AI14 -> 2957.7639 | AK14: =Cash0+SUM(AD14:AI14)-Cost_r*T14+Credit_10*AI14 -> 1681.5076
A15: your plan with a whole year-4 round | B15: =B13 -> 1 | C15: =C13 -> 1 | D15: =D13 -> 1 | E15: 1 | F15: =F13 -> 0.5 | G15: =G13 -> 0 | H15: =Gap0*(1-Share*B15) -> 7 | I15: =H15*(1-Share*C15) -> 3.5 | J15: =I15*(1-Share*D15) -> 1.75 | K15: =J15*(1-Share*E15) -> 0.875 | L15: =K15*(1-Share*F15) -> 0.65625 | M15: =L15*(1-Share*G15) -> 0.65625 | N15: =Smax-Val_pt*H15 -> 70 | O15: =Smax-Val_pt*I15 -> 105 | P15: =Smax-Val_pt*J15 -> 122.5 | Q15: =Smax-Val_pt*K15 -> 131.25 | R15: =Smax-Val_pt*L15 -> 133.4375 | S15: =Smax-Val_pt*M15 -> 133.4375 | T15: =SUM(B15:G15) -> 4.5 | U15: =Cash0+SUM(N15:S15)-Cost_r*T15+Credit_M*S15 -> 2974.375 | V15: =Cash0+SUM(N15:S15)-Cost_r*T15+Credit_10*S15 -> 1640 | W15: =Liq0+N15-Cost_r*B15 -> 570 | X15: =W15+O15-Cost_r*C15 -> 555 | Y15: =X15+P15-Cost_r*D15 -> 557.5 | Z15: =Y15+Q15-Cost_r*E15 -> 568.75 | AA15: =Z15+R15-Cost_r*F15 -> 642.1875 | AB15: =AA15+S15-Cost_r*G15 -> 775.625 | AC15: =MIN(MIN(Liq0-Cost_r*B15,W15-Cost_r*C15,X15-Cost_r*D15,Y15-Cost_r*E15,Z15-Cost_r*F15,AA15-Cost_r*G15,MIN(W15:AB15))-Floor_q,AB15-End_q) -> 85 | AD15: =Smax*(1-POWER(Keep,SUM($B15:B15))) -> 70 | AE15: =Smax*(1-POWER(Keep,SUM($B15:C15))) -> 105 | AF15: =Smax*(1-POWER(Keep,SUM($B15:D15))) -> 122.5 | AG15: =Smax*(1-POWER(Keep,SUM($B15:E15))) -> 131.25 | AH15: =Smax*(1-POWER(Keep,SUM($B15:F15))) -> 133.81282 | AI15: =Smax*(1-POWER(Keep,SUM($B15:G15))) -> 133.81282 | AJ15: =Cash0+SUM(AD15:AI15)-Cost_r*T15+Credit_M*AI15 -> 2982.6319 | AK15: =Cash0+SUM(AD15:AI15)-Cost_r*T15+Credit_10*AI15 -> 1644.5038
A17: The relaxation's plan at credit M, in the partial-round model, below running none | U17: =U5-U10 -> 3.6351196
A18: The relaxation's plan at ten years, in the partial-round model, below three rounds | V18: =V8-V11 -> 2.462911
A19: Your plan's year-4 round as a blend of none and whole: (1 - z4) V(none) + z4 V(whole) | U19: =(1-E13)*U14+E13*U15 -> 2957.8125
A20: Your plan's value less that blend (zero: Proposition 4.2(i)) | U20: =U13-U19 -> 0
A21: V is affine in each round: set any one blue z between 0 and 1 and the value moves in a straight line, never above the better end; the relaxation's value (AJ) always lies above it (2^-z <= 1 - z/2).

Sheet Schedules
A1: All 64 plans of whole rounds: values, floors, marginal values and the corner test (Proposition 4.2(iii))
A2: Plan i runs a round in year k when the k-th binary digit of i is 1 (i = 32 z1 + 16 z2 + ... + z6). Marginal values at credit M are exact: V is affine in each round. A corner is a strict local maximum when every marginal value points out of the box.
A4: i | B4: z1 | C4: z2 | D4: z3 | E4: z4 | F4: z5 | G4: z6 | H4: gap 1 | I4: gap 2 | J4: gap 3 | K4: gap 4 | L4: gap 5 | M4: gap 6 | N4: S 1 | O4: S 2 | P4: S 3 | Q4: S 4 | R4: S 5 | S4: S 6 | T4: Rounds | U4: V, credit M | V4: V, ten years | W4: q 1 | X4: q 2 | Y4: q 3 | Z4: q 4 | AA4: q 5 | AB4: q 6 | AC4: Smallest slack | AD4: marginal 1 | AE4: marginal 2 | AF4: marginal 3 | AG4: marginal 4 | AH4: marginal 5 | AI4: marginal 6 | AJ4: Strict local max | AL4: Summary | AM4: Value
A5: 0 | B5: =MOD(INT($A5/32),2) -> 0 | C5: =MOD(INT($A5/16),2) -> 0 | D5: =MOD(INT($A5/8),2) -> 0 | E5: =MOD(INT($A5/4),2) -> 0 | F5: =MOD(INT($A5/2),2) -> 0 | G5: =MOD(INT($A5/1),2) -> 0 | H5: =Gap0*(1-Share*B5) -> 14 | I5: =H5*(1-Share*C5) -> 14 | J5: =I5*(1-Share*D5) -> 14 | K5: =J5*(1-Share*E5) -> 14 | L5: =K5*(1-Share*F5) -> 14 | M5: =L5*(1-Share*G5) -> 14 | N5: =Smax-Val_pt*H5 -> 0 | O5: =Smax-Val_pt*I5 -> 0 | P5: =Smax-Val_pt*J5 -> 0 | Q5: =Smax-Val_pt*K5 -> 0 | R5: =Smax-Val_pt*L5 -> 0 | S5: =Smax-Val_pt*M5 -> 0 | T5: =SUM(B5:G5) -> 0 | U5: =Cash0+SUM(N5:S5)-Cost_r*T5+Credit_M*S5 -> 150 | V5: =Cash0+SUM(N5:S5)-Cost_r*T5+Credit_10*S5 -> 150 | W5: =Liq0+N5-Cost_r*B5 -> 620 | X5: =W5+O5-Cost_r*C5 -> 620 | Y5: =X5+P5-Cost_r*D5 -> 620 | Z5: =Y5+Q5-Cost_r*E5 -> 620 | AA5: =Z5+R5-Cost_r*F5 -> 620 | AB5: =AA5+S5-Cost_r*G5 -> 620 | AC5: =MIN(MIN(Liq0-Cost_r*B5,W5-Cost_r*C5,X5-Cost_r*D5,Y5-Cost_r*E5,Z5-Cost_r*F5,AA5-Cost_r*G5,MIN(W5:AB5))-Floor_q,AB5-End_q) -> 150 | AD5: =Val_pt*Share/(1-Share*B5)*(SUM(H5:M5)+Credit_M*M5)-Cost_r -> 1700 | AE5: =Val_pt*Share/(1-Share*C5)*(SUM(I5:M5)+Credit_M*M5)-Cost_r -> 1630 | AF5: =Val_pt*Share/(1-Share*D5)*(SUM(J5:M5)+Credit_M*M5)-Cost_r -> 1560 | AG5: =Val_pt*Share/(1-Share*E5)*(SUM(K5:M5)+Credit_M*M5)-Cost_r -> 1490 | AH5: =Val_pt*Share/(1-Share*F5)*(SUM(L5:M5)+Credit_M*M5)-Cost_r -> 1420 | AI5: =Val_pt*Share/(1-Share*G5)*(SUM(M5:M5)+Credit_M*M5)-Cost_r -> 1350 | AJ5: =IF(AND(IF(B5=1,AD5>0,AD5<0),IF(C5=1,AE5>0,AE5<0),IF(D5=1,AF5>0,AF5<0),IF(E5=1,AG5>0,AG5<0),IF(F5=1,AH5>0,AH5<0),IF(G5=1,AI5>0,AI5<0)),1,0) -> 0 | AL5: Strict local maxima at credit M | AM5: =SUM(AJ5:AJ68) -> 3
A6: 1 | B6: =MOD(INT($A6/32),2) -> 0 | C6: =MOD(INT($A6/16),2) -> 0 | D6: =MOD(INT($A6/8),2) -> 0 | E6: =MOD(INT($A6/4),2) -> 0 | F6: =MOD(INT($A6/2),2) -> 0 | G6: =MOD(INT($A6/1),2) -> 1 | H6: =Gap0*(1-Share*B6) -> 14 | I6: =H6*(1-Share*C6) -> 14 | J6: =I6*(1-Share*D6) -> 14 | K6: =J6*(1-Share*E6) -> 14 | L6: =K6*(1-Share*F6) -> 14 | M6: =L6*(1-Share*G6) -> 7 | N6: =Smax-Val_pt*H6 -> 0 | O6: =Smax-Val_pt*I6 -> 0 | P6: =Smax-Val_pt*J6 -> 0 | Q6: =Smax-Val_pt*K6 -> 0 | R6: =Smax-Val_pt*L6 -> 0 | S6: =Smax-Val_pt*M6 -> 70 | T6: =SUM(B6:G6) -> 1 | U6: =Cash0+SUM(N6:S6)-Cost_r*T6+Credit_M*S6 -> 1500 | V6: =Cash0+SUM(N6:S6)-Cost_r*T6+Credit_10*S6 -> 800 | W6: =Liq0+N6-Cost_r*B6 -> 620 | X6: =W6+O6-Cost_r*C6 -> 620 | Y6: =X6+P6-Cost_r*D6 -> 620 | Z6: =Y6+Q6-Cost_r*E6 -> 620 | AA6: =Z6+R6-Cost_r*F6 -> 620 | AB6: =AA6+S6-Cost_r*G6 -> 570 | AC6: =MIN(MIN(Liq0-Cost_r*B6,W6-Cost_r*C6,X6-Cost_r*D6,Y6-Cost_r*E6,Z6-Cost_r*F6,AA6-Cost_r*G6,MIN(W6:AB6))-Floor_q,AB6-End_q) -> 100 | AD6: =Val_pt*Share/(1-Share*B6)*(SUM(H6:M6)+Credit_M*M6)-Cost_r -> 965 | AE6: =Val_pt*Share/(1-Share*C6)*(SUM(I6:M6)+Credit_M*M6)-Cost_r -> 895 | AF6: =Val_pt*Share/(1-Share*D6)*(SUM(J6:M6)+Credit_M*M6)-Cost_r -> 825 | AG6: =Val_pt*Share/(1-Share*E6)*(SUM(K6:M6)+Credit_M*M6)-Cost_r -> 755 | AH6: =Val_pt*Share/(1-Share*F6)*(SUM(L6:M6)+Credit_M*M6)-Cost_r -> 685 | AI6: =Val_pt*Share/(1-Share*G6)*(SUM(M6:M6)+Credit_M*M6)-Cost_r -> 1350 | AJ6: =IF(AND(IF(B6=1,AD6>0,AD6<0),IF(C6=1,AE6>0,AE6<0),IF(D6=1,AF6>0,AF6<0),IF(E6=1,AG6>0,AG6<0),IF(F6=1,AH6>0,AH6<0),IF(G6=1,AI6>0,AI6<0)),1,0) -> 0 | AL6: Best plan of whole rounds at credit M | AM6: =MAX(U5:U68) -> 2986.25
A7: 2 | B7: =MOD(INT($A7/32),2) -> 0 | C7: =MOD(INT($A7/16),2) -> 0 | D7: =MOD(INT($A7/8),2) -> 0 | E7: =MOD(INT($A7/4),2) -> 0 | F7: =MOD(INT($A7/2),2) -> 1 | G7: =MOD(INT($A7/1),2) -> 0 | H7: =Gap0*(1-Share*B7) -> 14 | I7: =H7*(1-Share*C7) -> 14 | J7: =I7*(1-Share*D7) -> 14 | K7: =J7*(1-Share*E7) -> 14 | L7: =K7*(1-Share*F7) -> 7 | M7: =L7*(1-Share*G7) -> 7 | N7: =Smax-Val_pt*H7 -> 0 | O7: =Smax-Val_pt*I7 -> 0 | P7: =Smax-Val_pt*J7 -> 0 | Q7: =Smax-Val_pt*K7 -> 0 | R7: =Smax-Val_pt*L7 -> 70 | S7: =Smax-Val_pt*M7 -> 70 | T7: =SUM(B7:G7) -> 1 | U7: =Cash0+SUM(N7:S7)-Cost_r*T7+Credit_M*S7 -> 1570 | V7: =Cash0+SUM(N7:S7)-Cost_r*T7+Credit_10*S7 -> 870 | W7: =Liq0+N7-Cost_r*B7 -> 620 | X7: =W7+O7-Cost_r*C7 -> 620 | Y7: =X7+P7-Cost_r*D7 -> 620 | Z7: =Y7+Q7-Cost_r*E7 -> 620 | AA7: =Z7+R7-Cost_r*F7 -> 570 | AB7: =AA7+S7-Cost_r*G7 -> 640 | AC7: =MIN(MIN(Liq0-Cost_r*B7,W7-Cost_r*C7,X7-Cost_r*D7,Y7-Cost_r*E7,Z7-Cost_r*F7,AA7-Cost_r*G7,MIN(W7:AB7))-Floor_q,AB7-End_q) -> 150 | AD7: =Val_pt*Share/(1-Share*B7)*(SUM(H7:M7)+Credit_M*M7)-Cost_r -> 930 | AE7: =Val_pt*Share/(1-Share*C7)*(SUM(I7:M7)+Credit_M*M7)-Cost_r -> 860 | AF7: =Val_pt*Share/(1-Share*D7)*(SUM(J7:M7)+Credit_M*M7)-Cost_r -> 790 | AG7: =Val_pt*Share/(1-Share*E7)*(SUM(K7:M7)+Credit_M*M7)-Cost_r -> 720 | AH7: =Val_pt*Share/(1-Share*F7)*(SUM(L7:M7)+Credit_M*M7)-Cost_r -> 1420 | AI7: =Val_pt*Share/(1-Share*G7)*(SUM(M7:M7)+Credit_M*M7)-Cost_r -> 615 | AJ7: =IF(AND(IF(B7=1,AD7>0,AD7<0),IF(C7=1,AE7>0,AE7<0),IF(D7=1,AF7>0,AF7<0),IF(E7=1,AG7>0,AG7<0),IF(F7=1,AH7>0,AH7<0),IF(G7=1,AI7>0,AI7<0)),1,0) -> 0 | AL7: Its index i | AM7: =INDEX(A5:A68,MATCH(AM6,U5:U68,0)) -> 60
A8: 3 | B8: =MOD(INT($A8/32),2) -> 0 | C8: =MOD(INT($A8/16),2) -> 0 | D8: =MOD(INT($A8/8),2) -> 0 | E8: =MOD(INT($A8/4),2) -> 0 | F8: =MOD(INT($A8/2),2) -> 1 | G8: =MOD(INT($A8/1),2) -> 1 | H8: =Gap0*(1-Share*B8) -> 14 | I8: =H8*(1-Share*C8) -> 14 | J8: =I8*(1-Share*D8) -> 14 | K8: =J8*(1-Share*E8) -> 14 | L8: =K8*(1-Share*F8) -> 7 | M8: =L8*(1-Share*G8) -> 3.5 | N8: =Smax-Val_pt*H8 -> 0 | O8: =Smax-Val_pt*I8 -> 0 | P8: =Smax-Val_pt*J8 -> 0 | Q8: =Smax-Val_pt*K8 -> 0 | R8: =Smax-Val_pt*L8 -> 70 | S8: =Smax-Val_pt*M8 -> 105 | T8: =SUM(B8:G8) -> 2 | U8: =Cash0+SUM(N8:S8)-Cost_r*T8+Credit_M*S8 -> 2185 | V8: =Cash0+SUM(N8:S8)-Cost_r*T8+Credit_10*S8 -> 1135 | W8: =Liq0+N8-Cost_r*B8 -> 620 | X8: =W8+O8-Cost_r*C8 -> 620 | Y8: =X8+P8-Cost_r*D8 -> 620 | Z8: =Y8+Q8-Cost_r*E8 -> 620 | AA8: =Z8+R8-Cost_r*F8 -> 570 | AB8: =AA8+S8-Cost_r*G8 -> 555 | AC8: =MIN(MIN(Liq0-Cost_r*B8,W8-Cost_r*C8,X8-Cost_r*D8,Y8-Cost_r*E8,Z8-Cost_r*F8,AA8-Cost_r*G8,MIN(W8:AB8))-Floor_q,AB8-End_q) -> 85 | AD8: =Val_pt*Share/(1-Share*B8)*(SUM(H8:M8)+Credit_M*M8)-Cost_r -> 562.5 | AE8: =Val_pt*Share/(1-Share*C8)*(SUM(I8:M8)+Credit_M*M8)-Cost_r -> 492.5 | AF8: =Val_pt*Share/(1-Share*D8)*(SUM(J8:M8)+Credit_M*M8)-Cost_r -> 422.5 | AG8: =Val_pt*Share/(1-Share*E8)*(SUM(K8:M8)+Credit_M*M8)-Cost_r -> 352.5 | AH8: =Val_pt*Share/(1-Share*F8)*(SUM(L8:M8)+Credit_M*M8)-Cost_r -> 685 | AI8: =Val_pt*Share/(1-Share*G8)*(SUM(M8:M8)+Credit_M*M8)-Cost_r -> 615 | AJ8: =IF(AND(IF(B8=1,AD8>0,AD8<0),IF(C8=1,AE8>0,AE8<0),IF(D8=1,AF8>0,AF8<0),IF(E8=1,AG8>0,AG8<0),IF(F8=1,AH8>0,AH8<0),IF(G8=1,AI8>0,AI8<0)),1,0) -> 0 | AL8: Smallest slack in the floors over the 64 plans | AM8: =MIN(AC5:AC68) -> 85
A9: 4 | B9: =MOD(INT($A9/32),2) -> 0 | C9: =MOD(INT($A9/16),2) -> 0 | D9: =MOD(INT($A9/8),2) -> 0 | E9: =MOD(INT($A9/4),2) -> 1 | F9: =MOD(INT($A9/2),2) -> 0 | G9: =MOD(INT($A9/1),2) -> 0 | H9: =Gap0*(1-Share*B9) -> 14 | I9: =H9*(1-Share*C9) -> 14 | J9: =I9*(1-Share*D9) -> 14 | K9: =J9*(1-Share*E9) -> 7 | L9: =K9*(1-Share*F9) -> 7 | M9: =L9*(1-Share*G9) -> 7 | N9: =Smax-Val_pt*H9 -> 0 | O9: =Smax-Val_pt*I9 -> 0 | P9: =Smax-Val_pt*J9 -> 0 | Q9: =Smax-Val_pt*K9 -> 70 | R9: =Smax-Val_pt*L9 -> 70 | S9: =Smax-Val_pt*M9 -> 70 | T9: =SUM(B9:G9) -> 1 | U9: =Cash0+SUM(N9:S9)-Cost_r*T9+Credit_M*S9 -> 1640 | V9: =Cash0+SUM(N9:S9)-Cost_r*T9+Credit_10*S9 -> 940 | W9: =Liq0+N9-Cost_r*B9 -> 620 | X9: =W9+O9-Cost_r*C9 -> 620 | Y9: =X9+P9-Cost_r*D9 -> 620 | Z9: =Y9+Q9-Cost_r*E9 -> 570 | AA9: =Z9+R9-Cost_r*F9 -> 640 | AB9: =AA9+S9-Cost_r*G9 -> 710 | AC9: =MIN(MIN(Liq0-Cost_r*B9,W9-Cost_r*C9,X9-Cost_r*D9,Y9-Cost_r*E9,Z9-Cost_r*F9,AA9-Cost_r*G9,MIN(W9:AB9))-Floor_q,AB9-End_q) -> 150 | AD9: =Val_pt*Share/(1-Share*B9)*(SUM(H9:M9)+Credit_M*M9)-Cost_r -> 895 | AE9: =Val_pt*Share/(1-Share*C9)*(SUM(I9:M9)+Credit_M*M9)-Cost_r -> 825 | AF9: =Val_pt*Share/(1-Share*D9)*(SUM(J9:M9)+Credit_M*M9)-Cost_r -> 755 | AG9: =Val_pt*Share/(1-Share*E9)*(SUM(K9:M9)+Credit_M*M9)-Cost_r -> 1490 | AH9: =Val_pt*Share/(1-Share*F9)*(SUM(L9:M9)+Credit_M*M9)-Cost_r -> 650 | AI9: =Val_pt*Share/(1-Share*G9)*(SUM(M9:M9)+Credit_M*M9)-Cost_r -> 615 | AJ9: =IF(AND(IF(B9=1,AD9>0,AD9<0),IF(C9=1,AE9>0,AE9<0),IF(D9=1,AF9>0,AF9<0),IF(E9=1,AG9>0,AG9<0),IF(F9=1,AH9>0,AH9<0),IF(G9=1,AI9>0,AI9<0)),1,0) -> 0 | AL9: Best plan of whole rounds at ten years | AM9: =MAX(V5:V68) -> 1680
A10: 5 | B10: =MOD(INT($A10/32),2) -> 0 | C10: =MOD(INT($A10/16),2) -> 0 | D10: =MOD(INT($A10/8),2) -> 0 | E10: =MOD(INT($A10/4),2) -> 1 | F10: =MOD(INT($A10/2),2) -> 0 | G10: =MOD(INT($A10/1),2) -> 1 | H10: =Gap0*(1-Share*B10) -> 14 | I10: =H10*(1-Share*C10) -> 14 | J10: =I10*(1-Share*D10) -> 14 | K10: =J10*(1-Share*E10) -> 7 | L10: =K10*(1-Share*F10) -> 7 | M10: =L10*(1-Share*G10) -> 3.5 | N10: =Smax-Val_pt*H10 -> 0 | O10: =Smax-Val_pt*I10 -> 0 | P10: =Smax-Val_pt*J10 -> 0 | Q10: =Smax-Val_pt*K10 -> 70 | R10: =Smax-Val_pt*L10 -> 70 | S10: =Smax-Val_pt*M10 -> 105 | T10: =SUM(B10:G10) -> 2 | U10: =Cash0+SUM(N10:S10)-Cost_r*T10+Credit_M*S10 -> 2255 | V10: =Cash0+SUM(N10:S10)-Cost_r*T10+Credit_10*S10 -> 1205 | W10: =Liq0+N10-Cost_r*B10 -> 620 | X10: =W10+O10-Cost_r*C10 -> 620 | Y10: =X10+P10-Cost_r*D10 -> 620 | Z10: =Y10+Q10-Cost_r*E10 -> 570 | AA10: =Z10+R10-Cost_r*F10 -> 640 | AB10: =AA10+S10-Cost_r*G10 -> 625 | AC10: =MIN(MIN(Liq0-Cost_r*B10,W10-Cost_r*C10,X10-Cost_r*D10,Y10-Cost_r*E10,Z10-Cost_r*F10,AA10-Cost_r*G10,MIN(W10:AB10))-Floor_q,AB10-End_q) -> 150 | AD10: =Val_pt*Share/(1-Share*B10)*(SUM(H10:M10)+Credit_M*M10)-Cost_r -> 527.5 | AE10: =Val_pt*Share/(1-Share*C10)*(SUM(I10:M10)+Credit_M*M10)-Cost_r -> 457.5 | AF10: =Val_pt*Share/(1-Share*D10)*(SUM(J10:M10)+Credit_M*M10)-Cost_r -> 387.5 | AG10: =Val_pt*Share/(1-Share*E10)*(SUM(K10:M10)+Credit_M*M10)-Cost_r -> 755 | AH10: =Val_pt*Share/(1-Share*F10)*(SUM(L10:M10)+Credit_M*M10)-Cost_r -> 282.5 | AI10: =Val_pt*Share/(1-Share*G10)*(SUM(M10:M10)+Credit_M*M10)-Cost_r -> 615 | AJ10: =IF(AND(IF(B10=1,AD10>0,AD10<0),IF(C10=1,AE10>0,AE10<0),IF(D10=1,AF10>0,AF10<0),IF(E10=1,AG10>0,AG10<0),IF(F10=1,AH10>0,AH10<0),IF(G10=1,AI10>0,AI10<0)),1,0) -> 0
A11: 6 | B11: =MOD(INT($A11/32),2) -> 0 | C11: =MOD(INT($A11/16),2) -> 0 | D11: =MOD(INT($A11/8),2) -> 0 | E11: =MOD(INT($A11/4),2) -> 1 | F11: =MOD(INT($A11/2),2) -> 1 | G11: =MOD(INT($A11/1),2) -> 0 | H11: =Gap0*(1-Share*B11) -> 14 | I11: =H11*(1-Share*C11) -> 14 | J11: =I11*(1-Share*D11) -> 14 | K11: =J11*(1-Share*E11) -> 7 | L11: =K11*(1-Share*F11) -> 3.5 | M11: =L11*(1-Share*G11) -> 3.5 | N11: =Smax-Val_pt*H11 -> 0 | O11: =Smax-Val_pt*I11 -> 0 | P11: =Smax-Val_pt*J11 -> 0 | Q11: =Smax-Val_pt*K11 -> 70 | R11: =Smax-Val_pt*L11 -> 105 | S11: =Smax-Val_pt*M11 -> 105 | T11: =SUM(B11:G11) -> 2 | U11: =Cash0+SUM(N11:S11)-Cost_r*T11+Credit_M*S11 -> 2290 | V11: =Cash0+SUM(N11:S11)-Cost_r*T11+Credit_10*S11 -> 1240 | W11: =Liq0+N11-Cost_r*B11 -> 620 | X11: =W11+O11-Cost_r*C11 -> 620 | Y11: =X11+P11-Cost_r*D11 -> 620 | Z11: =Y11+Q11-Cost_r*E11 -> 570 | AA11: =Z11+R11-Cost_r*F11 -> 555 | AB11: =AA11+S11-Cost_r*G11 -> 660 | AC11: =MIN(MIN(Liq0-Cost_r*B11,W11-Cost_r*C11,X11-Cost_r*D11,Y11-Cost_r*E11,Z11-Cost_r*F11,AA11-Cost_r*G11,MIN(W11:AB11))-Floor_q,AB11-End_q) -> 100 | AD11: =Val_pt*Share/(1-Share*B11)*(SUM(H11:M11)+Credit_M*M11)-Cost_r -> 510 | AE11: =Val_pt*Share/(1-Share*C11)*(SUM(I11:M11)+Credit_M*M11)-Cost_r -> 440 | AF11: =Val_pt*Share/(1-Share*D11)*(SUM(J11:M11)+Credit_M*M11)-Cost_r -> 370 | AG11: =Val_pt*Share/(1-Share*E11)*(SUM(K11:M11)+Credit_M*M11)-Cost_r -> 720 | AH11: =Val_pt*Share/(1-Share*F11)*(SUM(L11:M11)+Credit_M*M11)-Cost_r -> 650 | AI11: =Val_pt*Share/(1-Share*G11)*(SUM(M11:M11)+Credit_M*M11)-Cost_r -> 247.5 | AJ11: =IF(AND(IF(B11=1,AD11>0,AD11<0),IF(C11=1,AE11>0,AE11<0),IF(D11=1,AF11>0,AF11<0),IF(E11=1,AG11>0,AG11<0),IF(F11=1,AH11>0,AH11<0),IF(G11=1,AI11>0,AI11<0)),1,0) -> 0 | AL11: Each slack is affine in each round, so its smallest value over the box [0, 1]^6 is taken at a corner (Online Appendix 4.B.3): 85 over every plan.
A12: 7 | B12: =MOD(INT($A12/32),2) -> 0 | C12: =MOD(INT($A12/16),2) -> 0 | D12: =MOD(INT($A12/8),2) -> 0 | E12: =MOD(INT($A12/4),2) -> 1 | F12: =MOD(INT($A12/2),2) -> 1 | G12: =MOD(INT($A12/1),2) -> 1 | H12: =Gap0*(1-Share*B12) -> 14 | I12: =H12*(1-Share*C12) -> 14 | J12: =I12*(1-Share*D12) -> 14 | K12: =J12*(1-Share*E12) -> 7 | L12: =K12*(1-Share*F12) -> 3.5 | M12: =L12*(1-Share*G12) -> 1.75 | N12: =Smax-Val_pt*H12 -> 0 | O12: =Smax-Val_pt*I12 -> 0 | P12: =Smax-Val_pt*J12 -> 0 | Q12: =Smax-Val_pt*K12 -> 70 | R12: =Smax-Val_pt*L12 -> 105 | S12: =Smax-Val_pt*M12 -> 122.5 | T12: =SUM(B12:G12) -> 3 | U12: =Cash0+SUM(N12:S12)-Cost_r*T12+Credit_M*S12 -> 2537.5 | V12: =Cash0+SUM(N12:S12)-Cost_r*T12+Credit_10*S12 -> 1312.5 | W12: =Liq0+N12-Cost_r*B12 -> 620 | X12: =W12+O12-Cost_r*C12 -> 620 | Y12: =X12+P12-Cost_r*D12 -> 620 | Z12: =Y12+Q12-Cost_r*E12 -> 570 | AA12: =Z12+R12-Cost_r*F12 -> 555 | AB12: =AA12+S12-Cost_r*G12 -> 557.5 | AC12: =MIN(MIN(Liq0-Cost_r*B12,W12-Cost_r*C12,X12-Cost_r*D12,Y12-Cost_r*E12,Z12-Cost_r*F12,AA12-Cost_r*G12,MIN(W12:AB12))-Floor_q,AB12-End_q) -> 85 | AD12: =Val_pt*Share/(1-Share*B12)*(SUM(H12:M12)+Credit_M*M12)-Cost_r -> 326.25 | AE12: =Val_pt*Share/(1-Share*C12)*(SUM(I12:M12)+Credit_M*M12)-Cost_r -> 256.25 | AF12: =Val_pt*Share/(1-Share*D12)*(SUM(J12:M12)+Credit_M*M12)-Cost_r -> 186.25 | AG12: =Val_pt*Share/(1-Share*E12)*(SUM(K12:M12)+Credit_M*M12)-Cost_r -> 352.5 | AH12: =Val_pt*Share/(1-Share*F12)*(SUM(L12:M12)+Credit_M*M12)-Cost_r -> 282.5 | AI12: =Val_pt*Share/(1-Share*G12)*(SUM(M12:M12)+Credit_M*M12)-Cost_r -> 247.5 | AJ12: =IF(AND(IF(B12=1,AD12>0,AD12<0),IF(C12=1,AE12>0,AE12<0),IF(D12=1,AF12>0,AF12<0),IF(E12=1,AG12>0,AG12<0),IF(F12=1,AH12>0,AH12<0),IF(G12=1,AI12>0,AI12<0)),1,0) -> 0
A13: 8 | B13: =MOD(INT($A13/32),2) -> 0 | C13: =MOD(INT($A13/16),2) -> 0 | D13: =MOD(INT($A13/8),2) -> 1 | E13: =MOD(INT($A13/4),2) -> 0 | F13: =MOD(INT($A13/2),2) -> 0 | G13: =MOD(INT($A13/1),2) -> 0 | H13: =Gap0*(1-Share*B13) -> 14 | I13: =H13*(1-Share*C13) -> 14 | J13: =I13*(1-Share*D13) -> 7 | K13: =J13*(1-Share*E13) -> 7 | L13: =K13*(1-Share*F13) -> 7 | M13: =L13*(1-Share*G13) -> 7 | N13: =Smax-Val_pt*H13 -> 0 | O13: =Smax-Val_pt*I13 -> 0 | P13: =Smax-Val_pt*J13 -> 70 | Q13: =Smax-Val_pt*K13 -> 70 | R13: =Smax-Val_pt*L13 -> 70 | S13: =Smax-Val_pt*M13 -> 70 | T13: =SUM(B13:G13) -> 1 | U13: =Cash0+SUM(N13:S13)-Cost_r*T13+Credit_M*S13 -> 1710 | V13: =Cash0+SUM(N13:S13)-Cost_r*T13+Credit_10*S13 -> 1010 | W13: =Liq0+N13-Cost_r*B13 -> 620 | X13: =W13+O13-Cost_r*C13 -> 620 | Y13: =X13+P13-Cost_r*D13 -> 570 | Z13: =Y13+Q13-Cost_r*E13 -> 640 | AA13: =Z13+R13-Cost_r*F13 -> 710 | AB13: =AA13+S13-Cost_r*G13 -> 780 | AC13: =MIN(MIN(Liq0-Cost_r*B13,W13-Cost_r*C13,X13-Cost_r*D13,Y13-Cost_r*E13,Z13-Cost_r*F13,AA13-Cost_r*G13,MIN(W13:AB13))-Floor_q,AB13-End_q) -> 150 | AD13: =Val_pt*Share/(1-Share*B13)*(SUM(H13:M13)+Credit_M*M13)-Cost_r -> 860 | AE13: =Val_pt*Share/(1-Share*C13)*(SUM(I13:M13)+Credit_M*M13)-Cost_r -> 790 | AF13: =Val_pt*Share/(1-Share*D13)*(SUM(J13:M13)+Credit_M*M13)-Cost_r -> 1560 | AG13: =Val_pt*Share/(1-Share*E13)*(SUM(K13:M13)+Credit_M*M13)-Cost_r -> 685 | AH13: =Val_pt*Share/(1-Share*F13)*(SUM(L13:M13)+Credit_M*M13)-Cost_r -> 650 | AI13: =Val_pt*Share/(1-Share*G13)*(SUM(M13:M13)+Credit_M*M13)-Cost_r -> 615 | AJ13: =IF(AND(IF(B13=1,AD13>0,AD13<0),IF(C13=1,AE13>0,AE13<0),IF(D13=1,AF13>0,AF13<0),IF(E13=1,AG13>0,AG13<0),IF(F13=1,AH13>0,AH13<0),IF(G13=1,AI13>0,AI13<0)),1,0) -> 0
A14: 9 | B14: =MOD(INT($A14/32),2) -> 0 | C14: =MOD(INT($A14/16),2) -> 0 | D14: =MOD(INT($A14/8),2) -> 1 | E14: =MOD(INT($A14/4),2) -> 0 | F14: =MOD(INT($A14/2),2) -> 0 | G14: =MOD(INT($A14/1),2) -> 1 | H14: =Gap0*(1-Share*B14) -> 14 | I14: =H14*(1-Share*C14) -> 14 | J14: =I14*(1-Share*D14) -> 7 | K14: =J14*(1-Share*E14) -> 7 | L14: =K14*(1-Share*F14) -> 7 | M14: =L14*(1-Share*G14) -> 3.5 | N14: =Smax-Val_pt*H14 -> 0 | O14: =Smax-Val_pt*I14 -> 0 | P14: =Smax-Val_pt*J14 -> 70 | Q14: =Smax-Val_pt*K14 -> 70 | R14: =Smax-Val_pt*L14 -> 70 | S14: =Smax-Val_pt*M14 -> 105 | T14: =SUM(B14:G14) -> 2 | U14: =Cash0+SUM(N14:S14)-Cost_r*T14+Credit_M*S14 -> 2325 | V14: =Cash0+SUM(N14:S14)-Cost_r*T14+Credit_10*S14 -> 1275 | W14: =Liq0+N14-Cost_r*B14 -> 620 | X14: =W14+O14-Cost_r*C14 -> 620 | Y14: =X14+P14-Cost_r*D14 -> 570 | Z14: =Y14+Q14-Cost_r*E14 -> 640 | AA14: =Z14+R14-Cost_r*F14 -> 710 | AB14: =AA14+S14-Cost_r*G14 -> 695 | AC14: =MIN(MIN(Liq0-Cost_r*B14,W14-Cost_r*C14,X14-Cost_r*D14,Y14-Cost_r*E14,Z14-Cost_r*F14,AA14-Cost_r*G14,MIN(W14:AB14))-Floor_q,AB14-End_q) -> 150 | AD14: =Val_pt*Share/(1-Share*B14)*(SUM(H14:M14)+Credit_M*M14)-Cost_r -> 492.5 | AE14: =Val_pt*Share/(1-Share*C14)*(SUM(I14:M14)+Credit_M*M14)-Cost_r -> 422.5 | AF14: =Val_pt*Share/(1-Share*D14)*(SUM(J14:M14)+Credit_M*M14)-Cost_r -> 825 | AG14: =Val_pt*Share/(1-Share*E14)*(SUM(K14:M14)+Credit_M*M14)-Cost_r -> 317.5 | AH14: =Val_pt*Share/(1-Share*F14)*(SUM(L14:M14)+Credit_M*M14)-Cost_r -> 282.5 | AI14: =Val_pt*Share/(1-Share*G14)*(SUM(M14:M14)+Credit_M*M14)-Cost_r -> 615 | AJ14: =IF(AND(IF(B14=1,AD14>0,AD14<0),IF(C14=1,AE14>0,AE14<0),IF(D14=1,AF14>0,AF14<0),IF(E14=1,AG14>0,AG14<0),IF(F14=1,AH14>0,AH14<0),IF(G14=1,AI14>0,AI14<0)),1,0) -> 0
A15: 10 | B15: =MOD(INT($A15/32),2) -> 0 | C15: =MOD(INT($A15/16),2) -> 0 | D15: =MOD(INT($A15/8),2) -> 1 | E15: =MOD(INT($A15/4),2) -> 0 | F15: =MOD(INT($A15/2),2) -> 1 | G15: =MOD(INT($A15/1),2) -> 0 | H15: =Gap0*(1-Share*B15) -> 14 | I15: =H15*(1-Share*C15) -> 14 | J15: =I15*(1-Share*D15) -> 7 | K15: =J15*(1-Share*E15) -> 7 | L15: =K15*(1-Share*F15) -> 3.5 | M15: =L15*(1-Share*G15) -> 3.5 | N15: =Smax-Val_pt*H15 -> 0 | O15: =Smax-Val_pt*I15 -> 0 | P15: =Smax-Val_pt*J15 -> 70 | Q15: =Smax-Val_pt*K15 -> 70 | R15: =Smax-Val_pt*L15 -> 105 | S15: =Smax-Val_pt*M15 -> 105 | T15: =SUM(B15:G15) -> 2 | U15: =Cash0+SUM(N15:S15)-Cost_r*T15+Credit_M*S15 -> 2360 | V15: =Cash0+SUM(N15:S15)-Cost_r*T15+Credit_10*S15 -> 1310 | W15: =Liq0+N15-Cost_r*B15 -> 620 | X15: =W15+O15-Cost_r*C15 -> 620 | Y15: =X15+P15-Cost_r*D15 -> 570 | Z15: =Y15+Q15-Cost_r*E15 -> 640 | AA15: =Z15+R15-Cost_r*F15 -> 625 | AB15: =AA15+S15-Cost_r*G15 -> 730 | AC15: =MIN(MIN(Liq0-Cost_r*B15,W15-Cost_r*C15,X15-Cost_r*D15,Y15-Cost_r*E15,Z15-Cost_r*F15,AA15-Cost_r*G15,MIN(W15:AB15))-Floor_q,AB15-End_q) -> 150 | AD15: =Val_pt*Share/(1-Share*B15)*(SUM(H15:M15)+Credit_M*M15)-Cost_r -> 475 | AE15: =Val_pt*Share/(1-Share*C15)*(SUM(I15:M15)+Credit_M*M15)-Cost_r -> 405 | AF15: =Val_pt*Share/(1-Share*D15)*(SUM(J15:M15)+Credit_M*M15)-Cost_r -> 790 | AG15: =Val_pt*Share/(1-Share*E15)*(SUM(K15:M15)+Credit_M*M15)-Cost_r -> 300 | AH15: =Val_pt*Share/(1-Share*F15)*(SUM(L15:M15)+Credit_M*M15)-Cost_r -> 650 | AI15: =Val_pt*Share/(1-Share*G15)*(SUM(M15:M15)+Credit_M*M15)-Cost_r -> 247.5 | AJ15: =IF(AND(IF(B15=1,AD15>0,AD15<0),IF(C15=1,AE15>0,AE15<0),IF(D15=1,AF15>0,AF15<0),IF(E15=1,AG15>0,AG15<0),IF(F15=1,AH15>0,AH15<0),IF(G15=1,AI15>0,AI15<0)),1,0) -> 0
A16: 11 | B16: =MOD(INT($A16/32),2) -> 0 | C16: =MOD(INT($A16/16),2) -> 0 | D16: =MOD(INT($A16/8),2) -> 1 | E16: =MOD(INT($A16/4),2) -> 0 | F16: =MOD(INT($A16/2),2) -> 1 | G16: =MOD(INT($A16/1),2) -> 1 | H16: =Gap0*(1-Share*B16) -> 14 | I16: =H16*(1-Share*C16) -> 14 | J16: =I16*(1-Share*D16) -> 7 | K16: =J16*(1-Share*E16) -> 7 | L16: =K16*(1-Share*F16) -> 3.5 | M16: =L16*(1-Share*G16) -> 1.75 | N16: =Smax-Val_pt*H16 -> 0 | O16: =Smax-Val_pt*I16 -> 0 | P16: =Smax-Val_pt*J16 -> 70 | Q16: =Smax-Val_pt*K16 -> 70 | R16: =Smax-Val_pt*L16 -> 105 | S16: =Smax-Val_pt*M16 -> 122.5 | T16: =SUM(B16:G16) -> 3 | U16: =Cash0+SUM(N16:S16)-Cost_r*T16+Credit_M*S16 -> 2607.5 | V16: =Cash0+SUM(N16:S16)-Cost_r*T16+Credit_10*S16 -> 1382.5 | W16: =Liq0+N16-Cost_r*B16 -> 620 | X16: =W16+O16-Cost_r*C16 -> 620 | Y16: =X16+P16-Cost_r*D16 -> 570 | Z16: =Y16+Q16-Cost_r*E16 -> 640 | AA16: =Z16+R16-Cost_r*F16 -> 625 | AB16: =AA16+S16-Cost_r*G16 -> 627.5 | AC16: =MIN(MIN(Liq0-Cost_r*B16,W16-Cost_r*C16,X16-Cost_r*D16,Y16-Cost_r*E16,Z16-Cost_r*F16,AA16-Cost_r*G16,MIN(W16:AB16))-Floor_q,AB16-End_q) -> 150 | AD16: =Val_pt*Share/(1-Share*B16)*(SUM(H16:M16)+Credit_M*M16)-Cost_r -> 291.25 | AE16: =Val_pt*Share/(1-Share*C16)*(SUM(I16:M16)+Credit_M*M16)-Cost_r -> 221.25 | AF16: =Val_pt*Share/(1-Share*D16)*(SUM(J16:M16)+Credit_M*M16)-Cost_r -> 422.5 | AG16: =Val_pt*Share/(1-Share*E16)*(SUM(K16:M16)+Credit_M*M16)-Cost_r -> 116.25 | AH16: =Val_pt*Share/(1-Share*F16)*(SUM(L16:M16)+Credit_M*M16)-Cost_r -> 282.5 | AI16: =Val_pt*Share/(1-Share*G16)*(SUM(M16:M16)+Credit_M*M16)-Cost_r -> 247.5 | AJ16: =IF(AND(IF(B16=1,AD16>0,AD16<0),IF(C16=1,AE16>0,AE16<0),IF(D16=1,AF16>0,AF16<0),IF(E16=1,AG16>0,AG16<0),IF(F16=1,AH16>0,AH16<0),IF(G16=1,AI16>0,AI16<0)),1,0) -> 0
A17: 12 | B17: =MOD(INT($A17/32),2) -> 0 | C17: =MOD(INT($A17/16),2) -> 0 | D17: =MOD(INT($A17/8),2) -> 1 | E17: =MOD(INT($A17/4),2) -> 1 | F17: =MOD(INT($A17/2),2) -> 0 | G17: =MOD(INT($A17/1),2) -> 0 | H17: =Gap0*(1-Share*B17) -> 14 | I17: =H17*(1-Share*C17) -> 14 | J17: =I17*(1-Share*D17) -> 7 | K17: =J17*(1-Share*E17) -> 3.5 | L17: =K17*(1-Share*F17) -> 3.5 | M17: =L17*(1-Share*G17) -> 3.5 | N17: =Smax-Val_pt*H17 -> 0 | O17: =Smax-Val_pt*I17 -> 0 | P17: =Smax-Val_pt*J17 -> 70 | Q17: =Smax-Val_pt*K17 -> 105 | R17: =Smax-Val_pt*L17 -> 105 | S17: =Smax-Val_pt*M17 -> 105 | T17: =SUM(B17:G17) -> 2 | U17: =Cash0+SUM(N17:S17)-Cost_r*T17+Credit_M*S17 -> 2395 | V17: =Cash0+SUM(N17:S17)-Cost_r*T17+Credit_10*S17 -> 1345 | W17: =Liq0+N17-Cost_r*B17 -> 620 | X17: =W17+O17-Cost_r*C17 -> 620 | Y17: =X17+P17-Cost_r*D17 -> 570 | Z17: =Y17+Q17-Cost_r*E17 -> 555 | AA17: =Z17+R17-Cost_r*F17 -> 660 | AB17: =AA17+S17-Cost_r*G17 -> 765 | AC17: =MIN(MIN(Liq0-Cost_r*B17,W17-Cost_r*C17,X17-Cost_r*D17,Y17-Cost_r*E17,Z17-Cost_r*F17,AA17-Cost_r*G17,MIN(W17:AB17))-Floor_q,AB17-End_q) -> 100 | AD17: =Val_pt*Share/(1-Share*B17)*(SUM(H17:M17)+Credit_M*M17)-Cost_r -> 457.5 | AE17: =Val_pt*Share/(1-Share*C17)*(SUM(I17:M17)+Credit_M*M17)-Cost_r -> 387.5 | AF17: =Val_pt*Share/(1-Share*D17)*(SUM(J17:M17)+Credit_M*M17)-Cost_r -> 755 | AG17: =Val_pt*Share/(1-Share*E17)*(SUM(K17:M17)+Credit_M*M17)-Cost_r -> 685 | AH17: =Val_pt*Share/(1-Share*F17)*(SUM(L17:M17)+Credit_M*M17)-Cost_r -> 265 | AI17: =Val_pt*Share/(1-Share*G17)*(SUM(M17:M17)+Credit_M*M17)-Cost_r -> 247.5 | AJ17: =IF(AND(IF(B17=1,AD17>0,AD17<0),IF(C17=1,AE17>0,AE17<0),IF(D17=1,AF17>0,AF17<0),IF(E17=1,AG17>0,AG17<0),IF(F17=1,AH17>0,AH17<0),IF(G17=1,AI17>0,AI17<0)),1,0) -> 0
A18: 13 | B18: =MOD(INT($A18/32),2) -> 0 | C18: =MOD(INT($A18/16),2) -> 0 | D18: =MOD(INT($A18/8),2) -> 1 | E18: =MOD(INT($A18/4),2) -> 1 | F18: =MOD(INT($A18/2),2) -> 0 | G18: =MOD(INT($A18/1),2) -> 1 | H18: =Gap0*(1-Share*B18) -> 14 | I18: =H18*(1-Share*C18) -> 14 | J18: =I18*(1-Share*D18) -> 7 | K18: =J18*(1-Share*E18) -> 3.5 | L18: =K18*(1-Share*F18) -> 3.5 | M18: =L18*(1-Share*G18) -> 1.75 | N18: =Smax-Val_pt*H18 -> 0 | O18: =Smax-Val_pt*I18 -> 0 | P18: =Smax-Val_pt*J18 -> 70 | Q18: =Smax-Val_pt*K18 -> 105 | R18: =Smax-Val_pt*L18 -> 105 | S18: =Smax-Val_pt*M18 -> 122.5 | T18: =SUM(B18:G18) -> 3 | U18: =Cash0+SUM(N18:S18)-Cost_r*T18+Credit_M*S18 -> 2642.5 | V18: =Cash0+SUM(N18:S18)-Cost_r*T18+Credit_10*S18 -> 1417.5 | W18: =Liq0+N18-Cost_r*B18 -> 620 | X18: =W18+O18-Cost_r*C18 -> 620 | Y18: =X18+P18-Cost_r*D18 -> 570 | Z18: =Y18+Q18-Cost_r*E18 -> 555 | AA18: =Z18+R18-Cost_r*F18 -> 660 | AB18: =AA18+S18-Cost_r*G18 -> 662.5 | AC18: =MIN(MIN(Liq0-Cost_r*B18,W18-Cost_r*C18,X18-Cost_r*D18,Y18-Cost_r*E18,Z18-Cost_r*F18,AA18-Cost_r*G18,MIN(W18:AB18))-Floor_q,AB18-End_q) -> 100 | AD18: =Val_pt*Share/(1-Share*B18)*(SUM(H18:M18)+Credit_M*M18)-Cost_r -> 273.75 | AE18: =Val_pt*Share/(1-Share*C18)*(SUM(I18:M18)+Credit_M*M18)-Cost_r -> 203.75 | AF18: =Val_pt*Share/(1-Share*D18)*(SUM(J18:M18)+Credit_M*M18)-Cost_r -> 387.5 | AG18: =Val_pt*Share/(1-Share*E18)*(SUM(K18:M18)+Credit_M*M18)-Cost_r -> 317.5 | AH18: =Val_pt*Share/(1-Share*F18)*(SUM(L18:M18)+Credit_M*M18)-Cost_r -> 81.25 | AI18: =Val_pt*Share/(1-Share*G18)*(SUM(M18:M18)+Credit_M*M18)-Cost_r -> 247.5 | AJ18: =IF(AND(IF(B18=1,AD18>0,AD18<0),IF(C18=1,AE18>0,AE18<0),IF(D18=1,AF18>0,AF18<0),IF(E18=1,AG18>0,AG18<0),IF(F18=1,AH18>0,AH18<0),IF(G18=1,AI18>0,AI18<0)),1,0) -> 0
A19: 14 | B19: =MOD(INT($A19/32),2) -> 0 | C19: =MOD(INT($A19/16),2) -> 0 | D19: =MOD(INT($A19/8),2) -> 1 | E19: =MOD(INT($A19/4),2) -> 1 | F19: =MOD(INT($A19/2),2) -> 1 | G19: =MOD(INT($A19/1),2) -> 0 | H19: =Gap0*(1-Share*B19) -> 14 | I19: =H19*(1-Share*C19) -> 14 | J19: =I19*(1-Share*D19) -> 7 | K19: =J19*(1-Share*E19) -> 3.5 | L19: =K19*(1-Share*F19) -> 1.75 | M19: =L19*(1-Share*G19) -> 1.75 | N19: =Smax-Val_pt*H19 -> 0 | O19: =Smax-Val_pt*I19 -> 0 | P19: =Smax-Val_pt*J19 -> 70 | Q19: =Smax-Val_pt*K19 -> 105 | R19: =Smax-Val_pt*L19 -> 122.5 | S19: =Smax-Val_pt*M19 -> 122.5 | T19: =SUM(B19:G19) -> 3 | U19: =Cash0+SUM(N19:S19)-Cost_r*T19+Credit_M*S19 -> 2660 | V19: =Cash0+SUM(N19:S19)-Cost_r*T19+Credit_10*S19 -> 1435 | W19: =Liq0+N19-Cost_r*B19 -> 620 | X19: =W19+O19-Cost_r*C19 -> 620 | Y19: =X19+P19-Cost_r*D19 -> 570 | Z19: =Y19+Q19-Cost_r*E19 -> 555 | AA19: =Z19+R19-Cost_r*F19 -> 557.5 | AB19: =AA19+S19-Cost_r*G19 -> 680 | AC19: =MIN(MIN(Liq0-Cost_r*B19,W19-Cost_r*C19,X19-Cost_r*D19,Y19-Cost_r*E19,Z19-Cost_r*F19,AA19-Cost_r*G19,MIN(W19:AB19))-Floor_q,AB19-End_q) -> 85 | AD19: =Val_pt*Share/(1-Share*B19)*(SUM(H19:M19)+Credit_M*M19)-Cost_r -> 265 | AE19: =Val_pt*Share/(1-Share*C19)*(SUM(I19:M19)+Credit_M*M19)-Cost_r -> 195 | AF19: =Val_pt*Share/(1-Share*D19)*(SUM(J19:M19)+Credit_M*M19)-Cost_r -> 370 | AG19: =Val_pt*Share/(1-Share*E19)*(SUM(K19:M19)+Credit_M*M19)-Cost_r -> 300 | AH19: =Val_pt*Share/(1-Share*F19)*(SUM(L19:M19)+Credit_M*M19)-Cost_r -> 265 | AI19: =Val_pt*Share/(1-Share*G19)*(SUM(M19:M19)+Credit_M*M19)-Cost_r -> 63.75 | AJ19: =IF(AND(IF(B19=1,AD19>0,AD19<0),IF(C19=1,AE19>0,AE19<0),IF(D19=1,AF19>0,AF19<0),IF(E19=1,AG19>0,AG19<0),IF(F19=1,AH19>0,AH19<0),IF(G19=1,AI19>0,AI19<0)),1,0) -> 0
A20: 15 | B20: =MOD(INT($A20/32),2) -> 0 | C20: =MOD(INT($A20/16),2) -> 0 | D20: =MOD(INT($A20/8),2) -> 1 | E20: =MOD(INT($A20/4),2) -> 1 | F20: =MOD(INT($A20/2),2) -> 1 | G20: =MOD(INT($A20/1),2) -> 1 | H20: =Gap0*(1-Share*B20) -> 14 | I20: =H20*(1-Share*C20) -> 14 | J20: =I20*(1-Share*D20) -> 7 | K20: =J20*(1-Share*E20) -> 3.5 | L20: =K20*(1-Share*F20) -> 1.75 | M20: =L20*(1-Share*G20) -> 0.875 | N20: =Smax-Val_pt*H20 -> 0 | O20: =Smax-Val_pt*I20 -> 0 | P20: =Smax-Val_pt*J20 -> 70 | Q20: =Smax-Val_pt*K20 -> 105 | R20: =Smax-Val_pt*L20 -> 122.5 | S20: =Smax-Val_pt*M20 -> 131.25 | T20: =SUM(B20:G20) -> 4 | U20: =Cash0+SUM(N20:S20)-Cost_r*T20+Credit_M*S20 -> 2723.75 | V20: =Cash0+SUM(N20:S20)-Cost_r*T20+Credit_10*S20 -> 1411.25 | W20: =Liq0+N20-Cost_r*B20 -> 620 | X20: =W20+O20-Cost_r*C20 -> 620 | Y20: =X20+P20-Cost_r*D20 -> 570 | Z20: =Y20+Q20-Cost_r*E20 -> 555 | AA20: =Z20+R20-Cost_r*F20 -> 557.5 | AB20: =AA20+S20-Cost_r*G20 -> 568.75 | AC20: =MIN(MIN(Liq0-Cost_r*B20,W20-Cost_r*C20,X20-Cost_r*D20,Y20-Cost_r*E20,Z20-Cost_r*F20,AA20-Cost_r*G20,MIN(W20:AB20))-Floor_q,AB20-End_q) -> 85 | AD20: =Val_pt*Share/(1-Share*B20)*(SUM(H20:M20)+Credit_M*M20)-Cost_r -> 173.125 | AE20: =Val_pt*Share/(1-Share*C20)*(SUM(I20:M20)+Credit_M*M20)-Cost_r -> 103.125 | AF20: =Val_pt*Share/(1-Share*D20)*(SUM(J20:M20)+Credit_M*M20)-Cost_r -> 186.25 | AG20: =Val_pt*Share/(1-Share*E20)*(SUM(K20:M20)+Credit_M*M20)-Cost_r -> 116.25 | AH20: =Val_pt*Share/(1-Share*F20)*(SUM(L20:M20)+Credit_M*M20)-Cost_r -> 81.25 | AI20: =Val_pt*Share/(1-Share*G20)*(SUM(M20:M20)+Credit_M*M20)-Cost_r -> 63.75 | AJ20: =IF(AND(IF(B20=1,AD20>0,AD20<0),IF(C20=1,AE20>0,AE20<0),IF(D20=1,AF20>0,AF20<0),IF(E20=1,AG20>0,AG20<0),IF(F20=1,AH20>0,AH20<0),IF(G20=1,AI20>0,AI20<0)),1,0) -> 0
A21: 16 | B21: =MOD(INT($A21/32),2) -> 0 | C21: =MOD(INT($A21/16),2) -> 1 | D21: =MOD(INT($A21/8),2) -> 0 | E21: =MOD(INT($A21/4),2) -> 0 | F21: =MOD(INT($A21/2),2) -> 0 | G21: =MOD(INT($A21/1),2) -> 0 | H21: =Gap0*(1-Share*B21) -> 14 | I21: =H21*(1-Share*C21) -> 7 | J21: =I21*(1-Share*D21) -> 7 | K21: =J21*(1-Share*E21) -> 7 | L21: =K21*(1-Share*F21) -> 7 | M21: =L21*(1-Share*G21) -> 7 | N21: =Smax-Val_pt*H21 -> 0 | O21: =Smax-Val_pt*I21 -> 70 | P21: =Smax-Val_pt*J21 -> 70 | Q21: =Smax-Val_pt*K21 -> 70 | R21: =Smax-Val_pt*L21 -> 70 | S21: =Smax-Val_pt*M21 -> 70 | T21: =SUM(B21:G21) -> 1 | U21: =Cash0+SUM(N21:S21)-Cost_r*T21+Credit_M*S21 -> 1780 | V21: =Cash0+SUM(N21:S21)-Cost_r*T21+Credit_10*S21 -> 1080 | W21: =Liq0+N21-Cost_r*B21 -> 620 | X21: =W21+O21-Cost_r*C21 -> 570 | Y21: =X21+P21-Cost_r*D21 -> 640 | Z21: =Y21+Q21-Cost_r*E21 -> 710 | AA21: =Z21+R21-Cost_r*F21 -> 780 | AB21: =AA21+S21-Cost_r*G21 -> 850 | AC21: =MIN(MIN(Liq0-Cost_r*B21,W21-Cost_r*C21,X21-Cost_r*D21,Y21-Cost_r*E21,Z21-Cost_r*F21,AA21-Cost_r*G21,MIN(W21:AB21))-Floor_q,AB21-End_q) -> 150 | AD21: =Val_pt*Share/(1-Share*B21)*(SUM(H21:M21)+Credit_M*M21)-Cost_r -> 825 | AE21: =Val_pt*Share/(1-Share*C21)*(SUM(I21:M21)+Credit_M*M21)-Cost_r -> 1630 | AF21: =Val_pt*Share/(1-Share*D21)*(SUM(J21:M21)+Credit_M*M21)-Cost_r -> 720 | AG21: =Val_pt*Share/(1-Share*E21)*(SUM(K21:M21)+Credit_M*M21)-Cost_r -> 685 | AH21: =Val_pt*Share/(1-Share*F21)*(SUM(L21:M21)+Credit_M*M21)-Cost_r -> 650 | AI21: =Val_pt*Share/(1-Share*G21)*(SUM(M21:M21)+Credit_M*M21)-Cost_r -> 615 | AJ21: =IF(AND(IF(B21=1,AD21>0,AD21<0),IF(C21=1,AE21>0,AE21<0),IF(D21=1,AF21>0,AF21<0),IF(E21=1,AG21>0,AG21<0),IF(F21=1,AH21>0,AH21<0),IF(G21=1,AI21>0,AI21<0)),1,0) -> 0
A22: 17 | B22: =MOD(INT($A22/32),2) -> 0 | C22: =MOD(INT($A22/16),2) -> 1 | D22: =MOD(INT($A22/8),2) -> 0 | E22: =MOD(INT($A22/4),2) -> 0 | F22: =MOD(INT($A22/2),2) -> 0 | G22: =MOD(INT($A22/1),2) -> 1 | H22: =Gap0*(1-Share*B22) -> 14 | I22: =H22*(1-Share*C22) -> 7 | J22: =I22*(1-Share*D22) -> 7 | K22: =J22*(1-Share*E22) -> 7 | L22: =K22*(1-Share*F22) -> 7 | M22: =L22*(1-Share*G22) -> 3.5 | N22: =Smax-Val_pt*H22 -> 0 | O22: =Smax-Val_pt*I22 -> 70 | P22: =Smax-Val_pt*J22 -> 70 | Q22: =Smax-Val_pt*K22 -> 70 | R22: =Smax-Val_pt*L22 -> 70 | S22: =Smax-Val_pt*M22 -> 105 | T22: =SUM(B22:G22) -> 2 | U22: =Cash0+SUM(N22:S22)-Cost_r*T22+Credit_M*S22 -> 2395 | V22: =Cash0+SUM(N22:S22)-Cost_r*T22+Credit_10*S22 -> 1345 | W22: =Liq0+N22-Cost_r*B22 -> 620 | X22: =W22+O22-Cost_r*C22 -> 570 | Y22: =X22+P22-Cost_r*D22 -> 640 | Z22: =Y22+Q22-Cost_r*E22 -> 710 | AA22: =Z22+R22-Cost_r*F22 -> 780 | AB22: =AA22+S22-Cost_r*G22 -> 765 | AC22: =MIN(MIN(Liq0-Cost_r*B22,W22-Cost_r*C22,X22-Cost_r*D22,Y22-Cost_r*E22,Z22-Cost_r*F22,AA22-Cost_r*G22,MIN(W22:AB22))-Floor_q,AB22-End_q) -> 150 | AD22: =Val_pt*Share/(1-Share*B22)*(SUM(H22:M22)+Credit_M*M22)-Cost_r -> 457.5 | AE22: =Val_pt*Share/(1-Share*C22)*(SUM(I22:M22)+Credit_M*M22)-Cost_r -> 895 | AF22: =Val_pt*Share/(1-Share*D22)*(SUM(J22:M22)+Credit_M*M22)-Cost_r -> 352.5 | AG22: =Val_pt*Share/(1-Share*E22)*(SUM(K22:M22)+Credit_M*M22)-Cost_r -> 317.5 | AH22: =Val_pt*Share/(1-Share*F22)*(SUM(L22:M22)+Credit_M*M22)-Cost_r -> 282.5 | AI22: =Val_pt*Share/(1-Share*G22)*(SUM(M22:M22)+Credit_M*M22)-Cost_r -> 615 | AJ22: =IF(AND(IF(B22=1,AD22>0,AD22<0),IF(C22=1,AE22>0,AE22<0),IF(D22=1,AF22>0,AF22<0),IF(E22=1,AG22>0,AG22<0),IF(F22=1,AH22>0,AH22<0),IF(G22=1,AI22>0,AI22<0)),1,0) -> 0
A23: 18 | B23: =MOD(INT($A23/32),2) -> 0 | C23: =MOD(INT($A23/16),2) -> 1 | D23: =MOD(INT($A23/8),2) -> 0 | E23: =MOD(INT($A23/4),2) -> 0 | F23: =MOD(INT($A23/2),2) -> 1 | G23: =MOD(INT($A23/1),2) -> 0 | H23: =Gap0*(1-Share*B23) -> 14 | I23: =H23*(1-Share*C23) -> 7 | J23: =I23*(1-Share*D23) -> 7 | K23: =J23*(1-Share*E23) -> 7 | L23: =K23*(1-Share*F23) -> 3.5 | M23: =L23*(1-Share*G23) -> 3.5 | N23: =Smax-Val_pt*H23 -> 0 | O23: =Smax-Val_pt*I23 -> 70 | P23: =Smax-Val_pt*J23 -> 70 | Q23: =Smax-Val_pt*K23 -> 70 | R23: =Smax-Val_pt*L23 -> 105 | S23: =Smax-Val_pt*M23 -> 105 | T23: =SUM(B23:G23) -> 2 | U23: =Cash0+SUM(N23:S23)-Cost_r*T23+Credit_M*S23 -> 2430 | V23: =Cash0+SUM(N23:S23)-Cost_r*T23+Credit_10*S23 -> 1380 | W23: =Liq0+N23-Cost_r*B23 -> 620 | X23: =W23+O23-Cost_r*C23 -> 570 | Y23: =X23+P23-Cost_r*D23 -> 640 | Z23: =Y23+Q23-Cost_r*E23 -> 710 | AA23: =Z23+R23-Cost_r*F23 -> 695 | AB23: =AA23+S23-Cost_r*G23 -> 800 | AC23: =MIN(MIN(Liq0-Cost_r*B23,W23-Cost_r*C23,X23-Cost_r*D23,Y23-Cost_r*E23,Z23-Cost_r*F23,AA23-Cost_r*G23,MIN(W23:AB23))-Floor_q,AB23-End_q) -> 150 | AD23: =Val_pt*Share/(1-Share*B23)*(SUM(H23:M23)+Credit_M*M23)-Cost_r -> 440 | AE23: =Val_pt*Share/(1-Share*C23)*(SUM(I23:M23)+Credit_M*M23)-Cost_r -> 860 | AF23: =Val_pt*Share/(1-Share*D23)*(SUM(J23:M23)+Credit_M*M23)-Cost_r -> 335 | AG23: =Val_pt*Share/(1-Share*E23)*(SUM(K23:M23)+Credit_M*M23)-Cost_r -> 300 | AH23: =Val_pt*Share/(1-Share*F23)*(SUM(L23:M23)+Credit_M*M23)-Cost_r -> 650 | AI23: =Val_pt*Share/(1-Share*G23)*(SUM(M23:M23)+Credit_M*M23)-Cost_r -> 247.5 | AJ23: =IF(AND(IF(B23=1,AD23>0,AD23<0),IF(C23=1,AE23>0,AE23<0),IF(D23=1,AF23>0,AF23<0),IF(E23=1,AG23>0,AG23<0),IF(F23=1,AH23>0,AH23<0),IF(G23=1,AI23>0,AI23<0)),1,0) -> 0
... A68: 63 | B68: =MOD(INT($A68/32),2) -> 1 | C68: =MOD(INT($A68/16),2) -> 1 | D68: =MOD(INT($A68/8),2) -> 1 | E68: =MOD(INT($A68/4),2) -> 1 | F68: =MOD(INT($A68/2),2) -> 1 | G68: =MOD(INT($A68/1),2) -> 1 | H68: =Gap0*(1-Share*B68) -> 7 | I68: =H68*(1-Share*C68) -> 3.5 | J68: =I68*(1-Share*D68) -> 1.75 | K68: =J68*(1-Share*E68) -> 0.875 | L68: =K68*(1-Share*F68) -> 0.4375 | M68: =L68*(1-Share*G68) -> 0.21875 | N68: =Smax-Val_pt*H68 -> 70 | O68: =Smax-Val_pt*I68 -> 105 | P68: =Smax-Val_pt*J68 -> 122.5 | Q68: =Smax-Val_pt*K68 -> 131.25 | R68: =Smax-Val_pt*L68 -> 135.625 | S68: =Smax-Val_pt*M68 -> 137.8125 | T68: =SUM(B68:G68) -> 6 | U68: =Cash0+SUM(N68:S68)-Cost_r*T68+Credit_M*S68 -> 2888.4375 | V68: =Cash0+SUM(N68:S68)-Cost_r*T68+Credit_10*S68 -> 1510.3125 | W68: =Liq0+N68-Cost_r*B68 -> 570 | X68: =W68+O68-Cost_r*C68 -> 555 | Y68: =X68+P68-Cost_r*D68 -> 557.5 | Z68: =Y68+Q68-Cost_r*E68 -> 568.75 | AA68: =Z68+R68-Cost_r*F68 -> 584.375 | AB68: =AA68+S68-Cost_r*G68 -> 602.1875 | AC68: =MIN(MIN(Liq0-Cost_r*B68,W68-Cost_r*C68,X68-Cost_r*D68,Y68-Cost_r*E68,Z68-Cost_r*F68,AA68-Cost_r*G68,MIN(W68:AB68))-Floor_q,AB68-End_q) -> 85 | AD68: =Val_pt*Share/(1-Share*B68)*(SUM(H68:M68)+Credit_M*M68)-Cost_r -> 61.5625 | AE68: =Val_pt*Share/(1-Share*C68)*(SUM(I68:M68)+Credit_M*M68)-Cost_r -> -8.4375 | AF68: =Val_pt*Share/(1-Share*D68)*(SUM(J68:M68)+Credit_M*M68)-Cost_r -> -43.4375 | AG68: =Val_pt*Share/(1-Share*E68)*(SUM(K68:M68)+Credit_M*M68)-Cost_r -> -60.9375 | AH68: =Val_pt*Share/(1-Share*F68)*(SUM(L68:M68)+Credit_M*M68)-Cost_r -> -69.6875 | AI68: =Val_pt*Share/(1-Share*G68)*(SUM(M68:M68)+Credit_M*M68)-Cost_r -> -74.0625 | AJ68: =IF(AND(IF(B68=1,AD68>0,AD68<0),IF(C68=1,AE68>0,AE68<0),IF(D68=1,AF68>0,AF68<0),IF(E68=1,AG68>0,AG68<0),IF(F68=1,AH68>0,AH68<0),IF(G68=1,AI68>0,AI68<0)),1,0) -> 0

Sheet Face
A1: Explore: the face where only years 4 and 5 vary (AXIOM Lab 2.4, step 1; Figure 4.1(a))
A2: Years 1-3 whole, none in year 6, x of a year-4 round and y of a year-5 round: V = a + b x + c y + d x y, read from the four corners on the Schedules sheet.
A3: Coefficient | B3: Value | C3: Reading
A4: a = V(0, 0), years 1–3 | B4: =INDEX(Schedules!$U$5:$U$68,57) -> 2905 | C4: 2,905
A5: b = V(1, 0) - a | B5: =INDEX(Schedules!$U$5:$U$68,61)-B4 -> 81.25 | C5: 81.25
A6: c = V(0, 1) - a | B6: =INDEX(Schedules!$U$5:$U$68,59)-B4 -> 72.5 | C6: 72.50
A7: d = V(1, 1) - V(1, 0) - V(0, 1) + a | B7: =INDEX(Schedules!$U$5:$U$68,63)-INDEX(Schedules!$U$5:$U$68,61)-INDEX(Schedules!$U$5:$U$68,59)+B4 -> -96.25 | C7: -96.25
A9: Corner (x, y) | B9: x | C9: y | D9: V | E9: Marginal value of x | F9: Marginal value of y | G9: Verdict
A10: years 1–3 | B10: 0 | C10: 0 | D10: =$B$4+$B$5*B10+$B$6*C10+$B$7*B10*C10 -> 2905 | E10: =$B$5+$B$7*C10 -> 81.25 | F10: =$B$6+$B$7*B10 -> 72.5 | G10: =IF(AND(IF(B10=1,E10>0,E10<0),IF(C10=1,F10>0,F10<0)),"strict local maximum","not a local maximum") -> not a local maximum
A11: years 1–4 | B11: 1 | C11: 0 | D11: =$B$4+$B$5*B11+$B$6*C11+$B$7*B11*C11 -> 2986.25 | E11: =$B$5+$B$7*C11 -> 81.25 | F11: =$B$6+$B$7*B11 -> -23.75 | G11: =IF(AND(IF(B11=1,E11>0,E11<0),IF(C11=1,F11>0,F11<0)),"strict local maximum","not a local maximum") -> strict local maximum
A12: years 1–3 and 5 | B12: 0 | C12: 1 | D12: =$B$4+$B$5*B12+$B$6*C12+$B$7*B12*C12 -> 2977.5 | E12: =$B$5+$B$7*C12 -> -15 | F12: =$B$6+$B$7*B12 -> 72.5 | G12: =IF(AND(IF(B12=1,E12>0,E12<0),IF(C12=1,F12>0,F12<0)),"strict local maximum","not a local maximum") -> strict local maximum
A13: years 1–5 | B13: 1 | C13: 1 | D13: =$B$4+$B$5*B13+$B$6*C13+$B$7*B13*C13 -> 2962.5 | E13: =$B$5+$B$7*C13 -> -15 | F13: =$B$6+$B$7*B13 -> -23.75 | G13: =IF(AND(IF(B13=1,E13>0,E13<0),IF(C13=1,F13>0,F13<0)),"strict local maximum","not a local maximum") -> not a local maximum
A16: The stationary plan inside the face | B16: Value | C16: Reading
A17: x* = -c / d (year-4 round) | B17: =-B6/B7 -> 0.75324675 | C17: 0.75
A18: y* = -b / d (year-5 round) | B18: =-B5/B7 -> 0.84415584 | C18: 0.84
A19: V* on the face | B19: =B4+B5*B17+B6*B18+B7*B17*B18 -> 2966.2013 | C19: 2,966.20
A20: V* from the model (Plans, the saddle's row) | B20: =Plans!U9 -> 2966.2013
A21: Hessian on the face, off the diagonal (the diagonal is 0) | B21: =B7 -> -96.25 | C21: the same at every point
A22: Its eigenvalue along (1, 1) | B22: =-ABS(B21) -> -96.25 | C22: value falls
A23: Its eigenvalue along (1, -1) | B23: =ABS(B21) -> 96.25 | C23: value rises: a saddle
A25: t (fraction of a round) | B25: Move t from year 5 to year 4: V - V* | C25: -d t^2 | D25: Add t to both rounds: V - V* | E25: d t^2
A26: 0.05 | B26: =$B$4+$B$5*($B$17+A26)+$B$6*($B$18-A26)+$B$7*($B$17+A26)*($B$18-A26)-$B$19 -> 0.240625 | C26: =-$B$7*A26^2 -> 0.240625 | D26: =$B$4+$B$5*($B$17+A26)+$B$6*($B$18+A26)+$B$7*($B$17+A26)*($B$18+A26)-$B$19 -> -0.240625 | E26: =$B$7*A26^2 -> -0.240625
A27: 0.1 | B27: =$B$4+$B$5*($B$17+A27)+$B$6*($B$18-A27)+$B$7*($B$17+A27)*($B$18-A27)-$B$19 -> 0.9625 | C27: =-$B$7*A27^2 -> 0.9625 | D27: =$B$4+$B$5*($B$17+A27)+$B$6*($B$18+A27)+$B$7*($B$17+A27)*($B$18+A27)-$B$19 -> -0.9625 | E27: =$B$7*A27^2 -> -0.9625
A28: 0.15 | B28: =$B$4+$B$5*($B$17+A28)+$B$6*($B$18-A28)+$B$7*($B$17+A28)*($B$18-A28)-$B$19 -> 2.165625 | C28: =-$B$7*A28^2 -> 2.165625 | D28: =$B$4+$B$5*($B$17+A28)+$B$6*($B$18+A28)+$B$7*($B$17+A28)*($B$18+A28)-$B$19 -> -2.165625 | E28: =$B$7*A28^2 -> -2.165625
A30: The basin boundary: y - y* = x - x*. Plans above it climb to years 1-3 and 5, plans below it to years 1-4. A tenth of a round moved from year 5 to year 4 adds about $1 million.
A32: V on the face: y down, x across | B32: x = 0.0 | C32: x = 0.1 | D32: x = 0.2 | E32: x = 0.3 | F32: x = 0.4 | G32: x = 0.5 | H32: x = 0.6 | I32: x = 0.7 | J32: x = 0.8 | K32: x = 0.9 | L32: x = 1.0
